Workbook

Sheet 廠價表
A1: check | B1: 溫層 | C1: 品名 | D1: 類別 | E1: 廠價
B2: 4度C | C2: 白酒蛤蜊義大利麵 | D2: 義大利麵 | E2: 57.21
B3: 4度C | C3: 熱那亞青醬義大利麵 | D3: 義大利麵 | E3: 50.67
B4: 4度C | C4: 義式蕃茄起司義大利麵 | D4: 義大利麵 | E4: 50.39
B5: 4度C | C5: 焗烤起司雙饗筆尖麵 | D5: 義大利麵 | E5: 49.97
B6: 4度C | C6: 奶油培根義大利麵 | D6: 義大利麵 | E6: 49.14
B7: 4度C | C7: 韓式起司炸雞義大利麵 | D7: 義大利麵 | E7: 57.21
B8: 4度C | C8: 韓式辣醬肉丸義大利麵 | D8: 義大利麵 | E8: 57.21
B9: 4度C | C9: 拿坡里義大利麵 | D9: 義大利麵 | E9: 58.17
B10: 4度C | C10: 羊乳起司培根筆尖麵 | D10: 義大利麵 | E10: 62.61
B11: 4度C | C11: 黑胡椒燻豬腿義大利麵 | D11: 義大利麵 | E11: 50.6
B12: 4度C | C12: 剝皮辣椒雞奶油扁麵 | D12: 義大利麵 | E12: 56.87
B13: 4度C | C13: 奶油蒜香雞義大利麵 | D13: 義大利麵 | E13: 55.13
... B32: 冷凍 | C32: 和風明太子細扁麵 | D32: 冷凍調理麵 | E32: 29.38

Sheet 產線配置圖
A1: 品項 | B1: 人數 | C1: 產能
A2: 白酒蛤蜊義大利麵 | B2: 13 | C2: 2000 | D2: ET-600
A3: 白酒蛤蜊義大利麵-手 | B3: 15 | C3: 1565 | D3: ET-55
A4: 熱那亞青醬義大利麵 | B4: 16 | C4: 1915
A5: 義式蕃茄起司義大利麵 | B5: 12 | C5: 2000
A6: 焗烤起司雙饗筆尖麵 | B6: 18 | C6: 1565
A7: 奶油培根義大利麵 | B7: 13 | C7: 2000
A8: 韓式起司炸雞義大利麵 | B8: 14 | C8: 1895
A9: 韓式辣醬肉丸義大利麵 | B9: 17 | C9: 1565
A10: 剝皮辣椒雞奶油扁麵 | B10: 17 | C10: 1500
A11: 拿坡里義大利麵 | B11: 16 | C11: 1429
A12: 家傳炸醬麵 | B12: 18 | C12: 1636
A13: 家傳炸醬麵-降速生產 | B13: 16 | C13: 1440
A14: 黑胡椒燻豬腿義大利麵 | B14: 18 | C14: 1500
A15: 黑胡椒燻豬腿義大利麵-降速生產 | B15: 13 | C15: 1385
... A27: 台式綜合甜不辣 | B27: 12 | C27: 1565
E32: 更新日期10/30

Sheet 1001總
B1: 長家廠組合室生產人時性分析
B3: 日期 | D3: 45931 | F3: 訂單量 | G3: ='1001'!E1 -> 59618 | I3: 營業額 | J3: ='1001'!G1 -> 2862983.5
B4: 項目 | D4: 3 | F4: ➀ | H4: ➁ | J4: ③
B5: 人時性 | D5: 組合室 | F5: 全溫層 | H5: 義大利麵 | J5: 袋裝小吃、義麵
D6: 排關平均 | F6: =AVERAGE(D13:J13) -> 117.9837 | H6: =AVERAGE(D13:H13) -> 113.67931 | J6: =AVERAGE(I13:J13) -> 128.74466
D7: 實績平均 | F7: =AVERAGE(D14:J14) -> 105.76208 | H7: =AVERAGE(D14:H14) -> 100.00485 | J7: =AVERAGE(I14:J14) -> 120.15516
D8: 達成率平均 | F8: =AVERAGE(D15:J15) -> 0.89982633 | H8: =AVERAGE(D15:H15) -> 0.88636358 | J8: =AVERAGE(I15:J15) -> 0.9334832 | L8: ※現行日本鮮食廠以達成率80%為基本(即為現行KPI)
B10: 溫層 | D10: 4度C-各編組展開
B11: 編組 | D11: 1 | E11: 2 | F11: 3 | G11: 4 | H11: 5 | I11: 6 | J11: 7
D12: 自動1線 | E12: 自動2線 | F12: 手工3線 | G12: 手工4線 | H12: 手工5線 | I12: 調理包1線 | J12: 調理包2線
B13: 人時性 | C13: 排關 | D13: =VALUE('1001'!L15) -> 149.2239 | E13: =VALUE('1001'!L26) -> 151.71675 | F13: =VALUE('1001'!L37) -> 87.449673 | G13: =VALUE('1001'!L48) -> 92.41636 | H13: =VALUE('1001'!L58) -> 87.589869 | I13: =VALUE('1001'!L69) -> 127.07265 | J13: =VALUE('1001'!L79) -> 130.41667
C14: 實績 | D14: =VALUE('1001'!O15) -> 130.15704 | E14: =VALUE('1001'!O26) -> 128.20092 | F14: =VALUE('1001'!O37) -> 77.822304 | G14: =VALUE('1001'!O48) -> 76.983357 | H14: =VALUE('1001'!O58) -> 86.860627 | I14: =VALUE('1001'!O69) -> 120.58206 | J14: =VALUE('1001'!O79) -> 119.72826
C15: 達成率 | D15: =D14/D13 -> 0.87222647 | E15: =E14/E13 -> 0.84500177 | F15: =F14/F13 -> 0.88990961 | G15: =G14/G13 -> 0.83300572 | H15: =H14/H13 -> 0.99167436 | I15: =I14/I13 -> 0.94892223 | J15: =J14/J13 -> 0.91804417
B16: 作業 時間 | C16: 開始 | D16: ='1001'!T5 -> 0.30347222 | E16: ='1001'!T16 -> 0.30347222 | F16: ='1001'!T27 -> 0.29305556 | G16: ='1001'!T38 -> 0.33263889 | H16: ='1001'!T49 -> 0.28819444 | I16: ='1001'!T59 -> 0.29166667 | J16: ='1001'!T70 -> 0.34930556
C17: 結束 | D17: 0.65138889 | E17: 0.64444444 | F17: 0.65486111 | G17: 0.63541667 | H17: 0.67986111 | I17: 0.62152778 | J17: 0.41319444
B18: 配置人數 | D18: =VALUE('1001'!M15) -> 13.5 | E18: =VALUE('1001'!M26) -> 13.25 | F18: =VALUE('1001'!M37) -> 16 | G18: =VALUE('1001'!M48) -> 16 | H18: =VALUE('1001'!M58) -> 17.5 | I18: =VALUE('1001'!M69) -> 12.333333 | J18: =VALUE('1001'!M79) -> 12
B19: 主要應用設備 | D19: ET-600 | E19: ET-600 | F19: ET-55 | G19: ET-55 | H19: ET-55 | I19: 八爪機 | J19: 封口機
B20: 次要應用設備 | H20: 封口機
B21: 備註 | J21: 義大利麵支援

Sheet 1001
A1: 長家廠4度C日報分析 | D1: 總生產量 | E1: =SUM(G5:G79) -> 59618 | F1: 營業額 | G1: =SUM(H5:H79) -> 2862983.5 | H1: 出勤人數 | I1: =M15+M26+M48+M58+M69+M79+M37 -> 100.58333 | J1: 產線配置圖 | M1: 生產實績 | P1: 人時性差異分析 | T1: 日報登錄 | Z1: 分析說明 | AB1: 產能差異分析
A2: 10月01日 星期三 | D2: 人時性 | E2: =AVERAGE(O15,O26,O37,O48,O58,O69,O79) -> 105.76208 | F2: 平均廠價 | G2: =G1/E1 -> 48.022132 | H2: 多次生產數 | I2: =COUNT(I5:I79) -> 0
A3: 線別 | B3: 品類 | D3: 品名 | F3: 廠價 | G3: 生產量 | H3: 營收 | I3: 多次 生產 | J3: 人數 | K3: 產能/時 | L3: 人時性 | M3: 人數 | N3: 產能/時 | O3: 人時性 | P3: 人數 | Q3: 人時性 | R3: 達成率 | S3: 達成率平均 | T3: 生產時間 | V3: 前置、換線時間/分 | W3: 稼動時間/分 | X3: 休息時間 | Z3: (長家回填) | AB3: 產能/時 | AC3: 達成率 | AD3: 達成率平均
T4: 開始 | U4: 結束 | X4: 開始 | Y4: 結束
A5: 自動一線 (ET-600) | B5: =VLOOKUP(D5,廠價表!$C$1:$E$39,2,0) -> 義大利麵 | D5: 白酒蛤蜊義大利麵 | F5: =VLOOKUP(D5,廠價表!$C$1:$E$39,3,0) -> 57.21 | G5: 1944 | H5: =F5*G5 -> 111216.24 | J5: =VLOOKUP(D5,產線配置圖!$A$2:$C$38,2,0) -> 13 | K5: =VLOOKUP(D5,產線配置圖!$A$2:$C$38,3,0) -> 2000 | L5: =K5/J5 -> 153.84615 | M5: 13 | N5: =G5/W5*60 -> 1715.2941 | O5: =N5/M5 -> 131.9457 | P5: =M5-J5 -> 0 | Q5: =O5-L5 -> -21.900452 | R5: =O5/L5 -> 0.85764706 | S5: =R15 -> 0.87222647 | T5: 0.30347222 | U5: 0.35069444 | W5: =(U5-T5)*24*60 -> 68 | Z5: 7:00-7:23試產煮麵 | AB5: =N5-K5 -> -284.70588 | AC5: =N5/K5 -> 0.85764706 | AD5: =AC15 -> 0.88446106
B6: =VLOOKUP(D6,廠價表!$C$1:$E$39,2,0) -> 義大利麵 | D6: 韓式起司炸雞義大利麵 | F6: =VLOOKUP(D6,廠價表!$C$1:$E$39,3,0) -> 57.21 | G6: 2871 | H6: =F6*G6 -> 164249.91 | J6: =VLOOKUP(D6,產線配置圖!$A$2:$C$38,2,0) -> 14 | K6: =VLOOKUP(D6,產線配置圖!$A$2:$C$38,3,0) -> 1895 | L6: =K6/J6 -> 135.35714 | M6: 15 | N6: =G6/W6*60 -> 1609.9065 | O6: =N6/M6 -> 107.3271 | P6: =M6-J6 -> 1 | Q6: =O6-L6 -> -28.03004 | R6: =O6/L6 -> 0.79291791 | T6: 0.36111111 | U6: 0.43541667 | V6: =(T6-U5)*24*60 -> 15 | W6: =(U6-T6)*24*60 -> 107 | Z6: 9:54-9:56玉取機異常 | AB6: =N6-K6 -> -285.09346 | AC6: =N6/K6 -> 0.8495549
B7: =VLOOKUP(D7,廠價表!$C$1:$E$39,2,0) -> 義大利麵 | D7: 奶油培根義大利麵 | F7: =VLOOKUP(D7,廠價表!$C$1:$E$39,3,0) -> 49.14 | G7: 2284 | H7: =F7*G7 -> 112235.76 | J7: =VLOOKUP(D7,產線配置圖!$A$2:$C$38,2,0) -> 13 | K7: =VLOOKUP(D7,產線配置圖!$A$2:$C$38,3,0) -> 2000 | L7: =K7/J7 -> 153.84615 | M7: 13 | N7: =G7/W7*60 -> 1803.1579 | O7: =N7/M7 -> 138.70445 | P7: =M7-J7 -> 0 | Q7: =O7-L7 -> -15.1417 | R7: =O7/L7 -> 0.90157895 | T7: 0.44722222 | U7: 0.5 | V7: =(T7-U6)*24*60 -> 17 | W7: =(U7-T7)*24*60 -> 76 | AB7: =N7-K7 -> -196.84211 | AC7: =N7/K7 -> 0.90157895
B8: =VLOOKUP(D8,廠價表!$C$1:$E$39,2,0) -> 義大利麵 | D8: 奶油培根義大利麵 | F8: =VLOOKUP(D8,廠價表!$C$1:$E$39,3,0) -> 49.14 | G8: 4018 | H8: =F8*G8 -> 197444.52 | J8: =VLOOKUP(D8,產線配置圖!$A$2:$C$38,2,0) -> 13 | K8: =VLOOKUP(D8,產線配置圖!$A$2:$C$38,3,0) -> 2000 | L8: =K8/J8 -> 153.84615 | M8: 13 | N8: =G8/W8*60 -> 1854.4615 | O8: =N8/M8 -> 142.65089 | P8: =M8-J8 -> 0 | Q8: =O8-L8 -> -11.195266 | R8: =O8/L8 -> 0.92723077 | T8: 0.56111111 | U8: 0.65138889 | V8: =(T8-U7)*24*60 -> 88 | W8: =(U8-T8)*24*60 -> 130 | X8: 0.51041667 | Y8: 0.55208333
H9: =F9*G9 -> 0 | W9: =(U9-T9)*24*60 -> 0
H10: =F10*G10 -> 0 | W10: =(U10-T10)*24*60 -> 0
H11: =F11*G11 -> 0 | W11: =(U11-T11)*24*60 -> 0
H12: =F12*G12 -> 0 | W12: =(U12-T12)*24*60 -> 0
H13: =F13*G13 -> 0 | W13: =(U13-T13)*24*60 -> 0
H14: =F14*G14 -> 0 | W14: =(U14-T14)*24*60 -> 0
C15: 4度一組 | D15: 平均 | J15: =AVERAGE(J5:J14) -> 13.25 | K15: =AVERAGE(K5:K14) -> 1973.75 | L15: =AVERAGE(L5:L14) -> 149.2239 | M15: =AVERAGE(M5:M14) -> 13.5 | N15: =AVERAGE(N5:N14) -> 1745.705 | O15: =AVERAGE(O5:O14) -> 130.15704 | P15: =M15-J15 -> 0.25 | Q15: =O15-L15 -> -19.066865 | R15: =O15/L15 -> 0.87222647 | AB15: =N15-K15 -> -228.04498 | AC15: =N15/K15 -> 0.88446106
A16: 自動二線 (ET-600) | B16: 義大利麵 | D16: 白酒蛤蜊義大利麵 | F16: =VLOOKUP(D16,廠價表!$C$1:$E$39,3,0) -> 57.21 | G16: 2286 | H16: =F16*G16 -> 130782.06 | J16: =VLOOKUP(D16,產線配置圖!$A$2:$C$38,2,0) -> 13 | K16: =VLOOKUP(D16,產線配置圖!$A$2:$C$38,3,0) -> 2000 | L16: =K16/J16 -> 153.84615 | M16: 13 | N16: =G16/W16*60 -> 1652.5301 | O16: =N16/M16 -> 127.1177 | P16: =M16-J16 -> 0 | Q16: =O16-L16 -> -26.728452 | R16: =O16/L16 -> 0.82626506 | S16: =R26 -> 0.84500177 | T16: 0.30347222 | U16: 0.36111111 | W16: =(U16-T16)*24*60 -> 83 | Z16: 7:06-7:20 封膜機故障、7:20-8:10 停麵 | AB16: =N16-K16 -> -347.46988 | AC16: =N16/K16 -> 0.82626506 | AD16: =AC26 -> 0.84269469
B17: 義大利麵 | D17: 熱那亞青醬義大利麵 | F17: =VLOOKUP(D17,廠價表!$C$1:$E$39,3,0) -> 50.67 | G17: 2335 | H17: =F17*G17 -> 118314.45 | J17: =VLOOKUP(D17,產線配置圖!$A$2:$C$38,2,0) -> 16 | K17: =VLOOKUP(D17,產線配置圖!$A$2:$C$38,3,0) -> 1915 | L17: =K17/J17 -> 119.6875 | M17: 16 | N17: =G17/W17*60 -> 1556.6667 | O17: =N17/M17 -> 97.291667 | P17: =M17-J17 -> 0 | Q17: =O17-L17 -> -22.395833 | R17: =O17/L17 -> 0.81288077 | T17: 0.36805556 | U17: 0.43055556 | V17: =(T17-U16)*24*60 -> 10 | W17: =(U17-T17)*24*60 -> 90 | AB17: =N17-K17 -> -358.33333 | AC17: =N17/K17 -> 0.81288077
B18: =VLOOKUP(D18,廠價表!$C$1:$E$39,2,0) -> 義大利麵 | D18: 義式蕃茄起司義大利麵 | F18: =VLOOKUP(D18,廠價表!$C$1:$E$39,3,0) -> 50.39 | G18: 2543 | H18: =F18*G18 -> 128141.77 | J18: =VLOOKUP(D18,產線配置圖!$A$2:$C$38,2,0) -> 12 | K18: =VLOOKUP(D18,產線配置圖!$A$2:$C$38,3,0) -> 2000 | L18: =K18/J18 -> 166.66667 | M18: 12 | N18: =G18/W18*60 -> 1860.7317 | O18: =N18/M18 -> 155.06098 | P18: =M18-J18 -> 0 | Q18: =O18-L18 -> -11.605691 | R18: =O18/L18 -> 0.93036585 | T18: 0.44027778 | U18: 0.49722222 | V18: =(T18-U17)*24*60 -> 14 | W18: =(U18-T18)*24*60 -> 82 | AB18: =N18-K18 -> -139.26829 | AC18: =N18/K18 -> 0.93036585
B19: =VLOOKUP(D19,廠價表!$C$1:$E$39,2,0) -> 義大利麵 | D19: 義式蕃茄起司義大利麵 | F19: =VLOOKUP(D19,廠價表!$C$1:$E$39,3,0) -> 50.39 | G19: 3200 | H19: =F19*G19 -> 161248 | J19: =VLOOKUP(D19,產線配置圖!$A$2:$C$38,2,0) -> 12 | K19: =VLOOKUP(D19,產線配置圖!$A$2:$C$38,3,0) -> 2000 | L19: =K19/J19 -> 166.66667 | M19: 12 | N19: =G19/W19*60 -> 1600 | O19: =N19/M19 -> 133.33333 | P19: =M19-J19 -> 0 | Q19: =O19-L19 -> -33.333333 | R19: =O19/L19 -> 0.8 | T19: 0.56111111 | U19: 0.64444444 | V19: =(T19-U18)*24*60 -> 92 | W19: =(U19-T19)*24*60 -> 120 | X19: 0.51041667 | Y19: 0.55208333 | Z19: 待料(牛絞肉) | AB19: =N19-K19 -> -400 | AC19: =N19/K19 -> 0.8
H20: =F20*G20 -> 0 | W20: 0
H21: =F21*G21 -> 0 | W21: 0
H22: =F22*G22 -> 0 | W22: 0
H23: =F23*G23 -> 0 | W23: =(U23-T23)*24*60 -> 0
H24: =F24*G24 -> 0 | W24: =(U24-T24)*24*60 -> 0
H25: =F25*G25 -> 0 | W25: =(U25-T25)*24*60 -> 0
C26: 4度二組A | D26: 平均 | J26: =AVERAGE(J16:J25) -> 13.25 | K26: =AVERAGE(K16:K25) -> 1978.75 | L26: =AVERAGE(L16:L25) -> 151.71675 | M26: =AVERAGE(M16:M25) -> 13.25 | N26: =AVERAGE(N16:N25) -> 1667.4821 | O26: =AVERAGE(O16:O25) -> 128.20092 | P26: =M26-J26 -> 0 | Q26: =O26-L26 -> -23.515827 | R26: =O26/L26 -> 0.84500177 | AB26: =N26-K26 -> -311.26788 | AC26: =N26/K26 -> 0.84269469
A27: 手工三線 (ET-55) | B27: 義大利麵 | D27: 黑胡椒燻豬腿義大利麵 | F27: =VLOOKUP(D27,廠價表!$C$1:$E$39,3,0) -> 50.6 | G27: 1431 | H27: =F27*G27 -> 72408.6 | J27: 17 | K27: 1636 | L27: =K27/J27 -> 96.235294 | M27: 16 | N27: =G27/W27*60 -> 1300.9091 | O27: =N27/M27 -> 81.306818 | P27: =M27-J27 -> -1 | Q27: =O27-L27 -> -14.928476 | R27: =O27/L27 -> 0.84487525 | S27: =R37 -> 0.88990961 | T27: 0.29305556 | U27: 0.33888889 | W27: =(U27-T27)*24*60 -> 66 | AB27: =N27-K27 -> -335.09091 | AC27: =N27/K27 -> 0.79517671 | AD27: =AC37 -> 0.81021675
B28: =VLOOKUP(D28,廠價表!$C$1:$E$39,2,0) -> 義大利麵 | D28: 韓式辣醬肉丸義大利麵 | F28: =VLOOKUP(D28,廠價表!$C$1:$E$39,3,0) -> 57.21 | G28: 2115 | H28: =F28*G28 -> 120999.15 | J28: 17 | K28: 1636 | L28: =K28/J28 -> 96.235294 | M28: 15 | N28: =G28/W28*60 -> 1164.2202 | O28: =N28/M28 -> 77.614679 | P28: =M28-J28 -> -2 | Q28: =O28-L28 -> -18.620615 | R28: =O28/L28 -> 0.8065095 | T28: 0.34722222 | U28: 0.42291667 | V28: =(T28-U27)*24*60 -> 12 | W28: =(U28-T28)*24*60 -> 109 | Z28: 待料(番茄丁) | AB28: =N28-K28 -> -471.77982 | AC28: =N28/K28 -> 0.71162603
B29: =VLOOKUP(D29,廠價表!$C$1:$E$39,2,0) -> 義大利麵 | D29: 奶油蒜香雞義大利麵 | F29: =VLOOKUP(D29,廠價表!$C$1:$E$39,3,0) -> 55.13 | G29: 1749 | H29: =F29*G29 -> 96422.37 | J29: =VLOOKUP(D29,產線配置圖!$A$2:$C$38,2,0) -> 18 | K29: =VLOOKUP(D29,產線配置圖!$A$2:$C$38,3,0) -> 1385 | L29: =K29/J29 -> 76.944444 | M29: 16 | N29: =G29/W29*60 -> 1220.2326 | O29: =N29/M29 -> 76.264535 | P29: =M29-J29 -> -2 | Q29: =O29-L29 -> -0.67990956 | R29: =O29/L29 -> 0.99116363 | T29: 0.42986111 | U29: 0.48958333 | V29: =(T29-U28)*24*60 -> 10 | W29: =(U29-T29)*24*60 -> 86 | AB29: =N29-K29 -> -164.76744 | AC29: =N29/K29 -> 0.88103434
B30: =VLOOKUP(D30,廠價表!$C$1:$E$39,2,0) -> 熱乾麵 | D30: 家傳炸醬麵 | F30: =VLOOKUP(D30,廠價表!$C$1:$E$39,3,0) -> 47.6 | G30: 1999 | H30: =F30*G30 -> 95152.4 | J30: =VLOOKUP(D30,產線配置圖!$A$2:$C$38,2,0) -> 18 | K30: =VLOOKUP(D30,產線配置圖!$A$2:$C$38,3,0) -> 1636 | L30: =K30/J30 -> 90.888889 | M30: 15 | N30: =G30/W30*60 -> 1175.8824 | O30: =N30/M30 -> 78.392157 | P30: =M30-J30 -> -3 | Q30: =O30-L30 -> -12.496732 | R30: =O30/L30 -> 0.86250539 | T30: 0.54513889 | U30: 0.61597222 | V30: =(T30-U29)*24*60 -> 80 | W30: =(U30-T30)*24*60 -> 102 | X30: 0.5 | Y30: 0.54166667 | AB30: =N30-K30 -> -460.11765 | AC30: =N30/K30 -> 0.71875449
B31: =VLOOKUP(D31,廠價表!$C$1:$E$39,2,0) -> 義大利麵 | D31: 奶油蒜香雞義大利麵 | F31: =VLOOKUP(D31,廠價表!$C$1:$E$39,3,0) -> 55.13 | G31: 1133 | H31: =F31*G31 -> 62462.29 | J31: =VLOOKUP(D31,產線配置圖!$A$2:$C$38,2,0) -> 18 | K31: =VLOOKUP(D31,產線配置圖!$A$2:$C$38,3,0) -> 1385 | L31: =K31/J31 -> 76.944444 | M31: 18 | N31: =G31/W31*60 -> 1359.6 | O31: =N31/M31 -> 75.533333 | P31: =M31-J31 -> 0 | Q31: =O31-L31 -> -1.4111111 | R31: =O31/L31 -> 0.98166065 | T31: 0.62013889 | U31: 0.65486111 | V31: =(T31-U30)*24*60 -> 6 | W31: =(U31-T31)*24*60 -> 50 | AB31: =N31-K31 -> -25.4 | AC31: =N31/K31 -> 0.98166065
H32: =F32*G32 -> 0 | W32: =(U32-T32)*24*60 -> 0
H33: =F33*G33 -> 0 | W33: =(U33-T33)*24*60 -> 0
H34: =F34*G34 -> 0 | W34: =(U34-T34)*24*60 -> 0
H35: =F35*G35 -> 0 | W35: =(U35-T35)*24*60 -> 0
H36: =F36*G36 -> 0 | W36: =(U36-T36)*24*60 -> 0
C37: 4度二組B | D37: 平均 | J37: =AVERAGE(J27:J36) -> 17.6 | K37: =AVERAGE(K27:K36) -> 1535.6 | L37: =AVERAGE(L27:L36) -> 87.449673 | M37: =AVERAGE(M27:M36) -> 16 | N37: =AVERAGE(N27:N36) -> 1244.1688 | O37: =AVERAGE(O27:O36) -> 77.822304 | P37: =M37-J37 -> -1.6 | Q37: =N37-K37 -> -291.43116 | R37: =O37/L37 -> 0.88990961 | AB37: =N37-K37 -> -291.43116 | AC37: =N37/K37 -> 0.81021675
A38: 手工四線 (ET-55) | B38: 熱乾麵 | C38: =VLOOKUP(E38,廠價表!$C$1:$E$39,2,0) -> #N/A | D38: 青花椒麻雞肉拌麵 | F38: =VLOOKUP(D38,廠價表!$C$1:$E$39,3,0) -> 49.91 | G38: 2618 | H38: =F38*G38 -> 130664.38 | J38: =VLOOKUP(D38,產線配置圖!$A$2:$C$38,2,0) -> 17 | K38: =VLOOKUP(D38,產線配置圖!$A$2:$C$38,3,0) -> 1565 | L38: =K38/J38 -> 92.058824 | M38: 16 | N38: =G38/W38*60 -> 1468.0374 | O38: =N38/M38 -> 91.752336 | P38: =M38-J38 -> -1 | Q38: =O38-L38 -> -0.30648708 | R38: =O38/L38 -> 0.99667075 | S38: =R48 -> 0.83300572 | T38: 0.33263889 | U38: 0.40694444 | W38: =(U38-T38)*24*60 -> 107 | AB38: =N38-K38 -> -96.962617 | AC38: =N38/K38 -> 0.93804306 | AD38: =AC48 -> 0.79530828
B39: =VLOOKUP(D39,廠價表!$C$1:$E$39,2,0) -> 義大利麵 | C39: =VLOOKUP(E39,廠價表!$C$1:$E$39,2,0) -> #N/A | D39: 羊乳起司培根筆尖麵 | F39: =VLOOKUP(D39,廠價表!$C$1:$E$39,3,0) -> 62.61 | G39: 1232 | H39: =F39*G39 -> 77135.52 | J39: =VLOOKUP(D39,產線配置圖!$A$2:$C$38,2,0) -> 17 | K39: =VLOOKUP(D39,產線配置圖!$A$2:$C$38,3,0) -> 1636 | L39: =K39/J39 -> 96.235294 | M39: 16 | N39: =G39/W39*60 -> 1137.2308 | O39: =N39/M39 -> 71.076923 | P39: =M39-J39 -> -1 | Q39: =O39-L39 -> -25.158371 | R39: =O39/L39 -> 0.73857438 | T39: 0.4125 | U39: 0.45763889 | V39: =(T39-U38)*24*60 -> 8 | W39: =(U39-T39)*24*60 -> 65 | Z39: 10:25-10:50機台異常 | AB39: =N39-K39 -> -498.76923 | AC39: =N39/K39 -> 0.69512883
B40: =VLOOKUP(D40,廠價表!$C$1:$E$39,2,0) -> 義大利麵 | D40: 拿坡里義大利麵 | F40: =VLOOKUP(D40,廠價表!$C$1:$E$39,3,0) -> 58.17 | G40: 1565 | H40: =F40*G40 -> 91036.05 | J40: =VLOOKUP(D40,產線配置圖!$A$2:$C$38,2,0) -> 16 | K40: =VLOOKUP(D40,產線配置圖!$A$2:$C$38,3,0) -> 1429 | L40: =K40/J40 -> 89.3125 | M40: 16 | N40: =G40/W40*60 -> 1043.3333 | O40: =N40/M40 -> 65.208333 | P40: =M40-J40 -> 0 | Q40: =O40-L40 -> -24.104167 | R40: =O40/L40 -> 0.7301143 | T40: 0.46458333 | U40: 0.52708333 | V40: =(T40-U39)*24*60 -> 10 | W40: =(U40-T40)*24*60 -> 90 | Z40: 封膜機台異常 | AB40: =N40-K40 -> -385.66667 | AC40: =N40/K40 -> 0.7301143
...

Sheet 1002總 
B1: 長家廠組合室生產人時性分析
B3: 日期 | D3: 45932 | F3: 訂單量 | G3: ='1002'!E1 -> 51111 | I3: 營業額 | J3: ='1002'!G1 -> 2526872.9
B4: 項目 | D4: 3 | F4: ➀ | H4: ➁ | J4: ③
B5: 人時性 | D5: 組合室 | F5: 全溫層 | H5: 義大利麵 | J5: 袋裝小吃、義麵
D6: 排關平均 | F6: =AVERAGE(D13:J13) -> 115.80807 | H6: =AVERAGE(D13:H13) -> 113.55516 | J6: =AVERAGE(I13) -> 127.07265
D7: 實績平均 | F7: =AVERAGE(D14:J14) -> 100.78229 | H7: =AVERAGE(D14:H14) -> 97.630617 | J7: =AVERAGE(I14) -> 116.54067
D8: 達成率平均 | F8: =AVERAGE(D15:J15) -> 0.87301928 | H8: =AVERAGE(D15:H15) -> 0.86419945 | J8: =AVERAGE(I15) -> 0.91711841 | L8: ※現行日本鮮食廠以達成率80%為基本(即為現行KPI)
B10: 溫層 | D10: 4度C-各編組展開
B11: 編組 | D11: 1 | E11: 2 | F11: 3 | G11: 4 | H11: 5 | I11: 6 | J11: 7
D12: 自動1線 | E12: 自動2線 | F12: 手工3線 | G12: 手工4線 | H12: 手工5線 | I12: 調理包1線 | J12: 調理包2線
B13: 人時性 | C13: 排關 | D13: =VALUE('1002'!L15) -> 149.2239 | E13: =VALUE('1002'!L26) -> 151.71675 | F13: =VALUE('1002'!L37) -> 87.449673 | G13: =VALUE('1002'!L48) -> 91.795588 | H13: =VALUE('1002'!L58) -> 87.589869 | I13: =VALUE('1002'!L69) -> 127.07265
C14: 實績 | D14: =VALUE('1002'!O15) -> 127.83883 | E14: =VALUE('1002'!O26) -> 126.37997 | F14: =VALUE('1002'!O37) -> 71.843325 | G14: =VALUE('1002'!O48) -> 78.000367 | H14: =VALUE('1002'!O58) -> 84.090586 | I14: =VALUE('1002'!O69) -> 116.54067
C15: 達成率 | D15: =D14/D13 -> 0.85669141 | E15: =E14/E13 -> 0.83299948 | F15: =F14/F13 -> 0.82153909 | G15: =G14/G13 -> 0.84971804 | H15: =H14/H13 -> 0.96004923 | I15: =I14/I13 -> 0.91711841
B16: 作業 時間 | C16: 開始 | D16: ='1002'!T5 -> 0.29166667 | E16: ='1002'!T16 -> 0.29236111 | F16: ='1002'!T27 -> 0.30486111 | G16: ='1002'!T38 -> 0.33263889 | H16: ='1002'!T49 -> 0.29166667 | I16: ='1002'!T59 -> 0.29166667
C17: 結束 | D17: 0.63402778 | E17: 0.64097222 | F17: 0.65555556 | G17: 0.60138889 | H17: 0.66597222 | I17: 0.51041667
B18: 配置人數 | D18: =VALUE('1002'!M15) -> 13.25 | E18: =VALUE('1002'!M26) -> 13.25 | F18: =VALUE('1002'!M37) -> 16.8 | G18: =VALUE('1002'!M48) -> 15.4 | H18: =VALUE('1002'!M58) -> 17.5 | I18: =VALUE('1002'!M69) -> 12.333333
B19: 主要應用設備 | D19: ET-600 | E19: ET-600 | F19: ET-55 | G19: ET-55 | H19: ET-55 | I19: 八爪機
B20: 次要應用設備 | H20: 封口機
B21: 備註

Sheet 1002
A1: 長家廠4度C日報分析 | D1: 總生產量 | E1: =SUM(G5:G79) -> 51111 | F1: 營業額 | G1: =SUM(H5:H79) -> 2526872.9 | H1: 出勤人數 | I1: =M15+M26+M48+M58+M69+M79+M37 -> 88.533333 | J1: 產線配置圖 | M1: 生產實績 | P1: 人時性差異分析 | T1: 日報登錄 | Z1: 分析說明 | AB1: 產能差異分析
A2: 10月02日 星期四 | D2: 人時性 | E2: =AVERAGE(O15,O26,O37,O48,O58,O69,O79) -> 100.78229 | F2: 平均廠價 | G2: =G1/E1 -> 49.438926 | H2: 多次生產數 | I2: =COUNT(I5:I79) -> 0
A3: 線別 | B3: 品類 | D3: 品名 | F3: 廠價 | G3: 生產量 | H3: 營收 | I3: 多次 生產 | J3: 人數 | K3: 產能/時 | L3: 人時性 | M3: 人數 | N3: 產能/時 | O3: 人時性 | P3: 人數 | Q3: 人時性 | R3: 達成率 | S3: 達成率平均 | T3: 生產時間 | V3: 前置、換線時間/分 | W3: 稼動時間/分 | X3: 休息時間 | Z3: (長家回填) | AB3: 產能/時 | AC3: 達成率 | AD3: 達成率平均
T4: 開始 | U4: 結束 | X4: 開始 | Y4: 結束
A5: 自動一線 (ET-600) | B5: =VLOOKUP(D5,廠價表!$C$1:$E$39,2,0) -> 義大利麵 | D5: 白酒蛤蜊義大利麵 | F5: =VLOOKUP(D5,廠價表!$C$1:$E$39,3,0) -> 57.21 | G5: 1895 | H5: =F5*G5 -> 108412.95 | J5: =VLOOKUP(D5,產線配置圖!$A$2:$C$38,2,0) -> 13 | K5: =VLOOKUP(D5,產線配置圖!$A$2:$C$38,3,0) -> 2000 | L5: =K5/J5 -> 153.84615 | M5: 13 | N5: =G5/W5*60 -> 1895 | O5: =N5/M5 -> 145.76923 | P5: =M5-J5 -> 0 | Q5: =O5-L5 -> -8.0769231 | R5: =O5/L5 -> 0.9475 | S5: =R15 -> 0.85669141 | T5: 0.29166667 | U5: 0.33333333 | W5: =(U5-T5)*24*60 -> 60 | AB5: =N5-K5 -> -105 | AC5: =N5/K5 -> 0.9475 | AD5: =AC15 -> 0.85352494
B6: =VLOOKUP(D6,廠價表!$C$1:$E$39,2,0) -> 義大利麵 | D6: 韓式起司炸雞義大利麵 | F6: =VLOOKUP(D6,廠價表!$C$1:$E$39,3,0) -> 57.21 | G6: 2653 | H6: =F6*G6 -> 151778.13 | J6: =VLOOKUP(D6,產線配置圖!$A$2:$C$38,2,0) -> 14 | K6: =VLOOKUP(D6,產線配置圖!$A$2:$C$38,3,0) -> 1895 | L6: =K6/J6 -> 135.35714 | M6: 14 | N6: =G6/W6*60 -> 1273.44 | O6: =N6/M6 -> 90.96 | P6: =M6-J6 -> 0 | Q6: =O6-L6 -> -44.397143 | R6: =O6/L6 -> 0.672 | T6: 0.34375 | U6: 0.43055556 | V6: =(T6-U5)*24*60 -> 15 | W6: =(U6-T6)*24*60 -> 125 | Z6: 8:46~9:06、9:32~9:43待料(炸雞未冷卻) | AB6: =N6-K6 -> -621.56 | AC6: =N6/K6 -> 0.672
B7: =VLOOKUP(D7,廠價表!$C$1:$E$39,2,0) -> 義大利麵 | D7: 奶油培根義大利麵 | F7: =VLOOKUP(D7,廠價表!$C$1:$E$39,3,0) -> 49.14 | G7: 2175 | H7: =F7*G7 -> 106879.5 | J7: =VLOOKUP(D7,產線配置圖!$A$2:$C$38,2,0) -> 13 | K7: =VLOOKUP(D7,產線配置圖!$A$2:$C$38,3,0) -> 2000 | L7: =K7/J7 -> 153.84615 | M7: 13 | N7: =G7/W7*60 -> 1864.2857 | O7: =N7/M7 -> 143.40659 | P7: =M7-J7 -> 0 | Q7: =O7-L7 -> -10.43956 | R7: =O7/L7 -> 0.93214286 | T7: 0.4375 | U7: 0.48611111 | V7: =(T7-U6)*24*60 -> 10 | W7: =(U7-T7)*24*60 -> 70 | AB7: =N7-K7 -> -135.71429 | AC7: =N7/K7 -> 0.93214286
B8: =VLOOKUP(D8,廠價表!$C$1:$E$39,2,0) -> 義大利麵 | D8: 奶油培根義大利麵 | F8: =VLOOKUP(D8,廠價表!$C$1:$E$39,3,0) -> 49.14 | G8: 3497 | H8: =F8*G8 -> 171842.58 | J8: =VLOOKUP(D8,產線配置圖!$A$2:$C$38,2,0) -> 13 | K8: =VLOOKUP(D8,產線配置圖!$A$2:$C$38,3,0) -> 2000 | L8: =K8/J8 -> 153.84615 | M8: 13 | N8: =G8/W8*60 -> 1705.8537 | O8: =N8/M8 -> 131.21951 | P8: =M8-J8 -> 0 | Q8: =O8-L8 -> -22.626642 | R8: =O8/L8 -> 0.85292683 | T8: 0.54861111 | U8: 0.63402778 | V8: =(T8-U7)*24*60 -> 90 | W8: =(U8-T8)*24*60 -> 123
H9: =F9*G9 -> 0 | W9: =(U9-T9)*24*60 -> 0
H10: =F10*G10 -> 0 | W10: =(U10-T10)*24*60 -> 0
H11: =F11*G11 -> 0 | W11: =(U11-T11)*24*60 -> 0
H12: =F12*G12 -> 0 | W12: =(U12-T12)*24*60 -> 0
H13: =F13*G13 -> 0 | W13: =(U13-T13)*24*60 -> 0
H14: =F14*G14 -> 0 | W14: =(U14-T14)*24*60 -> 0
C15: 4度一組 | D15: 平均 | J15: =AVERAGE(J5:J14) -> 13.25 | K15: =AVERAGE(K5:K14) -> 1973.75 | L15: =AVERAGE(L5:L14) -> 149.2239 | M15: =AVERAGE(M5:M14) -> 13.25 | N15: =AVERAGE(N5:N14) -> 1684.6448 | O15: =AVERAGE(O5:O14) -> 127.83883 | P15: =M15-J15 -> 0 | Q15: =O15-L15 -> -21.385067 | R15: =O15/L15 -> 0.85669141 | AB15: =N15-K15 -> -289.10516 | AC15: =N15/K15 -> 0.85352494
A16: 自動二線 (ET-600) | B16: 義大利麵 | D16: 白酒蛤蜊義大利麵 | F16: =VLOOKUP(D16,廠價表!$C$1:$E$39,3,0) -> 57.21 | G16: 2031 | H16: =F16*G16 -> 116193.51 | J16: =VLOOKUP(D16,產線配置圖!$A$2:$C$38,2,0) -> 13 | K16: =VLOOKUP(D16,產線配置圖!$A$2:$C$38,3,0) -> 2000 | L16: =K16/J16 -> 153.84615 | M16: 13 | N16: =G16/W16*60 -> 1904.0625 | O16: =N16/M16 -> 146.46635 | P16: =M16-J16 -> 0 | Q16: =O16-L16 -> -7.3798077 | R16: =O16/L16 -> 0.95203125 | S16: =R26 -> 0.83299948 | T16: 0.29236111 | U16: 0.33680556 | W16: =(U16-T16)*24*60 -> 64 | AB16: =N16-K16 -> -95.9375 | AC16: =N16/K16 -> 0.95203125 | AD16: =AC26 -> 0.83726648
B17: 義大利麵 | D17: 熱那亞青醬義大利麵 | F17: =VLOOKUP(D17,廠價表!$C$1:$E$39,3,0) -> 50.67 | G17: 2237 | H17: =F17*G17 -> 113348.79 | J17: =VLOOKUP(D17,產線配置圖!$A$2:$C$38,2,0) -> 16 | K17: =VLOOKUP(D17,產線配置圖!$A$2:$C$38,3,0) -> 1915 | L17: =K17/J17 -> 119.6875 | M17: 16 | N17: =G17/W17*60 -> 1657.037 | O17: =N17/M17 -> 103.56481 | P17: =M17-J17 -> 0 | Q17: =O17-L17 -> -16.122685 | R17: =O17/L17 -> 0.86529349 | T17: 0.34375 | U17: 0.4 | V17: =(T17-U16)*24*60 -> 10 | W17: =(U17-T17)*24*60 -> 81 | AB17: =N17-K17 -> -257.96296 | AC17: =N17/K17 -> 0.86529349
B18: =VLOOKUP(D18,廠價表!$C$1:$E$39,2,0) -> 義大利麵 | D18: 義式蕃茄起司義大利麵 | F18: =VLOOKUP(D18,廠價表!$C$1:$E$39,3,0) -> 50.39 | G18: 1870 | H18: =F18*G18 -> 94229.3 | J18: =VLOOKUP(D18,產線配置圖!$A$2:$C$38,2,0) -> 12 | K18: =VLOOKUP(D18,產線配置圖!$A$2:$C$38,3,0) -> 2000 | L18: =K18/J18 -> 166.66667 | M18: 12 | N18: =G18/W18*60 -> 1457.1429 | O18: =N18/M18 -> 121.42857 | P18: =M18-J18 -> 0 | Q18: =O18-L18 -> -45.238095 | R18: =O18/L18 -> 0.72857143 | T18: 0.41041667 | U18: 0.46388889 | V18: =(T18-U17)*24*60 -> 15 | W18: =(U18-T18)*24*60 -> 77 | Z18: 9:51~11:28製作2420盒，550盒報廢(湯凍異常) | AB18: =N18-K18 -> -542.85714 | AC18: =N18/K18 -> 0.72857143
B19: =VLOOKUP(D19,廠價表!$C$1:$E$39,2,0) -> 義大利麵 | D19: 義式蕃茄起司義大利麵 | F19: =VLOOKUP(D19,廠價表!$C$1:$E$39,3,0) -> 50.39 | G19: 3566 | H19: =F19*G19 -> 179690.74 | J19: =VLOOKUP(D19,產線配置圖!$A$2:$C$38,2,0) -> 12 | K19: =VLOOKUP(D19,產線配置圖!$A$2:$C$38,3,0) -> 2000 | L19: =K19/J19 -> 166.66667 | M19: 12 | N19: =G19/W19*60 -> 1608.7218 | O19: =N19/M19 -> 134.06015 | P19: =M19-J19 -> 0 | Q19: =O19-L19 -> -32.606516 | R19: =O19/L19 -> 0.8043609 | T19: 0.54861111 | U19: 0.64097222 | V19: =(T19-U18)*24*60 -> 122 | W19: =(U19-T19)*24*60 -> 133 | AB19: =N19-K19 -> -391.2782 | AC19: =N19/K19 -> 0.8043609
H20: =F20*G20 -> 0 | W20: 0
H21: =F21*G21 -> 0 | W21: 0
H22: =F22*G22 -> 0 | W22: 0
H23: =F23*G23 -> 0 | W23: =(U23-T23)*24*60 -> 0
H24: =F24*G24 -> 0 | W24: =(U24-T24)*24*60 -> 0
H25: =F25*G25 -> 0 | W25: =(U25-T25)*24*60 -> 0
C26: 4度二組A | D26: 平均 | J26: =AVERAGE(J16:J25) -> 13.25 | K26: =AVERAGE(K16:K25) -> 1978.75 | L26: =AVERAGE(L16:L25) -> 151.71675 | M26: =AVERAGE(M16:M25) -> 13.25 | N26: =AVERAGE(N16:N25) -> 1656.741 | O26: =AVERAGE(O16:O25) -> 126.37997 | P26: =M26-J26 -> 0 | Q26: =O26-L26 -> -25.336776 | R26: =O26/L26 -> 0.83299948 | AB26: =N26-K26 -> -322.00895 | AC26: =N26/K26 -> 0.83726648
A27: 手工三線 (ET-55) | B27: 義大利麵 | D27: 黑胡椒燻豬腿義大利麵 | F27: =VLOOKUP(D27,廠價表!$C$1:$E$39,3,0) -> 50.6 | G27: 1365 | H27: =F27*G27 -> 69069 | J27: 17 | K27: 1636 | L27: =K27/J27 -> 96.235294 | M27: 15 | N27: =G27/W27*60 -> 1092 | O27: =N27/M27 -> 72.8 | P27: =M27-J27 -> -2 | Q27: =O27-L27 -> -23.435294 | R27: =O27/L27 -> 0.75647922 | S27: =R37 -> 0.82153909 | T27: 0.30486111 | U27: 0.35694444 | W27: =(U27-T27)*24*60 -> 75 | Z27: 6:50~7:19醬太稀停線拆盒 | AB27: =N27-K27 -> -544 | AC27: =N27/K27 -> 0.66748166 | AD27: =AC37 -> 0.78473874
B28: =VLOOKUP(D28,廠價表!$C$1:$E$39,2,0) -> 義大利麵 | D28: 韓式辣醬肉丸義大利麵 | F28: =VLOOKUP(D28,廠價表!$C$1:$E$39,3,0) -> 57.21 | G28: 2019 | H28: =F28*G28 -> 115506.99 | J28: 17 | K28: 1636 | L28: =K28/J28 -> 96.235294 | M28: 15 | N28: =G28/W28*60 -> 1111.3761 | O28: =N28/M28 -> 74.091743 | P28: =M28-J28 -> -2 | Q28: =O28-L28 -> -22.143551 | R28: =O28/L28 -> 0.76990198 | T28: 0.36527778 | U28: 0.44097222 | V28: =(T28-U27)*24*60 -> 12 | W28: =(U28-T28)*24*60 -> 109 | Z28: 8:40~8:45待料(海苔酥) | AB28: =N28-K28 -> -524.62385 | AC28: =N28/K28 -> 0.67932527
B29: =VLOOKUP(D29,廠價表!$C$1:$E$39,2,0) -> 義大利麵 | D29: 奶油蒜香雞義大利麵 | F29: =VLOOKUP(D29,廠價表!$C$1:$E$39,3,0) -> 55.13 | G29: 1572 | H29: =F29*G29 -> 86664.36 | J29: =VLOOKUP(D29,產線配置圖!$A$2:$C$38,2,0) -> 18 | K29: =VLOOKUP(D29,產線配置圖!$A$2:$C$38,3,0) -> 1385 | L29: =K29/J29 -> 76.944444 | M29: 18 | N29: =G29/W29*60 -> 1136.3855 | O29: =N29/M29 -> 63.13253 | P29: =M29-J29 -> 0 | Q29: =O29-L29 -> -13.811914 | R29: =O29/L29 -> 0.82049498 | T29: 0.44583333 | U29: 0.50347222 | V29: =(T29-U28)*24*60 -> 7 | W29: =(U29-T29)*24*60 -> 83 | AB29: =N29-K29 -> -248.61446 | AC29: =N29/K29 -> 0.82049498
B30: =VLOOKUP(D30,廠價表!$C$1:$E$39,2,0) -> 熱乾麵 | D30: 家傳炸醬麵 | F30: =VLOOKUP(D30,廠價表!$C$1:$E$39,3,0) -> 47.6 | G30: 1602 | H30: =F30*G30 -> 76255.2 | J30: =VLOOKUP(D30,產線配置圖!$A$2:$C$38,2,0) -> 18 | K30: =VLOOKUP(D30,產線配置圖!$A$2:$C$38,3,0) -> 1636 | L30: =K30/J30 -> 90.888889 | M30: 18 | N30: =G30/W30*60 -> 1316.7123 | O30: =N30/M30 -> 73.150685 | P30: =M30-J30 -> 0 | Q30: =O30-L30 -> -17.738204 | R30: =O30/L30 -> 0.80483639 | T30: 0.56458333 | U30: 0.61527778 | V30: =(T30-U29)*24*60 -> 88 | W30: =(U30-T30)*24*60 -> 73 | AB30: =N30-K30 -> -319.28767 | AC30: =N30/K30 -> 0.80483639
B31: =VLOOKUP(D31,廠價表!$C$1:$E$39,2,0) -> 義大利麵 | D31: 奶油蒜香雞義大利麵 | F31: =VLOOKUP(D31,廠價表!$C$1:$E$39,3,0) -> 55.13 | G31: 1095 | H31: =F31*G31 -> 60367.35 | J31: =VLOOKUP(D31,產線配置圖!$A$2:$C$38,2,0) -> 18 | K31: =VLOOKUP(D31,產線配置圖!$A$2:$C$38,3,0) -> 1385 | L31: =K31/J31 -> 76.944444 | M31: 18 | N31: =G31/W31*60 -> 1368.75 | O31: =N31/M31 -> 76.041667 | P31: =M31-J31 -> 0 | Q31: =O31-L31 -> -0.90277778 | R31: =O31/L31 -> 0.98826715 | T31: 0.62222222 | U31: 0.65555556 | V31: =(T31-U30)*24*60 -> 10 | W31: =(U31-T31)*24*60 -> 48 | AB31: =N31-K31 -> -16.25 | AC31: =N31/K31 -> 0.98826715
H32: =F32*G32 -> 0 | W32: =(U32-T32)*24*60 -> 0
H33: =F33*G33 -> 0 | W33: =(U33-T33)*24*60 -> 0
H34: =F34*G34 -> 0 | W34: =(U34-T34)*24*60 -> 0
H35: =F35*G35 -> 0 | W35: =(U35-T35)*24*60 -> 0
H36: =F36*G36 -> 0 | W36: =(U36-T36)*24*60 -> 0
C37: 4度二組B | D37: 平均 | J37: =AVERAGE(J27:J36) -> 17.6 | K37: =AVERAGE(K27:K36) -> 1535.6 | L37: =AVERAGE(L27:L36) -> 87.449673 | M37: =AVERAGE(M27:M36) -> 16.8 | N37: =AVERAGE(N27:N36) -> 1205.0448 | O37: =AVERAGE(O27:O36) -> 71.843325 | P37: =M37-J37 -> -0.8 | Q37: =N37-K37 -> -330.5552 | R37: =O37/L37 -> 0.82153909 | AB37: =N37-K37 -> -330.5552 | AC37: =N37/K37 -> 0.78473874
A38: 手工四線 (ET-55) | B38: 熱乾麵 | C38: =VLOOKUP(E38,廠價表!$C$1:$E$39,2,0) -> #N/A | D38: 青花椒麻雞肉拌麵 | F38: =VLOOKUP(D38,廠價表!$C$1:$E$39,3,0) -> 49.91 | G38: 2016 | H38: =F38*G38 -> 100618.56 | J38: =VLOOKUP(D38,產線配置圖!$A$2:$C$38,2,0) -> 17 | K38: =VLOOKUP(D38,產線配置圖!$A$2:$C$38,3,0) -> 1565 | L38: =K38/J38 -> 92.058824 | M38: 17 | N38: =G38/W38*60 -> 1423.0588 | O38: =N38/M38 -> 83.709343 | P38: =M38-J38 -> 0 | Q38: =O38-L38 -> -8.349481 | R38: =O38/L38 -> 0.90930276 | S38: =R48 -> 0.84971804 | T38: 0.33263889 | U38: 0.39166667 | W38: =(U38-T38)*24*60 -> 85 | AB38: =N38-K38 -> -141.94118 | AC38: =N38/K38 -> 0.90930276 | AD38: =AC48 -> 0.79560532
B39: =VLOOKUP(D39,廠價表!$C$1:$E$39,2,0) -> 義大利麵 | C39: =VLOOKUP(E39,廠價表!$C$1:$E$39,2,0) -> #N/A | D39: 羊乳起司培根筆尖麵 | F39: =VLOOKUP(D39,廠價表!$C$1:$E$39,3,0) -> 62.61 | G39: 1094 | H39: =F39*G39 -> 68495.34 | J39: =VLOOKUP(D39,產線配置圖!$A$2:$C$38,2,0) -> 17 | K39: =VLOOKUP(D39,產線配置圖!$A$2:$C$38,3,0) -> 1636 | L39: =K39/J39 -> 96.235294 | M39: 15 | N39: =G39/W39*60 -> 1262.3077 | O39: =N39/M39 -> 84.153846 | P39: =M39-J39 -> -2 | Q39: =O39-L39 -> -12.081448 | R39: =O39/L39 -> 0.87445928 | T39: 0.39861111 | U39: 0.43472222 | V39: =(T39-U38)*24*60 -> 10 | W39: =(U39-T39)*24*60 -> 52 | AB39: =N39-K39 -> -373.69231 | AC39: =N39/K39 -> 0.77158172
B40: =VLOOKUP(D40,廠價表!$C$1:$E$39,2,0) -> 義大利麵 | D40: 拿坡里義大利麵 | F40: =VLOOKUP(D40,廠價表!$C$1:$E$39,3,0) -> 58.17 | G40: 748 | H40: =F40*G40 -> 43511.16 | J40: =VLOOKUP(D40,產線配置圖!$A$2:$C$38,2,0) -> 16 | K40: =VLOOKUP(D40,產線配置圖!$A$2:$C$38,3,0) -> 1429 | L40: =K40/J40 -> 89.3125 | M40: 14 | N40: =G40/W40*60 -> 997.33333 | O40: =N40/M40 -> 71.238095 | P40: =M40-J40 -> -2 | Q40: =O40-L40 -> -18.074405 | R40: =O40/L40 -> 0.79762738 | T40: 0.44097222 | U40: 0.47222222 | V40: =(T40-U39)*24*60 -> 9 | W40: =(U40-T40)*24*60 -> 45 | Z40: 封膜機台異常 | AB40: =N40-K40 -> -431.66667 | AC40: =N40/K40 -> 0.69792396
...

Sheet 1003總
B1: 長家廠組合室生產人時性分析
B3: 日期 | D3: 45933 | F3: 訂單量 | G3: ='1003'!E1 -> 39570 | I3: 營業額 | J3: ='1003'!G1 -> 1956294.8
B4: 項目 | D4: 3 | F4: ➀ | H4: ➁ | J4: ③
B5: 人時性 | D5: 組合室 | F5: 全溫層 | H5: 義大利麵 | J5: 袋裝小吃、義麵
D6: 排關平均 | F6: =AVERAGE(D13:J13) -> 114.87991 | H6: =AVERAGE(D13:H13) -> 112.44136 | J6: =AVERAGE(I13) -> 127.07265
D7: 實績平均 | F7: =AVERAGE(D14:J14) -> 98.96975 | H7: =AVERAGE(D14:H14) -> 97.916008 | J7: =AVERAGE(I14) -> 104.23846
D8: 達成率平均 | F8: =AVERAGE(D15:J15) -> 0.85980604 | H8: =AVERAGE(D15:H15) -> 0.86770605 | J8: =AVERAGE(I15) -> 0.82030601 | L8: ※現行日本鮮食廠以達成率80%為基本(即為現行KPI)
B10: 溫層 | D10: 4度C-各編組展開
B11: 編組 | D11: 1 | E11: 2 | F11: 3 | G11: 4 | H11: 5 | I11: 6 | J11: 7
D12: 自動1線 | E12: 自動2線 | F12: 手工3線 | G12: 手工4線 | H12: 手工5線 | I12: 調理包1線 | J12: 調理包2線
B13: 人時性 | C13: 排關 | D13: =VALUE('1003'!L15) -> 147.68315 | E13: =VALUE('1003'!L26) -> 146.73344 | F13: =VALUE('1003'!L37) -> 87.449673 | G13: =VALUE('1003'!L48) -> 92.535539 | H13: =VALUE('1003'!L58) -> 87.805011 | I13: =VALUE('1003'!L69) -> 127.07265
C14: 實績 | D14: =VALUE('1003'!O15) -> 130.65208 | E14: =VALUE('1003'!O26) -> 129.4077 | F14: =VALUE('1003'!O37) -> 72.097528 | G14: =VALUE('1003'!O48) -> 77.952597 | H14: =VALUE('1003'!O58) -> 79.470133 | I14: =VALUE('1003'!O69) -> 104.23846
C15: 達成率 | D15: =D14/D13 -> 0.88467831 | E15: =E14/E13 -> 0.88192373 | F15: =F14/F13 -> 0.82444594 | G15: =G14/G13 -> 0.84240712 | H15: =H14/H13 -> 0.90507514 | I15: =I14/I13 -> 0.82030601
B16: 作業 時間 | C16: 開始 | D16: ='1003'!T5 -> 0.29722222 | E16: ='1003'!T16 -> 0.29722222 | F16: ='1003'!T27 -> 0.29861111 | G16: ='1003'!T38 -> 0.33125 | H16: ='1003'!T49 -> 0.29166667 | I16: ='1003'!T59 -> 0.29166667
C17: 結束 | D17: 0.50138889 | E17: 0.49305556 | F17: 0.62847222 | G17: 0.50277778 | H17: 0.61388889 | I17: 0.48263889
B18: 配置人數 | D18: =VALUE('1003'!M15) -> 13.333333 | E18: =VALUE('1003'!M26) -> 13.666667 | F18: =VALUE('1003'!M37) -> 14.2 | G18: =VALUE('1003'!M48) -> 15.333333 | H18: =VALUE('1003'!M58) -> 18 | I18: =VALUE('1003'!M69) -> 12.333333
B19: 主要應用設備 | D19: ET-600 | E19: ET-600 | F19: ET-55 | G19: ET-55 | H19: ET-55 | I19: 八爪機
B20: 次要應用設備 | H20: 封口機
B21: 備註

Sheet 1003
A1: 長家廠4度C日報分析 | D1: 總生產量 | E1: =SUM(G5:G79) -> 39570 | F1: 營業額 | G1: =SUM(H5:H79) -> 1956294.8 | H1: 出勤人數 | I1: =M15+M26+M48+M58+M69+M79+M37 -> 86.866667 | J1: 產線配置圖 | M1: 生產實績 | P1: 人時性差異分析 | T1: 日報登錄 | Z1: 分析說明 | AB1: 產能差異分析
A2: 10月03日 星期五 | D2: 人時性 | E2: =AVERAGE(O15,O26,O37,O48,O58,O69,O79) -> 98.96975 | F2: 平均廠價 | G2: =G1/E1 -> 49.438837 | H2: 多次生產數 | I2: =COUNT(I5:I79) -> 0
A3: 線別 | B3: 品類 | D3: 品名 | F3: 廠價 | G3: 生產量 | H3: 營收 | I3: 多次 生產 | J3: 人數 | K3: 產能/時 | L3: 人時性 | M3: 人數 | N3: 產能/時 | O3: 人時性 | P3: 人數 | Q3: 人時性 | R3: 達成率 | S3: 達成率平均 | T3: 生產時間 | V3: 前置、換線時間/分 | W3: 稼動時間/分 | X3: 休息時間 | Z3: (長家回填) | AB3: 產能/時 | AC3: 達成率 | AD3: 達成率平均
T4: 開始 | U4: 結束 | X4: 開始 | Y4: 結束
A5: 自動一線 (ET-600) | B5: =VLOOKUP(D5,廠價表!$C$1:$E$39,2,0) -> 義大利麵 | D5: 白酒蛤蜊義大利麵 | F5: =VLOOKUP(D5,廠價表!$C$1:$E$39,3,0) -> 57.21 | G5: 1362 | H5: =F5*G5 -> 77920.02 | J5: =VLOOKUP(D5,產線配置圖!$A$2:$C$38,2,0) -> 13 | K5: =VLOOKUP(D5,產線配置圖!$A$2:$C$38,3,0) -> 2000 | L5: =K5/J5 -> 153.84615 | M5: 13 | N5: =G5/W5*60 -> 1738.7234 | O5: =N5/M5 -> 133.74795 | P5: =M5-J5 -> 0 | Q5: =O5-L5 -> -20.0982 | R5: =O5/L5 -> 0.8693617 | S5: =R15 -> 0.88467831 | T5: 0.29722222 | U5: 0.32986111 | W5: =(U5-T5)*24*60 -> 47 | AB5: =N5-K5 -> -261.2766 | AC5: =N5/K5 -> 0.8693617 | AD5: =AC15 -> 0.88322332
B6: =VLOOKUP(D6,廠價表!$C$1:$E$39,2,0) -> 義大利麵 | D6: 韓式起司炸雞義大利麵 | F6: =VLOOKUP(D6,廠價表!$C$1:$E$39,3,0) -> 57.21 | G6: 2153 | H6: =F6*G6 -> 123173.13 | J6: =VLOOKUP(D6,產線配置圖!$A$2:$C$38,2,0) -> 14 | K6: =VLOOKUP(D6,產線配置圖!$A$2:$C$38,3,0) -> 1895 | L6: =K6/J6 -> 135.35714 | M6: 14 | N6: =G6/W6*60 -> 1556.3855 | O6: =N6/M6 -> 111.1704 | P6: =M6-J6 -> 0 | Q6: =O6-L6 -> -24.186747 | R6: =O6/L6 -> 0.82131163 | T6: 0.34236111 | U6: 0.4 | V6: =(T6-U5)*24*60 -> 18 | W6: =(U6-T6)*24*60 -> 83 | AB6: =N6-K6 -> -338.61446 | AC6: =N6/K6 -> 0.82131163
B7: =VLOOKUP(D7,廠價表!$C$1:$E$39,2,0) -> 義大利麵 | D7: 奶油培根義大利麵 | F7: =VLOOKUP(D7,廠價表!$C$1:$E$39,3,0) -> 49.14 | G7: 4269 | H7: =F7*G7 -> 209778.66 | J7: =VLOOKUP(D7,產線配置圖!$A$2:$C$38,2,0) -> 13 | K7: =VLOOKUP(D7,產線配置圖!$A$2:$C$38,3,0) -> 2000 | L7: =K7/J7 -> 153.84615 | M7: 13 | N7: =G7/W7*60 -> 1911.4925 | O7: =N7/M7 -> 147.03789 | P7: =M7-J7 -> 0 | Q7: =O7-L7 -> -6.8082664 | R7: =O7/L7 -> 0.95574627 | T7: 0.40833333 | U7: 0.50138889 | V7: =(T7-U6)*24*60 -> 12 | W7: =(U7-T7)*24*60 -> 134 | AB7: =N7-K7 -> -88.507463 | AC7: =N7/K7 -> 0.95574627
W8: =(U8-T8)*24*60 -> 0
H9: =F9*G9 -> 0 | W9: =(U9-T9)*24*60 -> 0
H10: =F10*G10 -> 0 | W10: =(U10-T10)*24*60 -> 0
H11: =F11*G11 -> 0 | W11: =(U11-T11)*24*60 -> 0
H12: =F12*G12 -> 0 | W12: =(U12-T12)*24*60 -> 0
H13: =F13*G13 -> 0 | W13: =(U13-T13)*24*60 -> 0
H14: =F14*G14 -> 0 | W14: =(U14-T14)*24*60 -> 0
C15: 4度一組 | D15: 平均 | J15: =AVERAGE(J5:J14) -> 13.333333 | K15: =AVERAGE(K5:K14) -> 1965 | L15: =AVERAGE(L5:L14) -> 147.68315 | M15: =AVERAGE(M5:M14) -> 13.333333 | N15: =AVERAGE(N5:N14) -> 1735.5338 | O15: =AVERAGE(O5:O14) -> 130.65208 | P15: =M15-J15 -> 0 | Q15: =O15-L15 -> -17.031071 | R15: =O15/L15 -> 0.88467831 | AB15: =N15-K15 -> -229.46617 | AC15: =N15/K15 -> 0.88322332
A16: 自動二線 (ET-600) | B16: 義大利麵 | D16: 白酒蛤蜊義大利麵 | F16: =VLOOKUP(D16,廠價表!$C$1:$E$39,3,0) -> 57.21 | G16: 1404 | H16: =F16*G16 -> 80322.84 | J16: =VLOOKUP(D16,產線配置圖!$A$2:$C$38,2,0) -> 13 | K16: =VLOOKUP(D16,產線配置圖!$A$2:$C$38,3,0) -> 2000 | L16: =K16/J16 -> 153.84615 | M16: 13 | N16: =G16/W16*60 -> 1620 | O16: =N16/M16 -> 124.61538 | P16: =M16-J16 -> 0 | Q16: =O16-L16 -> -29.230769 | R16: =O16/L16 -> 0.81 | S16: =R26 -> 0.88192373 | T16: 0.29722222 | U16: 0.33333333 | W16: =(U16-T16)*24*60 -> 52 | AB16: =N16-K16 -> -380 | AC16: =N16/K16 -> 0.81 | AD16: =AC26 -> 0.87714162
B17: 義大利麵 | D17: 熱那亞青醬義大利麵 | F17: =VLOOKUP(D17,廠價表!$C$1:$E$39,3,0) -> 50.67 | G17: 1620 | H17: =F17*G17 -> 82085.4 | J17: =VLOOKUP(D17,產線配置圖!$A$2:$C$38,2,0) -> 16 | K17: =VLOOKUP(D17,產線配置圖!$A$2:$C$38,3,0) -> 1915 | L17: =K17/J17 -> 119.6875 | M17: 16 | N17: =G17/W17*60 -> 1620 | O17: =N17/M17 -> 101.25 | P17: =M17-J17 -> 0 | Q17: =O17-L17 -> -18.4375 | R17: =O17/L17 -> 0.845953 | T17: 0.34375 | U17: 0.38541667 | V17: =(T17-U16)*24*60 -> 15 | W17: =(U17-T17)*24*60 -> 60 | AB17: =N17-K17 -> -295 | AC17: =N17/K17 -> 0.845953
B18: =VLOOKUP(D18,廠價表!$C$1:$E$39,2,0) -> 義大利麵 | D18: 義式蕃茄起司義大利麵 | F18: =VLOOKUP(D18,廠價表!$C$1:$E$39,3,0) -> 50.39 | G18: 3994 | H18: =F18*G18 -> 201257.66 | J18: =VLOOKUP(D18,產線配置圖!$A$2:$C$38,2,0) -> 12 | K18: =VLOOKUP(D18,產線配置圖!$A$2:$C$38,3,0) -> 2000 | L18: =K18/J18 -> 166.66667 | M18: 12 | N18: =G18/W18*60 -> 1948.2927 | O18: =N18/M18 -> 162.35772 | P18: =M18-J18 -> 0 | Q18: =O18-L18 -> -4.3089431 | R18: =O18/L18 -> 0.97414634 | T18: 0.40763889 | U18: 0.49305556 | V18: =(T18-U17)*24*60 -> 32 | W18: =(U18-T18)*24*60 -> 123 | AB18: =N18-K18 -> -51.707317 | AC18: =N18/K18 -> 0.97414634
W19: =(U19-T19)*24*60 -> 0
H20: =F20*G20 -> 0 | W20: 0
H21: =F21*G21 -> 0 | W21: 0
H22: =F22*G22 -> 0 | W22: 0
H23: =F23*G23 -> 0 | W23: =(U23-T23)*24*60 -> 0
H24: =F24*G24 -> 0 | W24: =(U24-T24)*24*60 -> 0
H25: =F25*G25 -> 0 | W25: =(U25-T25)*24*60 -> 0
C26: 4度二組A | D26: 平均 | J26: =AVERAGE(J16:J25) -> 13.666667 | K26: =AVERAGE(K16:K25) -> 1971.6667 | L26: =AVERAGE(L16:L25) -> 146.73344 | M26: =AVERAGE(M16:M25) -> 13.666667 | N26: =AVERAGE(N16:N25) -> 1729.4309 | O26: =AVERAGE(O16:O25) -> 129.4077 | P26: =M26-J26 -> 0 | Q26: =O26-L26 -> -17.325737 | R26: =O26/L26 -> 0.88192373 | AB26: =N26-K26 -> -242.23577 | AC26: =N26/K26 -> 0.87714162
A27: 手工三線 (ET-55) | B27: 義大利麵 | D27: 黑胡椒燻豬腿義大利麵 | F27: =VLOOKUP(D27,廠價表!$C$1:$E$39,3,0) -> 50.6 | G27: 1102 | H27: =F27*G27 -> 55761.2 | J27: 17 | K27: 1636 | L27: =K27/J27 -> 96.235294 | M27: 13 | N27: =G27/W27*60 -> 1017.2308 | O27: =N27/M27 -> 78.248521 | P27: =M27-J27 -> -4 | Q27: =O27-L27 -> -17.986773 | R27: =O27/L27 -> 0.81309588 | S27: =R37 -> 0.82444594 | T27: 0.29861111 | U27: 0.34375 | W27: =(U27-T27)*24*60 -> 65 | AB27: =N27-K27 -> -618.76923 | AC27: =N27/K27 -> 0.6217792 | AD27: =AC37 -> 0.66275719
B28: =VLOOKUP(D28,廠價表!$C$1:$E$39,2,0) -> 義大利麵 | D28: 韓式辣醬肉丸義大利麵 | F28: =VLOOKUP(D28,廠價表!$C$1:$E$39,3,0) -> 57.21 | G28: 1546 | H28: =F28*G28 -> 88446.66 | J28: 17 | K28: 1636 | L28: =K28/J28 -> 96.235294 | M28: 13 | N28: =G28/W28*60 -> 1054.0909 | O28: =N28/M28 -> 81.083916 | P28: =M28-J28 -> -4 | Q28: =O28-L28 -> -15.151378 | R28: =O28/L28 -> 0.84255903 | T28: 0.35208333 | U28: 0.41319444 | V28: =(T28-U27)*24*60 -> 12 | W28: =(U28-T28)*24*60 -> 88 | AB28: =N28-K28 -> -581.90909 | AC28: =N28/K28 -> 0.64430985
B29: =VLOOKUP(D29,廠價表!$C$1:$E$39,2,0) -> 義大利麵 | D29: 奶油蒜香雞義大利麵 | F29: =VLOOKUP(D29,廠價表!$C$1:$E$39,3,0) -> 55.13 | G29: 1423 | H29: =F29*G29 -> 78449.99 | J29: =VLOOKUP(D29,產線配置圖!$A$2:$C$38,2,0) -> 18 | K29: =VLOOKUP(D29,產線配置圖!$A$2:$C$38,3,0) -> 1385 | L29: =K29/J29 -> 76.944444 | M29: 15 | N29: =G29/W29*60 -> 948.66667 | O29: =N29/M29 -> 63.244444 | P29: =M29-J29 -> -3 | Q29: =O29-L29 -> -13.7 | R29: =O29/L29 -> 0.82194946 | T29: 0.42083333 | U29: 0.48333333 | V29: =(T29-U28)*24*60 -> 11 | W29: =(U29-T29)*24*60 -> 90 | Z29: 待醬 | AB29: =N29-K29 -> -436.33333 | AC29: =N29/K29 -> 0.68495788
B30: =VLOOKUP(D30,廠價表!$C$1:$E$39,2,0) -> 熱乾麵 | D30: 家傳炸醬麵 | F30: =VLOOKUP(D30,廠價表!$C$1:$E$39,3,0) -> 47.6 | G30: 1095 | H30: =F30*G30 -> 52122 | J30: =VLOOKUP(D30,產線配置圖!$A$2:$C$38,2,0) -> 18 | K30: =VLOOKUP(D30,產線配置圖!$A$2:$C$38,3,0) -> 1636 | L30: =K30/J30 -> 90.888889 | M30: 15 | N30: =G30/W30*60 -> 1113.5593 | O30: =N30/M30 -> 74.237288 | P30: =M30-J30 -> -3 | Q30: =O30-L30 -> -16.651601 | R30: =O30/L30 -> 0.81679168 | T30: 0.54930556 | U30: 0.59027778 | V30: =(T30-U29)*24*60 -> 95 | W30: =(U30-T30)*24*60 -> 59 | X30: 0.49305556 | Y30: 0.53472222 | AB30: =N30-K30 -> -522.44068 | AC30: =N30/K30 -> 0.68065973
B31: =VLOOKUP(D31,廠價表!$C$1:$E$39,2,0) -> 義大利麵 | D31: 奶油蒜香雞義大利麵 | F31: =VLOOKUP(D31,廠價表!$C$1:$E$39,3,0) -> 55.13 | G31: 780 | H31: =F31*G31 -> 43001.4 | J31: =VLOOKUP(D31,產線配置圖!$A$2:$C$38,2,0) -> 18 | K31: =VLOOKUP(D31,產線配置圖!$A$2:$C$38,3,0) -> 1385 | L31: =K31/J31 -> 76.944444 | M31: 15 | N31: =G31/W31*60 -> 955.10204 | O31: =N31/M31 -> 63.673469 | P31: =M31-J31 -> -3 | Q31: =O31-L31 -> -13.270975 | R31: =O31/L31 -> 0.82752523 | T31: 0.59444444 | U31: 0.62847222 | V31: =(T31-U30)*24*60 -> 6 | W31: =(U31-T31)*24*60 -> 49 | Z31: 待醬 | AB31: =N31-K31 -> -429.89796 | AC31: =N31/K31 -> 0.68960436
H32: =F32*G32 -> 0 | W32: =(U32-T32)*24*60 -> 0
H33: =F33*G33 -> 0 | W33: =(U33-T33)*24*60 -> 0
H34: =F34*G34 -> 0 | W34: =(U34-T34)*24*60 -> 0
H35: =F35*G35 -> 0 | W35: =(U35-T35)*24*60 -> 0
H36: =F36*G36 -> 0 | W36: =(U36-T36)*24*60 -> 0
C37: 4度二組B | D37: 平均 | J37: =AVERAGE(J27:J36) -> 17.6 | K37: =AVERAGE(K27:K36) -> 1535.6 | L37: =AVERAGE(L27:L36) -> 87.449673 | M37: =AVERAGE(M27:M36) -> 14.2 | N37: =AVERAGE(N27:N36) -> 1017.7299 | O37: =AVERAGE(O27:O36) -> 72.097528 | P37: =M37-J37 -> -3.4 | Q37: =N37-K37 -> -517.87006 | R37: =O37/L37 -> 0.82444594 | AB37: =N37-K37 -> -517.87006 | AC37: =N37/K37 -> 0.66275719
A38: 手工四線 (ET-55) | B38: 熱乾麵 | C38: =VLOOKUP(E38,廠價表!$C$1:$E$39,2,0) -> #N/A | D38: 青花椒麻雞肉拌麵 | F38: =VLOOKUP(D38,廠價表!$C$1:$E$39,3,0) -> 49.91 | G38: 2325 | H38: =F38*G38 -> 116040.75 | J38: =VLOOKUP(D38,產線配置圖!$A$2:$C$38,2,0) -> 17 | K38: =VLOOKUP(D38,產線配置圖!$A$2:$C$38,3,0) -> 1565 | L38: =K38/J38 -> 92.058824 | M38: 16 | N38: =G38/W38*60 -> 1354.3689 | O38: =N38/M38 -> 84.648058 | P38: =M38-J38 -> -1 | Q38: =O38-L38 -> -7.4107653 | R38: =O38/L38 -> 0.91949967 | S38: =R48 -> 0.84240712 | T38: 0.33125 | U38: 0.40277778 | W38: =(U38-T38)*24*60 -> 103 | AB38: =N38-K38 -> -210.63107 | AC38: =N38/K38 -> 0.86541146 | AD38: =AC48 -> 0.78052266
B39: =VLOOKUP(D39,廠價表!$C$1:$E$39,2,0) -> 義大利麵 | C39: =VLOOKUP(E39,廠價表!$C$1:$E$39,2,0) -> #N/A | D39: 羊乳起司培根筆尖麵 | F39: =VLOOKUP(D39,廠價表!$C$1:$E$39,3,0) -> 62.61 | G39: 773 | H39: =F39*G39 -> 48397.53 | J39: =VLOOKUP(D39,產線配置圖!$A$2:$C$38,2,0) -> 17 | K39: =VLOOKUP(D39,產線配置圖!$A$2:$C$38,3,0) -> 1636 | L39: =K39/J39 -> 96.235294 | M39: 16 | N39: =G39/W39*60 -> 1364.1176 | O39: =N39/M39 -> 85.257353 | P39: =M39-J39 -> -1 | Q39: =O39-L39 -> -10.977941 | R39: =O39/L39 -> 0.88592604 | T39: 0.40972222 | U39: 0.43333333 | V39: =(T39-U38)*24*60 -> 10 | W39: =(U39-T39)*24*60 -> 34 | AB39: =N39-K39 -> -271.88235 | AC39: =N39/K39 -> 0.83381274
B40: =VLOOKUP(D40,廠價表!$C$1:$E$39,2,0) -> 義大利麵 | D40: 拿坡里義大利麵 | F40: =VLOOKUP(D40,廠價表!$C$1:$E$39,3,0) -> 58.17 | G40: 1343 | H40: =F40*G40 -> 78122.31 | J40: =VLOOKUP(D40,產線配置圖!$A$2:$C$38,2,0) -> 16 | K40: =VLOOKUP(D40,產線配置圖!$A$2:$C$38,3,0) -> 1429 | L40: =K40/J40 -> 89.3125 | M40: 14 | N40: =G40/W40*60 -> 895.33333 | O40: =N40/M40 -> 63.952381 | P40: =M40-J40 -> -2 | Q40: =O40-L40 -> -25.360119 | R40: =O40/L40 -> 0.71605185 | T40: 0.44027778 | U40: 0.50277778 | V40: =(T40-U39)*24*60 -> 10 | W40: =(U40-T40)*24*60 -> 90 | Z40: 待醬 | AB40: =N40-K40 -> -533.66667 | AC40: =N40/K40 -> 0.62654537
...

Sheet 1004總
B1: 長家廠組合室生產人時性分析
B3: 日期 | D3: 45934 | F3: 訂單量 | G3: ='1004'!E1 -> 39731 | I3: 營業額 | J3: ='1004'!G1 -> 1957596.6
B4: 項目 | D4: 3 | F4: ➀ | H4: ➁ | J4: ③
B5: 人時性 | D5: 組合室 | F5: 全溫層 | H5: 義大利麵 | J5: 袋裝小吃、義麵
D6: 排關平均 | F6: =AVERAGE(D13:J13) -> 115.14865 | H6: =AVERAGE(D13:H13) -> 112.59665 | J6: =AVERAGE(I13) -> 127.90865
D7: 實績平均 | F7: =AVERAGE(D14:I14) -> 105.05554 | H7: =AVERAGE(D14:H14) -> 102.37069 | J7: =AVERAGE(I14) -> 118.47982
D8: 達成率平均 | F8: =AVERAGE(D15:J15) -> 0.91350047 | H8: =AVERAGE(D15:H15) -> 0.91094365 | J8: =AVERAGE(I15) -> 0.92628461 | L8: ※現行日本鮮食廠以達成率80%為基本(即為現行KPI)
B10: 溫層 | D10: 4度C-各編組展開
B11: 編組 | D11: 1 | E11: 2 | F11: 3 | G11: 4 | H11: 5 | I11: 6 | J11: 7
D12: 自動1線 | E12: 自動2線 | F12: 手工3線 | G12: 手工4線 | H12: 手工5線 | I12: 調理包1線 | J12: 調理包2線
B13: 人時性 | C13: 排關 | D13: =VALUE('1004'!L15) -> 147.68315 | E13: =VALUE('1004'!L26) -> 146.73344 | F13: =VALUE('1004'!L37) -> 90.07598 | G13: =VALUE('1004'!L48) -> 90.685662 | H13: =VALUE('1004'!L58) -> 87.805011 | I13: =VALUE('1004'!L69) -> 127.90865
C14: 實績 | D14: =VALUE('1004'!O15) -> 134.80054 | E14: =VALUE('1004'!O26) -> 131.3154 | F14: =VALUE('1004'!O37) -> 74.899821 | G14: =VALUE('1004'!O48) -> 83.317754 | H14: =VALUE('1004'!O58) -> 87.519925 | I14: =VALUE('1004'!O69) -> 118.47982
C15: 達成率 | D15: =D14/D13 -> 0.91276861 | E15: =E14/E13 -> 0.89492485 | F15: =F14/F13 -> 0.83151825 | G15: =G14/G13 -> 0.91875333 | H15: =H14/H13 -> 0.9967532 | I15: =I14/I13 -> 0.92628461
B16: 作業 時間 | C16: 開始 | D16: ='1004'!T5 -> 0.29166667 | E16: ='1004'!T16 -> 0.29027778 | F16: ='1004'!T27 -> 0.29444444 | G16: ='1004'!T38 -> 0.33263889 | H16: ='1004'!T49 -> 0.28888889 | I16: ='1004'!T59 -> 0.29166667
C17: 結束 | D17: 0.49305556 | E17: 0.46736111 | F17: 0.58055556 | G17: 0.49791667 | H17: 0.62986111 | I17: 0.55972222
B18: 配置人數 | D18: =VALUE('1004'!M15) -> 13.333333 | E18: =VALUE('1004'!M26) -> 13.666667 | F18: =VALUE('1004'!M37) -> 16.25 | G18: =VALUE('1004'!M48) -> 15 | H18: =VALUE('1004'!M58) -> 17.333333 | I18: =VALUE('1004'!M69) -> 12.25
B19: 主要應用設備 | D19: ET-600 | E19: ET-600 | F19: ET-55 | G19: ET-55 | H19: ET-55 | I19: 八爪機
B20: 次要應用設備 | H20: 封口機
B21: 備註

Sheet 1004
A1: 長家廠4度C日報分析 | D1: 總生產量 | E1: =SUM(G5:G79) -> 39731 | F1: 營業額 | G1: =SUM(H5:H79) -> 1957596.6 | H1: 出勤人數 | I1: =M15+M26+M48+M58+M69+M79+M37 -> 87.833333 | J1: 產線配置圖 | M1: 生產實績 | P1: 人時性差異分析 | T1: 日報登錄 | Z1: 分析說明 | AB1: 產能差異分析
A2: 10月04日 星期六 | D2: 人時性 | E2: =AVERAGE(O15,O26,O37,O48,O58,O69,O79) -> 105.05554 | F2: 平均廠價 | G2: =G1/E1 -> 49.271264 | H2: 多次生產數 | I2: =COUNT(I5:I79) -> 0
A3: 線別 | B3: 品類 | D3: 品名 | F3: 廠價 | G3: 生產量 | H3: 營收 | I3: 多次 生產 | J3: 人數 | K3: 產能/時 | L3: 人時性 | M3: 人數 | N3: 產能/時 | O3: 人時性 | P3: 人數 | Q3: 人時性 | R3: 達成率 | S3: 達成率平均 | T3: 生產時間 | V3: 前置、換線時間/分 | W3: 稼動時間/分 | X3: 休息時間 | Z3: (長家回填) | AB3: 產能/時 | AC3: 達成率 | AD3: 達成率平均
T4: 開始 | U4: 結束 | X4: 開始 | Y4: 結束
A5: 自動一線 (ET-600) | B5: =VLOOKUP(D5,廠價表!$C$1:$E$39,2,0) -> 義大利麵 | D5: 白酒蛤蜊義大利麵 | F5: =VLOOKUP(D5,廠價表!$C$1:$E$39,3,0) -> 57.21 | G5: 1259 | H5: =F5*G5 -> 72027.39 | J5: =VLOOKUP(D5,產線配置圖!$A$2:$C$38,2,0) -> 13 | K5: =VLOOKUP(D5,產線配置圖!$A$2:$C$38,3,0) -> 2000 | L5: =K5/J5 -> 153.84615 | M5: 13 | N5: =G5/W5*60 -> 1888.5 | O5: =N5/M5 -> 145.26923 | P5: =M5-J5 -> 0 | Q5: =O5-L5 -> -8.5769231 | R5: =O5/L5 -> 0.94425 | S5: =R15 -> 0.91276861 | T5: 0.29166667 | U5: 0.31944444 | W5: =(U5-T5)*24*60 -> 40 | AB5: =N5-K5 -> -111.5 | AC5: =N5/K5 -> 0.94425 | AD5: =AC15 -> 0.9128256
B6: =VLOOKUP(D6,廠價表!$C$1:$E$39,2,0) -> 義大利麵 | D6: 韓式起司炸雞義大利麵 | F6: =VLOOKUP(D6,廠價表!$C$1:$E$39,3,0) -> 57.21 | G6: 2168 | H6: =F6*G6 -> 124031.28 | J6: =VLOOKUP(D6,產線配置圖!$A$2:$C$38,2,0) -> 14 | K6: =VLOOKUP(D6,產線配置圖!$A$2:$C$38,3,0) -> 1895 | L6: =K6/J6 -> 135.35714 | M6: 14 | N6: =G6/W6*60 -> 1734.4 | O6: =N6/M6 -> 123.88571 | P6: =M6-J6 -> 0 | Q6: =O6-L6 -> -11.471429 | R6: =O6/L6 -> 0.91525066 | T6: 0.32986111 | U6: 0.38194444 | V6: =(T6-U5)*24*60 -> 15 | W6: =(U6-T6)*24*60 -> 75 | AB6: =N6-K6 -> -160.6 | AC6: =N6/K6 -> 0.91525066
B7: =VLOOKUP(D7,廠價表!$C$1:$E$39,2,0) -> 義大利麵 | D7: 奶油培根義大利麵 | F7: =VLOOKUP(D7,廠價表!$C$1:$E$39,3,0) -> 49.14 | G7: 4249 | H7: =F7*G7 -> 208795.86 | J7: =VLOOKUP(D7,產線配置圖!$A$2:$C$38,2,0) -> 13 | K7: =VLOOKUP(D7,產線配置圖!$A$2:$C$38,3,0) -> 2000 | L7: =K7/J7 -> 153.84615 | M7: 13 | N7: =G7/W7*60 -> 1758.2069 | O7: =N7/M7 -> 135.24668 | P7: =M7-J7 -> 0 | Q7: =O7-L7 -> -18.599469 | R7: =O7/L7 -> 0.87910345 | T7: 0.39236111 | U7: 0.49305556 | V7: =(T7-U6)*24*60 -> 15 | W7: =(U7-T7)*24*60 -> 145 | AB7: =N7-K7 -> -241.7931 | AC7: =N7/K7 -> 0.87910345
W8: =(U8-T8)*24*60 -> 0
H9: =F9*G9 -> 0 | W9: =(U9-T9)*24*60 -> 0
H10: =F10*G10 -> 0 | W10: =(U10-T10)*24*60 -> 0
H11: =F11*G11 -> 0 | W11: =(U11-T11)*24*60 -> 0
H12: =F12*G12 -> 0 | W12: =(U12-T12)*24*60 -> 0
H13: =F13*G13 -> 0 | W13: =(U13-T13)*24*60 -> 0
H14: =F14*G14 -> 0 | W14: =(U14-T14)*24*60 -> 0
C15: 4度一組 | D15: 平均 | J15: =AVERAGE(J5:J14) -> 13.333333 | K15: =AVERAGE(K5:K14) -> 1965 | L15: =AVERAGE(L5:L14) -> 147.68315 | M15: =AVERAGE(M5:M14) -> 13.333333 | N15: =AVERAGE(N5:N14) -> 1793.7023 | O15: =AVERAGE(O5:O14) -> 134.80054 | P15: =M15-J15 -> 0 | Q15: =O15-L15 -> -12.882607 | R15: =O15/L15 -> 0.91276861 | AB15: =N15-K15 -> -171.2977 | AC15: =N15/K15 -> 0.9128256
A16: 自動二線 (ET-600) | B16: 義大利麵 | D16: 白酒蛤蜊義大利麵 | F16: =VLOOKUP(D16,廠價表!$C$1:$E$39,3,0) -> 57.21 | G16: 1361 | H16: =F16*G16 -> 77862.81 | J16: =VLOOKUP(D16,產線配置圖!$A$2:$C$38,2,0) -> 13 | K16: =VLOOKUP(D16,產線配置圖!$A$2:$C$38,3,0) -> 2000 | L16: =K16/J16 -> 153.84615 | M16: 13 | N16: =G16/W16*60 -> 1814.6667 | O16: =N16/M16 -> 139.58974 | P16: =M16-J16 -> 0 | Q16: =O16-L16 -> -14.25641 | R16: =O16/L16 -> 0.90733333 | S16: =R26 -> 0.89492485 | T16: 0.29027778 | U16: 0.32152778 | W16: =(U16-T16)*24*60 -> 45 | AB16: =N16-K16 -> -185.33333 | AC16: =N16/K16 -> 0.90733333 | AD16: =AC26 -> 0.88779699
B17: 義大利麵 | D17: 熱那亞青醬義大利麵 | F17: =VLOOKUP(D17,廠價表!$C$1:$E$39,3,0) -> 50.67 | G17: 1640 | H17: =F17*G17 -> 83098.8 | J17: =VLOOKUP(D17,產線配置圖!$A$2:$C$38,2,0) -> 16 | K17: =VLOOKUP(D17,產線配置圖!$A$2:$C$38,3,0) -> 1915 | L17: =K17/J17 -> 119.6875 | M17: 16 | N17: =G17/W17*60 -> 1537.5 | O17: =N17/M17 -> 96.09375 | P17: =M17-J17 -> 0 | Q17: =O17-L17 -> -23.59375 | R17: =O17/L17 -> 0.80287206 | T17: 0.32638889 | U17: 0.37083333 | V17: =(T17-U16)*24*60 -> 7 | W17: =(U17-T17)*24*60 -> 64 | AB17: =N17-K17 -> -377.5 | AC17: =N17/K17 -> 0.80287206
B18: =VLOOKUP(D18,廠價表!$C$1:$E$39,2,0) -> 義大利麵 | D18: 義式蕃茄起司義大利麵 | F18: =VLOOKUP(D18,廠價表!$C$1:$E$39,3,0) -> 50.39 | G18: 3735 | H18: =F18*G18 -> 188206.65 | J18: =VLOOKUP(D18,產線配置圖!$A$2:$C$38,2,0) -> 12 | K18: =VLOOKUP(D18,產線配置圖!$A$2:$C$38,3,0) -> 2000 | L18: =K18/J18 -> 166.66667 | M18: 12 | N18: =G18/W18*60 -> 1899.1525 | O18: =N18/M18 -> 158.26271 | P18: =M18-J18 -> 0 | Q18: =O18-L18 -> -8.4039548 | R18: =O18/L18 -> 0.94957627 | T18: 0.38541667 | U18: 0.46736111 | V18: =(T18-U17)*24*60 -> 21 | W18: =(U18-T18)*24*60 -> 118 | AB18: =N18-K18 -> -100.84746 | AC18: =N18/K18 -> 0.94957627
W19: =(U19-T19)*24*60 -> 0
H20: =F20*G20 -> 0 | W20: 0
H21: =F21*G21 -> 0 | W21: 0
H22: =F22*G22 -> 0 | W22: 0
H23: =F23*G23 -> 0 | W23: =(U23-T23)*24*60 -> 0
H24: =F24*G24 -> 0 | W24: =(U24-T24)*24*60 -> 0
H25: =F25*G25 -> 0 | W25: =(U25-T25)*24*60 -> 0
C26: 4度二組A | D26: 平均 | J26: =AVERAGE(J16:J25) -> 13.666667 | K26: =AVERAGE(K16:K25) -> 1971.6667 | L26: =AVERAGE(L16:L25) -> 146.73344 | M26: =AVERAGE(M16:M25) -> 13.666667 | N26: =AVERAGE(N16:N25) -> 1750.4397 | O26: =AVERAGE(O16:O25) -> 131.3154 | P26: =M26-J26 -> 0 | Q26: =O26-L26 -> -15.418038 | R26: =O26/L26 -> 0.89492485 | AB26: =N26-K26 -> -221.22693 | AC26: =N26/K26 -> 0.88779699
A27: 手工三線 (ET-55) | B27: 義大利麵 | D27: 黑胡椒燻豬腿義大利麵 | F27: =VLOOKUP(D27,廠價表!$C$1:$E$39,3,0) -> 50.6 | G27: 1132 | H27: =F27*G27 -> 57279.2 | J27: 17 | K27: 1636 | L27: =K27/J27 -> 96.235294 | M27: 15 | N27: =G27/W27*60 -> 1171.0345 | O27: =N27/M27 -> 78.068966 | P27: =M27-J27 -> -2 | Q27: =O27-L27 -> -18.166329 | R27: =O27/L27 -> 0.81123008 | S27: =R37 -> 0.83151825 | T27: 0.29444444 | U27: 0.33472222 | W27: =(U27-T27)*24*60 -> 58 | AB27: =N27-K27 -> -464.96552 | AC27: =N27/K27 -> 0.71579125 | AD27: =AC37 -> 0.77753384
B28: =VLOOKUP(D28,廠價表!$C$1:$E$39,2,0) -> 義大利麵 | D28: 韓式辣醬肉丸義大利麵 | F28: =VLOOKUP(D28,廠價表!$C$1:$E$39,3,0) -> 57.21 | G28: 1503 | H28: =F28*G28 -> 85986.63 | J28: 17 | K28: 1636 | L28: =K28/J28 -> 96.235294 | M28: 17 | N28: =G28/W28*60 -> 1478.3607 | O28: =N28/M28 -> 86.962392 | P28: =M28-J28 -> 0 | Q28: =O28-L28 -> -9.2729026 | R28: =O28/L28 -> 0.90364343 | T28: 0.34652778 | U28: 0.38888889 | V28: =(T28-U27)*24*60 -> 17 | W28: =(U28-T28)*24*60 -> 61 | AB28: =N28-K28 -> -157.63934 | AC28: =N28/K28 -> 0.90364343
B29: =VLOOKUP(D29,廠價表!$C$1:$E$39,2,0) -> 義大利麵 | D29: 奶油蒜香雞義大利麵 | F29: =VLOOKUP(D29,廠價表!$C$1:$E$39,3,0) -> 55.13 | G29: 2116 | H29: =F29*G29 -> 116655.08 | J29: =VLOOKUP(D29,產線配置圖!$A$2:$C$38,2,0) -> 18 | K29: =VLOOKUP(D29,產線配置圖!$A$2:$C$38,3,0) -> 1385 | L29: =K29/J29 -> 76.944444 | M29: 18 | N29: =G29/W29*60 -> 1350.6383 | O29: =N29/M29 -> 75.035461 | P29: =M29-J29 -> 0 | Q29: =O29-L29 -> -1.9089835 | R29: =O29/L29 -> 0.97519011 | T29: 0.39930556 | U29: 0.46458333 | V29: =(T29-U28)*24*60 -> 15 | W29: =(U29-T29)*24*60 -> 94 | AB29: =N29-K29 -> -34.361702 | AC29: =N29/K29 -> 0.97519011
B30: =VLOOKUP(D30,廠價表!$C$1:$E$39,2,0) -> 熱乾麵 | D30: 家傳炸醬麵 | F30: =VLOOKUP(D30,廠價表!$C$1:$E$39,3,0) -> 47.6 | G30: 1146 | H30: =F30*G30 -> 54549.6 | J30: =VLOOKUP(D30,產線配置圖!$A$2:$C$38,2,0) -> 18 | K30: =VLOOKUP(D30,產線配置圖!$A$2:$C$38,3,0) -> 1636 | L30: =K30/J30 -> 90.888889 | M30: 15 | N30: =G30/W30*60 -> 892.98701 | O30: =N30/M30 -> 59.532468 | P30: =M30-J30 -> -3 | Q30: =O30-L30 -> -31.356421 | R30: =O30/L30 -> 0.6550027 | T30: 0.52708333 | U30: 0.58055556 | V30: =(T30-U29)*24*60 -> 90 | W30: =(U30-T30)*24*60 -> 77 | X30: 0.46875 | Y30: 0.51041667 | Z30: 12:50-13:11熱轉印故障 | AB30: =N30-K30 -> -743.01299 | AC30: =N30/K30 -> 0.54583558
W31: =(U31-T31)*24*60 -> 0
H32: =F32*G32 -> 0 | W32: =(U32-T32)*24*60 -> 0
H33: =F33*G33 -> 0 | W33: =(U33-T33)*24*60 -> 0
H34: =F34*G34 -> 0 | W34: =(U34-T34)*24*60 -> 0
H35: =F35*G35 -> 0 | W35: =(U35-T35)*24*60 -> 0
H36: =F36*G36 -> 0 | W36: =(U36-T36)*24*60 -> 0
C37: 4度二組B | D37: 平均 | J37: =AVERAGE(J27:J36) -> 17.5 | K37: =AVERAGE(K27:K36) -> 1573.25 | L37: =AVERAGE(L27:L36) -> 90.07598 | M37: =AVERAGE(M27:M36) -> 16.25 | N37: =AVERAGE(N27:N36) -> 1223.2551 | O37: =AVERAGE(O27:O36) -> 74.899821 | P37: =M37-J37 -> -1.25 | Q37: =N37-K37 -> -349.99489 | R37: =O37/L37 -> 0.83151825 | AB37: =N37-K37 -> -349.99489 | AC37: =N37/K37 -> 0.77753384
A38: 手工四線 (ET-55) | B38: 熱乾麵 | C38: =VLOOKUP(E38,廠價表!$C$1:$E$39,2,0) -> #N/A | D38: 青花椒麻雞肉拌麵 | F38: =VLOOKUP(D38,廠價表!$C$1:$E$39,3,0) -> 49.91 | G38: 2320 | H38: =F38*G38 -> 115791.2 | J38: =VLOOKUP(D38,產線配置圖!$A$2:$C$38,2,0) -> 17 | K38: =VLOOKUP(D38,產線配置圖!$A$2:$C$38,3,0) -> 1565 | L38: =K38/J38 -> 92.058824 | M38: 16 | N38: =G38/W38*60 -> 1378.2178 | O38: =N38/M38 -> 86.138614 | P38: =M38-J38 -> -1 | Q38: =O38-L38 -> -5.9202097 | R38: =O38/L38 -> 0.93569101 | S38: =R48 -> 0.91875333 | T38: 0.33263889 | U38: 0.40277778 | W38: =(U38-T38)*24*60 -> 101 | AB38: =N38-K38 -> -186.78218 | AC38: =N38/K38 -> 0.88065037 | AD38: =AC48 -> 0.83673158
B39: =VLOOKUP(D39,廠價表!$C$1:$E$39,2,0) -> 義大利麵 | C39: =VLOOKUP(E39,廠價表!$C$1:$E$39,2,0) -> #N/A | D39: 拿坡里義大利麵 | F39: =VLOOKUP(D39,廠價表!$C$1:$E$39,3,0) -> 58.17 | G39: 1296 | H39: =F39*G39 -> 75388.32 | J39: =VLOOKUP(D39,產線配置圖!$A$2:$C$38,2,0) -> 16 | K39: =VLOOKUP(D39,產線配置圖!$A$2:$C$38,3,0) -> 1429 | L39: =K39/J39 -> 89.3125 | M39: 14 | N39: =G39/W39*60 -> 1126.9565 | O39: =N39/M39 -> 80.496894 | P39: =M39-J39 -> -2 | Q39: =O39-L39 -> -8.8156056 | R39: =O39/L39 -> 0.90129483 | T39: 0.45 | U39: 0.49791667 | V39: =(T39-U38)*24*60 -> 68 | W39: =(U39-T39)*24*60 -> 69 | AB39: =N39-K39 -> -302.04348 | AC39: =N39/K39 -> 0.78863298
W40: =(U40-T40)*24*60 -> 0
...

Sheet 1005總
B1: 長家廠組合室生產人時性分析
B3: 日期 | D3: 45935 | F3: 訂單量 | G3: ='1005'!E1 -> 44134 | I3: 營業額 | J3: ='1005'!G1 -> 2173287.6
B4: 項目 | D4: 3 | F4: ➀ | H4: ➁ | J4: ③
B5: 人時性 | D5: 組合室 | F5: 全溫層 | H5: 義大利麵 | J5: 袋裝小吃、義麵
D6: 排關平均 | F6: =AVERAGE(D13:J13) -> 112.47854 | H6: =AVERAGE(D13:H13) -> 109.55971 | J6: =AVERAGE(I13) -> 127.07265
D7: 實績平均 | F7: =AVERAGE(D14:J14) -> 100.67267 | H7: =AVERAGE(D14:H14) -> 98.011665 | J7: =AVERAGE(I14) -> 113.97771
D8: 達成率平均 | F8: =AVERAGE(D15:J15) -> 0.89518597 | H8: =AVERAGE(D15:H15) -> 0.89483332 | J8: =AVERAGE(I15) -> 0.89694922 | L8: ※現行日本鮮食廠以達成率80%為基本(即為現行KPI)
B10: 溫層 | D10: 4度C-各編組展開
B11: 編組 | D11: 1 | E11: 2 | F11: 3 | G11: 4 | H11: 5 | I11: 6 | J11: 7
D12: 自動1線 | E12: 自動2線 | F12: 手工3線 | G12: 手工4線 | H12: 手工5線 | I12: 調理包1線 | J12: 調理包2線
B13: 人時性 | C13: 排關 | D13: =VALUE('1005'!L15) -> 132.49847 | E13: =VALUE('1005'!L26) -> 146.73344 | F13: =VALUE('1005'!L37) -> 90.07598 | G13: =VALUE('1005'!L48) -> 90.685662 | H13: =VALUE('1005'!L58) -> 87.805011 | I13: =VALUE('1005'!L69) -> 127.07265
C14: 實績 | D14: =VALUE('1005'!O15) -> 121.89039 | E14: =VALUE('1005'!O26) -> 128.84787 | F14: =VALUE('1005'!O37) -> 74.659691 | G14: =VALUE('1005'!O48) -> 77.475 | H14: =VALUE('1005'!O58) -> 87.185371 | I14: =VALUE('1005'!O69) -> 113.97771
C15: 達成率 | D15: =D14/D13 -> 0.91993805 | E15: =E14/E13 -> 0.87810845 | F15: =F14/F13 -> 0.82885239 | G15: =G14/G13 -> 0.85432469 | H15: =H14/H13 -> 0.99294301 | I15: =I14/I13 -> 0.89694922
B16: 作業 時間 | C16: 開始 | D16: ='1005'!T5 -> 0.29027778 | E16: ='1005'!T16 -> 0.28958333 | F16: ='1005'!T27 -> 0.29166667 | G16: ='1005'!T38 -> 0.33263889 | H16: ='1005'!T49 -> 0.28888889 | I16: ='1005'!T59 -> 0.29166667
C17: 結束 | D17: 0.63888889 | E17: 0.49722222 | F17: 0.56597222 | G17: 0.46180556 | H17: 0.65625 | I17: 0.49652778
B18: 配置人數 | D18: =VALUE('1005'!M15) -> 14.5 | E18: =VALUE('1005'!M26) -> 13.666667 | F18: =VALUE('1005'!M37) -> 16.75 | G18: =VALUE('1005'!M48) -> 16.5 | H18: =VALUE('1005'!M58) -> 17.333333 | I18: =VALUE('1005'!M69) -> 12.333333
B19: 主要應用設備 | D19: ET-600 | E19: ET-600 | F19: ET-55 | G19: ET-55 | H19: ET-55 | I19: 八爪機
B20: 次要應用設備 | H20: 封口機
B21: 備註

Sheet 1005
A1: 長家廠4度C日報分析 | D1: 總生產量 | E1: =SUM(G5:G79) -> 44134 | F1: 營業額 | G1: =SUM(H5:H79) -> 2173287.6 | H1: 出勤人數 | I1: =M15+M26+M48+M58+M69+M79+M37 -> 91.083333 | J1: 產線配置圖 | M1: 生產實績 | P1: 人時性差異分析 | T1: 日報登錄 | Z1: 分析說明 | AB1: 產能差異分析
A2: 10月05日 星期日 | D2: 人時性 | E2: =AVERAGE(O15,O26,O37,O48,O58,O69,O79) -> 100.67267 | F2: 平均廠價 | G2: =G1/E1 -> 49.242933 | H2: 多次生產數 | I2: =COUNT(I5:I79) -> 0
A3: 線別 | B3: 品類 | D3: 品名 | F3: 廠價 | G3: 生產量 | H3: 營收 | I3: 多次 生產 | J3: 人數 | K3: 產能/時 | L3: 人時性 | M3: 人數 | N3: 產能/時 | O3: 人時性 | P3: 人數 | Q3: 人時性 | R3: 達成率 | S3: 達成率平均 | T3: 生產時間 | V3: 前置、換線時間/分 | W3: 稼動時間/分 | X3: 休息時間 | Z3: (長家回填) | AB3: 產能/時 | AC3: 達成率 | AD3: 達成率平均
T4: 開始 | U4: 結束 | X4: 開始 | Y4: 結束
A5: 自動一線 (ET-600) | B5: =VLOOKUP(D5,廠價表!$C$1:$E$39,2,0) -> 義大利麵 | D5: 白酒蛤蜊義大利麵 | F5: =VLOOKUP(D5,廠價表!$C$1:$E$39,3,0) -> 57.21 | G5: 1371 | H5: =F5*G5 -> 78434.91 | J5: =VLOOKUP(D5,產線配置圖!$A$2:$C$38,2,0) -> 13 | K5: =VLOOKUP(D5,產線配置圖!$A$2:$C$38,3,0) -> 2000 | L5: =K5/J5 -> 153.84615 | M5: 13 | N5: =G5/W5*60 -> 1750.2128 | O5: =N5/M5 -> 134.63175 | P5: =M5-J5 -> 0 | Q5: =O5-L5 -> -19.214403 | R5: =O5/L5 -> 0.87510638 | S5: =R15 -> 0.91993805 | T5: 0.29027778 | U5: 0.32291667 | W5: =(U5-T5)*24*60 -> 47 | AB5: =N5-K5 -> -249.78723 | AC5: =N5/K5 -> 0.87510638 | AD5: =AC15 -> 0.92286107
B6: =VLOOKUP(D6,廠價表!$C$1:$E$39,2,0) -> 義大利麵 | D6: 韓式起司炸雞義大利麵 | F6: =VLOOKUP(D6,廠價表!$C$1:$E$39,3,0) -> 57.21 | G6: 2242 | H6: =F6*G6 -> 128264.82 | J6: =VLOOKUP(D6,產線配置圖!$A$2:$C$38,2,0) -> 14 | K6: =VLOOKUP(D6,產線配置圖!$A$2:$C$38,3,0) -> 1895 | L6: =K6/J6 -> 135.35714 | M6: 14 | N6: =G6/W6*60 -> 1660.7407 | O6: =N6/M6 -> 118.62434 | P6: =M6-J6 -> 0 | Q6: =O6-L6 -> -16.732804 | R6: =O6/L6 -> 0.87638034 | T6: 0.32986111 | U6: 0.38611111 | W6: =(U6-T6)*24*60 -> 81 | AB6: =N6-K6 -> -234.25926 | AC6: =N6/K6 -> 0.87638034
B7: =VLOOKUP(D7,廠價表!$C$1:$E$39,2,0) -> 義大利麵 | D7: 奶油培根義大利麵 | F7: =VLOOKUP(D7,廠價表!$C$1:$E$39,3,0) -> 49.14 | G7: 5190 | H7: =F7*G7 -> 255036.6 | J7: =VLOOKUP(D7,產線配置圖!$A$2:$C$38,2,0) -> 13 | K7: =VLOOKUP(D7,產線配置圖!$A$2:$C$38,3,0) -> 2000 | L7: =K7/J7 -> 153.84615 | M7: 13 | N7: =G7/W7*60 -> 1934.1615 | O7: =N7/M7 -> 148.78165 | P7: =M7-J7 -> 0 | Q7: =O7-L7 -> -5.0645007 | R7: =O7/L7 -> 0.96708075 | T7: 0.39444444 | U7: 0.50625 | V7: =(T7-U6)*24*60 -> 12 | W7: =(U7-T7)*24*60 -> 161 | AB7: =N7-K7 -> -65.838509 | AC7: =N7/K7 -> 0.96708075
B8: 義大利麵 | D8: 焗烤起司雙饗筆尖麵 | F8: =VLOOKUP(D8,廠價表!$C$1:$E$39,3,0) -> 49.97 | G8: 898 | H8: =F8*G8 -> 44873.06 | J8: =VLOOKUP(D8,產線配置圖!$A$2:$C$38,2,0) -> 18 | K8: =VLOOKUP(D8,產線配置圖!$A$2:$C$38,3,0) -> 1565 | L8: =K8/J8 -> 86.944444 | M8: 18 | N8: =G8/W8*60 -> 1539.4286 | O8: =N8/M8 -> 85.52381 | P8: =M8-J8 -> 0 | Q8: =O8-L8 -> -1.4206349 | R8: =O8/L8 -> 0.98366043 | T8: 0.61458333 | U8: 0.63888889 | V8: =(T8-U7)*24*60 -> 156 | W8: =(U8-T8)*24*60 -> 35 | X8: 0.52083333 | Y8: 0.60416667 | Z8: 支援製作
H9: =F9*G9 -> 0 | W9: =(U9-T9)*24*60 -> 0
H10: =F10*G10 -> 0 | W10: =(U10-T10)*24*60 -> 0
H11: =F11*G11 -> 0 | W11: =(U11-T11)*24*60 -> 0
H12: =F12*G12 -> 0 | W12: =(U12-T12)*24*60 -> 0
H13: =F13*G13 -> 0 | W13: =(U13-T13)*24*60 -> 0
H14: =F14*G14 -> 0 | W14: =(U14-T14)*24*60 -> 0
C15: 4度一組 | D15: 平均 | J15: =AVERAGE(J5:J14) -> 14.5 | K15: =AVERAGE(K5:K14) -> 1865 | L15: =AVERAGE(L5:L14) -> 132.49847 | M15: =AVERAGE(M5:M14) -> 14.5 | N15: =AVERAGE(N5:N14) -> 1721.1359 | O15: =AVERAGE(O5:O14) -> 121.89039 | P15: =M15-J15 -> 0 | Q15: =O15-L15 -> -10.608086 | R15: =O15/L15 -> 0.91993805 | AB15: =N15-K15 -> -143.86411 | AC15: =N15/K15 -> 0.92286107
