Workbook

Sheet 廠價表
A1: check | B1: 溫層 | C1: 品名 | D1: 類別 | E1: 廠價
B2: 4度C | C2: 白酒蛤蜊義大利麵 | D2: 義大利麵 | E2: 57.21
B3: 4度C | C3: 南洋紅咖哩豬義大利麵 | D3: 義大利麵 | E3: 56.43
B4: 4度C | C4: 義式蕃茄起司義大利麵 | D4: 義大利麵 | E4: 50.39
B5: 4度C | C5: 焗烤起司雙饗筆尖麵 | D5: 義大利麵 | E5: 49.97
B6: 4度C | C6: 奶油培根義大利麵 | D6: 義大利麵 | E6: 49.14
B7: 4度C | C7: 韓式起司炸雞義大利麵 | D7: 義大利麵 | E7: 57.21
B8: 4度C | D8: 義大利麵
B9: 4度C | D9: 義大利麵
B10: 4度C | D10: 義大利麵
B11: 4度C | D11: 義大利麵
B12: 4度C | C12: 剝皮辣椒雞奶油扁麵 | D12: 義大利麵 | E12: 56.87
B13: 4度C | C13: 奶油蒜香雞義大利麵 | D13: 義大利麵 | E13: 55.13
B14: 4度C | C14: 青醬蛤蜊義大利麵 | D14: 義大利麵 | E14: 50.67
B15: 4度C | C15: 焗烤明太子筆尖麵 | D15: 義大利麵 | E15: 57.3
B16: 4度C | C16: 濃拿坡里義大利麵 | D16: 義大利麵 | E16: 56.43
B17: 4度C | C17: 奶油起司蝦仁通心粉 | D17: 義大利麵 | E17: 47.71
B18: 4度C | C18: 青花椒麻雞肉拌麵 | D18: 熱乾麵 | E18: 49.91
B19: 4度C | D19: 熱乾麵
B20: 4度C | C20: 小滷青蔬 | D20: 小吃、微波 | E20: 26.99
B21: 4度C | C21: 起司馬鈴薯 | D21: 小吃、微波 | E21: 28.26
B22: 4度C | C22: 台式綜合甜不辣 | D22: 小吃、微波 | E22: 28.47
B23: 冷凍 | C23: 青醬蛤蜊義大利麵 | D23: 冷凍調理麵 | E23: 29.38
B24: 冷凍 | C24: 經典肉醬義大利麵 | D24: 冷凍調理麵 | E24: 29.38
B25: 冷凍 | C25: 奶油蘑菇培根義大利麵 | D25: 冷凍調理麵 | E25: 29.38
B26: 冷凍 | C26: 清炒蛤蜊義大利麵 | D26: 冷凍調理麵 | E26: 29.38
B27: 冷凍 | C27: 青醬乳酪筆尖麵 | D27: 冷凍調理麵 | E27: 29.38
B28: 冷凍 | C28: 辣蕃茄義大利麵 | D28: 冷凍調理麵 | E28: 29.38
B29: 冷凍 | D29: 冷凍調理麵
B30: 冷凍 | C30: 韓式起司義大利麵 | D30: 冷凍調理麵 | E30: 29.38
B31: 冷凍 | D31: 冷凍調理麵
B32: 冷凍 | C32: 和風明太子細扁麵 | D32: 冷凍調理麵 | E32: 29.38

Sheet 產線配置圖
A1: 品項 | B1: 人數 | C1: 產能
A2: 白酒蛤蜊義大利麵 | B2: 13 | C2: 2105 | D2: ET-600
A3: 白酒蛤蜊義大利麵-手 | B3: 15 | C3: 1565 | D3: ET-55
A4: 青醬蛤蜊義大利麵 | B4: 13 | C4: 2000
A5: 義式蕃茄起司義大利麵 | B5: 12 | C5: 2000
A6: 焗烤起司雙饗筆尖麵 | B6: 18 | C6: 1600
A7: 奶油培根義大利麵 | B7: 13 | C7: 2000
A8: 韓式起司炸雞義大利麵 | B8: 17 | C8: 1895
A9: 剝皮辣椒雞奶油扁麵 | B9: 19 | C9: 1565
A10: 青花椒麻雞肉拌麵 | B10: 17 | C10: 1565
A11: 青花椒麻雞肉拌麵-降速生產 | B11: 14 | C11: 1385
A12: 奶油蒜香雞義大利麵 | B12: 18 | C12: 1385 | G12: 日一二正常版
A13: 奶油蒜香雞義大利麵-降速生產 | B13: 16 | C13: 1385
A14: 焗烤明太子筆尖麵 | B14: 15 | C14: 1385
A15: 濃拿坡里義大利麵 | B15: 15 | C15: 1406
A16: 奶油起司蝦仁通心粉 | B16: 15 | C16: 1500
A17: 剝皮辣椒雞奶油扁麵-降速生產(3線) | B17: 16 | C17: 1440
A18: 南洋紅咖哩豬義大利麵 | B18: 15 | C18: 1636
A19: 南洋紅咖哩豬義大利麵-手工 | B19: 16 | C19: 1500
A25: 小滷青蔬 | B25: 13 | C25: 1565
A26: 起司馬鈴薯 | B26: 12 | C26: 1565
A27: 台式綜合甜不辣 | B27: 12 | C27: 1565
E32: 更新日期11/02

Sheet 1101總
B1: 長家廠組合室生產人時性分析
B3: 日期 | D3: 45962 | F3: 訂單量 | G3: ='1101'!E1 -> 47648 | I3: 營業額 | J3: ='1101'!G1 -> 2315838.2
B4: 項目 | D4: 3 | F4: ➀ | H4: ➁ | J4: ③
B5: 人時性 | D5: 組合室 | F5: 全溫層 | H5: 義大利麵 | J5: 袋裝小吃、義麵
D6: 排關平均 | F6: =AVERAGE(D13:J13) -> 115.84788 | H6: =AVERAGE(D13:H13) -> 115.25584 | J6: =AVERAGE(I13:J13) -> 117.32799
D7: 實績平均 | F7: =AVERAGE(D14:J14) -> 93.7705 | H7: =AVERAGE(D14:H14) -> 96.710154 | J7: =AVERAGE(I14:J14) -> 86.421366
D8: 達成率平均 | F8: =AVERAGE(D15:J15) -> 0.80833172 | H8: =AVERAGE(D15:H15) -> 0.83672125 | J8: =AVERAGE(I15:J15) -> 0.73735788 | L8: ※現行日本鮮食廠以達成率80%為基本(即為現行KPI)
B10: 溫層 | D10: 4度C-各編組展開
B11: 編組 | D11: 1 | E11: 2 | F11: 3 | G11: 4 | H11: 5 | I11: 6 | J11: 7
D12: 自動1線 | E12: 自動2線 | F12: 手工3線 | G12: 手工4線 | H12: 手工5線 | I12: 調理包1線 | J12: 調理包2線
B13: 人時性 | C13: 排關 | D13: =VALUE('1101'!L15) -> 145.27149 | E13: =VALUE('1101'!L26) -> 162.27564 | F13: =VALUE('1101'!L37) -> 84.501634 | G13: =VALUE('1101'!L48) -> 93.733333 | H13: =VALUE('1101'!L58) -> 90.497076 | I13: =VALUE('1101'!L69) -> 127.90865 | J13: =VALUE('1101'!L79) -> 106.74733
C14: 實績 | D14: =VALUE('1101'!O15) -> 131.22365 | E14: =VALUE('1101'!O26) -> 131.12525 | F14: =VALUE('1101'!O37) -> 69.207178 | G14: =VALUE('1101'!O48) -> 68.911628 | H14: =VALUE('1101'!O58) -> 83.083057 | I14: =VALUE('1101'!O69) -> 93.210095 | J14: =VALUE('1101'!O79) -> 79.632637
C15: 達成率 | D15: =D14/D13 -> 0.90329939 | E15: =E14/E13 -> 0.80804028 | F15: =F14/F13 -> 0.81900403 | G15: =G14/G13 -> 0.73518806 | H15: =H14/H13 -> 0.9180745 | I15: =I14/I13 -> 0.72872391 | J15: =J14/J13 -> 0.74599184
B16: 作業 時間 | C16: 開始 | D16: ='1101'!T5 -> 0.29027778 | E16: ='1101'!T16 -> 0.29027778 | F16: ='1101'!T27 -> 0.28819444 | G16: ='1101'!T38 -> 0.33333333 | H16: ='1101'!T49 -> 0.29027778 | I16: ='1101'!T59 -> 0.29166667 | J16: ='1101'!T70 -> 0.34027778
C17: 結束 | D17: 0.5625 | E17: 0.62291667 | F17: 0.45347222 | G17: 0.48263889 | H17: 0.60763889 | I17: 0.61805556 | J17: 0.63958333
B18: 配置人數 | D18: =VALUE('1101'!M15) -> 14 | E18: =VALUE('1101'!M26) -> 13 | F18: =VALUE('1101'!M37) -> 17 | G18: =VALUE('1101'!M48) -> 15 | H18: =VALUE('1101'!M58) -> 17 | I18: =VALUE('1101'!M69) -> 12.25 | J18: =VALUE('1101'!M79) -> 13.75
B19: 主要應用設備 | D19: ET-600 | E19: ET-600 | F19: ET-55 | G19: ET-55 | H19: ET-55 | I19: 八爪機 | J19: ET-55
B20: 次要應用設備 | H20: 封口機
B21: 備註

Sheet 1101
A1: 長家廠4度C日報分析 | D1: 總生產量 | E1: =SUM(G5:G79) -> 47648 | F1: 營業額 | G1: =SUM(H5:H79) -> 2315838.2 | H1: 出勤人數 | I1: =M15+M26+M48+M58+M69+M79+M37 -> 102 | J1: 產線配置圖 | M1: 生產實績 | P1: 人時性差異分析 | T1: 日報登錄 | Z1: 分析說明 | AB1: 產能差異分析
A2: 11月01日 星期六 | D2: 人時性 | E2: =AVERAGE(O15,O26,O37,O48,O58,O69,O79) -> 93.7705 | F2: 平均廠價 | G2: =G1/E1 -> 48.603051 | H2: 多次生產數 | I2: =COUNT(I5:I79) -> 0
A3: 線別 | B3: 品類 | D3: 品名 | F3: 廠價 | G3: 生產量 | H3: 營收 | I3: 多次 生產 | J3: 人數 | K3: 產能/時 | L3: 人時性 | M3: 人數 | N3: 產能/時 | O3: 人時性 | P3: 人數 | Q3: 人時性 | R3: 達成率 | S3: 達成率平均 | T3: 生產時間 | V3: 前置、換線時間/分 | W3: 稼動時間/分 | X3: 休息時間 | Z3: (長家回填) | AB3: 產能/時 | AC3: 達成率 | AD3: 達成率平均
T4: 開始 | U4: 結束 | X4: 開始 | Y4: 結束
A5: 自動一線 (ET-600) | B5: =VLOOKUP(D5,廠價表!$C$1:$E$39,2,0) -> 義大利麵 | D5: 白酒蛤蜊義大利麵 | F5: =VLOOKUP(D5,廠價表!$C$1:$E$39,3,0) -> 57.21 | G5: 1423 | H5: =F5*G5 -> 81409.83 | J5: =VLOOKUP(D5,產線配置圖!$A$2:$C$38,2,0) -> 13 | K5: =VLOOKUP(D5,產線配置圖!$A$2:$C$38,3,0) -> 2105 | L5: =K5/J5 -> 161.92308 | M5: 13 | N5: =G5/W5*60 -> 1897.3333 | O5: =N5/M5 -> 145.94872 | P5: =M5-J5 -> 0 | Q5: =O5-L5 -> -15.974359 | R5: =O5/L5 -> 0.901346 | S5: =R15 -> 0.90329939 | T5: 0.29027778 | U5: 0.32152778 | W5: =(U5-T5)*24*60 -> 45 | AB5: =N5-K5 -> -207.66667 | AC5: =N5/K5 -> 0.901346 | AD5: =AC15 -> 0.90127553
B6: =VLOOKUP(D6,廠價表!$C$1:$E$39,2,0) -> 義大利麵 | D6: 韓式起司炸雞義大利麵 | F6: =VLOOKUP(D6,廠價表!$C$1:$E$39,3,0) -> 57.21 | G6: 1862 | H6: =F6*G6 -> 106525.02 | J6: =VLOOKUP(D6,產線配置圖!$A$2:$C$38,2,0) -> 17 | K6: =VLOOKUP(D6,產線配置圖!$A$2:$C$38,3,0) -> 1895 | L6: =K6/J6 -> 111.47059 | M6: 17 | N6: =G6/W6*60 -> 1642.9412 | O6: =N6/M6 -> 96.643599 | P6: =M6-J6 -> 0 | Q6: =O6-L6 -> -14.82699 | R6: =O6/L6 -> 0.86698743 | T6: 0.33055556 | U6: 0.37777778 | V6: =(T6-U5)*24*60 -> 13 | W6: =(U6-T6)*24*60 -> 68 | AB6: =N6-K6 -> -252.05882 | AC6: =N6/K6 -> 0.86698743
B7: =VLOOKUP(D7,廠價表!$C$1:$E$39,2,0) -> 義大利麵 | D7: 奶油培根義大利麵 | F7: =VLOOKUP(D7,廠價表!$C$1:$E$39,3,0) -> 49.14 | G7: 3786 | H7: =F7*G7 -> 186044.04 | J7: =VLOOKUP(D7,產線配置圖!$A$2:$C$38,2,0) -> 13 | K7: =VLOOKUP(D7,產線配置圖!$A$2:$C$38,3,0) -> 2000 | L7: =K7/J7 -> 153.84615 | M7: 13 | N7: =G7/W7*60 -> 1695.2239 | O7: =N7/M7 -> 130.40184 | P7: =M7-J7 -> 0 | Q7: =O7-L7 -> -23.444317 | R7: =O7/L7 -> 0.84761194 | T7: 0.38611111 | U7: 0.47916667 | V7: =(T7-U6)*24*60 -> 12 | W7: =(U7-T7)*24*60 -> 134 | AB7: =N7-K7 -> -304.77612 | AC7: =N7/K7 -> 0.84761194
B8: =VLOOKUP(D8,廠價表!$C$1:$E$39,2,0) -> 義大利麵 | D8: 奶油培根義大利麵 | F8: =VLOOKUP(D8,廠價表!$C$1:$E$39,3,0) -> 49.14 | G8: 1119 | H8: =F8*G8 -> 54987.66 | J8: =VLOOKUP(D8,產線配置圖!$A$2:$C$38,2,0) -> 13 | K8: =VLOOKUP(D8,產線配置圖!$A$2:$C$38,3,0) -> 2000 | L8: =K8/J8 -> 153.84615 | M8: 13 | N8: =G8/W8*60 -> 1974.7059 | O8: =N8/M8 -> 151.90045 | P8: =M8-J8 -> 0 | Q8: =O8-L8 -> -1.9457014 | R8: =O8/L8 -> 0.98735294 | T8: 0.53888889 | U8: 0.5625 | V8: =(T8-U7)*24*60 -> 86 | W8: =(U8-T8)*24*60 -> 34
W9: =(U9-T9)*24*60 -> 0
W10: =(U10-T10)*24*60 -> 0
H11: =F11*G11 -> 0 | W11: =(U11-T11)*24*60 -> 0
H12: =F12*G12 -> 0 | W12: =(U12-T12)*24*60 -> 0
H13: =F13*G13 -> 0 | W13: =(U13-T13)*24*60 -> 0
H14: =F14*G14 -> 0 | W14: =(U14-T14)*24*60 -> 0
C15: 4度一組 | D15: 平均 | J15: =AVERAGE(J5:J14) -> 14 | K15: =AVERAGE(K5:K14) -> 2000 | L15: =AVERAGE(L5:L14) -> 145.27149 | M15: =AVERAGE(M5:M14) -> 14 | N15: =AVERAGE(N5:N14) -> 1802.5511 | O15: =AVERAGE(O5:O14) -> 131.22365 | P15: =M15-J15 -> 0 | Q15: =O15-L15 -> -14.047842 | R15: =O15/L15 -> 0.90329939 | AB15: =N15-K15 -> -197.44893 | AC15: =N15/K15 -> 0.90127553
A16: 自動二線 (ET-600) | B16: 義大利麵 | D16: 白酒蛤蜊義大利麵 | F16: =VLOOKUP(D16,廠價表!$C$1:$E$39,3,0) -> 57.21 | G16: 1130 | H16: =F16*G16 -> 64647.3 | J16: =VLOOKUP(D16,產線配置圖!$A$2:$C$38,2,0) -> 13 | K16: =VLOOKUP(D16,產線配置圖!$A$2:$C$38,3,0) -> 2105 | L16: =K16/J16 -> 161.92308 | M16: 13 | N16: =G16/W16*60 -> 1883.3333 | O16: =N16/M16 -> 144.87179 | P16: =M16-J16 -> 0 | Q16: =O16-L16 -> -17.051282 | R16: =O16/L16 -> 0.89469517 | S16: =R26 -> 0.80804028 | T16: 0.29027778 | U16: 0.31527778 | W16: =(U16-T16)*24*60 -> 36 | AB16: =N16-K16 -> -221.66667 | AC16: =N16/K16 -> 0.89469517 | AD16: =AC26 -> 0.84060224
B17: 義大利麵 | D17: 青醬蛤蜊義大利麵 | F17: =VLOOKUP(D17,廠價表!$C$1:$E$39,3,0) -> 50.67 | G17: 4428 | H17: =F17*G17 -> 224366.76 | J17: =VLOOKUP(D17,產線配置圖!$A$2:$C$38,2,0) -> 13 | K17: =VLOOKUP(D17,產線配置圖!$A$2:$C$38,3,0) -> 2000 | L17: =K17/J17 -> 153.84615 | M17: 15 | N17: =G17/W17*60 -> 1870.9859 | O17: =N17/M17 -> 124.73239 | P17: =M17-J17 -> 2 | Q17: =O17-L17 -> -29.113759 | R17: =O17/L17 -> 0.81076056 | T17: 0.32361111 | U17: 0.42222222 | V17: =(T17-U16)*24*60 -> 12 | W17: =(U17-T17)*24*60 -> 142 | AB17: =N17-K17 -> -129.01408 | AC17: =N17/K17 -> 0.93549296
B18: 義大利麵 | D18: 義式蕃茄起司義大利麵 | F18: =VLOOKUP(D18,廠價表!$C$1:$E$39,3,0) -> 50.39 | G18: 2153 | H18: =F18*G18 -> 108489.67 | J18: =VLOOKUP(D18,產線配置圖!$A$2:$C$38,2,0) -> 12 | K18: =VLOOKUP(D18,產線配置圖!$A$2:$C$38,3,0) -> 2000 | L18: =K18/J18 -> 166.66667 | M18: 12 | N18: =G18/W18*60 -> 1845.4286 | O18: =N18/M18 -> 153.78571 | P18: =M18-J18 -> 0 | Q18: =O18-L18 -> -12.880952 | R18: =O18/L18 -> 0.92271429 | T18: 0.43055556 | U18: 0.47916667 | V18: =(T18-U17)*24*60 -> 12 | W18: =(U18-T18)*24*60 -> 70 | AB18: =N18-K18 -> -154.57143 | AC18: =N18/K18 -> 0.92271429
B19: 義大利麵 | D19: 義式蕃茄起司義大利麵 | F19: =VLOOKUP(D19,廠價表!$C$1:$E$39,3,0) -> 50.39 | G19: 2366 | H19: =F19*G19 -> 119222.74 | J19: =VLOOKUP(D19,產線配置圖!$A$2:$C$38,2,0) -> 12 | K19: =VLOOKUP(D19,產線配置圖!$A$2:$C$38,3,0) -> 2000 | L19: =K19/J19 -> 166.66667 | M19: 12 | N19: =G19/W19*60 -> 1213.3333 | O19: =N19/M19 -> 101.11111 | P19: =M19-J19 -> 0 | Q19: =O19-L19 -> -65.555556 | R19: =O19/L19 -> 0.60666667 | T19: 0.54166667 | U19: 0.62291667 | V19: =(T19-U18)*24*60 -> 90 | W19: =(U19-T19)*24*60 -> 117 | Z19: 13:35-14:10待玉取機煮麵 | AB19: =N19-K19 -> -786.66667 | AC19: =N19/K19 -> 0.60666667
W20: =(U20-T20)*24*60 -> 0
H21: =F21*G21 -> 0 | W21: 0
H22: =F22*G22 -> 0 | W22: 0
H23: =F23*G23 -> 0 | W23: =(U23-T23)*24*60 -> 0
H24: =F24*G24 -> 0 | W24: =(U24-T24)*24*60 -> 0
H25: =F25*G25 -> 0 | W25: =(U25-T25)*24*60 -> 0
C26: 4度二組A | D26: 平均 | J26: =AVERAGE(J16:J25) -> 12.5 | K26: =AVERAGE(K16:K25) -> 2026.25 | L26: =AVERAGE(L16:L25) -> 162.27564 | M26: =AVERAGE(M16:M25) -> 13 | N26: =AVERAGE(N16:N25) -> 1703.2703 | O26: =AVERAGE(O16:O25) -> 131.12525 | P26: =M26-J26 -> 0.5 | Q26: =O26-L26 -> -31.150387 | R26: =O26/L26 -> 0.80804028 | AB26: =N26-K26 -> -322.97971 | AC26: =N26/K26 -> 0.84060224
A27: 手工三線 (ET-55) | B27: 義大利麵 | D27: 青花椒麻雞肉拌麵 | F27: =VLOOKUP(D27,廠價表!$C$1:$E$39,3,0) -> 49.91 | G27: 2593 | H27: =F27*G27 -> 129416.63 | J27: =VLOOKUP(D27,產線配置圖!$A$2:$C$38,2,0) -> 17 | K27: =VLOOKUP(D27,產線配置圖!$A$2:$C$38,3,0) -> 1565 | L27: =K27/J27 -> 92.058824 | M27: 17 | N27: =G27/W27*60 -> 1275.2459 | O27: =N27/M27 -> 75.014465 | P27: =M27-J27 -> 0 | Q27: =O27-L27 -> -17.044359 | R27: =O27/L27 -> 0.81485361 | S27: =R37 -> 0.81900403 | T27: 0.28819444 | U27: 0.37291667 | W27: =(U27-T27)*24*60 -> 122 | AB27: =N27-K27 -> -289.7541 | AC27: =N27/K27 -> 0.81485361 | AD27: =AC37 -> 0.79764206
B28: =VLOOKUP(D28,廠價表!$C$1:$E$39,2,0) -> 義大利麵 | D28: 奶油蒜香雞義大利麵 | F28: =VLOOKUP(D28,廠價表!$C$1:$E$39,3,0) -> 55.13 | G28: 1958 | H28: =F28*G28 -> 107944.54 | J28: =VLOOKUP(D28,產線配置圖!$A$2:$C$38,2,0) -> 18 | K28: =VLOOKUP(D28,產線配置圖!$A$2:$C$38,3,0) -> 1385 | L28: =K28/J28 -> 76.944444 | M28: 17 | N28: =G28/W28*60 -> 1077.7982 | O28: =N28/M28 -> 63.399892 | P28: =M28-J28 -> -1 | Q28: =O28-L28 -> -13.544552 | R28: =O28/L28 -> 0.82396972 | T28: 0.37777778 | U28: 0.45347222 | V28: =(T28-U27)*24*60 -> 7 | W28: =(U28-T28)*24*60 -> 109 | AB28: =N28-K28 -> -307.20183 | AC28: =N28/K28 -> 0.77819362
W29: =(U29-T29)*24*60 -> 0
W30: =(U30-T30)*24*60 -> 0
W31: =(U31-T31)*24*60 -> 0
H32: =F32*G32 -> 0 | W32: =(U32-T32)*24*60 -> 0
H33: =F33*G33 -> 0 | W33: =(U33-T33)*24*60 -> 0
H34: =F34*G34 -> 0 | W34: =(U34-T34)*24*60 -> 0
H35: =F35*G35 -> 0 | W35: =(U35-T35)*24*60 -> 0
H36: =F36*G36 -> 0 | W36: =(U36-T36)*24*60 -> 0
C37: 4度二組B | D37: 平均 | J37: =AVERAGE(J27:J36) -> 17.5 | K37: =AVERAGE(K27:K36) -> 1475 | L37: =AVERAGE(L27:L36) -> 84.501634 | M37: =AVERAGE(M27:M36) -> 17 | N37: =AVERAGE(N27:N36) -> 1176.522 | O37: =AVERAGE(O27:O36) -> 69.207178 | P37: =M37-J37 -> -0.5 | Q37: =N37-K37 -> -298.47797 | R37: =O37/L37 -> 0.81900403 | AB37: =N37-K37 -> -298.47797 | AC37: =N37/K37 -> 0.79764206
A38: 手工四線 (ET-55) | B38: 義大利麵 | D38: 濃拿坡里義大利麵 | F38: =VLOOKUP(D38,廠價表!$C$1:$E$39,3,0) -> 56.43 | G38: 3704 | H38: =F38*G38 -> 209016.72 | J38: =VLOOKUP(D38,產線配置圖!$A$2:$C$38,2,0) -> 15 | K38: =VLOOKUP(D38,產線配置圖!$A$2:$C$38,3,0) -> 1406 | L38: =K38/J38 -> 93.733333 | M38: 15 | N38: =G38/W38*60 -> 1033.6744 | O38: =N38/M38 -> 68.911628 | P38: =M38-J38 -> 0 | Q38: =O38-L38 -> -24.821705 | R38: =O38/L38 -> 0.73518806 | S38: =R48 -> 0.73518806 | T38: 0.33333333 | U38: 0.48263889 | W38: =(U38-T38)*24*60 -> 215 | Z38: 封口設備異常 | AB38: =N38-K38 -> -372.32558 | AC38: =N38/K38 -> 0.73518806 | AD38: =AC48 -> 0.73518806
W39: =(U39-T39)*24*60 -> 0
W40: =(U40-T40)*24*60 -> 0
...

Sheet 1102總 
B1: 長家廠組合室生產人時性分析
B3: 日期 | D3: 45963 | F3: 訂單量 | G3: ='1102'!E1 -> 65617 | I3: 營業額 | J3: ='1102'!G1 -> 3113202.2
B4: 項目 | D4: 3 | F4: ➀ | H4: ➁ | J4: ③
B5: 人時性 | D5: 組合室 | F5: 全溫層 | H5: 義大利麵 | J5: 袋裝小吃、義麵
D6: 排關平均 | F6: =AVERAGE(D13:J13) -> 115.11769 | H6: =AVERAGE(D13:H13) -> 114.90237 | J6: =AVERAGE(I13:J13) -> 115.65598
D7: 實績平均 | F7: =AVERAGE(D14:J14) -> 102.69935 | H7: =AVERAGE(D14:H14) -> 104.34339 | J7: =AVERAGE(I14:J14) -> 98.58925
D8: 達成率平均 | F8: =AVERAGE(D15:J15) -> 0.88682946 | H8: =AVERAGE(D15:H15) -> 0.90145753 | J8: =AVERAGE(I15:J15) -> 0.85025927 | L8: ※現行日本鮮食廠以達成率80%為基本(即為現行KPI)
B10: 溫層 | D10: 4度C-各編組展開
B11: 編組 | D11: 1 | E11: 2 | F11: 3 | G11: 4 | H11: 5 | I11: 6 | J11: 7
D12: 自動1線 | E12: 自動2線 | F12: 手工3線 | G12: 手工4線 | H12: 手工5線 | I12: 調理包1線 | J12: 調理包2線
B13: 人時性 | C13: 排關 | D13: =VALUE('1102'!L15) -> 146.98643 | E13: =VALUE('1102'!L26) -> 160.58974 | F13: =VALUE('1102'!L37) -> 86.486928 | G13: =VALUE('1102'!L48) -> 93.733333 | H13: =VALUE('1102'!L58) -> 86.7154 | I13: =VALUE('1102'!L69) -> 125.40064 | J13: =VALUE('1102'!L79) -> 105.91132
C14: 實績 | D14: =VALUE('1102'!O15) -> 136.27735 | E14: =VALUE('1102'!O26) -> 150.71671 | F14: =VALUE('1102'!O37) -> 74.000833 | G14: =VALUE('1102'!O48) -> 78.118182 | H14: =VALUE('1102'!O58) -> 82.603879 | I14: =VALUE('1102'!O69) -> 109.86181 | J14: =VALUE('1102'!O79) -> 87.316688
C15: 達成率 | D15: =D14/D13 -> 0.92714242 | E15: =E14/E13 -> 0.93852016 | F15: =F14/F13 -> 0.85563026 | G15: =G14/G13 -> 0.83340877 | H15: =H14/H13 -> 0.95258604 | I15: =I14/I13 -> 0.87608652 | J15: =J14/J13 -> 0.82443202
B16: 作業 時間 | C16: 開始 | D16: ='1102'!T5 -> 0.29027778 | E16: ='1102'!T16 -> 0.29097222 | F16: ='1102'!T27 -> 0.29027778 | G16: ='1102'!T38 -> 0.33333333 | H16: ='1102'!T49 -> 0.29027778 | I16: ='1102'!T59 -> 0.29097222 | J16: ='1102'!T70 -> 0.34444444
C17: 結束 | D17: 0.67013889 | E17: 0.68333333 | F17: 0.67013889 | G17: 0.57638889 | H17: 0.63611111 | I17: 0.63333333 | J17: 0.68402778
B18: 配置人數 | D18: =VALUE('1102'!M15) -> 13.8 | E18: =VALUE('1102'!M26) -> 12.6 | F18: =VALUE('1102'!M37) -> 17 | G18: =VALUE('1102'!M48) -> 15 | H18: =VALUE('1102'!M58) -> 18.333333 | I18: =VALUE('1102'!M69) -> 12.5 | J18: =VALUE('1102'!M79) -> 13.5
B19: 主要應用設備 | D19: ET-600 | E19: ET-600 | F19: ET-55 | G19: ET-55 | H19: ET-55 | I19: 八爪機 | J19: ET-55
B20: 次要應用設備 | H20: 封口機
B21: 備註

Sheet 1102
A1: 長家廠4度C日報分析 | D1: 總生產量 | E1: =SUM(G5:G79) -> 65617 | F1: 營業額 | G1: =SUM(H5:H79) -> 3113202.2 | H1: 出勤人數 | I1: =M15+M26+M48+M58+M69+M79+M37 -> 102.73333 | J1: 產線配置圖 | M1: 生產實績 | P1: 人時性差異分析 | T1: 日報登錄 | Z1: 分析說明 | AB1: 產能差異分析
A2: 11月02日 星期日 | D2: 人時性 | E2: =AVERAGE(O15,O26,O37,O48,O58,O69,O79) -> 102.69935 | F2: 平均廠價 | G2: =G1/E1 -> 47.445055 | H2: 多次生產數 | I2: =COUNT(I5:I79) -> 0
A3: 線別 | B3: 品類 | D3: 品名 | F3: 廠價 | G3: 生產量 | H3: 營收 | I3: 多次 生產 | J3: 人數 | K3: 產能/時 | L3: 人時性 | M3: 人數 | N3: 產能/時 | O3: 人時性 | P3: 人數 | Q3: 人時性 | R3: 達成率 | S3: 達成率平均 | T3: 生產時間 | V3: 前置、換線時間/分 | W3: 稼動時間/分 | X3: 休息時間 | Z3: (長家回填) | AB3: 產能/時 | AC3: 達成率 | AD3: 達成率平均
T4: 開始 | U4: 結束 | X4: 開始 | Y4: 結束
A5: 自動一線 (ET-600) | B5: =VLOOKUP(D5,廠價表!$C$1:$E$39,2,0) -> 義大利麵 | D5: 白酒蛤蜊義大利麵 | F5: =VLOOKUP(D5,廠價表!$C$1:$E$39,3,0) -> 57.21 | G5: 1909 | H5: =F5*G5 -> 109213.89 | J5: =VLOOKUP(D5,產線配置圖!$A$2:$C$38,2,0) -> 13 | K5: =VLOOKUP(D5,產線配置圖!$A$2:$C$38,3,0) -> 2105 | L5: =K5/J5 -> 161.92308 | M5: 13 | N5: =G5/W5*60 -> 1941.3559 | O5: =N5/M5 -> 149.33507 | P5: =M5-J5 -> 0 | Q5: =O5-L5 -> -12.588005 | R5: =O5/L5 -> 0.92225935 | S5: =R15 -> 0.92714242 | T5: 0.29027778 | U5: 0.33125 | W5: =(U5-T5)*24*60 -> 59 | AB5: =N5-K5 -> -163.64407 | AC5: =N5/K5 -> 0.92225935 | AD5: =AC15 -> 0.92765027
B6: =VLOOKUP(D6,廠價表!$C$1:$E$39,2,0) -> 義大利麵 | D6: 青醬蛤蜊義大利麵 | F6: =VLOOKUP(D6,廠價表!$C$1:$E$39,3,0) -> 50.67 | G6: 1909 | H6: =F6*G6 -> 96729.03 | J6: =VLOOKUP(D6,產線配置圖!$A$2:$C$38,2,0) -> 13 | K6: =VLOOKUP(D6,產線配置圖!$A$2:$C$38,3,0) -> 2000 | L6: =K6/J6 -> 153.84615 | M6: 13 | N6: =G6/W6*60 -> 1941.3559 | O6: =N6/M6 -> 149.33507 | P6: =M6-J6 -> 0 | Q6: =O6-L6 -> -4.5110821 | R6: =O6/L6 -> 0.97067797 | T6: 0.3375 | U6: 0.37847222 | V6: =(T6-U5)*24*60 -> 9 | W6: =(U6-T6)*24*60 -> 59 | AB6: =N6-K6 -> -58.644068 | AC6: =N6/K6 -> 0.97067797
B7: =VLOOKUP(D7,廠價表!$C$1:$E$39,2,0) -> 義大利麵 | D7: 韓式起司炸雞義大利麵 | F7: =VLOOKUP(D7,廠價表!$C$1:$E$39,3,0) -> 57.21 | G7: 2401 | H7: =F7*G7 -> 137361.21 | J7: =VLOOKUP(D7,產線配置圖!$A$2:$C$38,2,0) -> 17 | K7: =VLOOKUP(D7,產線配置圖!$A$2:$C$38,3,0) -> 1895 | L7: =K7/J7 -> 111.47059 | M7: 17 | N7: =G7/W7*60 -> 1778.5185 | O7: =N7/M7 -> 104.61874 | P7: =M7-J7 -> 0 | Q7: =O7-L7 -> -6.8518519 | R7: =O7/L7 -> 0.9385322 | T7: 0.3875 | U7: 0.44375 | V7: =(T7-U6)*24*60 -> 13 | W7: =(U7-T7)*24*60 -> 81 | AB7: =N7-K7 -> -116.48148 | AC7: =N7/K7 -> 0.9385322
B8: =VLOOKUP(D8,廠價表!$C$1:$E$39,2,0) -> 義大利麵 | D8: 奶油培根義大利麵 | F8: =VLOOKUP(D8,廠價表!$C$1:$E$39,3,0) -> 49.14 | G8: 2697 | H8: =F8*G8 -> 132530.58 | J8: =VLOOKUP(D8,產線配置圖!$A$2:$C$38,2,0) -> 13 | K8: =VLOOKUP(D8,產線配置圖!$A$2:$C$38,3,0) -> 2000 | L8: =K8/J8 -> 153.84615 | M8: 13 | N8: =G8/W8*60 -> 1949.6386 | O8: =N8/M8 -> 149.9722 | P8: =M8-J8 -> 0 | Q8: =O8-L8 -> -3.8739574 | R8: =O8/L8 -> 0.97481928 | T8: 0.45138889 | U8: 0.50902778 | V8: =(T8-U7)*24*60 -> 11 | W8: =(U8-T8)*24*60 -> 83 | AB8: =N8-K8 -> -50.361446 | AC8: =N8/K8 -> 0.97481928
B9: =VLOOKUP(D9,廠價表!$C$1:$E$39,2,0) -> 義大利麵 | D9: 奶油培根義大利麵 | F9: =VLOOKUP(D9,廠價表!$C$1:$E$39,3,0) -> 49.14 | G9: 3942 | H9: =F9*G9 -> 193709.88 | J9: =VLOOKUP(D9,產線配置圖!$A$2:$C$38,2,0) -> 13 | K9: =VLOOKUP(D9,產線配置圖!$A$2:$C$38,3,0) -> 2000 | L9: =K9/J9 -> 153.84615 | M9: 13 | N9: =G9/W9*60 -> 1665.6338 | O9: =N9/M9 -> 128.12568 | P9: =M9-J9 -> 0 | Q9: =O9-L9 -> -25.720477 | R9: =O9/L9 -> 0.8328169 | T9: 0.57152778 | U9: 0.67013889 | V9: =(T9-U8)*24*60 -> 90 | W9: =(U9-T9)*24*60 -> 142
W10: =(U10-T10)*24*60 -> 0
H11: =F11*G11 -> 0 | W11: =(U11-T11)*24*60 -> 0
H12: =F12*G12 -> 0 | W12: =(U12-T12)*24*60 -> 0
H13: =F13*G13 -> 0 | W13: =(U13-T13)*24*60 -> 0
H14: =F14*G14 -> 0 | W14: =(U14-T14)*24*60 -> 0
C15: 4度一組 | D15: 平均 | J15: =AVERAGE(J5:J14) -> 13.8 | K15: =AVERAGE(K5:K14) -> 2000 | L15: =AVERAGE(L5:L14) -> 146.98643 | M15: =AVERAGE(M5:M14) -> 13.8 | N15: =AVERAGE(N5:N14) -> 1855.3005 | O15: =AVERAGE(O5:O14) -> 136.27735 | P15: =M15-J15 -> 0 | Q15: =O15-L15 -> -10.709075 | R15: =O15/L15 -> 0.92714242 | AB15: =N15-K15 -> -144.69945 | AC15: =N15/K15 -> 0.92765027
A16: 自動二線 (ET-600) | B16: 義大利麵 | D16: 白酒蛤蜊義大利麵 | F16: =VLOOKUP(D16,廠價表!$C$1:$E$39,3,0) -> 57.21 | G16: 1671 | H16: =F16*G16 -> 95597.91 | J16: =VLOOKUP(D16,產線配置圖!$A$2:$C$38,2,0) -> 13 | K16: =VLOOKUP(D16,產線配置圖!$A$2:$C$38,3,0) -> 2105 | L16: =K16/J16 -> 161.92308 | M16: 13 | N16: =G16/W16*60 -> 1965.8824 | O16: =N16/M16 -> 151.22172 | P16: =M16-J16 -> 0 | Q16: =O16-L16 -> -10.701357 | R16: =O16/L16 -> 0.93391086 | S16: =R26 -> 0.93852016 | T16: 0.29097222 | U16: 0.32638889 | W16: =(U16-T16)*24*60 -> 51 | AB16: =N16-K16 -> -139.11765 | AC16: =N16/K16 -> 0.93391086 | AD16: =AC26 -> 0.93872002
B17: 義大利麵 | D17: 青醬蛤蜊義大利麵 | F17: =VLOOKUP(D17,廠價表!$C$1:$E$39,3,0) -> 50.67 | G17: 2764 | H17: =F17*G17 -> 140051.88 | J17: =VLOOKUP(D17,產線配置圖!$A$2:$C$38,2,0) -> 13 | K17: =VLOOKUP(D17,產線配置圖!$A$2:$C$38,3,0) -> 2000 | L17: =K17/J17 -> 153.84615 | M17: 13 | N17: =G17/W17*60 -> 1863.3708 | O17: =N17/M17 -> 143.33621 | P17: =M17-J17 -> 0 | Q17: =O17-L17 -> -10.509939 | R17: =O17/L17 -> 0.93168539 | T17: 0.33402778 | U17: 0.39583333 | V17: =(T17-U16)*24*60 -> 11 | W17: =(U17-T17)*24*60 -> 89 | AB17: =N17-K17 -> -136.62921 | AC17: =N17/K17 -> 0.93168539
B18: 義大利麵 | D18: 義式蕃茄起司義大利麵 | F18: =VLOOKUP(D18,廠價表!$C$1:$E$39,3,0) -> 50.39 | G18: 3478 | H18: =F18*G18 -> 175256.42 | J18: =VLOOKUP(D18,產線配置圖!$A$2:$C$38,2,0) -> 12 | K18: =VLOOKUP(D18,產線配置圖!$A$2:$C$38,3,0) -> 2000 | L18: =K18/J18 -> 166.66667 | M18: 12 | N18: =G18/W18*60 -> 1932.2222 | O18: =N18/M18 -> 161.01852 | P18: =M18-J18 -> 0 | Q18: =O18-L18 -> -5.6481481 | R18: =O18/L18 -> 0.96611111 | T18: 0.40416667 | U18: 0.47916667 | V18: =(T18-U17)*24*60 -> 12 | W18: =(U18-T18)*24*60 -> 108 | AB18: =N18-K18 -> -67.777778 | AC18: =N18/K18 -> 0.96611111
B19: 義大利麵 | D19: 義式蕃茄起司義大利麵 | F19: =VLOOKUP(D19,廠價表!$C$1:$E$39,3,0) -> 50.39 | G19: 3026 | H19: =F19*G19 -> 152480.14 | J19: =VLOOKUP(D19,產線配置圖!$A$2:$C$38,2,0) -> 12 | K19: =VLOOKUP(D19,產線配置圖!$A$2:$C$38,3,0) -> 2000 | L19: =K19/J19 -> 166.66667 | M19: 12 | N19: =G19/W19*60 -> 1797.6238 | O19: =N19/M19 -> 149.80198 | P19: =M19-J19 -> 0 | Q19: =O19-L19 -> -16.864686 | R19: =O19/L19 -> 0.89881188 | T19: 0.56597222 | U19: 0.63611111 | V19: =(T19-U18)*24*60 -> 125 | W19: =(U19-T19)*24*60 -> 101 | AB19: =N19-K19 -> -202.37624 | AC19: =N19/K19 -> 0.89881188
B20: 義大利麵 | D20: 青醬蛤蜊義大利麵 | F20: =VLOOKUP(D20,廠價表!$C$1:$E$39,3,0) -> 50.67 | G20: 1156 | H20: =F20*G20 -> 58574.52 | J20: =VLOOKUP(D20,產線配置圖!$A$2:$C$38,2,0) -> 13 | K20: =VLOOKUP(D20,產線配置圖!$A$2:$C$38,3,0) -> 2000 | L20: =K20/J20 -> 153.84615 | M20: 13 | N20: =G20/W20*60 -> 1926.6667 | O20: =N20/M20 -> 148.20513 | P20: =M20-J20 -> 0 | Q20: =O20-L20 -> -5.6410256 | R20: =O20/L20 -> 0.96333333 | T20: 0.65833333 | U20: 0.68333333 | V20: =(T20-U19)*24*60 -> 32 | W20: =(U20-T20)*24*60 -> 36
H21: =F21*G21 -> 0 | W21: 0
H22: =F22*G22 -> 0 | W22: 0
H23: =F23*G23 -> 0 | W23: =(U23-T23)*24*60 -> 0
H24: =F24*G24 -> 0 | W24: =(U24-T24)*24*60 -> 0
H25: =F25*G25 -> 0 | W25: =(U25-T25)*24*60 -> 0
C26: 4度二組A | D26: 平均 | J26: =AVERAGE(J16:J25) -> 12.6 | K26: =AVERAGE(K16:K25) -> 2021 | L26: =AVERAGE(L16:L25) -> 160.58974 | M26: =AVERAGE(M16:M25) -> 12.6 | N26: =AVERAGE(N16:N25) -> 1897.1532 | O26: =AVERAGE(O16:O25) -> 150.71671 | P26: =M26-J26 -> 0 | Q26: =O26-L26 -> -9.8730314 | R26: =O26/L26 -> 0.93852016 | AB26: =N26-K26 -> -123.84684 | AC26: =N26/K26 -> 0.93872002
A27: 手工三線 (ET-55) | B27: 義大利麵 | D27: 青花椒麻雞肉拌麵 | F27: =VLOOKUP(D27,廠價表!$C$1:$E$39,3,0) -> 49.91 | G27: 3612 | H27: =F27*G27 -> 180274.92 | J27: =VLOOKUP(D27,產線配置圖!$A$2:$C$38,2,0) -> 17 | K27: =VLOOKUP(D27,產線配置圖!$A$2:$C$38,3,0) -> 1565 | L27: =K27/J27 -> 92.058824 | M27: 17 | N27: =G27/W27*60 -> 1297.7246 | O27: =N27/M27 -> 76.336738 | P27: =M27-J27 -> 0 | Q27: =O27-L27 -> -15.722085 | R27: =O27/L27 -> 0.82921697 | S27: =R37 -> 0.85563026 | T27: 0.29027778 | U27: 0.40625 | W27: =(U27-T27)*24*60 -> 167 | AB27: =N27-K27 -> -267.27545 | AC27: =N27/K27 -> 0.82921697 | AD27: =AC37 -> 0.8585546
B28: =VLOOKUP(D28,廠價表!$C$1:$E$39,2,0) -> 義大利麵 | D28: 奶油蒜香雞義大利麵 | F28: =VLOOKUP(D28,廠價表!$C$1:$E$39,3,0) -> 55.13 | G28: 1720 | H28: =F28*G28 -> 94823.6 | J28: =VLOOKUP(D28,產線配置圖!$A$2:$C$38,2,0) -> 18 | K28: =VLOOKUP(D28,產線配置圖!$A$2:$C$38,3,0) -> 1385 | L28: =K28/J28 -> 76.944444 | M28: 18 | N28: =G28/W28*60 -> 1159.5506 | O28: =N28/M28 -> 64.419476 | P28: =M28-J28 -> 0 | Q28: =O28-L28 -> -12.524969 | R28: =O28/L28 -> 0.83722062 | T28: 0.41180556 | U28: 0.47361111 | V28: =(T28-U27)*24*60 -> 8 | W28: =(U28-T28)*24*60 -> 89 | AB28: =N28-K28 -> -225.44944 | AC28: =N28/K28 -> 0.83722062
B29: 義大利麵 | D29: 奶油蒜香雞義大利麵 | F29: =VLOOKUP(D29,廠價表!$C$1:$E$39,3,0) -> 55.13 | G29: 850 | H29: =F29*G29 -> 46860.5 | J29: =VLOOKUP(D29,產線配置圖!$A$2:$C$38,2,0) -> 18 | K29: =VLOOKUP(D29,產線配置圖!$A$2:$C$38,3,0) -> 1385 | L29: =K29/J29 -> 76.944444 | M29: 18 | N29: =G29/W29*60 -> 1342.1053 | O29: =N29/M29 -> 74.561404 | P29: =M29-J29 -> 0 | Q29: =O29-L29 -> -2.3830409 | R29: =O29/L29 -> 0.96902907 | T29: 0.53819444 | U29: 0.56458333 | V29: =(T29-U28)*24*60 -> 93 | W29: =(U29-T29)*24*60 -> 38 | X29: 0.54166667 | Y29: 0.58333333 | AB29: =N29-K29 -> -42.894737 | AC29: =N29/K29 -> 0.96902907
B30: 義大利麵 | D30: 奶油起司蝦仁通心粉 | F30: =VLOOKUP(D30,廠價表!$C$1:$E$39,3,0) -> 47.71 | G30: 2824 | H30: =F30*G30 -> 134733.04 | J30: =VLOOKUP(D30,產線配置圖!$A$2:$C$38,2,0) -> 15 | K30: =VLOOKUP(D30,產線配置圖!$A$2:$C$38,3,0) -> 1500 | L30: =K30/J30 -> 100 | M30: 15 | N30: =G30/W30*60 -> 1210.2857 | O30: =N30/M30 -> 80.685714 | P30: =M30-J30 -> 0 | Q30: =O30-L30 -> -19.314286 | R30: =O30/L30 -> 0.80685714 | T30: 0.57291667 | U30: 0.67013889 | W30: =(U30-T30)*24*60 -> 140
W31: =(U31-T31)*24*60 -> 0
H32: =F32*G32 -> 0 | W32: =(U32-T32)*24*60 -> 0
H33: =F33*G33 -> 0 | W33: =(U33-T33)*24*60 -> 0
H34: =F34*G34 -> 0 | W34: =(U34-T34)*24*60 -> 0
H35: =F35*G35 -> 0 | W35: =(U35-T35)*24*60 -> 0
H36: =F36*G36 -> 0 | W36: =(U36-T36)*24*60 -> 0
C37: 4度二組B | D37: 平均 | J37: =AVERAGE(J27:J36) -> 17 | K37: =AVERAGE(K27:K36) -> 1458.75 | L37: =AVERAGE(L27:L36) -> 86.486928 | M37: =AVERAGE(M27:M36) -> 17 | N37: =AVERAGE(N27:N36) -> 1252.4165 | O37: =AVERAGE(O27:O36) -> 74.000833 | P37: =M37-J37 -> 0 | Q37: =N37-K37 -> -206.33348 | R37: =O37/L37 -> 0.85563026 | AB37: =N37-K37 -> -206.33348 | AC37: =N37/K37 -> 0.8585546
A38: 手工四線 (ET-55) | B38: 義大利麵 | D38: 濃拿坡里義大利麵 | F38: =VLOOKUP(D38,廠價表!$C$1:$E$39,3,0) -> 56.43 | G38: 4253 | H38: =F38*G38 -> 239996.79 | J38: =VLOOKUP(D38,產線配置圖!$A$2:$C$38,2,0) -> 15 | K38: =VLOOKUP(D38,產線配置圖!$A$2:$C$38,3,0) -> 1406 | L38: =K38/J38 -> 93.733333 | M38: 15 | N38: =G38/W38*60 -> 1159.9091 | O38: =N38/M38 -> 77.327273 | P38: =M38-J38 -> 0 | Q38: =O38-L38 -> -16.406061 | R38: =O38/L38 -> 0.8249709 | S38: =R48 -> 0.83340877 | T38: 0.33333333 | U38: 0.48611111 | W38: =(U38-T38)*24*60 -> 220 | AB38: =N38-K38 -> -246.09091 | AC38: =N38/K38 -> 0.8249709 | AD38: =AC48 -> 0.83340877
B39: 義大利麵 | D39: 濃拿坡里義大利麵 | F39: =VLOOKUP(D39,廠價表!$C$1:$E$39,3,0) -> 56.43 | G39: 1085 | H39: =F39*G39 -> 61226.55 | J39: =VLOOKUP(D39,產線配置圖!$A$2:$C$38,2,0) -> 15 | K39: =VLOOKUP(D39,產線配置圖!$A$2:$C$38,3,0) -> 1406 | L39: =K39/J39 -> 93.733333 | M39: 15 | N39: =G39/W39*60 -> 1183.6364 | O39: =N39/M39 -> 78.909091 | P39: =M39-J39 -> 0 | Q39: =O39-L39 -> -14.824242 | R39: =O39/L39 -> 0.84184663 | T39: 0.53819444 | U39: 0.57638889 | V39: =(T39-U38)*24*60 -> 75 | W39: =(U39-T39)*24*60 -> 55 | X39: 0.5 | Y39: 0.54166667 | AB39: =N39-K39 -> -222.36364 | AC39: =N39/K39 -> 0.84184663
W40: =(U40-T40)*24*60 -> 0 | AB40: =N40-K40 -> 0 | AC40: =N40/K40 -> #DIV/0!
...

Sheet 1103總 
B1: 長家廠組合室生產人時性分析
B3: 日期 | D3: 45964 | F3: 訂單量 | G3: ='1103'!E1 -> 56473 | I3: 營業額 | J3: ='1103'!G1 -> 2731807.4
B4: 項目 | D4: 3 | F4: ➀ | H4: ➁ | J4: ③
B5: 人時性 | D5: 組合室 | F5: 全溫層 | H5: 義大利麵 | J5: 袋裝小吃、義麵
D6: 排關平均 | F6: =AVERAGE(D13:J13) -> 115.5849 | H6: =AVERAGE(D13:H13) -> 114.19867 | J6: =AVERAGE(I13:J13) -> 119.05048
D7: 實績平均 | F7: =AVERAGE(D14:J14) -> 102.1865 | H7: =AVERAGE(D14:H14) -> 100.96666 | J7: =AVERAGE(I14:J14) -> 105.2361
D8: 達成率平均 | F8: =AVERAGE(D15:J15) -> 0.88659775 | H8: =AVERAGE(D15:H15) -> 0.8877674 | J8: =AVERAGE(I15:J15) -> 0.88367362 | L8: ※現行日本鮮食廠以達成率80%為基本(即為現行KPI)
B10: 溫層 | D10: 4度C-各編組展開
B11: 編組 | D11: 1 | E11: 2 | F11: 3 | G11: 4 | H11: 5 | I11: 6 | J11: 7
D12: 自動1線 | E12: 自動2線 | F12: 手工3線 | G12: 手工4線 | H12: 手工5線 | I12: 調理包1線 | J12: 調理包2線
B13: 人時性 | C13: 排關 | D13: =VALUE('1103'!L15) -> 146.98643 | E13: =VALUE('1103'!L26) -> 162.27564 | F13: =VALUE('1103'!L37) -> 81.982571 | G13: =VALUE('1103'!L48) -> 93.033333 | H13: =VALUE('1103'!L58) -> 86.7154 | I13: =VALUE('1103'!L69) -> 125.40064 | J13: =VALUE('1103'!L79) -> 112.70032
C14: 實績 | D14: =VALUE('1103'!O15) -> 129.91248 | E14: =VALUE('1103'!O26) -> 141.83473 | F14: =VALUE('1103'!O37) -> 75.920595 | G14: =VALUE('1103'!O48) -> 73.454545 | H14: =VALUE('1103'!O58) -> 83.710935 | I14: =VALUE('1103'!O69) -> 111.49128 | J14: =VALUE('1103'!O79) -> 98.980932
C15: 達成率 | D15: =D14/D13 -> 0.88384001 | E15: =E14/E13 -> 0.87403585 | F15: =F14/F13 -> 0.92605775 | G15: =G14/G13 -> 0.78955083 | H15: =H14/H13 -> 0.96535258 | I15: =I14/I13 -> 0.88908059 | J15: =J14/J13 -> 0.87826664
B16: 作業 時間 | C16: 開始 | D16: ='1103'!T5 -> 0.29027778 | E16: ='1103'!T16 -> 0.28958333 | F16: ='1103'!T27 -> 0.29097222 | G16: ='1103'!T38 -> 0.33333333 | H16: ='1103'!T49 -> 0.29027778 | I16: ='1103'!T59 -> 0.29166667 | J16: ='1103'!T70 -> 0.33819444
C17: 結束 | D17: 0.62916667 | E17: 0.62013889 | F17: 0.57916667 | G17: 0.59722222 | H17: 0.62777778 | I17: 0.625 | J17: 0.50347222
B18: 配置人數 | D18: =VALUE('1103'!M15) -> 13.8 | E18: =VALUE('1103'!M26) -> 12.5 | F18: =VALUE('1103'!M37) -> 15 | G18: =VALUE('1103'!M48) -> 15 | H18: =VALUE('1103'!M58) -> 18.333333 | I18: =VALUE('1103'!M69) -> 12.5 | J18: =VALUE('1103'!M79) -> 13.25
B19: 主要應用設備 | D19: ET-600 | E19: ET-600 | F19: ET-55 | G19: ET-55 | H19: ET-55 | I19: 八爪機 | J19: ET-55
B20: 次要應用設備 | H20: 封口機
B21: 備註

Sheet 1103
A1: 長家廠4度C日報分析 | D1: 總生產量 | E1: =SUM(G5:G79) -> 56473 | F1: 營業額 | G1: =SUM(H5:H79) -> 2731807.4 | H1: 出勤人數 | I1: =M15+M26+M48+M58+M69+M79+M37 -> 100.38333 | J1: 產線配置圖 | M1: 生產實績 | P1: 人時性差異分析 | T1: 日報登錄 | Z1: 分析說明 | AB1: 產能差異分析
A2: 11月03日 星期一 | D2: 人時性 | E2: =AVERAGE(O15,O26,O37,O48,O58,O69,O79) -> 102.1865 | F2: 平均廠價 | G2: =G1/E1 -> 48.37369 | H2: 多次生產數 | I2: =COUNT(I5:I79) -> 0
A3: 線別 | B3: 品類 | D3: 品名 | F3: 廠價 | G3: 生產量 | H3: 營收 | I3: 多次 生產 | J3: 人數 | K3: 產能/時 | L3: 人時性 | M3: 人數 | N3: 產能/時 | O3: 人時性 | P3: 人數 | Q3: 人時性 | R3: 達成率 | S3: 達成率平均 | T3: 生產時間 | V3: 前置、換線時間/分 | W3: 稼動時間/分 | X3: 休息時間 | Z3: (長家回填) | AB3: 產能/時 | AC3: 達成率 | AD3: 達成率平均
T4: 開始 | U4: 結束 | X4: 開始 | Y4: 結束
A5: 自動一線 (ET-600) | B5: =VLOOKUP(D5,廠價表!$C$1:$E$39,2,0) -> 義大利麵 | D5: 白酒蛤蜊義大利麵 | F5: =VLOOKUP(D5,廠價表!$C$1:$E$39,3,0) -> 57.21 | G5: 1799 | H5: =F5*G5 -> 102920.79 | J5: =VLOOKUP(D5,產線配置圖!$A$2:$C$38,2,0) -> 13 | K5: =VLOOKUP(D5,產線配置圖!$A$2:$C$38,3,0) -> 2105 | L5: =K5/J5 -> 161.92308 | M5: 13 | N5: =G5/W5*60 -> 1927.5 | O5: =N5/M5 -> 148.26923 | P5: =M5-J5 -> 0 | Q5: =O5-L5 -> -13.653846 | R5: =O5/L5 -> 0.91567696 | S5: =R15 -> 0.88384001 | T5: 0.29027778 | U5: 0.32916667 | W5: =(U5-T5)*24*60 -> 56 | AB5: =N5-K5 -> -177.5 | AC5: =N5/K5 -> 0.91567696 | AD5: =AC15 -> 0.88844924
B6: =VLOOKUP(D6,廠價表!$C$1:$E$39,2,0) -> 義大利麵 | D6: 青醬蛤蜊義大利麵 | F6: =VLOOKUP(D6,廠價表!$C$1:$E$39,3,0) -> 50.67 | G6: 1398 | H6: =F6*G6 -> 70836.66 | J6: =VLOOKUP(D6,產線配置圖!$A$2:$C$38,2,0) -> 13 | K6: =VLOOKUP(D6,產線配置圖!$A$2:$C$38,3,0) -> 2000 | L6: =K6/J6 -> 153.84615 | M6: 13 | N6: =G6/W6*60 -> 1784.6809 | O6: =N6/M6 -> 137.28314 | P6: =M6-J6 -> 0 | Q6: =O6-L6 -> -16.563011 | R6: =O6/L6 -> 0.89234043 | T6: 0.33680556 | U6: 0.36944444 | V6: =(T6-U5)*24*60 -> 11 | W6: =(U6-T6)*24*60 -> 47 | AB6: =N6-K6 -> -215.31915 | AC6: =N6/K6 -> 0.89234043
B7: =VLOOKUP(D7,廠價表!$C$1:$E$39,2,0) -> 義大利麵 | D7: 韓式起司炸雞義大利麵 | F7: =VLOOKUP(D7,廠價表!$C$1:$E$39,3,0) -> 57.21 | G7: 2432 | H7: =F7*G7 -> 139134.72 | J7: =VLOOKUP(D7,產線配置圖!$A$2:$C$38,2,0) -> 17 | K7: =VLOOKUP(D7,產線配置圖!$A$2:$C$38,3,0) -> 1895 | L7: =K7/J7 -> 111.47059 | M7: 17 | N7: =G7/W7*60 -> 1870.7692 | O7: =N7/M7 -> 110.04525 | P7: =M7-J7 -> 0 | Q7: =O7-L7 -> -1.4253394 | R7: =O7/L7 -> 0.98721331 | T7: 0.37638889 | U7: 0.43055556 | V7: =(T7-U6)*24*60 -> 10 | W7: =(U7-T7)*24*60 -> 78 | AB7: =N7-K7 -> -24.230769 | AC7: =N7/K7 -> 0.98721331
B8: =VLOOKUP(D8,廠價表!$C$1:$E$39,2,0) -> 義大利麵 | D8: 奶油培根義大利麵 | F8: =VLOOKUP(D8,廠價表!$C$1:$E$39,3,0) -> 49.14 | G8: 1880 | H8: =F8*G8 -> 92383.2 | J8: =VLOOKUP(D8,產線配置圖!$A$2:$C$38,2,0) -> 13 | K8: =VLOOKUP(D8,產線配置圖!$A$2:$C$38,3,0) -> 2000 | L8: =K8/J8 -> 153.84615 | M8: 13 | N8: =G8/W8*60 -> 1819.3548 | O8: =N8/M8 -> 139.95037 | P8: =M8-J8 -> 0 | Q8: =O8-L8 -> -13.895782 | R8: =O8/L8 -> 0.90967742 | T8: 0.43611111 | U8: 0.47916667 | V8: =(T8-U7)*24*60 -> 8 | W8: =(U8-T8)*24*60 -> 62 | AB8: =N8-K8 -> -180.64516 | AC8: =N8/K8 -> 0.90967742
B9: =VLOOKUP(D9,廠價表!$C$1:$E$39,2,0) -> 義大利麵 | D9: 奶油培根義大利麵 | F9: =VLOOKUP(D9,廠價表!$C$1:$E$39,3,0) -> 49.14 | G9: 3162 | H9: =F9*G9 -> 155380.68 | J9: =VLOOKUP(D9,產線配置圖!$A$2:$C$38,2,0) -> 13 | K9: =VLOOKUP(D9,產線配置圖!$A$2:$C$38,3,0) -> 2000 | L9: =K9/J9 -> 153.84615 | M9: 13 | N9: =G9/W9*60 -> 1482.1875 | O9: =N9/M9 -> 114.01442 | P9: =M9-J9 -> 0 | Q9: =O9-L9 -> -39.831731 | R9: =O9/L9 -> 0.74109375 | T9: 0.54027778 | U9: 0.62916667 | V9: =(T9-U8)*24*60 -> 88 | W9: =(U9-T9)*24*60 -> 128 | X9: 0.48611111 | Y9: 0.52777778 | Z9: 14:08~14:42待麵，停線
W10: =(U10-T10)*24*60 -> 0
H11: =F11*G11 -> 0 | W11: =(U11-T11)*24*60 -> 0
H12: =F12*G12 -> 0 | W12: =(U12-T12)*24*60 -> 0
H13: =F13*G13 -> 0 | W13: =(U13-T13)*24*60 -> 0
H14: =F14*G14 -> 0 | W14: =(U14-T14)*24*60 -> 0
C15: 4度一組 | D15: 平均 | J15: =AVERAGE(J5:J14) -> 13.8 | K15: =AVERAGE(K5:K14) -> 2000 | L15: =AVERAGE(L5:L14) -> 146.98643 | M15: =AVERAGE(M5:M14) -> 13.8 | N15: =AVERAGE(N5:N14) -> 1776.8985 | O15: =AVERAGE(O5:O14) -> 129.91248 | P15: =M15-J15 -> 0 | Q15: =O15-L15 -> -17.073942 | R15: =O15/L15 -> 0.88384001 | AB15: =N15-K15 -> -223.10152 | AC15: =N15/K15 -> 0.88844924
A16: 自動二線 (ET-600) | B16: 義大利麵 | D16: 白酒蛤蜊義大利麵 | F16: =VLOOKUP(D16,廠價表!$C$1:$E$39,3,0) -> 57.21 | G16: 1749 | H16: =F16*G16 -> 100060.29 | J16: =VLOOKUP(D16,產線配置圖!$A$2:$C$38,2,0) -> 13 | K16: =VLOOKUP(D16,產線配置圖!$A$2:$C$38,3,0) -> 2105 | L16: =K16/J16 -> 161.92308 | M16: 13 | N16: =G16/W16*60 -> 1873.9286 | O16: =N16/M16 -> 144.14835 | P16: =M16-J16 -> 0 | Q16: =O16-L16 -> -17.774725 | R16: =O16/L16 -> 0.89022735 | S16: =R26 -> 0.87403585 | T16: 0.28958333 | U16: 0.32847222 | W16: =(U16-T16)*24*60 -> 56 | AB16: =N16-K16 -> -231.07143 | AC16: =N16/K16 -> 0.89022735 | AD16: =AC26 -> 0.87663581
B17: 義大利麵 | D17: 青醬蛤蜊義大利麵 | F17: =VLOOKUP(D17,廠價表!$C$1:$E$39,3,0) -> 50.67 | G17: 4009 | H17: =F17*G17 -> 203136.03 | J17: =VLOOKUP(D17,產線配置圖!$A$2:$C$38,2,0) -> 13 | K17: =VLOOKUP(D17,產線配置圖!$A$2:$C$38,3,0) -> 2000 | L17: =K17/J17 -> 153.84615 | M17: 13 | N17: =G17/W17*60 -> 1987.9339 | O17: =N17/M17 -> 152.91799 | P17: =M17-J17 -> 0 | Q17: =O17-L17 -> -0.92816275 | R17: =O17/L17 -> 0.99396694 | T17: 0.33611111 | U17: 0.42013889 | V17: =(T17-U16)*24*60 -> 11 | W17: =(U17-T17)*24*60 -> 121 | AB17: =N17-K17 -> -12.066116 | AC17: =N17/K17 -> 0.99396694
B18: 義大利麵 | D18: 義式蕃茄起司義大利麵 | F18: =VLOOKUP(D18,廠價表!$C$1:$E$39,3,0) -> 50.39 | G18: 2349 | H18: =F18*G18 -> 118366.11 | J18: =VLOOKUP(D18,產線配置圖!$A$2:$C$38,2,0) -> 12 | K18: =VLOOKUP(D18,產線配置圖!$A$2:$C$38,3,0) -> 2000 | L18: =K18/J18 -> 166.66667 | M18: 12 | N18: =G18/W18*60 -> 1879.2 | O18: =N18/M18 -> 156.6 | P18: =M18-J18 -> 0 | Q18: =O18-L18 -> -10.066667 | R18: =O18/L18 -> 0.9396 | T18: 0.42708333 | U18: 0.47916667 | V18: =(T18-U17)*24*60 -> 10 | W18: =(U18-T18)*24*60 -> 75 | AB18: =N18-K18 -> -120.8 | AC18: =N18/K18 -> 0.9396
B19: 義大利麵 | D19: 義式蕃茄起司義大利麵 | F19: =VLOOKUP(D19,廠價表!$C$1:$E$39,3,0) -> 50.39 | G19: 2569 | H19: =F19*G19 -> 129451.91 | J19: =VLOOKUP(D19,產線配置圖!$A$2:$C$38,2,0) -> 12 | K19: =VLOOKUP(D19,產線配置圖!$A$2:$C$38,3,0) -> 2000 | L19: =K19/J19 -> 166.66667 | M19: 12 | N19: =G19/W19*60 -> 1364.0708 | O19: =N19/M19 -> 113.67257 | P19: =M19-J19 -> 0 | Q19: =O19-L19 -> -52.9941 | R19: =O19/L19 -> 0.6820354 | T19: 0.54166667 | U19: 0.62013889 | V19: =(T19-U18)*24*60 -> 90 | W19: =(U19-T19)*24*60 -> 113 | X19: 0.5 | Y19: 0.54166667 | Z19: 14:08~14:42待麵，停線 | AB19: =N19-K19 -> -635.9292 | AC19: =N19/K19 -> 0.6820354
W20: =(U20-T20)*24*60 -> 0
H21: =F21*G21 -> 0 | W21: 0
H22: =F22*G22 -> 0 | W22: 0
H23: =F23*G23 -> 0 | W23: =(U23-T23)*24*60 -> 0
H24: =F24*G24 -> 0 | W24: =(U24-T24)*24*60 -> 0
H25: =F25*G25 -> 0 | W25: =(U25-T25)*24*60 -> 0
C26: 4度二組A | D26: 平均 | J26: =AVERAGE(J16:J25) -> 12.5 | K26: =AVERAGE(K16:K25) -> 2026.25 | L26: =AVERAGE(L16:L25) -> 162.27564 | M26: =AVERAGE(M16:M25) -> 12.5 | N26: =AVERAGE(N16:N25) -> 1776.2833 | O26: =AVERAGE(O16:O25) -> 141.83473 | P26: =M26-J26 -> 0 | Q26: =O26-L26 -> -20.440914 | R26: =O26/L26 -> 0.87403585 | AB26: =N26-K26 -> -249.96669 | AC26: =N26/K26 -> 0.87663581
A27: 手工三線 (ET-55) | B27: 義大利麵 | D27: 青花椒麻雞肉拌麵 | F27: =VLOOKUP(D27,廠價表!$C$1:$E$39,3,0) -> 49.91 | G27: 3657 | H27: =F27*G27 -> 182520.87 | J27: =VLOOKUP(D27,產線配置圖!$A$2:$C$38,2,0) -> 17 | K27: =VLOOKUP(D27,產線配置圖!$A$2:$C$38,3,0) -> 1565 | L27: =K27/J27 -> 92.058824 | M27: 15 | N27: =G27/W27*60 -> 1246.7045 | O27: =N27/M27 -> 83.113636 | P27: =M27-J27 -> -2 | Q27: =O27-L27 -> -8.9451872 | R27: =O27/L27 -> 0.90283183 | S27: =R37 -> 0.92605775 | T27: 0.29097222 | U27: 0.41319444 | W27: =(U27-T27)*24*60 -> 176 | AB27: =N27-K27 -> -318.29545 | AC27: =N27/K27 -> 0.79661632 | AD27: =AC37 -> 0.78810306
B28: =VLOOKUP(D28,廠價表!$C$1:$E$39,2,0) -> 義大利麵 | D28: 奶油蒜香雞義大利麵 | F28: =VLOOKUP(D28,廠價表!$C$1:$E$39,3,0) -> 55.13 | G28: 1542 | H28: =F28*G28 -> 85010.46 | J28: =VLOOKUP(D28,產線配置圖!$A$2:$C$38,2,0) -> 18 | K28: =VLOOKUP(D28,產線配置圖!$A$2:$C$38,3,0) -> 1385 | L28: =K28/J28 -> 76.944444 | M28: 15 | N28: =G28/W28*60 -> 1142.2222 | O28: =N28/M28 -> 76.148148 | P28: =M28-J28 -> -3 | Q28: =O28-L28 -> -0.7962963 | R28: =O28/L28 -> 0.98965102 | T28: 0.42361111 | U28: 0.47986111 | V28: =(T28-U27)*24*60 -> 15 | W28: =(U28-T28)*24*60 -> 81 | AB28: =N28-K28 -> -242.77778 | AC28: =N28/K28 -> 0.82470919
B29: 義大利麵 | D29: 奶油蒜香雞義大利麵 | F29: =VLOOKUP(D29,廠價表!$C$1:$E$39,3,0) -> 55.13 | G29: 1096 | H29: =F29*G29 -> 60422.48 | J29: =VLOOKUP(D29,產線配置圖!$A$2:$C$38,2,0) -> 18 | K29: =VLOOKUP(D29,產線配置圖!$A$2:$C$38,3,0) -> 1385 | L29: =K29/J29 -> 76.944444 | M29: 15 | N29: =G29/W29*60 -> 1027.5 | O29: =N29/M29 -> 68.5 | P29: =M29-J29 -> -3 | Q29: =O29-L29 -> -8.4444444 | R29: =O29/L29 -> 0.89025271 | T29: 0.53472222 | U29: 0.57916667 | V29: =(T29-U28)*24*60 -> 79 | W29: =(U29-T29)*24*60 -> 64 | X29: 0.48611111 | Y29: 0.52777778 | AB29: =N29-K29 -> -357.5 | AC29: =N29/K29 -> 0.74187726
W30: =(U30-T30)*24*60 -> 0
W31: =(U31-T31)*24*60 -> 0
H32: =F32*G32 -> 0 | W32: =(U32-T32)*24*60 -> 0
H33: =F33*G33 -> 0 | W33: =(U33-T33)*24*60 -> 0
H34: =F34*G34 -> 0 | W34: =(U34-T34)*24*60 -> 0
H35: =F35*G35 -> 0 | W35: =(U35-T35)*24*60 -> 0
H36: =F36*G36 -> 0 | W36: =(U36-T36)*24*60 -> 0
C37: 4度二組B | D37: 平均 | J37: =AVERAGE(J27:J36) -> 17.666667 | K37: =AVERAGE(K27:K36) -> 1445 | L37: =AVERAGE(L27:L36) -> 81.982571 | M37: =AVERAGE(M27:M36) -> 15 | N37: =AVERAGE(N27:N36) -> 1138.8089 | O37: =AVERAGE(O27:O36) -> 75.920595 | P37: =M37-J37 -> -2.6666667 | Q37: =N37-K37 -> -306.19108 | R37: =O37/L37 -> 0.92605775 | AB37: =N37-K37 -> -306.19108 | AC37: =N37/K37 -> 0.78810306
A38: 手工四線 (ET-55) | B38: 義大利麵 | D38: 濃拿坡里義大利麵 | F38: =VLOOKUP(D38,廠價表!$C$1:$E$39,3,0) -> 56.43 | G38: 2760 | H38: =F38*G38 -> 155746.8 | J38: =VLOOKUP(D38,產線配置圖!$A$2:$C$38,2,0) -> 15 | K38: =VLOOKUP(D38,產線配置圖!$A$2:$C$38,3,0) -> 1406 | L38: =K38/J38 -> 93.733333 | M38: 15 | N38: =G38/W38*60 -> 1003.6364 | O38: =N38/M38 -> 66.909091 | P38: =M38-J38 -> 0 | Q38: =O38-L38 -> -26.824242 | R38: =O38/L38 -> 0.71382387 | S38: =R48 -> 0.78955083 | T38: 0.33333333 | U38: 0.44791667 | W38: =(U38-T38)*24*60 -> 165 | Z38: 9:14~9:37蓋子不足停線貼標，4人補封膜216盒 | AB38: =N38-K38 -> -402.36364 | AC38: =N38/K38 -> 0.71382387 | AD38: =AC48 -> 0.78955083
B39: 義大利麵 | D39: 焗烤明太子筆尖麵 | F39: =VLOOKUP(D39,廠價表!$C$1:$E$39,3,0) -> 57.3 | G39: 2500 | H39: =F39*G39 -> 143250 | J39: =VLOOKUP(D39,產線配置圖!$A$2:$C$38,2,0) -> 15 | K39: =VLOOKUP(D39,產線配置圖!$A$2:$C$38,3,0) -> 1385 | L39: =K39/J39 -> 92.333333 | M39: 15 | N39: =G39/W39*60 -> 1200 | O39: =N39/M39 -> 80 | P39: =M39-J39 -> 0 | Q39: =O39-L39 -> -12.333333 | R39: =O39/L39 -> 0.86642599 | T39: 0.51041667 | U39: 0.59722222 | V39: =(T39-U38)*24*60 -> 90 | W39: =(U39-T39)*24*60 -> 125 | X39: 0.45833333 | Y39: 0.5 | AB39: =N39-K39 -> -185 | AC39: =N39/K39 -> 0.86642599
W40: =(U40-T40)*24*60 -> 0 | AB40: =N40-K40 -> 0 | AC40: =N40/K40 -> #DIV/0!
...

Sheet 1104總
B1: 長家廠組合室生產人時性分析
B3: 日期 | D3: 45965 | F3: 訂單量 | G3: ='1104'!E1 -> 53251 | I3: 營業額 | J3: ='1104'!G1 -> 2563731
B4: 項目 | D4: 3 | F4: ➀ | H4: ➁ | J4: ③
B5: 人時性 | D5: 組合室 | F5: 全溫層 | H5: 義大利麵 | J5: 袋裝小吃、義麵
D6: 排關平均 | F6: =AVERAGE(D13:J13) -> 114.80613 | H6: =AVERAGE(D13:H13) -> 114.19867 | J6: =AVERAGE(I13:J13) -> 116.32479
D7: 實績平均 | F7: =AVERAGE(D14:J14) -> 103.60219 | H7: =AVERAGE(D14:H14) -> 105.01526 | J7: =AVERAGE(I14:J14) -> 100.06951
D8: 達成率平均 | F8: =AVERAGE(D15:J15) -> 0.89969228 | H8: =AVERAGE(D15:H15) -> 0.91690406 | J8: =AVERAGE(I15:J15) -> 0.85666282 | L8: ※現行日本鮮食廠以達成率80%為基本(即為現行KPI)
B10: 溫層 | D10: 4度C-各編組展開
B11: 編組 | D11: 1 | E11: 2 | F11: 3 | G11: 4 | H11: 5 | I11: 6 | J11: 7
D12: 自動1線 | E12: 自動2線 | F12: 手工3線 | G12: 手工4線 | H12: 手工5線 | I12: 調理包1線 | J12: 調理包2線
B13: 人時性 | C13: 排關 | D13: =VALUE('1104'!L15) -> 146.98643 | E13: =VALUE('1104'!L26) -> 162.27564 | F13: =VALUE('1104'!L37) -> 81.982571 | G13: =VALUE('1104'!L48) -> 93.033333 | H13: =VALUE('1104'!L58) -> 86.7154 | I13: =VALUE('1104'!L69) -> 126.40385 | J13: =VALUE('1104'!L79) -> 106.24573
C14: 實績 | D14: =VALUE('1104'!O15) -> 136.41259 | E14: =VALUE('1104'!O26) -> 152.03055 | F14: =VALUE('1104'!O37) -> 76.008459 | G14: =VALUE('1104'!O48) -> 76.433333 | H14: =VALUE('1104'!O58) -> 84.191364 | I14: =VALUE('1104'!O69) -> 113.53262 | J14: =VALUE('1104'!O79) -> 86.606406
C15: 達成率 | D15: =D14/D13 -> 0.92806252 | E15: =E14/E13 -> 0.93686611 | F15: =F14/F13 -> 0.92712949 | G15: =G14/G13 -> 0.82156933 | H15: =H14/H13 -> 0.97089287 | I15: =I14/I13 -> 0.89817374 | J15: =J14/J13 -> 0.8151519
B16: 作業 時間 | C16: 開始 | D16: ='1104'!T5 -> 0.29027778 | E16: ='1104'!T16 -> 0.29027778 | F16: ='1104'!T27 -> 0.28888889 | G16: ='1104'!T38 -> 0.33333333 | H16: ='1104'!T49 -> 0.29166667 | I16: ='1104'!T59 -> 0.29444444 | J16: ='1104'!T70 -> 0.33680556
C17: 結束 | D17: 0.60833333 | E17: 0.59652778 | F17: 0.55069444 | G17: 0.47916667 | H17: 0.61875 | I17: 0.61944444 | J17: 0.60416667
B18: 配置人數 | D18: =VALUE('1104'!M15) -> 13.8 | E18: =VALUE('1104'!M26) -> 12.5 | F18: =VALUE('1104'!M37) -> 16.666667 | G18: =VALUE('1104'!M48) -> 15 | H18: =VALUE('1104'!M58) -> 18.333333 | I18: =VALUE('1104'!M69) -> 12.4 | J18: =VALUE('1104'!M79) -> 13.466667
B19: 主要應用設備 | D19: ET-600 | E19: ET-600 | F19: ET-55 | G19: ET-55 | H19: ET-55 | I19: 八爪機 | J19: ET-55
B20: 次要應用設備 | H20: 封口機
B21: 備註

Sheet 1104
A1: 長家廠4度C日報分析 | D1: 總生產量 | E1: =SUM(G5:G79) -> 53251 | F1: 營業額 | G1: =SUM(H5:H79) -> 2563731 | H1: 出勤人數 | I1: =M15+M26+M48+M58+M69+M79+M37 -> 102.16667 | J1: 產線配置圖 | M1: 生產實績 | P1: 人時性差異分析 | T1: 日報登錄 | Z1: 分析說明 | AB1: 產能差異分析
A2: 11月04日 星期二 | D2: 人時性 | E2: =AVERAGE(O15,O26,O37,O48,O58,O69,O79) -> 103.60219 | F2: 平均廠價 | G2: =G1/E1 -> 48.144278 | H2: 多次生產數 | I2: =COUNT(I5:I79) -> 0
A3: 線別 | B3: 品類 | D3: 品名 | F3: 廠價 | G3: 生產量 | H3: 營收 | I3: 多次 生產 | J3: 人數 | K3: 產能/時 | L3: 人時性 | M3: 人數 | N3: 產能/時 | O3: 人時性 | P3: 人數 | Q3: 人時性 | R3: 達成率 | S3: 達成率平均 | T3: 生產時間 | V3: 前置、換線時間/分 | W3: 稼動時間/分 | X3: 休息時間 | Z3: (長家回填) | AB3: 產能/時 | AC3: 達成率 | AD3: 達成率平均
T4: 開始 | U4: 結束 | X4: 開始 | Y4: 結束
A5: 自動一線 (ET-600) | B5: =VLOOKUP(D5,廠價表!$C$1:$E$39,2,0) -> 義大利麵 | D5: 白酒蛤蜊義大利麵 | F5: =VLOOKUP(D5,廠價表!$C$1:$E$39,3,0) -> 57.21 | G5: 1870 | H5: =F5*G5 -> 106982.7 | J5: =VLOOKUP(D5,產線配置圖!$A$2:$C$38,2,0) -> 13 | K5: =VLOOKUP(D5,產線配置圖!$A$2:$C$38,3,0) -> 2105 | L5: =K5/J5 -> 161.92308 | M5: 13 | N5: =G5/W5*60 -> 1780.9524 | O5: =N5/M5 -> 136.99634 | P5: =M5-J5 -> 0 | Q5: =O5-L5 -> -24.92674 | R5: =O5/L5 -> 0.84605814 | S5: =R15 -> 0.92806252 | T5: 0.29027778 | U5: 0.33402778 | W5: =(U5-T5)*24*60 -> 63 | AB5: =N5-K5 -> -324.04762 | AC5: =N5/K5 -> 0.84605814 | AD5: =AC15 -> 0.92914773
B6: =VLOOKUP(D6,廠價表!$C$1:$E$39,2,0) -> 義大利麵 | D6: 青醬蛤蜊義大利麵 | F6: =VLOOKUP(D6,廠價表!$C$1:$E$39,3,0) -> 50.67 | G6: 1109 | H6: =F6*G6 -> 56193.03 | J6: =VLOOKUP(D6,產線配置圖!$A$2:$C$38,2,0) -> 13 | K6: =VLOOKUP(D6,產線配置圖!$A$2:$C$38,3,0) -> 2000 | L6: =K6/J6 -> 153.84615 | M6: 13 | N6: =G6/W6*60 -> 1901.1429 | O6: =N6/M6 -> 146.24176 | P6: =M6-J6 -> 0 | Q6: =O6-L6 -> -7.6043956 | R6: =O6/L6 -> 0.95057143 | T6: 0.34027778 | U6: 0.36458333 | V6: =(T6-U5)*24*60 -> 9 | W6: =(U6-T6)*24*60 -> 35 | AB6: =N6-K6 -> -98.857143 | AC6: =N6/K6 -> 0.95057143
B7: =VLOOKUP(D7,廠價表!$C$1:$E$39,2,0) -> 義大利麵 | D7: 韓式起司炸雞義大利麵 | F7: =VLOOKUP(D7,廠價表!$C$1:$E$39,3,0) -> 57.21 | G7: 2256 | H7: =F7*G7 -> 129065.76 | J7: =VLOOKUP(D7,產線配置圖!$A$2:$C$38,2,0) -> 17 | K7: =VLOOKUP(D7,產線配置圖!$A$2:$C$38,3,0) -> 1895 | L7: =K7/J7 -> 111.47059 | M7: 17 | N7: =G7/W7*60 -> 1804.8 | O7: =N7/M7 -> 106.16471 | P7: =M7-J7 -> 0 | Q7: =O7-L7 -> -5.3058824 | R7: =O7/L7 -> 0.95240106 | T7: 0.37083333 | U7: 0.42291667 | V7: =(T7-U6)*24*60 -> 9 | W7: =(U7-T7)*24*60 -> 75 | AB7: =N7-K7 -> -90.2 | AC7: =N7/K7 -> 0.95240106
B8: =VLOOKUP(D8,廠價表!$C$1:$E$39,2,0) -> 義大利麵 | D8: 奶油培根義大利麵 | F8: =VLOOKUP(D8,廠價表!$C$1:$E$39,3,0) -> 49.14 | G8: 2316 | H8: =F8*G8 -> 113808.24 | J8: =VLOOKUP(D8,產線配置圖!$A$2:$C$38,2,0) -> 13 | K8: =VLOOKUP(D8,產線配置圖!$A$2:$C$38,3,0) -> 2000 | L8: =K8/J8 -> 153.84615 | M8: 13 | N8: =G8/W8*60 -> 1903.5616 | O8: =N8/M8 -> 146.42782 | P8: =M8-J8 -> 0 | Q8: =O8-L8 -> -7.4183351 | R8: =O8/L8 -> 0.95178082 | T8: 0.42847222 | U8: 0.47916667 | V8: =(T8-U7)*24*60 -> 8 | W8: =(U8-T8)*24*60 -> 73 | AB8: =N8-K8 -> -96.438356 | AC8: =N8/K8 -> 0.95178082
B9: =VLOOKUP(D9,廠價表!$C$1:$E$39,2,0) -> 義大利麵 | D9: 奶油培根義大利麵 | F9: =VLOOKUP(D9,廠價表!$C$1:$E$39,3,0) -> 49.14 | G9: 3105 | H9: =F9*G9 -> 152579.7 | J9: =VLOOKUP(D9,產線配置圖!$A$2:$C$38,2,0) -> 13 | K9: =VLOOKUP(D9,產線配置圖!$A$2:$C$38,3,0) -> 2000 | L9: =K9/J9 -> 153.84615 | M9: 13 | N9: =G9/W9*60 -> 1901.0204 | O9: =N9/M9 -> 146.23234 | P9: =M9-J9 -> 0 | Q9: =O9-L9 -> -7.6138148 | R9: =O9/L9 -> 0.9505102 | T9: 0.54027778 | U9: 0.60833333 | V9: =(T9-U8)*24*60 -> 88 | W9: =(U9-T9)*24*60 -> 98 | X9: 0.48611111 | Y9: 0.52777778 | AB9: =N9-K9 -> -98.979592 | AC9: =N9/K9 -> 0.9505102
W10: =(U10-T10)*24*60 -> 0
H11: =F11*G11 -> 0 | W11: =(U11-T11)*24*60 -> 0
H12: =F12*G12 -> 0 | W12: =(U12-T12)*24*60 -> 0
H13: =F13*G13 -> 0 | W13: =(U13-T13)*24*60 -> 0
H14: =F14*G14 -> 0 | W14: =(U14-T14)*24*60 -> 0
C15: 4度一組 | D15: 平均 | J15: =AVERAGE(J5:J14) -> 13.8 | K15: =AVERAGE(K5:K14) -> 2000 | L15: =AVERAGE(L5:L14) -> 146.98643 | M15: =AVERAGE(M5:M14) -> 13.8 | N15: =AVERAGE(N5:N14) -> 1858.2955 | O15: =AVERAGE(O5:O14) -> 136.41259 | P15: =M15-J15 -> 0 | Q15: =O15-L15 -> -10.573834 | R15: =O15/L15 -> 0.92806252 | AB15: =N15-K15 -> -141.70454 | AC15: =N15/K15 -> 0.92914773
A16: 自動二線 (ET-600) | B16: 義大利麵 | D16: 白酒蛤蜊義大利麵 | F16: =VLOOKUP(D16,廠價表!$C$1:$E$39,3,0) -> 57.21 | G16: 1484 | H16: =F16*G16 -> 84899.64 | J16: =VLOOKUP(D16,產線配置圖!$A$2:$C$38,2,0) -> 13 | K16: =VLOOKUP(D16,產線配置圖!$A$2:$C$38,3,0) -> 2105 | L16: =K16/J16 -> 161.92308 | M16: 13 | N16: =G16/W16*60 -> 1817.1429 | O16: =N16/M16 -> 139.78022 | P16: =M16-J16 -> 0 | Q16: =O16-L16 -> -22.142857 | R16: =O16/L16 -> 0.86325076 | S16: =R26 -> 0.93686611 | T16: 0.29027778 | U16: 0.32430556 | W16: =(U16-T16)*24*60 -> 49 | AB16: =N16-K16 -> -287.85714 | AC16: =N16/K16 -> 0.86325076 | AD16: =AC26 -> 0.93597931
B17: 義大利麵 | D17: 青醬蛤蜊義大利麵 | F17: =VLOOKUP(D17,廠價表!$C$1:$E$39,3,0) -> 50.67 | G17: 3806 | H17: =F17*G17 -> 192850.02 | J17: =VLOOKUP(D17,產線配置圖!$A$2:$C$38,2,0) -> 13 | K17: =VLOOKUP(D17,產線配置圖!$A$2:$C$38,3,0) -> 2000 | L17: =K17/J17 -> 153.84615 | M17: 13 | N17: =G17/W17*60 -> 1935.2542 | O17: =N17/M17 -> 148.86571 | P17: =M17-J17 -> 0 | Q17: =O17-L17 -> -4.9804433 | R17: =O17/L17 -> 0.96762712 | T17: 0.33194444 | U17: 0.41388889 | V17: =(T17-U16)*24*60 -> 11 | W17: =(U17-T17)*24*60 -> 118 | AB17: =N17-K17 -> -64.745763 | AC17: =N17/K17 -> 0.96762712
B18: 義大利麵 | D18: 義式蕃茄起司義大利麵 | F18: =VLOOKUP(D18,廠價表!$C$1:$E$39,3,0) -> 50.39 | G18: 2502 | H18: =F18*G18 -> 126075.78 | J18: =VLOOKUP(D18,產線配置圖!$A$2:$C$38,2,0) -> 12 | K18: =VLOOKUP(D18,產線配置圖!$A$2:$C$38,3,0) -> 2000 | L18: =K18/J18 -> 166.66667 | M18: 12 | N18: =G18/W18*60 -> 1876.5 | O18: =N18/M18 -> 156.375 | P18: =M18-J18 -> 0 | Q18: =O18-L18 -> -10.291667 | R18: =O18/L18 -> 0.93825 | T18: 0.42361111 | U18: 0.47916667 | V18: =(T18-U17)*24*60 -> 14 | W18: =(U18-T18)*24*60 -> 80 | Z18: 10:18-10:19玉取機停麵 | AB18: =N18-K18 -> -123.5 | AC18: =N18/K18 -> 0.93825
B19: 義大利麵 | D19: 義式蕃茄起司義大利麵 | F19: =VLOOKUP(D19,廠價表!$C$1:$E$39,3,0) -> 50.39 | G19: 2577 | H19: =F19*G19 -> 129855.03 | J19: =VLOOKUP(D19,產線配置圖!$A$2:$C$38,2,0) -> 12 | K19: =VLOOKUP(D19,產線配置圖!$A$2:$C$38,3,0) -> 2000 | L19: =K19/J19 -> 166.66667 | M19: 12 | N19: =G19/W19*60 -> 1957.2152 | O19: =N19/M19 -> 163.10127 | P19: =M19-J19 -> 0 | Q19: =O19-L19 -> -3.5654008 | R19: =O19/L19 -> 0.97860759 | T19: 0.54166667 | U19: 0.59652778 | V19: =(T19-U18)*24*60 -> 90 | W19: =(U19-T19)*24*60 -> 79 | X19: 0.48611111 | Y19: 0.52777778 | AB19: =N19-K19 -> -42.78481 | AC19: =N19/K19 -> 0.97860759
W20: =(U20-T20)*24*60 -> 0
H21: =F21*G21 -> 0 | W21: 0
H22: =F22*G22 -> 0 | W22: 0
H23: =F23*G23 -> 0 | W23: =(U23-T23)*24*60 -> 0
H24: =F24*G24 -> 0 | W24: =(U24-T24)*24*60 -> 0
H25: =F25*G25 -> 0 | W25: =(U25-T25)*24*60 -> 0
C26: 4度二組A | D26: 平均 | J26: =AVERAGE(J16:J25) -> 12.5 | K26: =AVERAGE(K16:K25) -> 2026.25 | L26: =AVERAGE(L16:L25) -> 162.27564 | M26: =AVERAGE(M16:M25) -> 12.5 | N26: =AVERAGE(N16:N25) -> 1896.5281 | O26: =AVERAGE(O16:O25) -> 152.03055 | P26: =M26-J26 -> 0 | Q26: =O26-L26 -> -10.245092 | R26: =O26/L26 -> 0.93686611 | AB26: =N26-K26 -> -129.72193 | AC26: =N26/K26 -> 0.93597931
A27: 手工三線 (ET-55) | B27: 義大利麵 | D27: 青花椒麻雞肉拌麵 | F27: =VLOOKUP(D27,廠價表!$C$1:$E$39,3,0) -> 49.91 | G27: 3497 | H27: =F27*G27 -> 174535.27 | J27: =VLOOKUP(D27,產線配置圖!$A$2:$C$38,2,0) -> 17 | K27: =VLOOKUP(D27,產線配置圖!$A$2:$C$38,3,0) -> 1565 | L27: =K27/J27 -> 92.058824 | M27: 16 | N27: =G27/W27*60 -> 1271.6364 | O27: =N27/M27 -> 79.477273 | P27: =M27-J27 -> -1 | Q27: =O27-L27 -> -12.581551 | R27: =O27/L27 -> 0.8633314 | S27: =R37 -> 0.92712949 | T27: 0.28888889 | U27: 0.40347222 | W27: =(U27-T27)*24*60 -> 165 | AB27: =N27-K27 -> -293.36364 | AC27: =N27/K27 -> 0.8125472 | AD27: =AC37 -> 0.87616459
B28: =VLOOKUP(D28,廠價表!$C$1:$E$39,2,0) -> 義大利麵 | D28: 奶油蒜香雞義大利麵 | F28: =VLOOKUP(D28,廠價表!$C$1:$E$39,3,0) -> 55.13 | G28: 1434 | H28: =F28*G28 -> 79056.42 | J28: =VLOOKUP(D28,產線配置圖!$A$2:$C$38,2,0) -> 18 | K28: =VLOOKUP(D28,產線配置圖!$A$2:$C$38,3,0) -> 1385 | L28: =K28/J28 -> 76.944444 | M28: 16 | N28: =G28/W28*60 -> 1178.6301 | O28: =N28/M28 -> 73.664384 | P28: =M28-J28 -> -2 | Q28: =O28-L28 -> -3.2800609 | R28: =O28/L28 -> 0.95737105 | T28: 0.40972222 | U28: 0.46041667 | V28: =(T28-U27)*24*60 -> 9 | W28: =(U28-T28)*24*60 -> 73 | AB28: =N28-K28 -> -206.36986 | AC28: =N28/K28 -> 0.85099649
B29: 義大利麵 | D29: 奶油蒜香雞義大利麵 | F29: =VLOOKUP(D29,廠價表!$C$1:$E$39,3,0) -> 55.13 | G29: 966 | H29: =F29*G29 -> 53255.58 | J29: =VLOOKUP(D29,產線配置圖!$A$2:$C$38,2,0) -> 18 | K29: =VLOOKUP(D29,產線配置圖!$A$2:$C$38,3,0) -> 1385 | L29: =K29/J29 -> 76.944444 | M29: 18 | N29: =G29/W29*60 -> 1347.907 | O29: =N29/M29 -> 74.883721 | P29: =M29-J29 -> 0 | Q29: =O29-L29 -> -2.0607235 | R29: =O29/L29 -> 0.97321803 | T29: 0.52083333 | U29: 0.55069444 | V29: =(T29-U28)*24*60 -> 87 | W29: =(U29-T29)*24*60 -> 43 | X29: 0.47222222 | Y29: 0.51388889 | AB29: =N29-K29 -> -37.093023 | AC29: =N29/K29 -> 0.97321803
W30: =(U30-T30)*24*60 -> 0
W31: =(U31-T31)*24*60 -> 0
H32: =F32*G32 -> 0 | W32: =(U32-T32)*24*60 -> 0
H33: =F33*G33 -> 0 | W33: =(U33-T33)*24*60 -> 0
H34: =F34*G34 -> 0 | W34: =(U34-T34)*24*60 -> 0
H35: =F35*G35 -> 0 | W35: =(U35-T35)*24*60 -> 0
H36: =F36*G36 -> 0 | W36: =(U36-T36)*24*60 -> 0
C37: 4度二組B | D37: 平均 | J37: =AVERAGE(J27:J36) -> 17.666667 | K37: =AVERAGE(K27:K36) -> 1445 | L37: =AVERAGE(L27:L36) -> 81.982571 | M37: =AVERAGE(M27:M36) -> 16.666667 | N37: =AVERAGE(N27:N36) -> 1266.0578 | O37: =AVERAGE(O27:O36) -> 76.008459 | P37: =M37-J37 -> -1 | Q37: =N37-K37 -> -178.94217 | R37: =O37/L37 -> 0.92712949 | AB37: =N37-K37 -> -178.94217 | AC37: =N37/K37 -> 0.87616459
A38: 手工四線 (ET-55) | B38: 義大利麵 | D38: 濃拿坡里義大利麵 | F38: =VLOOKUP(D38,廠價表!$C$1:$E$39,3,0) -> 56.43 | G38: 2324 | H38: =F38*G38 -> 131143.32 | J38: =VLOOKUP(D38,產線配置圖!$A$2:$C$38,2,0) -> 15 | K38: =VLOOKUP(D38,產線配置圖!$A$2:$C$38,3,0) -> 1406 | L38: =K38/J38 -> 93.733333 | M38: 15 | N38: =G38/W38*60 -> 1162 | O38: =N38/M38 -> 77.466667 | P38: =M38-J38 -> 0 | Q38: =O38-L38 -> -16.266667 | R38: =O38/L38 -> 0.82645804 | S38: =R48 -> 0.82156933 | T38: 0.33333333 | U38: 0.41666667 | W38: =(U38-T38)*24*60 -> 120 | Z38: 9:45-9:48待醬 | AB38: =N38-K38 -> -244 | AC38: =N38/K38 -> 0.82645804 | AD38: =AC48 -> 0.82156933
B39: 義大利麵 | D39: 焗烤明太子筆尖麵 | F39: =VLOOKUP(D39,廠價表!$C$1:$E$39,3,0) -> 57.3 | G39: 1131 | H39: =F39*G39 -> 64806.3 | J39: =VLOOKUP(D39,產線配置圖!$A$2:$C$38,2,0) -> 15 | K39: =VLOOKUP(D39,產線配置圖!$A$2:$C$38,3,0) -> 1385 | L39: =K39/J39 -> 92.333333 | M39: 15 | N39: =G39/W39*60 -> 1131 | O39: =N39/M39 -> 75.4 | P39: =M39-J39 -> 0 | Q39: =O39-L39 -> -16.933333 | R39: =O39/L39 -> 0.8166065 | T39: 0.4375 | U39: 0.47916667 | V39: =(T39-U38)*24*60 -> 30 | W39: =(U39-T39)*24*60 -> 60 | AB39: =N39-K39 -> -254 | AC39: =N39/K39 -> 0.8166065
W40: =(U40-T40)*24*60 -> 0
...

Sheet 1105總 
B1: 長家廠組合室生產人時性分析
B3: 日期 | D3: 45966 | F3: 訂單量 | G3: ='1105'!E1 -> 53267 | I3: 營業額 | J3: ='1105'!G1 -> 2583087.8
B4: 項目 | D4: 3 | F4: ➀ | H4: ➁ | J4: ③
B5: 人時性 | D5: 組合室 | F5: 全溫層 | H5: 義大利麵 | J5: 袋裝小吃、義麵
D6: 排關平均 | F6: =AVERAGE(D13:J13) -> 116.12218 | H6: =AVERAGE(D13:H13) -> 114.6499 | J6: =AVERAGE(I13:J13) -> 119.80288
D7: 實績平均 | F7: =AVERAGE(D14:J14) -> 104.39823 | H7: =AVERAGE(D14:H14) -> 104.1057 | J7: =AVERAGE(I14:J14) -> 105.12955
D8: 達成率平均 | F8: =AVERAGE(D15:J15) -> 0.89804388 | H8: =AVERAGE(D15:H15) -> 0.90611106 | J8: =AVERAGE(I15:J15) -> 0.87787593 | L8: ※現行日本鮮食廠以達成率80%為基本(即為現行KPI)
B10: 溫層 | D10: 4度C-各編組展開
B11: 編組 | D11: 1 | E11: 2 | F11: 3 | G11: 4 | H11: 5 | I11: 6 | J11: 7
D12: 自動1線 | E12: 自動2線 | F12: 手工3線 | G12: 手工4線 | H12: 手工5線 | I12: 調理包1線 | J12: 調理包2線
B13: 人時性 | C13: 排關 | D13: =VALUE('1105'!L15) -> 149.47587 | E13: =VALUE('1105'!L26) -> 162.27564 | F13: =VALUE('1105'!L37) -> 81.982571 | G13: =VALUE('1105'!L48) -> 92.8 | H13: =VALUE('1105'!L58) -> 86.7154 | I13: =VALUE('1105'!L69) -> 126.40385 | J13: =VALUE('1105'!L79) -> 113.20192
C14: 實績 | D14: =VALUE('1105'!O15) -> 139.48261 | E14: =VALUE('1105'!O26) -> 147.29258 | F14: =VALUE('1105'!O37) -> 76.846924 | G14: =VALUE('1105'!O48) -> 75.459634 | H14: =VALUE('1105'!O58) -> 81.446758 | I14: =VALUE('1105'!O69) -> 110.15266 | J14: =VALUE('1105'!O79) -> 100.10643
C15: 達成率 | D15: =D14/D13 -> 0.93314467 | E15: =E14/E13 -> 0.90766905 | F15: =F14/F13 -> 0.93735685 | G15: =G14/G13 -> 0.8131426 | H15: =H14/H13 -> 0.93924214 | I15: =I14/I13 -> 0.87143443 | J15: =J14/J13 -> 0.88431742
B16: 作業 時間 | C16: 開始 | D16: ='1105'!T5 -> 0.29027778 | E16: ='1105'!T16 -> 0.28958333 | F16: ='1105'!T27 -> 0.28888889 | G16: ='1105'!T38 -> 0.33333333 | H16: ='1105'!T49 -> 0.28888889 | I16: ='1105'!T59 -> 0.29097222 | J16: ='1105'!T70 -> 0.33333333
C17: 結束 | D17: 0.63194444 | E17: 0.6 | F17: 0.56805556 | G17: 0.58680556 | H17: 0.61319444 | I17: 0.61527778 | J17: 0.49305556
B18: 配置人數 | D18: =VALUE('1105'!M15) -> 13.666667 | E18: =VALUE('1105'!M26) -> 12.5 | F18: =VALUE('1105'!M37) -> 14.666667 | G18: =VALUE('1105'!M48) -> 14.666667 | H18: =VALUE('1105'!M58) -> 18.333333 | I18: =VALUE('1105'!M69) -> 12.4 | J18: =VALUE('1105'!M79) -> 12.7
B19: 主要應用設備 | D19: ET-600 | E19: ET-600 | F19: ET-55 | G19: ET-55 | H19: ET-55 | I19: 八爪機 | J19: ET-55
B20: 次要應用設備 | H20: 封口機
B21: 備註

Sheet 1105
A1: 長家廠4度C日報分析 | D1: 總生產量 | E1: =SUM(G5:G79) -> 53267 | F1: 營業額 | G1: =SUM(H5:H79) -> 2583087.8 | H1: 出勤人數 | I1: =M15+M26+M48+M58+M69+M79+M37 -> 98.933333 | J1: 產線配置圖 | M1: 生產實績 | P1: 人時性差異分析 | T1: 日報登錄 | Z1: 分析說明 | AB1: 產能差異分析
A2: 11月05日 星期三 | D2: 人時性 | E2: =AVERAGE(O15,O26,O37,O48,O58,O69,O79) -> 104.39823 | F2: 平均廠價 | G2: =G1/E1 -> 48.49321 | H2: 多次生產數 | I2: =COUNT(I5:I79) -> 0
A3: 線別 | B3: 品類 | D3: 品名 | F3: 廠價 | G3: 生產量 | H3: 營收 | I3: 多次 生產 | J3: 人數 | K3: 產能/時 | L3: 人時性 | M3: 人數 | N3: 產能/時 | O3: 人時性 | P3: 人數 | Q3: 人時性 | R3: 達成率 | S3: 達成率平均 | T3: 生產時間 | V3: 前置、換線時間/分 | W3: 稼動時間/分 | X3: 休息時間 | Z3: (長家回填) | AB3: 產能/時 | AC3: 達成率 | AD3: 達成率平均
T4: 開始 | U4: 結束 | X4: 開始 | Y4: 結束
A5: 自動一線 (ET-600) | B5: =VLOOKUP(D5,廠價表!$C$1:$E$39,2,0) -> 義大利麵 | D5: 白酒蛤蜊義大利麵 | F5: =VLOOKUP(D5,廠價表!$C$1:$E$39,3,0) -> 57.21 | G5: 1224 | H5: =F5*G5 -> 70025.04 | J5: =VLOOKUP(D5,產線配置圖!$A$2:$C$38,2,0) -> 13 | K5: =VLOOKUP(D5,產線配置圖!$A$2:$C$38,3,0) -> 2105 | L5: =K5/J5 -> 161.92308 | M5: 13 | N5: =G5/W5*60 -> 1836 | O5: =N5/M5 -> 141.23077 | P5: =M5-J5 -> 0 | Q5: =O5-L5 -> -20.692308 | R5: =O5/L5 -> 0.87220903 | S5: =R15 -> 0.93314467 | T5: 0.29027778 | U5: 0.31805556 | W5: =(U5-T5)*24*60 -> 40 | AB5: =N5-K5 -> -269 | AC5: =N5/K5 -> 0.87220903 | AD5: =AC15 -> 0.93186548
B6: =VLOOKUP(D6,廠價表!$C$1:$E$39,2,0) -> 義大利麵 | D6: 青醬蛤蜊義大利麵 | F6: =VLOOKUP(D6,廠價表!$C$1:$E$39,3,0) -> 50.67 | G6: 1076 | H6: =F6*G6 -> 54520.92 | J6: =VLOOKUP(D6,產線配置圖!$A$2:$C$38,2,0) -> 13 | K6: =VLOOKUP(D6,產線配置圖!$A$2:$C$38,3,0) -> 2000 | L6: =K6/J6 -> 153.84615 | M6: 13 | N6: =G6/W6*60 -> 1844.5714 | O6: =N6/M6 -> 141.89011 | P6: =M6-J6 -> 0 | Q6: =O6-L6 -> -11.956044 | R6: =O6/L6 -> 0.92228571 | T6: 0.32986111 | U6: 0.35416667 | V6: =(T6-U5)*24*60 -> 17 | W6: =(U6-T6)*24*60 -> 35 | Z6: 7:50~7:55待玉取機出麵 | AB6: =N6-K6 -> -155.42857 | AC6: =N6/K6 -> 0.92228571
B7: =VLOOKUP(D7,廠價表!$C$1:$E$39,2,0) -> 義大利麵 | D7: 韓式起司炸雞義大利麵 | F7: =VLOOKUP(D7,廠價表!$C$1:$E$39,3,0) -> 57.21 | G7: 2270 | H7: =F7*G7 -> 129866.7 | J7: =VLOOKUP(D7,產線配置圖!$A$2:$C$38,2,0) -> 17 | K7: =VLOOKUP(D7,產線配置圖!$A$2:$C$38,3,0) -> 1895 | L7: =K7/J7 -> 111.47059 | M7: 17 | N7: =G7/W7*60 -> 1702.5 | O7: =N7/M7 -> 100.14706 | P7: =M7-J7 -> 0 | Q7: =O7-L7 -> -11.323529 | R7: =O7/L7 -> 0.89841689 | T7: 0.35972222 | U7: 0.41527778 | V7: =(T7-U6)*24*60 -> 8 | W7: =(U7-T7)*24*60 -> 80 | AB7: =N7-K7 -> -192.5 | AC7: =N7/K7 -> 0.89841689
B8: =VLOOKUP(D8,廠價表!$C$1:$E$39,2,0) -> 義大利麵 | D8: 奶油培根義大利麵 | F8: =VLOOKUP(D8,廠價表!$C$1:$E$39,3,0) -> 49.14 | G8: 2608 | H8: =F8*G8 -> 128157.12 | J8: =VLOOKUP(D8,產線配置圖!$A$2:$C$38,2,0) -> 13 | K8: =VLOOKUP(D8,產線配置圖!$A$2:$C$38,3,0) -> 2000 | L8: =K8/J8 -> 153.84615 | M8: 13 | N8: =G8/W8*60 -> 1931.8519 | O8: =N8/M8 -> 148.60399 | P8: =M8-J8 -> 0 | Q8: =O8-L8 -> -5.2421652 | R8: =O8/L8 -> 0.96592593 | T8: 0.42222222 | U8: 0.47847222 | V8: =(T8-U7)*24*60 -> 10 | W8: =(U8-T8)*24*60 -> 81 | AB8: =N8-K8 -> -68.148148 | AC8: =N8/K8 -> 0.96592593
B9: =VLOOKUP(D9,廠價表!$C$1:$E$39,2,0) -> 義大利麵 | D9: 奶油培根義大利麵 | F9: =VLOOKUP(D9,廠價表!$C$1:$E$39,3,0) -> 49.14 | G9: 2797 | H9: =F9*G9 -> 137444.58 | J9: =VLOOKUP(D9,產線配置圖!$A$2:$C$38,2,0) -> 13 | K9: =VLOOKUP(D9,產線配置圖!$A$2:$C$38,3,0) -> 2000 | L9: =K9/J9 -> 153.84615 | M9: 13 | N9: =G9/W9*60 -> 1951.3953 | O9: =N9/M9 -> 150.10733 | P9: =M9-J9 -> 0 | Q9: =O9-L9 -> -3.7388193 | R9: =O9/L9 -> 0.97569767 | T9: 0.54027778 | U9: 0.6 | V9: =(T9-U8)*24*60 -> 89 | W9: =(U9-T9)*24*60 -> 86 | X9: 0.48611111 | Y9: 0.52777778 | AB9: =N9-K9 -> -48.604651 | AC9: =N9/K9 -> 0.97569767
B10: =VLOOKUP(D10,廠價表!$C$1:$E$39,2,0) -> 義大利麵 | D10: 白酒蛤蜊義大利麵 | F10: =VLOOKUP(D10,廠價表!$C$1:$E$39,3,0) -> 57.21 | G10: 772 | H10: =F10*G10 -> 44166.12 | J10: =VLOOKUP(D10,產線配置圖!$A$2:$C$38,2,0) -> 13 | K10: =VLOOKUP(D10,產線配置圖!$A$2:$C$38,3,0) -> 2105 | L10: =K10/J10 -> 161.92308 | M10: 13 | N10: =G10/W10*60 -> 2013.913 | O10: =N10/M10 -> 154.91639 | P10: =M10-J10 -> 0 | Q10: =O10-L10 -> -7.006689 | R10: =O10/L10 -> 0.95672829 | T10: 0.61597222 | U10: 0.63194444 | V10: =(T10-U9)*24*60 -> 23 | W10: =(U10-T10)*24*60 -> 23
W11: =(U11-T11)*24*60 -> 0
H12: =F12*G12 -> 0 | W12: =(U12-T12)*24*60 -> 0
H13: =F13*G13 -> 0 | W13: =(U13-T13)*24*60 -> 0
H14: =F14*G14 -> 0 | W14: =(U14-T14)*24*60 -> 0
