Workbook

Sheet 廠價表
A1: check | B1: 溫層 | C1: 品名 | D1: 類別 | E1: 廠價
B2: 4度C | C2: 白酒蛤蜊義大利麵 | D2: 義大利麵 | E2: 57.21
B3: 4度C | C3: 南洋紅咖哩豬義大利麵 | D3: 義大利麵 | E3: 56.43
B4: 4度C | C4: 義式蕃茄起司義大利麵 | D4: 義大利麵 | E4: 50.39
B5: 4度C | C5: 焗烤起司雙饗筆尖麵 | D5: 義大利麵 | E5: 49.97
B6: 4度C | C6: 奶油培根義大利麵 | D6: 義大利麵 | E6: 49.14
B7: 4度C | C7: 韓式起司炸雞義大利麵 | D7: 義大利麵 | E7: 57.21
B8: 4度C | C8: 惡魔乳酪生義大利麵 | D8: 義大利麵 | E8: 57.3
B9: 4度C | C9: 焗烤起司肉醬筆尖麵 | D9: 義大利麵 | E9: 50.67
B10: 4度C | D10: 義大利麵
B11: 4度C | D11: 義大利麵
B12: 4度C | C12: 剝皮辣椒雞奶油扁麵 | D12: 義大利麵 | E12: 56.87
B13: 4度C | C13: 奶油蒜香雞義大利麵 | D13: 義大利麵 | E13: 55.13
B14: 4度C | C14: 青醬蛤蜊義大利麵 | D14: 義大利麵 | E14: 50.67
B15: 4度C | C15: 焗烤明太子筆尖麵 | D15: 義大利麵 | E15: 57.3
B16: 4度C | C16: 濃拿坡里義大利麵 | D16: 義大利麵 | E16: 56.43
B17: 4度C | C17: 奶油起司蝦仁通心粉 | D17: 義大利麵 | E17: 47.71
B18: 4度C | C18: 青花椒麻雞肉拌麵 | D18: 熱乾麵 | E18: 49.91
B19: 4度C | C19: 府城鹽水意麵 | D19: 熱乾麵 | E19: 44.3
B20: 4度C | C20: 沙茶豬肉炒麵 | D20: 熱乾麵 | E20: 49.52
B21: 4度C | C21: 小滷青蔬 | D21: 小吃、微波 | E21: 26.99
B22: 4度C | C22: 起司馬鈴薯 | D22: 小吃、微波 | E22: 28.26
B23: 4度C | C23: 台式綜合甜不辣 | D23: 小吃、微波 | E23: 28.47
... B48: 冷凍 | C48: 辣蕃茄義大利麵 | D48: 冷凍調理麵 | E48: 29.38
B49: 冷凍 | D49: 冷凍調理麵
B50: 冷凍 | C50: 韓式起司義大利麵 | D50: 冷凍調理麵 | E50: 29.38 | M50: 19 | T50: 0.2875 | U50: 0.3375
B51: 冷凍 | D51: 冷凍調理麵 | M51: 18 | T51: 0.34166667 | U51: 0.41180556
B52: 冷凍 | C52: 和風明太子細扁麵 | D52: 冷凍調理麵 | E52: 29.38 | T52: 0.41597222 | U52: 0.47291667
M53: 18 | T53: 0.52777778 | U53: 0.61319444
T54: 0.61805556 | U54: 0.63611111
Z55: 生產數量少
G60: 2772 | T60: 0.28819444 | U60: 0.36458333
G63: 2367 | U63: 0.62708333
G64: 1335 | U64: 0.67361111
Z71: 手工作業
Z72: 手工作業

Sheet 產線配置圖
A1: 品項 | B1: 人數 | C1: 產能
A2: 義大利麵
A3: 白酒蛤蜊義大利麵 | B3: 13 | C3: 2105 | D3: ET-600
A4: 白酒蛤蜊義大利麵-手 | B4: 15 | C4: 1565 | D4: ET-55
A5: 青醬蛤蜊義大利麵 | B5: 13 | C5: 2000
A6: 義式蕃茄起司義大利麵 | B6: 12 | C6: 2000
A7: 焗烤起司雙饗筆尖麵 | B7: 18 | C7: 1600
A8: 奶油培根義大利麵 | B8: 13 | C8: 2000
A9: 韓式起司炸雞義大利麵 | B9: 17 | C9: 1895
A10: 剝皮辣椒雞奶油扁麵 | B10: 19 | C10: 1565
A11: 青花椒麻雞肉拌麵 | B11: 17 | C11: 1565
A12: 青花椒麻雞肉拌麵-降速生產 | B12: 14 | C12: 1385
A13: 奶油蒜香雞義大利麵 | B13: 18 | C13: 1385 | G13: 日一二正常版
A14: 奶油蒜香雞義大利麵-降速生產 | B14: 16 | C14: 1385
A15: 焗烤明太子筆尖麵 | B15: 15 | C15: 1385
A16: 濃拿坡里義大利麵 | B16: 15 | C16: 1406
A17: 奶油起司蝦仁通心粉 | B17: 15 | C17: 1500
A18: 剝皮辣椒雞奶油扁麵-降速生產(3線) | B18: 16 | C18: 1440
A19: 南洋紅咖哩豬義大利麵 | B19: 15 | C19: 1636
A20: 南洋紅咖哩豬義大利麵-手工 | B20: 16 | C20: 1500
A21: 惡魔乳酪生義大利麵 | B21: 15 | C21: 1440
A22: 沙茶豬肉炒麵 | B22: 18 | C22: 1440
A23: 府城鹽水意麵 | B23: 19 | C23: 1440
A24: 焗烤起司肉醬筆尖麵 | B24: 15 | C24: 1440
A25: 調理包
A26: 小滷青蔬 | B26: 13 | C26: 1565
A27: 起司馬鈴薯 | B27: 12 | C27: 1565
A28: 台式綜合甜不辣 | B28: 12 | C28: 1565
E33: 更新日期11/02

Sheet 1201總
B1: 長家廠組合室生產人時性分析
B3: 日期 | D3: 45992 | F3: 訂單量 | G3: ='1201'!E1 -> 52776 | I3: 營業額 | J3: ='1201'!G1 -> 2567818.6
B4: 項目 | D4: 3 | F4: ➀ | H4: ➁ | J4: ③
B5: 人時性 | D5: 組合室 | F5: 全溫層 | H5: 義大利麵 | J5: 袋裝小吃、義麵
D6: 排關平均 | F6: =AVERAGE(D13:J13) -> 116.75455 | H6: =AVERAGE(D13:H13) -> 114.52373 | J6: =AVERAGE(I13:J13) -> 127.90865
D7: 實績平均 | F7: =AVERAGE(D14:J14) -> 104.67026 | H7: =AVERAGE(D14:H14) -> 101.80244 | J7: =AVERAGE(I14:J14) -> 119.00936
D8: 達成率平均 | F8: =AVERAGE(D15:J15) -> 0.90441506 | H8: =AVERAGE(D15:H15) -> 0.89921315 | J8: =AVERAGE(I15:J15) -> 0.9304246 | L8: ※現行日本鮮食廠以達成率80%為基本(即為現行KPI)
B10: 溫層 | D10: 4度C-各編組展開
B11: 編組 | D11: 1 | E11: 2 | F11: 3 | G11: 4 | H11: 5 | I11: 6 | J11: 7
D12: 自動1線 | E12: 自動2線 | F12: 手工3線 | G12: 手工4線 | H12: 手工5線 | I12: 調理包1線 | J12: 調理包2線
B13: 人時性 | C13: 排關 | D13: =VALUE('1201'!L15) -> 136.91288 | E13: =VALUE('1201'!L26) -> 160.58974 | F13: =VALUE('1201'!L37) -> 92.250817 | G13: =VALUE('1201'!L48) -> 94.813971 | H13: =VALUE('1201'!L58) -> 88.051256 | I13: =VALUE('1201'!L69) -> 127.90865
C14: 實績 | D14: =VALUE('1201'!O15) -> 117.58745 | E14: =VALUE('1201'!O26) -> 135.41864 | F14: =VALUE('1201'!O37) -> 84.690731 | G14: =VALUE('1201'!O48) -> 86.071029 | H14: =VALUE('1201'!O58) -> 85.244325 | I14: =VALUE('1201'!O69) -> 119.00936
C15: 達成率 | D15: =D14/D13 -> 0.85884872 | E15: =E14/E13 -> 0.84325837 | F15: =F14/F13 -> 0.91804857 | G15: =G14/G13 -> 0.90778847 | H15: =H14/H13 -> 0.96812163 | I15: =I14/I13 -> 0.9304246
B16: 作業 時間 | C16: 開始 | D16: ='1201'!T5 -> 0.29166667 | E16: ='1201'!T16 -> 0.29027778 | F16: ='1201'!T27 -> 0.29166667 | G16: ='1201'!T38 -> 0.33263889 | H16: ='1201'!T49 -> 0.29166667 | I16: ='1201'!T59 -> 0.29166667
C17: 結束 | D17: 0.65 | E17: 0.65902778 | F17: 0.625 | G17: 0.61875 | H17: 0.65208333 | I17: 0.57291667
B18: 配置人數 | D18: =VALUE('1201'!M15) -> 14.2 | E18: =VALUE('1201'!M26) -> 12.6 | F18: =VALUE('1201'!M37) -> 15.75 | G18: =VALUE('1201'!M48) -> 13.5 | H18: =VALUE('1201'!M58) -> 17.75 | I18: =VALUE('1201'!M69) -> 12.25
B19: 主要應用設備 | D19: ET-600 | E19: ET-600 | F19: ET-55 | G19: ET-55 | H19: ET-55 | I19: 八爪機
B20: 次要應用設備 | H20: 封口機
B21: 備註

Sheet 1201
A1: 長家廠4度C日報分析 | D1: 總生產量 | E1: =SUM(G5:G79) -> 52776 | F1: 營業額 | G1: =SUM(H5:H79) -> 2567818.6 | H1: 出勤人數 | I1: =M15+M26+M48+M58+M69+M79+M37 -> 86.05 | J1: 產線配置圖 | M1: 生產實績 | P1: 人時性差異分析 | T1: 日報登錄 | Z1: 分析說明 | AB1: 產能差異分析
A2: 12月01日 星期二 | D2: 人時性 | E2: =AVERAGE(O15,O26,O37,O48,O58,O69,O79) -> 104.67026 | F2: 平均廠價 | G2: =G1/E1 -> 48.655044 | H2: 多次生產數 | I2: =COUNT(I5:I79) -> 0
A3: 線別 | B3: 品類 | D3: 品名 | F3: 廠價 | G3: 生產量 | H3: 營收 | I3: 多次 生產 | J3: 人數 | K3: 產能/時 | L3: 人時性 | M3: 人數 | N3: 產能/時 | O3: 人時性 | P3: 人數 | Q3: 人時性 | R3: 達成率 | S3: 達成率平均 | T3: 生產時間 | V3: 前置、換線時間/分 | W3: 稼動時間/分 | X3: 休息時間 | AB3: 產能/時 | AC3: 達成率 | AD3: 達成率平均
T4: 開始 | U4: 結束 | X4: 開始 | Y4: 結束
A5: 自動一線 (ET-600) | B5: =VLOOKUP(D5,廠價表!$C$1:$E$40,2,0) -> 義大利麵 | D5: 白酒蛤蜊義大利麵 | F5: =VLOOKUP(D5,廠價表!$C$1:$E$40,3,0) -> 57.21 | G5: 1534 | H5: =F5*G5 -> 87760.14 | J5: =VLOOKUP(D5,產線配置圖!$A$3:$C$39,2,0) -> 13 | K5: =VLOOKUP(D5,產線配置圖!$A$3:$C$39,3,0) -> 2105 | L5: =K5/J5 -> 161.92308 | M5: 13 | N5: =G5/W5*60 -> 1704.4444 | O5: =N5/M5 -> 131.11111 | P5: =M5-J5 -> 0 | Q5: =O5-L5 -> -30.811966 | R5: =O5/L5 -> 0.80971233 | S5: =R15 -> 0.85884872 | T5: 0.29166667 | U5: 0.32916667 | W5: =(U5-T5)*24*60 -> 54 | AB5: =N5-K5 -> -400.55556 | AC5: =N5/K5 -> 0.80971233 | AD5: =AC15 -> 0.85654713
B6: =VLOOKUP(D6,廠價表!$C$1:$E$40,2,0) -> 義大利麵 | D6: 韓式起司炸雞義大利麵 | F6: =VLOOKUP(D6,廠價表!$C$1:$E$40,3,0) -> 57.21 | G6: 1986 | H6: =F6*G6 -> 113619.06 | J6: =VLOOKUP(D6,產線配置圖!$A$3:$C$39,2,0) -> 17 | K6: 1800 | L6: =K6/J6 -> 105.88235 | M6: 17 | N6: =G6/W6*60 -> 1678.3099 | O6: =N6/M6 -> 98.724109 | P6: =M6-J6 -> 0 | Q6: =O6-L6 -> -7.1582436 | R6: =O6/L6 -> 0.93239437 | T6: 0.33680556 | U6: 0.38611111 | V6: =(T6-U5)*24*60 -> 11 | W6: =(U6-T6)*24*60 -> 71 | AB6: =N6-K6 -> -121.69014 | AC6: =N6/K6 -> 0.93239437
B7: =VLOOKUP(D7,廠價表!$C$1:$E$40,2,0) -> 義大利麵 | D7: 奶油培根義大利麵 | F7: =VLOOKUP(D7,廠價表!$C$1:$E$40,3,0) -> 49.14 | G7: 3700 | H7: =F7*G7 -> 181818 | J7: =VLOOKUP(D7,產線配置圖!$A$3:$C$39,2,0) -> 13 | K7: =VLOOKUP(D7,產線配置圖!$A$3:$C$39,3,0) -> 2000 | L7: =K7/J7 -> 153.84615 | M7: 13 | N7: =G7/W7*60 -> 1819.6721 | O7: =N7/M7 -> 139.97478 | P7: =M7-J7 -> 0 | Q7: =O7-L7 -> -13.871375 | R7: =O7/L7 -> 0.90983607 | T7: 0.39305556 | U7: 0.47777778 | V7: =(T7-U6)*24*60 -> 10 | W7: =(U7-T7)*24*60 -> 122 | AB7: =N7-K7 -> -180.32787 | AC7: =N7/K7 -> 0.90983607
B8: =VLOOKUP(D8,廠價表!$C$1:$E$40,2,0) -> 義大利麵 | D8: 奶油培根義大利麵 | F8: =VLOOKUP(D8,廠價表!$C$1:$E$40,3,0) -> 49.14 | G8: 2094 | H8: =F8*G8 -> 102899.16 | J8: =VLOOKUP(D8,產線配置圖!$A$3:$C$39,2,0) -> 13 | K8: =VLOOKUP(D8,產線配置圖!$A$3:$C$39,3,0) -> 2000 | L8: =K8/J8 -> 153.84615 | M8: 13 | N8: =G8/W8*60 -> 1963.125 | O8: =N8/M8 -> 151.00962 | P8: =M8-J8 -> 0 | Q8: =O8-L8 -> -2.8365385 | R8: =O8/L8 -> 0.9815625 | T8: 0.54027778 | U8: 0.58472222 | V8: =(T8-U7)*24*60 -> 90 | W8: =(U8-T8)*24*60 -> 64 | AB8: =N8-K8 -> -36.875 | AC8: =N8/K8 -> 0.9815625
B9: =VLOOKUP(D9,廠價表!$C$1:$E$40,2,0) -> 義大利麵 | D9: 南洋紅咖哩豬義大利麵 | F9: =VLOOKUP(D9,廠價表!$C$1:$E$40,3,0) -> 56.43 | G9: 1141 | H9: =F9*G9 -> 64386.63 | J9: =VLOOKUP(D9,產線配置圖!$A$3:$C$39,2,0) -> 15 | K9: =VLOOKUP(D9,產線配置圖!$A$3:$C$39,3,0) -> 1636 | L9: =K9/J9 -> 109.06667 | M9: 15 | N9: =G9/W9*60 -> 1006.7647 | O9: =N9/M9 -> 67.117647 | P9: =M9-J9 -> 0 | Q9: =O9-L9 -> -41.94902 | R9: =O9/L9 -> 0.61538185 | T9: 0.60277778 | U9: 0.65 | V9: =(T9-U8)*24*60 -> 26 | W9: =(U9-T9)*24*60 -> 68 | X9: 0.48958333 | Y9: 0.53125 | Z9: 14:28-15:36手抓麵作業 | AB9: =N9-K9 -> -629.23529 | AC9: =N9/K9 -> 0.61538185
W10: =(U10-T10)*24*60 -> 0
H11: =F11*G11 -> 0 | W11: =(U11-T11)*24*60 -> 0
H12: =F12*G12 -> 0 | W12: =(U12-T12)*24*60 -> 0
W13: =(U13-T13)*24*60 -> 0
W14: =(U14-T14)*24*60 -> 0
C15: 4度一組 | D15: 平均 | J15: =AVERAGE(J5:J14) -> 14.2 | K15: =AVERAGE(K5:K14) -> 1908.2 | L15: =AVERAGE(L5:L14) -> 136.91288 | M15: =AVERAGE(M5:M14) -> 14.2 | N15: =AVERAGE(N5:N14) -> 1634.4632 | O15: =AVERAGE(O5:O14) -> 117.58745 | P15: =M15-J15 -> 0 | Q15: =O15-L15 -> -19.325428 | R15: =O15/L15 -> 0.85884872 | AB15: =N15-K15 -> -273.73677 | AC15: =N15/K15 -> 0.85654713
A16: 自動二線 (ET-600) | B16: =VLOOKUP(D16,廠價表!$C$1:$E$40,2,0) -> 義大利麵 | D16: 白酒蛤蜊義大利麵 | F16: =VLOOKUP(D16,廠價表!$C$1:$E$40,3,0) -> 57.21 | G16: 1438 | H16: =F16*G16 -> 82267.98 | J16: =VLOOKUP(D16,產線配置圖!$A$3:$C$39,2,0) -> 13 | K16: =VLOOKUP(D16,產線配置圖!$A$3:$C$39,3,0) -> 2105 | L16: =K16/J16 -> 161.92308 | M16: 13 | N16: =G16/W16*60 -> 1760.8163 | O16: =N16/M16 -> 135.44741 | P16: =M16-J16 -> 0 | Q16: =O16-L16 -> -26.475667 | R16: =O16/L16 -> 0.83649232 | S16: =R26 -> 0.84325837 | T16: 0.29027778 | U16: 0.32430556 | W16: =(U16-T16)*24*60 -> 49 | AB16: =N16-K16 -> -344.18367 | AC16: =N16/K16 -> 0.83649232 | AD16: =AC26 -> 0.84170175
B17: =VLOOKUP(D17,廠價表!$C$1:$E$40,2,0) -> 義大利麵 | D17: 青醬蛤蜊義大利麵 | F17: =VLOOKUP(D17,廠價表!$C$1:$E$40,3,0) -> 50.67 | G17: 2664 | H17: =F17*G17 -> 134984.88 | J17: =VLOOKUP(D17,產線配置圖!$A$3:$C$39,2,0) -> 13 | K17: =VLOOKUP(D17,產線配置圖!$A$3:$C$39,3,0) -> 2000 | L17: =K17/J17 -> 153.84615 | M17: 13 | N17: =G17/W17*60 -> 1795.9551 | O17: =N17/M17 -> 138.15039 | P17: =M17-J17 -> 0 | Q17: =O17-L17 -> -15.695765 | R17: =O17/L17 -> 0.89797753 | T17: 0.33263889 | U17: 0.39444444 | V17: =(T17-U16)*24*60 -> 12 | W17: =(U17-T17)*24*60 -> 89 | AB17: =N17-K17 -> -204.04494 | AC17: =N17/K17 -> 0.89797753
B18: =VLOOKUP(D18,廠價表!$C$1:$E$40,2,0) -> 義大利麵 | D18: 義式蕃茄起司義大利麵 | F18: =VLOOKUP(D18,廠價表!$C$1:$E$40,3,0) -> 50.39 | G18: 3052 | H18: =F18*G18 -> 153790.28 | J18: =VLOOKUP(D18,產線配置圖!$A$3:$C$39,2,0) -> 12 | K18: =VLOOKUP(D18,產線配置圖!$A$3:$C$39,3,0) -> 2000 | L18: =K18/J18 -> 166.66667 | M18: 12 | N18: =G18/W18*60 -> 1695.5556 | O18: =N18/M18 -> 141.2963 | P18: =M18-J18 -> 0 | Q18: =O18-L18 -> -25.37037 | R18: =O18/L18 -> 0.84777778 | T18: 0.40277778 | U18: 0.47777778 | V18: =(T18-U17)*24*60 -> 12 | W18: =(U18-T18)*24*60 -> 108 | AB18: =N18-K18 -> -304.44444 | AC18: =N18/K18 -> 0.84777778
B19: =VLOOKUP(D19,廠價表!$C$1:$E$40,2,0) -> 義大利麵 | D19: 義式蕃茄起司義大利麵 | F19: =VLOOKUP(D19,廠價表!$C$1:$E$40,3,0) -> 50.39 | G19: 2395 | H19: =F19*G19 -> 120684.05 | J19: =VLOOKUP(D19,產線配置圖!$A$3:$C$39,2,0) -> 12 | K19: =VLOOKUP(D19,產線配置圖!$A$3:$C$39,3,0) -> 2000 | L19: =K19/J19 -> 166.66667 | M19: 12 | N19: =G19/W19*60 -> 1866.2338 | O19: =N19/M19 -> 155.51948 | P19: =M19-J19 -> 0 | Q19: =O19-L19 -> -11.147186 | R19: =O19/L19 -> 0.93311688 | T19: 0.54166667 | U19: 0.59513889 | V19: =(T19-U18)*24*60 -> 92 | W19: =(U19-T19)*24*60 -> 77 | X19: 0.48958333 | Y19: 0.53125 | AB19: =N19-K19 -> -133.76623 | AC19: =N19/K19 -> 0.93311688
B20: =VLOOKUP(D20,廠價表!$C$1:$E$40,2,0) -> 義大利麵 | D20: 青醬蛤蜊義大利麵 | F20: =VLOOKUP(D20,廠價表!$C$1:$E$40,3,0) -> 50.67 | G20: 1826 | H20: =F20*G20 -> 92523.42 | J20: =VLOOKUP(D20,產線配置圖!$A$3:$C$39,2,0) -> 13 | K20: =VLOOKUP(D20,產線配置圖!$A$3:$C$39,3,0) -> 2000 | L20: =K20/J20 -> 153.84615 | M20: 13 | N20: =G20/W20*60 -> 1386.8354 | O20: =N20/M20 -> 106.67965 | P20: =M20-J20 -> 0 | Q20: =O20-L20 -> -47.166504 | R20: =O20/L20 -> 0.69341772 | T20: 0.60416667 | U20: 0.65902778 | V20: =(T20-U19)*24*60 -> 13 | W20: =(U20-T20)*24*60 -> 79 | Z20: 15:30~15:42玉取機停麵 | AB20: =N20-K20 -> -613.16456 | AC20: =N20/K20 -> 0.69341772
W21: =(U21-T21)*24*60 -> 0
H22: =F22*G22 -> 0 | W22: 0
W23: =(U23-T23)*24*60 -> 0
H24: =F24*G24 -> 0 | W24: =(U24-T24)*24*60 -> 0
H25: =F25*G25 -> 0 | W25: =(U25-T25)*24*60 -> 0
C26: 4度二組A | D26: 平均 | J26: =AVERAGE(J16:J25) -> 12.6 | K26: =AVERAGE(K16:K25) -> 2021 | L26: =AVERAGE(L16:L25) -> 160.58974 | M26: =AVERAGE(M16:M25) -> 12.6 | N26: =AVERAGE(N16:N25) -> 1701.0792 | O26: =AVERAGE(O16:O25) -> 135.41864 | P26: =M26-J26 -> 0 | Q26: =O26-L26 -> -25.171099 | R26: =O26/L26 -> 0.84325837 | AB26: =N26-K26 -> -319.92077 | AC26: =N26/K26 -> 0.84170175
A27: 手工三線 (ET-55) | B27: 義大利麵 | D27: 青花椒麻雞肉拌麵 | F27: =VLOOKUP(D27,廠價表!$C$1:$E$40,3,0) -> 49.91 | G27: 1716 | H27: =F27*G27 -> 85645.56 | J27: =VLOOKUP(D27,產線配置圖!$A$3:$C$39,2,0) -> 17 | K27: =VLOOKUP(D27,產線配置圖!$A$3:$C$39,3,0) -> 1565 | L27: =K27/J27 -> 92.058824 | M27: 15 | N27: =G27/W27*60 -> 1170 | O27: =N27/M27 -> 78 | P27: =M27-J27 -> -2 | Q27: =O27-L27 -> -14.058824 | R27: =O27/L27 -> 0.84728435 | S27: =R37 -> 0.91804857 | T27: 0.29166667 | U27: 0.35277778 | W27: =(U27-T27)*24*60 -> 88 | AB27: =N27-K27 -> -395 | AC27: =N27/K27 -> 0.74760383 | AD27: =AC37 -> 0.89553975
B28: =VLOOKUP(D28,廠價表!$C$1:$E$40,2,0) -> 義大利麵 | D28: 奶油蒜香雞義大利麵 | F28: =VLOOKUP(D28,廠價表!$C$1:$E$40,3,0) -> 55.13 | G28: 2083 | H28: =F28*G28 -> 114835.79 | J28: =VLOOKUP(D28,產線配置圖!$A$3:$C$39,2,0) -> 18 | K28: =VLOOKUP(D28,產線配置圖!$A$3:$C$39,3,0) -> 1385 | L28: =K28/J28 -> 76.944444 | M28: 16 | N28: =G28/W28*60 -> 1201.7308 | O28: =N28/M28 -> 75.108173 | P28: =M28-J28 -> -2 | Q28: =O28-L28 -> -1.8362714 | R28: =O28/L28 -> 0.9761351 | T28: 0.35972222 | U28: 0.43194444 | V28: =(T28-U27)*24*60 -> 10 | W28: =(U28-T28)*24*60 -> 104 | AB28: =N28-K28 -> -183.26923 | AC28: =N28/K28 -> 0.86767565
B29: =VLOOKUP(D29,廠價表!$C$1:$E$40,2,0) -> 義大利麵 | D29: 奶油起司蝦仁通心粉 | F29: =VLOOKUP(D29,廠價表!$C$1:$E$40,3,0) -> 47.71 | G29: 1583 | H29: =F29*G29 -> 75524.93 | J29: =VLOOKUP(D29,產線配置圖!$A$3:$C$39,2,0) -> 15 | K29: =VLOOKUP(D29,產線配置圖!$A$3:$C$39,3,0) -> 1500 | L29: =K29/J29 -> 100 | M29: 17 | N29: =G29/W29*60 -> 1461.2308 | O29: =N29/M29 -> 85.954751 | P29: =M29-J29 -> 2 | Q29: =O29-L29 -> -14.045249 | R29: =O29/L29 -> 0.85954751 | T29: 0.4375 | U29: 0.48263889 | V29: =(T29-U28)*24*60 -> 8 | W29: =(U29-T29)*24*60 -> 65 | Z29: 10:45-10:50停線更換注醬機作業 | AB29: =N29-K29 -> -38.769231 | AC29: =N29/K29 -> 0.97415385
B30: =VLOOKUP(D30,廠價表!$C$1:$E$40,2,0) -> 義大利麵 | D30: 奶油起司蝦仁通心粉 | F30: =VLOOKUP(D30,廠價表!$C$1:$E$40,3,0) -> 47.71 | G30: 2991 | H30: =F30*G30 -> 142700.61 | J30: =VLOOKUP(D30,產線配置圖!$A$3:$C$39,2,0) -> 15 | K30: =VLOOKUP(D30,產線配置圖!$A$3:$C$39,3,0) -> 1500 | L30: =K30/J30 -> 100 | M30: 15 | N30: =G30/W30*60 -> 1495.5 | O30: =N30/M30 -> 99.7 | P30: =M30-J30 -> 0 | Q30: =O30-L30 -> -0.3 | R30: =O30/L30 -> 0.997 | T30: 0.54166667 | U30: 0.625 | V30: =(T30-U29)*24*60 -> 85 | W30: =(U30-T30)*24*60 -> 120 | X30: 0.48958333 | Y30: 0.53125 | AB30: =N30-K30 -> -4.5 | AC30: =N30/K30 -> 0.997
W31: =(U31-T31)*24*60 -> 0
W32: =(U32-T32)*24*60 -> 0
H33: =F33*G33 -> 0 | W33: =(U33-T33)*24*60 -> 0
H34: =F34*G34 -> 0 | W34: =(U34-T34)*24*60 -> 0
H35: =F35*G35 -> 0 | W35: =(U35-T35)*24*60 -> 0
H36: =F36*G36 -> 0 | W36: =(U36-T36)*24*60 -> 0
C37: 4度二組B | D37: 平均 | J37: =AVERAGE(J27:J36) -> 16.25 | K37: =AVERAGE(K27:K36) -> 1487.5 | L37: =AVERAGE(L27:L36) -> 92.250817 | M37: =AVERAGE(M27:M36) -> 15.75 | N37: =AVERAGE(N27:N36) -> 1332.1154 | O37: =AVERAGE(O27:O36) -> 84.690731 | P37: =M37-J37 -> -0.5 | Q37: =N37-K37 -> -155.38462 | R37: =O37/L37 -> 0.91804857 | AB37: =N37-K37 -> -155.38462 | AC37: =N37/K37 -> 0.89553975
A38: 手工四線 (ET-55) | B38: 義大利麵 | D38: 焗烤明太子筆尖麵 | F38: =VLOOKUP(D38,廠價表!$C$1:$E$40,3,0) -> 57.3 | G38: 2487 | H38: =F38*G38 -> 142505.1 | J38: 16 | K38: 1500 | L38: =K38/J38 -> 93.75 | M38: 14 | N38: =G38/W38*60 -> 1233.2231 | O38: =N38/M38 -> 88.087367 | P38: =M38-J38 -> -2 | Q38: =O38-L38 -> -5.6626328 | R38: =O38/L38 -> 0.93959858 | S38: =R48 -> 0.90778847 | T38: 0.33263889 | U38: 0.41666667 | W38: =(U38-T38)*24*60 -> 121 | AB38: =N38-K38 -> -266.77686 | AC38: =N38/K38 -> 0.82214876 | AD38: =AC48 -> 0.78283727
B39: 義大利麵 | D39: 濃拿坡里義大利麵 | F39: =VLOOKUP(D39,廠價表!$C$1:$E$40,3,0) -> 56.43 | G39: 700 | H39: =F39*G39 -> 39501 | J39: 17 | K39: =VLOOKUP(D39,產線配置圖!$A$3:$C$39,3,0) -> 1406 | L39: =K39/J39 -> 82.705882 | M39: 13 | N39: =G39/W39*60 -> 1050 | O39: =N39/M39 -> 80.769231 | P39: =M39-J39 -> -4 | Q39: =O39-L39 -> -1.9366516 | R39: =O39/L39 -> 0.97658387 | T39: 0.42708333 | U39: 0.45486111 | V39: =(T39-U38)*24*60 -> 15 | W39: =(U39-T39)*24*60 -> 40 | AB39: =N39-K39 -> -356 | AC39: =N39/K39 -> 0.74679943
B40: 義大利麵 | D40: 南洋紅咖哩豬義大利麵 | F40: =VLOOKUP(D40,廠價表!$C$1:$E$40,3,0) -> 56.43 | G40: 898 | H40: =F40*G40 -> 50674.14 | J40: =VLOOKUP(D40,產線配置圖!$A$3:$C$39,2,0) -> 15 | K40: =VLOOKUP(D40,產線配置圖!$A$3:$C$39,3,0) -> 1636 | L40: =K40/J40 -> 109.06667 | M40: 13 | N40: =G40/W40*60 -> 1077.6 | O40: =N40/M40 -> 82.892308 | P40: =M40-J40 -> -2 | Q40: =O40-L40 -> -26.174359 | R40: =O40/L40 -> 0.76001505 | T40: 0.47569444 | U40: 0.51041667 | V40: =(T40-U39)*24*60 -> 30 | W40: =(U40-T40)*24*60 -> 50 | Z40: 生產數量少 | AB40: =N40-K40 -> -558.4 | AC40: =N40/K40 -> 0.65867971
...

Sheet 1202總
B1: 長家廠組合室生產人時性分析
B3: 日期 | D3: 45993 | F3: 訂單量 | G3: ='1202'!E1 -> 49146 | I3: 營業額 | J3: ='1202'!G1 -> 2383910.6
B4: 項目 | D4: 3 | F4: ➀ | H4: ➁ | J4: ③
B5: 人時性 | D5: 組合室 | F5: 全溫層 | H5: 義大利麵 | J5: 袋裝小吃、義麵
D6: 排關平均 | F6: =AVERAGE(D13:J13) -> 116.75455 | H6: =AVERAGE(D13:H13) -> 114.52373 | J6: =AVERAGE(I13:J13) -> 127.90865
D7: 實績平均 | F7: =AVERAGE(D14:J14) -> 99.626736 | H7: =AVERAGE(D14:H14) -> 96.125353 | J7: =AVERAGE(I14:J14) -> 117.13365
D8: 達成率平均 | F8: =AVERAGE(D15:J15) -> 0.85422385 | H8: =AVERAGE(D15:H15) -> 0.84191659 | J8: =AVERAGE(I15:J15) -> 0.91576016 | L8: ※現行日本鮮食廠以達成率80%為基本(即為現行KPI)
B10: 溫層 | D10: 4度C-各編組展開
B11: 編組 | D11: 1 | E11: 2 | F11: 3 | G11: 4 | H11: 5 | I11: 6 | J11: 7
D12: 自動1線 | E12: 自動2線 | F12: 手工3線 | G12: 手工4線 | H12: 手工5線 | I12: 調理包1線 | J12: 調理包2線
B13: 人時性 | C13: 排關 | D13: =VALUE('1202'!L15) -> 136.91288 | E13: =VALUE('1202'!L26) -> 160.58974 | F13: =VALUE('1202'!L37) -> 92.250817 | G13: =VALUE('1202'!L48) -> 94.813971 | H13: =VALUE('1202'!L58) -> 88.051256 | I13: =VALUE('1202'!L69) -> 127.90865
C14: 實績 | D14: =VALUE('1202'!O15) -> 106.96632 | E14: =VALUE('1202'!O26) -> 139.51299 | F14: =VALUE('1202'!O37) -> 83.303881 | G14: =VALUE('1202'!O48) -> 69.863126 | H14: =VALUE('1202'!O58) -> 80.980449 | I14: =VALUE('1202'!O69) -> 117.13365
C15: 達成率 | D15: =D14/D13 -> 0.78127286 | E15: =E14/E13 -> 0.86875406 | F15: =F14/F13 -> 0.9030151 | G15: =G14/G13 -> 0.73684422 | H15: =H14/H13 -> 0.9196967 | I15: =I14/I13 -> 0.91576016
B16: 作業 時間 | C16: 開始 | D16: ='1202'!T5 -> 0.29027778 | E16: ='1202'!T16 -> 0.29027778 | F16: ='1202'!T27 -> 0.29166667 | G16: ='1202'!T38 -> 0.29166667 | H16: ='1202'!T49 -> 0.29166667 | I16: ='1202'!T59 -> 0.29027778
C17: 結束 | D17: 0.61875 | E17: 0.64027778 | F17: 0.61805556 | G17: 0.60416667 | H17: 0.62916667 | I17: 0.56944444
B18: 配置人數 | D18: =VALUE('1202'!M15) -> 14.2 | E18: =VALUE('1202'!M26) -> 12.6 | F18: =VALUE('1202'!M37) -> 15.25 | G18: =VALUE('1202'!M48) -> 13.5 | H18: =VALUE('1202'!M58) -> 17.5 | I18: =VALUE('1202'!M69) -> 12.25
B19: 主要應用設備 | D19: ET-600 | E19: ET-600 | F19: ET-55 | G19: ET-55 | H19: ET-55 | I19: 八爪機
B20: 次要應用設備 | H20: 封口機
B21: 備註

Sheet 1202
A1: 長家廠4度C日報分析 | D1: 總生產量 | E1: =SUM(G5:G79) -> 49146 | F1: 營業額 | G1: =SUM(H5:H79) -> 2383910.6 | H1: 出勤人數 | I1: =M15+M26+M48+M58+M69+M79+M37 -> 85.3 | J1: 產線配置圖 | M1: 生產實績 | P1: 人時性差異分析 | T1: 日報登錄 | Z1: 分析說明 | AB1: 產能差異分析
A2: 12月02日 星期二 | D2: 人時性 | E2: =AVERAGE(O15,O26,O37,O48,O58,O69,O79) -> 99.626736 | F2: 平均廠價 | G2: =G1/E1 -> 48.506706 | H2: 多次生產數 | I2: =COUNT(I5:I79) -> 0
A3: 線別 | B3: 品類 | D3: 品名 | F3: 廠價 | G3: 生產量 | H3: 營收 | I3: 多次 生產 | J3: 人數 | K3: 產能/時 | L3: 人時性 | M3: 人數 | N3: 產能/時 | O3: 人時性 | P3: 人數 | Q3: 人時性 | R3: 達成率 | S3: 達成率平均 | T3: 生產時間 | V3: 前置、換線時間/分 | W3: 稼動時間/分 | X3: 休息時間 | AB3: 產能/時 | AC3: 達成率 | AD3: 達成率平均
T4: 開始 | U4: 結束 | X4: 開始 | Y4: 結束
A5: 自動一線 (ET-600) | B5: =VLOOKUP(D5,廠價表!$C$1:$E$40,2,0) -> 義大利麵 | D5: 白酒蛤蜊義大利麵 | F5: =VLOOKUP(D5,廠價表!$C$1:$E$40,3,0) -> 57.21 | G5: 1525 | H5: =F5*G5 -> 87245.25 | J5: =VLOOKUP(D5,產線配置圖!$A$3:$C$39,2,0) -> 13 | K5: =VLOOKUP(D5,產線配置圖!$A$3:$C$39,3,0) -> 2105 | L5: =K5/J5 -> 161.92308 | M5: 13 | N5: =G5/W5*60 -> 1759.6154 | O5: =N5/M5 -> 135.35503 | P5: =M5-J5 -> 0 | Q5: =O5-L5 -> -26.568047 | R5: =O5/L5 -> 0.8359218 | S5: =R15 -> 0.78127286 | T5: 0.29027778 | U5: 0.32638889 | W5: =(U5-T5)*24*60 -> 52 | AB5: =N5-K5 -> -345.38462 | AC5: =N5/K5 -> 0.8359218 | AD5: =AC15 -> 0.77390086
B6: =VLOOKUP(D6,廠價表!$C$1:$E$40,2,0) -> 義大利麵 | D6: 韓式起司炸雞義大利麵 | F6: =VLOOKUP(D6,廠價表!$C$1:$E$40,3,0) -> 57.21 | G6: 1830 | H6: =F6*G6 -> 104694.3 | J6: =VLOOKUP(D6,產線配置圖!$A$3:$C$39,2,0) -> 17 | K6: 1800 | L6: =K6/J6 -> 105.88235 | M6: 17 | N6: =G6/W6*60 -> 1525 | O6: =N6/M6 -> 89.705882 | P6: =M6-J6 -> 0 | Q6: =O6-L6 -> -16.176471 | R6: =O6/L6 -> 0.84722222 | T6: 0.33402778 | U6: 0.38402778 | V6: =(T6-U5)*24*60 -> 11 | W6: =(U6-T6)*24*60 -> 72 | AB6: =N6-K6 -> -275 | AC6: =N6/K6 -> 0.84722222
B7: =VLOOKUP(D7,廠價表!$C$1:$E$40,2,0) -> 義大利麵 | D7: 奶油培根義大利麵 | F7: =VLOOKUP(D7,廠價表!$C$1:$E$40,3,0) -> 49.14 | G7: 4077 | H7: =F7*G7 -> 200343.78 | J7: =VLOOKUP(D7,產線配置圖!$A$3:$C$39,2,0) -> 13 | K7: =VLOOKUP(D7,產線配置圖!$A$3:$C$39,3,0) -> 2000 | L7: =K7/J7 -> 153.84615 | M7: 13 | N7: =G7/W7*60 -> 1881.6923 | O7: =N7/M7 -> 144.74556 | P7: =M7-J7 -> 0 | Q7: =O7-L7 -> -9.1005917 | R7: =O7/L7 -> 0.94084615 | T7: 0.3875 | U7: 0.47777778 | V7: =(T7-U6)*24*60 -> 5 | W7: =(U7-T7)*24*60 -> 130 | AB7: =N7-K7 -> -118.30769 | AC7: =N7/K7 -> 0.94084615
B8: =VLOOKUP(D8,廠價表!$C$1:$E$40,2,0) -> 義大利麵 | D8: 奶油培根義大利麵 | F8: =VLOOKUP(D8,廠價表!$C$1:$E$40,3,0) -> 49.14 | G8: 1369 | H8: =F8*G8 -> 67272.66 | J8: =VLOOKUP(D8,產線配置圖!$A$3:$C$39,2,0) -> 13 | K8: =VLOOKUP(D8,產線配置圖!$A$3:$C$39,3,0) -> 2000 | L8: =K8/J8 -> 153.84615 | M8: 13 | N8: =G8/W8*60 -> 1676.3265 | O8: =N8/M8 -> 128.94819 | P8: =M8-J8 -> 0 | Q8: =O8-L8 -> -24.897959 | R8: =O8/L8 -> 0.83816327 | T8: 0.54027778 | U8: 0.57430556 | V8: =(T8-U7)*24*60 -> 90 | W8: =(U8-T8)*24*60 -> 49 | AB8: =N8-K8 -> -323.67347 | AC8: =N8/K8 -> 0.83816327
B9: =VLOOKUP(D9,廠價表!$C$1:$E$40,2,0) -> 義大利麵 | D9: 南洋紅咖哩豬義大利麵 | F9: =VLOOKUP(D9,廠價表!$C$1:$E$40,3,0) -> 56.43 | G9: 469 | H9: =F9*G9 -> 26465.67 | J9: =VLOOKUP(D9,產線配置圖!$A$3:$C$39,2,0) -> 15 | K9: =VLOOKUP(D9,產線配置圖!$A$3:$C$39,3,0) -> 1636 | L9: =K9/J9 -> 109.06667 | M9: 15 | N9: =G9/W9*60 -> 541.15385 | O9: =N9/M9 -> 36.076923 | P9: =M9-J9 -> 0 | Q9: =O9-L9 -> -72.989744 | R9: =O9/L9 -> 0.33077863 | T9: 0.58263889 | U9: 0.61875 | V9: =(T9-U8)*24*60 -> 12 | W9: =(U9-T9)*24*60 -> 52 | X9: 0.48958333 | Y9: 0.53125 | Z9: 生產數量少 | AB9: =N9-K9 -> -1094.8462 | AC9: =N9/K9 -> 0.33077863
W10: =(U10-T10)*24*60 -> 0
H11: =F11*G11 -> 0 | W11: =(U11-T11)*24*60 -> 0
H12: =F12*G12 -> 0 | W12: =(U12-T12)*24*60 -> 0
W13: =(U13-T13)*24*60 -> 0
W14: =(U14-T14)*24*60 -> 0
C15: 4度一組 | D15: 平均 | J15: =AVERAGE(J5:J14) -> 14.2 | K15: =AVERAGE(K5:K14) -> 1908.2 | L15: =AVERAGE(L5:L14) -> 136.91288 | M15: =AVERAGE(M5:M14) -> 14.2 | N15: =AVERAGE(N5:N14) -> 1476.7576 | O15: =AVERAGE(O5:O14) -> 106.96632 | P15: =M15-J15 -> 0 | Q15: =O15-L15 -> -29.946562 | R15: =O15/L15 -> 0.78127286 | AB15: =N15-K15 -> -431.44239 | AC15: =N15/K15 -> 0.77390086
A16: 自動二線 (ET-600) | B16: =VLOOKUP(D16,廠價表!$C$1:$E$40,2,0) -> 義大利麵 | D16: 白酒蛤蜊義大利麵 | F16: =VLOOKUP(D16,廠價表!$C$1:$E$40,3,0) -> 57.21 | G16: 1325 | H16: =F16*G16 -> 75803.25 | J16: =VLOOKUP(D16,產線配置圖!$A$3:$C$39,2,0) -> 13 | K16: =VLOOKUP(D16,產線配置圖!$A$3:$C$39,3,0) -> 2105 | L16: =K16/J16 -> 161.92308 | M16: 13 | N16: =G16/W16*60 -> 1691.4894 | O16: =N16/M16 -> 130.11457 | P16: =M16-J16 -> 0 | Q16: =O16-L16 -> -31.808511 | R16: =O16/L16 -> 0.80355789 | S16: =R26 -> 0.86875406 | T16: 0.29027778 | U16: 0.32291667 | W16: =(U16-T16)*24*60 -> 47 | AB16: =N16-K16 -> -413.51064 | AC16: =N16/K16 -> 0.80355789 | AD16: =AC26 -> 0.86876574
B17: =VLOOKUP(D17,廠價表!$C$1:$E$40,2,0) -> 義大利麵 | D17: 青醬蛤蜊義大利麵 | F17: =VLOOKUP(D17,廠價表!$C$1:$E$40,3,0) -> 50.67 | G17: 2808 | H17: =F17*G17 -> 142281.36 | J17: =VLOOKUP(D17,產線配置圖!$A$3:$C$39,2,0) -> 13 | K17: =VLOOKUP(D17,產線配置圖!$A$3:$C$39,3,0) -> 2000 | L17: =K17/J17 -> 153.84615 | M17: 13 | N17: =G17/W17*60 -> 1893.0337 | O17: =N17/M17 -> 145.61798 | P17: =M17-J17 -> 0 | Q17: =O17-L17 -> -8.2281763 | R17: =O17/L17 -> 0.94651685 | T17: 0.33333333 | U17: 0.39513889 | V17: =(T17-U16)*24*60 -> 15 | W17: =(U17-T17)*24*60 -> 89 | AB17: =N17-K17 -> -106.96629 | AC17: =N17/K17 -> 0.94651685
B18: =VLOOKUP(D18,廠價表!$C$1:$E$40,2,0) -> 義大利麵 | D18: 義式蕃茄起司義大利麵 | F18: =VLOOKUP(D18,廠價表!$C$1:$E$40,3,0) -> 50.39 | G18: 3101 | H18: =F18*G18 -> 156259.39 | J18: =VLOOKUP(D18,產線配置圖!$A$3:$C$39,2,0) -> 12 | K18: =VLOOKUP(D18,產線配置圖!$A$3:$C$39,3,0) -> 2000 | L18: =K18/J18 -> 166.66667 | M18: 12 | N18: =G18/W18*60 -> 1772 | O18: =N18/M18 -> 147.66667 | P18: =M18-J18 -> 0 | Q18: =O18-L18 -> -19 | R18: =O18/L18 -> 0.886 | T18: 0.40625 | U18: 0.47916667 | V18: =(T18-U17)*24*60 -> 16 | W18: =(U18-T18)*24*60 -> 105 | AB18: =N18-K18 -> -228 | AC18: =N18/K18 -> 0.886
B19: =VLOOKUP(D19,廠價表!$C$1:$E$40,2,0) -> 義大利麵 | D19: 義式蕃茄起司義大利麵 | F19: =VLOOKUP(D19,廠價表!$C$1:$E$40,3,0) -> 50.39 | G19: 2127 | H19: =F19*G19 -> 107179.53 | J19: =VLOOKUP(D19,產線配置圖!$A$3:$C$39,2,0) -> 12 | K19: =VLOOKUP(D19,產線配置圖!$A$3:$C$39,3,0) -> 2000 | L19: =K19/J19 -> 166.66667 | M19: 12 | N19: =G19/W19*60 -> 1701.6 | O19: =N19/M19 -> 141.8 | P19: =M19-J19 -> 0 | Q19: =O19-L19 -> -24.866667 | R19: =O19/L19 -> 0.8508 | T19: 0.54166667 | U19: 0.59375 | V19: =(T19-U18)*24*60 -> 90 | W19: =(U19-T19)*24*60 -> 75 | X19: 0.48958333 | Y19: 0.53125 | AB19: =N19-K19 -> -298.4 | AC19: =N19/K19 -> 0.8508
B20: =VLOOKUP(D20,廠價表!$C$1:$E$40,2,0) -> 義大利麵 | D20: 青醬蛤蜊義大利麵 | F20: =VLOOKUP(D20,廠價表!$C$1:$E$40,3,0) -> 50.67 | G20: 1520 | H20: =F20*G20 -> 77018.4 | J20: =VLOOKUP(D20,產線配置圖!$A$3:$C$39,2,0) -> 13 | K20: =VLOOKUP(D20,產線配置圖!$A$3:$C$39,3,0) -> 2000 | L20: =K20/J20 -> 153.84615 | M20: 13 | N20: =G20/W20*60 -> 1720.7547 | O20: =N20/M20 -> 132.36575 | P20: =M20-J20 -> 0 | Q20: =O20-L20 -> -21.480406 | R20: =O20/L20 -> 0.86037736 | T20: 0.60347222 | U20: 0.64027778 | V20: =(T20-U19)*24*60 -> 14 | W20: =(U20-T20)*24*60 -> 53 | AB20: =N20-K20 -> -279.24528 | AC20: =N20/K20 -> 0.86037736
W21: =(U21-T21)*24*60 -> 0
H22: =F22*G22 -> 0 | W22: 0
W23: =(U23-T23)*24*60 -> 0
H24: =F24*G24 -> 0 | W24: =(U24-T24)*24*60 -> 0
H25: =F25*G25 -> 0 | W25: =(U25-T25)*24*60 -> 0
C26: 4度二組A | D26: 平均 | J26: =AVERAGE(J16:J25) -> 12.6 | K26: =AVERAGE(K16:K25) -> 2021 | L26: =AVERAGE(L16:L25) -> 160.58974 | M26: =AVERAGE(M16:M25) -> 12.6 | N26: =AVERAGE(N16:N25) -> 1755.7756 | O26: =AVERAGE(O16:O25) -> 139.51299 | P26: =M26-J26 -> 0 | Q26: =O26-L26 -> -21.076752 | R26: =O26/L26 -> 0.86875406 | AB26: =N26-K26 -> -265.22444 | AC26: =N26/K26 -> 0.86876574
A27: 手工三線 (ET-55) | B27: 義大利麵 | D27: 青花椒麻雞肉拌麵 | F27: =VLOOKUP(D27,廠價表!$C$1:$E$40,3,0) -> 49.91 | G27: 1620 | H27: =F27*G27 -> 80854.2 | J27: =VLOOKUP(D27,產線配置圖!$A$3:$C$39,2,0) -> 17 | K27: =VLOOKUP(D27,產線配置圖!$A$3:$C$39,3,0) -> 1565 | L27: =K27/J27 -> 92.058824 | M27: 15 | N27: =G27/W27*60 -> 1262.3377 | O27: =N27/M27 -> 84.155844 | P27: =M27-J27 -> -2 | Q27: =O27-L27 -> -7.9029794 | R27: =O27/L27 -> 0.91415294 | S27: =R37 -> 0.9030151 | T27: 0.29166667 | U27: 0.34513889 | W27: =(U27-T27)*24*60 -> 77 | AB27: =N27-K27 -> -302.66234 | AC27: =N27/K27 -> 0.80660554 | AD27: =AC37 -> 0.85120961
B28: =VLOOKUP(D28,廠價表!$C$1:$E$40,2,0) -> 義大利麵 | D28: 奶油蒜香雞義大利麵 | F28: =VLOOKUP(D28,廠價表!$C$1:$E$40,3,0) -> 55.13 | G28: 1861 | H28: =F28*G28 -> 102596.93 | J28: =VLOOKUP(D28,產線配置圖!$A$3:$C$39,2,0) -> 18 | K28: =VLOOKUP(D28,產線配置圖!$A$3:$C$39,3,0) -> 1385 | L28: =K28/J28 -> 76.944444 | M28: 16 | N28: =G28/W28*60 -> 1063.4286 | O28: =N28/M28 -> 66.464286 | P28: =M28-J28 -> -2 | Q28: =O28-L28 -> -10.480159 | R28: =O28/L28 -> 0.86379577 | T28: 0.35416667 | U28: 0.42708333 | V28: =(T28-U27)*24*60 -> 13 | W28: =(U28-T28)*24*60 -> 105 | AB28: =N28-K28 -> -321.57143 | AC28: =N28/K28 -> 0.76781846
B29: =VLOOKUP(D29,廠價表!$C$1:$E$40,2,0) -> 義大利麵 | D29: 奶油起司蝦仁通心粉 | F29: =VLOOKUP(D29,廠價表!$C$1:$E$40,3,0) -> 47.71 | G29: 1367 | H29: =F29*G29 -> 65219.57 | J29: =VLOOKUP(D29,產線配置圖!$A$3:$C$39,2,0) -> 15 | K29: =VLOOKUP(D29,產線配置圖!$A$3:$C$39,3,0) -> 1500 | L29: =K29/J29 -> 100 | M29: 15 | N29: =G29/W29*60 -> 1281.5625 | O29: =N29/M29 -> 85.4375 | P29: =M29-J29 -> 0 | Q29: =O29-L29 -> -14.5625 | R29: =O29/L29 -> 0.854375 | T29: 0.43611111 | U29: 0.48055556 | V29: =(T29-U28)*24*60 -> 13 | W29: =(U29-T29)*24*60 -> 64 | AB29: =N29-K29 -> -218.4375 | AC29: =N29/K29 -> 0.854375
B30: =VLOOKUP(D30,廠價表!$C$1:$E$40,2,0) -> 義大利麵 | D30: 奶油起司蝦仁通心粉 | F30: =VLOOKUP(D30,廠價表!$C$1:$E$40,3,0) -> 47.71 | G30: 2769 | H30: =F30*G30 -> 132108.99 | J30: =VLOOKUP(D30,產線配置圖!$A$3:$C$39,2,0) -> 15 | K30: =VLOOKUP(D30,產線配置圖!$A$3:$C$39,3,0) -> 1500 | L30: =K30/J30 -> 100 | M30: 15 | N30: =G30/W30*60 -> 1457.3684 | O30: =N30/M30 -> 97.157895 | P30: =M30-J30 -> 0 | Q30: =O30-L30 -> -2.8421053 | R30: =O30/L30 -> 0.97157895 | T30: 0.53888889 | U30: 0.61805556 | V30: =(T30-U29)*24*60 -> 84 | W30: =(U30-T30)*24*60 -> 114 | X30: 0.48958333 | Y30: 0.53125 | AB30: =N30-K30 -> -42.631579 | AC30: =N30/K30 -> 0.97157895
W31: =(U31-T31)*24*60 -> 0
W32: =(U32-T32)*24*60 -> 0
H33: =F33*G33 -> 0 | W33: =(U33-T33)*24*60 -> 0
H34: =F34*G34 -> 0 | W34: =(U34-T34)*24*60 -> 0
H35: =F35*G35 -> 0 | W35: =(U35-T35)*24*60 -> 0
H36: =F36*G36 -> 0 | W36: =(U36-T36)*24*60 -> 0
C37: 4度二組B | D37: 平均 | J37: =AVERAGE(J27:J36) -> 16.25 | K37: =AVERAGE(K27:K36) -> 1487.5 | L37: =AVERAGE(L27:L36) -> 92.250817 | M37: =AVERAGE(M27:M36) -> 15.25 | N37: =AVERAGE(N27:N36) -> 1266.1743 | O37: =AVERAGE(O27:O36) -> 83.303881 | P37: =M37-J37 -> -1 | Q37: =N37-K37 -> -221.32571 | R37: =O37/L37 -> 0.9030151 | AB37: =N37-K37 -> -221.32571 | AC37: =N37/K37 -> 0.85120961
A38: 手工四線 (ET-55) | B38: 義大利麵 | D38: 焗烤明太子筆尖麵 | F38: =VLOOKUP(D38,廠價表!$C$1:$E$40,3,0) -> 57.3 | G38: 2334 | H38: =F38*G38 -> 133738.2 | J38: 16 | K38: 1500 | L38: =K38/J38 -> 93.75 | M38: 14 | N38: =G38/W38*60 -> 933.6 | O38: =N38/M38 -> 66.685714 | P38: =M38-J38 -> -2 | Q38: =O38-L38 -> -27.064286 | R38: =O38/L38 -> 0.71131429 | S38: =R48 -> 0.73684422 | T38: 0.29166667 | U38: 0.39583333 | W38: =(U38-T38)*24*60 -> 150 | Z38: L型封膜機異常 | AB38: =N38-K38 -> -566.4 | AC38: =N38/K38 -> 0.6224 | AD38: =AC48 -> 0.63178446
B39: 義大利麵 | D39: 濃拿坡里義大利麵 | F39: =VLOOKUP(D39,廠價表!$C$1:$E$40,3,0) -> 56.43 | G39: 1095 | H39: =F39*G39 -> 61790.85 | J39: 17 | K39: =VLOOKUP(D39,產線配置圖!$A$3:$C$39,3,0) -> 1406 | L39: =K39/J39 -> 82.705882 | M39: 13 | N39: =G39/W39*60 -> 811.11111 | O39: =N39/M39 -> 62.393162 | P39: =M39-J39 -> -4 | Q39: =O39-L39 -> -20.31272 | R39: =O39/L39 -> 0.75439812 | T39: 0.39930556 | U39: 0.45555556 | V39: =(T39-U38)*24*60 -> 5 | W39: =(U39-T39)*24*60 -> 81 | Z39: L型封膜機異常 | AB39: =N39-K39 -> -594.88889 | AC39: =N39/K39 -> 0.57689268
B40: 義大利麵 | D40: 南洋紅咖哩豬義大利麵 | F40: =VLOOKUP(D40,廠價表!$C$1:$E$40,3,0) -> 56.43 | G40: 838 | H40: =F40*G40 -> 47288.34 | J40: =VLOOKUP(D40,產線配置圖!$A$3:$C$39,2,0) -> 15 | K40: =VLOOKUP(D40,產線配置圖!$A$3:$C$39,3,0) -> 1636 | L40: =K40/J40 -> 109.06667 | M40: 13 | N40: =G40/W40*60 -> 1197.1429 | O40: =N40/M40 -> 92.087912 | P40: =M40-J40 -> -2 | Q40: =O40-L40 -> -16.978755 | R40: =O40/L40 -> 0.84432682 | T40: 0.46180556 | U40: 0.49097222 | V40: =(T40-U39)*24*60 -> 9 | W40: =(U40-T40)*24*60 -> 42 | AB40: =N40-K40 -> -438.85714 | AC40: =N40/K40 -> 0.73174991
...

Sheet 1203總 
B1: 長家廠組合室生產人時性分析
B3: 日期 | D3: 45994 | F3: 訂單量 | G3: ='1203'!E1 -> 45862 | I3: 營業額 | J3: ='1203'!G1 -> 2223447.2
B4: 項目 | D4: 3 | F4: ➀ | H4: ➁ | J4: ③
B5: 人時性 | D5: 組合室 | F5: 全溫層 | H5: 義大利麵 | J5: 袋裝小吃、義麵
D6: 排關平均 | F6: =AVERAGE(D13:J13) -> 116.69565 | H6: =AVERAGE(D13:H13) -> 114.75401 | J6: =AVERAGE(I13:J13) -> 126.40385
D7: 實績平均 | F7: =AVERAGE(D14:J14) -> 90.85517 | H7: =AVERAGE(D14:H14) -> 89.849163 | J7: =AVERAGE(I14:J14) -> 95.885208
D8: 達成率平均 | F8: =AVERAGE(D15:J15) -> 0.77292091 | H8: =AVERAGE(D15:H15) -> 0.7757926 | J8: =AVERAGE(I15:J15) -> 0.75856242 | L8: ※現行日本鮮食廠以達成率80%為基本(即為現行KPI)
B10: 溫層 | D10: 4度C-各編組展開
B11: 編組 | D11: 1 | E11: 2 | F11: 3 | G11: 4 | H11: 5 | I11: 6 | J11: 7
D12: 自動1線 | E12: 自動2線 | F12: 手工3線 | G12: 手工4線 | H12: 手工5線 | I12: 調理包1線 | J12: 調理包2線
B13: 人時性 | C13: 排關 | D13: =VALUE('1203'!L15) -> 136.91288 | E13: =VALUE('1203'!L26) -> 162.27564 | F13: =VALUE('1203'!L37) -> 92.212418 | G13: =VALUE('1203'!L48) -> 94.317843 | H13: =VALUE('1203'!L58) -> 88.051256 | I13: =VALUE('1203'!L69) -> 126.40385
C14: 實績 | D14: =VALUE('1203'!O15) -> 97.725065 | E14: =VALUE('1203'!O26) -> 144.08491 | F14: =VALUE('1203'!O37) -> 62.117995 | G14: =VALUE('1203'!O48) -> 61.932876 | H14: =VALUE('1203'!O58) -> 83.384971 | I14: =VALUE('1203'!O69) -> 95.885208
C15: 達成率 | D15: =D14/D13 -> 0.71377554 | E15: =E14/E13 -> 0.88790226 | F15: =F14/F13 -> 0.67364023 | G15: =G14/G13 -> 0.65664008 | H15: =H14/H13 -> 0.9470049 | I15: =I14/I13 -> 0.75856242
B16: 作業 時間 | C16: 開始 | D16: ='1203'!T5 -> 0.29027778 | E16: ='1203'!T16 -> 0.29027778 | F16: ='1203'!T27 -> 0.29166667 | G16: ='1203'!T38 -> 0.33333333 | H16: ='1203'!T49 -> 0.29027778 | I16: ='1203'!T59 -> 0.29166667
C17: 結束 | D17: 0.70833333 | E17: 0.59583333 | F17: 0.64583333 | G17: 0.63680556 | H17: 0.63055556 | I17: 0.62152778
B18: 配置人數 | D18: =VALUE('1203'!M15) -> 14.2 | E18: =VALUE('1203'!M26) -> 12.5 | F18: =VALUE('1203'!M37) -> 15.4 | G18: =VALUE('1203'!M48) -> 15 | H18: =VALUE('1203'!M58) -> 16.5 | I18: =VALUE('1203'!M69) -> 12.4
B19: 主要應用設備 | D19: ET-600 | E19: ET-600 | F19: ET-55 | G19: ET-55 | H19: ET-55 | I19: 八爪機
B20: 次要應用設備 | H20: 封口機
B21: 備註

Sheet 1203
A1: 長家廠4度C日報分析 | D1: 總生產量 | E1: =SUM(G5:G79) -> 45862 | F1: 營業額 | G1: =SUM(H5:H79) -> 2223447.2 | H1: 出勤人數 | I1: =M15+M26+M48+M58+M69+M79+M37 -> 86 | J1: 產線配置圖 | M1: 生產實績 | P1: 人時性差異分析 | T1: 日報登錄 | Z1: 分析說明 | AB1: 產能差異分析
A2: 12月03日 星期三 | D2: 人時性 | E2: =AVERAGE(O15,O26,O37,O48,O58,O69,O79) -> 90.85517 | F2: 平均廠價 | G2: =G1/E1 -> 48.481253 | H2: 多次生產數 | I2: =COUNT(I5:I79) -> 0
A3: 線別 | B3: 品類 | D3: 品名 | F3: 廠價 | G3: 生產量 | H3: 營收 | I3: 多次 生產 | J3: 人數 | K3: 產能/時 | L3: 人時性 | M3: 人數 | N3: 產能/時 | O3: 人時性 | P3: 人數 | Q3: 人時性 | R3: 達成率 | S3: 達成率平均 | T3: 生產時間 | V3: 前置、換線時間/分 | W3: 稼動時間/分 | X3: 休息時間 | AB3: 產能/時 | AC3: 達成率 | AD3: 達成率平均
T4: 開始 | U4: 結束 | X4: 開始 | Y4: 結束
A5: 自動一線 (ET-600) | B5: =VLOOKUP(D5,廠價表!$C$1:$E$40,2,0) -> 義大利麵 | D5: 白酒蛤蜊義大利麵 | F5: =VLOOKUP(D5,廠價表!$C$1:$E$40,3,0) -> 57.21 | G5: 1421 | H5: =F5*G5 -> 81295.41 | J5: =VLOOKUP(D5,產線配置圖!$A$3:$C$39,2,0) -> 13 | K5: =VLOOKUP(D5,產線配置圖!$A$3:$C$39,3,0) -> 2105 | L5: =K5/J5 -> 161.92308 | M5: 13 | N5: =G5/W5*60 -> 1776.25 | O5: =N5/M5 -> 136.63462 | P5: =M5-J5 -> 0 | Q5: =O5-L5 -> -25.288462 | R5: =O5/L5 -> 0.84382423 | S5: =R15 -> 0.71377554 | T5: 0.29027778 | U5: 0.32361111 | W5: =(U5-T5)*24*60 -> 48 | AB5: =N5-K5 -> -328.75 | AC5: =N5/K5 -> 0.84382423 | AD5: =AC15 -> 0.71878282
B6: =VLOOKUP(D6,廠價表!$C$1:$E$40,2,0) -> 義大利麵 | D6: 韓式起司炸雞義大利麵 | F6: =VLOOKUP(D6,廠價表!$C$1:$E$40,3,0) -> 57.21 | G6: 1773 | H6: =F6*G6 -> 101433.33 | J6: =VLOOKUP(D6,產線配置圖!$A$3:$C$39,2,0) -> 17 | K6: 1800 | L6: =K6/J6 -> 105.88235 | M6: 17 | N6: =G6/W6*60 -> 1611.8182 | O6: =N6/M6 -> 94.812834 | P6: =M6-J6 -> 0 | Q6: =O6-L6 -> -11.069519 | R6: =O6/L6 -> 0.89545455 | T6: 0.33888889 | U6: 0.38472222 | V6: =(T6-U5)*24*60 -> 22 | W6: =(U6-T6)*24*60 -> 66 | AB6: =N6-K6 -> -188.18182 | AC6: =N6/K6 -> 0.89545455
B7: =VLOOKUP(D7,廠價表!$C$1:$E$40,2,0) -> 義大利麵 | D7: 奶油培根義大利麵 | F7: =VLOOKUP(D7,廠價表!$C$1:$E$40,3,0) -> 49.14 | G7: 1095 | H7: =F7*G7 -> 53808.3 | J7: =VLOOKUP(D7,產線配置圖!$A$3:$C$39,2,0) -> 13 | K7: =VLOOKUP(D7,產線配置圖!$A$3:$C$39,3,0) -> 2000 | L7: =K7/J7 -> 153.84615 | M7: 13 | N7: =G7/W7*60 -> 529.83871 | O7: =N7/M7 -> 40.756824 | P7: =M7-J7 -> 0 | Q7: =O7-L7 -> -113.08933 | R7: =O7/L7 -> 0.26491935 | T7: 0.39236111 | U7: 0.47847222 | V7: =(T7-U6)*24*60 -> 11 | W7: =(U7-T7)*24*60 -> 124 | Z7: 商品傾倒報廢2040 | AB7: =N7-K7 -> -1470.1613 | AC7: =N7/K7 -> 0.26491935
B8: =VLOOKUP(D8,廠價表!$C$1:$E$40,2,0) -> 義大利麵 | D8: 南洋紅咖哩豬義大利麵 | F8: =VLOOKUP(D8,廠價表!$C$1:$E$40,3,0) -> 56.43 | G8: 601 | H8: =F8*G8 -> 33914.43 | J8: =VLOOKUP(D8,產線配置圖!$A$3:$C$39,2,0) -> 15 | K8: =VLOOKUP(D8,產線配置圖!$A$3:$C$39,3,0) -> 1636 | L8: =K8/J8 -> 109.06667 | M8: 15 | N8: =G8/W8*60 -> 948.94737 | O8: =N8/M8 -> 63.263158 | P8: =M8-J8 -> 0 | Q8: =O8-L8 -> -45.803509 | R8: =O8/L8 -> 0.58004118 | T8: 0.59930556 | U8: 0.62569444 | V8: =(T8-U7)*24*60 -> 174 | W8: =(U8-T8)*24*60 -> 38 | Z8: 生產數量少 | AB8: =N8-K8 -> -687.05263 | AC8: =N8/K8 -> 0.58004118
B9: =VLOOKUP(D9,廠價表!$C$1:$E$40,2,0) -> 義大利麵 | D9: 奶油培根義大利麵 | F9: =VLOOKUP(D9,廠價表!$C$1:$E$40,3,0) -> 49.14 | G9: 3783 | H9: =F9*G9 -> 185896.62 | J9: =VLOOKUP(D9,產線配置圖!$A$3:$C$39,2,0) -> 13 | K9: =VLOOKUP(D9,產線配置圖!$A$3:$C$39,3,0) -> 2000 | L9: =K9/J9 -> 153.84615 | M9: 13 | N9: =G9/W9*60 -> 1991.0526 | O9: =N9/M9 -> 153.15789 | P9: =M9-J9 -> 0 | Q9: =O9-L9 -> -0.68825911 | R9: =O9/L9 -> 0.99552632 | T9: 0.62916667 | U9: 0.70833333 | V9: =(T9-U8)*24*60 -> 5 | W9: =(U9-T9)*24*60 -> 114 | X9: 0.48958333 | Y9: 0.53125 | AB9: =N9-K9 -> -8.9473684 | AC9: =N9/K9 -> 0.99552632
W10: =(U10-T10)*24*60 -> 0
H11: =F11*G11 -> 0 | W11: =(U11-T11)*24*60 -> 0
H12: =F12*G12 -> 0 | W12: =(U12-T12)*24*60 -> 0
W13: =(U13-T13)*24*60 -> 0
W14: =(U14-T14)*24*60 -> 0
C15: 4度一組 | D15: 平均 | J15: =AVERAGE(J5:J14) -> 14.2 | K15: =AVERAGE(K5:K14) -> 1908.2 | L15: =AVERAGE(L5:L14) -> 136.91288 | M15: =AVERAGE(M5:M14) -> 14.2 | N15: =AVERAGE(N5:N14) -> 1371.5814 | O15: =AVERAGE(O5:O14) -> 97.725065 | P15: =M15-J15 -> 0 | Q15: =O15-L15 -> -39.187816 | R15: =O15/L15 -> 0.71377554 | AB15: =N15-K15 -> -536.61862 | AC15: =N15/K15 -> 0.71878282
A16: 自動二線 (ET-600) | B16: =VLOOKUP(D16,廠價表!$C$1:$E$40,2,0) -> 義大利麵 | D16: 白酒蛤蜊義大利麵 | F16: =VLOOKUP(D16,廠價表!$C$1:$E$40,3,0) -> 57.21 | G16: 1195 | H16: =F16*G16 -> 68365.95 | J16: =VLOOKUP(D16,產線配置圖!$A$3:$C$39,2,0) -> 13 | K16: =VLOOKUP(D16,產線配置圖!$A$3:$C$39,3,0) -> 2105 | L16: =K16/J16 -> 161.92308 | M16: 13 | N16: =G16/W16*60 -> 1707.1429 | O16: =N16/M16 -> 131.31868 | P16: =M16-J16 -> 0 | Q16: =O16-L16 -> -30.604396 | R16: =O16/L16 -> 0.81099423 | S16: =R26 -> 0.88790226 | T16: 0.29027778 | U16: 0.31944444 | W16: =(U16-T16)*24*60 -> 42 | AB16: =N16-K16 -> -397.85714 | AC16: =N16/K16 -> 0.81099423 | AD16: =AC26 -> 0.88829901
B17: =VLOOKUP(D17,廠價表!$C$1:$E$40,2,0) -> 義大利麵 | D17: 青醬蛤蜊義大利麵 | F17: =VLOOKUP(D17,廠價表!$C$1:$E$40,3,0) -> 50.67 | G17: 3959 | H17: =F17*G17 -> 200602.53 | J17: =VLOOKUP(D17,產線配置圖!$A$3:$C$39,2,0) -> 13 | K17: =VLOOKUP(D17,產線配置圖!$A$3:$C$39,3,0) -> 2000 | L17: =K17/J17 -> 153.84615 | M17: 13 | N17: =G17/W17*60 -> 1979.5 | O17: =N17/M17 -> 152.26923 | P17: =M17-J17 -> 0 | Q17: =O17-L17 -> -1.5769231 | R17: =O17/L17 -> 0.98975 | T17: 0.32986111 | U17: 0.41319444 | V17: =(T17-U16)*24*60 -> 15 | W17: =(U17-T17)*24*60 -> 120 | AB17: =N17-K17 -> -20.5 | AC17: =N17/K17 -> 0.98975
B18: =VLOOKUP(D18,廠價表!$C$1:$E$40,2,0) -> 義大利麵 | D18: 義式蕃茄起司義大利麵 | F18: =VLOOKUP(D18,廠價表!$C$1:$E$40,3,0) -> 50.39 | G18: 2318 | H18: =F18*G18 -> 116804.02 | J18: =VLOOKUP(D18,產線配置圖!$A$3:$C$39,2,0) -> 12 | K18: =VLOOKUP(D18,產線配置圖!$A$3:$C$39,3,0) -> 2000 | L18: =K18/J18 -> 166.66667 | M18: 12 | N18: =G18/W18*60 -> 1696.0976 | O18: =N18/M18 -> 141.34146 | P18: =M18-J18 -> 0 | Q18: =O18-L18 -> -25.325203 | R18: =O18/L18 -> 0.84804878 | T18: 0.42152778 | U18: 0.47847222 | V18: =(T18-U17)*24*60 -> 12 | W18: =(U18-T18)*24*60 -> 82 | AB18: =N18-K18 -> -303.90244 | AC18: =N18/K18 -> 0.84804878
B19: =VLOOKUP(D19,廠價表!$C$1:$E$40,2,0) -> 義大利麵 | D19: 義式蕃茄起司義大利麵 | F19: =VLOOKUP(D19,廠價表!$C$1:$E$40,3,0) -> 50.39 | G19: 2362 | H19: =F19*G19 -> 119021.18 | J19: =VLOOKUP(D19,產線配置圖!$A$3:$C$39,2,0) -> 12 | K19: =VLOOKUP(D19,產線配置圖!$A$3:$C$39,3,0) -> 2000 | L19: =K19/J19 -> 166.66667 | M19: 12 | N19: =G19/W19*60 -> 1816.9231 | O19: =N19/M19 -> 151.41026 | P19: =M19-J19 -> 0 | Q19: =O19-L19 -> -15.25641 | R19: =O19/L19 -> 0.90846154 | T19: 0.54166667 | U19: 0.59583333 | V19: =(T19-U18)*24*60 -> 91 | W19: =(U19-T19)*24*60 -> 78 | X19: 0.48958333 | Y19: 0.53125 | AB19: =N19-K19 -> -183.07692 | AC19: =N19/K19 -> 0.90846154
W20: =(U20-T20)*24*60 -> 0 | AB20: =N20-K20 -> 0 | AC20: =N20/K20 -> #DIV/0!
W21: =(U21-T21)*24*60 -> 0
H22: =F22*G22 -> 0 | W22: 0
W23: =(U23-T23)*24*60 -> 0
H24: =F24*G24 -> 0 | W24: =(U24-T24)*24*60 -> 0
H25: =F25*G25 -> 0 | W25: =(U25-T25)*24*60 -> 0
C26: 4度二組A | D26: 平均 | J26: =AVERAGE(J16:J25) -> 12.5 | K26: =AVERAGE(K16:K25) -> 2026.25 | L26: =AVERAGE(L16:L25) -> 162.27564 | M26: =AVERAGE(M16:M25) -> 12.5 | N26: =AVERAGE(N16:N25) -> 1799.9159 | O26: =AVERAGE(O16:O25) -> 144.08491 | P26: =M26-J26 -> 0 | Q26: =O26-L26 -> -18.190733 | R26: =O26/L26 -> 0.88790226 | AB26: =N26-K26 -> -226.33413 | AC26: =N26/K26 -> 0.88829901
A27: 手工三線 (ET-55) | B27: =VLOOKUP(D27,廠價表!$C$1:$E$40,2,0) -> 熱乾麵 | D27: 青花椒麻雞肉拌麵 | F27: =VLOOKUP(D27,廠價表!$C$1:$E$40,3,0) -> 49.91 | G27: 750 | H27: =F27*G27 -> 37432.5 | J27: =VLOOKUP(D27,產線配置圖!$A$3:$C$39,2,0) -> 17 | K27: =VLOOKUP(D27,產線配置圖!$A$3:$C$39,3,0) -> 1565 | L27: =K27/J27 -> 92.058824 | M27: 15 | N27: =G27/W27*60 -> 900 | O27: =N27/M27 -> 60 | P27: =M27-J27 -> -2 | Q27: =O27-L27 -> -32.058824 | R27: =O27/L27 -> 0.65175719 | S27: =R37 -> 0.67364023 | T27: 0.29166667 | U27: 0.32638889 | W27: =(U27-T27)*24*60 -> 50 | Z27: 封口與熱轉印異常 | AB27: =N27-K27 -> -665 | AC27: =N27/K27 -> 0.57507987 | AD27: =AC37 -> 0.63906254
B28: =VLOOKUP(D28,廠價表!$C$1:$E$40,2,0) -> 義大利麵 | D28: 奶油蒜香雞義大利麵 | F28: =VLOOKUP(D28,廠價表!$C$1:$E$40,3,0) -> 55.13 | G28: 1873 | H28: =F28*G28 -> 103258.49 | J28: =VLOOKUP(D28,產線配置圖!$A$3:$C$39,2,0) -> 18 | K28: =VLOOKUP(D28,產線配置圖!$A$3:$C$39,3,0) -> 1385 | L28: =K28/J28 -> 76.944444 | M28: 16 | N28: =G28/W28*60 -> 928.76033 | O28: =N28/M28 -> 58.047521 | P28: =M28-J28 -> -2 | Q28: =O28-L28 -> -18.896924 | R28: =O28/L28 -> 0.75440821 | T28: 0.33194444 | U28: 0.41597222 | V28: =(T28-U27)*24*60 -> 8 | W28: =(U28-T28)*24*60 -> 121 | Z28: 封口與熱轉印異常 | AB28: =N28-K28 -> -456.23967 | AC28: =N28/K28 -> 0.67058508
B29: =VLOOKUP(D29,廠價表!$C$1:$E$40,2,0) -> 熱乾麵 | D29: 青花椒麻雞肉拌麵 | F29: =VLOOKUP(D29,廠價表!$C$1:$E$40,3,0) -> 49.91 | G29: 283 | H29: =F29*G29 -> 14124.53 | J29: =VLOOKUP(D29,產線配置圖!$A$3:$C$39,2,0) -> 17 | K29: =VLOOKUP(D29,產線配置圖!$A$3:$C$39,3,0) -> 1565 | L29: =K29/J29 -> 92.058824 | M29: 15 | N29: =G29/W29*60 -> 369.13043 | O29: =N29/M29 -> 24.608696 | P29: =M29-J29 -> -2 | Q29: =O29-L29 -> -67.450128 | R29: =O29/L29 -> 0.2673149 | T29: 0.42361111 | U29: 0.45555556 | V29: =(T29-U28)*24*60 -> 11 | W29: =(U29-T29)*24*60 -> 46 | Z29: 製作與補封膜(第一次生產封口異常) | AB29: =N29-K29 -> -1195.8696 | AC29: =N29/K29 -> 0.23586609
B30: =VLOOKUP(D30,廠價表!$C$1:$E$40,2,0) -> 義大利麵 | D30: 奶油起司蝦仁通心粉 | F30: =VLOOKUP(D30,廠價表!$C$1:$E$40,3,0) -> 47.71 | G30: 1193 | H30: =F30*G30 -> 56918.03 | J30: =VLOOKUP(D30,產線配置圖!$A$3:$C$39,2,0) -> 15 | K30: =VLOOKUP(D30,產線配置圖!$A$3:$C$39,3,0) -> 1500 | L30: =K30/J30 -> 100 | M30: 15 | N30: =G30/W30*60 -> 1234.1379 | O30: =N30/M30 -> 82.275862 | P30: =M30-J30 -> 0 | Q30: =O30-L30 -> -17.724138 | R30: =O30/L30 -> 0.82275862 | T30: 0.46388889 | U30: 0.50416667 | V30: =(T30-U29)*24*60 -> 12 | W30: =(U30-T30)*24*60 -> 58 | X30: 0.48958333 | Y30: 0.53125 | AB30: =N30-K30 -> -265.86207 | AC30: =N30/K30 -> 0.82275862
B31: =VLOOKUP(D31,廠價表!$C$1:$E$40,2,0) -> 義大利麵 | D31: 奶油起司蝦仁通心粉 | F31: =VLOOKUP(D31,廠價表!$C$1:$E$40,3,0) -> 47.71 | G31: 2604 | H31: =F31*G31 -> 124236.84 | J31: =VLOOKUP(D31,產線配置圖!$A$3:$C$39,2,0) -> 15 | K31: =VLOOKUP(D31,產線配置圖!$A$3:$C$39,3,0) -> 1500 | L31: =K31/J31 -> 100 | M31: 16 | N31: =G31/W31*60 -> 1370.5263 | O31: =N31/M31 -> 85.657895 | P31: =M31-J31 -> 1 | Q31: =O31-L31 -> -14.342105 | R31: =O31/L31 -> 0.85657895 | T31: 0.56666667 | U31: 0.64583333 | W31: =(U31-T31)*24*60 -> 114
W32: =(U32-T32)*24*60 -> 0
H33: =F33*G33 -> 0 | W33: =(U33-T33)*24*60 -> 0
H34: =F34*G34 -> 0 | W34: =(U34-T34)*24*60 -> 0
H35: =F35*G35 -> 0 | W35: =(U35-T35)*24*60 -> 0
H36: =F36*G36 -> 0 | W36: =(U36-T36)*24*60 -> 0
C37: 4度二組B | D37: 平均 | J37: =AVERAGE(J27:J36) -> 16.4 | K37: =AVERAGE(K27:K36) -> 1503 | L37: =AVERAGE(L27:L36) -> 92.212418 | M37: =AVERAGE(M27:M36) -> 15.4 | N37: =AVERAGE(N27:N36) -> 960.511 | O37: =AVERAGE(O27:O36) -> 62.117995 | P37: =M37-J37 -> -1 | Q37: =N37-K37 -> -542.489 | R37: =O37/L37 -> 0.67364023 | AB37: =N37-K37 -> -542.489 | AC37: =N37/K37 -> 0.63906254
A38: 手工四線 (ET-55) | B38: 義大利麵 | D38: 焗烤明太子筆尖麵 | F38: =VLOOKUP(D38,廠價表!$C$1:$E$40,3,0) -> 57.3 | G38: 1658 | H38: =F38*G38 -> 95003.4 | J38: 16 | K38: 1500 | L38: =K38/J38 -> 93.75 | M38: 15 | N38: =G38/W38*60 -> 912.66055 | O38: =N38/M38 -> 60.844037 | P38: =M38-J38 -> -1 | Q38: =O38-L38 -> -32.905963 | R38: =O38/L38 -> 0.64900306 | S38: =R48 -> 0.65664008 | T38: 0.33333333 | U38: 0.40902778 | W38: =(U38-T38)*24*60 -> 109 | Z38: L型封膜機異常 | AB38: =N38-K38 -> -587.33945 | AC38: =N38/K38 -> 0.60844037 | AD38: =AC48 -> 0.63343321
B39: 義大利麵 | D39: 濃拿坡里義大利麵 | F39: =VLOOKUP(D39,廠價表!$C$1:$E$40,3,0) -> 56.43 | G39: 1079 | H39: =F39*G39 -> 60887.97 | J39: 17 | K39: =VLOOKUP(D39,產線配置圖!$A$3:$C$39,3,0) -> 1406 | L39: =K39/J39 -> 82.705882 | M39: 15 | N39: =G39/W39*60 -> 924.85714 | O39: =N39/M39 -> 61.657143 | P39: =M39-J39 -> -2 | Q39: =O39-L39 -> -21.048739 | R39: =O39/L39 -> 0.74549888 | T39: 0.41666667 | U39: 0.46527778 | V39: =(T39-U38)*24*60 -> 11 | W39: =(U39-T39)*24*60 -> 70 | Z39: L型封膜機異常 | AB39: =N39-K39 -> -481.14286 | AC39: =N39/K39 -> 0.65779313
B40: 義大利麵 | D40: 南洋紅咖哩豬義大利麵 | F40: =VLOOKUP(D40,廠價表!$C$1:$E$40,3,0) -> 56.43 | G40: 884 | H40: =F40*G40 -> 49884.12 | J40: =VLOOKUP(D40,產線配置圖!$A$3:$C$39,2,0) -> 15 | K40: =VLOOKUP(D40,產線配置圖!$A$3:$C$39,3,0) -> 1636 | L40: =K40/J40 -> 109.06667 | M40: 15 | N40: =G40/W40*60 -> 982.22222 | O40: =N40/M40 -> 65.481481 | P40: =M40-J40 -> 0 | Q40: =O40-L40 -> -43.585185 | R40: =O40/L40 -> 0.60038033 | T40: 0.47291667 | U40: 0.51041667 | V40: =(T40-U39)*24*60 -> 11 | W40: =(U40-T40)*24*60 -> 54 | Z40: 生產數量少 | AB40: =N40-K40 -> -653.77778 | AC40: =N40/K40 -> 0.60038033
...

Sheet 1204總
B1: 長家廠組合室生產人時性分析
B3: 日期 | D3: 45995 | F3: 訂單量 | G3: ='1204'!E1 -> 44569 | I3: 營業額 | J3: ='1204'!G1 -> 2165820.2
B4: 項目 | D4: 3 | F4: ➀ | H4: ➁ | J4: ③
B5: 人時性 | D5: 組合室 | F5: 全溫層 | H5: 義大利麵 | J5: 袋裝小吃、義麵
D6: 排關平均 | F6: =AVERAGE(D13:J13) -> 117.33743 | H6: =AVERAGE(D13:H13) -> 115.72479 | J6: =AVERAGE(I13:J13) -> 125.40064
D7: 實績平均 | F7: =AVERAGE(D14:J14) -> 100.17318 | H7: =AVERAGE(D14:H14) -> 97.820456 | J7: =AVERAGE(I14:J14) -> 111.93677
D8: 達成率平均 | F8: =AVERAGE(D15:J15) -> 0.85210476 | H8: =AVERAGE(D15:H15) -> 0.84399907 | J8: =AVERAGE(I15:J15) -> 0.89263319 | L8: ※現行日本鮮食廠以達成率80%為基本(即為現行KPI)
B10: 溫層 | D10: 4度C-各編組展開
B11: 編組 | D11: 1 | E11: 2 | F11: 3 | G11: 4 | H11: 5 | I11: 6 | J11: 7
D12: 自動1線 | E12: 自動2線 | F12: 手工3線 | G12: 手工4線 | H12: 手工5線 | I12: 調理包1線 | J12: 調理包2線
B13: 人時性 | C13: 排關 | D13: =VALUE('1204'!L15) -> 136.91288 | E13: =VALUE('1204'!L26) -> 162.27564 | F13: =VALUE('1204'!L37) -> 92.250817 | G13: =VALUE('1204'!L48) -> 99.133333 | H13: =VALUE('1204'!L58) -> 88.051256 | I13: =VALUE('1204'!L69) -> 125.40064
C14: 實績 | D14: =VALUE('1204'!O15) -> 120.92064 | E14: =VALUE('1204'!O26) -> 137.06761 | F14: =VALUE('1204'!O37) -> 80.980216 | G14: =VALUE('1204'!O48) -> 71.485163 | H14: =VALUE('1204'!O58) -> 78.64865 | I14: =VALUE('1204'!O69) -> 111.93677
C15: 達成率 | D15: =D14/D13 -> 0.88319405 | E15: =E14/E13 -> 0.84465918 | F15: =F14/F13 -> 0.87782654 | G15: =G14/G13 -> 0.72110117 | H15: =H14/H13 -> 0.8932144 | I15: =I14/I13 -> 0.89263319
B16: 作業 時間 | C16: 開始 | D16: ='1204'!T5 -> 0.29027778 | E16: ='1204'!T16 -> 0.29027778 | F16: ='1204'!T27 -> 0.29027778 | G16: ='1204'!T38 -> 0.33333333 | H16: ='1204'!T49 -> 0.29166667 | I16: ='1204'!T59 -> 0.29166667
C17: 結束 | D17: 0.62430556 | E17: 0.59097222 | F17: 0.61458333 | G17: 0.59375 | H17: 0.61180556 | I17: 0.55208333
B18: 配置人數 | D18: =VALUE('1204'!M15) -> 14.2 | E18: =VALUE('1204'!M26) -> 12.5 | F18: =VALUE('1204'!M37) -> 14.5 | G18: =VALUE('1204'!M48) -> 15 | H18: =VALUE('1204'!M58) -> 16.5 | I18: =VALUE('1204'!M69) -> 12.5
B19: 主要應用設備 | D19: ET-600 | E19: ET-600 | F19: ET-55 | G19: ET-55 | H19: ET-55 | I19: 八爪機
B20: 次要應用設備 | H20: 封口機
B21: 備註

Sheet 1204
A1: 長家廠4度C日報分析 | D1: 總生產量 | E1: =SUM(G5:G79) -> 44569 | F1: 營業額 | G1: =SUM(H5:H79) -> 2165820.2 | H1: 出勤人數 | I1: =M15+M26+M48+M58+M69+M79+M37 -> 85.2 | J1: 產線配置圖 | M1: 生產實績 | P1: 人時性差異分析 | T1: 日報登錄 | Z1: 分析說明 | AB1: 產能差異分析
A2: 12月04日 星期四 | D2: 人時性 | E2: =AVERAGE(O15,O26,O37,O48,O58,O69,O79) -> 100.17318 | F2: 平均廠價 | G2: =G1/E1 -> 48.594768 | H2: 多次生產數 | I2: =COUNT(I5:I79) -> 0
A3: 線別 | B3: 品類 | D3: 品名 | F3: 廠價 | G3: 生產量 | H3: 營收 | I3: 多次 生產 | J3: 人數 | K3: 產能/時 | L3: 人時性 | M3: 人數 | N3: 產能/時 | O3: 人時性 | P3: 人數 | Q3: 人時性 | R3: 達成率 | S3: 達成率平均 | T3: 生產時間 | V3: 前置、換線時間/分 | W3: 稼動時間/分 | X3: 休息時間 | AB3: 產能/時 | AC3: 達成率 | AD3: 達成率平均
T4: 開始 | U4: 結束 | X4: 開始 | Y4: 結束
A5: 自動一線 (ET-600) | B5: =VLOOKUP(D5,廠價表!$C$1:$E$40,2,0) -> 義大利麵 | D5: 白酒蛤蜊義大利麵 | F5: =VLOOKUP(D5,廠價表!$C$1:$E$40,3,0) -> 57.21 | G5: 1369 | H5: =F5*G5 -> 78320.49 | J5: =VLOOKUP(D5,產線配置圖!$A$3:$C$39,2,0) -> 13 | K5: =VLOOKUP(D5,產線配置圖!$A$3:$C$39,3,0) -> 2105 | L5: =K5/J5 -> 161.92308 | M5: 13 | N5: =G5/W5*60 -> 1825.3333 | O5: =N5/M5 -> 140.41026 | P5: =M5-J5 -> 0 | Q5: =O5-L5 -> -21.512821 | R5: =O5/L5 -> 0.86714173 | S5: =R15 -> 0.88319405 | T5: 0.29027778 | U5: 0.32152778 | W5: =(U5-T5)*24*60 -> 45 | AB5: =N5-K5 -> -279.66667 | AC5: =N5/K5 -> 0.86714173 | AD5: =AC15 -> 0.88087693
B6: =VLOOKUP(D6,廠價表!$C$1:$E$40,2,0) -> 義大利麵 | D6: 韓式起司炸雞義大利麵 | F6: =VLOOKUP(D6,廠價表!$C$1:$E$40,3,0) -> 57.21 | G6: 1773 | H6: =F6*G6 -> 101433.33 | J6: =VLOOKUP(D6,產線配置圖!$A$3:$C$39,2,0) -> 17 | K6: 1800 | L6: =K6/J6 -> 105.88235 | M6: 17 | N6: =G6/W6*60 -> 1773 | O6: =N6/M6 -> 104.29412 | P6: =M6-J6 -> 0 | Q6: =O6-L6 -> -1.5882353 | R6: =O6/L6 -> 0.985 | T6: 0.33125 | U6: 0.37291667 | V6: =(T6-U5)*24*60 -> 14 | W6: =(U6-T6)*24*60 -> 60 | AB6: =N6-K6 -> -27 | AC6: =N6/K6 -> 0.985
B7: =VLOOKUP(D7,廠價表!$C$1:$E$40,2,0) -> 義大利麵 | D7: 奶油培根義大利麵 | F7: =VLOOKUP(D7,廠價表!$C$1:$E$40,3,0) -> 49.14 | G7: 4361 | H7: =F7*G7 -> 214299.54 | J7: =VLOOKUP(D7,產線配置圖!$A$3:$C$39,2,0) -> 13 | K7: =VLOOKUP(D7,產線配置圖!$A$3:$C$39,3,0) -> 2000 | L7: =K7/J7 -> 153.84615 | M7: 13 | N7: =G7/W7*60 -> 1923.9706 | O7: =N7/M7 -> 147.99774 | P7: =M7-J7 -> 0 | Q7: =O7-L7 -> -5.8484163 | R7: =O7/L7 -> 0.96198529 | T7: 0.38194444 | U7: 0.47638889 | V7: =(T7-U6)*24*60 -> 13 | W7: =(U7-T7)*24*60 -> 136 | AB7: =N7-K7 -> -76.029412 | AC7: =N7/K7 -> 0.96198529
B8: =VLOOKUP(D8,廠價表!$C$1:$E$40,2,0) -> 義大利麵 | D8: 奶油培根義大利麵 | F8: =VLOOKUP(D8,廠價表!$C$1:$E$40,3,0) -> 49.14 | G8: 899 | H8: =F8*G8 -> 44176.86 | J8: =VLOOKUP(D8,產線配置圖!$A$3:$C$39,2,0) -> 13 | K8: =VLOOKUP(D8,產線配置圖!$A$3:$C$39,3,0) -> 2000 | L8: =K8/J8 -> 153.84615 | M8: 13 | N8: =G8/W8*60 -> 1926.4286 | O8: =N8/M8 -> 148.18681 | P8: =M8-J8 -> 0 | Q8: =O8-L8 -> -5.6593407 | R8: =O8/L8 -> 0.96321429 | T8: 0.54305556 | U8: 0.5625 | V8: =(T8-U7)*24*60 -> 96 | W8: =(U8-T8)*24*60 -> 28 | AB8: =N8-K8 -> -73.571429 | AC8: =N8/K8 -> 0.96321429
B9: =VLOOKUP(D9,廠價表!$C$1:$E$40,2,0) -> 義大利麵 | D9: 南洋紅咖哩豬義大利麵 | F9: =VLOOKUP(D9,廠價表!$C$1:$E$40,3,0) -> 56.43 | G9: 892 | H9: =F9*G9 -> 50335.56 | J9: =VLOOKUP(D9,產線配置圖!$A$3:$C$39,2,0) -> 15 | K9: =VLOOKUP(D9,產線配置圖!$A$3:$C$39,3,0) -> 1636 | L9: =K9/J9 -> 109.06667 | M9: 15 | N9: =G9/W9*60 -> 955.71429 | O9: =N9/M9 -> 63.714286 | P9: =M9-J9 -> 0 | Q9: =O9-L9 -> -45.352381 | R9: =O9/L9 -> 0.58417744 | T9: 0.58541667 | U9: 0.62430556 | V9: =(T9-U8)*24*60 -> 33 | W9: =(U9-T9)*24*60 -> 56 | X9: 0.48958333 | Y9: 0.53125 | Z9: 生產數量少 | AB9: =N9-K9 -> -680.28571 | AC9: =N9/K9 -> 0.58417744
W10: =(U10-T10)*24*60 -> 0
H11: =F11*G11 -> 0 | W11: =(U11-T11)*24*60 -> 0
H12: =F12*G12 -> 0 | W12: =(U12-T12)*24*60 -> 0
W13: =(U13-T13)*24*60 -> 0
W14: =(U14-T14)*24*60 -> 0
C15: 4度一組 | D15: 平均 | J15: =AVERAGE(J5:J14) -> 14.2 | K15: =AVERAGE(K5:K14) -> 1908.2 | L15: =AVERAGE(L5:L14) -> 136.91288 | M15: =AVERAGE(M5:M14) -> 14.2 | N15: =AVERAGE(N5:N14) -> 1680.8894 | O15: =AVERAGE(O5:O14) -> 120.92064 | P15: =M15-J15 -> 0 | Q15: =O15-L15 -> -15.992239 | R15: =O15/L15 -> 0.88319405 | AB15: =N15-K15 -> -227.31064 | AC15: =N15/K15 -> 0.88087693
A16: 自動二線 (ET-600) | B16: =VLOOKUP(D16,廠價表!$C$1:$E$40,2,0) -> 義大利麵 | D16: 白酒蛤蜊義大利麵 | F16: =VLOOKUP(D16,廠價表!$C$1:$E$40,3,0) -> 57.21 | G16: 1175 | H16: =F16*G16 -> 67221.75 | J16: =VLOOKUP(D16,產線配置圖!$A$3:$C$39,2,0) -> 13 | K16: =VLOOKUP(D16,產線配置圖!$A$3:$C$39,3,0) -> 2105 | L16: =K16/J16 -> 161.92308 | M16: 13 | N16: =G16/W16*60 -> 1855.2632 | O16: =N16/M16 -> 142.71255 | P16: =M16-J16 -> 0 | Q16: =O16-L16 -> -19.210526 | R16: =O16/L16 -> 0.88136017 | S16: =R26 -> 0.84465918 | T16: 0.29027778 | U16: 0.31666667 | W16: =(U16-T16)*24*60 -> 38 | AB16: =N16-K16 -> -249.73684 | AC16: =N16/K16 -> 0.88136017 | AD16: =AC26 -> 0.84608221
B17: =VLOOKUP(D17,廠價表!$C$1:$E$40,2,0) -> 義大利麵 | D17: 青醬蛤蜊義大利麵 | F17: =VLOOKUP(D17,廠價表!$C$1:$E$40,3,0) -> 50.67 | G17: 3524 | H17: =F17*G17 -> 178561.08 | J17: =VLOOKUP(D17,產線配置圖!$A$3:$C$39,2,0) -> 13 | K17: =VLOOKUP(D17,產線配置圖!$A$3:$C$39,3,0) -> 2000 | L17: =K17/J17 -> 153.84615 | M17: 13 | N17: =G17/W17*60 -> 1762 | O17: =N17/M17 -> 135.53846 | P17: =M17-J17 -> 0 | Q17: =O17-L17 -> -18.307692 | R17: =O17/L17 -> 0.881 | T17: 0.32638889 | U17: 0.40972222 | V17: =(T17-U16)*24*60 -> 14 | W17: =(U17-T17)*24*60 -> 120 | AB17: =N17-K17 -> -238 | AC17: =N17/K17 -> 0.881
B18: =VLOOKUP(D18,廠價表!$C$1:$E$40,2,0) -> 義大利麵 | D18: 義式蕃茄起司義大利麵 | F18: =VLOOKUP(D18,廠價表!$C$1:$E$40,3,0) -> 50.39 | G18: 2043 | H18: =F18*G18 -> 102946.77 | J18: =VLOOKUP(D18,產線配置圖!$A$3:$C$39,2,0) -> 12 | K18: =VLOOKUP(D18,產線配置圖!$A$3:$C$39,3,0) -> 2000 | L18: =K18/J18 -> 166.66667 | M18: 12 | N18: =G18/W18*60 -> 1408.9655 | O18: =N18/M18 -> 117.41379 | P18: =M18-J18 -> 0 | Q18: =O18-L18 -> -49.252874 | R18: =O18/L18 -> 0.70448276 | T18: 0.41875 | U18: 0.47916667 | V18: =(T18-U17)*24*60 -> 13 | W18: =(U18-T18)*24*60 -> 87 | Z18: 10:10~11:30注醬機異常改 | AB18: =N18-K18 -> -591.03448 | AC18: =N18/K18 -> 0.70448276
B19: =VLOOKUP(D19,廠價表!$C$1:$E$40,2,0) -> 義大利麵 | D19: 義式蕃茄起司義大利麵 | F19: =VLOOKUP(D19,廠價表!$C$1:$E$40,3,0) -> 50.39 | G19: 2167 | H19: =F19*G19 -> 109195.13 | J19: =VLOOKUP(D19,產線配置圖!$A$3:$C$39,2,0) -> 12 | K19: =VLOOKUP(D19,產線配置圖!$A$3:$C$39,3,0) -> 2000 | L19: =K19/J19 -> 166.66667 | M19: 12 | N19: =G19/W19*60 -> 1831.2676 | O19: =N19/M19 -> 152.60563 | P19: =M19-J19 -> 0 | Q19: =O19-L19 -> -14.061033 | R19: =O19/L19 -> 0.9156338 | T19: 0.54166667 | U19: 0.59097222 | V19: =(T19-U18)*24*60 -> 90 | W19: =(U19-T19)*24*60 -> 71 | X19: 0.48958333 | Y19: 0.53125 | AB19: =N19-K19 -> -168.73239 | AC19: =N19/K19 -> 0.9156338
W20: =(U20-T20)*24*60 -> 0 | AB20: =N20-K20 -> 0 | AC20: =N20/K20 -> #DIV/0!
W21: =(U21-T21)*24*60 -> 0
H22: =F22*G22 -> 0 | W22: 0
W23: =(U23-T23)*24*60 -> 0
H24: =F24*G24 -> 0 | W24: =(U24-T24)*24*60 -> 0
H25: =F25*G25 -> 0 | W25: =(U25-T25)*24*60 -> 0
C26: 4度二組A | D26: 平均 | J26: =AVERAGE(J16:J25) -> 12.5 | K26: =AVERAGE(K16:K25) -> 2026.25 | L26: =AVERAGE(L16:L25) -> 162.27564 | M26: =AVERAGE(M16:M25) -> 12.5 | N26: =AVERAGE(N16:N25) -> 1714.3741 | O26: =AVERAGE(O16:O25) -> 137.06761 | P26: =M26-J26 -> 0 | Q26: =O26-L26 -> -25.208031 | R26: =O26/L26 -> 0.84465918 | AB26: =N26-K26 -> -311.87593 | AC26: =N26/K26 -> 0.84608221
A27: 手工三線 (ET-55) | B27: =VLOOKUP(D27,廠價表!$C$1:$E$40,2,0) -> 熱乾麵 | D27: 青花椒麻雞肉拌麵 | F27: =VLOOKUP(D27,廠價表!$C$1:$E$40,3,0) -> 49.91 | G27: 1920 | H27: =F27*G27 -> 95827.2 | J27: =VLOOKUP(D27,產線配置圖!$A$3:$C$39,2,0) -> 17 | K27: =VLOOKUP(D27,產線配置圖!$A$3:$C$39,3,0) -> 1565 | L27: =K27/J27 -> 92.058824 | M27: 13 | N27: =G27/W27*60 -> 1140.5941 | O27: =N27/M27 -> 87.738005 | P27: =M27-J27 -> -4 | Q27: =O27-L27 -> -4.320819 | R27: =O27/L27 -> 0.95306459 | S27: =R37 -> 0.87782654 | T27: 0.29027778 | U27: 0.36041667 | W27: =(U27-T27)*24*60 -> 101 | AB27: =N27-K27 -> -424.40594 | AC27: =N27/K27 -> 0.7288141 | AD27: =AC37 -> 0.79060493
B28: =VLOOKUP(D28,廠價表!$C$1:$E$40,2,0) -> 義大利麵 | D28: 奶油蒜香雞義大利麵 | F28: =VLOOKUP(D28,廠價表!$C$1:$E$40,3,0) -> 55.13 | G28: 1778 | H28: =F28*G28 -> 98021.14 | J28: =VLOOKUP(D28,產線配置圖!$A$3:$C$39,2,0) -> 18 | K28: =VLOOKUP(D28,產線配置圖!$A$3:$C$39,3,0) -> 1385 | L28: =K28/J28 -> 76.944444 | M28: 13 | N28: =G28/W28*60 -> 944.0708 | O28: =N28/M28 -> 72.62083 | P28: =M28-J28 -> -5 | Q28: =O28-L28 -> -4.3236139 | R28: =O28/L28 -> 0.94380863 | T28: 0.37291667 | U28: 0.45138889 | V28: =(T28-U27)*24*60 -> 18 | W28: =(U28-T28)*24*60 -> 113 | AB28: =N28-K28 -> -440.9292 | AC28: =N28/K28 -> 0.68163956
B29: =VLOOKUP(D29,廠價表!$C$1:$E$40,2,0) -> 義大利麵 | D29: 奶油起司蝦仁通心粉 | F29: =VLOOKUP(D29,廠價表!$C$1:$E$40,3,0) -> 47.71 | G29: 1364 | H29: =F29*G29 -> 65076.44 | J29: =VLOOKUP(D29,產線配置圖!$A$3:$C$39,2,0) -> 15 | K29: =VLOOKUP(D29,產線配置圖!$A$3:$C$39,3,0) -> 1500 | L29: =K29/J29 -> 100 | M29: 17 | N29: =G29/W29*60 -> 1411.0345 | O29: =N29/M29 -> 83.002028 | P29: =M29-J29 -> 2 | Q29: =O29-L29 -> -16.997972 | R29: =O29/L29 -> 0.83002028 | T29: 0.45625 | U29: 0.49652778 | V29: =(T29-U28)*24*60 -> 7 | W29: =(U29-T29)*24*60 -> 58 | AB29: =N29-K29 -> -88.965517 | AC29: =N29/K29 -> 0.94068966
B30: =VLOOKUP(D30,廠價表!$C$1:$E$40,2,0) -> 義大利麵 | D30: 奶油起司蝦仁通心粉 | F30: =VLOOKUP(D30,廠價表!$C$1:$E$40,3,0) -> 47.71 | G30: 2014 | H30: =F30*G30 -> 96087.94 | J30: =VLOOKUP(D30,產線配置圖!$A$3:$C$39,2,0) -> 15 | K30: =VLOOKUP(D30,產線配置圖!$A$3:$C$39,3,0) -> 1500 | L30: =K30/J30 -> 100 | M30: 15 | N30: =G30/W30*60 -> 1208.4 | O30: =N30/M30 -> 80.56 | P30: =M30-J30 -> 0 | Q30: =O30-L30 -> -19.44 | R30: =O30/L30 -> 0.8056 | T30: 0.54513889 | U30: 0.61458333 | V30: =(T30-U29)*24*60 -> 70 | W30: =(U30-T30)*24*60 -> 100 | X30: 0.48958333 | Y30: 0.53125 | AB30: =N30-K30 -> -291.6 | AC30: =N30/K30 -> 0.8056
W31: =(U31-T31)*24*60 -> 0
W32: =(U32-T32)*24*60 -> 0
H33: =F33*G33 -> 0 | W33: =(U33-T33)*24*60 -> 0
H34: =F34*G34 -> 0 | W34: =(U34-T34)*24*60 -> 0
H35: =F35*G35 -> 0 | W35: =(U35-T35)*24*60 -> 0
H36: =F36*G36 -> 0 | W36: =(U36-T36)*24*60 -> 0
C37: 4度二組B | D37: 平均 | J37: =AVERAGE(J27:J36) -> 16.25 | K37: =AVERAGE(K27:K36) -> 1487.5 | L37: =AVERAGE(L27:L36) -> 92.250817 | M37: =AVERAGE(M27:M36) -> 14.5 | N37: =AVERAGE(N27:N36) -> 1176.0248 | O37: =AVERAGE(O27:O36) -> 80.980216 | P37: =M37-J37 -> -1.75 | Q37: =N37-K37 -> -311.47517 | R37: =O37/L37 -> 0.87782654 | AB37: =N37-K37 -> -311.47517 | AC37: =N37/K37 -> 0.79060493
A38: 手工四線 (ET-55) | B38: 義大利麵 | D38: 焗烤明太子筆尖麵 | F38: =VLOOKUP(D38,廠價表!$C$1:$E$40,3,0) -> 57.3 | G38: 1964 | H38: =F38*G38 -> 112537.2 | J38: =VLOOKUP(D38,產線配置圖!$A$3:$C$39,2,0) -> 15 | K38: 1500 | L38: =K38/J38 -> 100 | M38: 15 | N38: =G38/W38*60 -> 1111.6981 | O38: =N38/M38 -> 74.113208 | P38: =M38-J38 -> 0 | Q38: =O38-L38 -> -25.886792 | R38: =O38/L38 -> 0.74113208 | S38: =R48 -> 0.72110117 | T38: 0.33333333 | U38: 0.40694444 | W38: =(U38-T38)*24*60 -> 106 | Z38: 下貼標異常 | AB38: =N38-K38 -> -388.30189 | AC38: =N38/K38 -> 0.74113208 | AD38: =AC48 -> 0.72110117
B39: 義大利麵 | D39: 濃拿坡里義大利麵 | F39: =VLOOKUP(D39,廠價表!$C$1:$E$40,3,0) -> 56.43 | G39: 1109 | H39: =F39*G39 -> 62580.87 | J39: =VLOOKUP(D39,產線配置圖!$A$3:$C$39,2,0) -> 15 | K39: =VLOOKUP(D39,產線配置圖!$A$3:$C$39,3,0) -> 1406 | L39: =K39/J39 -> 93.733333 | M39: 15 | N39: =G39/W39*60 -> 937.1831 | O39: =N39/M39 -> 62.478873 | P39: =M39-J39 -> 0 | Q39: =O39-L39 -> -31.25446 | R39: =O39/L39 -> 0.66655981 | T39: 0.41319444 | U39: 0.4625 | V39: =(T39-U38)*24*60 -> 9 | W39: =(U39-T39)*24*60 -> 71 | Z39: 下貼標異常 | AB39: =N39-K39 -> -468.8169 | AC39: =N39/K39 -> 0.66655981
B40: 義大利麵 | D40: 南洋紅咖哩豬義大利麵 | F40: =VLOOKUP(D40,廠價表!$C$1:$E$40,3,0) -> 56.43 | G40: 876 | H40: =F40*G40 -> 49432.68 | J40: =VLOOKUP(D40,產線配置圖!$A$3:$C$39,2,0) -> 15 | K40: =VLOOKUP(D40,產線配置圖!$A$3:$C$39,3,0) -> 1636 | L40: =K40/J40 -> 109.06667 | M40: 15 | N40: =G40/W40*60 -> 1251.4286 | O40: =N40/M40 -> 83.428571 | P40: =M40-J40 -> 0 | Q40: =O40-L40 -> -25.638095 | R40: =O40/L40 -> 0.76493189 | T40: 0.47083333 | U40: 0.5 | V40: =(T40-U39)*24*60 -> 12 | W40: =(U40-T40)*24*60 -> 42 | Z40: 11:18~11:27封膜異常、生產數量少 | AB40: =N40-K40 -> -384.57143 | AC40: =N40/K40 -> 0.76493189
...

Sheet 1205總
B1: 長家廠組合室生產人時性分析
B3: 日期 | D3: 45996 | F3: 訂單量 | G3: ='1205'!E1 -> 38620 | I3: 營業額 | J3: ='1205'!G1 -> 1870192.3
B4: 項目 | D4: 3 | F4: ➀ | H4: ➁ | J4: ③
B5: 人時性 | D5: 組合室 | F5: 全溫層 | H5: 義大利麵 | J5: 袋裝小吃、義麵
D6: 排關平均 | F6: =AVERAGE(D13:J13) -> 116.50678 | H6: =AVERAGE(D13:H13) -> 114.3936 | J6: =AVERAGE(I13:J13) -> 127.07265
D7: 實績平均 | F7: =AVERAGE(D14:J14) -> 98.255159 | H7: =AVERAGE(D14:H14) -> 96.630661 | J7: =AVERAGE(I14:J14) -> 106.37765
