Workbook

Sheet 廠價表
A1: check | B1: 溫層 | C1: 品名 | D1: 類別 | E1: 廠價
B2: 4度C | C2: 白酒蛤蜊義大利麵 | D2: 義大利麵 | E2: 57.21
B3: 4度C | C3: 南洋紅咖哩豬義大利麵 | D3: 義大利麵 | E3: 56.43
B4: 4度C | C4: 義式蕃茄起司義大利麵 | D4: 義大利麵 | E4: 50.39
B5: 4度C | C5: 焗烤起司雙饗筆尖麵 | D5: 義大利麵 | E5: 49.97
B6: 4度C | C6: 奶油培根義大利麵 | D6: 義大利麵 | E6: 49.14
B7: 4度C | C7: 韓式起司炸雞義大利麵 | D7: 義大利麵 | E7: 57.21
B8: 4度C | C8: 惡魔乳酪生義大利麵 | D8: 義大利麵 | E8: 57.3
B9: 4度C | C9: 焗烤起司肉醬筆尖麵 | D9: 義大利麵 | E9: 50.67
B10: 4度C | C10: 辣味香菜雞肉義大利麵 | D10: 義大利麵 | E10: 56.28
B11: 4度C | D11: 義大利麵
B12: 4度C | C12: 剝皮辣椒雞奶油扁麵 | D12: 義大利麵 | E12: 56.87
B13: 4度C | C13: 奶油蒜香雞義大利麵 | D13: 義大利麵 | E13: 55.13
B14: 4度C | C14: 青醬蛤蜊義大利麵 | D14: 義大利麵 | E14: 50.67
B15: 4度C | C15: 焗烤明太子筆尖麵 | D15: 義大利麵 | E15: 57.3
B16: 4度C | C16: 濃拿坡里義大利麵 | D16: 義大利麵 | E16: 56.43
B17: 4度C | C17: 奶油起司蝦仁通心粉 | D17: 義大利麵 | E17: 47.71
B18: 4度C | C18: 青花椒麻雞肉拌麵 | D18: 熱乾麵 | E18: 49.91
B19: 4度C | C19: 府城鹽水意麵 | D19: 熱乾麵 | E19: 44.3
B20: 4度C | C20: 沙茶豬肉炒麵 | D20: 熱乾麵 | E20: 49.52
B21: 4度C | C21: 三杯菇菇米血 | D21: 小吃、微波 | E21: 28.26
B22: 4度C | C22: 小滷青蔬 | D22: 小吃、微波 | E22: 26.99
B23: 4度C | C23: 起司馬鈴薯 | D23: 小吃、微波 | E23: 28.26
... B49: 冷凍 | C49: 辣蕃茄義大利麵 | D49: 冷凍調理麵 | E49: 29.38
B50: 冷凍 | D50: 冷凍調理麵
B51: 冷凍 | C51: 韓式起司義大利麵 | D51: 冷凍調理麵 | E51: 29.38
B52: 冷凍 | D52: 冷凍調理麵
B53: 冷凍 | C53: 和風明太子細扁麵 | D53: 冷凍調理麵 | E53: 29.38

Sheet 產線配置圖
A1: 品項 | B1: 人數 | C1: 產能
A2: 義大利麵
A3: 白酒蛤蜊義大利麵 | B3: 13 | C3: 2105 | D3: ET-600
A4: 白酒蛤蜊義大利麵-手 | B4: 15 | C4: 1565 | D4: ET-55
A5: 青醬蛤蜊義大利麵 | B5: 13 | C5: 2000
A6: 義式蕃茄起司義大利麵 | B6: 12 | C6: 2000
A7: 焗烤起司雙饗筆尖麵 | B7: 18 | C7: 1600
A8: 奶油培根義大利麵 | B8: 14 | C8: 2000
A9: 韓式起司炸雞義大利麵 | B9: 17 | C9: 2000
A10: 剝皮辣椒雞奶油扁麵 | B10: 18 | C10: 1565
A11: 青花椒麻雞肉拌麵 | B11: 17 | C11: 1565
A12: 青花椒麻雞肉拌麵-降速生產 | B12: 14 | C12: 1385
A13: 奶油蒜香雞義大利麵 | B13: 17 | C13: 1385 | G13: 日一二正常版
A14: 奶油蒜香雞義大利麵-降速生產 | B14: 17 | C14: 1385
A15: 焗烤明太子筆尖麵 | B15: 16 | C15: 1385
A16: 濃拿坡里義大利麵 | B16: 16 | C16: 1406
A17: 奶油起司蝦仁通心粉 | B17: 14 | C17: 1440
A18: 剝皮辣椒雞奶油扁麵-降速生產(3線) | B18: 16 | C18: 1440
A19: 辣味香菜雞肉義大利麵 | B19: 16 | C19: 1800
A21: 惡魔乳酪生義大利麵 | B21: 17 | C21: 1500
A22: 沙茶豬肉炒麵 | B22: 17 | C22: 1440
A23: 府城鹽水意麵 | B23: 19 | C23: 1440
A24: 焗烤起司肉醬筆尖麵 | B24: 10 | C24: 1125
A25: 調理包
A26: 小滷青蔬 | B26: 13 | C26: 1565
A27: 起司馬鈴薯 | B27: 12 | C27: 1565
A28: 台式綜合甜不辣 | B28: 12 | C28: 1565
A29: 三杯菇菇米血 | B29: 12 | C29: 1565
E33: 更新日期11/02

Sheet 範本總
B1: 長家廠組合室生產人時性分析
B3: 日期 | D3: 46015 | F3: 訂單量 | G3: =範本!E1 -> 43309 | I3: 營業額 | J3: =範本!G1 -> #N/A
B4: 項目 | D4: 3 | F4: ➀ | H4: ➁ | J4: ③ | L4: 異常停線 | N4: 短暫停線
B5: 人時性 | D5: 組合室 | F5: 全溫層 | H5: 義大利麵 | J5: 袋裝小吃、義麵 | L5: 合計次數 | M5: 時間 | N5: 合計次數 | O5: 設備次數
D6: 排關平均 | F6: =AVERAGE(D13:J13) -> #N/A | H6: =AVERAGE(D13:H13) -> #N/A | J6: =AVERAGE(I13:J13) -> #N/A | L6: =範本!Z2 -> 0 | M6: =範本!AA2 -> 0 | N6: =範本!AD2 -> 0 | O6: =範本!AE2 -> 0
D7: 實績平均 | F7: =AVERAGE(D14:J14) -> 116.11475 | H7: =AVERAGE(D14:H14) -> 117.36075 | J7: =AVERAGE(I14:J14) -> 112.99975
D8: 達成率平均 | F8: =AVERAGE(D15:J15) -> #N/A | H8: =AVERAGE(D15:H15) -> #N/A | J8: =AVERAGE(I15:J15) -> #N/A
J9: ※現行日本鮮食廠以達成率80%為基本(即為現行KPI)
B10: 溫層 | D10: 4度C-各編組展開
B11: 編組 | D11: 1 | E11: 2 | F11: 3 | G11: 4 | H11: 5 | I11: 6 | J11: 7
D12: 自動1線 | E12: 自動2線 | F12: 手工3線 | G12: 手工4線 | H12: 手工5線 | I12: 調理包1線 | J12: 調理包2線
B13: 人時性 | C13: 排關 | D13: =VALUE(範本!L15) -> #N/A | E13: =VALUE(範本!L26) -> #N/A | F13: =VALUE(範本!L37) -> #N/A | G13: =VALUE(範本!L48) -> #N/A | H13: =VALUE(範本!L58) -> #N/A | I13: =VALUE(範本!L69) -> #N/A | J13: =範本!L79 -> #N/A
C14: 實績 | D14: =VALUE(範本!O15) -> 113.91637 | E14: =VALUE(範本!O26) -> 132.12003 | F14: =VALUE(範本!O37) -> 126.23842 | G14: =VALUE(範本!O48) -> 112.0543 | H14: =VALUE(範本!O58) -> 102.47462 | I14: =VALUE(範本!O69) -> 155.46443 | J14: =範本!O79 -> 70.535065
C15: 達成率 | D15: =D14/D13 -> #N/A | E15: =E14/E13 -> #N/A | F15: =F14/F13 -> #N/A | G15: =G14/G13 -> #N/A | H15: =H14/H13 -> #N/A | I15: =I14/I13 -> #N/A | J15: =範本!S70 -> #N/A
B16: 作業 時間 | C16: 開始 | D16: =範本!T5 -> 0.29097222 | E16: =範本!T16 -> 0.29097222 | F16: =範本!T27 -> 0.29166667 | G16: =範本!T38 -> 0.33333333 | H16: =範本!T49 -> 0.29166667 | I16: =範本!T59 -> 0.29166667 | J16: =範本!T70 -> 0.34722222
C17: 結束 | D17: 0.47361111 | E17: 0.48263889 | F17: 0.56944444 | G17: 0.60416667 | H17: 0.58333333 | I17: 0.48819444 | J17: 0.46875
B18: 產線異常 (5分鐘以上) | C18: 次數
C19: 時間/分
B20: 短暫停線 (5分鐘以下) | C20: 次數
C21: 設備次數
B22: 配置人數 | D22: =VALUE(範本!M15) -> 15 | E22: =VALUE(範本!M26) -> 12.666667 | F22: =VALUE(範本!M37) -> 14.666667 | G22: =VALUE(範本!M48) -> 14 | H22: =VALUE(範本!M58) -> 17.666667 | I22: =VALUE(範本!M69) -> 12.333333 | J22: =範本!M79 -> 11
B23: 主要應用設備 | D23: ET-600 | E23: ET-600 | F23: ET-55 | G23: ET-55 | H23: ET-55 | I23: 八爪機
B24: 次要應用設備 | H24: 封口機
B25: 備註

Sheet 範本
A1: 長家廠4度C日報分析 | D1: 總生產量 | E1: =SUM(G5:G79) -> 43309 | F1: 營業額 | G1: =SUM(H5:H79) -> #N/A | H1: 出勤人數 | I1: =M15+M26+M48+M58+M69+M79+M37 -> 97.333333 | J1: 產線配置圖 | M1: 生產實績 | P1: 人時性差異分析 | T1: 日報登錄 | Z1: 合計 次數 | AA1: 合計 時間/分 | AB1: 分析說明 | AD1: 合計 次數 | AE1: 合計 設備次數 | AF1: 產能差異分析
A2: 12月24日 星期三 | D2: 人時性 | E2: =AVERAGE(O15,O26,O37,O48,O58,O69,O79) -> 116.11475 | F2: 平均廠價 | G2: =G1/E1 -> #N/A | H2: 多次生產數 | I2: =COUNT(I5:I79) -> 0 | Z2: =Z15+Z26+Z37+Z48+Z58+Z69+Z79 -> 0 | AA2: =AA15+AA26+AA37+AA48+AA58+AA69+AA79 -> 0 | AD2: =AD15+AD26+AD37+AD48+AD58+AD69+AD79 -> 0 | AE2: =AE15+AE26+AE37+AE48+AE58+AE69+AE79 -> 0
A3: 線別 | B3: 品類 | D3: 品名 | F3: 廠價 | G3: 生產量 | H3: 營收 | I3: 多次 生產 | J3: 人數 | K3: 產能/時 | L3: 人時性 | M3: 人數 | N3: 產能/時 | O3: 人時性 | P3: 人數 | Q3: 人時性 | R3: 達成率 | S3: 達成率平均 | T3: 生產時間 | V3: 前置、換線時間/分 | W3: 稼動時間/分 | X3: 休息時間 | Z3: 產線異常統計 (5分鐘以上) | AD3: 短暫停線統計 (5分鐘以下) | AF3: 產能/時 | AG3: 達成率 | AH3: 達成率平均
T4: 開始 | U4: 結束 | X4: 開始 | Y4: 結束 | Z4: 次數 | AA4: 時間/分 | AD4: 總次數 | AE4: 設備因素(次數)
A5: 自動一線 (ET-600) | B5: =VLOOKUP(D5,廠價表!$C$1:$E$41,2,0) -> #N/A | F5: =VLOOKUP(D5,廠價表!$C$1:$E$41,3,0) -> #N/A | G5: 2263 | H5: =F5*G5 -> #N/A | J5: =VLOOKUP(D5,產線配置圖!$A$3:$C$39,2,0) -> #N/A | K5: =VLOOKUP(D5,產線配置圖!$A$3:$C$39,3,0) -> #N/A | L5: =K5/J5 -> #N/A | M5: 15 | N5: =G5/W5*60 -> 1444.4681 | O5: =N5/M5 -> 96.297872 | P5: =M5-J5 -> #N/A | Q5: =O5-L5 -> #N/A | R5: =O5/L5 -> #N/A | S5: =R15 -> #N/A | T5: 0.29097222 | U5: 0.35625 | W5: =(U5-T5)*24*60 -> 94 | AF5: =N5-K5 -> #N/A | AG5: =N5/K5 -> #N/A | AH5: =AG15 -> #N/A
B6: =VLOOKUP(D6,廠價表!$C$1:$E$41,2,0) -> #N/A | F6: =VLOOKUP(D6,廠價表!$C$1:$E$41,3,0) -> #N/A | G6: 1180 | H6: =F6*G6 -> #N/A | J6: =VLOOKUP(D6,產線配置圖!$A$3:$C$39,2,0) -> #N/A | K6: =VLOOKUP(D6,產線配置圖!$A$3:$C$39,3,0) -> #N/A | L6: =K6/J6 -> #N/A | M6: 17 | N6: =G6/W6*60 -> 1609.0909 | O6: =N6/M6 -> 94.652406 | P6: =M6-J6 -> #N/A | Q6: =O6-L6 -> #N/A | R6: =O6/L6 -> #N/A | T6: 0.36458333 | U6: 0.39513889 | V6: =(T6-U5)*24*60 -> 12 | W6: =(U6-T6)*24*60 -> 44 | AF6: =N6-K6 -> #N/A | AG6: =N6/K6 -> #N/A
B7: =VLOOKUP(D7,廠價表!$C$1:$E$41,2,0) -> #N/A | F7: =VLOOKUP(D7,廠價表!$C$1:$E$41,3,0) -> #N/A | G7: 3398 | H7: =F7*G7 -> #N/A | J7: =VLOOKUP(D7,產線配置圖!$A$3:$C$39,2,0) -> #N/A | K7: =VLOOKUP(D7,產線配置圖!$A$3:$C$39,3,0) -> #N/A | L7: =K7/J7 -> #N/A | M7: 13 | N7: =G7/W7*60 -> 1960.3846 | O7: =N7/M7 -> 150.79882 | P7: =M7-J7 -> #N/A | Q7: =O7-L7 -> #N/A | R7: =O7/L7 -> #N/A | T7: 0.40138889 | U7: 0.47361111 | V7: =(T7-U6)*24*60 -> 9 | W7: =(U7-T7)*24*60 -> 104 | AF7: =N7-K7 -> #N/A | AG7: =N7/K7 -> #N/A
W8: =(U8-T8)*24*60 -> 0 | X8: 0.48611111 | Y8: 0.52777778 | AF8: =N8-K8 -> 0 | AG8: =N8/K8 -> #DIV/0!
W9: =(U9-T9)*24*60 -> 0 | AF9: =N9-K9 -> 0 | AG9: =N9/K9 -> #DIV/0!
W10: =(U10-T10)*24*60 -> 0 | AF10: =N10-K10 -> 0 | AG10: =N10/K10 -> #DIV/0!
W11: =(U11-T11)*24*60 -> 0 | AF11: =N11-K11 -> 0 | AG11: =N11/K11 -> #DIV/0!
W12: =(U12-T12)*24*60 -> 0
W13: =(U13-T13)*24*60 -> 0
W14: =(U14-T14)*24*60 -> 0
C15: 4度一組 | D15: 平均 | J15: =AVERAGE(J5:J14) -> #N/A | K15: =AVERAGE(K5:K14) -> #N/A | L15: =AVERAGE(L5:L14) -> #N/A | M15: =AVERAGE(M5:M14) -> 15 | N15: =AVERAGE(N5:N14) -> 1671.3145 | O15: =AVERAGE(O5:O14) -> 113.91637 | P15: =M15-J15 -> #N/A | Q15: =O15-L15 -> #N/A | R15: =O15/L15 -> #N/A | Z15: =SUM(Z5:Z14) -> 0 | AA15: =SUM(AA5:AA14) -> 0 | AD15: =SUM(AD5:AD14) -> 0 | AE15: =SUM(AE5:AE14) -> 0 | AF15: =N15-K15 -> #N/A | AG15: =N15/K15 -> #N/A
A16: 自動二線 (ET-600) | B16: =VLOOKUP(D16,廠價表!$C$1:$E$41,2,0) -> #N/A | F16: =VLOOKUP(D16,廠價表!$C$1:$E$41,3,0) -> #N/A | G16: 2263 | H16: =F16*G16 -> #N/A | J16: =VLOOKUP(D16,產線配置圖!$A$3:$C$39,2,0) -> #N/A | K16: =VLOOKUP(D16,產線配置圖!$A$3:$C$39,3,0) -> #N/A | L16: =K16/J16 -> #N/A | M16: 13 | N16: =G16/W16*60 -> 2225.9016 | O16: =N16/M16 -> 171.2232 | P16: =M16-J16 -> #N/A | Q16: =O16-L16 -> #N/A | R16: =O16/L16 -> #N/A | S16: =R26 -> #N/A | T16: 0.29097222 | U16: 0.33333333 | W16: =(U16-T16)*24*60 -> 61 | AF16: =N16-K16 -> #N/A | AG16: =N16/K16 -> #N/A | AH16: =AG26 -> #N/A
B17: =VLOOKUP(D17,廠價表!$C$1:$E$41,2,0) -> #N/A | F17: =VLOOKUP(D17,廠價表!$C$1:$E$41,3,0) -> #N/A | G17: 1180 | H17: =F17*G17 -> #N/A | J17: =VLOOKUP(D17,產線配置圖!$A$3:$C$39,2,0) -> #N/A | K17: =VLOOKUP(D17,產線配置圖!$A$3:$C$39,3,0) -> #N/A | L17: =K17/J17 -> #N/A | M17: 13 | N17: =G17/W17*60 -> 823.25581 | O17: =N17/M17 -> 63.32737 | P17: =M17-J17 -> #N/A | Q17: =O17-L17 -> #N/A | R17: =O17/L17 -> #N/A | T17: 0.34166667 | U17: 0.40138889 | V17: =(T17-U16)*24*60 -> 12 | W17: =(U17-T17)*24*60 -> 86 | AF17: =N17-K17 -> #N/A | AG17: =N17/K17 -> #N/A
B18: =VLOOKUP(D18,廠價表!$C$1:$E$41,2,0) -> #N/A | F18: =VLOOKUP(D18,廠價表!$C$1:$E$41,3,0) -> #N/A | G18: 3398 | H18: =F18*G18 -> #N/A | J18: =VLOOKUP(D18,產線配置圖!$A$3:$C$39,2,0) -> #N/A | K18: =VLOOKUP(D18,產線配置圖!$A$3:$C$39,3,0) -> #N/A | L18: =K18/J18 -> #N/A | M18: 12 | N18: =G18/W18*60 -> 1941.7143 | O18: =N18/M18 -> 161.80952 | P18: =M18-J18 -> #N/A | Q18: =O18-L18 -> #N/A | R18: =O18/L18 -> #N/A | T18: 0.40972222 | U18: 0.48263889 | V18: =(T18-U17)*24*60 -> 12 | W18: =(U18-T18)*24*60 -> 105 | X18: 0.48611111 | Y18: 0.52777778 | AF18: =N18-K18 -> #N/A | AG18: =N18/K18 -> #N/A
V19: =(T19-U18)*24*60 -> -695 | W19: =(U19-T19)*24*60 -> 0 | AF19: =N19-K19 -> 0 | AG19: =N19/K19 -> #DIV/0!
V20: =(T20-U19)*24*60 -> 0 | W20: =(U20-T20)*24*60 -> 0
W21: =(U21-T21)*24*60 -> 0
W22: 0
W23: =(U23-T23)*24*60 -> 0
H24: =F24*G24 -> 0 | W24: =(U24-T24)*24*60 -> 0
H25: =F25*G25 -> 0 | W25: =(U25-T25)*24*60 -> 0
C26: 4度二組A | D26: 平均 | J26: =AVERAGE(J16:J25) -> #N/A | K26: =AVERAGE(K16:K25) -> #N/A | L26: =AVERAGE(L16:L25) -> #N/A | M26: =AVERAGE(M16:M25) -> 12.666667 | N26: =AVERAGE(N16:N25) -> 1663.6239 | O26: =AVERAGE(O16:O25) -> 132.12003 | P26: =M26-J26 -> #N/A | Q26: =O26-L26 -> #N/A | R26: =O26/L26 -> #N/A | Z26: =SUM(Z16:Z25) -> 0 | AA26: =SUM(AA16:AA25) -> 0 | AD26: =SUM(AD16:AD25) -> 0 | AE26: =SUM(AE16:AE25) -> 0 | AF26: =N26-K26 -> #N/A | AG26: =N26/K26 -> #N/A
A27: 手工三線 (ET-55) | B27: =VLOOKUP(D27,廠價表!$C$1:$E$41,2,0) -> #N/A | F27: =VLOOKUP(D27,廠價表!$C$1:$E$41,3,0) -> #N/A | G27: 2263 | H27: =F27*G27 -> #N/A | J27: =VLOOKUP(D27,產線配置圖!$A$3:$C$39,2,0) -> #N/A | K27: =VLOOKUP(D27,產線配置圖!$A$3:$C$39,3,0) -> #N/A | L27: =K27/J27 -> #N/A | M27: 14 | N27: =G27/W27*60 -> 1212.3214 | O27: =N27/M27 -> 86.594388 | P27: =M27-J27 -> #N/A | Q27: =O27-L27 -> #N/A | R27: =O27/L27 -> #N/A | S27: =R37 -> #N/A | T27: 0.29166667 | U27: 0.36944444 | W27: =(U27-T27)*24*60 -> 112 | AF27: =N27-K27 -> #N/A | AG27: =N27/K27 -> #N/A | AH27: =AG37 -> #N/A
B28: =VLOOKUP(D28,廠價表!$C$1:$E$41,2,0) -> #N/A | F28: =VLOOKUP(D28,廠價表!$C$1:$E$41,3,0) -> #N/A | G28: 1180 | H28: =F28*G28 -> #N/A | J28: =VLOOKUP(D28,產線配置圖!$A$3:$C$39,2,0) -> #N/A | K28: =VLOOKUP(D28,產線配置圖!$A$3:$C$39,3,0) -> #N/A | L28: =K28/J28 -> #N/A | M28: 16 | N28: =G28/W28*60 -> 1089.2308 | O28: =N28/M28 -> 68.076923 | P28: =M28-J28 -> #N/A | Q28: =O28-L28 -> #N/A | R28: =O28/L28 -> #N/A | T28: 0.375 | U28: 0.42013889 | V28: =(T28-U27)*24*60 -> 8 | W28: =(U28-T28)*24*60 -> 65 | AF28: =N28-K28 -> #N/A | AG28: =N28/K28 -> #N/A
B29: =VLOOKUP(D29,廠價表!$C$1:$E$41,2,0) -> #N/A | F29: =VLOOKUP(D29,廠價表!$C$1:$E$41,3,0) -> #N/A | G29: 3398 | H29: =F29*G29 -> #N/A | J29: =VLOOKUP(D29,產線配置圖!$A$3:$C$39,2,0) -> #N/A | K29: =VLOOKUP(D29,產線配置圖!$A$3:$C$39,3,0) -> #N/A | L29: =K29/J29 -> #N/A | M29: 14 | N29: =G29/W29*60 -> 3136.6154 | O29: =N29/M29 -> 224.04396 | P29: =M29-J29 -> #N/A | Q29: =O29-L29 -> #N/A | R29: =O29/L29 -> #N/A | T29: 0.43055556 | U29: 0.47569444 | V29: =(T29-U28)*24*60 -> 15 | W29: =(U29-T29)*24*60 -> 65 | AF29: =N29-K29 -> #N/A | AG29: =N29/K29 -> #N/A
T30: 0.53958333 | U30: 0.56944444 | V30: =(T30-U29)*24*60 -> 92 | W30: =(U30-T30)*24*60 -> 43 | X30: 0.49652778 | Y30: 0.53819444 | AF30: =N30-K30 -> 0 | AG30: =N30/K30 -> #DIV/0!
W31: =(U31-T31)*24*60 -> 0 | AF31: =N31-K31 -> 0 | AG31: =N31/K31 -> #DIV/0!
W32: =(U32-T32)*24*60 -> 0
W33: =(U33-T33)*24*60 -> 0
W34: =(U34-T34)*24*60 -> 0
W35: =(U35-T35)*24*60 -> 0
H36: =F36*G36 -> 0 | W36: =(U36-T36)*24*60 -> 0
C37: 4度二組B | D37: 平均 | J37: =AVERAGE(J27:J36) -> #N/A | K37: =AVERAGE(K27:K36) -> #N/A | L37: =AVERAGE(L27:L36) -> #N/A | M37: =AVERAGE(M27:M36) -> 14.666667 | N37: =AVERAGE(N27:N36) -> 1812.7225 | O37: =AVERAGE(O27:O36) -> 126.23842 | P37: =M37-J37 -> #N/A | Q37: =N37-K37 -> #N/A | R37: =O37/L37 -> #N/A | Z37: =SUM(Z27:Z36) -> 0 | AA37: =SUM(AA27:AA36) -> 0 | AD37: =SUM(AD27:AD36) -> 0 | AE37: =SUM(AE27:AE36) -> 0 | AF37: =N37-K37 -> #N/A | AG37: =N37/K37 -> #N/A
A38: 手工四線 (ET-55) | B38: =VLOOKUP(D38,廠價表!$C$1:$E$41,2,0) -> #N/A | F38: =VLOOKUP(D38,廠價表!$C$1:$E$41,3,0) -> #N/A | G38: 2263 | H38: =F38*G38 -> #N/A | J38: =VLOOKUP(D38,產線配置圖!$A$3:$C$39,2,0) -> #N/A | K38: =VLOOKUP(D38,產線配置圖!$A$3:$C$39,3,0) -> #N/A | L38: =K38/J38 -> #N/A | M38: 14 | N38: =G38/W38*60 -> 1967.8261 | O38: =N38/M38 -> 140.55901 | P38: =M38-J38 -> #N/A | Q38: =O38-L38 -> #N/A | R38: =O38/L38 -> #N/A | S38: =R48 -> #N/A | T38: 0.33333333 | U38: 0.38125 | W38: =(U38-T38)*24*60 -> 69 | AF38: =N38-K38 -> #N/A | AG38: =N38/K38 -> #N/A | AH38: =AG48 -> #N/A
B39: =VLOOKUP(D39,廠價表!$C$1:$E$41,2,0) -> #N/A | F39: =VLOOKUP(D39,廠價表!$C$1:$E$41,3,0) -> #N/A | G39: 1180 | H39: =F39*G39 -> #N/A | J39: =VLOOKUP(D39,產線配置圖!$A$3:$C$39,2,0) -> #N/A | K39: =VLOOKUP(D39,產線配置圖!$A$3:$C$39,3,0) -> #N/A | L39: =K39/J39 -> #N/A | M39: 14 | N39: =G39/W39*60 -> 885 | O39: =N39/M39 -> 63.214286 | P39: =M39-J39 -> #N/A | Q39: =O39-L39 -> #N/A | R39: =O39/L39 -> #N/A | T39: 0.38888889 | U39: 0.44444444 | V39: =(T39-U38)*24*60 -> 11 | W39: =(U39-T39)*24*60 -> 80 | AF39: =N39-K39 -> #N/A | AG39: =N39/K39 -> #N/A
B40: =VLOOKUP(D40,廠價表!$C$1:$E$41,2,0) -> #N/A | F40: =VLOOKUP(D40,廠價表!$C$1:$E$41,3,0) -> #N/A | G40: 3398 | H40: =F40*G40 -> #N/A | J40: =VLOOKUP(D40,產線配置圖!$A$3:$C$39,2,0) -> #N/A | K40: =VLOOKUP(D40,產線配置圖!$A$3:$C$39,3,0) -> #N/A | L40: =K40/J40 -> #N/A | M40: 14 | N40: =G40/W40*60 -> 1853.4545 | O40: =N40/M40 -> 132.38961 | P40: =M40-J40 -> #N/A | Q40: =O40-L40 -> #N/A | R40: =O40/L40 -> #N/A | T40: 0.52777778 | U40: 0.60416667 | V40: =(T40-U39)*24*60 -> 120 | W40: =(U40-T40)*24*60 -> 110 | AF40: =N40-K40 -> #N/A | AG40: =N40/K40 -> #N/A
...

Sheet 0101總
B1: 長家廠組合室生產人時性分析
B3: 日期 | D3: 46023 | F3: 訂單量 | G3: ='0101'!E1 -> 46936 | I3: 營業額 | J3: ='0101'!G1 -> 2271948.9
B4: 項目 | D4: 3 | F4: ➀ | H4: ➁ | J4: ③ | L4: 異常停線 | N4: 短暫停線
B5: 人時性 | D5: 組合室 | F5: 全溫層 | H5: 義大利麵 | J5: 袋裝小吃、義麵 | L5: 合計次數 | M5: 時間 | N5: 合計次數 | O5: 設備次數
D6: 排關平均 | F6: =AVERAGE(D13:J13) -> 110.92422 | H6: =AVERAGE(D13:H13,J13) -> 108.09348 | J6: =AVERAGE(I13) -> 127.90865 | L6: ='0101'!Z2 -> 4 | M6: ='0101'!AA2 -> 88 | N6: ='0101'!AD2 -> 0 | O6: ='0101'!AE2 -> 0
D7: 實績平均 | F7: =AVERAGE(D14:J14) -> 96.330213 | H7: =AVERAGE(D14:H14,J14) -> 93.598205 | J7: =AVERAGE(I14) -> 112.72226
D8: 達成率平均 | F8: =F7/F6 -> 0.86843262 | H8: =H7/H6 -> 0.86590054 | J8: =J7/J6 -> 0.88127158
J9: ※現行日本鮮食廠以達成率80%為基本(即為現行KPI)
B10: 溫層 | D10: 4度C-各編組展開
B11: 編組 | D11: 1 | E11: 2 | F11: 3 | G11: 4 | H11: 5 | I11: 6 | J11: 7
D12: 自動1線 | E12: 自動2線 | F12: 手工3線 | G12: 手工4線 | H12: 手工5線 | I12: 調理包1線 | J12: 調理包2線
B13: 人時性 | C13: 排關 | D13: =VALUE('0101'!L15) -> 116.40159 | E13: =VALUE('0101'!L26) -> 162.27564 | F13: =VALUE('0101'!L37) -> 84.779412 | G13: =VALUE('0101'!L48) -> 83.408991 | H13: =VALUE('0101'!L58) -> 89.195261 | I13: =VALUE('0101'!L69) -> 127.90865 | J13: ='0101'!L79 -> 112.5
C14: 實績 | D14: =VALUE('0101'!O15) -> 103.81803 | E14: =VALUE('0101'!O26) -> 138.58069 | F14: =VALUE('0101'!O37) -> 78.256979 | G14: =VALUE('0101'!O48) -> 71.6794 | H14: =VALUE('0101'!O58) -> 80.992062 | I14: =VALUE('0101'!O69) -> 112.72226 | J14: ='0101'!O79 -> 88.262069
C15: 達成率 | D15: =D14/D13 -> 0.89189529 | E15: =E14/E13 -> 0.8539833 | F15: =F14/F13 -> 0.92306584 | G15: =G14/G13 -> 0.85937258 | H15: =H14/H13 -> 0.90803099 | I15: =I14/I13 -> 0.88127158 | J15: =J14/J13 -> 0.78455172
B16: 作業 時間 | C16: 開始 | D16: ='0101'!T5 -> 0.29027778 | E16: ='0101'!T16 -> 0.29027778 | F16: ='0101'!T27 -> 0.29166667 | G16: ='0101'!T38 -> 0.33333333 | H16: ='0101'!T49 -> 0.28888889 | I16: ='0101'!T59 -> 0.29166667 | J16: ='0101'!T70 -> 0.34027778
C17: 結束 | D17: 0.64583333 | E17: 0.59652778 | F17: 0.58333333 | G17: 0.60902778 | H17: 0.61458333 | I17: 0.55902778 | J17: 0.44097222
B18: 產線異常 (5分鐘以上) | C18: 次數 | D18: ='0101'!Z15 -> 1 | E18: ='0101'!Z26 -> 1 | F18: ='0101'!Z37 -> 1 | G18: ='0101'!Z48 -> 1 | H18: ='0101'!Z58 -> 0 | I18: ='0101'!Z69 -> 0 | J18: ='0101'!Z79 -> 0
C19: 時間/分 | D19: ='0101'!AA15 -> 23 | E19: ='0101'!AA26 -> 29 | F19: ='0101'!AA37 -> 15 | G19: ='0101'!AA48 -> 21 | H19: ='0101'!AA58 -> 0 | I19: ='0101'!AA69 -> 0 | J19: ='0101'!AA79 -> 0
B20: 短暫停線 (5分鐘以下) | C20: 次數 | D20: ='0101'!AD15 -> 0 | E20: ='0101'!AD26 -> 0 | F20: ='0101'!AD37 -> 0 | G20: ='0101'!AD48 -> 0 | H20: ='0101'!AD58 -> 0 | I20: ='0101'!AD69 -> 0 | J20: ='0101'!AD79 -> 0
C21: 設備次數 | D21: ='0101'!AE15 -> 0 | E21: ='0101'!AD15 -> 0 | F21: ='0101'!AE37 -> 0 | G21: ='0101'!AE48 -> 0 | H21: ='0101'!AE58 -> 0 | I21: ='0101'!AE69 -> 0 | J21: ='0101'!AE79 -> 0
B22: 配置人數 | D22: =VALUE('0101'!M15) -> 15.2 | E22: =VALUE('0101'!M26) -> 12.75 | F22: =VALUE('0101'!M37) -> 15.5 | G22: =VALUE('0101'!M48) -> 14 | H22: =VALUE('0101'!M58) -> 16.75 | I22: =VALUE('0101'!M69) -> 11.75 | J22: ='0101'!M79 -> 10
B23: 主要應用設備 | D23: ET-600 | E23: ET-600 | F23: ET-55 | G23: ET-55 | H23: ET-55 | I23: 八爪機
B24: 次要應用設備 | H24: 封口機
B25: 備註

Sheet 0101
A1: 長家廠4度C日報分析 | D1: 總生產量 | E1: =SUM(G5:G79) -> 46936 | F1: 營業額 | G1: =SUM(H5:H79) -> 2271948.9 | H1: 出勤人數 | I1: =M15+M26+M48+M58+M69+M79+M37 -> 95.95 | J1: 產線配置圖 | M1: 生產實績 | P1: 人時性差異分析 | T1: 日報登錄 | Z1: 合計 次數 | AA1: 合計 時間/分 | AB1: 分析說明 | AD1: 合計 次數 | AE1: 合計 設備次數 | AF1: 產能差異分析
A2: 01月01日 星期四 | D2: 人時性 | E2: =AVERAGE(O15,O26,O37,O48,O58,O69,O79) -> 96.330213 | F2: 平均廠價 | G2: =G1/E1 -> 48.405251 | H2: 多次生產數 | I2: =COUNT(I5:I79) -> 0 | Z2: =Z15+Z26+Z37+Z48+Z58+Z69+Z79 -> 4 | AA2: =AA15+AA26+AA37+AA48+AA58+AA69+AA79 -> 88 | AD2: =AD15+AD26+AD37+AD48+AD58+AD69+AD79 -> 0 | AE2: =AE15+AE26+AE37+AE48+AE58+AE69+AE79 -> 0
A3: 線別 | B3: 品類 | D3: 品名 | F3: 廠價 | G3: 生產量 | H3: 營收 | I3: 多次 生產 | J3: 人數 | K3: 產能/時 | L3: 人時性 | M3: 人數 | N3: 產能/時 | O3: 人時性 | P3: 人數 | Q3: 人時性 | R3: 達成率 | S3: 達成率平均 | T3: 生產時間 | V3: 前置、換線時間/分 | W3: 稼動時間/分 | X3: 休息時間 | Z3: 產線異常統計 (5分鐘以上) | AD3: 短暫停線統計 (5分鐘以下) | AF3: 產能/時 | AG3: 達成率 | AH3: 達成率平均
T4: 開始 | U4: 結束 | X4: 開始 | Y4: 結束 | Z4: 次數 | AA4: 時間/分 | AD4: 總次數 | AE4: 設備因素(次數)
A5: 自動一線 (ET-600) | B5: 義大利麵 | D5: 奶油起司蝦仁通心粉 | F5: =VLOOKUP(D5,廠價表!$C$1:$E$41,3,0) -> 47.71 | G5: 2682 | H5: =F5*G5 -> 127958.22 | J5: =VLOOKUP(D5,產線配置圖!$A$3:$C$39,2,0) -> 14 | K5: =VLOOKUP(D5,產線配置圖!$A$3:$C$39,3,0) -> 1440 | L5: =K5/J5 -> 102.85714 | M5: 14 | N5: =G5/W5*60 -> 1436.7857 | O5: =N5/M5 -> 102.62755 | P5: =M5-J5 -> 0 | Q5: =O5-L5 -> -0.22959184 | R5: =O5/L5 -> 0.99776786 | S5: =R15 -> 0.89189529 | T5: 0.29027778 | U5: 0.36805556 | W5: =(U5-T5)*24*60 -> 112 | AF5: =N5-K5 -> -3.2142857 | AG5: =N5/K5 -> 0.99776786 | AH5: =AG15 -> 0.88224908
B6: 義大利麵 | D6: 韓式起司炸雞義大利麵 | F6: =VLOOKUP(D6,廠價表!$C$1:$E$41,3,0) -> 57.21 | G6: 1463 | H6: =F6*G6 -> 83698.23 | J6: =VLOOKUP(D6,產線配置圖!$A$3:$C$39,2,0) -> 17 | K6: =VLOOKUP(D6,產線配置圖!$A$3:$C$39,3,0) -> 2000 | L6: =K6/J6 -> 117.64706 | M6: 17 | N6: =G6/W6*60 -> 1995 | O6: =N6/M6 -> 117.35294 | P6: =M6-J6 -> 0 | Q6: =O6-L6 -> -0.29411765 | R6: =O6/L6 -> 0.9975 | T6: 0.37361111 | U6: 0.40416667 | V6: =(T6-U5)*24*60 -> 8 | W6: =(U6-T6)*24*60 -> 44 | AF6: =N6-K6 -> -5 | AG6: =N6/K6 -> 0.9975
B7: 義大利麵 | D7: 奶油培根義大利麵 | F7: =VLOOKUP(D7,廠價表!$C$1:$E$41,3,0) -> 49.14 | G7: 3223 | H7: =F7*G7 -> 158378.22 | J7: =VLOOKUP(D7,產線配置圖!$A$3:$C$39,2,0) -> 14 | K7: =VLOOKUP(D7,產線配置圖!$A$3:$C$39,3,0) -> 2000 | L7: =K7/J7 -> 142.85714 | M7: 14 | N7: =G7/W7*60 -> 1993.6082 | O7: =N7/M7 -> 142.40059 | P7: =M7-J7 -> 0 | Q7: =O7-L7 -> -0.45655376 | R7: =O7/L7 -> 0.99680412 | T7: 0.41041667 | U7: 0.47777778 | V7: =(T7-U6)*24*60 -> 9 | W7: =(U7-T7)*24*60 -> 97 | AF7: =N7-K7 -> -6.3917526 | AG7: =N7/K7 -> 0.99680412
B8: 義大利麵 | D8: 奶油培根義大利麵 | F8: =VLOOKUP(D8,廠價表!$C$1:$E$41,3,0) -> 49.14 | G8: 1111 | H8: =F8*G8 -> 54594.54 | J8: =VLOOKUP(D8,產線配置圖!$A$3:$C$39,2,0) -> 14 | K8: =VLOOKUP(D8,產線配置圖!$A$3:$C$39,3,0) -> 2000 | L8: =K8/J8 -> 142.85714 | M8: 14 | N8: =G8/W8*60 -> 1190.3571 | O8: =N8/M8 -> 85.02551 | P8: =M8-J8 -> 0 | Q8: =O8-L8 -> -57.831633 | R8: =O8/L8 -> 0.59517857 | T8: 0.54027778 | U8: 0.57916667 | V8: =(T8-U7)*24*60 -> 90 | W8: =(U8-T8)*24*60 -> 56 | X8: 0.48611111 | Y8: 0.52777778 | Z8: 1 | AA8: 23 | AB8: 玉取機停麵 | AF8: =N8-K8 -> -809.64286 | AG8: =N8/K8 -> 0.59517857
B9: 熱乾麵 | D9: 府城鹽水意麵 | F9: =VLOOKUP(D9,廠價表!$C$1:$E$41,3,0) -> 44.3 | G9: 1178 | H9: =F9*G9 -> 52185.4 | J9: =VLOOKUP(D9,產線配置圖!$A$3:$C$39,2,0) -> 19 | K9: =VLOOKUP(D9,產線配置圖!$A$3:$C$39,3,0) -> 1440 | L9: =K9/J9 -> 75.789474 | M9: 17 | N9: =G9/W9*60 -> 1218.6207 | O9: =N9/M9 -> 71.68357 | P9: =M9-J9 -> -2 | Q9: =O9-L9 -> -4.1059037 | R9: =O9/L9 -> 0.94582488 | T9: 0.60555556 | U9: 0.64583333 | W9: =(U9-T9)*24*60 -> 58 | AB9: 協助製作 | AF9: =N9-K9 -> -221.37931 | AG9: =N9/K9 -> 0.84626437
AF10: =N10-K10 -> 0 | AG10: =N10/K10 -> #DIV/0!
AF11: =N11-K11 -> 0 | AG11: =N11/K11 -> #DIV/0!
W12: =(U12-T12)*24*60 -> 0
V13: . | W13: =(U13-T13)*24*60 -> 0
W14: =(U14-T14)*24*60 -> 0
C15: 4度一組 | D15: 平均 | J15: =AVERAGE(J5:J14) -> 15.6 | K15: =AVERAGE(K5:K14) -> 1776 | L15: =AVERAGE(L5:L14) -> 116.40159 | M15: =AVERAGE(M5:M14) -> 15.2 | N15: =AVERAGE(N5:N14) -> 1566.8744 | O15: =AVERAGE(O5:O14) -> 103.81803 | P15: =M15-J15 -> -0.4 | Q15: =O15-L15 -> -12.58356 | R15: =O15/L15 -> 0.89189529 | Z15: =SUM(Z5:Z14) -> 1 | AA15: =SUM(AA5:AA14) -> 23 | AD15: =SUM(AD5:AD14) -> 0 | AE15: =SUM(AE5:AE14) -> 0 | AF15: =N15-K15 -> -209.12564 | AG15: =N15/K15 -> 0.88224908
A16: 自動二線 (ET-600) | B16: 義大利麵 | D16: 白酒蛤蜊義大利麵 | F16: =VLOOKUP(D16,廠價表!$C$1:$E$41,3,0) -> 57.21 | G16: 2324 | H16: =F16*G16 -> 132956.04 | J16: =VLOOKUP(D16,產線配置圖!$A$3:$C$39,2,0) -> 13 | K16: =VLOOKUP(D16,產線配置圖!$A$3:$C$39,3,0) -> 2105 | L16: =K16/J16 -> 161.92308 | M16: 14 | N16: =G16/W16*60 -> 1936.6667 | O16: =N16/M16 -> 138.33333 | P16: =M16-J16 -> 1 | Q16: =O16-L16 -> -23.589744 | R16: =O16/L16 -> 0.85431512 | S16: =R26 -> 0.8539833 | T16: 0.29027778 | U16: 0.34027778 | W16: =(U16-T16)*24*60 -> 72 | AB16: 封膜頻繁異常，多一人進行作業 | AF16: =N16-K16 -> -168.33333 | AG16: =N16/K16 -> 0.92003167 | AH16: =AG26 -> 0.87374294
B17: 義大利麵 | D17: 青醬蛤蜊義大利麵 | F17: =VLOOKUP(D17,廠價表!$C$1:$E$41,3,0) -> 50.67 | G17: 3285 | H17: =F17*G17 -> 166450.95 | J17: =VLOOKUP(D17,產線配置圖!$A$3:$C$39,2,0) -> 13 | K17: =VLOOKUP(D17,產線配置圖!$A$3:$C$39,3,0) -> 2000 | L17: =K17/J17 -> 153.84615 | M17: 13 | N17: =G17/W17*60 -> 1990.9091 | O17: =N17/M17 -> 153.14685 | P17: =M17-J17 -> 0 | Q17: =O17-L17 -> -0.6993007 | R17: =O17/L17 -> 0.99545455 | T17: 0.34722222 | U17: 0.41597222 | V17: =(T17-U16)*24*60 -> 10 | W17: =(U17-T17)*24*60 -> 99 | AF17: =N17-K17 -> -9.0909091 | AG17: =N17/K17 -> 0.99545455
B18: 義大利麵 | D18: 義式蕃茄起司義大利麵 | F18: =VLOOKUP(D18,廠價表!$C$1:$E$41,3,0) -> 50.39 | G18: 2487 | H18: =F18*G18 -> 125319.93 | J18: =VLOOKUP(D18,產線配置圖!$A$3:$C$39,2,0) -> 12 | K18: =VLOOKUP(D18,產線配置圖!$A$3:$C$39,3,0) -> 2000 | L18: =K18/J18 -> 166.66667 | M18: 12 | N18: =G18/W18*60 -> 1865.25 | O18: =N18/M18 -> 155.4375 | P18: =M18-J18 -> 0 | Q18: =O18-L18 -> -11.229167 | R18: =O18/L18 -> 0.932625 | T18: 0.42361111 | U18: 0.47916667 | V18: =(T18-U17)*24*60 -> 11 | W18: =(U18-T18)*24*60 -> 80 | X18: 0.48611111 | Y18: 0.52777778 | AF18: =N18-K18 -> -134.75 | AG18: =N18/K18 -> 0.932625
B19: 義大利麵 | D19: 義式蕃茄起司義大利麵 | F19: =VLOOKUP(D19,廠價表!$C$1:$E$41,3,0) -> 50.39 | G19: 1697 | H19: =F19*G19 -> 85511.83 | J19: =VLOOKUP(D19,產線配置圖!$A$3:$C$39,2,0) -> 12 | K19: =VLOOKUP(D19,產線配置圖!$A$3:$C$39,3,0) -> 2000 | L19: =K19/J19 -> 166.66667 | M19: 12 | N19: =G19/W19*60 -> 1288.8608 | O19: =N19/M19 -> 107.40506 | P19: =M19-J19 -> 0 | Q19: =O19-L19 -> -59.261603 | R19: =O19/L19 -> 0.64443038 | T19: 0.54166667 | U19: 0.59652778 | V19: =(T19-U18)*24*60 -> 90 | W19: =(U19-T19)*24*60 -> 79 | Z19: 1 | AA19: 29 | AB19: 玉取機停麵 | AF19: =N19-K19 -> -711.13924 | AG19: =N19/K19 -> 0.64443038
W20: =(U20-T20)*24*60 -> 0
W21: =(U21-T21)*24*60 -> 0
W22: 0
W23: =(U23-T23)*24*60 -> 0
H24: =F24*G24 -> 0 | W24: =(U24-T24)*24*60 -> 0
H25: =F25*G25 -> 0 | W25: =(U25-T25)*24*60 -> 0
C26: 4度二組A | D26: 平均 | J26: =AVERAGE(J16:J25) -> 12.5 | K26: =AVERAGE(K16:K25) -> 2026.25 | L26: =AVERAGE(L16:L25) -> 162.27564 | M26: =AVERAGE(M16:M25) -> 12.75 | N26: =AVERAGE(N16:N25) -> 1770.4216 | O26: =AVERAGE(O16:O25) -> 138.58069 | P26: =M26-J26 -> 0.25 | Q26: =O26-L26 -> -23.694954 | R26: =O26/L26 -> 0.8539833 | Z26: =SUM(Z16:Z25) -> 1 | AA26: =SUM(AA16:AA25) -> 29 | AD26: =SUM(AD16:AD25) -> 0 | AE26: =SUM(AE16:AE25) -> 0 | AF26: =N26-K26 -> -255.82837 | AG26: =N26/K26 -> 0.87374294
A27: 手工三線 (ET-55) | B27: 義大利麵 | D27: 惡魔乳酪生義大利麵 | F27: =VLOOKUP(D27,廠價表!$C$1:$E$41,3,0) -> 57.3 | G27: 2725 | H27: =F27*G27 -> 156142.5 | J27: =VLOOKUP(D27,產線配置圖!$A$3:$C$39,2,0) -> 17 | K27: =VLOOKUP(D27,產線配置圖!$A$3:$C$39,3,0) -> 1500 | L27: =K27/J27 -> 88.235294 | M27: 14 | N27: =G27/W27*60 -> 1202.2059 | O27: =N27/M27 -> 85.871849 | P27: =M27-J27 -> -3 | Q27: =O27-L27 -> -2.3634454 | R27: =O27/L27 -> 0.97321429 | S27: =R37 -> 0.92306584 | T27: 0.29166667 | U27: 0.38611111 | W27: =(U27-T27)*24*60 -> 136 | Z27: 1 | AA27: 15 | AB27: 熱轉印異常 | AF27: =N27-K27 -> -297.79412 | AG27: =N27/K27 -> 0.80147059 | AH27: =AG37 -> 0.83888406
B28: 義大利麵 | D28: 奶油蒜香雞義大利麵 | F28: =VLOOKUP(D28,廠價表!$C$1:$E$41,3,0) -> 55.13 | G28: 1609 | H28: =F28*G28 -> 88704.17 | J28: =VLOOKUP(D28,產線配置圖!$A$3:$C$39,2,0) -> 17 | K28: =VLOOKUP(D28,產線配置圖!$A$3:$C$39,3,0) -> 1385 | L28: =K28/J28 -> 81.470588 | M28: 18 | N28: =G28/W28*60 -> 1359.7183 | O28: =N28/M28 -> 75.539906 | P28: =M28-J28 -> 1 | Q28: =O28-L28 -> -5.9306821 | R28: =O28/L28 -> 0.92720462 | T28: 0.39166667 | U28: 0.44097222 | V28: =(T28-U27)*24*60 -> 8 | W28: =(U28-T28)*24*60 -> 71 | AF28: =N28-K28 -> -25.28169 | AG28: =N28/K28 -> 0.98174607
B29: 熱乾麵 | D29: 沙茶豬肉炒麵 | F29: =VLOOKUP(D29,廠價表!$C$1:$E$41,3,0) -> 49.52 | G29: 1065 | H29: =F29*G29 -> 52738.8 | J29: =VLOOKUP(D29,產線配置圖!$A$3:$C$39,2,0) -> 17 | K29: =VLOOKUP(D29,產線配置圖!$A$3:$C$39,3,0) -> 1440 | L29: =K29/J29 -> 84.705882 | M29: 15 | N29: =G29/W29*60 -> 1183.3333 | O29: =N29/M29 -> 78.888889 | P29: =M29-J29 -> -2 | Q29: =O29-L29 -> -5.8169935 | R29: =O29/L29 -> 0.93132716 | T29: 0.44722222 | U29: 0.48472222 | V29: =(T29-U28)*24*60 -> 9 | W29: =(U29-T29)*24*60 -> 54 | AF29: =N29-K29 -> -256.66667 | AG29: =N29/K29 -> 0.82175926
B30: 熱乾麵 | D30: 沙茶豬肉炒麵 | F30: =VLOOKUP(D30,廠價表!$C$1:$E$41,3,0) -> 49.52 | G30: 1000 | H30: =F30*G30 -> 49520 | J30: =VLOOKUP(D30,產線配置圖!$A$3:$C$39,2,0) -> 17 | K30: =VLOOKUP(D30,產線配置圖!$A$3:$C$39,3,0) -> 1440 | L30: =K30/J30 -> 84.705882 | M30: 15 | N30: =G30/W30*60 -> 1090.9091 | O30: =N30/M30 -> 72.727273 | P30: =M30-J30 -> -2 | Q30: =O30-L30 -> -11.97861 | R30: =O30/L30 -> 0.85858586 | T30: 0.54513889 | U30: 0.58333333 | V30: =(T30-U29)*24*60 -> 87 | W30: =(U30-T30)*24*60 -> 55 | X30: 0.49652778 | Y30: 0.53819444 | AF30: =N30-K30 -> -349.09091 | AG30: =N30/K30 -> 0.75757576
W31: =(U31-T31)*24*60 -> 0 | AF31: =N31-K31 -> 0 | AG31: =N31/K31 -> #DIV/0!
W32: =(U32-T32)*24*60 -> 0
W33: =(U33-T33)*24*60 -> 0
W34: =(U34-T34)*24*60 -> 0
W35: =(U35-T35)*24*60 -> 0
H36: =F36*G36 -> 0 | W36: =(U36-T36)*24*60 -> 0
C37: 4度二組B | D37: 平均 | J37: =AVERAGE(J27:J36) -> 17 | K37: =AVERAGE(K27:K36) -> 1441.25 | L37: =AVERAGE(L27:L36) -> 84.779412 | M37: =AVERAGE(M27:M36) -> 15.5 | N37: =AVERAGE(N27:N36) -> 1209.0417 | O37: =AVERAGE(O27:O36) -> 78.256979 | P37: =M37-J37 -> -1.5 | Q37: =N37-K37 -> -232.20835 | R37: =O37/L37 -> 0.92306584 | Z37: =SUM(Z27:Z36) -> 1 | AA37: =SUM(AA27:AA36) -> 15 | AD37: =SUM(AD27:AD36) -> 0 | AE37: =SUM(AE27:AE36) -> 0 | AF37: =N37-K37 -> -232.20835 | AG37: =N37/K37 -> 0.83888406
A38: 手工四線 (ET-55) | B38: 義大利麵 | D38: 焗烤明太子筆尖麵 | F38: =VLOOKUP(D38,廠價表!$C$1:$E$41,3,0) -> 57.3 | G38: 1821 | H38: =F38*G38 -> 104343.3 | J38: =VLOOKUP(D38,產線配置圖!$A$3:$C$39,2,0) -> 16 | K38: =VLOOKUP(D38,產線配置圖!$A$3:$C$39,3,0) -> 1385 | L38: =K38/J38 -> 86.5625 | M38: 14 | N38: =G38/W38*60 -> 1150.1053 | O38: =N38/M38 -> 82.150376 | P38: =M38-J38 -> -2 | Q38: =O38-L38 -> -4.4121241 | R38: =O38/L38 -> 0.94902961 | S38: =R48 -> 0.85937258 | T38: 0.33333333 | U38: 0.39930556 | W38: =(U38-T38)*24*60 -> 95 | AF38: =N38-K38 -> -234.89474 | AG38: =N38/K38 -> 0.83040091 | AH38: =AG48 -> 0.71154215
B39: 義大利麵 | D39: 濃拿坡里義大利麵 | F39: =VLOOKUP(D39,廠價表!$C$1:$E$41,3,0) -> 56.43 | G39: 1356 | H39: =F39*G39 -> 76519.08 | J39: =VLOOKUP(D39,產線配置圖!$A$3:$C$39,2,0) -> 16 | K39: =VLOOKUP(D39,產線配置圖!$A$3:$C$39,3,0) -> 1406 | L39: =K39/J39 -> 87.875 | M39: 14 | N39: =G39/W39*60 -> 838.76289 | O39: =N39/M39 -> 59.911635 | P39: =M39-J39 -> -2 | Q39: =O39-L39 -> -27.963365 | R39: =O39/L39 -> 0.68178247 | T39: 0.40972222 | U39: 0.47708333 | V39: =(T39-U38)*24*60 -> 15 | W39: =(U39-T39)*24*60 -> 97 | Z39: 1 | AA39: 21 | AB39: 封膜機異常 | AF39: =N39-K39 -> -567.23711 | AG39: =N39/K39 -> 0.59655966
B40: 熱乾麵 | D40: 府城鹽水意麵 | F40: =VLOOKUP(D40,廠價表!$C$1:$E$41,3,0) -> 44.3 | G40: 1226 | H40: =F40*G40 -> 54311.8 | J40: =VLOOKUP(D40,產線配置圖!$A$3:$C$39,2,0) -> 19 | K40: =VLOOKUP(D40,產線配置圖!$A$3:$C$39,3,0) -> 1440 | L40: =K40/J40 -> 75.789474 | M40: 14 | N40: =G40/W40*60 -> 1021.6667 | O40: =N40/M40 -> 72.97619 | P40: =M40-J40 -> -5 | Q40: =O40-L40 -> -2.8132832 | R40: =O40/L40 -> 0.96288029 | T40: 0.55902778 | U40: 0.60902778 | V40: =(T40-U39)*24*60 -> 118 | W40: =(U40-T40)*24*60 -> 72 | AF40: =N40-K40 -> -418.33333 | AG40: =N40/K40 -> 0.70949074
...

Sheet 0102總
B1: 長家廠組合室生產人時性分析
B3: 日期 | D3: 46024 | F3: 訂單量 | G3: ='0102'!E1 -> 40942 | I3: 營業額 | J3: ='0102'!G1 -> 1980092.8
B4: 項目 | D4: 3 | F4: ➀ | H4: ➁ | J4: ③ | L4: 異常停線 | N4: 短暫停線
B5: 人時性 | D5: 組合室 | F5: 全溫層 | H5: 義大利麵 | J5: 袋裝小吃、義麵 | L5: 合計次數 | M5: 時間 | N5: 合計次數 | O5: 設備次數
D6: 排關平均 | F6: =AVERAGE(D13:J13) -> 111.99825 | H6: =AVERAGE(D13:H13,J13) -> 109.48585 | J6: =AVERAGE(I13) -> 127.07265 | L6: ='0102'!Z2 -> 4 | M6: ='0102'!AA2 -> 48 | N6: ='0102'!AD2 -> 3 | O6: ='0102'!AE2 -> 2
D7: 實績平均 | F7: =AVERAGE(D14:J14) -> 92.00702 | H7: =AVERAGE(D14:H14,J14) -> 91.72482 | J7: =AVERAGE(I14) -> 93.700216
D8: 達成率平均 | F8: =F7/F6 -> 0.82150406 | H8: =H7/H6 -> 0.83777782 | J8: =J7/J6 -> 0.73737517
J9: ※現行日本鮮食廠以達成率80%為基本(即為現行KPI)
B10: 溫層 | D10: 4度C-各編組展開
B11: 編組 | D11: 1 | E11: 2 | F11: 3 | G11: 4 | H11: 5 | I11: 6 | J11: 7
D12: 自動1線 | E12: 自動2線 | F12: 手工3線 | G12: 手工4線 | H12: 手工5線 | I12: 調理包1線 | J12: 調理包2線
B13: 人時性 | C13: 排關 | D13: =VALUE('0102'!L15) -> 126.55462 | E13: =VALUE('0102'!L26) -> 162.27564 | F13: =VALUE('0102'!L37) -> 85.661765 | G13: =VALUE('0102'!L48) -> 83.408991 | H13: =VALUE('0102'!L58) -> 86.514104 | I13: =VALUE('0102'!L69) -> 127.07265 | J13: ='0102'!L79 -> 112.5
C14: 實績 | D14: =VALUE('0102'!O15) -> 105.12203 | E14: =VALUE('0102'!O26) -> 131.27021 | F14: =VALUE('0102'!O37) -> 78.069443 | G14: =VALUE('0102'!O48) -> 71.322761 | H14: =VALUE('0102'!O58) -> 78.928112 | I14: =VALUE('0102'!O69) -> 93.700216 | J14: ='0102'!O79 -> 85.636364
C15: 達成率 | D15: =D14/D13 -> 0.83064552 | E15: =E14/E13 -> 0.80893355 | F15: =F14/F13 -> 0.9113686 | G15: =G14/G13 -> 0.85509679 | H15: =H14/H13 -> 0.91231497 | I15: =I14/I13 -> 0.73737517 | J15: =J14/J13 -> 0.76121212
B16: 作業 時間 | C16: 開始 | D16: ='0102'!T5 -> 0.29027778 | E16: ='0102'!T16 -> 0.29027778 | F16: ='0102'!T27 -> 0.29027778 | G16: ='0102'!T38 -> 0.33333333 | H16: ='0102'!T49 -> 0.29097222 | I16: ='0102'!T59 -> 0.29166667 | J16: ='0102'!T70 -> 0.34027778
C17: 結束 | D17: 0.58472222 | E17: 0.61111111 | F17: 0.57291667 | G17: 0.58333333 | H17: 0.64583333 | I17: 0.48263889 | J17: 0.44722222
B18: 產線異常 (5分鐘以上) | C18: 次數 | D18: ='0102'!Z15 -> 0 | E18: ='0102'!Z26 -> 2 | F18: ='0102'!Z37 -> 1 | G18: ='0102'!Z48 -> 1 | H18: ='0102'!Z58 -> 0 | I18: ='0102'!Z69 -> 0 | J18: ='0102'!Z79 -> 0
C19: 時間/分 | D19: ='0102'!AA15 -> 0 | E19: ='0102'!AA26 -> 34 | F19: ='0102'!AA37 -> 8 | G19: ='0102'!AA48 -> 6 | H19: ='0102'!AA58 -> 0 | I19: ='0102'!AA69 -> 0 | J19: ='0102'!AA79 -> 0
B20: 短暫停線 (5分鐘以下) | C20: 次數 | D20: ='0102'!AD15 -> 1 | E20: ='0102'!AD26 -> 2 | F20: ='0102'!AD37 -> 0 | G20: ='0102'!AD48 -> 0 | H20: ='0102'!AD58 -> 0 | I20: ='0102'!AD69 -> 0 | J20: ='0102'!AD79 -> 0
C21: 設備次數 | D21: ='0102'!AE15 -> 1 | E21: ='0102'!AD15 -> 1 | F21: ='0102'!AE37 -> 0 | G21: ='0102'!AE48 -> 0 | H21: ='0102'!AE58 -> 0 | I21: ='0102'!AE69 -> 0 | J21: ='0102'!AE79 -> 0
B22: 配置人數 | D22: =VALUE('0102'!M15) -> 14.75 | E22: =VALUE('0102'!M26) -> 12.75 | F22: =VALUE('0102'!M37) -> 14.5 | G22: =VALUE('0102'!M48) -> 14.666667 | H22: =VALUE('0102'!M58) -> 16.2 | I22: =VALUE('0102'!M69) -> 11.666667 | J22: ='0102'!M79 -> 10
B23: 主要應用設備 | D23: ET-600 | E23: ET-600 | F23: ET-55 | G23: ET-55 | H23: ET-55 | I23: 八爪機
B24: 次要應用設備 | H24: 封口機
B25: 備註

Sheet 0102
A1: 長家廠4度C日報分析 | D1: 總生產量 | E1: =SUM(G5:G79) -> 40942 | F1: 營業額 | G1: =SUM(H5:H79) -> 1980092.8 | H1: 出勤人數 | I1: =M15+M26+M48+M58+M69+M79+M37 -> 94.533333 | J1: 產線配置圖 | M1: 生產實績 | P1: 人時性差異分析 | T1: 日報登錄 | Z1: 合計 次數 | AA1: 合計 時間/分 | AB1: 分析說明 | AD1: 合計 次數 | AE1: 合計 設備次數 | AF1: 產能差異分析
A2: 01月02日 星期五 | D2: 人時性 | E2: =AVERAGE(O15,O26,O37,O48,O58,O69,O79) -> 92.00702 | F2: 平均廠價 | G2: =G1/E1 -> 48.363363 | H2: 多次生產數 | I2: =COUNT(I5:I79) -> 0 | Z2: =Z15+Z26+Z37+Z48+Z58+Z69+Z79 -> 4 | AA2: =AA15+AA26+AA37+AA48+AA58+AA69+AA79 -> 48 | AD2: =AD15+AD26+AD37+AD48+AD58+AD69+AD79 -> 3 | AE2: =AE15+AE26+AE37+AE48+AE58+AE69+AE79 -> 2
A3: 線別 | B3: 品類 | D3: 品名 | F3: 廠價 | G3: 生產量 | H3: 營收 | I3: 多次 生產 | J3: 人數 | K3: 產能/時 | L3: 人時性 | M3: 人數 | N3: 產能/時 | O3: 人時性 | P3: 人數 | Q3: 人時性 | R3: 達成率 | S3: 達成率平均 | T3: 生產時間 | V3: 前置、換線時間/分 | W3: 稼動時間/分 | X3: 休息時間 | Z3: 產線異常統計 (5分鐘以上) | AD3: 短暫停線統計 (5分鐘以下) | AF3: 產能/時 | AG3: 達成率 | AH3: 達成率平均
T4: 開始 | U4: 結束 | X4: 開始 | Y4: 結束 | Z4: 次數 | AA4: 時間/分 | AD4: 總次數 | AE4: 設備因素(次數)
A5: 自動一線 (ET-600) | B5: 義大利麵 | D5: 奶油起司蝦仁通心粉 | F5: =VLOOKUP(D5,廠價表!$C$1:$E$41,3,0) -> 47.71 | G5: 2393 | H5: =F5*G5 -> 114170.03 | J5: =VLOOKUP(D5,產線配置圖!$A$3:$C$39,2,0) -> 14 | K5: =VLOOKUP(D5,產線配置圖!$A$3:$C$39,3,0) -> 1440 | L5: =K5/J5 -> 102.85714 | M5: 14 | N5: =G5/W5*60 -> 1227.1795 | O5: =N5/M5 -> 87.655678 | P5: =M5-J5 -> 0 | Q5: =O5-L5 -> -15.201465 | R5: =O5/L5 -> 0.85220798 | S5: =R15 -> 0.83064552 | T5: 0.29027778 | U5: 0.37152778 | W5: =(U5-T5)*24*60 -> 117 | AF5: =N5-K5 -> -212.82051 | AG5: =N5/K5 -> 0.85220798 | AH5: =AG15 -> 0.82257885
B6: 義大利麵 | D6: 韓式起司炸雞義大利麵 | F6: =VLOOKUP(D6,廠價表!$C$1:$E$41,3,0) -> 57.21 | G6: 1101 | H6: =F6*G6 -> 62988.21 | J6: =VLOOKUP(D6,產線配置圖!$A$3:$C$39,2,0) -> 17 | K6: =VLOOKUP(D6,產線配置圖!$A$3:$C$39,3,0) -> 2000 | L6: =K6/J6 -> 117.64706 | M6: 17 | N6: =G6/W6*60 -> 1321.2 | O6: =N6/M6 -> 77.717647 | P6: =M6-J6 -> 0 | Q6: =O6-L6 -> -39.929412 | R6: =O6/L6 -> 0.6606 | T6: 0.38055556 | U6: 0.41527778 | V6: =(T6-U5)*24*60 -> 13 | W6: =(U6-T6)*24*60 -> 50 | AF6: =N6-K6 -> -678.8 | AG6: =N6/K6 -> 0.6606
B7: 義大利麵 | D7: 奶油培根義大利麵 | F7: =VLOOKUP(D7,廠價表!$C$1:$E$41,3,0) -> 49.14 | G7: 2288 | H7: =F7*G7 -> 112432.32 | J7: =VLOOKUP(D7,產線配置圖!$A$3:$C$39,2,0) -> 14 | K7: =VLOOKUP(D7,產線配置圖!$A$3:$C$39,3,0) -> 2000 | L7: =K7/J7 -> 142.85714 | M7: 14 | N7: =G7/W7*60 -> 1782.8571 | O7: =N7/M7 -> 127.34694 | P7: =M7-J7 -> 0 | Q7: =O7-L7 -> -15.510204 | R7: =O7/L7 -> 0.89142857 | T7: 0.42222222 | U7: 0.47569444 | V7: =(T7-U6)*24*60 -> 10 | W7: =(U7-T7)*24*60 -> 77 | AF7: =N7-K7 -> -217.14286 | AG7: =N7/K7 -> 0.89142857
B8: 義大利麵 | D8: 奶油培根義大利麵 | F8: =VLOOKUP(D8,廠價表!$C$1:$E$41,3,0) -> 49.14 | G8: 1908 | H8: =F8*G8 -> 93759.12 | J8: =VLOOKUP(D8,產線配置圖!$A$3:$C$39,2,0) -> 14 | K8: =VLOOKUP(D8,產線配置圖!$A$3:$C$39,3,0) -> 2000 | L8: =K8/J8 -> 142.85714 | M8: 14 | N8: =G8/W8*60 -> 1788.75 | O8: =N8/M8 -> 127.76786 | P8: =M8-J8 -> 0 | Q8: =O8-L8 -> -15.089286 | R8: =O8/L8 -> 0.894375 | T8: 0.54027778 | U8: 0.58472222 | W8: =(U8-T8)*24*60 -> 64 | X8: 0.48611111 | Y8: 0.52777778 | AB8: 注醬機異常 | AD8: 1 | AE8: 1 | AF8: =N8-K8 -> -211.25 | AG8: =N8/K8 -> 0.894375
W9: =(U9-T9)*24*60 -> 0 | AF9: =N9-K9 -> 0 | AG9: =N9/K9 -> #DIV/0!
W10: =(U10-T10)*24*60 -> 0 | AF10: =N10-K10 -> 0 | AG10: =N10/K10 -> #DIV/0!
W11: =(U11-T11)*24*60 -> 0 | AF11: =N11-K11 -> 0 | AG11: =N11/K11 -> #DIV/0!
W12: =(U12-T12)*24*60 -> 0
W13: =(U13-T13)*24*60 -> 0
W14: =(U14-T14)*24*60 -> 0
C15: 4度一組 | D15: 平均 | J15: =AVERAGE(J5:J14) -> 14.75 | K15: =AVERAGE(K5:K14) -> 1860 | L15: =AVERAGE(L5:L14) -> 126.55462 | M15: =AVERAGE(M5:M14) -> 14.75 | N15: =AVERAGE(N5:N14) -> 1529.9967 | O15: =AVERAGE(O5:O14) -> 105.12203 | P15: =M15-J15 -> 0 | Q15: =O15-L15 -> -21.432592 | R15: =O15/L15 -> 0.83064552 | Z15: =SUM(Z5:Z14) -> 0 | AA15: =SUM(AA5:AA14) -> 0 | AD15: =SUM(AD5:AD14) -> 1 | AE15: =SUM(AE5:AE14) -> 1 | AF15: =N15-K15 -> -330.00334 | AG15: =N15/K15 -> 0.82257885
A16: 自動二線 (ET-600) | B16: 義大利麵 | D16: 白酒蛤蜊義大利麵 | F16: =VLOOKUP(D16,廠價表!$C$1:$E$41,3,0) -> 57.21 | G16: 1841 | H16: =F16*G16 -> 105323.61 | J16: =VLOOKUP(D16,產線配置圖!$A$3:$C$39,2,0) -> 13 | K16: =VLOOKUP(D16,產線配置圖!$A$3:$C$39,3,0) -> 2105 | L16: =K16/J16 -> 161.92308 | M16: 14 | N16: =G16/W16*60 -> 2008.3636 | O16: =N16/M16 -> 143.45455 | P16: =M16-J16 -> 1 | Q16: =O16-L16 -> -18.468531 | R16: =O16/L16 -> 0.88594256 | S16: =R26 -> 0.80893355 | T16: 0.29027778 | U16: 0.32847222 | W16: =(U16-T16)*24*60 -> 55 | AB16: 封膜頻繁異常，多一人進行作業 | AF16: =N16-K16 -> -96.636364 | AG16: =N16/K16 -> 0.95409199 | AH16: =AG26 -> 0.82691391
B17: 義大利麵 | D17: 青醬蛤蜊義大利麵 | F17: =VLOOKUP(D17,廠價表!$C$1:$E$41,3,0) -> 50.67 | G17: 3144 | H17: =F17*G17 -> 159306.48 | J17: =VLOOKUP(D17,產線配置圖!$A$3:$C$39,2,0) -> 13 | K17: =VLOOKUP(D17,產線配置圖!$A$3:$C$39,3,0) -> 2000 | L17: =K17/J17 -> 153.84615 | M17: 13 | N17: =G17/W17*60 -> 1485.3543 | O17: =N17/M17 -> 114.25803 | P17: =M17-J17 -> 0 | Q17: =O17-L17 -> -39.588128 | R17: =O17/L17 -> 0.74267717 | T17: 0.33680556 | U17: 0.425 | V17: =(T17-U16)*24*60 -> 12 | W17: =(U17-T17)*24*60 -> 127 | Z17: 1 | AA17: 28 | AB17: 封膜異常 | AF17: =N17-K17 -> -514.64567 | AG17: =N17/K17 -> 0.74267717
B18: 義大利麵 | D18: 義式蕃茄起司義大利麵 | F18: =VLOOKUP(D18,廠價表!$C$1:$E$41,3,0) -> 50.39 | G18: 802 | H18: =F18*G18 -> 40412.78 | J18: =VLOOKUP(D18,產線配置圖!$A$3:$C$39,2,0) -> 12 | K18: =VLOOKUP(D18,產線配置圖!$A$3:$C$39,3,0) -> 2000 | L18: =K18/J18 -> 166.66667 | M18: 12 | N18: =G18/W18*60 -> 1336.6667 | O18: =N18/M18 -> 111.38889 | P18: =M18-J18 -> 0 | Q18: =O18-L18 -> -55.277778 | R18: =O18/L18 -> 0.66833333 | T18: 0.43333333 | U18: 0.45833333 | V18: =(T18-U17)*24*60 -> 12 | W18: =(U18-T18)*24*60 -> 36 | X18: 0.48611111 | Y18: 0.52777778 | Z18: 1 | AA18: 6 | AB18: 封膜異常 | AF18: =N18-K18 -> -663.33333 | AG18: =N18/K18 -> 0.66833333
B19: 義大利麵 | D19: 義式蕃茄起司義大利麵 | F19: =VLOOKUP(D19,廠價表!$C$1:$E$41,3,0) -> 50.39 | G19: 3026 | H19: =F19*G19 -> 152480.14 | J19: =VLOOKUP(D19,產線配置圖!$A$3:$C$39,2,0) -> 12 | K19: =VLOOKUP(D19,產線配置圖!$A$3:$C$39,3,0) -> 2000 | L19: =K19/J19 -> 166.66667 | M19: 12 | N19: =G19/W19*60 -> 1871.7526 | O19: =N19/M19 -> 155.97938 | P19: =M19-J19 -> 0 | Q19: =O19-L19 -> -10.687285 | R19: =O19/L19 -> 0.93587629 | T19: 0.54375 | U19: 0.61111111 | V19: =(T19-U18)*24*60 -> 123 | W19: =(U19-T19)*24*60 -> 97 | AB19: 玉取機停麵 | AD19: 2 | AE19: 1 | AF19: =N19-K19 -> -128.24742 | AG19: =N19/K19 -> 0.93587629
W20: =(U20-T20)*24*60 -> 0
W21: =(U21-T21)*24*60 -> 0
W22: 0
W23: =(U23-T23)*24*60 -> 0
H24: =F24*G24 -> 0 | W24: =(U24-T24)*24*60 -> 0
H25: =F25*G25 -> 0 | W25: =(U25-T25)*24*60 -> 0
C26: 4度二組A | D26: 平均 | J26: =AVERAGE(J16:J25) -> 12.5 | K26: =AVERAGE(K16:K25) -> 2026.25 | L26: =AVERAGE(L16:L25) -> 162.27564 | M26: =AVERAGE(M16:M25) -> 12.75 | N26: =AVERAGE(N16:N25) -> 1675.5343 | O26: =AVERAGE(O16:O25) -> 131.27021 | P26: =M26-J26 -> 0.25 | Q26: =O26-L26 -> -31.005431 | R26: =O26/L26 -> 0.80893355 | Z26: =SUM(Z16:Z25) -> 2 | AA26: =SUM(AA16:AA25) -> 34 | AD26: =SUM(AD16:AD25) -> 2 | AE26: =SUM(AE16:AE25) -> 1 | AF26: =N26-K26 -> -350.7157 | AG26: =N26/K26 -> 0.82691391
A27: 手工三線 (ET-55) | B27: 義大利麵 | D27: 惡魔乳酪生義大利麵 | F27: =VLOOKUP(D27,廠價表!$C$1:$E$41,3,0) -> 57.3 | G27: 1164 | H27: =F27*G27 -> 66697.2 | J27: =VLOOKUP(D27,產線配置圖!$A$3:$C$39,2,0) -> 17 | K27: =VLOOKUP(D27,產線配置圖!$A$3:$C$39,3,0) -> 1500 | L27: =K27/J27 -> 88.235294 | M27: 14 | N27: =G27/W27*60 -> 1225.2632 | O27: =N27/M27 -> 87.518797 | P27: =M27-J27 -> -3 | Q27: =O27-L27 -> -0.71649713 | R27: =O27/L27 -> 0.9918797 | S27: =R37 -> 0.9113686 | T27: 0.29027778 | U27: 0.32986111 | W27: =(U27-T27)*24*60 -> 57 | AF27: =N27-K27 -> -274.73684 | AG27: =N27/K27 -> 0.81684211 | AH27: =AG37 -> 0.77559618
B28: 義大利麵 | D28: 奶油蒜香雞義大利麵 | F28: =VLOOKUP(D28,廠價表!$C$1:$E$41,3,0) -> 55.13 | G28: 1054 | H28: =F28*G28 -> 58107.02 | J28: =VLOOKUP(D28,產線配置圖!$A$3:$C$39,2,0) -> 17 | K28: =VLOOKUP(D28,產線配置圖!$A$3:$C$39,3,0) -> 1385 | L28: =K28/J28 -> 81.470588 | M28: 15 | N28: =G28/W28*60 -> 1054 | O28: =N28/M28 -> 70.266667 | P28: =M28-J28 -> -2 | Q28: =O28-L28 -> -11.203922 | R28: =O28/L28 -> 0.86247894 | T28: 0.33680556 | U28: 0.37847222 | V28: =(T28-U27)*24*60 -> 10 | W28: =(U28-T28)*24*60 -> 60 | AF28: =N28-K28 -> -331 | AG28: =N28/K28 -> 0.76101083
B29: 熱乾麵 | D29: 沙茶豬肉炒麵 | F29: =VLOOKUP(D29,廠價表!$C$1:$E$41,3,0) -> 49.52 | G29: 1722 | H29: =F29*G29 -> 85273.44 | J29: =VLOOKUP(D29,產線配置圖!$A$3:$C$39,2,0) -> 17 | K29: =VLOOKUP(D29,產線配置圖!$A$3:$C$39,3,0) -> 1440 | L29: =K29/J29 -> 84.705882 | M29: 15 | N29: =G29/W29*60 -> 1135.3846 | O29: =N29/M29 -> 75.692308 | P29: =M29-J29 -> -2 | Q29: =O29-L29 -> -9.0135747 | R29: =O29/L29 -> 0.89358974 | T29: 0.38611111 | U29: 0.44930556 | V29: =(T29-U28)*24*60 -> 11 | W29: =(U29-T29)*24*60 -> 91 | Z29: 1 | AA29: 8 | AB29: 封膜機異常 | AF29: =N29-K29 -> -304.61538 | AG29: =N29/K29 -> 0.78846154
B30: 義大利麵 | D30: 惡魔乳酪生義大利麵 | F30: =VLOOKUP(D30,廠價表!$C$1:$E$41,3,0) -> 57.3 | G30: 1379 | H30: =F30*G30 -> 79016.7 | J30: =VLOOKUP(D30,產線配置圖!$A$3:$C$39,2,0) -> 17 | K30: =VLOOKUP(D30,產線配置圖!$A$3:$C$39,3,0) -> 1500 | L30: =K30/J30 -> 88.235294 | M30: 14 | N30: =G30/W30*60 -> 1103.2 | O30: =N30/M30 -> 78.8 | P30: =M30-J30 -> -3 | Q30: =O30-L30 -> -9.4352941 | R30: =O30/L30 -> 0.89306667 | T30: 0.52083333 | U30: 0.57291667 | V30: =(T30-U29)*24*60 -> 103 | W30: =(U30-T30)*24*60 -> 75 | X30: 0.49652778 | Y30: 0.53819444 | AF30: =N30-K30 -> -396.8 | AG30: =N30/K30 -> 0.73546667
W31: =(U31-T31)*24*60 -> 0 | AF31: =N31-K31 -> 0 | AG31: =N31/K31 -> #DIV/0!
W32: =(U32-T32)*24*60 -> 0
W33: =(U33-T33)*24*60 -> 0
W34: =(U34-T34)*24*60 -> 0
W35: =(U35-T35)*24*60 -> 0
H36: =F36*G36 -> 0 | W36: =(U36-T36)*24*60 -> 0
C37: 4度二組B | D37: 平均 | J37: =AVERAGE(J27:J36) -> 17 | K37: =AVERAGE(K27:K36) -> 1456.25 | L37: =AVERAGE(L27:L36) -> 85.661765 | M37: =AVERAGE(M27:M36) -> 14.5 | N37: =AVERAGE(N27:N36) -> 1129.4619 | O37: =AVERAGE(O27:O36) -> 78.069443 | P37: =M37-J37 -> -2.5 | Q37: =N37-K37 -> -326.78806 | R37: =O37/L37 -> 0.9113686 | Z37: =SUM(Z27:Z36) -> 1 | AA37: =SUM(AA27:AA36) -> 8 | AD37: =SUM(AD27:AD36) -> 0 | AE37: =SUM(AE27:AE36) -> 0 | AF37: =N37-K37 -> -326.78806 | AG37: =N37/K37 -> 0.77559618
A38: 手工四線 (ET-55) | B38: 義大利麵 | D38: 焗烤明太子筆尖麵 | F38: =VLOOKUP(D38,廠價表!$C$1:$E$41,3,0) -> 57.3 | G38: 1215 | H38: =F38*G38 -> 69619.5 | J38: =VLOOKUP(D38,產線配置圖!$A$3:$C$39,2,0) -> 16 | K38: =VLOOKUP(D38,產線配置圖!$A$3:$C$39,3,0) -> 1385 | L38: =K38/J38 -> 86.5625 | M38: 15 | N38: =G38/W38*60 -> 1121.5385 | O38: =N38/M38 -> 74.769231 | P38: =M38-J38 -> -1 | Q38: =O38-L38 -> -11.793269 | R38: =O38/L38 -> 0.86376007 | S38: =R48 -> 0.85509679 | T38: 0.33333333 | U38: 0.37847222 | W38: =(U38-T38)*24*60 -> 65 | AF38: =N38-K38 -> -263.46154 | AG38: =N38/K38 -> 0.80977506 | AH38: =AG48 -> 0.74239677
B39: 義大利麵 | D39: 濃拿坡里義大利麵 | F39: =VLOOKUP(D39,廠價表!$C$1:$E$41,3,0) -> 56.43 | G39: 1070 | H39: =F39*G39 -> 60380.1 | J39: =VLOOKUP(D39,產線配置圖!$A$3:$C$39,2,0) -> 16 | K39: =VLOOKUP(D39,產線配置圖!$A$3:$C$39,3,0) -> 1406 | L39: =K39/J39 -> 87.875 | M39: 14 | N39: =G39/W39*60 -> 958.20896 | O39: =N39/M39 -> 68.443497 | P39: =M39-J39 -> -2 | Q39: =O39-L39 -> -19.431503 | R39: =O39/L39 -> 0.77887336 | T39: 0.38541667 | U39: 0.43194444 | V39: =(T39-U38)*24*60 -> 10 | W39: =(U39-T39)*24*60 -> 67 | Z39: 1 | AA39: 6 | AB39: 封膜機異常 | AF39: =N39-K39 -> -447.79104 | AG39: =N39/K39 -> 0.68151419
B40: 熱乾麵 | D40: 府城鹽水意麵 | F40: =VLOOKUP(D40,廠價表!$C$1:$E$41,3,0) -> 44.3 | G40: 796 | H40: =F40*G40 -> 35262.8 | J40: =VLOOKUP(D40,產線配置圖!$A$3:$C$39,2,0) -> 19 | K40: =VLOOKUP(D40,產線配置圖!$A$3:$C$39,3,0) -> 1440 | L40: =K40/J40 -> 75.789474 | M40: 15 | N40: =G40/W40*60 -> 1061.3333 | O40: =N40/M40 -> 70.755556 | P40: =M40-J40 -> -4 | Q40: =O40-L40 -> -5.0339181 | R40: =O40/L40 -> 0.93358025 | T40: 0.55208333 | U40: 0.58333333 | V40: =(T40-U39)*24*60 -> 173 | W40: =(U40-T40)*24*60 -> 45 | AF40: =N40-K40 -> -378.66667 | AG40: =N40/K40 -> 0.73703704
...

Sheet 0103總
B1: 長家廠組合室生產人時性分析
B3: 日期 | D3: 46025 | F3: 訂單量 | G3: ='0103'!E1 -> 46190 | I3: 營業額 | J3: ='0103'!G1 -> 2232274.1
B4: 項目 | D4: 3 | F4: ➀ | H4: ➁ | J4: ③ | L4: 異常停線 | N4: 短暫停線
B5: 人時性 | D5: 組合室 | F5: 全溫層 | H5: 義大利麵 | J5: 袋裝小吃、義麵 | L5: 合計次數 | M5: 時間 | N5: 合計次數 | O5: 設備次數
D6: 排關平均 | F6: =AVERAGE(D13:J13) -> 111.74129 | H6: =AVERAGE(D13:H13,J13) -> 109.63193 | J6: =AVERAGE(I13) -> 124.39744 | L6: ='0103'!Z2 -> 2 | M6: ='0103'!AA2 -> 37 | N6: ='0103'!AD2 -> 4 | O6: ='0103'!AE2 -> 4
D7: 實績平均 | F7: =AVERAGE(D14:J14) -> 94.132744 | H7: =AVERAGE(D14:H14,J14) -> 93.211961 | J7: =AVERAGE(I14) -> 99.657443
D8: 達成率平均 | F8: =F7/F6 -> 0.84241685 | H8: =H7/H6 -> 0.85022639 | J8: =J7/J6 -> 0.80112136
J9: ※現行日本鮮食廠以達成率80%為基本(即為現行KPI)
B10: 溫層 | D10: 4度C-各編組展開
B11: 編組 | D11: 1 | E11: 2 | F11: 3 | G11: 4 | H11: 5 | I11: 6 | J11: 7
D12: 自動1線 | E12: 自動2線 | F12: 手工3線 | G12: 手工4線 | H12: 手工5線 | I12: 調理包1線 | J12: 調理包2線
B13: 人時性 | C13: 排關 | D13: =VALUE('0103'!L15) -> 126.55462 | E13: =VALUE('0103'!L26) -> 162.27564 | F13: =VALUE('0103'!L37) -> 83.857069 | G13: =VALUE('0103'!L48) -> 83.408991 | H13: =VALUE('0103'!L58) -> 89.195261 | I13: =VALUE('0103'!L69) -> 124.39744 | J13: ='0103'!L79 -> 112.5
C14: 實績 | D14: =VALUE('0103'!O15) -> 114.13839 | E14: =VALUE('0103'!O26) -> 155.21739 | F14: =VALUE('0103'!O37) -> 73.480039 | G14: =VALUE('0103'!O48) -> 74.634797 | H14: =VALUE('0103'!O58) -> 78.457205 | I14: =VALUE('0103'!O69) -> 99.657443 | J14: ='0103'!O79 -> 63.343949
C15: 達成率 | D15: =D14/D13 -> 0.90189029 | E15: =E14/E13 -> 0.95650456 | F15: =F14/F13 -> 0.87625337 | G15: =G14/G13 -> 0.89480517 | H15: =H14/H13 -> 0.87961181 | I15: =I14/I13 -> 0.80112136 | J15: =J14/J13 -> 0.56305732
B16: 作業 時間 | C16: 開始 | D16: ='0103'!T5 -> 0.30277778 | E16: ='0103'!T16 -> 0.30208333 | F16: ='0103'!T27 -> 0.29166667 | G16: ='0103'!T38 -> 0.33194444 | H16: ='0103'!T49 -> 0.29583333 | I16: ='0103'!T59 -> 0.29166667 | J16: ='0103'!T70 -> 0.33541667
C17: 結束 | D17: 0.60069444 | E17: 0.57986111 | F17: 0.65555556 | G17: 0.61111111 | H17: 0.63333333 | I17: 0.57638889 | J17: 0.44444444
B18: 產線異常 (5分鐘以上) | C18: 次數 | D18: ='0103'!Z15 -> 0 | E18: ='0103'!Z26 -> 0 | F18: ='0103'!Z37 -> 0 | G18: ='0103'!Z48 -> 0 | H18: ='0103'!Z58 -> 1 | I18: ='0103'!Z69 -> 0 | J18: ='0103'!Z79 -> 1
C19: 時間/分 | D19: ='0103'!AA15 -> 0 | E19: ='0103'!AA26 -> 0 | F19: ='0103'!AA37 -> 0 | G19: ='0103'!AA48 -> 0 | H19: ='0103'!AA58 -> 7 | I19: ='0103'!AA69 -> 0 | J19: ='0103'!AA79 -> 30
B20: 短暫停線 (5分鐘以下) | C20: 次數 | D20: ='0103'!AD15 -> 0 | E20: ='0103'!AD26 -> 3 | F20: ='0103'!AD37 -> 0 | G20: ='0103'!AD48 -> 1 | H20: ='0103'!AD58 -> 0 | I20: ='0103'!AD69 -> 0 | J20: ='0103'!AD79 -> 0
C21: 設備次數 | D21: ='0103'!AE15 -> 0 | E21: ='0103'!AE26 -> 3 | F21: ='0103'!AE37 -> 0 | G21: ='0103'!AE48 -> 1 | H21: ='0103'!AE58 -> 0 | I21: ='0103'!AE69 -> 0 | J21: ='0103'!AE79 -> 0
B22: 配置人數 | D22: =VALUE('0103'!M15) -> 14.75 | E22: =VALUE('0103'!M26) -> 12.75 | F22: =VALUE('0103'!M37) -> 14 | G22: =VALUE('0103'!M48) -> 14.333333 | H22: =VALUE('0103'!M58) -> 16.5 | I22: =VALUE('0103'!M69) -> 12.6 | J22: ='0103'!M79 -> 12
B23: 主要應用設備 | D23: ET-600 | E23: ET-600 | F23: ET-55 | G23: ET-55 | H23: ET-55 | I23: 八爪機
B24: 次要應用設備 | H24: 封口機
B25: 備註

Sheet 0103
A1: 長家廠4度C日報分析 | D1: 總生產量 | E1: =SUM(G5:G79) -> 46190 | F1: 營業額 | G1: =SUM(H5:H79) -> 2232274.1 | H1: 出勤人數 | I1: =M15+M26+M48+M58+M69+M79+M37 -> 96.933333 | J1: 產線配置圖 | M1: 生產實績 | P1: 人時性差異分析 | T1: 日報登錄 | Z1: 合計 次數 | AA1: 合計 時間/分 | AB1: 分析說明 | AD1: 合計 次數 | AE1: 合計 設備次數 | AF1: 產能差異分析
A2: 01月03日 星期六 | D2: 人時性 | E2: =AVERAGE(O15,O26,O37,O48,O58,O69,O79) -> 94.132744 | F2: 平均廠價 | G2: =G1/E1 -> 48.328081 | H2: 多次生產數 | I2: =COUNT(I5:I79) -> 0 | Z2: =Z15+Z26+Z37+Z48+Z58+Z69+Z79 -> 2 | AA2: =AA15+AA26+AA37+AA48+AA58+AA69+AA79 -> 37 | AD2: =AD15+AD26+AD37+AD48+AD58+AD69+AD79 -> 4 | AE2: =AE15+AE26+AE37+AE48+AE58+AE69+AE79 -> 4
A3: 線別 | B3: 品類 | D3: 品名 | F3: 廠價 | G3: 生產量 | H3: 營收 | I3: 多次 生產 | J3: 人數 | K3: 產能/時 | L3: 人時性 | M3: 人數 | N3: 產能/時 | O3: 人時性 | P3: 人數 | Q3: 人時性 | R3: 達成率 | S3: 達成率平均 | T3: 生產時間 | V3: 前置、換線時間/分 | W3: 稼動時間/分 | X3: 休息時間 | Z3: 產線異常統計 (5分鐘以上) | AD3: 短暫停線統計 (5分鐘以下) | AF3: 產能/時 | AG3: 達成率 | AH3: 達成率平均
T4: 開始 | U4: 結束 | X4: 開始 | Y4: 結束 | Z4: 次數 | AA4: 時間/分 | AD4: 總次數 | AE4: 設備因素(次數)
A5: 自動一線 (ET-600) | B5: 義大利麵 | D5: 奶油起司蝦仁通心粉 | F5: =VLOOKUP(D5,廠價表!$C$1:$E$41,3,0) -> 47.71 | G5: 2638 | H5: =F5*G5 -> 125858.98 | J5: =VLOOKUP(D5,產線配置圖!$A$3:$C$39,2,0) -> 14 | K5: =VLOOKUP(D5,產線配置圖!$A$3:$C$39,3,0) -> 1440 | L5: =K5/J5 -> 102.85714 | M5: 14 | N5: =G5/W5*60 -> 1352.8205 | O5: =N5/M5 -> 96.630037 | P5: =M5-J5 -> 0 | Q5: =O5-L5 -> -6.2271062 | R5: =O5/L5 -> 0.93945869 | S5: =R15 -> 0.90189029 | T5: 0.30277778 | U5: 0.38402778 | W5: =(U5-T5)*24*60 -> 117 | AF5: =N5-K5 -> -87.179487 | AG5: =N5/K5 -> 0.93945869 | AH5: =AG15 -> 0.89977975
B6: 義大利麵 | D6: 韓式起司炸雞義大利麵 | F6: =VLOOKUP(D6,廠價表!$C$1:$E$41,3,0) -> 57.21 | G6: 1429 | H6: =F6*G6 -> 81753.09 | J6: =VLOOKUP(D6,產線配置圖!$A$3:$C$39,2,0) -> 17 | K6: =VLOOKUP(D6,產線配置圖!$A$3:$C$39,3,0) -> 2000 | L6: =K6/J6 -> 117.64706 | M6: 17 | N6: =G6/W6*60 -> 1714.8 | O6: =N6/M6 -> 100.87059 | P6: =M6-J6 -> 0 | Q6: =O6-L6 -> -16.776471 | R6: =O6/L6 -> 0.8574 | T6: 0.39375 | U6: 0.42847222 | V6: =(T6-U5)*24*60 -> 14 | W6: =(U6-T6)*24*60 -> 50 | AF6: =N6-K6 -> -285.2 | AG6: =N6/K6 -> 0.8574
B7: 義大利麵 | D7: 奶油培根義大利麵 | F7: =VLOOKUP(D7,廠價表!$C$1:$E$41,3,0) -> 49.14 | G7: 1790 | H7: =F7*G7 -> 87960.6 | J7: =VLOOKUP(D7,產線配置圖!$A$3:$C$39,2,0) -> 14 | K7: =VLOOKUP(D7,產線配置圖!$A$3:$C$39,3,0) -> 2000 | L7: =K7/J7 -> 142.85714 | M7: 14 | N7: =G7/W7*60 -> 1732.2581 | O7: =N7/M7 -> 123.73272 | P7: =M7-J7 -> 0 | Q7: =O7-L7 -> -19.124424 | R7: =O7/L7 -> 0.86612903 | T7: 0.43472222 | U7: 0.47777778 | V7: =(T7-U6)*24*60 -> 9 | W7: =(U7-T7)*24*60 -> 62 | AF7: =N7-K7 -> -267.74194 | AG7: =N7/K7 -> 0.86612903
B8: 義大利麵 | D8: 奶油培根義大利麵 | F8: =VLOOKUP(D8,廠價表!$C$1:$E$41,3,0) -> 49.14 | G8: 2747 | H8: =F8*G8 -> 134987.58 | J8: =VLOOKUP(D8,產線配置圖!$A$3:$C$39,2,0) -> 14 | K8: =VLOOKUP(D8,產線配置圖!$A$3:$C$39,3,0) -> 2000 | L8: =K8/J8 -> 142.85714 | M8: 14 | N8: =G8/W8*60 -> 1894.4828 | O8: =N8/M8 -> 135.3202 | P8: =M8-J8 -> 0 | Q8: =O8-L8 -> -7.5369458 | R8: =O8/L8 -> 0.94724138 | T8: 0.54027778 | U8: 0.60069444 | W8: =(U8-T8)*24*60 -> 87 | X8: 0.48611111 | Y8: 0.52777778 | AF8: =N8-K8 -> -105.51724 | AG8: =N8/K8 -> 0.94724138
W9: =(U9-T9)*24*60 -> 0 | AF9: =N9-K9 -> 0 | AG9: =N9/K9 -> #DIV/0!
W10: =(U10-T10)*24*60 -> 0 | AF10: =N10-K10 -> 0 | AG10: =N10/K10 -> #DIV/0!
W11: =(U11-T11)*24*60 -> 0 | AF11: =N11-K11 -> 0 | AG11: =N11/K11 -> #DIV/0!
W12: =(U12-T12)*24*60 -> 0
W13: =(U13-T13)*24*60 -> 0
W14: =(U14-T14)*24*60 -> 0
C15: 4度一組 | D15: 平均 | J15: =AVERAGE(J5:J14) -> 14.75 | K15: =AVERAGE(K5:K14) -> 1860 | L15: =AVERAGE(L5:L14) -> 126.55462 | M15: =AVERAGE(M5:M14) -> 14.75 | N15: =AVERAGE(N5:N14) -> 1673.5903 | O15: =AVERAGE(O5:O14) -> 114.13839 | P15: =M15-J15 -> 0 | Q15: =O15-L15 -> -12.416237 | R15: =O15/L15 -> 0.90189029 | Z15: =SUM(Z5:Z14) -> 0 | AA15: =SUM(AA5:AA14) -> 0 | AD15: =SUM(AD5:AD14) -> 0 | AE15: =SUM(AE5:AE14) -> 0 | AF15: =N15-K15 -> -186.40967 | AG15: =N15/K15 -> 0.89977975
A16: 自動二線 (ET-600) | B16: 義大利麵 | D16: 白酒蛤蜊義大利麵 | F16: =VLOOKUP(D16,廠價表!$C$1:$E$41,3,0) -> 57.21 | G16: 2096 | H16: =F16*G16 -> 119912.16 | J16: =VLOOKUP(D16,產線配置圖!$A$3:$C$39,2,0) -> 13 | K16: =VLOOKUP(D16,產線配置圖!$A$3:$C$39,3,0) -> 2105 | L16: =K16/J16 -> 161.92308 | M16: 14 | N16: =G16/W16*60 -> 2168.2759 | O16: =N16/M16 -> 154.87685 | P16: =M16-J16 -> 1 | Q16: =O16-L16 -> -7.0462296 | R16: =O16/L16 -> 0.95648409 | S16: =R26 -> 0.95650456 | T16: 0.30208333 | U16: 0.34236111 | W16: =(U16-T16)*24*60 -> 58 | AD16: 1 | AE16: 1 | AF16: =N16-K16 -> 63.275862 | AG16: =N16/K16 -> 1.0300598 | AH16: =AG26 -> 0.97628129
B17: 義大利麵 | D17: 青醬蛤蜊義大利麵 | F17: =VLOOKUP(D17,廠價表!$C$1:$E$41,3,0) -> 50.67 | G17: 3471 | H17: =F17*G17 -> 175875.57 | J17: =VLOOKUP(D17,產線配置圖!$A$3:$C$39,2,0) -> 13 | K17: =VLOOKUP(D17,產線配置圖!$A$3:$C$39,3,0) -> 2000 | L17: =K17/J17 -> 153.84615 | M17: 13 | N17: =G17/W17*60 -> 1983.4286 | O17: =N17/M17 -> 152.57143 | P17: =M17-J17 -> 0 | Q17: =O17-L17 -> -1.2747253 | R17: =O17/L17 -> 0.99171429 | T17: 0.34722222 | U17: 0.42013889 | V17: =(T17-U16)*24*60 -> 7 | W17: =(U17-T17)*24*60 -> 105 | AD17: 1 | AE17: 1 | AF17: =N17-K17 -> -16.571429 | AG17: =N17/K17 -> 0.99171429
B18: 義大利麵 | D18: 義式蕃茄起司義大利麵 | F18: =VLOOKUP(D18,廠價表!$C$1:$E$41,3,0) -> 50.39 | G18: 2698 | H18: =F18*G18 -> 135952.22 | J18: =VLOOKUP(D18,產線配置圖!$A$3:$C$39,2,0) -> 12 | K18: =VLOOKUP(D18,產線配置圖!$A$3:$C$39,3,0) -> 2000 | L18: =K18/J18 -> 166.66667 | M18: 12 | N18: =G18/W18*60 -> 1974.1463 | O18: =N18/M18 -> 164.5122 | P18: =M18-J18 -> 0 | Q18: =O18-L18 -> -2.1544715 | R18: =O18/L18 -> 0.98707317 | T18: 0.425 | U18: 0.48194444 | V18: =(T18-U17)*24*60 -> 7 | W18: =(U18-T18)*24*60 -> 82 | X18: 0.48611111 | Y18: 0.52777778 | AF18: =N18-K18 -> -25.853659 | AG18: =N18/K18 -> 0.98707317
B19: 義大利麵 | D19: 義式蕃茄起司義大利麵 | F19: =VLOOKUP(D19,廠價表!$C$1:$E$41,3,0) -> 50.39 | G19: 1638 | H19: =F19*G19 -> 82538.82 | J19: =VLOOKUP(D19,產線配置圖!$A$3:$C$39,2,0) -> 12 | K19: =VLOOKUP(D19,產線配置圖!$A$3:$C$39,3,0) -> 2000 | L19: =K19/J19 -> 166.66667 | M19: 12 | N19: =G19/W19*60 -> 1786.9091 | O19: =N19/M19 -> 148.90909 | P19: =M19-J19 -> 0 | Q19: =O19-L19 -> -17.757576 | R19: =O19/L19 -> 0.89345455 | T19: 0.54166667 | U19: 0.57986111 | V19: =(T19-U18)*24*60 -> 86 | W19: =(U19-T19)*24*60 -> 55 | AD19: 1 | AE19: 1 | AF19: =N19-K19 -> -213.09091 | AG19: =N19/K19 -> 0.89345455
W20: =(U20-T20)*24*60 -> 0
W21: =(U21-T21)*24*60 -> 0
W22: 0
W23: =(U23-T23)*24*60 -> 0
H24: =F24*G24 -> 0 | W24: =(U24-T24)*24*60 -> 0
H25: =F25*G25 -> 0 | W25: =(U25-T25)*24*60 -> 0
C26: 4度二組A | D26: 平均 | J26: =AVERAGE(J16:J25) -> 12.5 | K26: =AVERAGE(K16:K25) -> 2026.25 | L26: =AVERAGE(L16:L25) -> 162.27564 | M26: =AVERAGE(M16:M25) -> 12.75 | N26: =AVERAGE(N16:N25) -> 1978.19 | O26: =AVERAGE(O16:O25) -> 155.21739 | P26: =M26-J26 -> 0.25 | Q26: =O26-L26 -> -7.0582506 | R26: =O26/L26 -> 0.95650456 | Z26: =SUM(Z16:Z25) -> 0 | AA26: =SUM(AA16:AA25) -> 0 | AD26: =SUM(AD16:AD25) -> 3 | AE26: =SUM(AE16:AE25) -> 3 | AF26: =N26-K26 -> -48.060034 | AG26: =N26/K26 -> 0.97628129
A27: 手工三線 (ET-55) | B27: 義大利麵 | D27: 惡魔乳酪生義大利麵 | F27: =VLOOKUP(D27,廠價表!$C$1:$E$41,3,0) -> 57.3 | G27: 1924 | H27: =F27*G27 -> 110245.2 | J27: =VLOOKUP(D27,產線配置圖!$A$3:$C$39,2,0) -> 17 | K27: =VLOOKUP(D27,產線配置圖!$A$3:$C$39,3,0) -> 1500 | L27: =K27/J27 -> 88.235294 | M27: 13 | N27: =G27/W27*60 -> 1099.4286 | O27: =N27/M27 -> 84.571429 | P27: =M27-J27 -> -4 | Q27: =O27-L27 -> -3.6638655 | R27: =O27/L27 -> 0.95847619 | S27: =R37 -> 0.87625337 | T27: 0.29166667 | U27: 0.36458333 | W27: =(U27-T27)*24*60 -> 105 | AF27: =N27-K27 -> -400.57143 | AG27: =N27/K27 -> 0.73295238 | AH27: =AG37 -> 0.70797014
B28: 義大利麵 | D28: 奶油蒜香雞義大利麵 | F28: =VLOOKUP(D28,廠價表!$C$1:$E$41,3,0) -> 55.13 | G28: 1465 | H28: =F28*G28 -> 80765.45 | J28: =VLOOKUP(D28,產線配置圖!$A$3:$C$39,2,0) -> 17 | K28: =VLOOKUP(D28,產線配置圖!$A$3:$C$39,3,0) -> 1385 | L28: =K28/J28 -> 81.470588 | M28: 15 | N28: =G28/W28*60 -> 1126.9231 | O28: =N28/M28 -> 75.128205 | P28: =M28-J28 -> -2 | Q28: =O28-L28 -> -6.3423831 | R28: =O28/L28 -> 0.92215125 | T28: 0.37291667 | U28: 0.42708333 | V28: =(T28-U27)*24*60 -> 12 | W28: =(U28-T28)*24*60 -> 78 | AF28: =N28-K28 -> -258.07692 | AG28: =N28/K28 -> 0.81366287
B29: 熱乾麵 | D29: 沙茶豬肉炒麵 | F29: =VLOOKUP(D29,廠價表!$C$1:$E$41,3,0) -> 49.52 | G29: 899 | H29: =F29*G29 -> 44518.48 | J29: =VLOOKUP(D29,產線配置圖!$A$3:$C$39,2,0) -> 17 | K29: =VLOOKUP(D29,產線配置圖!$A$3:$C$39,3,0) -> 1440 | L29: =K29/J29 -> 84.705882 | M29: 14 | N29: =G29/W29*60 -> 963.21429 | O29: =N29/M29 -> 68.80102 | P29: =M29-J29 -> -3 | Q29: =O29-L29 -> -15.904862 | R29: =O29/L29 -> 0.81223427 | T29: 0.43541667 | U29: 0.47430556 | V29: =(T29-U28)*24*60 -> 12 | W29: =(U29-T29)*24*60 -> 56 | AF29: =N29-K29 -> -476.78571 | AG29: =N29/K29 -> 0.66889881
B30: 熱乾麵 | D30: 沙茶豬肉炒麵 | F30: =VLOOKUP(D30,廠價表!$C$1:$E$41,3,0) -> 49.52 | G30: 1062 | H30: =F30*G30 -> 52590.24 | J30: =VLOOKUP(D30,產線配置圖!$A$3:$C$39,2,0) -> 17 | K30: =VLOOKUP(D30,產線配置圖!$A$3:$C$39,3,0) -> 1440 | L30: =K30/J30 -> 84.705882 | M30: 14 | N30: =G30/W30*60 -> 980.30769 | O30: =N30/M30 -> 70.021978 | P30: =M30-J30 -> -3 | Q30: =O30-L30 -> -14.683904 | R30: =O30/L30 -> 0.82664835 | T30: 0.53472222 | U30: 0.57986111 | V30: =(T30-U29)*24*60 -> 87 | W30: =(U30-T30)*24*60 -> 65 | X30: 0.49652778 | Y30: 0.53819444 | AF30: =N30-K30 -> -459.69231 | AG30: =N30/K30 -> 0.68076923
B31: 義大利麵 | D31: 惡魔乳酪生義大利麵 | F31: =VLOOKUP(D31,廠價表!$C$1:$E$41,3,0) -> 57.3 | G31: 453 | H31: =F31*G31 -> 25956.9 | J31: =VLOOKUP(D31,產線配置圖!$A$3:$C$39,2,0) -> 17 | K31: =VLOOKUP(D31,產線配置圖!$A$3:$C$39,3,0) -> 1500 | L31: =K31/J31 -> 88.235294 | M31: 14 | N31: =G31/W31*60 -> 1087.2 | O31: =N31/M31 -> 77.657143 | P31: =M31-J31 -> -3 | Q31: =O31-L31 -> -10.578151 | R31: =O31/L31 -> 0.88011429 | T31: 0.58680556 | U31: 0.60416667 | V31: =(T31-U30)*24*60 -> 10 | W31: =(U31-T31)*24*60 -> 25 | AF31: =N31-K31 -> -412.8 | AG31: =N31/K31 -> 0.7248
B32: 熱乾麵 | D32: 府城鹽水意麵 | F32: =VLOOKUP(D32,廠價表!$C$1:$E$41,3,0) -> 44.3 | G32: 936 | H32: =F32*G32 -> 41464.8 | J32: =VLOOKUP(D32,產線配置圖!$A$3:$C$39,2,0) -> 19 | K32: =VLOOKUP(D32,產線配置圖!$A$3:$C$39,3,0) -> 1440 | L32: =K32/J32 -> 75.789474 | M32: 14 | N32: =G32/W32*60 -> 905.80645 | O32: =N32/M32 -> 64.700461 | P32: =M32-J32 -> -5 | Q32: =O32-L32 -> -11.089013 | R32: =O32/L32 -> 0.85368664 | T32: 0.6125 | U32: 0.65555556 | V32: =(T32-U31)*24*60 -> 12 | W32: =(U32-T32)*24*60 -> 62
W33: =(U33-T33)*24*60 -> 0
W34: =(U34-T34)*24*60 -> 0
W35: =(U35-T35)*24*60 -> 0
H36: =F36*G36 -> 0 | W36: =(U36-T36)*24*60 -> 0
C37: 4度二組B | D37: 平均 | J37: =AVERAGE(J27:J36) -> 17.333333 | K37: =AVERAGE(K27:K36) -> 1450.8333 | L37: =AVERAGE(L27:L36) -> 83.857069 | M37: =AVERAGE(M27:M36) -> 14 | N37: =AVERAGE(N27:N36) -> 1027.1467 | O37: =AVERAGE(O27:O36) -> 73.480039 | P37: =M37-J37 -> -3.3333333 | Q37: =N37-K37 -> -423.68665 | R37: =O37/L37 -> 0.87625337 | Z37: =SUM(Z27:Z36) -> 0 | AA37: =SUM(AA27:AA36) -> 0 | AD37: =SUM(AD27:AD36) -> 0 | AE37: =SUM(AE27:AE36) -> 0 | AF37: =N37-K37 -> -423.68665 | AG37: =N37/K37 -> 0.70797014
A38: 手工四線 (ET-55) | B38: 義大利麵 | D38: 焗烤明太子筆尖麵 | F38: =VLOOKUP(D38,廠價表!$C$1:$E$41,3,0) -> 57.3 | G38: 1572 | H38: =F38*G38 -> 90075.6 | J38: =VLOOKUP(D38,產線配置圖!$A$3:$C$39,2,0) -> 16 | K38: =VLOOKUP(D38,產線配置圖!$A$3:$C$39,3,0) -> 1385 | L38: =K38/J38 -> 86.5625 | M38: 14 | N38: =G38/W38*60 -> 1084.1379 | O38: =N38/M38 -> 77.438424 | P38: =M38-J38 -> -2 | Q38: =O38-L38 -> -9.1240764 | R38: =O38/L38 -> 0.89459551 | S38: =R48 -> 0.89480517 | T38: 0.33194444 | U38: 0.39236111 | W38: =(U38-T38)*24*60 -> 87 | AF38: =N38-K38 -> -300.86207 | AG38: =N38/K38 -> 0.78277107 | AH38: =AG48 -> 0.75802682
