Workbook

Sheet 廠價表
A1: check | B1: 溫層 | C1: 品名 | D1: 類別 | E1: 廠價
B2: 4度C | C2: 白酒蛤蜊義大利麵 | D2: 義大利麵 | E2: 57.21
B3: 4度C | C3: 南洋紅咖哩豬義大利麵 | D3: 義大利麵 | E3: 56.43
B4: 4度C | C4: 義式蕃茄起司義大利麵 | D4: 義大利麵 | E4: 50.39
B5: 4度C | C5: 焗烤起司雙饗筆尖麵 | D5: 義大利麵 | E5: 49.97
B6: 4度C | C6: 奶油培根義大利麵 | D6: 義大利麵 | E6: 49.14
B7: 4度C | C7: 韓式起司炸雞義大利麵 | D7: 義大利麵 | E7: 57.21
B8: 4度C | C8: 惡魔乳酪生義大利麵 | D8: 義大利麵 | E8: 57.3
B9: 4度C | C9: 焗烤起司肉醬筆尖麵 | D9: 義大利麵 | E9: 50.67
B10: 4度C | C10: 辣味香菜雞肉義大利麵 | D10: 義大利麵 | E10: 56.28
B11: 4度C | D11: 義大利麵
B12: 4度C | C12: 剝皮辣椒雞奶油扁麵 | D12: 義大利麵 | E12: 56.87
B13: 4度C | C13: 奶油蒜香雞義大利麵 | D13: 義大利麵 | E13: 55.13
B14: 4度C | C14: 青醬蛤蜊義大利麵 | D14: 義大利麵 | E14: 50.67
B15: 4度C | C15: 焗烤明太子筆尖麵 | D15: 義大利麵 | E15: 57.3
B16: 4度C | C16: 濃拿坡里義大利麵 | D16: 義大利麵 | E16: 56.43
B17: 4度C | C17: 奶油起司蝦仁通心粉 | D17: 義大利麵 | E17: 47.71
B18: 4度C | C18: 青花椒麻雞肉拌麵 | D18: 熱乾麵 | E18: 49.91
B19: 4度C | C19: 府城鹽水意麵 | D19: 熱乾麵 | E19: 44.3
B20: 4度C | C20: 沙茶豬肉炒麵 | D20: 熱乾麵 | E20: 49.52
B21: 4度C | C21: 三杯菇菇米血 | D21: 小吃、微波 | E21: 28.26
B22: 4度C | C22: 小滷青蔬 | D22: 小吃、微波 | E22: 26.99
B23: 4度C | C23: 起司馬鈴薯 | D23: 小吃、微波 | E23: 28.26
... B49: 冷凍 | C49: 辣蕃茄義大利麵 | D49: 冷凍調理麵 | E49: 29.38
B50: 冷凍 | D50: 冷凍調理麵
B51: 冷凍 | C51: 韓式起司義大利麵 | D51: 冷凍調理麵 | E51: 29.38
B52: 冷凍 | D52: 冷凍調理麵
B53: 冷凍 | C53: 和風明太子細扁麵 | D53: 冷凍調理麵 | E53: 29.38

Sheet 產線配置圖
A1: 品項 | B1: 人數 | C1: 產能
A2: 義大利麵
A3: 白酒蛤蜊義大利麵 | B3: 12 | C3: 2105 | D3: ET-600
A4: 白酒蛤蜊義大利麵-手 | B4: 15 | C4: 1565 | D4: ET-55
A5: 青醬蛤蜊義大利麵 | B5: 12 | C5: 2000
A6: 義式蕃茄起司義大利麵 | B6: 11 | C6: 2000
A7: 焗烤起司雙饗筆尖麵 | B7: 18 | C7: 1600
A8: 奶油培根義大利麵 | B8: 13 | C8: 2000
A9: 韓式起司炸雞義大利麵 | B9: 17 | C9: 2000
A10: 剝皮辣椒雞奶油扁麵 | B10: 18 | C10: 1565
A11: 青花椒麻雞肉拌麵 | B11: 17 | C11: 1565
A12: 青花椒麻雞肉拌麵-降速生產 | B12: 14 | C12: 1385
A13: 奶油蒜香雞義大利麵 | B13: 17 | C13: 1385 | G13: 日一二正常版
A14: 奶油蒜香雞義大利麵-降速生產 | B14: 17 | C14: 1385
A15: 焗烤明太子筆尖麵 | B15: 16 | C15: 1385
A16: 濃拿坡里義大利麵 | B16: 16 | C16: 1406
A17: 奶油起司蝦仁通心粉 | B17: 16 | C17: 1440
A18: 剝皮辣椒雞奶油扁麵-降速生產(3線) | B18: 16 | C18: 1440
A19: 辣味香菜雞肉義大利麵 | B19: 15 | C19: 1800
A21: 惡魔乳酪生義大利麵 | B21: 17 | C21: 1500
A22: 沙茶豬肉炒麵 | B22: 15 | C22: 1440
A23: 府城鹽水意麵 | B23: 17 | C23: 1440
A24: 焗烤起司肉醬筆尖麵 | B24: 10 | C24: 1125
A25: 調理包
A26: 小滷青蔬 | B26: 13 | C26: 1565
A27: 起司馬鈴薯 | B27: 12 | C27: 1565
A28: 台式綜合甜不辣 | B28: 12 | C28: 1565
A29: 三杯菇菇米血 | B29: 12 | C29: 1565
E33: 更新日期02/01

Sheet 範本總
B1: 長家廠組合室生產人時性分析
B3: 日期 | D3: 46015 | F3: 訂單量 | G3: =範本!E1 -> 43309 | I3: 營業額 | J3: =範本!G1 -> #N/A
B4: 項目 | D4: 3 | F4: ➀ | H4: ➁ | J4: ③ | L4: 異常停線 | N4: 短暫停線
B5: 人時性 | D5: 組合室 | F5: 全溫層 | H5: 義大利麵 | J5: 袋裝小吃、義麵 | L5: 合計次數 | M5: 時間 | N5: 合計次數 | O5: 設備次數
D6: 排關平均 | F6: =AVERAGE(D13:J13) -> #N/A | H6: =AVERAGE(D13:H13) -> #N/A | J6: =AVERAGE(I13:J13) -> #N/A | L6: =範本!Z2 -> 0 | M6: =範本!AA2 -> 0 | N6: =範本!AD2 -> 0 | O6: =範本!AE2 -> 0
D7: 實績平均 | F7: =AVERAGE(D14:J14) -> 116.11475 | H7: =AVERAGE(D14:H14) -> 117.36075 | J7: =AVERAGE(I14:J14) -> 112.99975
D8: 達成率平均 | F8: =AVERAGE(D15:J15) -> #N/A | H8: =AVERAGE(D15:H15) -> #N/A | J8: =AVERAGE(I15:J15) -> #N/A
J9: ※現行日本鮮食廠以達成率80%為基本(即為現行KPI)
B10: 溫層 | D10: 4度C-各編組展開
B11: 編組 | D11: 1 | E11: 2 | F11: 3 | G11: 4 | H11: 5 | I11: 6 | J11: 7
D12: 自動1線 | E12: 自動2線 | F12: 手工3線 | G12: 手工4線 | H12: 手工5線 | I12: 調理包1線 | J12: 調理包2線
B13: 人時性 | C13: 排關 | D13: =VALUE(範本!L15) -> #N/A | E13: =VALUE(範本!L26) -> #N/A | F13: =VALUE(範本!L37) -> #N/A | G13: =VALUE(範本!L48) -> #N/A | H13: =VALUE(範本!L58) -> #N/A | I13: =VALUE(範本!L69) -> #N/A | J13: =範本!L79 -> #N/A
C14: 實績 | D14: =VALUE(範本!O15) -> 113.91637 | E14: =VALUE(範本!O26) -> 132.12003 | F14: =VALUE(範本!O37) -> 126.23842 | G14: =VALUE(範本!O48) -> 112.0543 | H14: =VALUE(範本!O58) -> 102.47462 | I14: =VALUE(範本!O69) -> 155.46443 | J14: =範本!O79 -> 70.535065
C15: 達成率 | D15: =D14/D13 -> #N/A | E15: =E14/E13 -> #N/A | F15: =F14/F13 -> #N/A | G15: =G14/G13 -> #N/A | H15: =H14/H13 -> #N/A | I15: =I14/I13 -> #N/A | J15: =範本!S70 -> #N/A
B16: 作業 時間 | C16: 開始 | D16: =範本!T5 -> 0.29097222 | E16: =範本!T16 -> 0.29097222 | F16: =範本!T27 -> 0.29166667 | G16: =範本!T38 -> 0.33333333 | H16: =範本!T49 -> 0.29166667 | I16: =範本!T59 -> 0.29166667 | J16: =範本!T70 -> 0.34722222
C17: 結束 | D17: 0.47361111 | E17: 0.48263889 | F17: 0.56944444 | G17: 0.60416667 | H17: 0.58333333 | I17: 0.48819444 | J17: 0.46875
B18: 產線異常 (5分鐘以上) | C18: 次數
C19: 時間/分
B20: 短暫停線 (5分鐘以下) | C20: 次數
C21: 設備次數
B22: 配置人數 | D22: =VALUE(範本!M15) -> 15 | E22: =VALUE(範本!M26) -> 12.666667 | F22: =VALUE(範本!M37) -> 14.666667 | G22: =VALUE(範本!M48) -> 14 | H22: =VALUE(範本!M58) -> 17.666667 | I22: =VALUE(範本!M69) -> 12.333333 | J22: =範本!M79 -> 11
B23: 主要應用設備 | D23: ET-600 | E23: ET-600 | F23: ET-55 | G23: ET-55 | H23: ET-55 | I23: 八爪機
B24: 次要應用設備 | H24: 封口機
B25: 備註

Sheet 範本
A1: 長家廠4度C日報分析 | D1: 總生產量 | E1: =SUM(G5:G79) -> 43309 | F1: 營業額 | G1: =SUM(H5:H79) -> #N/A | H1: 出勤人數 | I1: =M15+M26+M48+M58+M69+M79+M37 -> 97.333333 | J1: 產線配置圖 | M1: 生產實績 | P1: 人時性差異分析 | T1: 日報登錄 | Z1: 合計 次數 | AA1: 合計 時間/分 | AB1: 分析說明 | AD1: 合計 次數 | AE1: 合計 設備次數 | AF1: 產能差異分析
A2: 12月24日 星期三 | D2: 人時性 | E2: =AVERAGE(O15,O26,O37,O48,O58,O69,O79) -> 116.11475 | F2: 平均廠價 | G2: =G1/E1 -> #N/A | H2: 多次生產數 | I2: =COUNT(I5:I79) -> 0 | Z2: =Z15+Z26+Z37+Z48+Z58+Z69+Z79 -> 0 | AA2: =AA15+AA26+AA37+AA48+AA58+AA69+AA79 -> 0 | AD2: =AD15+AD26+AD37+AD48+AD58+AD69+AD79 -> 0 | AE2: =AE15+AE26+AE37+AE48+AE58+AE69+AE79 -> 0
A3: 線別 | B3: 品類 | D3: 品名 | F3: 廠價 | G3: 生產量 | H3: 營收 | I3: 多次 生產 | J3: 人數 | K3: 產能/時 | L3: 人時性 | M3: 人數 | N3: 產能/時 | O3: 人時性 | P3: 人數 | Q3: 人時性 | R3: 達成率 | S3: 達成率平均 | T3: 生產時間 | V3: 前置、換線時間/分 | W3: 稼動時間/分 | X3: 休息時間 | Z3: 產線異常統計 (5分鐘以上) | AD3: 短暫停線統計 (5分鐘以下) | AF3: 產能/時 | AG3: 達成率 | AH3: 達成率平均
T4: 開始 | U4: 結束 | X4: 開始 | Y4: 結束 | Z4: 次數 | AA4: 時間/分 | AD4: 總次數 | AE4: 設備因素(次數)
A5: 自動一線 (ET-600) | B5: =VLOOKUP(D5,廠價表!$C$1:$E$41,2,0) -> #N/A | F5: =VLOOKUP(D5,廠價表!$C$1:$E$41,3,0) -> #N/A | G5: 2263 | H5: =F5*G5 -> #N/A | J5: =VLOOKUP(D5,產線配置圖!$A$3:$C$39,2,0) -> #N/A | K5: =VLOOKUP(D5,產線配置圖!$A$3:$C$39,3,0) -> #N/A | L5: =K5/J5 -> #N/A | M5: 15 | N5: =G5/W5*60 -> 1444.4681 | O5: =N5/M5 -> 96.297872 | P5: =M5-J5 -> #N/A | Q5: =O5-L5 -> #N/A | R5: =O5/L5 -> #N/A | S5: =R15 -> #N/A | T5: 0.29097222 | U5: 0.35625 | W5: =(U5-T5)*24*60 -> 94 | AF5: =N5-K5 -> #N/A | AG5: =N5/K5 -> #N/A | AH5: =AG15 -> #N/A
B6: =VLOOKUP(D6,廠價表!$C$1:$E$41,2,0) -> #N/A | F6: =VLOOKUP(D6,廠價表!$C$1:$E$41,3,0) -> #N/A | G6: 1180 | H6: =F6*G6 -> #N/A | J6: =VLOOKUP(D6,產線配置圖!$A$3:$C$39,2,0) -> #N/A | K6: =VLOOKUP(D6,產線配置圖!$A$3:$C$39,3,0) -> #N/A | L6: =K6/J6 -> #N/A | M6: 17 | N6: =G6/W6*60 -> 1609.0909 | O6: =N6/M6 -> 94.652406 | P6: =M6-J6 -> #N/A | Q6: =O6-L6 -> #N/A | R6: =O6/L6 -> #N/A | T6: 0.36458333 | U6: 0.39513889 | V6: =(T6-U5)*24*60 -> 12 | W6: =(U6-T6)*24*60 -> 44 | AF6: =N6-K6 -> #N/A | AG6: =N6/K6 -> #N/A
B7: =VLOOKUP(D7,廠價表!$C$1:$E$41,2,0) -> #N/A | F7: =VLOOKUP(D7,廠價表!$C$1:$E$41,3,0) -> #N/A | G7: 3398 | H7: =F7*G7 -> #N/A | J7: =VLOOKUP(D7,產線配置圖!$A$3:$C$39,2,0) -> #N/A | K7: =VLOOKUP(D7,產線配置圖!$A$3:$C$39,3,0) -> #N/A | L7: =K7/J7 -> #N/A | M7: 13 | N7: =G7/W7*60 -> 1960.3846 | O7: =N7/M7 -> 150.79882 | P7: =M7-J7 -> #N/A | Q7: =O7-L7 -> #N/A | R7: =O7/L7 -> #N/A | T7: 0.40138889 | U7: 0.47361111 | V7: =(T7-U6)*24*60 -> 9 | W7: =(U7-T7)*24*60 -> 104 | AF7: =N7-K7 -> #N/A | AG7: =N7/K7 -> #N/A
W8: =(U8-T8)*24*60 -> 0 | X8: 0.48611111 | Y8: 0.52777778 | AF8: =N8-K8 -> 0 | AG8: =N8/K8 -> #DIV/0!
W9: =(U9-T9)*24*60 -> 0 | AF9: =N9-K9 -> 0 | AG9: =N9/K9 -> #DIV/0!
W10: =(U10-T10)*24*60 -> 0 | AF10: =N10-K10 -> 0 | AG10: =N10/K10 -> #DIV/0!
W11: =(U11-T11)*24*60 -> 0 | AF11: =N11-K11 -> 0 | AG11: =N11/K11 -> #DIV/0!
W12: =(U12-T12)*24*60 -> 0
W13: =(U13-T13)*24*60 -> 0
W14: =(U14-T14)*24*60 -> 0
C15: 4度一組 | D15: 平均 | J15: =AVERAGE(J5:J14) -> #N/A | K15: =AVERAGE(K5:K14) -> #N/A | L15: =AVERAGE(L5:L14) -> #N/A | M15: =AVERAGE(M5:M14) -> 15 | N15: =AVERAGE(N5:N14) -> 1671.3145 | O15: =AVERAGE(O5:O14) -> 113.91637 | P15: =M15-J15 -> #N/A | Q15: =O15-L15 -> #N/A | R15: =O15/L15 -> #N/A | Z15: =SUM(Z5:Z14) -> 0 | AA15: =SUM(AA5:AA14) -> 0 | AD15: =SUM(AD5:AD14) -> 0 | AE15: =SUM(AE5:AE14) -> 0 | AF15: =N15-K15 -> #N/A | AG15: =N15/K15 -> #N/A
A16: 自動二線 (ET-600) | B16: =VLOOKUP(D16,廠價表!$C$1:$E$41,2,0) -> #N/A | F16: =VLOOKUP(D16,廠價表!$C$1:$E$41,3,0) -> #N/A | G16: 2263 | H16: =F16*G16 -> #N/A | J16: =VLOOKUP(D16,產線配置圖!$A$3:$C$39,2,0) -> #N/A | K16: =VLOOKUP(D16,產線配置圖!$A$3:$C$39,3,0) -> #N/A | L16: =K16/J16 -> #N/A | M16: 13 | N16: =G16/W16*60 -> 2225.9016 | O16: =N16/M16 -> 171.2232 | P16: =M16-J16 -> #N/A | Q16: =O16-L16 -> #N/A | R16: =O16/L16 -> #N/A | S16: =R26 -> #N/A | T16: 0.29097222 | U16: 0.33333333 | W16: =(U16-T16)*24*60 -> 61 | AF16: =N16-K16 -> #N/A | AG16: =N16/K16 -> #N/A | AH16: =AG26 -> #N/A
B17: =VLOOKUP(D17,廠價表!$C$1:$E$41,2,0) -> #N/A | F17: =VLOOKUP(D17,廠價表!$C$1:$E$41,3,0) -> #N/A | G17: 1180 | H17: =F17*G17 -> #N/A | J17: =VLOOKUP(D17,產線配置圖!$A$3:$C$39,2,0) -> #N/A | K17: =VLOOKUP(D17,產線配置圖!$A$3:$C$39,3,0) -> #N/A | L17: =K17/J17 -> #N/A | M17: 13 | N17: =G17/W17*60 -> 823.25581 | O17: =N17/M17 -> 63.32737 | P17: =M17-J17 -> #N/A | Q17: =O17-L17 -> #N/A | R17: =O17/L17 -> #N/A | T17: 0.34166667 | U17: 0.40138889 | V17: =(T17-U16)*24*60 -> 12 | W17: =(U17-T17)*24*60 -> 86 | AF17: =N17-K17 -> #N/A | AG17: =N17/K17 -> #N/A
B18: =VLOOKUP(D18,廠價表!$C$1:$E$41,2,0) -> #N/A | F18: =VLOOKUP(D18,廠價表!$C$1:$E$41,3,0) -> #N/A | G18: 3398 | H18: =F18*G18 -> #N/A | J18: =VLOOKUP(D18,產線配置圖!$A$3:$C$39,2,0) -> #N/A | K18: =VLOOKUP(D18,產線配置圖!$A$3:$C$39,3,0) -> #N/A | L18: =K18/J18 -> #N/A | M18: 12 | N18: =G18/W18*60 -> 1941.7143 | O18: =N18/M18 -> 161.80952 | P18: =M18-J18 -> #N/A | Q18: =O18-L18 -> #N/A | R18: =O18/L18 -> #N/A | T18: 0.40972222 | U18: 0.48263889 | V18: =(T18-U17)*24*60 -> 12 | W18: =(U18-T18)*24*60 -> 105 | X18: 0.48611111 | Y18: 0.52777778 | AF18: =N18-K18 -> #N/A | AG18: =N18/K18 -> #N/A
V19: =(T19-U18)*24*60 -> -695 | W19: =(U19-T19)*24*60 -> 0 | AF19: =N19-K19 -> 0 | AG19: =N19/K19 -> #DIV/0!
V20: =(T20-U19)*24*60 -> 0 | W20: =(U20-T20)*24*60 -> 0
W21: =(U21-T21)*24*60 -> 0
W22: 0
W23: =(U23-T23)*24*60 -> 0
H24: =F24*G24 -> 0 | W24: =(U24-T24)*24*60 -> 0
H25: =F25*G25 -> 0 | W25: =(U25-T25)*24*60 -> 0
C26: 4度二組A | D26: 平均 | J26: =AVERAGE(J16:J25) -> #N/A | K26: =AVERAGE(K16:K25) -> #N/A | L26: =AVERAGE(L16:L25) -> #N/A | M26: =AVERAGE(M16:M25) -> 12.666667 | N26: =AVERAGE(N16:N25) -> 1663.6239 | O26: =AVERAGE(O16:O25) -> 132.12003 | P26: =M26-J26 -> #N/A | Q26: =O26-L26 -> #N/A | R26: =O26/L26 -> #N/A | Z26: =SUM(Z16:Z25) -> 0 | AA26: =SUM(AA16:AA25) -> 0 | AD26: =SUM(AD16:AD25) -> 0 | AE26: =SUM(AE16:AE25) -> 0 | AF26: =N26-K26 -> #N/A | AG26: =N26/K26 -> #N/A
A27: 手工三線 (ET-55) | B27: =VLOOKUP(D27,廠價表!$C$1:$E$41,2,0) -> #N/A | F27: =VLOOKUP(D27,廠價表!$C$1:$E$41,3,0) -> #N/A | G27: 2263 | H27: =F27*G27 -> #N/A | J27: =VLOOKUP(D27,產線配置圖!$A$3:$C$39,2,0) -> #N/A | K27: =VLOOKUP(D27,產線配置圖!$A$3:$C$39,3,0) -> #N/A | L27: =K27/J27 -> #N/A | M27: 14 | N27: =G27/W27*60 -> 1212.3214 | O27: =N27/M27 -> 86.594388 | P27: =M27-J27 -> #N/A | Q27: =O27-L27 -> #N/A | R27: =O27/L27 -> #N/A | S27: =R37 -> #N/A | T27: 0.29166667 | U27: 0.36944444 | W27: =(U27-T27)*24*60 -> 112 | AF27: =N27-K27 -> #N/A | AG27: =N27/K27 -> #N/A | AH27: =AG37 -> #N/A
B28: =VLOOKUP(D28,廠價表!$C$1:$E$41,2,0) -> #N/A | F28: =VLOOKUP(D28,廠價表!$C$1:$E$41,3,0) -> #N/A | G28: 1180 | H28: =F28*G28 -> #N/A | J28: =VLOOKUP(D28,產線配置圖!$A$3:$C$39,2,0) -> #N/A | K28: =VLOOKUP(D28,產線配置圖!$A$3:$C$39,3,0) -> #N/A | L28: =K28/J28 -> #N/A | M28: 16 | N28: =G28/W28*60 -> 1089.2308 | O28: =N28/M28 -> 68.076923 | P28: =M28-J28 -> #N/A | Q28: =O28-L28 -> #N/A | R28: =O28/L28 -> #N/A | T28: 0.375 | U28: 0.42013889 | V28: =(T28-U27)*24*60 -> 8 | W28: =(U28-T28)*24*60 -> 65 | AF28: =N28-K28 -> #N/A | AG28: =N28/K28 -> #N/A
B29: =VLOOKUP(D29,廠價表!$C$1:$E$41,2,0) -> #N/A | F29: =VLOOKUP(D29,廠價表!$C$1:$E$41,3,0) -> #N/A | G29: 3398 | H29: =F29*G29 -> #N/A | J29: =VLOOKUP(D29,產線配置圖!$A$3:$C$39,2,0) -> #N/A | K29: =VLOOKUP(D29,產線配置圖!$A$3:$C$39,3,0) -> #N/A | L29: =K29/J29 -> #N/A | M29: 14 | N29: =G29/W29*60 -> 3136.6154 | O29: =N29/M29 -> 224.04396 | P29: =M29-J29 -> #N/A | Q29: =O29-L29 -> #N/A | R29: =O29/L29 -> #N/A | T29: 0.43055556 | U29: 0.47569444 | V29: =(T29-U28)*24*60 -> 15 | W29: =(U29-T29)*24*60 -> 65 | AF29: =N29-K29 -> #N/A | AG29: =N29/K29 -> #N/A
T30: 0.53958333 | U30: 0.56944444 | V30: =(T30-U29)*24*60 -> 92 | W30: =(U30-T30)*24*60 -> 43 | X30: 0.49652778 | Y30: 0.53819444 | AF30: =N30-K30 -> 0 | AG30: =N30/K30 -> #DIV/0!
W31: =(U31-T31)*24*60 -> 0 | AF31: =N31-K31 -> 0 | AG31: =N31/K31 -> #DIV/0!
W32: =(U32-T32)*24*60 -> 0
W33: =(U33-T33)*24*60 -> 0
W34: =(U34-T34)*24*60 -> 0
W35: =(U35-T35)*24*60 -> 0
H36: =F36*G36 -> 0 | W36: =(U36-T36)*24*60 -> 0
C37: 4度二組B | D37: 平均 | J37: =AVERAGE(J27:J36) -> #N/A | K37: =AVERAGE(K27:K36) -> #N/A | L37: =AVERAGE(L27:L36) -> #N/A | M37: =AVERAGE(M27:M36) -> 14.666667 | N37: =AVERAGE(N27:N36) -> 1812.7225 | O37: =AVERAGE(O27:O36) -> 126.23842 | P37: =M37-J37 -> #N/A | Q37: =N37-K37 -> #N/A | R37: =O37/L37 -> #N/A | Z37: =SUM(Z27:Z36) -> 0 | AA37: =SUM(AA27:AA36) -> 0 | AD37: =SUM(AD27:AD36) -> 0 | AE37: =SUM(AE27:AE36) -> 0 | AF37: =N37-K37 -> #N/A | AG37: =N37/K37 -> #N/A
A38: 手工四線 (ET-55) | B38: =VLOOKUP(D38,廠價表!$C$1:$E$41,2,0) -> #N/A | F38: =VLOOKUP(D38,廠價表!$C$1:$E$41,3,0) -> #N/A | G38: 2263 | H38: =F38*G38 -> #N/A | J38: =VLOOKUP(D38,產線配置圖!$A$3:$C$39,2,0) -> #N/A | K38: =VLOOKUP(D38,產線配置圖!$A$3:$C$39,3,0) -> #N/A | L38: =K38/J38 -> #N/A | M38: 14 | N38: =G38/W38*60 -> 1967.8261 | O38: =N38/M38 -> 140.55901 | P38: =M38-J38 -> #N/A | Q38: =O38-L38 -> #N/A | R38: =O38/L38 -> #N/A | S38: =R48 -> #N/A | T38: 0.33333333 | U38: 0.38125 | W38: =(U38-T38)*24*60 -> 69 | AF38: =N38-K38 -> #N/A | AG38: =N38/K38 -> #N/A | AH38: =AG48 -> #N/A
B39: =VLOOKUP(D39,廠價表!$C$1:$E$41,2,0) -> #N/A | F39: =VLOOKUP(D39,廠價表!$C$1:$E$41,3,0) -> #N/A | G39: 1180 | H39: =F39*G39 -> #N/A | J39: =VLOOKUP(D39,產線配置圖!$A$3:$C$39,2,0) -> #N/A | K39: =VLOOKUP(D39,產線配置圖!$A$3:$C$39,3,0) -> #N/A | L39: =K39/J39 -> #N/A | M39: 14 | N39: =G39/W39*60 -> 885 | O39: =N39/M39 -> 63.214286 | P39: =M39-J39 -> #N/A | Q39: =O39-L39 -> #N/A | R39: =O39/L39 -> #N/A | T39: 0.38888889 | U39: 0.44444444 | V39: =(T39-U38)*24*60 -> 11 | W39: =(U39-T39)*24*60 -> 80 | AF39: =N39-K39 -> #N/A | AG39: =N39/K39 -> #N/A
B40: =VLOOKUP(D40,廠價表!$C$1:$E$41,2,0) -> #N/A | F40: =VLOOKUP(D40,廠價表!$C$1:$E$41,3,0) -> #N/A | G40: 3398 | H40: =F40*G40 -> #N/A | J40: =VLOOKUP(D40,產線配置圖!$A$3:$C$39,2,0) -> #N/A | K40: =VLOOKUP(D40,產線配置圖!$A$3:$C$39,3,0) -> #N/A | L40: =K40/J40 -> #N/A | M40: 14 | N40: =G40/W40*60 -> 1853.4545 | O40: =N40/M40 -> 132.38961 | P40: =M40-J40 -> #N/A | Q40: =O40-L40 -> #N/A | R40: =O40/L40 -> #N/A | T40: 0.52777778 | U40: 0.60416667 | V40: =(T40-U39)*24*60 -> 120 | W40: =(U40-T40)*24*60 -> 110 | AF40: =N40-K40 -> #N/A | AG40: =N40/K40 -> #N/A
...

Sheet 0201總
B1: 長家廠組合室生產人時性分析
B3: 日期 | D3: 46054 | F3: 訂單量 | G3: ='0201'!E1 -> 63199 | I3: 營業額 | J3: ='0201'!G1 -> 3059903.2
B4: 項目 | D4: 3 | F4: ➀ | H4: ➁ | J4: ③ | L4: 異常停線 | N4: 短暫停線
B5: 人時性 | D5: 組合室 | F5: 全溫層 | H5: 義大利麵 | J5: 袋裝小吃、義麵 | L5: 合計次數 | M5: 時間 | N5: 合計次數 | O5: 設備次數
D6: 排關平均 | F6: =AVERAGE(D13:J13) -> 114.25156 | H6: =AVERAGE(D13:H13,J13) -> 111.97538 | J6: =AVERAGE(I13) -> 127.90865 | L6: =SUM(D18:J18) -> 0 | M6: =SUM(D19:J19) -> 0 | N6: =SUM(D20:J20) -> 2 | O6: =SUM(D20:J20) -> 2
D7: 實績平均 | F7: =AVERAGE(D14:J14) -> 106.92283 | H7: =AVERAGE(D14:H14,J14) -> 104.95916 | J7: =AVERAGE(I14) -> 118.70487 | L7: =AVERAGE(K14:L14) -> #DIV/0! | M7: =AVERAGE(L14:M14) -> #DIV/0! | N7: =AVERAGE(M14:N14) -> #DIV/0! | O7: =AVERAGE(N14:O14) -> #DIV/0!
D8: 達成率平均 | F8: =F7/F6 -> 0.93585442 | H8: =H7/H6 -> 0.93734136 | J8: =J7/J6 -> 0.92804411 | L8: =AVERAGE(K15:L15) -> #DIV/0! | M8: =AVERAGE(L15:M15) -> #DIV/0! | N8: =AVERAGE(M15:N15) -> #DIV/0! | O8: =AVERAGE(N15:O15) -> #DIV/0!
J9: ※現行日本鮮食廠以達成率80%為基本(即為現行KPI)
B10: 溫層 | D10: 4度C-各編組展開
B11: 編組 | D11: 1 | E11: 2 | F11: 3 | G11: 4 | H11: 5 | I11: 6 | J11: 7
D12: 自動1線 | E12: 自動2線 | F12: 手工3線 | G12: 手工4線 | H12: 手工5線 | I12: 調理包1線 | J12: 調理包2線
B13: 人時性 | C13: 排關 | D13: =VALUE('0201'!L15) -> 130.84034 | E13: =VALUE('0201'!L26) -> 162.15812 | F13: =VALUE('0201'!L37) -> 89.988235 | G13: =VALUE('0201'!L48) -> 87.685049 | H13: =VALUE('0201'!L58) -> 88.680556 | I13: =VALUE('0201'!L69) -> 127.90865 | J13: ='0201'!L79 -> 112.5
C14: 實績 | D14: =VALUE('0201'!O15) -> 121.37443 | E14: =VALUE('0201'!O26) -> 147.28542 | F14: =VALUE('0201'!O37) -> 82.326962 | G14: =VALUE('0201'!O48) -> 80.444351 | H14: =VALUE('0201'!O58) -> 87.232876 | I14: =VALUE('0201'!O69) -> 118.70487 | J14: ='0201'!O79 -> 111.09091
C15: 達成率 | D15: =D14/D13 -> 0.92765298 | E15: =E14/E13 -> 0.90828274 | F15: =F14/F13 -> 0.91486361 | G15: =G14/G13 -> 0.9174238 | H15: =H14/H13 -> 0.98367534 | I15: =I14/I13 -> 0.92804411 | J15: ='0201'!S70 -> 0.98747475
B16: 作業 時間 | C16: 開始 | D16: ='0201'!T5 -> 0.3125 | E16: ='0201'!T16 -> 0.28958333 | F16: ='0201'!T27 -> 0.29166667 | G16: ='0201'!T38 -> 0.33333333 | H16: ='0201'!T49 -> 0.29513889 | I16: ='0201'!T59 -> 0.29166667 | J16: ='0201'!T70 -> 0.33333333
C17: 結束 | D17: 0.63888889 | E17: 0.68402778 | F17: 0.64930556 | G17: 0.71527778 | H17: 0.65138889 | I17: 0.59375 | J17: 0.44791667
B18: 產線異常 (5分鐘以上) | C18: 次數 | D18: ='0201'!Z15 -> 0 | E18: ='0201'!Z26 -> 0 | F18: ='0201'!Z37 -> 0 | G18: ='0201'!Z48 -> 0 | H18: ='0201'!Z58 -> 0 | I18: ='0201'!Z69 -> 0 | J18: ='0201'!AA79 -> 0
C19: 時間/分 | D19: ='0201'!AA15 -> 0 | E19: ='0201'!AA26 -> 0 | F19: ='0201'!AA37 -> 0 | G19: ='0201'!AA48 -> 0 | H19: ='0201'!AA58 -> 0 | I19: ='0201'!AA69 -> 0 | J19: ='0201'!AB79 -> 0
B20: 短暫停線 (5分鐘以下) | C20: 次數 | D20: ='0201'!AD15 -> 0 | E20: ='0201'!AD26 -> 2 | F20: ='0201'!AD37 -> 0 | G20: ='0201'!AD48 -> 0 | H20: ='0201'!AD58 -> 0 | I20: ='0201'!AD69 -> 0 | J20: ='0201'!AD79 -> 0
C21: 設備次數 | D21: ='0201'!AE15 -> 0 | E21: ='0201'!AE26 -> 2 | F21: ='0201'!AE37 -> 0 | G21: ='0201'!AE48 -> 0 | H21: ='0201'!AE58 -> 0 | I21: ='0201'!AE69 -> 0 | J21: ='0201'!AE79 -> 0
B22: 配置人數 | D22: =VALUE('0201'!M15) -> 15 | E22: =VALUE('0201'!M26) -> 13.333333 | F22: =VALUE('0201'!M37) -> 15.6 | G22: =VALUE('0201'!M48) -> 16 | H22: =VALUE('0201'!M58) -> 17 | I22: =VALUE('0201'!M69) -> 12.25 | J22: ='0201'!M79 -> 10
B23: 主要應用設備 | D23: ET-600 | E23: ET-600 | F23: ET-55 | G23: ET-55 | H23: ET-55 | I23: 八爪機 | J23: 八爪機
B24: 次要應用設備 | H24: 封口機 | J24: 封口機
B25: 備註

Sheet 0201
A1: 長家廠4度C日報分析 | D1: 總生產量 | E1: =SUM(G5:G79) -> 63199 | F1: 營業額 | G1: =SUM(H5:H79) -> 3059903.2 | H1: 出勤人數 | I1: =M15+M26+M48+M58+M69+M79+M37 -> 99.183333 | J1: 產線配置圖 | M1: 生產實績 | P1: 人時性差異分析 | T1: 日報登錄 | Z1: 合計 次數 | AA1: 合計 時間/分 | AB1: 分析說明 | AD1: 合計 次數 | AE1: 合計 設備次數 | AF1: 產能差異分析
A2: 02月01日 星期六 | D2: 人時性 | E2: =AVERAGE(O15,O26,O37,O48,O58,O69,O79) -> 106.92283 | F2: 平均廠價 | G2: =G1/E1 -> 48.416956 | H2: 多次生產數 | I2: =COUNT(I5:I79) -> 0 | Z2: =Z15+Z26+Z37+Z48+Z58+Z69+Z79 -> 0 | AA2: =AA15+AA26+AA37+AA48+AA58+AA69+AA79 -> 0 | AD2: =AD15+AD26+AD37+AD48+AD58+AD69+AD79 -> 2 | AE2: =AE15+AE26+AE37+AE48+AE58+AE69+AE79 -> 2
A3: 線別 | B3: 品類 | D3: 品名 | F3: 廠價 | G3: 生產量 | H3: 營收 | I3: 多次 生產 | J3: 人數 | K3: 產能/時 | L3: 人時性 | M3: 人數 | N3: 產能/時 | O3: 人時性 | P3: 人數 | Q3: 人時性 | R3: 達成率 | S3: 達成率平均 | T3: 生產時間 | V3: 前置、換線時間/分 | W3: 稼動時間/分 | X3: 休息時間 | Z3: 產線異常統計 (5分鐘以上) | AD3: 短暫停線統計 (5分鐘以下) | AF3: 產能/時 | AG3: 達成率 | AH3: 達成率平均
T4: 開始 | U4: 結束 | X4: 開始 | Y4: 結束 | Z4: 次數 | AA4: 時間/分 | AD4: 總次數 | AE4: 設備因素(次數)
A5: 自動一線 (ET-600) | B5: 義大利麵 | D5: 韓式起司炸雞義大利麵 | F5: =VLOOKUP(D5,廠價表!$C$1:$E$41,3,0) -> 57.21 | G5: 1343 | H5: =F5*G5 -> 76833.03 | J5: =VLOOKUP(D5,產線配置圖!$A$3:$C$39,2,0) -> 17 | K5: =VLOOKUP(D5,產線配置圖!$A$3:$C$39,3,0) -> 2000 | L5: =K5/J5 -> 117.64706 | M5: 17 | N5: =G5/W5*60 -> 1611.6 | O5: =N5/M5 -> 94.8 | P5: =M5-J5 -> 0 | Q5: =O5-L5 -> -22.847059 | R5: =O5/L5 -> 0.8058 | S5: =R15 -> 0.92765298 | T5: 0.3125 | U5: 0.34722222 | W5: =(U5-T5)*24*60 -> 50 | AF5: =N5-K5 -> -388.4 | AG5: =N5/K5 -> 0.8058 | AH5: =AG15 -> 0.92309726
B6: 義大利麵 | D6: 辣味香菜雞肉義大利麵 | F6: =VLOOKUP(D6,廠價表!$C$1:$E$41,3,0) -> 56.28 | G6: 2554 | H6: =F6*G6 -> 143739.12 | J6: =VLOOKUP(D6,產線配置圖!$A$3:$C$39,2,0) -> 15 | K6: =VLOOKUP(D6,產線配置圖!$A$3:$C$39,3,0) -> 1800 | L6: =K6/J6 -> 120 | M6: 15 | N6: =G6/W6*60 -> 1781.8605 | O6: =N6/M6 -> 118.7907 | P6: =M6-J6 -> 0 | Q6: =O6-L6 -> -1.2093023 | R6: =O6/L6 -> 0.98992248 | T6: 0.35555556 | U6: 0.41527778 | V6: =(T6-U5)*24*60 -> 12 | W6: =(U6-T6)*24*60 -> 86 | AF6: =N6-K6 -> -18.139535 | AG6: =N6/K6 -> 0.98992248
B7: 義大利麵 | D7: 奶油培根義大利麵 | F7: =VLOOKUP(D7,廠價表!$C$1:$E$41,3,0) -> 49.14 | G7: 1613 | H7: =F7*G7 -> 79262.82 | J7: 14 | K7: =VLOOKUP(D7,產線配置圖!$A$3:$C$39,3,0) -> 2000 | L7: =K7/J7 -> 142.85714 | M7: 14 | N7: =G7/W7*60 -> 1897.6471 | O7: =N7/M7 -> 135.54622 | P7: =M7-J7 -> 0 | Q7: =O7-L7 -> -7.3109244 | R7: =O7/L7 -> 0.94882353 | T7: 0.44305556 | U7: 0.47847222 | V7: =(T7-U6)*24*60 -> 40 | W7: =(U7-T7)*24*60 -> 51 | AF7: =N7-K7 -> -102.35294 | AG7: =N7/K7 -> 0.94882353
B8: 義大利麵 | D8: 奶油培根義大利麵 | F8: =VLOOKUP(D8,廠價表!$C$1:$E$41,3,0) -> 49.14 | G8: 4359 | H8: =F8*G8 -> 214201.26 | J8: 14 | K8: =VLOOKUP(D8,產線配置圖!$A$3:$C$39,3,0) -> 2000 | L8: =K8/J8 -> 142.85714 | M8: 14 | N8: =G8/W8*60 -> 1909.0511 | O8: =N8/M8 -> 136.36079 | P8: =M8-J8 -> 0 | Q8: =O8-L8 -> -6.4963504 | R8: =O8/L8 -> 0.95452555 | T8: 0.54375 | U8: 0.63888889 | V8: =(T8-U7)*24*60 -> 94 | W8: =(U8-T8)*24*60 -> 137 | X8: 0.48611111 | Y8: 0.52777778 | AF8: =N8-K8 -> -90.948905 | AG8: =N8/K8 -> 0.95452555
W9: =(U9-T9)*24*60 -> 0 | AF9: =N9-K9 -> 0 | AG9: =N9/K9 -> #DIV/0!
W10: =(U10-T10)*24*60 -> 0 | AF10: =N10-K10 -> 0 | AG10: =N10/K10 -> #DIV/0!
W11: =(U11-T11)*24*60 -> 0 | AF11: =N11-K11 -> 0 | AG11: =N11/K11 -> #DIV/0!
W12: =(U12-T12)*24*60 -> 0
W13: =(U13-T13)*24*60 -> 0
W14: =(U14-T14)*24*60 -> 0
C15: 4度一組 | D15: 平均 | J15: =AVERAGE(J5:J14) -> 15 | K15: =AVERAGE(K5:K14) -> 1950 | L15: =AVERAGE(L5:L14) -> 130.84034 | M15: =AVERAGE(M5:M14) -> 15 | N15: =AVERAGE(N5:N14) -> 1800.0397 | O15: =AVERAGE(O5:O14) -> 121.37443 | P15: =M15-J15 -> 0 | Q15: =O15-L15 -> -9.465909 | R15: =O15/L15 -> 0.92765298 | Z15: =SUM(Z5:Z14) -> 0 | AA15: =SUM(AA5:AA14) -> 0 | AD15: =SUM(AD5:AD14) -> 0 | AE15: =SUM(AE5:AE14) -> 0 | AF15: =N15-K15 -> -149.96035 | AG15: =N15/K15 -> 0.92309726
A16: 自動二線 (ET-600) | B16: 義大利麵 | D16: 白酒蛤蜊義大利麵 | F16: =VLOOKUP(D16,廠價表!$C$1:$E$41,3,0) -> 57.21 | G16: 1217 | H16: =F16*G16 -> 69624.57 | J16: 13 | K16: =VLOOKUP(D16,產線配置圖!$A$3:$C$39,3,0) -> 2105 | L16: =K16/J16 -> 161.92308 | M16: 14 | N16: =G16/W16*60 -> 2212.7273 | O16: =N16/M16 -> 158.05195 | P16: =M16-J16 -> 1 | Q16: =O16-L16 -> -3.8711289 | R16: =O16/L16 -> 0.97609279 | S16: =R26 -> 0.90828274 | T16: 0.28958333 | U16: 0.3125 | W16: =(U16-T16)*24*60 -> 33 | AF16: =N16-K16 -> 107.72727 | AG16: =N16/K16 -> 1.0511769 | AH16: =AG26 -> 0.95271966
B17: 義大利麵 | D17: 白酒蛤蜊義大利麵 | F17: =VLOOKUP(D17,廠價表!$C$1:$E$41,3,0) -> 57.21 | G17: 1829 | H17: =F17*G17 -> 104637.09 | J17: 13 | K17: =VLOOKUP(D17,產線配置圖!$A$3:$C$39,3,0) -> 2105 | L17: =K17/J17 -> 161.92308 | M17: 16 | N17: =G17/W17*60 -> 2110.3846 | O17: =N17/M17 -> 131.89904 | P17: =M17-J17 -> 3 | Q17: =O17-L17 -> -30.024038 | R17: =O17/L17 -> 0.81457838 | T17: 0.31805556 | U17: 0.35416667 | V17: =(T17-U16)*24*60 -> 8 | W17: =(U17-T17)*24*60 -> 52 | AB17: 改手抓麵 | AF17: =N17-K17 -> 5.3846154 | AG17: =N17/K17 -> 1.002558
B18: 義大利麵 | D18: 青醬蛤蜊義大利麵 | F18: =VLOOKUP(D18,廠價表!$C$1:$E$41,3,0) -> 50.67 | G18: 3984 | H18: =F18*G18 -> 201869.28 | J18: 13 | K18: =VLOOKUP(D18,產線配置圖!$A$3:$C$39,3,0) -> 2000 | L18: =K18/J18 -> 153.84615 | M18: 13 | N18: =G18/W18*60 -> 1992 | O18: =N18/M18 -> 153.23077 | P18: =M18-J18 -> 0 | Q18: =O18-L18 -> -0.61538462 | R18: =O18/L18 -> 0.996 | T18: 0.36111111 | U18: 0.44444444 | V18: =(T18-U17)*24*60 -> 10 | W18: =(U18-T18)*24*60 -> 120 | AF18: =N18-K18 -> -8 | AG18: =N18/K18 -> 0.996
B19: 義大利麵 | D19: 義式蕃茄起司義大利麵 | F19: =VLOOKUP(D19,廠價表!$C$1:$E$41,3,0) -> 50.39 | G19: 1156 | H19: =F19*G19 -> 58250.84 | J19: 12 | K19: =VLOOKUP(D19,產線配置圖!$A$3:$C$39,3,0) -> 2000 | L19: =K19/J19 -> 166.66667 | M19: 12 | N19: =G19/W19*60 -> 1734 | O19: =N19/M19 -> 144.5 | P19: =M19-J19 -> 0 | Q19: =O19-L19 -> -22.166667 | R19: =O19/L19 -> 0.867 | T19: 0.45138889 | U19: 0.47916667 | V19: =(T19-U18)*24*60 -> 10 | W19: =(U19-T19)*24*60 -> 40 | AF19: =N19-K19 -> -266 | AG19: =N19/K19 -> 0.867
B20: 義大利麵 | D20: 義式蕃茄起司義大利麵 | F20: =VLOOKUP(D20,廠價表!$C$1:$E$41,3,0) -> 50.39 | G20: 4284 | H20: =F20*G20 -> 215870.76 | J20: 12 | K20: =VLOOKUP(D20,產線配置圖!$A$3:$C$39,3,0) -> 2000 | L20: =K20/J20 -> 166.66667 | M20: 12 | N20: =G20/W20*60 -> 1977.2308 | O20: =N20/M20 -> 164.76923 | P20: =M20-J20 -> 0 | Q20: =O20-L20 -> -1.8974359 | R20: =O20/L20 -> 0.98861538 | T20: 0.53472222 | U20: 0.625 | V20: =(T20-U19)*24*60 -> 80 | W20: =(U20-T20)*24*60 -> 130 | X20: 0.48611111 | Y20: 0.52777778 | AB20: 玉取機停麵 | AD20: 1 | AE20: 1
B21: 義大利麵 | D21: 白酒蛤蜊義大利麵 | F21: =VLOOKUP(D21,廠價表!$C$1:$E$41,3,0) -> 57.21 | G21: 2133 | H21: =F21*G21 -> 122028.93 | J21: 13 | K21: =VLOOKUP(D21,產線配置圖!$A$3:$C$39,3,0) -> 2105 | L21: =K21/J21 -> 161.92308 | M21: 13 | N21: =G21/W21*60 -> 1706.4 | O21: =N21/M21 -> 131.26154 | P21: =M21-J21 -> 0 | Q21: =O21-L21 -> -30.661538 | R21: =O21/L21 -> 0.81064133 | T21: 0.63194444 | U21: 0.68402778 | V21: =(T21-U20)*24*60 -> 10 | W21: =(U21-T21)*24*60 -> 75 | AB21: 玉取機停麵 | AD21: 1 | AE21: 1
W22: 0
W23: =(U23-T23)*24*60 -> 0
H24: =F24*G24 -> 0 | W24: =(U24-T24)*24*60 -> 0
H25: =F25*G25 -> 0 | W25: =(U25-T25)*24*60 -> 0
C26: 4度二組A | D26: 平均 | J26: =AVERAGE(J16:J25) -> 12.666667 | K26: =AVERAGE(K16:K25) -> 2052.5 | L26: =AVERAGE(L16:L25) -> 162.15812 | M26: =AVERAGE(M16:M25) -> 13.333333 | N26: =AVERAGE(N16:N25) -> 1955.4571 | O26: =AVERAGE(O16:O25) -> 147.28542 | P26: =M26-J26 -> 0.66666667 | Q26: =O26-L26 -> -14.872699 | R26: =O26/L26 -> 0.90828274 | Z26: =SUM(Z16:Z25) -> 0 | AA26: =SUM(AA16:AA25) -> 0 | AD26: =SUM(AD16:AD25) -> 2 | AE26: =SUM(AE16:AE25) -> 2 | AF26: =N26-K26 -> -97.04289 | AG26: =N26/K26 -> 0.95271966
A27: 手工三線 (ET-55) | B27: 義大利麵 | D27: 惡魔乳酪生義大利麵 | F27: =VLOOKUP(D27,廠價表!$C$1:$E$41,3,0) -> 57.3 | G27: 2000 | H27: =F27*G27 -> 114600 | J27: =VLOOKUP(D27,產線配置圖!$A$3:$C$39,2,0) -> 17 | K27: =VLOOKUP(D27,產線配置圖!$A$3:$C$39,3,0) -> 1500 | L27: =K27/J27 -> 88.235294 | M27: 16 | N27: =G27/W27*60 -> 1395.3488 | O27: =N27/M27 -> 87.209302 | P27: =M27-J27 -> -1 | Q27: =O27-L27 -> -1.0259918 | R27: =O27/L27 -> 0.98837209 | S27: =R37 -> 0.91486361 | T27: 0.29166667 | U27: 0.35138889 | W27: =(U27-T27)*24*60 -> 86 | AF27: =N27-K27 -> -104.65116 | AG27: =N27/K27 -> 0.93023256 | AH27: =AG37 -> 0.88514459
B28: 義大利麵 | D28: 奶油蒜香雞義大利麵 | F28: =VLOOKUP(D28,廠價表!$C$1:$E$41,3,0) -> 55.13 | G28: 1528 | H28: =F28*G28 -> 84238.64 | J28: =VLOOKUP(D28,產線配置圖!$A$3:$C$39,2,0) -> 17 | K28: =VLOOKUP(D28,產線配置圖!$A$3:$C$39,3,0) -> 1385 | L28: =K28/J28 -> 81.470588 | M28: 16 | N28: =G28/W28*60 -> 1291.2676 | O28: =N28/M28 -> 80.704225 | P28: =M28-J28 -> -1 | Q28: =O28-L28 -> -0.76636288 | R28: =O28/L28 -> 0.99059338 | T28: 0.35763889 | U28: 0.40694444 | V28: =(T28-U27)*24*60 -> 9 | W28: =(U28-T28)*24*60 -> 71 | AF28: =N28-K28 -> -93.732394 | AG28: =N28/K28 -> 0.93232318
B29: 熱乾麵 | D29: 沙茶豬肉炒麵 | F29: =VLOOKUP(D29,廠價表!$C$1:$E$41,3,0) -> 49.52 | G29: 1446 | H29: =F29*G29 -> 71605.92 | J29: =VLOOKUP(D29,產線配置圖!$A$3:$C$39,2,0) -> 15 | K29: =VLOOKUP(D29,產線配置圖!$A$3:$C$39,3,0) -> 1440 | L29: =K29/J29 -> 96 | M29: 15 | N29: =G29/W29*60 -> 1172.4324 | O29: =N29/M29 -> 78.162162 | P29: =M29-J29 -> 0 | Q29: =O29-L29 -> -17.837838 | R29: =O29/L29 -> 0.81418919 | T29: 0.41527778 | U29: 0.46666667 | V29: =(T29-U28)*24*60 -> 12 | W29: =(U29-T29)*24*60 -> 74 | AF29: =N29-K29 -> -267.56757 | AG29: =N29/K29 -> 0.81418919
B30: 熱乾麵 | D30: 沙茶豬肉炒麵 | F30: =VLOOKUP(D30,廠價表!$C$1:$E$41,3,0) -> 49.52 | G30: 600 | H30: =F30*G30 -> 29712 | J30: =VLOOKUP(D30,產線配置圖!$A$3:$C$39,2,0) -> 15 | K30: =VLOOKUP(D30,產線配置圖!$A$3:$C$39,3,0) -> 1440 | L30: =K30/J30 -> 96 | M30: 15 | N30: =G30/W30*60 -> 1161.2903 | O30: =N30/M30 -> 77.419355 | P30: =M30-J30 -> 0 | Q30: =O30-L30 -> -18.580645 | R30: =O30/L30 -> 0.80645161 | T30: 0.53194444 | U30: 0.55347222 | V30: =(T30-U29)*24*60 -> 94 | W30: =(U30-T30)*24*60 -> 31 | X30: 0.47916667 | Y30: 0.52083333 | AF30: =N30-K30 -> -278.70968 | AG30: =N30/K30 -> 0.80645161
B31: 義大利麵 | D31: 惡魔乳酪生義大利麵 | F31: =VLOOKUP(D31,廠價表!$C$1:$E$41,3,0) -> 57.3 | G31: 2985 | H31: =F31*G31 -> 171040.5 | J31: =VLOOKUP(D31,產線配置圖!$A$3:$C$39,2,0) -> 17 | K31: =VLOOKUP(D31,產線配置圖!$A$3:$C$39,3,0) -> 1500 | L31: =K31/J31 -> 88.235294 | M31: 16 | N31: =G31/W31*60 -> 1410.2362 | O31: =N31/M31 -> 88.139764 | P31: =M31-J31 -> -1 | Q31: =O31-L31 -> -0.095530338 | R31: =O31/L31 -> 0.99891732 | T31: 0.56111111 | U31: 0.64930556 | V31: =(T31-U30)*24*60 -> 11 | W31: =(U31-T31)*24*60 -> 127 | AF31: =N31-K31 -> -89.76378 | AG31: =N31/K31 -> 0.94015748
W32: =(U32-T32)*24*60 -> 0
W33: =(U33-T33)*24*60 -> 0
W34: =(U34-T34)*24*60 -> 0
W35: =(U35-T35)*24*60 -> 0
H36: =F36*G36 -> 0 | W36: =(U36-T36)*24*60 -> 0
C37: 4度二組B | D37: 平均 | J37: =AVERAGE(J27:J36) -> 16.2 | K37: =AVERAGE(K27:K36) -> 1453 | L37: =AVERAGE(L27:L36) -> 89.988235 | M37: =AVERAGE(M27:M36) -> 15.6 | N37: =AVERAGE(N27:N36) -> 1286.1151 | O37: =AVERAGE(O27:O36) -> 82.326962 | P37: =M37-J37 -> -0.6 | Q37: =N37-K37 -> -166.88492 | R37: =O37/L37 -> 0.91486361 | Z37: =SUM(Z27:Z36) -> 0 | AA37: =SUM(AA27:AA36) -> 0 | AD37: =SUM(AD27:AD36) -> 0 | AE37: =SUM(AE27:AE36) -> 0 | AF37: =N37-K37 -> -166.88492 | AG37: =N37/K37 -> 0.88514459
A38: 手工四線 (ET-55) | B38: 義大利麵 | D38: 濃拿坡里義大利麵 | F38: =VLOOKUP(D38,廠價表!$C$1:$E$41,3,0) -> 56.43 | G38: 1019 | H38: =F38*G38 -> 57502.17 | J38: =VLOOKUP(D38,產線配置圖!$A$3:$C$39,2,0) -> 16 | K38: =VLOOKUP(D38,產線配置圖!$A$3:$C$39,3,0) -> 1406 | L38: =K38/J38 -> 87.875 | M38: 15 | N38: =G38/W38*60 -> 1019 | O38: =N38/M38 -> 67.933333 | P38: =M38-J38 -> -1 | Q38: =O38-L38 -> -19.941667 | R38: =O38/L38 -> 0.7730678 | S38: =R48 -> 0.9174238 | T38: 0.33333333 | U38: 0.375 | W38: =(U38-T38)*24*60 -> 60 | AB38: 生產數量少 | AF38: =N38-K38 -> -387 | AG38: =N38/K38 -> 0.72475107 | AH38: =AG48 -> 0.87118983
B39: 熱乾麵 | D39: 青花椒麻雞肉拌麵 | F39: =VLOOKUP(D39,廠價表!$C$1:$E$41,3,0) -> 49.91 | G39: 1568 | H39: =F39*G39 -> 78258.88 | J39: =VLOOKUP(D39,產線配置圖!$A$3:$C$39,2,0) -> 17 | K39: =VLOOKUP(D39,產線配置圖!$A$3:$C$39,3,0) -> 1565 | L39: =K39/J39 -> 92.058824 | M39: 15 | N39: =G39/W39*60 -> 1344 | O39: =N39/M39 -> 89.6 | P39: =M39-J39 -> -2 | Q39: =O39-L39 -> -2.4588235 | R39: =O39/L39 -> 0.97329073 | T39: 0.38194444 | U39: 0.43055556 | V39: =(T39-U38)*24*60 -> 10 | W39: =(U39-T39)*24*60 -> 70 | AF39: =N39-K39 -> -221 | AG39: =N39/K39 -> 0.85878594
B40: 熱乾麵 | D40: 府城鹽水意麵 | F40: =VLOOKUP(D40,廠價表!$C$1:$E$41,3,0) -> 44.3 | G40: 1646 | H40: =F40*G40 -> 72917.8 | J40: =VLOOKUP(D40,產線配置圖!$A$3:$C$39,2,0) -> 17 | K40: =VLOOKUP(D40,產線配置圖!$A$3:$C$39,3,0) -> 1440 | L40: =K40/J40 -> 84.705882 | M40: 17 | N40: =G40/W40*60 -> 1410.8571 | O40: =N40/M40 -> 82.991597 | P40: =M40-J40 -> 0 | Q40: =O40-L40 -> -1.7142857 | R40: =O40/L40 -> 0.9797619 | T40: 0.44791667 | U40: 0.49652778 | V40: =(T40-U39)*24*60 -> 25 | W40: =(U40-T40)*24*60 -> 70 | AF40: =N40-K40 -> -29.142857 | AG40: =N40/K40 -> 0.9797619
...

Sheet 0202總
B1: 長家廠組合室生產人時性分析
B3: 日期 | D3: 46055 | F3: 訂單量 | G3: ='0202'!E1 -> 61832 | I3: 營業額 | J3: ='0202'!G1 -> 2986243.9
B4: 項目 | D4: 3 | F4: ➀ | H4: ➁ | J4: ③ | L4: 異常停線 | N4: 短暫停線
B5: 人時性 | D5: 組合室 | F5: 全溫層 | H5: 義大利麵 | J5: 袋裝小吃、義麵 | L5: 合計次數 | M5: 時間 | N5: 合計次數 | O5: 設備次數
D6: 排關平均 | F6: =AVERAGE(D13:J13) -> 114.20983 | H6: =AVERAGE(D13:H13,J13) -> 111.92669 | J6: =AVERAGE(I13) -> 127.90865 | L6: =SUM(D18:J18) -> 5 | M6: =SUM(D19:J19) -> 46 | N6: =SUM(D20:J20) -> 0 | O6: =SUM(D20:J20) -> 0
D7: 實績平均 | F7: =AVERAGE(D14:J14) -> 106.44299 | H7: =AVERAGE(D14:H14,J14) -> 104.66462 | J7: =AVERAGE(I14) -> 117.11321 | L7: =AVERAGE(K14:L14) -> #DIV/0! | M7: =AVERAGE(L14:M14) -> #DIV/0! | N7: =AVERAGE(M14:N14) -> #DIV/0! | O7: =AVERAGE(N14:O14) -> #DIV/0!
D8: 達成率平均 | F8: =F7/F6 -> 0.93199503 | H8: =H7/H6 -> 0.93511764 | J8: =J7/J6 -> 0.91560033 | L8: =AVERAGE(K15:L15) -> #DIV/0! | M8: =AVERAGE(L15:M15) -> #DIV/0! | N8: =AVERAGE(M15:N15) -> #DIV/0! | O8: =AVERAGE(N15:O15) -> #DIV/0!
J9: ※現行日本鮮食廠以達成率80%為基本(即為現行KPI)
B10: 溫層 | D10: 4度C-各編組展開
B11: 編組 | D11: 1 | E11: 2 | F11: 3 | G11: 4 | H11: 5 | I11: 6 | J11: 7
D12: 自動1線 | E12: 自動2線 | F12: 手工3線 | G12: 手工4線 | H12: 手工5線 | I12: 調理包1線 | J12: 調理包2線
B13: 人時性 | C13: 排關 | D13: =VALUE('0202'!L15) -> 130.84034 | E13: =VALUE('0202'!L26) -> 162.15812 | F13: =VALUE('0202'!L37) -> 89.696078 | G13: =VALUE('0202'!L48) -> 87.685049 | H13: =VALUE('0202'!L58) -> 88.680556 | I13: =VALUE('0202'!L69) -> 127.90865 | J13: ='0202'!L79 -> 112.5
C14: 實績 | D14: =VALUE('0202'!O15) -> 120.2835 | E14: =VALUE('0202'!O26) -> 138.61438 | F14: =VALUE('0202'!O37) -> 73.94805 | G14: =VALUE('0202'!O48) -> 79.323757 | H14: =VALUE('0202'!O58) -> 84.145205 | I14: =VALUE('0202'!O69) -> 117.11321 | J14: ='0202'!O79 -> 131.67284
C15: 達成率 | D15: =D14/D13 -> 0.91931509 | E15: =E14/E13 -> 0.85481 | F15: =F14/F13 -> 0.82442902 | G15: =G14/G13 -> 0.90464404 | H15: =H14/H13 -> 0.94885744 | I15: =I14/I13 -> 0.91560033 | J15: ='0202'!S70 -> 1.1704253
B16: 作業 時間 | C16: 開始 | D16: ='0202'!T5 -> 0.3125 | E16: ='0202'!T16 -> 0.29097222 | F16: ='0202'!T27 -> 0.29166667 | G16: ='0202'!T38 -> 0.33333333 | H16: ='0202'!T49 -> 0.29166667 | I16: ='0202'!T59 -> 0.29166667 | J16: ='0202'!T70 -> 0.36458333
C17: 結束 | D17: 0.64861111 | E17: 0.70486111 | F17: 0.69791667 | G17: 0.71875 | H17: 0.63680556 | I17: 0.61805556 | J17: 0.71875
B18: 產線異常 (5分鐘以上) | C18: 次數 | D18: ='0202'!Z15 -> 0 | E18: ='0202'!Z26 -> 0 | F18: ='0202'!Z37 -> 3 | G18: ='0202'!Z48 -> 0 | H18: ='0202'!Z58 -> 1 | I18: ='0202'!Z69 -> 1 | J18: ='0202'!AA79 -> 0
C19: 時間/分 | D19: ='0202'!AA15 -> 0 | E19: ='0202'!AA26 -> 0 | F19: ='0202'!AA37 -> 23 | G19: ='0202'!AA48 -> 0 | H19: ='0202'!AA58 -> 18 | I19: ='0202'!AA69 -> 5 | J19: ='0202'!AB79 -> 0
B20: 短暫停線 (5分鐘以下) | C20: 次數 | D20: ='0202'!AD15 -> 0 | E20: ='0202'!AD26 -> 0 | F20: ='0202'!AD37 -> 0 | G20: ='0202'!AD48 -> 0 | H20: ='0202'!AD58 -> 0 | I20: ='0202'!AD69 -> 0 | J20: ='0202'!AD79 -> 0
C21: 設備次數 | D21: ='0202'!AE15 -> 0 | E21: ='0202'!AE26 -> 0 | F21: ='0202'!AE37 -> 0 | G21: ='0202'!AE48 -> 0 | H21: ='0202'!AE58 -> 0 | I21: ='0202'!AE69 -> 0 | J21: ='0202'!AE79 -> 0
B22: 配置人數 | D22: =VALUE('0202'!M15) -> 15 | E22: =VALUE('0202'!M26) -> 13 | F22: =VALUE('0202'!M37) -> 15.666667 | G22: =VALUE('0202'!M48) -> 16.666667 | H22: =VALUE('0202'!M58) -> 17.5 | I22: =VALUE('0202'!M69) -> 12.25 | J22: ='0202'!M79 -> 5.5
B23: 主要應用設備 | D23: ET-600 | E23: ET-600 | F23: ET-55 | G23: ET-55 | H23: ET-55 | I23: 八爪機 | J23: 八爪機
B24: 次要應用設備 | H24: 封口機 | J24: 封口機
B25: 備註

Sheet 0202
A1: 長家廠4度C日報分析 | D1: 總生產量 | E1: =SUM(G5:G79) -> 61832 | F1: 營業額 | G1: =SUM(H5:H79) -> 2986243.9 | H1: 出勤人數 | I1: =M15+M26+M48+M58+M69+M79+M37 -> 95.583333 | J1: 產線配置圖 | M1: 生產實績 | P1: 人時性差異分析 | T1: 日報登錄 | Z1: 合計 次數 | AA1: 合計 時間/分 | AB1: 分析說明 | AD1: 合計 次數 | AE1: 合計 設備次數 | AF1: 產能差異分析
A2: 02月02日 星期一 | D2: 人時性 | E2: =AVERAGE(O15,O26,O37,O48,O58,O69,O79) -> 106.44299 | F2: 平均廠價 | G2: =G1/E1 -> 48.296091 | H2: 多次生產數 | I2: =COUNT(I5:I79) -> 0 | Z2: =Z15+Z26+Z37+Z48+Z58+Z69+Z79 -> 5 | AA2: =AA15+AA26+AA37+AA48+AA58+AA69+AA79 -> 46 | AD2: =AD15+AD26+AD37+AD48+AD58+AD69+AD79 -> 0 | AE2: =AE15+AE26+AE37+AE48+AE58+AE69+AE79 -> 0
A3: 線別 | B3: 品類 | D3: 品名 | F3: 廠價 | G3: 生產量 | H3: 營收 | I3: 多次 生產 | J3: 人數 | K3: 產能/時 | L3: 人時性 | M3: 人數 | N3: 產能/時 | O3: 人時性 | P3: 人數 | Q3: 人時性 | R3: 達成率 | S3: 達成率平均 | T3: 生產時間 | V3: 前置、換線時間/分 | W3: 稼動時間/分 | X3: 休息時間 | Z3: 產線異常統計 (5分鐘以上) | AD3: 短暫停線統計 (5分鐘以下) | AF3: 產能/時 | AG3: 達成率 | AH3: 達成率平均
T4: 開始 | U4: 結束 | X4: 開始 | Y4: 結束 | Z4: 次數 | AA4: 時間/分 | AD4: 總次數 | AE4: 設備因素(次數)
A5: 自動一線 (ET-600) | B5: 義大利麵 | D5: 韓式起司炸雞義大利麵 | F5: =VLOOKUP(D5,廠價表!$C$1:$E$41,3,0) -> 57.21 | G5: 1572 | H5: =F5*G5 -> 89934.12 | J5: =VLOOKUP(D5,產線配置圖!$A$3:$C$39,2,0) -> 17 | K5: =VLOOKUP(D5,產線配置圖!$A$3:$C$39,3,0) -> 2000 | L5: =K5/J5 -> 117.64706 | M5: 17 | N5: =G5/W5*60 -> 1626.2069 | O5: =N5/M5 -> 95.659229 | P5: =M5-J5 -> 0 | Q5: =O5-L5 -> -21.98783 | R5: =O5/L5 -> 0.81310345 | S5: =R15 -> 0.91931509 | T5: 0.3125 | U5: 0.35277778 | W5: =(U5-T5)*24*60 -> 58 | AF5: =N5-K5 -> -373.7931 | AG5: =N5/K5 -> 0.81310345 | AH5: =AG15 -> 0.91520418
B6: 義大利麵 | D6: 辣味香菜雞肉義大利麵 | F6: =VLOOKUP(D6,廠價表!$C$1:$E$41,3,0) -> 56.28 | G6: 2662 | H6: =F6*G6 -> 149817.36 | J6: =VLOOKUP(D6,產線配置圖!$A$3:$C$39,2,0) -> 15 | K6: =VLOOKUP(D6,產線配置圖!$A$3:$C$39,3,0) -> 1800 | L6: =K6/J6 -> 120 | M6: 15 | N6: =G6/W6*60 -> 1736.087 | O6: =N6/M6 -> 115.73913 | P6: =M6-J6 -> 0 | Q6: =O6-L6 -> -4.2608696 | R6: =O6/L6 -> 0.96449275 | T6: 0.36527778 | U6: 0.42916667 | V6: =(T6-U5)*24*60 -> 18 | W6: =(U6-T6)*24*60 -> 92 | AF6: =N6-K6 -> -63.913043 | AG6: =N6/K6 -> 0.96449275
B7: 義大利麵 | D7: 奶油培根義大利麵 | F7: =VLOOKUP(D7,廠價表!$C$1:$E$41,3,0) -> 49.14 | G7: 1497 | H7: =F7*G7 -> 73562.58 | J7: 14 | K7: =VLOOKUP(D7,產線配置圖!$A$3:$C$39,3,0) -> 2000 | L7: =K7/J7 -> 142.85714 | M7: 14 | N7: =G7/W7*60 -> 1911.0638 | O7: =N7/M7 -> 136.50456 | P7: =M7-J7 -> 0 | Q7: =O7-L7 -> -6.3525836 | R7: =O7/L7 -> 0.95553191 | T7: 0.44722222 | U7: 0.47986111 | V7: =(T7-U6)*24*60 -> 26 | W7: =(U7-T7)*24*60 -> 47 | AF7: =N7-K7 -> -88.93617 | AG7: =N7/K7 -> 0.95553191
B8: 義大利麵 | D8: 奶油培根義大利麵 | F8: =VLOOKUP(D8,廠價表!$C$1:$E$41,3,0) -> 49.14 | G8: 4632 | H8: =F8*G8 -> 227616.48 | J8: 14 | K8: =VLOOKUP(D8,產線配置圖!$A$3:$C$39,3,0) -> 2000 | L8: =K8/J8 -> 142.85714 | M8: 14 | N8: =G8/W8*60 -> 1865.2349 | O8: =N8/M8 -> 133.23106 | P8: =M8-J8 -> 0 | Q8: =O8-L8 -> -9.6260786 | R8: =O8/L8 -> 0.93261745 | T8: 0.54513889 | U8: 0.64861111 | V8: =(T8-U7)*24*60 -> 94 | W8: =(U8-T8)*24*60 -> 149 | X8: 0.48611111 | Y8: 0.52777778 | AF8: =N8-K8 -> -134.7651 | AG8: =N8/K8 -> 0.93261745
W9: =(U9-T9)*24*60 -> 0 | AF9: =N9-K9 -> 0 | AG9: =N9/K9 -> #DIV/0!
W10: =(U10-T10)*24*60 -> 0 | AF10: =N10-K10 -> 0 | AG10: =N10/K10 -> #DIV/0!
W11: =(U11-T11)*24*60 -> 0 | AF11: =N11-K11 -> 0 | AG11: =N11/K11 -> #DIV/0!
W12: =(U12-T12)*24*60 -> 0
W13: =(U13-T13)*24*60 -> 0
W14: =(U14-T14)*24*60 -> 0
C15: 4度一組 | D15: 平均 | J15: =AVERAGE(J5:J14) -> 15 | K15: =AVERAGE(K5:K14) -> 1950 | L15: =AVERAGE(L5:L14) -> 130.84034 | M15: =AVERAGE(M5:M14) -> 15 | N15: =AVERAGE(N5:N14) -> 1784.6481 | O15: =AVERAGE(O5:O14) -> 120.2835 | P15: =M15-J15 -> 0 | Q15: =O15-L15 -> -10.55684 | R15: =O15/L15 -> 0.91931509 | Z15: =SUM(Z5:Z14) -> 0 | AA15: =SUM(AA5:AA14) -> 0 | AD15: =SUM(AD5:AD14) -> 0 | AE15: =SUM(AE5:AE14) -> 0 | AF15: =N15-K15 -> -165.35185 | AG15: =N15/K15 -> 0.91520418
A16: 自動二線 (ET-600) | B16: 義大利麵 | D16: 白酒蛤蜊義大利麵 | F16: =VLOOKUP(D16,廠價表!$C$1:$E$41,3,0) -> 57.21 | G16: 1867 | H16: =F16*G16 -> 106811.07 | J16: 13 | K16: =VLOOKUP(D16,產線配置圖!$A$3:$C$39,3,0) -> 2105 | L16: =K16/J16 -> 161.92308 | M16: 13 | N16: =G16/W16*60 -> 1898.6441 | O16: =N16/M16 -> 146.04954 | P16: =M16-J16 -> 0 | Q16: =O16-L16 -> -15.873533 | R16: =O16/L16 -> 0.90196868 | S16: =R26 -> 0.85481 | T16: 0.29097222 | U16: 0.33194444 | W16: =(U16-T16)*24*60 -> 59 | AB16: 手抓麵(06:59~07:20) | AF16: =N16-K16 -> -206.35593 | AG16: =N16/K16 -> 0.90196868 | AH16: =AG26 -> 0.87090426
B17: 義大利麵 | D17: 青醬蛤蜊義大利麵 | F17: =VLOOKUP(D17,廠價表!$C$1:$E$41,3,0) -> 50.67 | G17: 3872 | H17: =F17*G17 -> 196194.24 | J17: 13 | K17: =VLOOKUP(D17,產線配置圖!$A$3:$C$39,3,0) -> 2000 | L17: =K17/J17 -> 153.84615 | M17: 13 | N17: =G17/W17*60 -> 1787.0769 | O17: =N17/M17 -> 137.46746 | P17: =M17-J17 -> 0 | Q17: =O17-L17 -> -16.378698 | R17: =O17/L17 -> 0.89353846 | T17: 0.34027778 | U17: 0.43055556 | V17: =(T17-U16)*24*60 -> 12 | W17: =(U17-T17)*24*60 -> 130 | AF17: =N17-K17 -> -212.92308 | AG17: =N17/K17 -> 0.89353846
B18: 義大利麵 | D18: 義式蕃茄起司義大利麵 | F18: =VLOOKUP(D18,廠價表!$C$1:$E$41,3,0) -> 50.39 | G18: 1722 | H18: =F18*G18 -> 86771.58 | J18: 12 | K18: =VLOOKUP(D18,產線配置圖!$A$3:$C$39,3,0) -> 2000 | L18: =K18/J18 -> 166.66667 | M18: 12 | N18: =G18/W18*60 -> 1751.1864 | O18: =N18/M18 -> 145.9322 | P18: =M18-J18 -> 0 | Q18: =O18-L18 -> -20.734463 | R18: =O18/L18 -> 0.87559322 | T18: 0.43611111 | U18: 0.47708333 | V18: =(T18-U17)*24*60 -> 8 | W18: =(U18-T18)*24*60 -> 59 | AF18: =N18-K18 -> -248.81356 | AG18: =N18/K18 -> 0.87559322
B19: 義大利麵 | D19: 義式蕃茄起司義大利麵 | F19: =VLOOKUP(D19,廠價表!$C$1:$E$41,3,0) -> 50.39 | G19: 3520 | H19: =F19*G19 -> 177372.8 | J19: 12 | K19: =VLOOKUP(D19,產線配置圖!$A$3:$C$39,3,0) -> 2000 | L19: =K19/J19 -> 166.66667 | M19: 12 | N19: =G19/W19*60 -> 1717.0732 | O19: =N19/M19 -> 143.08943 | P19: =M19-J19 -> 0 | Q19: =O19-L19 -> -23.577236 | R19: =O19/L19 -> 0.85853659 | T19: 0.54513889 | U19: 0.63055556 | V19: =(T19-U18)*24*60 -> 98 | W19: =(U19-T19)*24*60 -> 123 | X19: 0.48611111 | Y19: 0.52777778 | AF19: =N19-K19 -> -282.92683 | AG19: =N19/K19 -> 0.85853659
B20: 義大利麵 | D20: 白酒蛤蜊義大利麵 | F20: =VLOOKUP(D20,廠價表!$C$1:$E$41,3,0) -> 57.21 | G20: 708 | H20: =F20*G20 -> 40504.68 | J20: 13 | K20: =VLOOKUP(D20,產線配置圖!$A$3:$C$39,3,0) -> 2105 | L20: =K20/J20 -> 161.92308 | M20: 15 | N20: =G20/W20*60 -> 1517.1429 | O20: =N20/M20 -> 101.14286 | P20: =M20-J20 -> 2 | Q20: =O20-L20 -> -60.78022 | R20: =O20/L20 -> 0.62463522 | T20: 0.63888889 | U20: 0.65833333 | V20: =(T20-U19)*24*60 -> 12 | W20: =(U20-T20)*24*60 -> 28 | AB20: 手抓麵
B21: 義大利麵 | D21: 白酒蛤蜊義大利麵 | F21: =VLOOKUP(D21,廠價表!$C$1:$E$41,3,0) -> 57.21 | G21: 2191 | H21: =F21*G21 -> 125347.11 | J21: 13 | K21: =VLOOKUP(D21,產線配置圖!$A$3:$C$39,3,0) -> 2105 | L21: =K21/J21 -> 161.92308 | M21: 13 | N21: =G21/W21*60 -> 2054.0625 | O21: =N21/M21 -> 158.00481 | P21: =M21-J21 -> 0 | Q21: =O21-L21 -> -3.9182692 | R21: =O21/L21 -> 0.97580166 | T21: 0.66041667 | U21: 0.70486111 | V21: =(T21-U20)*24*60 -> 3 | W21: =(U21-T21)*24*60 -> 64
W22: =(U22-T22)*24*60 -> 0
W23: =(U23-T23)*24*60 -> 0
H24: =F24*G24 -> 0 | W24: =(U24-T24)*24*60 -> 0
H25: =F25*G25 -> 0 | W25: =(U25-T25)*24*60 -> 0
C26: 4度二組A | D26: 平均 | J26: =AVERAGE(J16:J25) -> 12.666667 | K26: =AVERAGE(K16:K25) -> 2052.5 | L26: =AVERAGE(L16:L25) -> 162.15812 | M26: =AVERAGE(M16:M25) -> 13 | N26: =AVERAGE(N16:N25) -> 1787.531 | O26: =AVERAGE(O16:O25) -> 138.61438 | P26: =M26-J26 -> 0.33333333 | Q26: =O26-L26 -> -23.543737 | R26: =O26/L26 -> 0.85481 | Z26: =SUM(Z16:Z25) -> 0 | AA26: =SUM(AA16:AA25) -> 0 | AD26: =SUM(AD16:AD25) -> 0 | AE26: =SUM(AE16:AE25) -> 0 | AF26: =N26-K26 -> -264.96901 | AG26: =N26/K26 -> 0.87090426
A27: 手工三線 (ET-55) | B27: 義大利麵 | D27: 惡魔乳酪生義大利麵 | F27: =VLOOKUP(D27,廠價表!$C$1:$E$41,3,0) -> 57.3 | G27: 2180 | H27: =F27*G27 -> 124914 | J27: =VLOOKUP(D27,產線配置圖!$A$3:$C$39,2,0) -> 17 | K27: =VLOOKUP(D27,產線配置圖!$A$3:$C$39,3,0) -> 1500 | L27: =K27/J27 -> 88.235294 | M27: 16 | N27: =G27/W27*60 -> 1348.4536 | O27: =N27/M27 -> 84.278351 | P27: =M27-J27 -> -1 | Q27: =O27-L27 -> -3.9569436 | R27: =O27/L27 -> 0.95515464 | S27: =R37 -> 0.82442902 | T27: 0.29166667 | U27: 0.35902778 | W27: =(U27-T27)*24*60 -> 97 | Z27: 1 | AA27: 7 | AB27: 熱轉印異常 | AF27: =N27-K27 -> -151.54639 | AG27: =N27/K27 -> 0.89896907 | AH27: =AG37 -> 0.79374518
B28: 義大利麵 | D28: 奶油蒜香雞義大利麵 | F28: =VLOOKUP(D28,廠價表!$C$1:$E$41,3,0) -> 55.13 | G28: 1785 | H28: =F28*G28 -> 98407.05 | J28: =VLOOKUP(D28,產線配置圖!$A$3:$C$39,2,0) -> 17 | K28: =VLOOKUP(D28,產線配置圖!$A$3:$C$39,3,0) -> 1385 | L28: =K28/J28 -> 81.470588 | M28: 16 | N28: =G28/W28*60 -> 1151.6129 | O28: =N28/M28 -> 71.975806 | P28: =M28-J28 -> -1 | Q28: =O28-L28 -> -9.4947818 | R28: =O28/L28 -> 0.88345755 | T28: 0.36597222 | U28: 0.43055556 | V28: =(T28-U27)*24*60 -> 10 | W28: =(U28-T28)*24*60 -> 93 | AF28: =N28-K28 -> -233.3871 | AG28: =N28/K28 -> 0.83148946
B29: 義大利麵 | D29: 惡魔乳酪生義大利麵 | F29: =VLOOKUP(D29,廠價表!$C$1:$E$41,3,0) -> 57.3 | G29: 912 | H29: =F29*G29 -> 52257.6 | J29: =VLOOKUP(D29,產線配置圖!$A$3:$C$39,2,0) -> 17 | K29: =VLOOKUP(D29,產線配置圖!$A$3:$C$39,3,0) -> 1500 | L29: =K29/J29 -> 88.235294 | M29: 16 | N29: =G29/W29*60 -> 1189.5652 | O29: =N29/M29 -> 74.347826 | P29: =M29-J29 -> -1 | Q29: =O29-L29 -> -13.887468 | R29: =O29/L29 -> 0.8426087 | T29: 0.44444444 | U29: 0.47638889 | V29: =(T29-U28)*24*60 -> 20 | W29: =(U29-T29)*24*60 -> 46 | AF29: =N29-K29 -> -310.43478 | AG29: =N29/K29 -> 0.79304348
B30: 熱乾麵 | D30: 沙茶豬肉炒麵 | F30: =VLOOKUP(D30,廠價表!$C$1:$E$41,3,0) -> 49.52 | G30: 933 | H30: =F30*G30 -> 46202.16 | J30: =VLOOKUP(D30,產線配置圖!$A$3:$C$39,2,0) -> 15 | K30: =VLOOKUP(D30,產線配置圖!$A$3:$C$39,3,0) -> 1440 | L30: =K30/J30 -> 96 | M30: 15 | N30: =G30/W30*60 -> 1216.9565 | O30: =N30/M30 -> 81.130435 | P30: =M30-J30 -> 0 | Q30: =O30-L30 -> -14.869565 | R30: =O30/L30 -> 0.8451087 | T30: 0.48194444 | U30: 0.51388889 | V30: =(T30-U29)*24*60 -> 8 | W30: =(U30-T30)*24*60 -> 46 | AF30: =N30-K30 -> -223.04348 | AG30: =N30/K30 -> 0.8451087
B31: 熱乾麵 | D31: 沙茶豬肉炒麵 | F31: =VLOOKUP(D31,廠價表!$C$1:$E$41,3,0) -> 49.52 | G31: 1290 | H31: =F31*G31 -> 63880.8 | J31: =VLOOKUP(D31,產線配置圖!$A$3:$C$39,2,0) -> 15 | K31: =VLOOKUP(D31,產線配置圖!$A$3:$C$39,3,0) -> 1440 | L31: =K31/J31 -> 96 | M31: 15 | N31: =G31/W31*60 -> 910.58824 | O31: =N31/M31 -> 60.705882 | P31: =M31-J31 -> 0 | Q31: =O31-L31 -> -35.294118 | R31: =O31/L31 -> 0.63235294 | T31: 0.60763889 | U31: 0.66666667 | V31: =(T31-U30)*24*60 -> 135 | W31: =(U31-T31)*24*60 -> 85 | X31: 0.52083333 | Y31: 0.5625 | Z31: 2 | AA31: 16 | AB31: 封膜機異常、13:50-14:28試產 | AF31: =N31-K31 -> -529.41176 | AG31: =N31/K31 -> 0.63235294
B32: 義大利麵 | D32: 惡魔乳酪生義大利麵 | F32: =VLOOKUP(D32,廠價表!$C$1:$E$41,3,0) -> 57.3 | G32: 703 | H32: =F32*G32 -> 40281.9 | J32: =VLOOKUP(D32,產線配置圖!$A$3:$C$39,2,0) -> 17 | K32: =VLOOKUP(D32,產線配置圖!$A$3:$C$39,3,0) -> 1500 | L32: =K32/J32 -> 88.235294 | M32: 16 | N32: =G32/W32*60 -> 1140 | O32: =N32/M32 -> 71.25 | P32: =M32-J32 -> -1 | Q32: =O32-L32 -> -16.985294 | R32: =O32/L32 -> 0.8075 | T32: 0.67222222 | U32: 0.69791667 | V32: =(T32-U31)*24*60 -> 8 | W32: =(U32-T32)*24*60 -> 37
W33: =(U33-T33)*24*60 -> 0
W34: =(U34-T34)*24*60 -> 0
W35: =(U35-T35)*24*60 -> 0
H36: =F36*G36 -> 0 | W36: =(U36-T36)*24*60 -> 0
C37: 4度二組B | D37: 平均 | J37: =AVERAGE(J27:J36) -> 16.333333 | K37: =AVERAGE(K27:K36) -> 1460.8333 | L37: =AVERAGE(L27:L36) -> 89.696078 | M37: =AVERAGE(M27:M36) -> 15.666667 | N37: =AVERAGE(N27:N36) -> 1159.5294 | O37: =AVERAGE(O27:O36) -> 73.94805 | P37: =M37-J37 -> -0.66666667 | Q37: =N37-K37 -> -301.30392 | R37: =O37/L37 -> 0.82442902 | Z37: =SUM(Z27:Z36) -> 3 | AA37: =SUM(AA27:AA36) -> 23 | AD37: =SUM(AD27:AD36) -> 0 | AE37: =SUM(AE27:AE36) -> 0 | AF37: =N37-K37 -> -301.30392 | AG37: =N37/K37 -> 0.79374518
A38: 手工四線 (ET-55) | B38: 義大利麵 | D38: 濃拿坡里義大利麵 | F38: =VLOOKUP(D38,廠價表!$C$1:$E$41,3,0) -> 56.43 | G38: 1259 | H38: =F38*G38 -> 71045.37 | J38: =VLOOKUP(D38,產線配置圖!$A$3:$C$39,2,0) -> 16 | K38: =VLOOKUP(D38,產線配置圖!$A$3:$C$39,3,0) -> 1406 | L38: =K38/J38 -> 87.875 | M38: 15 | N38: =G38/W38*60 -> 1110.8824 | O38: =N38/M38 -> 74.058824 | P38: =M38-J38 -> -1 | Q38: =O38-L38 -> -13.816176 | R38: =O38/L38 -> 0.84277466 | S38: =R48 -> 0.90464404 | T38: 0.33333333 | U38: 0.38055556 | W38: =(U38-T38)*24*60 -> 68 | AF38: =N38-K38 -> -295.11765 | AG38: =N38/K38 -> 0.79010125 | AH38: =AG48 -> 0.89689539
B39: 熱乾麵 | D39: 青花椒麻雞肉拌麵 | F39: =VLOOKUP(D39,廠價表!$C$1:$E$41,3,0) -> 49.91 | G39: 1502 | H39: =F39*G39 -> 74964.82 | J39: =VLOOKUP(D39,產線配置圖!$A$3:$C$39,2,0) -> 17 | K39: =VLOOKUP(D39,產線配置圖!$A$3:$C$39,3,0) -> 1565 | L39: =K39/J39 -> 92.058824 | M39: 17 | N39: =G39/W39*60 -> 1345.0746 | O39: =N39/M39 -> 79.122037 | P39: =M39-J39 -> 0 | Q39: =O39-L39 -> -12.936787 | R39: =O39/L39 -> 0.85947261 | T39: 0.3875 | U39: 0.43402778 | V39: =(T39-U38)*24*60 -> 10 | W39: =(U39-T39)*24*60 -> 67 | AF39: =N39-K39 -> -219.92537 | AG39: =N39/K39 -> 0.85947261
B40: 熱乾麵 | D40: 府城鹽水意麵 | F40: =VLOOKUP(D40,廠價表!$C$1:$E$41,3,0) -> 44.3 | G40: 1683 | H40: =F40*G40 -> 74556.9 | J40: =VLOOKUP(D40,產線配置圖!$A$3:$C$39,2,0) -> 17 | K40: =VLOOKUP(D40,產線配置圖!$A$3:$C$39,3,0) -> 1440 | L40: =K40/J40 -> 84.705882 | M40: 17 | N40: =G40/W40*60 -> 1311.4286 | O40: =N40/M40 -> 77.142857 | P40: =M40-J40 -> 0 | Q40: =O40-L40 -> -7.5630252 | R40: =O40/L40 -> 0.91071429 | T40: 0.44791667 | U40: 0.50138889 | V40: =(T40-U39)*24*60 -> 20 | W40: =(U40-T40)*24*60 -> 77 | AF40: =N40-K40 -> -128.57143 | AG40: =N40/K40 -> 0.91071429
...

Sheet 0203總
B1: 長家廠組合室生產人時性分析
B3: 日期 | D3: 46056 | F3: 訂單量 | G3: ='0203'!E1 -> 58371 | I3: 營業額 | J3: ='0203'!G1 -> 2797918.5
B4: 項目 | D4: 3 | F4: ➀ | H4: ➁ | J4: ③ | L4: 異常停線 | N4: 短暫停線
B5: 人時性 | D5: 組合室 | F5: 全溫層 | H5: 義大利麵 | J5: 袋裝小吃、義麵 | L5: 合計次數 | M5: 時間 | N5: 合計次數 | O5: 設備次數
D6: 排關平均 | F6: =AVERAGE(D13:J13) -> 118.18497 | H6: =AVERAGE(D13:H13,J13) -> 116.56436 | J6: =AVERAGE(I13) -> 127.90865 | L6: =SUM(D18:J18) -> 2 | M6: =SUM(D19:J19) -> 10 | N6: =SUM(D20:J20) -> 11 | O6: =SUM(D20:J20) -> 11
D7: 實績平均 | F7: =AVERAGE(D14:J14) -> 107.0513 | H7: =AVERAGE(D14:H14,J14) -> 106.18528 | J7: =AVERAGE(I14) -> 112.24741 | L7: =AVERAGE(K14:L14) -> #DIV/0! | M7: =AVERAGE(L14:M14) -> #DIV/0! | N7: =AVERAGE(M14:N14) -> #DIV/0! | O7: =AVERAGE(N14:O14) -> #DIV/0!
D8: 達成率平均 | F8: =F7/F6 -> 0.90579449 | H8: =H7/H6 -> 0.91095837 | J8: =J7/J6 -> 0.87755917 | L8: =AVERAGE(K15:L15) -> #DIV/0! | M8: =AVERAGE(L15:M15) -> #DIV/0! | N8: =AVERAGE(M15:N15) -> #DIV/0! | O8: =AVERAGE(N15:O15) -> #DIV/0!
J9: ※現行日本鮮食廠以達成率80%為基本(即為現行KPI)
B10: 溫層 | D10: 4度C-各編組展開
B11: 編組 | D11: 1 | E11: 2 | F11: 3 | G11: 4 | H11: 5 | I11: 6 | J11: 7
D12: 自動1線 | E12: 自動2線 | F12: 手工3線 | G12: 手工4線 | H12: 手工5線 | I12: 調理包1線 | J12: 調理包2線
B13: 人時性 | C13: 排關 | D13: =VALUE('0203'!L15) -> 144.15121 | E13: =VALUE('0203'!L26) -> 176.22727 | F13: =VALUE('0203'!L37) -> 89.282353 | G13: =VALUE('0203'!L48) -> 88.280882 | H13: =VALUE('0203'!L58) -> 88.944444 | I13: =VALUE('0203'!L69) -> 127.90865 | J13: ='0203'!L79 -> 112.5
C14: 實績 | D14: =VALUE('0203'!O15) -> 134.15063 | E14: =VALUE('0203'!O26) -> 156.90349 | F14: =VALUE('0203'!O37) -> 81.02552 | G14: =VALUE('0203'!O48) -> 81.85962 | H14: =VALUE('0203'!O58) -> 86.95423 | I14: =VALUE('0203'!O69) -> 112.24741 | J14: ='0203'!O79 -> 96.218182
C15: 達成率 | D15: =D14/D13 -> 0.93062443 | E15: =E14/E13 -> 0.89034736 | F15: =F14/F13 -> 0.90751999 | G15: =G14/G13 -> 0.92726328 | H15: =H14/H13 -> 0.97762407 | I15: =I14/I13 -> 0.87755917 | J15: ='0203'!S70 -> 0.85527273
B16: 作業 時間 | C16: 開始 | D16: ='0203'!T5 -> 0.31597222 | E16: ='0203'!T16 -> 0.29027778 | F16: ='0203'!T27 -> 0.29166667 | G16: ='0203'!T38 -> 0.33333333 | H16: ='0203'!T49 -> 0.29027778 | I16: ='0203'!T59 -> 0.29166667 | J16: ='0203'!T70 -> 0.37152778
C17: 結束 | D17: 0.68472222 | E17: 0.68055556 | F17: 0.60416667 | G17: 0.68888889 | H17: 0.62777778 | I17: 0.61111111 | J17: 0.48611111
B18: 產線異常 (5分鐘以上) | C18: 次數 | D18: ='0203'!Z15 -> 0 | E18: ='0203'!Z26 -> 0 | F18: ='0203'!Z37 -> 0 | G18: ='0203'!Z48 -> 0 | H18: ='0203'!Z58 -> 2 | I18: ='0203'!Z69 -> 0 | J18: ='0203'!AA79 -> 0
C19: 時間/分 | D19: ='0203'!AA15 -> 0 | E19: ='0203'!AA26 -> 0 | F19: ='0203'!AA37 -> 0 | G19: ='0203'!AA48 -> 0 | H19: ='0203'!AA58 -> 10 | I19: ='0203'!AA69 -> 0 | J19: ='0203'!AB79 -> 0
B20: 短暫停線 (5分鐘以下) | C20: 次數 | D20: ='0203'!AD15 -> 0 | E20: ='0203'!AD26 -> 11 | F20: ='0203'!AD37 -> 0 | G20: ='0203'!AD48 -> 0 | H20: ='0203'!AD58 -> 0 | I20: ='0203'!AD69 -> 0 | J20: ='0203'!AD79 -> 0
C21: 設備次數 | D21: ='0203'!AE15 -> 0 | E21: ='0203'!AE26 -> 11 | F21: ='0203'!AE37 -> 0 | G21: ='0203'!AE48 -> 0 | H21: ='0203'!AE58 -> 0 | I21: ='0203'!AE69 -> 0 | J21: ='0203'!AE79 -> 0
B22: 配置人數 | D22: =VALUE('0203'!M15) -> 14 | E22: =VALUE('0203'!M26) -> 11.6 | F22: =VALUE('0203'!M37) -> 15 | G22: =VALUE('0203'!M48) -> 15.4 | H22: =VALUE('0203'!M58) -> 17.2 | I22: =VALUE('0203'!M69) -> 12.25 | J22: ='0203'!M79 -> 10
B23: 主要應用設備 | D23: ET-600 | E23: ET-600 | F23: ET-55 | G23: ET-55 | H23: ET-55 | I23: 八爪機 | J23: 八爪機
B24: 次要應用設備 | H24: 封口機 | J24: 封口機
B25: 備註

Sheet 0203
A1: 長家廠4度C日報分析 | D1: 總生產量 | E1: =SUM(G5:G79) -> 58371 | F1: 營業額 | G1: =SUM(H5:H79) -> 2797918.5 | H1: 出勤人數 | I1: =M15+M26+M48+M58+M69+M79+M37 -> 95.45 | J1: 產線配置圖 | M1: 生產實績 | P1: 人時性差異分析 | T1: 日報登錄 | Z1: 合計 次數 | AA1: 合計 時間/分 | AB1: 分析說明 | AD1: 合計 次數 | AE1: 合計 設備次數 | AF1: 產能差異分析
A2: 02月03日 星期二 | D2: 人時性 | E2: =AVERAGE(O15,O26,O37,O48,O58,O69,O79) -> 107.0513 | F2: 平均廠價 | G2: =G1/E1 -> 47.933367 | H2: 多次生產數 | I2: =COUNT(I5:I79) -> 0 | Z2: =Z15+Z26+Z37+Z48+Z58+Z69+Z79 -> 2 | AA2: =AA15+AA26+AA37+AA48+AA58+AA69+AA79 -> 10 | AD2: =AD15+AD26+AD37+AD48+AD58+AD69+AD79 -> 11 | AE2: =AE15+AE26+AE37+AE48+AE58+AE69+AE79 -> 11
A3: 線別 | B3: 品類 | D3: 品名 | F3: 廠價 | G3: 生產量 | H3: 營收 | I3: 多次 生產 | J3: 人數 | K3: 產能/時 | L3: 人時性 | M3: 人數 | N3: 產能/時 | O3: 人時性 | P3: 人數 | Q3: 人時性 | R3: 達成率 | S3: 達成率平均 | T3: 生產時間 | V3: 前置、換線時間/分 | W3: 稼動時間/分 | X3: 休息時間 | Z3: 產線異常統計 (5分鐘以上) | AD3: 短暫停線統計 (5分鐘以下) | AF3: 產能/時 | AG3: 達成率 | AH3: 達成率平均
T4: 開始 | U4: 結束 | X4: 開始 | Y4: 結束 | Z4: 次數 | AA4: 時間/分 | AD4: 總次數 | AE4: 設備因素(次數)
A5: 自動一線 (ET-600) | B5: 義大利麵 | D5: 韓式起司炸雞義大利麵 | F5: =VLOOKUP(D5,廠價表!$C$1:$E$41,3,0) -> 57.21 | G5: 1439 | H5: =F5*G5 -> 82325.19 | J5: =VLOOKUP(D5,產線配置圖!$A$3:$C$39,2,0) -> 17 | K5: =VLOOKUP(D5,產線配置圖!$A$3:$C$39,3,0) -> 2000 | L5: =K5/J5 -> 117.64706 | M5: 17 | N5: =G5/W5*60 -> 1660.3846 | O5: =N5/M5 -> 97.669683 | P5: =M5-J5 -> 0 | Q5: =O5-L5 -> -19.977376 | R5: =O5/L5 -> 0.83019231 | S5: =R15 -> 0.93062443 | T5: 0.31597222 | U5: 0.35208333 | W5: =(U5-T5)*24*60 -> 52 | AF5: =N5-K5 -> -339.61538 | AG5: =N5/K5 -> 0.83019231 | AH5: =AG15 -> 0.9266961
B6: 義大利麵 | D6: 辣味香菜雞肉義大利麵 | F6: =VLOOKUP(D6,廠價表!$C$1:$E$41,3,0) -> 56.28 | G6: 2036 | H6: =F6*G6 -> 114586.08 | J6: =VLOOKUP(D6,產線配置圖!$A$3:$C$39,2,0) -> 15 | K6: =VLOOKUP(D6,產線配置圖!$A$3:$C$39,3,0) -> 1800 | L6: =K6/J6 -> 120 | M6: 15 | N6: =G6/W6*60 -> 1745.1429 | O6: =N6/M6 -> 116.34286 | P6: =M6-J6 -> 0 | Q6: =O6-L6 -> -3.6571429 | R6: =O6/L6 -> 0.96952381 | T6: 0.36111111 | U6: 0.40972222 | V6: =(T6-U5)*24*60 -> 13 | W6: =(U6-T6)*24*60 -> 70 | AF6: =N6-K6 -> -54.857143 | AG6: =N6/K6 -> 0.96952381
B7: 義大利麵 | D7: 奶油培根義大利麵 | F7: =VLOOKUP(D7,廠價表!$C$1:$E$41,3,0) -> 49.14 | G7: 2401 | H7: =F7*G7 -> 117985.14 | J7: =VLOOKUP(D7,產線配置圖!$A$3:$C$39,2,0) -> 13 | K7: =VLOOKUP(D7,產線配置圖!$A$3:$C$39,3,0) -> 2000 | L7: =K7/J7 -> 153.84615 | M7: 13 | N7: =G7/W7*60 -> 1973.4247 | O7: =N7/M7 -> 151.8019 | P7: =M7-J7 -> 0 | Q7: =O7-L7 -> -2.0442571 | R7: =O7/L7 -> 0.98671233 | T7: 0.425 | U7: 0.47569444 | V7: =(T7-U6)*24*60 -> 22 | W7: =(U7-T7)*24*60 -> 73 | AF7: =N7-K7 -> -26.575342 | AG7: =N7/K7 -> 0.98671233
B8: 義大利麵 | D8: 奶油培根義大利麵 | F8: =VLOOKUP(D8,廠價表!$C$1:$E$41,3,0) -> 49.14 | G8: 3445 | H8: =F8*G8 -> 169287.3 | J8: =VLOOKUP(D8,產線配置圖!$A$3:$C$39,2,0) -> 13 | K8: =VLOOKUP(D8,產線配置圖!$A$3:$C$39,3,0) -> 2000 | L8: =K8/J8 -> 153.84615 | M8: 13 | N8: =G8/W8*60 -> 1829.2035 | O8: =N8/M8 -> 140.70796 | P8: =M8-J8 -> 0 | Q8: =O8-L8 -> -13.138189 | R8: =O8/L8 -> 0.91460177 | T8: 0.55069444 | U8: 0.62916667 | V8: =(T8-U7)*24*60 -> 108 | W8: =(U8-T8)*24*60 -> 113 | X8: 0.48611111 | Y8: 0.52777778 | AF8: =N8-K8 -> -170.79646 | AG8: =N8/K8 -> 0.91460177
B9: 義大利麵 | D9: 白酒蛤蜊義大利麵 | F9: =VLOOKUP(D9,廠價表!$C$1:$E$41,3,0) -> 57.21 | G9: 1708 | H9: =F9*G9 -> 97714.68 | J9: =VLOOKUP(D9,產線配置圖!$A$3:$C$39,2,0) -> 12 | K9: =VLOOKUP(D9,產線配置圖!$A$3:$C$39,3,0) -> 2105 | L9: =K9/J9 -> 175.41667 | M9: 12 | N9: =G9/W9*60 -> 1970.7692 | O9: =N9/M9 -> 164.23077 | P9: =M9-J9 -> 0 | Q9: =O9-L9 -> -11.185897 | R9: =O9/L9 -> 0.93623241 | T9: 0.64861111 | U9: 0.68472222 | V9: =(T9-U8)*24*60 -> 28 | W9: =(U9-T9)*24*60 -> 52 | AF9: =N9-K9 -> -134.23077 | AG9: =N9/K9 -> 0.93623241
W10: =(U10-T10)*24*60 -> 0
W11: =(U11-T11)*24*60 -> 0
W12: =(U12-T12)*24*60 -> 0
W13: =(U13-T13)*24*60 -> 0
W14: =(U14-T14)*24*60 -> 0
C15: 4度一組 | D15: 平均 | J15: =AVERAGE(J5:J14) -> 14 | K15: =AVERAGE(K5:K14) -> 1981 | L15: =AVERAGE(L5:L14) -> 144.15121 | M15: =AVERAGE(M5:M14) -> 14 | N15: =AVERAGE(N5:N14) -> 1835.785 | O15: =AVERAGE(O5:O14) -> 134.15063 | P15: =M15-J15 -> 0 | Q15: =O15-L15 -> -10.000572 | R15: =O15/L15 -> 0.93062443 | Z15: =SUM(Z5:Z14) -> 0 | AA15: =SUM(AA5:AA14) -> 0 | AD15: =SUM(AD5:AD14) -> 0 | AE15: =SUM(AE5:AE14) -> 0 | AF15: =N15-K15 -> -145.21502 | AG15: =N15/K15 -> 0.9266961
A16: 自動二線 (ET-600) | B16: 義大利麵 | D16: 白酒蛤蜊義大利麵 | F16: =VLOOKUP(D16,廠價表!$C$1:$E$41,3,0) -> 57.21 | G16: 2203 | H16: =F16*G16 -> 126033.63 | J16: =VLOOKUP(D16,產線配置圖!$A$3:$C$39,2,0) -> 12 | K16: =VLOOKUP(D16,產線配置圖!$A$3:$C$39,3,0) -> 2105 | L16: =K16/J16 -> 175.41667 | M16: 12 | N16: =G16/W16*60 -> 1915.6522 | O16: =N16/M16 -> 159.63768 | P16: =M16-J16 -> 0 | Q16: =O16-L16 -> -15.778986 | R16: =O16/L16 -> 0.91004854 | S16: =R26 -> 0.89034736 | T16: 0.29027778 | U16: 0.33819444 | W16: =(U16-T16)*24*60 -> 69 | AB16: 熱轉印鬆脫 | AD16: 1 | AE16: 1 | AF16: =N16-K16 -> -189.34783 | AG16: =N16/K16 -> 0.91004854 | AH16: =AG26 -> 0.89092733
B17: 義大利麵 | D17: 青醬蛤蜊義大利麵 | F17: =VLOOKUP(D17,廠價表!$C$1:$E$41,3,0) -> 50.67 | G17: 3651 | H17: =F17*G17 -> 184996.17 | J17: =VLOOKUP(D17,產線配置圖!$A$3:$C$39,2,0) -> 12 | K17: =VLOOKUP(D17,產線配置圖!$A$3:$C$39,3,0) -> 2000 | L17: =K17/J17 -> 166.66667 | M17: 12 | N17: =G17/W17*60 -> 1795.5738 | O17: =N17/M17 -> 149.63115 | P17: =M17-J17 -> 0 | Q17: =O17-L17 -> -17.035519 | R17: =O17/L17 -> 0.89778689 | T17: 0.34444444 | U17: 0.42916667 | V17: =(T17-U16)*24*60 -> 9 | W17: =(U17-T17)*24*60 -> 122 | AB17: 玉取機停麵 | AD17: 10 | AE17: 10 | AF17: =N17-K17 -> -204.42623 | AG17: =N17/K17 -> 0.89778689
B18: 義大利麵 | D18: 義式蕃茄起司義大利麵 | F18: =VLOOKUP(D18,廠價表!$C$1:$E$41,3,0) -> 50.39 | G18: 1825 | H18: =F18*G18 -> 91961.75 | J18: =VLOOKUP(D18,產線配置圖!$A$3:$C$39,2,0) -> 11 | K18: =VLOOKUP(D18,產線配置圖!$A$3:$C$39,3,0) -> 2000 | L18: =K18/J18 -> 181.81818 | M18: 11 | N18: =G18/W18*60 -> 1887.931 | O18: =N18/M18 -> 171.63009 | P18: =M18-J18 -> 0 | Q18: =O18-L18 -> -10.188088 | R18: =O18/L18 -> 0.94396552 | T18: 0.4375 | U18: 0.47777778 | V18: =(T18-U17)*24*60 -> 12 | W18: =(U18-T18)*24*60 -> 58 | AF18: =N18-K18 -> -112.06897 | AG18: =N18/K18 -> 0.94396552
B19: 義大利麵 | D19: 義式蕃茄起司義大利麵 | F19: =VLOOKUP(D19,廠價表!$C$1:$E$41,3,0) -> 50.39 | G19: 3994 | H19: =F19*G19 -> 201257.66 | J19: =VLOOKUP(D19,產線配置圖!$A$3:$C$39,2,0) -> 11 | K19: =VLOOKUP(D19,產線配置圖!$A$3:$C$39,3,0) -> 2000 | L19: =K19/J19 -> 181.81818 | M19: 11 | N19: =G19/W19*60 -> 1608.3221 | O19: =N19/M19 -> 146.2111 | P19: =M19-J19 -> 0 | Q19: =O19-L19 -> -35.607077 | R19: =O19/L19 -> 0.80416107 | T19: 0.55 | U19: 0.65347222 | V19: =(T19-U18)*24*60 -> 104 | W19: =(U19-T19)*24*60 -> 149 | X19: 0.48611111 | Y19: 0.52777778 | AF19: =N19-K19 -> -391.67785 | AG19: =N19/K19 -> 0.80416107
B20: 義大利麵 | D20: 白酒蛤蜊義大利麵 | F20: =VLOOKUP(D20,廠價表!$C$1:$E$41,3,0) -> 57.21 | G20: 850 | H20: =F20*G20 -> 48628.5 | J20: =VLOOKUP(D20,產線配置圖!$A$3:$C$39,2,0) -> 12 | K20: =VLOOKUP(D20,產線配置圖!$A$3:$C$39,3,0) -> 2105 | L20: =K20/J20 -> 175.41667 | M20: 12 | N20: =G20/W20*60 -> 1888.8889 | O20: =N20/M20 -> 157.40741 | P20: =M20-J20 -> 0 | Q20: =O20-L20 -> -18.009259 | R20: =O20/L20 -> 0.89733439 | T20: 0.66180556 | U20: 0.68055556 | V20: =(T20-U19)*24*60 -> 12 | W20: =(U20-T20)*24*60 -> 27 | AF20: =N20-K20 -> -216.11111 | AG20: =N20/K20 -> 0.89733439
W21: =(U21-T21)*24*60 -> 0
W22: =(U22-T22)*24*60 -> 0
W23: =(U23-T23)*24*60 -> 0
H24: =F24*G24 -> 0 | W24: =(U24-T24)*24*60 -> 0
H25: =F25*G25 -> 0 | W25: =(U25-T25)*24*60 -> 0
C26: 4度二組A | D26: 平均 | J26: =AVERAGE(J16:J25) -> 11.6 | K26: =AVERAGE(K16:K25) -> 2042 | L26: =AVERAGE(L16:L25) -> 176.22727 | M26: =AVERAGE(M16:M25) -> 11.6 | N26: =AVERAGE(N16:N25) -> 1819.2736 | O26: =AVERAGE(O16:O25) -> 156.90349 | P26: =M26-J26 -> 0 | Q26: =O26-L26 -> -19.323786 | R26: =O26/L26 -> 0.89034736 | Z26: =SUM(Z16:Z25) -> 0 | AA26: =SUM(AA16:AA25) -> 0 | AD26: =SUM(AD16:AD25) -> 11 | AE26: =SUM(AE16:AE25) -> 11 | AF26: =N26-K26 -> -222.7264 | AG26: =N26/K26 -> 0.89092733
A27: 手工三線 (ET-55) | B27: 義大利麵 | D27: 惡魔乳酪生義大利麵 | F27: =VLOOKUP(D27,廠價表!$C$1:$E$41,3,0) -> 57.3 | G27: 1888 | H27: =F27*G27 -> 108182.4 | J27: =VLOOKUP(D27,產線配置圖!$A$3:$C$39,2,0) -> 17 | K27: =VLOOKUP(D27,產線配置圖!$A$3:$C$39,3,0) -> 1500 | L27: =K27/J27 -> 88.235294 | M27: 17 | N27: =G27/W27*60 -> 1490.5263 | O27: =N27/M27 -> 87.678019 | P27: =M27-J27 -> 0 | Q27: =O27-L27 -> -0.55727554 | R27: =O27/L27 -> 0.99368421 | S27: =R37 -> 0.90751999 | T27: 0.29166667 | U27: 0.34444444 | W27: =(U27-T27)*24*60 -> 76 | AF27: =N27-K27 -> -9.4736842 | AG27: =N27/K27 -> 0.99368421 | AH27: =AG37 -> 0.84452747
