Workbook

Sheet 廠價表
A1: check | B1: 溫層 | C1: 品名 | D1: 類別 | E1: 廠價
B2: 4度C | C2: 奶油鮮蝦明太子細扁麵 | D2: 義大利麵 | E2: 57.21
B3: 4度C | C3: 白酒清炒鮮蛤義大利麵 | D3: 義大利麵 | E3: 56.87
B4: 4度C | C4: 義式蕃茄起司義大利麵 | D4: 義大利麵 | E4: 50.39
B5: 4度C | C5: 焗烤起司雙饗筆尖麵 | D5: 義大利麵 | E5: 49.97
B6: 4度C | C6: 奶油培根義大利麵 | D6: 義大利麵 | E6: 49.14
B7: 4度C | C7: 香煎魚排佐檸檬奶油義大利麵 | D7: 義大利麵 | E7: 58.17
B8: 4度C | C8: 青醬蛤蜊義大利麵 | D8: 義大利麵 | E8: 50.67
B9: 4度C | C9: 金沙豆腐義大利麵 | D9: 義大利麵 | E9: 49.91
B10: 4度C | C10: 黑松露野菇義大利麵 | D10: 義大利麵 | E10: 50.289
B11: 4度C | C11: 燻鴨佐白蘭地義大利麵 | D11: 義大利麵 | E11: 61.65
B12: 4度C | C12: 拿坡里燻腸義大利麵 | D12: 義大利麵 | E12: 52.21
B13: 4度C | C13: 羅馬黑胡椒起司義大利麵 | D13: 義大利麵 | E13: 50.67
... B19: 4度C | C19: 番茄蘑菇義大利麵 | D19: 義大利麵 | E19: 43.89
B20: 4度C | D20: 義大利麵
B21: 4度C | D21: 義大利麵
B22: 4度C | D22: 義大利麵
B23: 4度C | C23: 韓式炒冬粉 | D23: 小吃、微波 | E23: 28.26
B24: 4度C | C24: 小滷青蔬 | D24: 小吃、微波 | E24: 26.99
B25: 4度C | C25: 起司馬鈴薯 | D25: 小吃、微波 | E25: 28.26
B26: 4度C | C26: 麻辣雞心 | D26: 小吃、微波 | E26: 28.26
B46: 冷凍 | C46: 青醬蛤蜊義大利麵 | D46: 冷凍調理麵 | E46: 29.38
B47: 冷凍 | C47: 經典肉醬義大利麵 | D47: 冷凍調理麵 | E47: 29.38
B48: 冷凍 | C48: 奶油蘑菇培根義大利麵 | D48: 冷凍調理麵 | E48: 29.38
B49: 冷凍 | C49: 清炒蛤蜊義大利麵 | D49: 冷凍調理麵 | E49: 29.38
B50: 冷凍 | C50: 青醬乳酪筆尖麵 | D50: 冷凍調理麵 | E50: 29.38
B51: 冷凍 | C51: 辣蕃茄義大利麵 | D51: 冷凍調理麵 | E51: 29.38
B52: 冷凍 | D52: 冷凍調理麵
B53: 冷凍 | C53: 韓式起司義大利麵 | D53: 冷凍調理麵 | E53: 29.38
B54: 冷凍 | D54: 冷凍調理麵
B55: 冷凍 | C55: 和風明太子細扁麵 | D55: 冷凍調理麵 | E55: 29.38

Sheet 產線配置圖
A1: 品項 | B1: 人數 | C1: 產能 | E1: 人時 | G1: 備註
A2: 義大利麵
A3: 白酒清炒鮮蛤義大利麵 | B3: 14 | C3: 2250 | D3: ET-600 | E3: =C3/B3 -> 160.71429
A4: 白酒清炒鮮蛤義大利麵-手 | B4: 15 | C4: 1716 | D4: ET-55 | E4: =C4/B4 -> 114.4
A5: 青醬蛤蜊義大利麵 | B5: 13 | C5: 2250 | E5: =C5/B5 -> 173.07692
A6: 青醬蛤蜊義大利麵-手 | B6: 16 | C6: 1714 | E6: =C6/B6 -> 107.125
A7: 義式蕃茄起司義大利麵 | B7: 12 | C7: 2250 | E7: =C7/B7 -> 187.5
A8: 奶油培根義大利麵 | B8: 14 | C8: 2250 | E8: =C8/B8 -> 160.71429
A9: 燻鴨佐白蘭地義大利麵 | B9: 18 | C9: 1636 | E9: =C9/B9 -> 90.888889
A10: 蒜香奶油蝦蝦義大利麵-手 | B10: 17 | C10: 1716 | E10: =C10/B10 -> 100.94118
A11: 拿坡里燻腸義大利麵 | B11: 18 | C11: 1636 | E11: =C11/B11 -> 90.888889
A12: 香煎魚排佐檸檬奶油義大利麵 | B12: 13 | C12: 2250 | E12: =C12/B12 -> 173.07692
A13: 黑松露野菇義大利麵 | B13: 17 | C13: 1636 | E13: =C13/B13 -> 96.235294 | J13: 黑松露野菇義大利麵 | K13: 17 | L13: 1565 | N13: =L13/K13 -> 92.058824
A14: 青花椒麻雞肉拌麵 | B14: 16 | C14: 1714 | E14: =C14/B14 -> 107.125 | J14: 青花椒麻雞肉拌麵 | K14: 14 | L14: 1714 | N14: =L14/K14 -> 122.42857
A15: 焗烤起司雙饗筆尖麵 | B15: 16 | C15: 1800 | E15: =C15/B15 -> 112.5 | G15: 目前使用手工 | J15: 焗烤起司雙饗筆尖麵 | K15: 15 | L15: 1800 | N15: =L15/K15 -> 120
A16: 沙茶豬肉炒麵 | B16: 17 | C16: 1800 | E16: =C16/B16 -> 105.88235 | J16: 沙茶豬肉炒麵 | K16: 16 | L16: 1500 | N16: =L16/K16 -> 93.75
A17: 府城鹽水意麵 | B17: 18 | C17: 1636 | E17: =C17/B17 -> 90.888889 | J17: 府城鹽水意麵 | K17: 16 | L17: 1636 | N17: =L17/K17 -> 102.25
A18: 羅馬黑胡椒起司義大利麵 | B18: 17 | C18: 2250 | E18: =C18/B18 -> 132.35294 | J18: 焗烤起司肉醬筆尖麵 | K18: 12 | L18: 1440 | N18: =L18/K18 -> 120
A19: 羅馬黑胡椒起司義大利麵-自動 | B19: 14 | C19: 2250 | E19: =C19/B19 -> 160.71429 | G19: 目前使用雙排 | J19: 整條德式香腸義大利麵 | K19: 16 | L19: 1565 | N19: =L19/K19 -> 97.8125
A20: 義式蛋蛋青醬鮪魚冷義大利麵 | B20: 17 | C20: 1636 | E20: =C20/B20 -> 96.235294
A21: 蕃茄莎莎海鮮冷義大利麵 | B21: 16 | C21: 1636 | E21: =C21/B21 -> 102.25
A22: 金沙豆腐義大利麵 | B22: 18 | C22: 2250 | E22: =C22/B22 -> 125
A23: 奶油鮮蝦明太子細扁麵 | B23: 18 | C23: 1636
A24: 番茄蘑菇義大利麵 | B24: 13 | C24: 1565
A26: 調理包
A27: 小滷青蔬 | B27: 15 | C27: 1636 | E27: =C27/B27 -> 109.06667 | G27: 夏季+1人補料
A28: 起司馬鈴薯 | B28: 11 | C28: 1636 | E28: =C28/B28 -> 148.72727
A29: 麻辣雞心 | B29: 11 | C29: 1636 | E29: =C29/B29 -> 148.72727
A30: 韓式炒冬粉 | B30: 11 | C30: 1636 | E30: =C30/B30 -> 148.72727
E34: 更新日期07/03

Sheet 範本總
B1: 長家廠組合室生產人時性分析
B3: 日期 | D3: 46015 | F3: 訂單量 | G3: =範本!E1 -> 43309 | I3: 營業額 | J3: =範本!G1 -> #N/A
B4: 項目 | D4: 3 | F4: ➀ | H4: ➁ | J4: ③ | L4: 異常停線 | N4: 短暫停線
B5: 人時性 | D5: 組合室 | F5: 全溫層 | H5: 義大利麵 | J5: 袋裝小吃、義麵 | L5: 合計次數 | M5: 時間 | N5: 合計次數 | O5: 設備次數
D6: 排關平均 | F6: =AVERAGE(D13:J13) -> #N/A | H6: =AVERAGE(D13:H13) -> #N/A | J6: =AVERAGE(I13:J13) -> #N/A | L6: =範本!Z2 -> 0 | M6: =範本!AA2 -> 0 | N6: =範本!AD2 -> 0 | O6: =範本!AE2 -> 0
D7: 實績平均 | F7: =AVERAGE(D14:J14) -> 116.11475 | H7: =AVERAGE(D14:H14) -> 117.36075 | J7: =AVERAGE(I14:J14) -> 112.99975
D8: 達成率平均 | F8: =AVERAGE(D15:J15) -> #N/A | H8: =AVERAGE(D15:H15) -> #N/A | J8: =AVERAGE(I15:J15) -> #N/A
J9: ※現行日本鮮食廠以達成率80%為基本(即為現行KPI)
B10: 溫層 | D10: 4度C-各編組展開
B11: 編組 | D11: 1 | E11: 2 | F11: 3 | G11: 4 | H11: 5 | I11: 6 | J11: 7
D12: 自動1線 | E12: 自動2線 | F12: 手工3線 | G12: 手工4線 | H12: 手工5線 | I12: 調理包1線 | J12: 調理包2線
B13: 人時性 | C13: 排關 | D13: =VALUE(範本!L15) -> #N/A | E13: =VALUE(範本!L26) -> #N/A | F13: =VALUE(範本!L37) -> #N/A | G13: =VALUE(範本!L48) -> #N/A | H13: =VALUE(範本!L58) -> #N/A | I13: =VALUE(範本!L69) -> #N/A | J13: =範本!L79 -> #N/A
C14: 實績 | D14: =VALUE(範本!O15) -> 113.91637 | E14: =VALUE(範本!O26) -> 132.12003 | F14: =VALUE(範本!O37) -> 126.23842 | G14: =VALUE(範本!O48) -> 112.0543 | H14: =VALUE(範本!O58) -> 102.47462 | I14: =VALUE(範本!O69) -> 155.46443 | J14: =範本!O79 -> 70.535065
C15: 達成率 | D15: =D14/D13 -> #N/A | E15: =E14/E13 -> #N/A | F15: =F14/F13 -> #N/A | G15: =G14/G13 -> #N/A | H15: =H14/H13 -> #N/A | I15: =I14/I13 -> #N/A | J15: =範本!S70 -> #N/A
B16: 作業 時間 | C16: 開始 | D16: =範本!T5 -> 0.29097222 | E16: =範本!T16 -> 0.29097222 | F16: =範本!T27 -> 0.29166667 | G16: =範本!T38 -> 0.33333333 | H16: =範本!T49 -> 0.29166667 | I16: =範本!T59 -> 0.29166667 | J16: =範本!T70 -> 0.34722222
C17: 結束 | D17: 0.47361111 | E17: 0.48263889 | F17: 0.56944444 | G17: 0.60416667 | H17: 0.58333333 | I17: 0.48819444 | J17: 0.46875
B18: 產線異常 (5分鐘以上) | C18: 次數
C19: 時間/分
B20: 短暫停線 (5分鐘以下) | C20: 次數
C21: 設備次數
B22: 配置人數 | D22: =VALUE(範本!M15) -> 15 | E22: =VALUE(範本!M26) -> 12.666667 | F22: =VALUE(範本!M37) -> 14.666667 | G22: =VALUE(範本!M48) -> 14 | H22: =VALUE(範本!M58) -> 17.666667 | I22: =VALUE(範本!M69) -> 12.333333 | J22: =範本!M79 -> 11
B23: 主要應用設備 | D23: ET-600 | E23: ET-600 | F23: ET-55 | G23: ET-55 | H23: ET-55 | I23: 八爪機
B24: 次要應用設備 | H24: 封口機
B25: 備註

Sheet 範本
A1: 長家廠4度C日報分析 | D1: 總生產量 | E1: =SUM(G5:G79) -> 43309 | F1: 營業額 | G1: =SUM(H5:H79) -> #N/A | H1: 出勤人數 | I1: =M15+M26+M48+M58+M69+M79+M37 -> 97.333333 | J1: 產線配置圖 | M1: 生產實績 | P1: 人時性差異分析 | T1: 日報登錄 | Z1: 合計 次數 | AA1: 合計 時間/分 | AB1: 分析說明 | AD1: 合計 次數 | AE1: 合計 設備次數 | AF1: 產能差異分析
A2: 12月24日 星期三 | D2: 人時性 | E2: =AVERAGE(O15,O26,O37,O48,O58,O69,O79) -> 116.11475 | F2: 平均廠價 | G2: =G1/E1 -> #N/A | H2: 多次生產數 | I2: =COUNT(I5:I79) -> 0 | Z2: =Z15+Z26+Z37+Z48+Z58+Z69+Z79 -> 0 | AA2: =AA15+AA26+AA37+AA48+AA58+AA69+AA79 -> 0 | AD2: =AD15+AD26+AD37+AD48+AD58+AD69+AD79 -> 0 | AE2: =AE15+AE26+AE37+AE48+AE58+AE69+AE79 -> 0
A3: 線別 | B3: 品類 | D3: 品名 | F3: 廠價 | G3: 生產量 | H3: 營收 | I3: 多次 生產 | J3: 人數 | K3: 產能/時 | L3: 人時性 | M3: 人數 | N3: 產能/時 | O3: 人時性 | P3: 人數 | Q3: 人時性 | R3: 達成率 | S3: 達成率平均 | T3: 生產時間 | V3: 前置、換線時間/分 | W3: 稼動時間/分 | X3: 休息時間 | Z3: 產線異常統計 (5分鐘以上) | AD3: 短暫停線統計 (5分鐘以下) | AF3: 產能/時 | AG3: 達成率 | AH3: 達成率平均
T4: 開始 | U4: 結束 | X4: 開始 | Y4: 結束 | Z4: 次數 | AA4: 時間/分 | AD4: 總次數 | AE4: 設備因素(次數)
A5: 自動一線 (ET-600) | B5: =VLOOKUP(D5,廠價表!$C$1:$E$43,2,0) -> #N/A | F5: =VLOOKUP(D5,廠價表!$C$1:$E$43,3,0) -> #N/A | G5: 2263 | H5: =F5*G5 -> #N/A | J5: =VLOOKUP(D5,產線配置圖!$A$3:$C$40,2,0) -> #N/A | K5: =VLOOKUP(D5,產線配置圖!$A$3:$C$40,3,0) -> #N/A | L5: =K5/J5 -> #N/A | M5: 15 | N5: =G5/W5*60 -> 1444.4681 | O5: =N5/M5 -> 96.297872 | P5: =M5-J5 -> #N/A | Q5: =O5-L5 -> #N/A | R5: =O5/L5 -> #N/A | S5: =R15 -> #N/A | T5: 0.29097222 | U5: 0.35625 | W5: =(U5-T5)*24*60 -> 94 | AF5: =N5-K5 -> #N/A | AG5: =N5/K5 -> #N/A | AH5: =AG15 -> #N/A
B6: =VLOOKUP(D6,廠價表!$C$1:$E$43,2,0) -> #N/A | F6: =VLOOKUP(D6,廠價表!$C$1:$E$43,3,0) -> #N/A | G6: 1180 | H6: =F6*G6 -> #N/A | J6: =VLOOKUP(D6,產線配置圖!$A$3:$C$40,2,0) -> #N/A | K6: =VLOOKUP(D6,產線配置圖!$A$3:$C$40,3,0) -> #N/A | L6: =K6/J6 -> #N/A | M6: 17 | N6: =G6/W6*60 -> 1609.0909 | O6: =N6/M6 -> 94.652406 | P6: =M6-J6 -> #N/A | Q6: =O6-L6 -> #N/A | R6: =O6/L6 -> #N/A | T6: 0.36458333 | U6: 0.39513889 | V6: =(T6-U5)*24*60 -> 12 | W6: =(U6-T6)*24*60 -> 44 | AF6: =N6-K6 -> #N/A | AG6: =N6/K6 -> #N/A
B7: =VLOOKUP(D7,廠價表!$C$1:$E$43,2,0) -> #N/A | F7: =VLOOKUP(D7,廠價表!$C$1:$E$43,3,0) -> #N/A | G7: 3398 | H7: =F7*G7 -> #N/A | J7: =VLOOKUP(D7,產線配置圖!$A$3:$C$40,2,0) -> #N/A | K7: =VLOOKUP(D7,產線配置圖!$A$3:$C$40,3,0) -> #N/A | L7: =K7/J7 -> #N/A | M7: 13 | N7: =G7/W7*60 -> 1960.3846 | O7: =N7/M7 -> 150.79882 | P7: =M7-J7 -> #N/A | Q7: =O7-L7 -> #N/A | R7: =O7/L7 -> #N/A | T7: 0.40138889 | U7: 0.47361111 | V7: =(T7-U6)*24*60 -> 9 | W7: =(U7-T7)*24*60 -> 104 | AF7: =N7-K7 -> #N/A | AG7: =N7/K7 -> #N/A
W8: =(U8-T8)*24*60 -> 0 | X8: 0.48611111 | Y8: 0.52777778 | AF8: =N8-K8 -> 0 | AG8: =N8/K8 -> #DIV/0!
W9: =(U9-T9)*24*60 -> 0 | AF9: =N9-K9 -> 0 | AG9: =N9/K9 -> #DIV/0!
W10: =(U10-T10)*24*60 -> 0 | AF10: =N10-K10 -> 0 | AG10: =N10/K10 -> #DIV/0!
W11: =(U11-T11)*24*60 -> 0 | AF11: =N11-K11 -> 0 | AG11: =N11/K11 -> #DIV/0!
W12: =(U12-T12)*24*60 -> 0
W13: =(U13-T13)*24*60 -> 0
W14: =(U14-T14)*24*60 -> 0
C15: 4度一組 | D15: 平均 | J15: =AVERAGE(J5:J14) -> #N/A | K15: =AVERAGE(K5:K14) -> #N/A | L15: =AVERAGE(L5:L14) -> #N/A | M15: =AVERAGE(M5:M14) -> 15 | N15: =AVERAGE(N5:N14) -> 1671.3145 | O15: =AVERAGE(O5:O14) -> 113.91637 | P15: =M15-J15 -> #N/A | Q15: =O15-L15 -> #N/A | R15: =O15/L15 -> #N/A | Z15: =SUM(Z5:Z14) -> 0 | AA15: =SUM(AA5:AA14) -> 0 | AD15: =SUM(AD5:AD14) -> 0 | AE15: =SUM(AE5:AE14) -> 0 | AF15: =N15-K15 -> #N/A | AG15: =N15/K15 -> #N/A
A16: 自動二線 (ET-600) | B16: =VLOOKUP(D16,廠價表!$C$1:$E$43,2,0) -> #N/A | F16: =VLOOKUP(D16,廠價表!$C$1:$E$43,3,0) -> #N/A | G16: 2263 | H16: =F16*G16 -> #N/A | J16: =VLOOKUP(D16,產線配置圖!$A$3:$C$40,2,0) -> #N/A | K16: =VLOOKUP(D16,產線配置圖!$A$3:$C$40,3,0) -> #N/A | L16: =K16/J16 -> #N/A | M16: 13 | N16: =G16/W16*60 -> 2225.9016 | O16: =N16/M16 -> 171.2232 | P16: =M16-J16 -> #N/A | Q16: =O16-L16 -> #N/A | R16: =O16/L16 -> #N/A | S16: =R26 -> #N/A | T16: 0.29097222 | U16: 0.33333333 | W16: =(U16-T16)*24*60 -> 61 | AF16: =N16-K16 -> #N/A | AG16: =N16/K16 -> #N/A | AH16: =AG26 -> #N/A
B17: =VLOOKUP(D17,廠價表!$C$1:$E$43,2,0) -> #N/A | F17: =VLOOKUP(D17,廠價表!$C$1:$E$43,3,0) -> #N/A | G17: 1180 | H17: =F17*G17 -> #N/A | J17: =VLOOKUP(D17,產線配置圖!$A$3:$C$40,2,0) -> #N/A | K17: =VLOOKUP(D17,產線配置圖!$A$3:$C$40,3,0) -> #N/A | L17: =K17/J17 -> #N/A | M17: 13 | N17: =G17/W17*60 -> 823.25581 | O17: =N17/M17 -> 63.32737 | P17: =M17-J17 -> #N/A | Q17: =O17-L17 -> #N/A | R17: =O17/L17 -> #N/A | T17: 0.34166667 | U17: 0.40138889 | V17: =(T17-U16)*24*60 -> 12 | W17: =(U17-T17)*24*60 -> 86 | AF17: =N17-K17 -> #N/A | AG17: =N17/K17 -> #N/A
B18: =VLOOKUP(D18,廠價表!$C$1:$E$43,2,0) -> #N/A | F18: =VLOOKUP(D18,廠價表!$C$1:$E$43,3,0) -> #N/A | G18: 3398 | H18: =F18*G18 -> #N/A | J18: =VLOOKUP(D18,產線配置圖!$A$3:$C$40,2,0) -> #N/A | K18: =VLOOKUP(D18,產線配置圖!$A$3:$C$40,3,0) -> #N/A | L18: =K18/J18 -> #N/A | M18: 12 | N18: =G18/W18*60 -> 1941.7143 | O18: =N18/M18 -> 161.80952 | P18: =M18-J18 -> #N/A | Q18: =O18-L18 -> #N/A | R18: =O18/L18 -> #N/A | T18: 0.40972222 | U18: 0.48263889 | V18: =(T18-U17)*24*60 -> 12 | W18: =(U18-T18)*24*60 -> 105 | X18: 0.48611111 | Y18: 0.52777778 | AF18: =N18-K18 -> #N/A | AG18: =N18/K18 -> #N/A
V19: =(T19-U18)*24*60 -> -695 | W19: =(U19-T19)*24*60 -> 0 | AF19: =N19-K19 -> 0 | AG19: =N19/K19 -> #DIV/0!
V20: =(T20-U19)*24*60 -> 0 | W20: =(U20-T20)*24*60 -> 0
W21: =(U21-T21)*24*60 -> 0
W22: 0
W23: =(U23-T23)*24*60 -> 0
H24: =F24*G24 -> 0 | W24: =(U24-T24)*24*60 -> 0
H25: =F25*G25 -> 0 | W25: =(U25-T25)*24*60 -> 0
C26: 4度二組A | D26: 平均 | J26: =AVERAGE(J16:J25) -> #N/A | K26: =AVERAGE(K16:K25) -> #N/A | L26: =AVERAGE(L16:L25) -> #N/A | M26: =AVERAGE(M16:M25) -> 12.666667 | N26: =AVERAGE(N16:N25) -> 1663.6239 | O26: =AVERAGE(O16:O25) -> 132.12003 | P26: =M26-J26 -> #N/A | Q26: =O26-L26 -> #N/A | R26: =O26/L26 -> #N/A | Z26: =SUM(Z16:Z25) -> 0 | AA26: =SUM(AA16:AA25) -> 0 | AD26: =SUM(AD16:AD25) -> 0 | AE26: =SUM(AE16:AE25) -> 0 | AF26: =N26-K26 -> #N/A | AG26: =N26/K26 -> #N/A
A27: 手工三線 (ET-55) | B27: =VLOOKUP(D27,廠價表!$C$1:$E$43,2,0) -> #N/A | F27: =VLOOKUP(D27,廠價表!$C$1:$E$43,3,0) -> #N/A | G27: 2263 | H27: =F27*G27 -> #N/A | J27: =VLOOKUP(D27,產線配置圖!$A$3:$C$40,2,0) -> #N/A | K27: =VLOOKUP(D27,產線配置圖!$A$3:$C$40,3,0) -> #N/A | L27: =K27/J27 -> #N/A | M27: 14 | N27: =G27/W27*60 -> 1212.3214 | O27: =N27/M27 -> 86.594388 | P27: =M27-J27 -> #N/A | Q27: =O27-L27 -> #N/A | R27: =O27/L27 -> #N/A | S27: =R37 -> #N/A | T27: 0.29166667 | U27: 0.36944444 | W27: =(U27-T27)*24*60 -> 112 | AF27: =N27-K27 -> #N/A | AG27: =N27/K27 -> #N/A | AH27: =AG37 -> #N/A
B28: =VLOOKUP(D28,廠價表!$C$1:$E$43,2,0) -> #N/A | F28: =VLOOKUP(D28,廠價表!$C$1:$E$43,3,0) -> #N/A | G28: 1180 | H28: =F28*G28 -> #N/A | J28: =VLOOKUP(D28,產線配置圖!$A$3:$C$40,2,0) -> #N/A | K28: =VLOOKUP(D28,產線配置圖!$A$3:$C$40,3,0) -> #N/A | L28: =K28/J28 -> #N/A | M28: 16 | N28: =G28/W28*60 -> 1089.2308 | O28: =N28/M28 -> 68.076923 | P28: =M28-J28 -> #N/A | Q28: =O28-L28 -> #N/A | R28: =O28/L28 -> #N/A | T28: 0.375 | U28: 0.42013889 | V28: =(T28-U27)*24*60 -> 8 | W28: =(U28-T28)*24*60 -> 65 | AF28: =N28-K28 -> #N/A | AG28: =N28/K28 -> #N/A
B29: =VLOOKUP(D29,廠價表!$C$1:$E$43,2,0) -> #N/A | F29: =VLOOKUP(D29,廠價表!$C$1:$E$43,3,0) -> #N/A | G29: 3398 | H29: =F29*G29 -> #N/A | J29: =VLOOKUP(D29,產線配置圖!$A$3:$C$40,2,0) -> #N/A | K29: =VLOOKUP(D29,產線配置圖!$A$3:$C$40,3,0) -> #N/A | L29: =K29/J29 -> #N/A | M29: 14 | N29: =G29/W29*60 -> 3136.6154 | O29: =N29/M29 -> 224.04396 | P29: =M29-J29 -> #N/A | Q29: =O29-L29 -> #N/A | R29: =O29/L29 -> #N/A | T29: 0.43055556 | U29: 0.47569444 | V29: =(T29-U28)*24*60 -> 15 | W29: =(U29-T29)*24*60 -> 65 | AF29: =N29-K29 -> #N/A | AG29: =N29/K29 -> #N/A
T30: 0.53958333 | U30: 0.56944444 | V30: =(T30-U29)*24*60 -> 92 | W30: =(U30-T30)*24*60 -> 43 | X30: 0.49652778 | Y30: 0.53819444 | AF30: =N30-K30 -> 0 | AG30: =N30/K30 -> #DIV/0!
W31: =(U31-T31)*24*60 -> 0 | AF31: =N31-K31 -> 0 | AG31: =N31/K31 -> #DIV/0!
W32: =(U32-T32)*24*60 -> 0
W33: =(U33-T33)*24*60 -> 0
W34: =(U34-T34)*24*60 -> 0
W35: =(U35-T35)*24*60 -> 0
H36: =F36*G36 -> 0 | W36: =(U36-T36)*24*60 -> 0
C37: 4度二組B | D37: 平均 | J37: =AVERAGE(J27:J36) -> #N/A | K37: =AVERAGE(K27:K36) -> #N/A | L37: =AVERAGE(L27:L36) -> #N/A | M37: =AVERAGE(M27:M36) -> 14.666667 | N37: =AVERAGE(N27:N36) -> 1812.7225 | O37: =AVERAGE(O27:O36) -> 126.23842 | P37: =M37-J37 -> #N/A | Q37: =N37-K37 -> #N/A | R37: =O37/L37 -> #N/A | Z37: =SUM(Z27:Z36) -> 0 | AA37: =SUM(AA27:AA36) -> 0 | AD37: =SUM(AD27:AD36) -> 0 | AE37: =SUM(AE27:AE36) -> 0 | AF37: =N37-K37 -> #N/A | AG37: =N37/K37 -> #N/A
A38: 手工四線 (ET-55) | B38: =VLOOKUP(D38,廠價表!$C$1:$E$43,2,0) -> #N/A | F38: =VLOOKUP(D38,廠價表!$C$1:$E$43,3,0) -> #N/A | G38: 2263 | H38: =F38*G38 -> #N/A | J38: =VLOOKUP(D38,產線配置圖!$A$3:$C$40,2,0) -> #N/A | K38: =VLOOKUP(D38,產線配置圖!$A$3:$C$40,3,0) -> #N/A | L38: =K38/J38 -> #N/A | M38: 14 | N38: =G38/W38*60 -> 1967.8261 | O38: =N38/M38 -> 140.55901 | P38: =M38-J38 -> #N/A | Q38: =O38-L38 -> #N/A | R38: =O38/L38 -> #N/A | S38: =R48 -> #N/A | T38: 0.33333333 | U38: 0.38125 | W38: =(U38-T38)*24*60 -> 69 | AF38: =N38-K38 -> #N/A | AG38: =N38/K38 -> #N/A | AH38: =AG48 -> #N/A
B39: =VLOOKUP(D39,廠價表!$C$1:$E$43,2,0) -> #N/A | F39: =VLOOKUP(D39,廠價表!$C$1:$E$43,3,0) -> #N/A | G39: 1180 | H39: =F39*G39 -> #N/A | J39: =VLOOKUP(D39,產線配置圖!$A$3:$C$40,2,0) -> #N/A | K39: =VLOOKUP(D39,產線配置圖!$A$3:$C$40,3,0) -> #N/A | L39: =K39/J39 -> #N/A | M39: 14 | N39: =G39/W39*60 -> 885 | O39: =N39/M39 -> 63.214286 | P39: =M39-J39 -> #N/A | Q39: =O39-L39 -> #N/A | R39: =O39/L39 -> #N/A | T39: 0.38888889 | U39: 0.44444444 | V39: =(T39-U38)*24*60 -> 11 | W39: =(U39-T39)*24*60 -> 80 | AF39: =N39-K39 -> #N/A | AG39: =N39/K39 -> #N/A
B40: =VLOOKUP(D40,廠價表!$C$1:$E$43,2,0) -> #N/A | F40: =VLOOKUP(D40,廠價表!$C$1:$E$43,3,0) -> #N/A | G40: 3398 | H40: =F40*G40 -> #N/A | J40: =VLOOKUP(D40,產線配置圖!$A$3:$C$40,2,0) -> #N/A | K40: =VLOOKUP(D40,產線配置圖!$A$3:$C$40,3,0) -> #N/A | L40: =K40/J40 -> #N/A | M40: 14 | N40: =G40/W40*60 -> 1853.4545 | O40: =N40/M40 -> 132.38961 | P40: =M40-J40 -> #N/A | Q40: =O40-L40 -> #N/A | R40: =O40/L40 -> #N/A | T40: 0.52777778 | U40: 0.60416667 | V40: =(T40-U39)*24*60 -> 120 | W40: =(U40-T40)*24*60 -> 110 | AF40: =N40-K40 -> #N/A | AG40: =N40/K40 -> #N/A
...

Sheet 0901總
B1: 長家廠組合室生產人時性分析
B3: 日期 | D3: 46266 | F3: 訂單量 | G3: ='0901'!E1 -> 56325 | I3: 營業額 | J3: ='0901'!G1 -> 2635970.6
B4: 項目 | D4: 3 | F4: ➀ | H4: ➁ | J4: ③ | L4: 異常停線 | N4: 短暫停線
B5: 人時性 | D5: 組合室 | F5: 全溫層 | H5: 義大利麵 | J5: 袋裝小吃、義麵 | L5: 合計次數 | M5: 時間 | N5: 合計次數 | O5: 設備次數
D6: 排關平均 | F6: =AVERAGE(D13:J13) -> 129.38591 | H6: =AVERAGE(D13:H13) -> 126.46666 | J6: =AVERAGE(I13:J13) -> 136.68403 | L6: ='0901'!Z2 -> 0 | M6: ='0901'!AA2 -> 0 | N6: ='0901'!AD2 -> 0 | O6: ='0901'!AE2 -> 0
D7: 實績平均 | F7: =AVERAGE(D14:J14) -> 111.92004 | H7: =AVERAGE(D14:H14) -> 109.7724 | J7: =AVERAGE(I14:J14) -> 117.28914
D8: 達成率平均 | F8: =AVERAGE(D15:J15) -> 0.86688563 | H8: =AVERAGE(D15:H15) -> 0.86993221 | J8: =AVERAGE(I15:J15) -> 0.85926918
J9: ※現行日本鮮食廠以達成率80%為基本(即為現行KPI)
B10: 溫層 | D10: 4度C-各編組展開
B11: 編組 | D11: 1 | E11: 2 | F11: 3 | G11: 4 | H11: 5 | I11: 6 | J11: 7
D12: 自動1線 | E12: 自動2線 | F12: 手工3線 | G12: 手工4線 | H12: 手工5線 | I12: 調理包1線 | J12: 調理包2線
B13: 人時性 | C13: 排關 | D13: =VALUE('0901'!L15) -> 157.51454 | E13: =VALUE('0901'!L26) -> 176.37363 | F13: =VALUE('0901'!L37) -> 95.065768 | G13: =VALUE('0901'!L48) -> 96.300926 | H13: =VALUE('0901'!L58) -> 107.07843 | I13: =VALUE('0901'!L69) -> 138.81212 | J13: ='0901'!L79 -> 134.55594
C14: 實績 | D14: =VALUE('0901'!O15) -> 128.89228 | E14: =VALUE('0901'!O26) -> 157.35262 | F14: =VALUE('0901'!O37) -> 83.132191 | G14: =VALUE('0901'!O48) -> 84.720816 | H14: =VALUE('0901'!O58) -> 94.764073 | I14: =VALUE('0901'!O69) -> 108.88997 | J14: ='0901'!O79 -> 125.6883
C15: 達成率 | D15: =D14/D13 -> 0.8182881 | E15: =E14/E13 -> 0.89215503 | F15: =F14/F13 -> 0.87447031 | G15: =G14/G13 -> 0.87975079 | H15: =H14/H13 -> 0.88499684 | I15: =I14/I13 -> 0.78444137 | J15: ='0901'!S70 -> 0.93409698
B16: 作業 時間 | C16: 開始 | D16: ='0901'!T5 -> 0.29236111 | E16: ='0901'!T16 -> 0.29166667 | F16: ='0901'!T27 -> 0.29166667 | G16: ='0901'!T38 -> 0.33333333 | H16: ='0901'!T49 -> 0.29166667 | I16: ='0901'!T59 -> 0.29166667 | J16: ='0901'!T70 -> 0.39027778
C17: 結束 | D17: 0.62638889 | E17: 0.63194444 | F17: 0.46527778 | G17: 0.65972222 | H17: 0.58472222 | I17: 0.59027778 | J17: 0.51180556
B18: 產線異常 (5分鐘以上) | C18: 次數 | D18: ='0901'!Z15 -> 0 | E18: ='0901'!Z26 -> 0 | F18: ='0901'!Z37 -> 0 | G18: ='0901'!Z48 -> 0 | H18: ='0901'!Z58 -> 0 | I18: ='0901'!Z69 -> 0 | J18: ='0901'!AA79 -> 0
C19: 時間/分 | D19: ='0901'!AA15 -> 0 | E19: ='0901'!AA26 -> 0 | F19: ='0901'!AA37 -> 0 | G19: ='0901'!AA48 -> 0 | H19: ='0901'!AA58 -> 0 | I19: ='0901'!AA69 -> 0 | J19: ='0901'!AB79 -> 0
B20: 短暫停線 (5分鐘以下) | C20: 次數 | D20: ='0901'!AD15 -> 0 | E20: ='0901'!AD26 -> 0 | F20: ='0901'!AD37 -> 0 | G20: ='0901'!AD48 -> 0 | H20: ='0901'!AD58 -> 0 | I20: ='0901'!AD69 -> 0 | J20: ='0901'!AD79 -> 0
C21: 設備次數 | D21: ='0901'!AE15 -> 0 | E21: ='0901'!AE26 -> 0 | F21: ='0901'!AE37 -> 0 | G21: ='0901'!AE48 -> 0 | H21: ='0901'!AE58 -> 0 | I21: ='0901'!AE69 -> 0 | J21: ='0901'!AE79 -> 0
B22: 配置人數 | D22: =VALUE('0901'!M15) -> 16.2 | E22: =VALUE('0901'!M26) -> 13.6 | F22: =VALUE('0901'!M37) -> 16.5 | G22: =VALUE('0901'!M48) -> 17.333333 | H22: =VALUE('0901'!M58) -> 16.333333 | I22: =VALUE('0901'!M69) -> 14 | J22: ='0901'!M79 -> 8.5
B23: 主要應用設備 | D23: ET-600 | E23: ET-600 | F23: ET-55 | G23: ET-55 | H23: ET-55 | I23: 八爪機
B24: 次要應用設備 | H24: 封口機
B25: 備註

Sheet 0901
A1: 長家廠4度C日報分析 | D1: 總生產量 | E1: =SUM(G5:G79) -> 56325 | F1: 營業額 | G1: =SUM(H5:H79) -> 2635970.6 | H1: 出勤人數 | I1: =M15+M26+M48+M58+M69+M79+M37 -> 102.46667 | J1: 產線配置圖 | M1: 生產實績 | P1: 人時性差異分析 | T1: 日報登錄 | Z1: 合計 次數 | AA1: 合計 時間/分 | AB1: 分析說明 | AD1: 合計 次數 | AE1: 合計 設備次數 | AF1: 產能差異分析
A2: 9月1日 星期二 | D2: 人時性 | E2: =AVERAGE(O15,O26,O37,O48,O58,O69,O79) -> 111.92004 | F2: 平均廠價 | G2: =G1/E1 -> 46.799301 | H2: 多次生產數 | I2: =COUNT(I5:I79) -> 0 | Z2: =Z15+Z26+Z37+Z48+Z58+Z69+Z79 -> 0 | AA2: =AA15+AA26+AA37+AA48+AA58+AA69+AA79 -> 0 | AD2: =AD15+AD26+AD37+AD48+AD58+AD69+AD79 -> 0 | AE2: =AE15+AE26+AE37+AE48+AE58+AE69+AE79 -> 0
A3: 線別 | B3: 品類 | D3: 品名 | F3: 廠價 | G3: 生產量 | H3: 營收 | I3: 多次 生產 | J3: 人數 | K3: 產能/時 | L3: 人時性 | M3: 人數 | N3: 產能/時 | O3: 人時性 | P3: 人數 | Q3: 人時性 | R3: 達成率 | S3: 達成率平均 | T3: 生產時間 | V3: 前置、換線時間/分 | W3: 稼動時間/分 | X3: 休息時間 | Z3: 產線異常統計 (5分鐘以上) | AD3: 短暫停線統計 (5分鐘以下) | AF3: 產能/時 | AG3: 達成率 | AH3: 達成率平均
T4: 開始 | U4: 結束 | X4: 開始 | Y4: 結束 | Z4: 次數 | AA4: 時間/分 | AD4: 總次數 | AE4: 設備因素(次數)
A5: 自動一線 (ET-600) | B5: 義大利麵 | D5: 白酒清炒鮮蛤義大利麵 | F5: =VLOOKUP(D5,廠價表!$C$1:$E$43,3,0) -> 56.87 | G5: 2083 | H5: =F5*G5 -> 118460.21 | J5: =VLOOKUP(D5,產線配置圖!$A$3:$C$40,2,0) -> 14 | K5: =VLOOKUP(D5,產線配置圖!$A$3:$C$40,3,0) -> 2250 | L5: =K5/J5 -> 160.71429 | M5: 16 | N5: =G5/W5*60 -> 2048.8525 | O5: =N5/M5 -> 128.05328 | P5: =M5-J5 -> 2 | Q5: =O5-L5 -> -32.661007 | R5: =O5/L5 -> 0.79677596 | S5: =R15 -> 0.8182881 | T5: 0.29236111 | U5: 0.33472222 | W5: =(U5-T5)*24*60 -> 61 | AF5: =N5-K5 -> -201.14754 | AG5: =N5/K5 -> 0.91060109 | AH5: =AG15 -> 0.92346241
B6: 義大利麵 | D6: 羅馬黑胡椒起司義大利麵 | F6: =VLOOKUP(D6,廠價表!$C$1:$E$43,3,0) -> 50.67 | G6: 1021 | H6: =F6*G6 -> 51734.07 | J6: =VLOOKUP(D6,產線配置圖!$A$3:$C$40,2,0) -> 17 | K6: =VLOOKUP(D6,產線配置圖!$A$3:$C$40,3,0) -> 2250 | L6: =K6/J6 -> 132.35294 | M6: 18 | N6: =G6/W6*60 -> 1976.129 | O6: =N6/M6 -> 109.78495 | P6: =M6-J6 -> 1 | Q6: =O6-L6 -> -22.567995 | R6: =O6/L6 -> 0.82948626 | T6: 0.35069444 | U6: 0.37222222 | V6: =(T6-U5)*24*60 -> 23 | W6: =(U6-T6)*24*60 -> 31 | AB6: 8:12-8:25待玉取機換麵 | AF6: =N6-K6 -> -273.87097 | AG6: =N6/K6 -> 0.87827957
B7: 義大利麵 | D7: 香煎魚排佐檸檬奶油義大利麵 | F7: =VLOOKUP(D7,廠價表!$C$1:$E$43,3,0) -> 58.17 | G7: 2698 | H7: =F7*G7 -> 156942.66 | J7: =VLOOKUP(D7,產線配置圖!$A$3:$C$40,2,0) -> 13 | K7: =VLOOKUP(D7,產線配置圖!$A$3:$C$40,3,0) -> 2250 | L7: =K7/J7 -> 173.07692 | M7: 15 | N7: =G7/W7*60 -> 2130 | O7: =N7/M7 -> 142 | P7: =M7-J7 -> 2 | Q7: =O7-L7 -> -31.076923 | R7: =O7/L7 -> 0.82044444 | T7: 0.37777778 | U7: 0.43055556 | V7: =(T7-U6)*24*60 -> 8 | W7: =(U7-T7)*24*60 -> 76 | AF7: =N7-K7 -> -120 | AG7: =N7/K7 -> 0.94666667
B8: 義大利麵 | D8: 奶油培根義大利麵 | F8: =VLOOKUP(D8,廠價表!$C$1:$E$43,3,0) -> 49.14 | G8: 1971 | H8: =F8*G8 -> 96854.94 | J8: =VLOOKUP(D8,產線配置圖!$A$3:$C$40,2,0) -> 14 | K8: =VLOOKUP(D8,產線配置圖!$A$3:$C$40,3,0) -> 2250 | L8: =K8/J8 -> 160.71429 | M8: 16 | N8: =G8/W8*60 -> 2111.7857 | O8: =N8/M8 -> 131.98661 | P8: =M8-J8 -> 2 | Q8: =O8-L8 -> -28.727679 | R8: =O8/L8 -> 0.82125 | T8: 0.4375 | U8: 0.47638889 | V8: =(T8-U7)*24*60 -> 10 | W8: =(U8-T8)*24*60 -> 56 | X8: 0.48611111 | Y8: 0.52777778 | AF8: =N8-K8 -> -138.21429 | AG8: =N8/K8 -> 0.93857143
B9: 義大利麵 | D9: 奶油培根義大利麵 | F9: =VLOOKUP(D9,廠價表!$C$1:$E$43,3,0) -> 49.14 | G9: 4209 | H9: =F9*G9 -> 206830.26 | J9: =VLOOKUP(D9,產線配置圖!$A$3:$C$40,2,0) -> 14 | K9: =VLOOKUP(D9,產線配置圖!$A$3:$C$40,3,0) -> 2250 | L9: =K9/J9 -> 160.71429 | M9: 16 | N9: =G9/W9*60 -> 2122.1849 | O9: =N9/M9 -> 132.63655 | P9: =M9-J9 -> 2 | Q9: =O9-L9 -> -28.077731 | R9: =O9/L9 -> 0.82529412 | T9: 0.54375 | U9: 0.62638889 | V9: =(T9-U8)*24*60 -> 97 | W9: =(U9-T9)*24*60 -> 119 | AF9: =N9-K9 -> -127.81513 | AG9: =N9/K9 -> 0.94319328
W10: =(U10-T10)*24*60 -> 0 | AF10: =N10-K10 -> 0 | AG10: =N10/K10 -> #DIV/0!
W11: =(U11-T11)*24*60 -> 0 | AB11: 多兩位新人學習 | AF11: =N11-K11 -> 0 | AG11: =N11/K11 -> #DIV/0!
W12: =(U12-T12)*24*60 -> 0
W13: =(U13-T13)*24*60 -> 0
W14: =(U14-T14)*24*60 -> 0
C15: 4度一組 | D15: 平均 | J15: =AVERAGE(J5:J14) -> 14.4 | K15: =AVERAGE(K5:K14) -> 2250 | L15: =AVERAGE(L5:L14) -> 157.51454 | M15: =AVERAGE(M5:M14) -> 16.2 | N15: =AVERAGE(N5:N14) -> 2077.7904 | O15: =AVERAGE(O5:O14) -> 128.89228 | P15: =M15-J15 -> 1.8 | Q15: =O15-L15 -> -28.622267 | R15: =O15/L15 -> 0.8182881 | Z15: =SUM(Z5:Z14) -> 0 | AA15: =SUM(AA5:AA14) -> 0 | AD15: =SUM(AD5:AD14) -> 0 | AE15: =SUM(AE5:AE14) -> 0 | AF15: =N15-K15 -> -172.20958 | AG15: =N15/K15 -> 0.92346241
A16: 自動二線 (ET-600) | B16: 義大利麵 | D16: 白酒清炒鮮蛤義大利麵 | F16: =VLOOKUP(D16,廠價表!$C$1:$E$43,3,0) -> 56.87 | G16: 2451 | H16: =F16*G16 -> 139388.37 | J16: =VLOOKUP(D16,產線配置圖!$A$3:$C$40,2,0) -> 14 | K16: =VLOOKUP(D16,產線配置圖!$A$3:$C$40,3,0) -> 2250 | L16: =K16/J16 -> 160.71429 | M16: 15 | N16: =G16/W16*60 -> 1909.8701 | O16: =N16/M16 -> 127.32468 | P16: =M16-J16 -> 1 | Q16: =O16-L16 -> -33.38961 | R16: =O16/L16 -> 0.79224242 | S16: =R26 -> 0.89215503 | T16: 0.29166667 | U16: 0.34513889 | W16: =(U16-T16)*24*60 -> 77 | AF16: =N16-K16 -> -340.12987 | AG16: =N16/K16 -> 0.84883117 | AH16: =AG26 -> 0.94511221
B17: 義大利麵 | D17: 青醬蛤蜊義大利麵 | F17: =VLOOKUP(D17,廠價表!$C$1:$E$43,3,0) -> 50.67 | G17: 2624 | H17: =F17*G17 -> 132958.08 | J17: =VLOOKUP(D17,產線配置圖!$A$3:$C$40,2,0) -> 13 | K17: =VLOOKUP(D17,產線配置圖!$A$3:$C$40,3,0) -> 2250 | L17: =K17/J17 -> 173.07692 | M17: 14 | N17: =G17/W17*60 -> 2099.2 | O17: =N17/M17 -> 149.94286 | P17: =M17-J17 -> 1 | Q17: =O17-L17 -> -23.134066 | R17: =O17/L17 -> 0.86633651 | T17: 0.35555556 | U17: 0.40763889 | V17: =(T17-U16)*24*60 -> 15 | W17: =(U17-T17)*24*60 -> 75 | AF17: =N17-K17 -> -150.8 | AG17: =N17/K17 -> 0.93297778
B18: 義大利麵 | D18: 義式蕃茄起司義大利麵 | F18: =VLOOKUP(D18,廠價表!$C$1:$E$43,3,0) -> 50.39 | G18: 3108 | H18: =F18*G18 -> 156612.12 | J18: =VLOOKUP(D18,產線配置圖!$A$3:$C$40,2,0) -> 12 | K18: =VLOOKUP(D18,產線配置圖!$A$3:$C$40,3,0) -> 2250 | L18: =K18/J18 -> 187.5 | M18: 13 | N18: =G18/W18*60 -> 2220 | O18: =N18/M18 -> 170.76923 | P18: =M18-J18 -> 1 | Q18: =O18-L18 -> -16.730769 | R18: =O18/L18 -> 0.91076923 | T18: 0.41805556 | U18: 0.47638889 | V18: =(T18-U17)*24*60 -> 15 | W18: =(U18-T18)*24*60 -> 84 | X18: 0.48611111 | Y18: 0.52777778 | AF18: =N18-K18 -> -30 | AG18: =N18/K18 -> 0.98666667
B19: 義大利麵 | D19: 義式蕃茄起司義大利麵 | F19: =VLOOKUP(D19,廠價表!$C$1:$E$43,3,0) -> 50.39 | G19: 3062 | H19: =F19*G19 -> 154294.18 | J19: =VLOOKUP(D19,產線配置圖!$A$3:$C$40,2,0) -> 12 | K19: =VLOOKUP(D19,產線配置圖!$A$3:$C$40,3,0) -> 2250 | L19: =K19/J19 -> 187.5 | M19: 13 | N19: =G19/W19*60 -> 2268.1481 | O19: =N19/M19 -> 174.47293 | P19: =M19-J19 -> 1 | Q19: =O19-L19 -> -13.027066 | R19: =O19/L19 -> 0.93052232 | T19: 0.54166667 | U19: 0.59791667 | V19: =(T19-U18)*24*60 -> 94 | W19: =(U19-T19)*24*60 -> 81 | AF19: =N19-K19 -> 18.148148 | AG19: =N19/K19 -> 1.0080658
B20: 義大利麵 | D20: 青醬蛤蜊義大利麵 | F20: =VLOOKUP(D20,廠價表!$C$1:$E$43,3,0) -> 50.67 | G20: 1210 | H20: =F20*G20 -> 61310.7 | J20: =VLOOKUP(D20,產線配置圖!$A$3:$C$40,2,0) -> 13 | K20: =VLOOKUP(D20,產線配置圖!$A$3:$C$40,3,0) -> 2250 | L20: =K20/J20 -> 173.07692 | M20: 13 | N20: =G20/W20*60 -> 2135.2941 | O20: =N20/M20 -> 164.25339 | P20: =M20-J20 -> 0 | Q20: =O20-L20 -> -8.8235294 | R20: =O20/L20 -> 0.94901961 | T20: 0.60833333 | U20: 0.63194444 | V20: =(T20-U19)*24*60 -> 15 | W20: =(U20-T20)*24*60 -> 34
W21: =(U21-T21)*24*60 -> 0 | AB21: 多一位新人學習
W22: 0
W23: =(U23-T23)*24*60 -> 0
H24: =F24*G24 -> 0 | W24: =(U24-T24)*24*60 -> 0
H25: =F25*G25 -> 0 | W25: =(U25-T25)*24*60 -> 0
C26: 4度二組A | D26: 平均 | J26: =AVERAGE(J16:J25) -> 12.8 | K26: =AVERAGE(K16:K25) -> 2250 | L26: =AVERAGE(L16:L25) -> 176.37363 | M26: =AVERAGE(M16:M25) -> 13.6 | N26: =AVERAGE(N16:N25) -> 2126.5025 | O26: =AVERAGE(O16:O25) -> 157.35262 | P26: =M26-J26 -> 0.8 | Q26: =O26-L26 -> -19.021008 | R26: =O26/L26 -> 0.89215503 | Z26: =SUM(Z16:Z25) -> 0 | AA26: =SUM(AA16:AA25) -> 0 | AD26: =SUM(AD16:AD25) -> 0 | AE26: =SUM(AE16:AE25) -> 0 | AF26: =N26-K26 -> -123.49752 | AG26: =N26/K26 -> 0.94511221
A27: 手工三線 (ET-55) | B27: 義大利麵 | D27: 金沙豆腐義大利麵 | F27: =VLOOKUP(D27,廠價表!$C$1:$E$43,3,0) -> 49.91 | G27: 997 | H27: =F27*G27 -> 49760.27 | J27: =VLOOKUP(D27,產線配置圖!$A$3:$C$40,2,0) -> 18 | K27: 1636 | L27: =K27/J27 -> 90.888889 | M27: 18 | N27: =G27/W27*60 -> 1329.3333 | O27: =N27/M27 -> 73.851852 | P27: =M27-J27 -> 0 | Q27: =O27-L27 -> -17.037037 | R27: =O27/L27 -> 0.81255094 | S27: =R37 -> 0.87447031 | T27: 0.29166667 | U27: 0.32291667 | W27: =(U27-T27)*24*60 -> 45 | AF27: =N27-K27 -> -306.66667 | AG27: =N27/K27 -> 0.81255094 | AH27: =AG37 -> 0.83511457
B28: 義大利麵 | D28: 奶油鮮蝦明太子細扁麵 | F28: =VLOOKUP(D28,廠價表!$C$1:$E$43,3,0) -> 57.21 | G28: 1446 | H28: =F28*G28 -> 82725.66 | J28: =VLOOKUP(D28,產線配置圖!$A$3:$C$40,2,0) -> 18 | K28: =VLOOKUP(D28,產線配置圖!$A$3:$C$40,3,0) -> 1636 | L28: =K28/J28 -> 90.888889 | M28: 14 | N28: =G28/W28*60 -> 1221.9718 | O28: =N28/M28 -> 87.283702 | P28: =M28-J28 -> -4 | Q28: =O28-L28 -> -3.6051867 | R28: =O28/L28 -> 0.96033413 | T28: 0.32986111 | U28: 0.37916667 | V28: =(T28-U27)*24*60 -> 10 | W28: =(U28-T28)*24*60 -> 71 | AF28: =N28-K28 -> -414.02817 | AG28: =N28/K28 -> 0.74692655
B29: 義大利麵 | D29: 蕃茄莎莎海鮮冷義大利麵 | F29: =VLOOKUP(D29,廠價表!$C$1:$E$43,3,0) -> 46.34 | G29: 1273 | H29: =F29*G29 -> 58990.82 | J29: =VLOOKUP(D29,產線配置圖!$A$3:$C$40,2,0) -> 16 | K29: =VLOOKUP(D29,產線配置圖!$A$3:$C$40,3,0) -> 1636 | L29: =K29/J29 -> 102.25 | M29: 17 | N29: =G29/W29*60 -> 1558.7755 | O29: =N29/M29 -> 91.692677 | P29: =M29-J29 -> 1 | Q29: =O29-L29 -> -10.557323 | R29: =O29/L29 -> 0.8967499 | T29: 0.38611111 | U29: 0.42013889 | V29: =(T29-U28)*24*60 -> 10 | W29: =(U29-T29)*24*60 -> 49 | AB29: 多一位新人學習收籃 | AF29: =N29-K29 -> -77.22449 | AG29: =N29/K29 -> 0.95279677
B30: 義大利麵 | D30: 義式蛋蛋青醬鮪魚冷義大利麵 | F30: =VLOOKUP(D30,廠價表!$C$1:$E$43,3,0) -> 45.66 | G30: 1242 | H30: =F30*G30 -> 56709.72 | J30: =VLOOKUP(D30,產線配置圖!$A$3:$C$40,2,0) -> 17 | K30: =VLOOKUP(D30,產線配置圖!$A$3:$C$40,3,0) -> 1636 | L30: =K30/J30 -> 96.235294 | M30: 17 | N30: =G30/W30*60 -> 1354.9091 | O30: =N30/M30 -> 79.700535 | P30: =M30-J30 -> 0 | Q30: =O30-L30 -> -16.534759 | R30: =O30/L30 -> 0.82818404 | T30: 0.42708333 | U30: 0.46527778 | V30: =(T30-U29)*24*60 -> 10 | W30: =(U30-T30)*24*60 -> 55 | X30: 0.49652778 | Y30: 0.53819444 | AF30: =N30-K30 -> -281.09091 | AG30: =N30/K30 -> 0.82818404
W31: =(U31-T31)*24*60 -> 0 | AF31: =N31-K31 -> 0 | AG31: =N31/K31 -> #DIV/0!
W32: =(U32-T32)*24*60 -> 0
W33: =(U33-T33)*24*60 -> 0
W34: =(U34-T34)*24*60 -> 0
W35: =(U35-T35)*24*60 -> 0
H36: =F36*G36 -> 0 | W36: =(U36-T36)*24*60 -> 0
C37: 4度二組B | D37: 平均 | J37: =AVERAGE(J27:J36) -> 17.25 | K37: =AVERAGE(K27:K36) -> 1636 | L37: =AVERAGE(L27:L36) -> 95.065768 | M37: =AVERAGE(M27:M36) -> 16.5 | N37: =AVERAGE(N27:N36) -> 1366.2474 | O37: =AVERAGE(O27:O36) -> 83.132191 | P37: =M37-J37 -> -0.75 | Q37: =N37-K37 -> -269.75256 | R37: =O37/L37 -> 0.87447031 | Z37: =SUM(Z27:Z36) -> 0 | AA37: =SUM(AA27:AA36) -> 0 | AD37: =SUM(AD27:AD36) -> 0 | AE37: =SUM(AE27:AE36) -> 0 | AF37: =N37-K37 -> -269.75256 | AG37: =N37/K37 -> 0.83511457
A38: 手工四線 (ET-55) | B38: 熱乾麵 | D38: 青花椒麻雞肉拌麵 | F38: =VLOOKUP(D38,廠價表!$C$1:$E$43,3,0) -> 49.91 | G38: 2615 | H38: =F38*G38 -> 130514.65 | J38: =VLOOKUP(D38,產線配置圖!$A$3:$C$40,2,0) -> 16 | K38: =VLOOKUP(D38,產線配置圖!$A$3:$C$40,3,0) -> 1714 | L38: =K38/J38 -> 107.125 | M38: 16 | N38: =G38/W38*60 -> 1569 | O38: =N38/M38 -> 98.0625 | P38: =M38-J38 -> 0 | Q38: =O38-L38 -> -9.0625 | R38: =O38/L38 -> 0.91540257 | S38: =R48 -> 0.87975079 | T38: 0.33333333 | U38: 0.40277778 | W38: =(U38-T38)*24*60 -> 100 | AF38: =N38-K38 -> -145 | AG38: =N38/K38 -> 0.91540257 | AH38: =AG48 -> 0.87821882
B39: 熱乾麵 | D39: 府城鹽水意麵 | F39: =VLOOKUP(D39,廠價表!$C$1:$E$43,3,0) -> 44.3 | G39: 2322 | H39: =F39*G39 -> 102864.6 | J39: =VLOOKUP(D39,產線配置圖!$A$3:$C$40,2,0) -> 18 | K39: =VLOOKUP(D39,產線配置圖!$A$3:$C$40,3,0) -> 1636 | L39: =K39/J39 -> 90.888889 | M39: 18 | N39: =G39/W39*60 -> 1466.5263 | O39: =N39/M39 -> 81.473684 | P39: =M39-J39 -> 0 | Q39: =O39-L39 -> -9.4152047 | R39: =O39/L39 -> 0.89640973 | T39: 0.41319444 | U39: 0.47916667 | V39: =(T39-U38)*24*60 -> 15 | W39: =(U39-T39)*24*60 -> 95 | AF39: =N39-K39 -> -169.47368 | AG39: =N39/K39 -> 0.89640973
B40: 熱乾麵 | D40: 府城鹽水意麵 | F40: =VLOOKUP(D40,廠價表!$C$1:$E$43,3,0) -> 44.3 | G40: 3694 | H40: =F40*G40 -> 163644.2 | J40: =VLOOKUP(D40,產線配置圖!$A$3:$C$40,2,0) -> 18 | K40: =VLOOKUP(D40,產線配置圖!$A$3:$C$40,3,0) -> 1636 | L40: =K40/J40 -> 90.888889 | M40: 18 | N40: =G40/W40*60 -> 1343.2727 | O40: =N40/M40 -> 74.626263 | P40: =M40-J40 -> 0 | Q40: =O40-L40 -> -16.262626 | R40: =O40/L40 -> 0.82107135 | T40: 0.54513889 | U40: 0.65972222 | V40: =(T40-U39)*24*60 -> 95 | W40: =(U40-T40)*24*60 -> 165 | AF40: =N40-K40 -> -292.72727 | AG40: =N40/K40 -> 0.82107135
...

Sheet 0902總
B1: 長家廠組合室生產人時性分析
B3: 日期 | D3: 46267 | F3: 訂單量 | G3: ='0902'!E1 -> 51934 | I3: 營業額 | J3: ='0902'!G1 -> 2427089.2
B4: 項目 | D4: 3 | F4: ➀ | H4: ➁ | J4: ③ | L4: 異常停線 | N4: 短暫停線
B5: 人時性 | D5: 組合室 | F5: 全溫層 | H5: 義大利麵 | J5: 袋裝小吃、義麵 | L5: 合計次數 | M5: 時間 | N5: 合計次數 | O5: 設備次數
D6: 排關平均 | F6: =AVERAGE(D13:J13) -> 130.24975 | H6: =AVERAGE(D13:H13) -> 128.33705 | J6: =AVERAGE(I13:J13) -> 135.03151 | L6: ='0902'!Z2 -> 0 | M6: ='0902'!AA2 -> 0 | N6: ='0902'!AD2 -> 0 | O6: ='0902'!AE2 -> 0
D7: 實績平均 | F7: =AVERAGE(D14:J14) -> 116.81133 | H7: =AVERAGE(D14:H14) -> 114.14255 | J7: =AVERAGE(I14:J14) -> 123.48328
D8: 達成率平均 | F8: =AVERAGE(D15:J15) -> 0.89131714 | H8: =AVERAGE(D15:H15) -> 0.88202685 | J8: =AVERAGE(I15:J15) -> 0.91454286
J9: ※現行日本鮮食廠以達成率80%為基本(即為現行KPI)
B10: 溫層 | D10: 4度C-各編組展開
B11: 編組 | D11: 1 | E11: 2 | F11: 3 | G11: 4 | H11: 5 | I11: 6 | J11: 7
D12: 自動1線 | E12: 自動2線 | F12: 手工3線 | G12: 手工4線 | H12: 手工5線 | I12: 調理包1線 | J12: 調理包2線
B13: 人時性 | C13: 排關 | D13: =VALUE('0902'!L15) -> 157.51454 | E13: =VALUE('0902'!L26) -> 177.1978 | F13: =VALUE('0902'!L37) -> 103.59355 | G13: =VALUE('0902'!L48) -> 96.300926 | H13: =VALUE('0902'!L58) -> 107.07843 | I13: =VALUE('0902'!L69) -> 135.50707 | J13: ='0902'!L79 -> 134.55594
C14: 實績 | D14: =VALUE('0902'!O15) -> 140.93249 | E14: =VALUE('0902'!O26) -> 165.32903 | F14: =VALUE('0902'!O37) -> 90.79917 | G14: =VALUE('0902'!O48) -> 80.528481 | H14: =VALUE('0902'!O58) -> 93.123566 | I14: =VALUE('0902'!O69) -> 121.414 | J14: ='0902'!O79 -> 125.55256
C15: 達成率 | D15: =D14/D13 -> 0.89472681 | E15: =E14/E13 -> 0.93301965 | F15: =F14/F13 -> 0.87649447 | G15: =G14/G13 -> 0.8362171 | H15: =H14/H13 -> 0.86967622 | I15: =I14/I13 -> 0.8959975 | J15: ='0902'!S70 -> 0.93308821
B16: 作業 時間 | C16: 開始 | D16: ='0902'!T5 -> 0.29861111 | E16: ='0902'!T16 -> 0.29861111 | F16: ='0902'!T27 -> 0.29166667 | G16: ='0902'!T38 -> 0.33541667 | H16: ='0902'!T49 -> 0.29166667 | I16: ='0902'!T59 -> 0.29166667 | J16: ='0902'!T70 -> 0.29305556
C17: 結束 | D17: 0.62152778 | E17: 0.59166667 | F17: 0.59305556 | G17: 0.64583333 | H17: 0.56944444 | I17: 0.44791667 | J17: 0.49305556
B18: 產線異常 (5分鐘以上) | C18: 次數 | D18: ='0902'!Z15 -> 0 | E18: ='0902'!Z26 -> 0 | F18: ='0902'!Z37 -> 0 | G18: ='0902'!Z48 -> 0 | H18: ='0902'!Z58 -> 0 | I18: ='0902'!Z69 -> 0 | J18: ='0902'!AA79 -> 0
C19: 時間/分 | D19: ='0902'!AA15 -> 0 | E19: ='0902'!AA26 -> 0 | F19: ='0902'!AA37 -> 0 | G19: ='0902'!AA48 -> 0 | H19: ='0902'!AA58 -> 0 | I19: ='0902'!AA69 -> 0 | J19: ='0902'!AB79 -> 0
B20: 短暫停線 (5分鐘以下) | C20: 次數 | D20: ='0902'!AD15 -> 0 | E20: ='0902'!AD26 -> 0 | F20: ='0902'!AD37 -> 0 | G20: ='0902'!AD48 -> 0 | H20: ='0902'!AD58 -> 0 | I20: ='0902'!AD69 -> 0 | J20: ='0902'!AD79 -> 0
C21: 設備次數 | D21: ='0902'!AE15 -> 0 | E21: ='0902'!AE26 -> 0 | F21: ='0902'!AE37 -> 0 | G21: ='0902'!AE48 -> 0 | H21: ='0902'!AE58 -> 0 | I21: ='0902'!AE69 -> 0 | J21: ='0902'!AE79 -> 0
B22: 配置人數 | D22: =VALUE('0902'!M15) -> 14.4 | E22: =VALUE('0902'!M26) -> 12.75 | F22: =VALUE('0902'!M37) -> 16.75 | G22: =VALUE('0902'!M48) -> 16.666667 | H22: =VALUE('0902'!M58) -> 16.333333 | I22: =VALUE('0902'!M69) -> 12.333333 | J22: ='0902'!M79 -> 7.5
B23: 主要應用設備 | D23: ET-600 | E23: ET-600 | F23: ET-55 | G23: ET-55 | H23: ET-55 | I23: 八爪機
B24: 次要應用設備 | H24: 封口機
B25: 備註

Sheet 0902
A1: 長家廠4度C日報分析 | D1: 總生產量 | E1: =SUM(G5:G79) -> 51934 | F1: 營業額 | G1: =SUM(H5:H79) -> 2427089.2 | H1: 出勤人數 | I1: =M15+M26+M48+M58+M69+M79+M37 -> 96.733333 | J1: 產線配置圖 | M1: 生產實績 | P1: 人時性差異分析 | T1: 日報登錄 | Z1: 合計 次數 | AA1: 合計 時間/分 | AB1: 分析說明 | AD1: 合計 次數 | AE1: 合計 設備次數 | AF1: 產能差異分析
A2: 9月2日 星期三 | D2: 人時性 | E2: =AVERAGE(O15,O26,O37,O48,O58,O69,O79) -> 116.81133 | F2: 平均廠價 | G2: =G1/E1 -> 46.734108 | H2: 多次生產數 | I2: =COUNT(I5:I79) -> 0 | Z2: =Z15+Z26+Z37+Z48+Z58+Z69+Z79 -> 0 | AA2: =AA15+AA26+AA37+AA48+AA58+AA69+AA79 -> 0 | AD2: =AD15+AD26+AD37+AD48+AD58+AD69+AD79 -> 0 | AE2: =AE15+AE26+AE37+AE48+AE58+AE69+AE79 -> 0
A3: 線別 | B3: 品類 | D3: 品名 | F3: 廠價 | G3: 生產量 | H3: 營收 | I3: 多次 生產 | J3: 人數 | K3: 產能/時 | L3: 人時性 | M3: 人數 | N3: 產能/時 | O3: 人時性 | P3: 人數 | Q3: 人時性 | R3: 達成率 | S3: 達成率平均 | T3: 生產時間 | V3: 前置、換線時間/分 | W3: 稼動時間/分 | X3: 休息時間 | Z3: 產線異常統計 (5分鐘以上) | AD3: 短暫停線統計 (5分鐘以下) | AF3: 產能/時 | AG3: 達成率 | AH3: 達成率平均
T4: 開始 | U4: 結束 | X4: 開始 | Y4: 結束 | Z4: 次數 | AA4: 時間/分 | AD4: 總次數 | AE4: 設備因素(次數)
A5: 自動一線 (ET-600) | B5: 義大利麵 | D5: 白酒清炒鮮蛤義大利麵 | F5: =VLOOKUP(D5,廠價表!$C$1:$E$43,3,0) -> 56.87 | G5: 2255 | H5: =F5*G5 -> 128241.85 | J5: =VLOOKUP(D5,產線配置圖!$A$3:$C$40,2,0) -> 14 | K5: =VLOOKUP(D5,產線配置圖!$A$3:$C$40,3,0) -> 2250 | L5: =K5/J5 -> 160.71429 | M5: 14 | N5: =G5/W5*60 -> 2182.2581 | O5: =N5/M5 -> 155.87558 | P5: =M5-J5 -> 0 | Q5: =O5-L5 -> -4.8387097 | R5: =O5/L5 -> 0.96989247 | S5: =R15 -> 0.89472681 | T5: 0.29861111 | U5: 0.34166667 | W5: =(U5-T5)*24*60 -> 62 | AF5: =N5-K5 -> -67.741935 | AG5: =N5/K5 -> 0.96989247 | AH5: =AG15 -> 0.89417506
B6: 義大利麵 | D6: 羅馬黑胡椒起司義大利麵 | F6: =VLOOKUP(D6,廠價表!$C$1:$E$43,3,0) -> 50.67 | G6: 986 | H6: =F6*G6 -> 49960.62 | J6: =VLOOKUP(D6,產線配置圖!$A$3:$C$40,2,0) -> 17 | K6: =VLOOKUP(D6,產線配置圖!$A$3:$C$40,3,0) -> 2250 | L6: =K6/J6 -> 132.35294 | M6: 17 | N6: =G6/W6*60 -> 1972 | O6: =N6/M6 -> 116 | P6: =M6-J6 -> 0 | Q6: =O6-L6 -> -16.352941 | R6: =O6/L6 -> 0.87644444 | T6: 0.35208333 | U6: 0.37291667 | V6: =(T6-U5)*24*60 -> 15 | W6: =(U6-T6)*24*60 -> 30 | AF6: =N6-K6 -> -278 | AG6: =N6/K6 -> 0.87644444
B7: 義大利麵 | D7: 香煎魚排佐檸檬奶油義大利麵 | F7: =VLOOKUP(D7,廠價表!$C$1:$E$43,3,0) -> 58.17 | G7: 2466 | H7: =F7*G7 -> 143447.22 | J7: =VLOOKUP(D7,產線配置圖!$A$3:$C$40,2,0) -> 13 | K7: =VLOOKUP(D7,產線配置圖!$A$3:$C$40,3,0) -> 2250 | L7: =K7/J7 -> 173.07692 | M7: 13 | N7: =G7/W7*60 -> 1999.4595 | O7: =N7/M7 -> 153.80457 | P7: =M7-J7 -> 0 | Q7: =O7-L7 -> -19.272349 | R7: =O7/L7 -> 0.88864865 | T7: 0.38055556 | U7: 0.43194444 | V7: =(T7-U6)*24*60 -> 11 | W7: =(U7-T7)*24*60 -> 74 | AF7: =N7-K7 -> -250.54054 | AG7: =N7/K7 -> 0.88864865
B8: 義大利麵 | D8: 奶油培根義大利麵 | F8: =VLOOKUP(D8,廠價表!$C$1:$E$43,3,0) -> 49.14 | G8: 1762 | H8: =F8*G8 -> 86584.68 | J8: =VLOOKUP(D8,產線配置圖!$A$3:$C$40,2,0) -> 14 | K8: =VLOOKUP(D8,產線配置圖!$A$3:$C$40,3,0) -> 2250 | L8: =K8/J8 -> 160.71429 | M8: 14 | N8: =G8/W8*60 -> 1887.8571 | O8: =N8/M8 -> 134.84694 | P8: =M8-J8 -> 0 | Q8: =O8-L8 -> -25.867347 | R8: =O8/L8 -> 0.83904762 | T8: 0.43888889 | U8: 0.47777778 | V8: =(T8-U7)*24*60 -> 10 | W8: =(U8-T8)*24*60 -> 56 | X8: 0.48611111 | Y8: 0.52777778 | AF8: =N8-K8 -> -362.14286 | AG8: =N8/K8 -> 0.83904762
B9: 義大利麵 | D9: 奶油培根義大利麵 | F9: =VLOOKUP(D9,廠價表!$C$1:$E$43,3,0) -> 49.14 | G9: 3834 | H9: =F9*G9 -> 188402.76 | J9: =VLOOKUP(D9,產線配置圖!$A$3:$C$40,2,0) -> 14 | K9: =VLOOKUP(D9,產線配置圖!$A$3:$C$40,3,0) -> 2250 | L9: =K9/J9 -> 160.71429 | M9: 14 | N9: =G9/W9*60 -> 2017.8947 | O9: =N9/M9 -> 144.13534 | P9: =M9-J9 -> 0 | Q9: =O9-L9 -> -16.578947 | R9: =O9/L9 -> 0.89684211 | T9: 0.54236111 | U9: 0.62152778 | V9: =(T9-U8)*24*60 -> 93 | W9: =(U9-T9)*24*60 -> 114 | AF9: =N9-K9 -> -232.10526 | AG9: =N9/K9 -> 0.89684211
W10: =(U10-T10)*24*60 -> 0 | AF10: =N10-K10 -> 0 | AG10: =N10/K10 -> #DIV/0!
W11: =(U11-T11)*24*60 -> 0 | AF11: =N11-K11 -> 0 | AG11: =N11/K11 -> #DIV/0!
W12: =(U12-T12)*24*60 -> 0
W13: =(U13-T13)*24*60 -> 0
W14: =(U14-T14)*24*60 -> 0
C15: 4度一組 | D15: 平均 | J15: =AVERAGE(J5:J14) -> 14.4 | K15: =AVERAGE(K5:K14) -> 2250 | L15: =AVERAGE(L5:L14) -> 157.51454 | M15: =AVERAGE(M5:M14) -> 14.4 | N15: =AVERAGE(N5:N14) -> 2011.8939 | O15: =AVERAGE(O5:O14) -> 140.93249 | P15: =M15-J15 -> 0 | Q15: =O15-L15 -> -16.582059 | R15: =O15/L15 -> 0.89472681 | Z15: =SUM(Z5:Z14) -> 0 | AA15: =SUM(AA5:AA14) -> 0 | AD15: =SUM(AD5:AD14) -> 0 | AE15: =SUM(AE5:AE14) -> 0 | AF15: =N15-K15 -> -238.10612 | AG15: =N15/K15 -> 0.89417506
A16: 自動二線 (ET-600) | B16: 義大利麵 | D16: 白酒清炒鮮蛤義大利麵 | F16: =VLOOKUP(D16,廠價表!$C$1:$E$43,3,0) -> 56.87 | G16: 1924 | H16: =F16*G16 -> 109417.88 | J16: =VLOOKUP(D16,產線配置圖!$A$3:$C$40,2,0) -> 14 | K16: =VLOOKUP(D16,產線配置圖!$A$3:$C$40,3,0) -> 2250 | L16: =K16/J16 -> 160.71429 | M16: 14 | N16: =G16/W16*60 -> 2098.9091 | O16: =N16/M16 -> 149.92208 | P16: =M16-J16 -> 0 | Q16: =O16-L16 -> -10.792208 | R16: =O16/L16 -> 0.93284848 | S16: =R26 -> 0.93301965 | T16: 0.29861111 | U16: 0.33680556 | W16: =(U16-T16)*24*60 -> 55 | AF16: =N16-K16 -> -151.09091 | AG16: =N16/K16 -> 0.93284848 | AH16: =AG26 -> 0.93383153
B17: 義大利麵 | D17: 青醬蛤蜊義大利麵 | F17: =VLOOKUP(D17,廠價表!$C$1:$E$43,3,0) -> 50.67 | G17: 3512 | H17: =F17*G17 -> 177953.04 | J17: =VLOOKUP(D17,產線配置圖!$A$3:$C$40,2,0) -> 13 | K17: =VLOOKUP(D17,產線配置圖!$A$3:$C$40,3,0) -> 2250 | L17: =K17/J17 -> 173.07692 | M17: 13 | N17: =G17/W17*60 -> 2195 | O17: =N17/M17 -> 168.84615 | P17: =M17-J17 -> 0 | Q17: =O17-L17 -> -4.2307692 | R17: =O17/L17 -> 0.97555556 | T17: 0.34305556 | U17: 0.40972222 | V17: =(T17-U16)*24*60 -> 9 | W17: =(U17-T17)*24*60 -> 96 | AF17: =N17-K17 -> -55 | AG17: =N17/K17 -> 0.97555556
B18: 義大利麵 | D18: 義式蕃茄起司義大利麵 | F18: =VLOOKUP(D18,廠價表!$C$1:$E$43,3,0) -> 50.39 | G18: 2983 | H18: =F18*G18 -> 150313.37 | J18: =VLOOKUP(D18,產線配置圖!$A$3:$C$40,2,0) -> 12 | K18: =VLOOKUP(D18,產線配置圖!$A$3:$C$40,3,0) -> 2250 | L18: =K18/J18 -> 187.5 | M18: 12 | N18: =G18/W18*60 -> 2057.2414 | O18: =N18/M18 -> 171.43678 | P18: =M18-J18 -> 0 | Q18: =O18-L18 -> -16.063218 | R18: =O18/L18 -> 0.9143295 | T18: 0.41597222 | U18: 0.47638889 | V18: =(T18-U17)*24*60 -> 9 | W18: =(U18-T18)*24*60 -> 87 | X18: 0.48611111 | Y18: 0.52777778 | AF18: =N18-K18 -> -192.75862 | AG18: =N18/K18 -> 0.9143295
B19: 義大利麵 | D19: 義式蕃茄起司義大利麵 | F19: =VLOOKUP(D19,廠價表!$C$1:$E$43,3,0) -> 50.39 | G19: 2464 | H19: =F19*G19 -> 124160.96 | J19: =VLOOKUP(D19,產線配置圖!$A$3:$C$40,2,0) -> 12 | K19: =VLOOKUP(D19,產線配置圖!$A$3:$C$40,3,0) -> 2250 | L19: =K19/J19 -> 187.5 | M19: 12 | N19: =G19/W19*60 -> 2053.3333 | O19: =N19/M19 -> 171.11111 | P19: =M19-J19 -> 0 | Q19: =O19-L19 -> -16.388889 | R19: =O19/L19 -> 0.91259259 | T19: 0.54166667 | U19: 0.59166667 | V19: =(T19-U18)*24*60 -> 94 | W19: =(U19-T19)*24*60 -> 72 | AF19: =N19-K19 -> -196.66667 | AG19: =N19/K19 -> 0.91259259
W20: =(U20-T20)*24*60 -> 0
W21: =(U21-T21)*24*60 -> 0
W22: 0
W23: =(U23-T23)*24*60 -> 0
H24: =F24*G24 -> 0 | W24: =(U24-T24)*24*60 -> 0
H25: =F25*G25 -> 0 | W25: =(U25-T25)*24*60 -> 0
C26: 4度二組A | D26: 平均 | J26: =AVERAGE(J16:J25) -> 12.75 | K26: =AVERAGE(K16:K25) -> 2250 | L26: =AVERAGE(L16:L25) -> 177.1978 | M26: =AVERAGE(M16:M25) -> 12.75 | N26: =AVERAGE(N16:N25) -> 2101.121 | O26: =AVERAGE(O16:O25) -> 165.32903 | P26: =M26-J26 -> 0 | Q26: =O26-L26 -> -11.868771 | R26: =O26/L26 -> 0.93301965 | Z26: =SUM(Z16:Z25) -> 0 | AA26: =SUM(AA16:AA25) -> 0 | AD26: =SUM(AD16:AD25) -> 0 | AE26: =SUM(AE16:AE25) -> 0 | AF26: =N26-K26 -> -148.87905 | AG26: =N26/K26 -> 0.93383153
A27: 手工三線 (ET-55) | B27: 義大利麵 | D27: 金沙豆腐義大利麵 | F27: =VLOOKUP(D27,廠價表!$C$1:$E$43,3,0) -> 49.91 | G27: 995 | H27: =F27*G27 -> 49660.45 | J27: =VLOOKUP(D27,產線配置圖!$A$3:$C$40,2,0) -> 18 | K27: =VLOOKUP(D27,產線配置圖!$A$3:$C$40,3,0) -> 2250 | L27: =K27/J27 -> 125 | M27: 17 | N27: =G27/W27*60 -> 1705.7143 | O27: =N27/M27 -> 100.33613 | P27: =M27-J27 -> -1 | Q27: =O27-L27 -> -24.663866 | R27: =O27/L27 -> 0.80268908 | S27: =R37 -> 0.87649447 | T27: 0.29166667 | U27: 0.31597222 | W27: =(U27-T27)*24*60 -> 35 | AF27: =N27-K27 -> -544.28571 | AG27: =N27/K27 -> 0.75809524 | AH27: =AG37 -> 0.84913045
B28: 義大利麵 | D28: 奶油鮮蝦明太子細扁麵 | F28: =VLOOKUP(D28,廠價表!$C$1:$E$43,3,0) -> 57.21 | G28: 1363 | H28: =F28*G28 -> 77977.23 | J28: =VLOOKUP(D28,產線配置圖!$A$3:$C$40,2,0) -> 18 | K28: =VLOOKUP(D28,產線配置圖!$A$3:$C$40,3,0) -> 1636 | L28: =K28/J28 -> 90.888889 | M28: 17 | N28: =G28/W28*60 -> 1319.0323 | O28: =N28/M28 -> 77.590133 | P28: =M28-J28 -> -1 | Q28: =O28-L28 -> -13.298756 | R28: =O28/L28 -> 0.85368117 | T28: 0.32291667 | U28: 0.36597222 | V28: =(T28-U27)*24*60 -> 10 | W28: =(U28-T28)*24*60 -> 62 | AF28: =N28-K28 -> -316.96774 | AG28: =N28/K28 -> 0.80625444
B29: 義大利麵 | D29: 義式蛋蛋青醬鮪魚冷義大利麵 | F29: =VLOOKUP(D29,廠價表!$C$1:$E$43,3,0) -> 45.66 | G29: 1160 | H29: =F29*G29 -> 52965.6 | J29: =VLOOKUP(D29,產線配置圖!$A$3:$C$40,2,0) -> 17 | K29: =VLOOKUP(D29,產線配置圖!$A$3:$C$40,3,0) -> 1636 | L29: =K29/J29 -> 96.235294 | M29: 17 | N29: =G29/W29*60 -> 1513.0435 | O29: =N29/M29 -> 89.002558 | P29: =M29-J29 -> 0 | Q29: =O29-L29 -> -7.2327366 | R29: =O29/L29 -> 0.9248432 | T29: 0.37291667 | U29: 0.40486111 | V29: =(T29-U28)*24*60 -> 10 | W29: =(U29-T29)*24*60 -> 46 | AF29: =N29-K29 -> -122.95652 | AG29: =N29/K29 -> 0.9248432
B30: 義大利麵 | D30: 蕃茄莎莎海鮮冷義大利麵 | F30: =VLOOKUP(D30,廠價表!$C$1:$E$43,3,0) -> 46.34 | G30: 1797 | H30: =F30*G30 -> 83272.98 | J30: =VLOOKUP(D30,產線配置圖!$A$3:$C$40,2,0) -> 16 | K30: =VLOOKUP(D30,產線配置圖!$A$3:$C$40,3,0) -> 1636 | L30: =K30/J30 -> 102.25 | M30: 16 | N30: =G30/W30*60 -> 1540.2857 | O30: =N30/M30 -> 96.267857 | P30: =M30-J30 -> 0 | Q30: =O30-L30 -> -5.9821429 | R30: =O30/L30 -> 0.94149494 | T30: 0.41111111 | U30: 0.45972222 | V30: =(T30-U29)*24*60 -> 9 | W30: =(U30-T30)*24*60 -> 70 | X30: 0.49652778 | Y30: 0.53819444 | AF30: =N30-K30 -> -95.714286 | AG30: =N30/K30 -> 0.94149494
T31: 0.59027778 | U31: 0.59305556 | W31: =(U31-T31)*24*60 -> 4 | AF31: =N31-K31 -> 0 | AG31: =N31/K31 -> #DIV/0!
W32: =(U32-T32)*24*60 -> 0
W33: =(U33-T33)*24*60 -> 0
W34: =(U34-T34)*24*60 -> 0
W35: =(U35-T35)*24*60 -> 0
H36: =F36*G36 -> 0 | W36: =(U36-T36)*24*60 -> 0
C37: 4度二組B | D37: 平均 | J37: =AVERAGE(J27:J36) -> 17.25 | K37: =AVERAGE(K27:K36) -> 1789.5 | L37: =AVERAGE(L27:L36) -> 103.59355 | M37: =AVERAGE(M27:M36) -> 16.75 | N37: =AVERAGE(N27:N36) -> 1519.5189 | O37: =AVERAGE(O27:O36) -> 90.79917 | P37: =M37-J37 -> -0.5 | Q37: =N37-K37 -> -269.98107 | R37: =O37/L37 -> 0.87649447 | Z37: =SUM(Z27:Z36) -> 0 | AA37: =SUM(AA27:AA36) -> 0 | AD37: =SUM(AD27:AD36) -> 0 | AE37: =SUM(AE27:AE36) -> 0 | AF37: =N37-K37 -> -269.98107 | AG37: =N37/K37 -> 0.84913045
A38: 手工四線 (ET-55) | B38: 熱乾麵 | D38: 青花椒麻雞肉拌麵 | F38: =VLOOKUP(D38,廠價表!$C$1:$E$43,3,0) -> 49.91 | G38: 2135 | H38: =F38*G38 -> 106557.85 | J38: =VLOOKUP(D38,產線配置圖!$A$3:$C$40,2,0) -> 16 | K38: =VLOOKUP(D38,產線配置圖!$A$3:$C$40,3,0) -> 1714 | L38: =K38/J38 -> 107.125 | M38: 16 | N38: =G38/W38*60 -> 1377.4194 | O38: =N38/M38 -> 86.08871 | P38: =M38-J38 -> 0 | Q38: =O38-L38 -> -21.03629 | R38: =O38/L38 -> 0.80362856 | S38: =R48 -> 0.8362171 | T38: 0.33541667 | U38: 0.4 | W38: =(U38-T38)*24*60 -> 93 | AF38: =N38-K38 -> -336.58065 | AG38: =N38/K38 -> 0.80362856 | AH38: =AG48 -> 0.80643077
B39: 熱乾麵 | D39: 府城鹽水意麵 | F39: =VLOOKUP(D39,廠價表!$C$1:$E$43,3,0) -> 44.3 | G39: 2447 | H39: =F39*G39 -> 108402.1 | J39: =VLOOKUP(D39,產線配置圖!$A$3:$C$40,2,0) -> 18 | K39: =VLOOKUP(D39,產線配置圖!$A$3:$C$40,3,0) -> 1636 | L39: =K39/J39 -> 90.888889 | M39: 17 | N39: =G39/W39*60 -> 1359.4444 | O39: =N39/M39 -> 79.96732 | P39: =M39-J39 -> -1 | Q39: =O39-L39 -> -10.921569 | R39: =O39/L39 -> 0.87983604 | T39: 0.41458333 | U39: 0.48958333 | V39: =(T39-U38)*24*60 -> 21 | W39: =(U39-T39)*24*60 -> 108 | AF39: =N39-K39 -> -276.55556 | AG39: =N39/K39 -> 0.83095626
B40: 熱乾麵 | D40: 府城鹽水意麵 | F40: =VLOOKUP(D40,廠價表!$C$1:$E$43,3,0) -> 44.3 | G40: 2996 | H40: =F40*G40 -> 132722.8 | J40: =VLOOKUP(D40,產線配置圖!$A$3:$C$40,2,0) -> 18 | K40: =VLOOKUP(D40,產線配置圖!$A$3:$C$40,3,0) -> 1636 | L40: =K40/J40 -> 90.888889 | M40: 17 | N40: =G40/W40*60 -> 1284 | O40: =N40/M40 -> 75.529412 | P40: =M40-J40 -> -1 | Q40: =O40-L40 -> -15.359477 | R40: =O40/L40 -> 0.8310082 | T40: 0.54861111 | U40: 0.64583333 | V40: =(T40-U39)*24*60 -> 85 | W40: =(U40-T40)*24*60 -> 140 | AF40: =N40-K40 -> -352 | AG40: =N40/K40 -> 0.78484108
...

Sheet 0903總
B1: 長家廠組合室生產人時性分析
B3: 日期 | D3: 46268 | F3: 訂單量 | G3: ='0903'!E1 -> 44607 | I3: 營業額 | J3: ='0903'!G1 -> 2072932.1
B4: 項目 | D4: 3 | F4: ➀ | H4: ➁ | J4: ③ | L4: 異常停線 | N4: 短暫停線
B5: 人時性 | D5: 組合室 | F5: 全溫層 | H5: 義大利麵 | J5: 袋裝小吃、義麵 | L5: 合計次數 | M5: 時間 | N5: 合計次數 | O5: 設備次數
D6: 排關平均 | F6: =AVERAGE(D13:I13) -> 127.40298 | H6: =AVERAGE(D13:H13) -> 124.72455 | J6: =AVERAGE(I13) -> 140.79515 | L6: ='0903'!Z2 -> 4 | M6: ='0903'!AA2 -> 50 | N6: ='0903'!AD2 -> 0 | O6: ='0903'!AE2 -> 0
D7: 實績平均 | F7: =AVERAGE(D14:I14) -> 110.15841 | H7: =AVERAGE(D14:H14) -> 107.04519 | J7: =AVERAGE(I14) -> 125.72454
D8: 達成率平均 | F8: =AVERAGE(D15:I15) -> 0.86735403 | H8: =AVERAGE(D15:H15) -> 0.86223269 | J8: =AVERAGE(I15) -> 0.89296073
J9: ※現行日本鮮食廠以達成率80%為基本(即為現行KPI)
B10: 溫層 | D10: 4度C-各編組展開
B11: 編組 | D11: 1 | E11: 2 | F11: 3 | G11: 4 | H11: 5 | I11: 6 | J11: 7
D12: 自動1線 | E12: 自動2線 | F12: 手工3線 | G12: 手工4線 | H12: 手工5線 | I12: 調理包1線 | J12: 調理包2線
B13: 人時性 | C13: 排關 | D13: =VALUE('0903'!L15) -> 149.22173 | E13: =VALUE('0903'!L26) -> 174.10714 | F13: =VALUE('0903'!L37) -> 96.919281 | G13: =VALUE('0903'!L48) -> 99.006944 | H13: =VALUE('0903'!L58) -> 104.36765 | I13: =VALUE('0903'!L69) -> 140.79515 | J13: ='0903'!L79 -> 0
C14: 實績 | D14: =VALUE('0903'!O15) -> 120.37079 | E14: =VALUE('0903'!O26) -> 150.4186 | F14: =VALUE('0903'!O37) -> 86.67939 | G14: =VALUE('0903'!O48) -> 82.952186 | H14: =VALUE('0903'!O58) -> 94.804983 | I14: =VALUE('0903'!O69) -> 125.72454 | J14: ='0903'!O79 -> 0
C15: 達成率 | D15: =D14/D13 -> 0.8066572 | E15: =E14/E13 -> 0.86394274 | F15: =F14/F13 -> 0.89434619 | G15: =G14/G13 -> 0.8378421 | H15: =H14/H13 -> 0.90837521 | I15: =I14/I13 -> 0.89296073 | J15: ='0903'!S70 -> 0
B16: 作業 時間 | C16: 開始 | D16: ='0903'!T5 -> 0.30555556 | E16: ='0903'!T16 -> 0.29861111 | F16: ='0903'!T27 -> 0.29166667 | G16: ='0903'!T38 -> 0.33333333 | H16: ='0903'!T49 -> 0.29166667 | I16: ='0903'!T59 -> 0.29166667 | J16: ='0903'!T70 -> 0
C17: 結束 | D17: 0.6125 | E17: 0.61111111 | F17: 0.5 | G17: 0.49583333 | H17: 0.45486111 | I17: 0.59861111 | J17: ='0903'!T71 -> 0
B18: 產線異常 (5分鐘以上) | C18: 次數 | D18: ='0903'!Z15 -> 2 | E18: ='0903'!Z26 -> 2 | F18: ='0903'!Z37 -> 0 | G18: ='0903'!Z48 -> 0 | H18: ='0903'!Z58 -> 0 | I18: ='0903'!Z69 -> 0 | J18: ='0903'!AA79 -> 0
C19: 時間/分 | D19: ='0903'!AA15 -> 25 | E19: ='0903'!AA26 -> 25 | F19: ='0903'!AA37 -> 0 | G19: ='0903'!AA48 -> 0 | H19: ='0903'!AA58 -> 0 | I19: ='0903'!AA69 -> 0 | J19: ='0903'!AB79 -> 0
B20: 短暫停線 (5分鐘以下) | C20: 次數 | D20: ='0903'!AD15 -> 0 | E20: ='0903'!AD26 -> 0 | F20: ='0903'!AD37 -> 0 | G20: ='0903'!AD48 -> 0 | H20: ='0903'!AD58 -> 0 | I20: ='0903'!AD69 -> 0 | J20: ='0903'!AD79 -> 0
C21: 設備次數 | D21: ='0903'!AE15 -> 0 | E21: ='0903'!AE26 -> 0 | F21: ='0903'!AE37 -> 0 | G21: ='0903'!AE48 -> 0 | H21: ='0903'!AE58 -> 0 | I21: ='0903'!AE69 -> 0 | J21: ='0903'!AE79 -> 0
B22: 配置人數 | D22: =VALUE('0903'!M15) -> 14.6 | E22: =VALUE('0903'!M26) -> 13 | F22: =VALUE('0903'!M37) -> 16.4 | G22: =VALUE('0903'!M48) -> 16.5 | H22: =VALUE('0903'!M58) -> 16.5 | I22: =VALUE('0903'!M69) -> 11.8 | J22: ='0903'!M79 -> 0
B23: 主要應用設備 | D23: ET-600 | E23: ET-600 | F23: ET-55 | G23: ET-55 | H23: ET-55 | I23: 八爪機
B24: 次要應用設備 | H24: 封口機
B25: 備註

Sheet 0903
A1: 長家廠4度C日報分析 | D1: 總生產量 | E1: =SUM(G5:G79) -> 44607 | F1: 營業額 | G1: =SUM(H5:H79) -> 2072932.1 | H1: 出勤人數 | I1: =M15+M26+M48+M58+M69+M79+M37 -> 88.8 | J1: 產線配置圖 | M1: 生產實績 | P1: 人時性差異分析 | T1: 日報登錄 | Z1: 合計 次數 | AA1: 合計 時間/分 | AB1: 分析說明 | AD1: 合計 次數 | AE1: 合計 設備次數 | AF1: 產能差異分析
A2: 9月3日 星期四 | D2: 人時性 | E2: =AVERAGE(O15,O26,O37,O48,O58,O69,O79) -> 110.15841 | F2: 平均廠價 | G2: =G1/E1 -> 46.471006 | H2: 多次生產數 | I2: =COUNT(I5:I79) -> 0 | Z2: =Z15+Z26+Z37+Z48+Z58+Z69+Z79 -> 4 | AA2: =AA15+AA26+AA37+AA48+AA58+AA69+AA79 -> 50 | AD2: =AD15+AD26+AD37+AD48+AD58+AD69+AD79 -> 0 | AE2: =AE15+AE26+AE37+AE48+AE58+AE69+AE79 -> 0
A3: 線別 | B3: 品類 | D3: 品名 | F3: 廠價 | G3: 生產量 | H3: 營收 | I3: 多次 生產 | J3: 人數 | K3: 產能/時 | L3: 人時性 | M3: 人數 | N3: 產能/時 | O3: 人時性 | P3: 人數 | Q3: 人時性 | R3: 達成率 | S3: 達成率平均 | T3: 生產時間 | V3: 前置、換線時間/分 | W3: 稼動時間/分 | X3: 休息時間 | Z3: 產線異常統計 (5分鐘以上) | AD3: 短暫停線統計 (5分鐘以下) | AF3: 產能/時 | AG3: 達成率 | AH3: 達成率平均
T4: 開始 | U4: 結束 | X4: 開始 | Y4: 結束 | Z4: 次數 | AA4: 時間/分 | AD4: 總次數 | AE4: 設備因素(次數)
A5: 自動一線 (ET-600) | B5: 義大利麵 | D5: 白酒清炒鮮蛤義大利麵 | F5: =VLOOKUP(D5,廠價表!$C$1:$E$43,3,0) -> 56.87 | G5: 1905 | H5: =F5*G5 -> 108337.35 | J5: =VLOOKUP(D5,產線配置圖!$A$3:$C$40,2,0) -> 14 | K5: =VLOOKUP(D5,產線配置圖!$A$3:$C$40,3,0) -> 2250 | L5: =K5/J5 -> 160.71429 | M5: 14 | N5: =G5/W5*60 -> 1465.3846 | O5: =N5/M5 -> 104.67033 | P5: =M5-J5 -> 0 | Q5: =O5-L5 -> -56.043956 | R5: =O5/L5 -> 0.65128205 | S5: =R15 -> 0.8066572 | T5: 0.30555556 | U5: 0.35972222 | W5: =(U5-T5)*24*60 -> 78 | Z5: 2 | AA5: 25 | AB5: 7:00-7:20、7:58-8:03玉取機異常 | AF5: =N5-K5 -> -784.61538 | AG5: =N5/K5 -> 0.65128205 | AH5: =AG15 -> 0.80665064
B6: 義大利麵 | D6: 香煎魚排佐檸檬奶油義大利麵 | F6: =VLOOKUP(D6,廠價表!$C$1:$E$43,3,0) -> 58.17 | G6: 2280 | H6: =F6*G6 -> 132627.6 | J6: =VLOOKUP(D6,產線配置圖!$A$3:$C$40,2,0) -> 13 | K6: =VLOOKUP(D6,產線配置圖!$A$3:$C$40,3,0) -> 2250 | L6: =K6/J6 -> 173.07692 | M6: 13 | N6: =G6/W6*60 -> 1824 | O6: =N6/M6 -> 140.30769 | P6: =M6-J6 -> 0 | Q6: =O6-L6 -> -32.769231 | R6: =O6/L6 -> 0.81066667 | T6: 0.36805556 | U6: 0.42013889 | V6: =(T6-U5)*24*60 -> 12 | W6: =(U6-T6)*24*60 -> 75 | AF6: =N6-K6 -> -426 | AG6: =N6/K6 -> 0.81066667
B7: 義大利麵 | D7: 奶油培根義大利麵 | F7: =VLOOKUP(D7,廠價表!$C$1:$E$43,3,0) -> 49.14 | G7: 2476 | H7: =F7*G7 -> 121670.64 | J7: =VLOOKUP(D7,產線配置圖!$A$3:$C$40,2,0) -> 14 | K7: =VLOOKUP(D7,產線配置圖!$A$3:$C$40,3,0) -> 2250 | L7: =K7/J7 -> 160.71429 | M7: 14 | N7: =G7/W7*60 -> 2122.2857 | O7: =N7/M7 -> 151.59184 | P7: =M7-J7 -> 0 | Q7: =O7-L7 -> -9.122449 | R7: =O7/L7 -> 0.9432381 | T7: 0.42847222 | U7: 0.47708333 | V7: =(T7-U6)*24*60 -> 12 | W7: =(U7-T7)*24*60 -> 70 | AF7: =N7-K7 -> -127.71429 | AG7: =N7/K7 -> 0.9432381
B8: 義大利麵 | D8: 奶油培根義大利麵 | F8: =VLOOKUP(D8,廠價表!$C$1:$E$43,3,0) -> 49.14 | G8: 1261 | H8: =F8*G8 -> 61965.54 | J8: =VLOOKUP(D8,產線配置圖!$A$3:$C$40,2,0) -> 14 | K8: =VLOOKUP(D8,產線配置圖!$A$3:$C$40,3,0) -> 2250 | L8: =K8/J8 -> 160.71429 | M8: 14 | N8: =G8/W8*60 -> 1845.3659 | O8: =N8/M8 -> 131.81185 | P8: =M8-J8 -> 0 | Q8: =O8-L8 -> -28.902439 | R8: =O8/L8 -> 0.8201626 | T8: 0.54375 | U8: 0.57222222 | V8: =(T8-U7)*24*60 -> 96 | W8: =(U8-T8)*24*60 -> 41 | AF8: =N8-K8 -> -404.63415 | AG8: =N8/K8 -> 0.8201626
B9: 熱乾麵 | D9: 府城鹽水意麵 | F9: =VLOOKUP(D9,廠價表!$C$1:$E$43,3,0) -> 44.3 | G9: 1058 | H9: =F9*G9 -> 46869.4 | J9: =VLOOKUP(D9,產線配置圖!$A$3:$C$40,2,0) -> 18 | K9: =VLOOKUP(D9,產線配置圖!$A$3:$C$40,3,0) -> 1636 | L9: =K9/J9 -> 90.888889 | M9: 18 | N9: =G9/W9*60 -> 1322.5 | O9: =N9/M9 -> 73.472222 | P9: =M9-J9 -> 0 | Q9: =O9-L9 -> -17.416667 | R9: =O9/L9 -> 0.80837408 | T9: 0.57916667 | U9: 0.6125 | V9: =(T9-U8)*24*60 -> 10 | W9: =(U9-T9)*24*60 -> 48 | AF9: =N9-K9 -> -313.5 | AG9: =N9/K9 -> 0.80837408
W10: =(U10-T10)*24*60 -> 0 | AF10: =N10-K10 -> 0 | AG10: =N10/K10 -> #DIV/0!
W11: =(U11-T11)*24*60 -> 0 | AF11: =N11-K11 -> 0 | AG11: =N11/K11 -> #DIV/0!
W12: =(U12-T12)*24*60 -> 0
W13: =(U13-T13)*24*60 -> 0
W14: =(U14-T14)*24*60 -> 0
C15: 4度一組 | D15: 平均 | J15: =AVERAGE(J5:J14) -> 14.6 | K15: =AVERAGE(K5:K14) -> 2127.2 | L15: =AVERAGE(L5:L14) -> 149.22173 | M15: =AVERAGE(M5:M14) -> 14.6 | N15: =AVERAGE(N5:N14) -> 1715.9072 | O15: =AVERAGE(O5:O14) -> 120.37079 | P15: =M15-J15 -> 0 | Q15: =O15-L15 -> -28.850948 | R15: =O15/L15 -> 0.8066572 | Z15: =SUM(Z5:Z14) -> 2 | AA15: =SUM(AA5:AA14) -> 25 | AD15: =SUM(AD5:AD14) -> 0 | AE15: =SUM(AE5:AE14) -> 0 | AF15: =N15-K15 -> -411.29276 | AG15: =N15/K15 -> 0.80665064
A16: 自動二線 (ET-600) | B16: 義大利麵 | D16: 白酒清炒鮮蛤義大利麵 | F16: =VLOOKUP(D16,廠價表!$C$1:$E$43,3,0) -> 56.87 | G16: 2003 | H16: =F16*G16 -> 113910.61 | J16: =VLOOKUP(D16,產線配置圖!$A$3:$C$40,2,0) -> 14 | K16: =VLOOKUP(D16,產線配置圖!$A$3:$C$40,3,0) -> 2250 | L16: =K16/J16 -> 160.71429 | M16: 14 | N16: =G16/W16*60 -> 1465.6098 | O16: =N16/M16 -> 104.68641 | P16: =M16-J16 -> 0 | Q16: =O16-L16 -> -56.027875 | R16: =O16/L16 -> 0.65138211 | S16: =R26 -> 0.86394274 | T16: 0.29861111 | U16: 0.35555556 | W16: =(U16-T16)*24*60 -> 82 | Z16: 2 | AA16: 25 | AB16: 7:00-7:20、7:58-8:03玉取機異常 | AF16: =N16-K16 -> -784.39024 | AG16: =N16/K16 -> 0.65138211 | AH16: =AG26 -> 0.86022064
B17: 義大利麵 | D17: 青醬蛤蜊義大利麵 | F17: =VLOOKUP(D17,廠價表!$C$1:$E$43,3,0) -> 50.67 | G17: 3245 | H17: =F17*G17 -> 164424.15 | J17: 14 | K17: =VLOOKUP(D17,產線配置圖!$A$3:$C$40,3,0) -> 2250 | L17: =K17/J17 -> 160.71429 | M17: 14 | N17: =G17/W17*60 -> 2187.6404 | O17: =N17/M17 -> 156.26003 | P17: =M17-J17 -> 0 | Q17: =O17-L17 -> -4.4542536 | R17: =O17/L17 -> 0.97228464 | T17: 0.36388889 | U17: 0.42569444 | V17: =(T17-U16)*24*60 -> 12 | W17: =(U17-T17)*24*60 -> 89 | AB17: 秤蛤蠣+1人 | AF17: =N17-K17 -> -62.359551 | AG17: =N17/K17 -> 0.97228464
B18: 義大利麵 | D18: 義式蕃茄起司義大利麵 | F18: =VLOOKUP(D18,廠價表!$C$1:$E$43,3,0) -> 50.39 | G18: 2014 | H18: =F18*G18 -> 101485.46 | J18: =VLOOKUP(D18,產線配置圖!$A$3:$C$40,2,0) -> 12 | K18: =VLOOKUP(D18,產線配置圖!$A$3:$C$40,3,0) -> 2250 | L18: =K18/J18 -> 187.5 | M18: 12 | N18: =G18/W18*60 -> 2048.1356 | O18: =N18/M18 -> 170.67797 | P18: =M18-J18 -> 0 | Q18: =O18-L18 -> -16.822034 | R18: =O18/L18 -> 0.91028249 | T18: 0.43611111 | U18: 0.47708333 | V18: =(T18-U17)*24*60 -> 15 | W18: =(U18-T18)*24*60 -> 59 | AF18: =N18-K18 -> -201.86441 | AG18: =N18/K18 -> 0.91028249
B19: 義大利麵 | D19: 義式蕃茄起司義大利麵 | F19: =VLOOKUP(D19,廠價表!$C$1:$E$43,3,0) -> 50.39 | G19: 3401 | H19: =F19*G19 -> 171376.39 | J19: =VLOOKUP(D19,產線配置圖!$A$3:$C$40,2,0) -> 12 | K19: =VLOOKUP(D19,產線配置圖!$A$3:$C$40,3,0) -> 2250 | L19: =K19/J19 -> 187.5 | M19: 12 | N19: =G19/W19*60 -> 2040.6 | O19: =N19/M19 -> 170.05 | P19: =M19-J19 -> 0 | Q19: =O19-L19 -> -17.45 | R19: =O19/L19 -> 0.90693333 | T19: 0.54166667 | U19: 0.61111111 | V19: =(T19-U18)*24*60 -> 93 | W19: =(U19-T19)*24*60 -> 100 | AF19: =N19-K19 -> -209.4 | AG19: =N19/K19 -> 0.90693333
W20: =(U20-T20)*24*60 -> 0
W21: =(U21-T21)*24*60 -> 0
W22: 0
W23: =(U23-T23)*24*60 -> 0
W24: =(U24-T24)*24*60 -> 0
H25: =F25*G25 -> 0 | W25: =(U25-T25)*24*60 -> 0
C26: 4度二組A | D26: 平均 | J26: =AVERAGE(J16:J25) -> 13 | K26: =AVERAGE(K16:K25) -> 2250 | L26: =AVERAGE(L16:L25) -> 174.10714 | M26: =AVERAGE(M16:M25) -> 13 | N26: =AVERAGE(N16:N25) -> 1935.4964 | O26: =AVERAGE(O16:O25) -> 150.4186 | P26: =M26-J26 -> 0 | Q26: =O26-L26 -> -23.688541 | R26: =O26/L26 -> 0.86394274 | Z26: =SUM(Z16:Z25) -> 2 | AA26: =SUM(AA16:AA25) -> 25 | AD26: =SUM(AD16:AD25) -> 0 | AE26: =SUM(AE16:AE25) -> 0 | AF26: =N26-K26 -> -314.50355 | AG26: =N26/K26 -> 0.86022064
A27: 手工三線 (ET-55) | B27: 義大利麵 | D27: 金沙豆腐義大利麵 | F27: =VLOOKUP(D27,廠價表!$C$1:$E$43,3,0) -> 49.91 | G27: 1004 | H27: =F27*G27 -> 50109.64 | J27: =VLOOKUP(D27,產線配置圖!$A$3:$C$40,2,0) -> 18 | K27: 1636 | L27: =K27/J27 -> 90.888889 | M27: 17 | N27: =G27/W27*60 -> 1434.2857 | O27: =N27/M27 -> 84.369748 | P27: =M27-J27 -> -1 | Q27: =O27-L27 -> -6.519141 | R27: =O27/L27 -> 0.92827351 | S27: =R37 -> 0.89434619 | T27: 0.29166667 | U27: 0.32083333 | W27: =(U27-T27)*24*60 -> 42 | AF27: =N27-K27 -> -201.71429 | AG27: =N27/K27 -> 0.87670276 | AH27: =AG37 -> 0.87414001
B28: 義大利麵 | D28: 奶油鮮蝦明太子細扁麵 | F28: =VLOOKUP(D28,廠價表!$C$1:$E$43,3,0) -> 57.21 | G28: 1320 | H28: =F28*G28 -> 75517.2 | J28: =VLOOKUP(D28,產線配置圖!$A$3:$C$40,2,0) -> 18 | K28: =VLOOKUP(D28,產線配置圖!$A$3:$C$40,3,0) -> 1636 | L28: =K28/J28 -> 90.888889 | M28: 17 | N28: =G28/W28*60 -> 1365.5172 | O28: =N28/M28 -> 80.324544 | P28: =M28-J28 -> -1 | Q28: =O28-L28 -> -10.564345 | R28: =O28/L28 -> 0.88376637 | T28: 0.32777778 | U28: 0.36805556 | V28: =(T28-U27)*24*60 -> 10 | W28: =(U28-T28)*24*60 -> 58 | AF28: =N28-K28 -> -270.48276 | AG28: =N28/K28 -> 0.83466824
B29: 義大利麵 | D29: 義式蛋蛋青醬鮪魚冷義大利麵 | F29: =VLOOKUP(D29,廠價表!$C$1:$E$43,3,0) -> 45.66 | G29: 1204 | H29: =F29*G29 -> 54974.64 | J29: =VLOOKUP(D29,產線配置圖!$A$3:$C$40,2,0) -> 17 | K29: =VLOOKUP(D29,產線配置圖!$A$3:$C$40,3,0) -> 1636 | L29: =K29/J29 -> 96.235294 | M29: 17 | N29: =G29/W29*60 -> 1389.2308 | O29: =N29/M29 -> 81.719457 | P29: =M29-J29 -> 0 | Q29: =O29-L29 -> -14.515837 | R29: =O29/L29 -> 0.84916306 | T29: 0.37361111 | U29: 0.40972222 | V29: =(T29-U28)*24*60 -> 8 | W29: =(U29-T29)*24*60 -> 52 | AF29: =N29-K29 -> -246.76923 | AG29: =N29/K29 -> 0.84916306
B30: 義大利麵 | D30: 番茄蘑菇義大利麵 | F30: =VLOOKUP(D30,廠價表!$C$1:$E$43,3,0) -> 43.89 | G30: 1016 | H30: =F30*G30 -> 44592.24 | J30: 15 | K30: =VLOOKUP(D30,產線配置圖!$A$3:$C$40,3,0) -> 1565 | L30: =K30/J30 -> 104.33333 | M30: 15 | N30: =G30/W30*60 -> 1385.4545 | O30: =N30/M30 -> 92.363636 | P30: =M30-J30 -> 0 | Q30: =O30-L30 -> -11.969697 | R30: =O30/L30 -> 0.88527447 | T30: 0.41597222 | U30: 0.44652778 | V30: =(T30-U29)*24*60 -> 9 | W30: =(U30-T30)*24*60 -> 44 | AF30: =N30-K30 -> -179.54545 | AG30: =N30/K30 -> 0.88527447
