Workbook

Sheet 廠價表
A1: check | B1: 溫層 | C1: 品名 | D1: 類別 | E1: 廠價
B2: 4度C | C2: 奶油鮮蝦明太子細扁麵 | D2: 義大利麵 | E2: 57.21
B3: 4度C | C3: 白酒清炒鮮蛤義大利麵 | D3: 義大利麵 | E3: 56.87
B4: 4度C | C4: 義式蕃茄起司義大利麵 | D4: 義大利麵 | E4: 50.39
B5: 4度C | C5: 焗烤起司雙饗筆尖麵 | D5: 義大利麵 | E5: 49.97
B6: 4度C | C6: 奶油培根義大利麵 | D6: 義大利麵 | E6: 49.14
B7: 4度C | C7: 香煎魚排佐檸檬奶油義大利麵 | D7: 義大利麵 | E7: 58.17
B8: 4度C | C8: 青醬蛤蜊義大利麵 | D8: 義大利麵 | E8: 50.67
B9: 4度C | C9: 金沙豆腐義大利麵 | D9: 義大利麵 | E9: 49.91
B10: 4度C | C10: 黑松露野菇義大利麵 | D10: 義大利麵 | E10: 50.289
B11: 4度C | C11: 蒜香奶油蝦蝦義大利麵 | D11: 義大利麵 | E11: 57.21
B12: 4度C | C12: 鱈魚粉紅青醬筆尖麵 | D12: 義大利麵 | E12: 43.89
B13: 4度C | C13: 羅馬黑胡椒起司義大利麵 | D13: 義大利麵 | E13: 50.67
... B19: 4度C | C19: 番茄蘑菇義大利麵 | D19: 義大利麵 | E19: 43.89
B20: 4度C | D20: 義大利麵
B21: 4度C | D21: 義大利麵
B22: 4度C | D22: 義大利麵
B23: 4度C | C23: 韓式炒冬粉 | D23: 小吃、微波 | E23: 28.26
B24: 4度C | C24: 小滷青蔬 | D24: 小吃、微波 | E24: 26.99
B25: 4度C | C25: 起司馬鈴薯 | D25: 小吃、微波 | E25: 28.26
B26: 4度C | C26: 麻辣雞心 | D26: 小吃、微波 | E26: 28.26
B46: 冷凍 | C46: 青醬蛤蜊義大利麵 | D46: 冷凍調理麵 | E46: 29.38
B47: 冷凍 | C47: 經典肉醬義大利麵 | D47: 冷凍調理麵 | E47: 29.38
B48: 冷凍 | C48: 奶油蘑菇培根義大利麵 | D48: 冷凍調理麵 | E48: 29.38
B49: 冷凍 | C49: 清炒蛤蜊義大利麵 | D49: 冷凍調理麵 | E49: 29.38
B50: 冷凍 | C50: 青醬乳酪筆尖麵 | D50: 冷凍調理麵 | E50: 29.38
B51: 冷凍 | C51: 辣蕃茄義大利麵 | D51: 冷凍調理麵 | E51: 29.38
B52: 冷凍 | D52: 冷凍調理麵
B53: 冷凍 | C53: 韓式起司義大利麵 | D53: 冷凍調理麵 | E53: 29.38
B54: 冷凍 | D54: 冷凍調理麵
B55: 冷凍 | C55: 和風明太子細扁麵 | D55: 冷凍調理麵 | E55: 29.38

Sheet 產線配置圖
A1: 品項 | B1: 人數 | C1: 產能 | E1: 人時 | G1: 備註
A2: 義大利麵
A3: 白酒清炒鮮蛤義大利麵 | B3: 15 | C3: 2250 | D3: ET-600 | E3: =C3/B3 -> 150
A4: 白酒清炒鮮蛤義大利麵-手 | B4: 15 | C4: 1716 | D4: ET-55 | E4: =C4/B4 -> 114.4
A5: 青醬蛤蜊義大利麵 | B5: 13 | C5: 2250 | E5: =C5/B5 -> 173.07692
A6: 青醬蛤蜊義大利麵-手 | B6: 16 | C6: 1714 | E6: =C6/B6 -> 107.125
A7: 義式蕃茄起司義大利麵 | B7: 12 | C7: 2250 | E7: =C7/B7 -> 187.5
A8: 奶油培根義大利麵 | B8: 15 | C8: 2250 | E8: =C8/B8 -> 150
A9: 蒜香奶油蝦蝦義大利麵 | B9: 17 | C9: 2250 | E9: =C9/B9 -> 132.35294
A10: 蒜香奶油蝦蝦義大利麵-手 | B10: 17 | C10: 1716 | E10: =C10/B10 -> 100.94118
A11: 鱈魚粉紅青醬筆尖麵 | B11: 14 | C11: 1565 | E11: =C11/B11 -> 111.78571
A12: 香煎魚排佐檸檬奶油義大利麵 | B12: 13 | C12: 2250 | E12: =C12/B12 -> 173.07692
A13: 黑松露野菇義大利麵 | B13: 17 | C13: 1636 | E13: =C13/B13 -> 96.235294 | J13: 黑松露野菇義大利麵 | K13: 17 | L13: 1565 | N13: =L13/K13 -> 92.058824
A14: 青花椒麻雞肉拌麵 | B14: 16 | C14: 1714 | E14: =C14/B14 -> 107.125 | J14: 青花椒麻雞肉拌麵 | K14: 14 | L14: 1714 | N14: =L14/K14 -> 122.42857
A15: 焗烤起司雙饗筆尖麵 | B15: 16 | C15: 1800 | E15: =C15/B15 -> 112.5 | G15: 目前使用手工 | J15: 焗烤起司雙饗筆尖麵 | K15: 15 | L15: 1800 | N15: =L15/K15 -> 120
A16: 沙茶豬肉炒麵 | B16: 17 | C16: 1800 | E16: =C16/B16 -> 105.88235 | J16: 沙茶豬肉炒麵 | K16: 16 | L16: 1500 | N16: =L16/K16 -> 93.75
A17: 府城鹽水意麵 | B17: 18 | C17: 1636 | E17: =C17/B17 -> 90.888889 | J17: 府城鹽水意麵 | K17: 16 | L17: 1636 | N17: =L17/K17 -> 102.25
A18: 羅馬黑胡椒起司義大利麵 | B18: 17 | C18: 2250 | E18: =C18/B18 -> 132.35294 | J18: 焗烤起司肉醬筆尖麵 | K18: 12 | L18: 1440 | N18: =L18/K18 -> 120
A19: 羅馬黑胡椒起司義大利麵-自動 | B19: 14 | C19: 2250 | E19: =C19/B19 -> 160.71429 | G19: 目前使用雙排 | J19: 整條德式香腸義大利麵 | K19: 16 | L19: 1565 | N19: =L19/K19 -> 97.8125
A20: 義式蛋蛋青醬鮪魚冷義大利麵 | B20: 17 | C20: 1636 | E20: =C20/B20 -> 96.235294
A21: 蕃茄莎莎海鮮冷義大利麵 | B21: 16 | C21: 1636 | E21: =C21/B21 -> 102.25
A22: 金沙豆腐義大利麵 | B22: 18 | C22: 2250 | E22: =C22/B22 -> 125
A23: 奶油鮮蝦明太子細扁麵 | B23: 18 | C23: 1636
A24: 番茄蘑菇義大利麵 | B24: 13 | C24: 1565
A26: 調理包
A27: 小滷青蔬 | B27: 15 | C27: 1636 | E27: =C27/B27 -> 109.06667 | G27: 夏季+1人補料
A28: 起司馬鈴薯 | B28: 11 | C28: 1636 | E28: =C28/B28 -> 148.72727
A29: 麻辣雞心 | B29: 11 | C29: 1636 | E29: =C29/B29 -> 148.72727
A30: 韓式炒冬粉 | B30: 11 | C30: 1636 | E30: =C30/B30 -> 148.72727
E34: 更新日期07/03

Sheet 範本總
B1: 長家廠組合室生產人時性分析
B3: 日期 | D3: 46015 | F3: 訂單量 | G3: =範本!E1 -> 43309 | I3: 營業額 | J3: =範本!G1 -> #N/A
B4: 項目 | D4: 3 | F4: ➀ | H4: ➁ | J4: ③ | L4: 異常停線 | N4: 短暫停線
B5: 人時性 | D5: 組合室 | F5: 全溫層 | H5: 義大利麵 | J5: 袋裝小吃、義麵 | L5: 合計次數 | M5: 時間 | N5: 合計次數 | O5: 設備次數
D6: 排關平均 | F6: =AVERAGE(D13:J13) -> #N/A | H6: =AVERAGE(D13:H13) -> #N/A | J6: =AVERAGE(I13:J13) -> #N/A | L6: =範本!Z2 -> 0 | M6: =範本!AA2 -> 0 | N6: =範本!AD2 -> 0 | O6: =範本!AE2 -> 0
D7: 實績平均 | F7: =AVERAGE(D14:J14) -> 116.11475 | H7: =AVERAGE(D14:H14) -> 117.36075 | J7: =AVERAGE(I14:J14) -> 112.99975
D8: 達成率平均 | F8: =AVERAGE(D15:J15) -> #N/A | H8: =AVERAGE(D15:H15) -> #N/A | J8: =AVERAGE(I15:J15) -> #N/A
J9: ※現行日本鮮食廠以達成率80%為基本(即為現行KPI)
B10: 溫層 | D10: 4度C-各編組展開
B11: 編組 | D11: 1 | E11: 2 | F11: 3 | G11: 4 | H11: 5 | I11: 6 | J11: 7
D12: 自動1線 | E12: 自動2線 | F12: 手工3線 | G12: 手工4線 | H12: 手工5線 | I12: 調理包1線 | J12: 調理包2線
B13: 人時性 | C13: 排關 | D13: =VALUE(範本!L15) -> #N/A | E13: =VALUE(範本!L26) -> #N/A | F13: =VALUE(範本!L37) -> #N/A | G13: =VALUE(範本!L48) -> #N/A | H13: =VALUE(範本!L58) -> #N/A | I13: =VALUE(範本!L69) -> #N/A | J13: =範本!L79 -> #N/A
C14: 實績 | D14: =VALUE(範本!O15) -> 113.91637 | E14: =VALUE(範本!O26) -> 132.12003 | F14: =VALUE(範本!O37) -> 126.23842 | G14: =VALUE(範本!O48) -> 112.0543 | H14: =VALUE(範本!O58) -> 102.47462 | I14: =VALUE(範本!O69) -> 155.46443 | J14: =範本!O79 -> 70.535065
C15: 達成率 | D15: =D14/D13 -> #N/A | E15: =E14/E13 -> #N/A | F15: =F14/F13 -> #N/A | G15: =G14/G13 -> #N/A | H15: =H14/H13 -> #N/A | I15: =I14/I13 -> #N/A | J15: =範本!S70 -> #N/A
B16: 作業 時間 | C16: 開始 | D16: =範本!T5 -> 0.29097222 | E16: =範本!T16 -> 0.29097222 | F16: =範本!T27 -> 0.29166667 | G16: =範本!T38 -> 0.33333333 | H16: =範本!T49 -> 0.29166667 | I16: =範本!T59 -> 0.29166667 | J16: =範本!T70 -> 0.34722222
C17: 結束 | D17: 0.47361111 | E17: 0.48263889 | F17: 0.56944444 | G17: 0.60416667 | H17: 0.58333333 | I17: 0.48819444 | J17: 0.46875
B18: 產線異常 (5分鐘以上) | C18: 次數
C19: 時間/分
B20: 短暫停線 (5分鐘以下) | C20: 次數
C21: 設備次數
B22: 配置人數 | D22: =VALUE(範本!M15) -> 15 | E22: =VALUE(範本!M26) -> 12.666667 | F22: =VALUE(範本!M37) -> 14.666667 | G22: =VALUE(範本!M48) -> 14 | H22: =VALUE(範本!M58) -> 17.666667 | I22: =VALUE(範本!M69) -> 12.333333 | J22: =範本!M79 -> 11
B23: 主要應用設備 | D23: ET-600 | E23: ET-600 | F23: ET-55 | G23: ET-55 | H23: ET-55 | I23: 八爪機
B24: 次要應用設備 | H24: 封口機
B25: 備註

Sheet 範本
A1: 長家廠4度C日報分析 | D1: 總生產量 | E1: =SUM(G5:G79) -> 43309 | F1: 營業額 | G1: =SUM(H5:H79) -> #N/A | H1: 出勤人數 | I1: =M15+M26+M48+M58+M69+M79+M37 -> 97.333333 | J1: 產線配置圖 | M1: 生產實績 | P1: 人時性差異分析 | T1: 日報登錄 | Z1: 合計 次數 | AA1: 合計 時間/分 | AB1: 分析說明 | AD1: 合計 次數 | AE1: 合計 設備次數 | AF1: 產能差異分析
A2: 12月24日 星期三 | D2: 人時性 | E2: =AVERAGE(O15,O26,O37,O48,O58,O69,O79) -> 116.11475 | F2: 平均廠價 | G2: =G1/E1 -> #N/A | H2: 多次生產數 | I2: =COUNT(I5:I79) -> 0 | Z2: =Z15+Z26+Z37+Z48+Z58+Z69+Z79 -> 0 | AA2: =AA15+AA26+AA37+AA48+AA58+AA69+AA79 -> 0 | AD2: =AD15+AD26+AD37+AD48+AD58+AD69+AD79 -> 0 | AE2: =AE15+AE26+AE37+AE48+AE58+AE69+AE79 -> 0
A3: 線別 | B3: 品類 | D3: 品名 | F3: 廠價 | G3: 生產量 | H3: 營收 | I3: 多次 生產 | J3: 人數 | K3: 產能/時 | L3: 人時性 | M3: 人數 | N3: 產能/時 | O3: 人時性 | P3: 人數 | Q3: 人時性 | R3: 達成率 | S3: 達成率平均 | T3: 生產時間 | V3: 前置、換線時間/分 | W3: 稼動時間/分 | X3: 休息時間 | Z3: 產線異常統計 (5分鐘以上) | AD3: 短暫停線統計 (5分鐘以下) | AF3: 產能/時 | AG3: 達成率 | AH3: 達成率平均
T4: 開始 | U4: 結束 | X4: 開始 | Y4: 結束 | Z4: 次數 | AA4: 時間/分 | AD4: 總次數 | AE4: 設備因素(次數)
A5: 自動一線 (ET-600) | B5: =VLOOKUP(D5,廠價表!$C$1:$E$43,2,0) -> #N/A | F5: =VLOOKUP(D5,廠價表!$C$1:$E$43,3,0) -> #N/A | G5: 2263 | H5: =F5*G5 -> #N/A | J5: =VLOOKUP(D5,產線配置圖!$A$3:$C$40,2,0) -> #N/A | K5: =VLOOKUP(D5,產線配置圖!$A$3:$C$40,3,0) -> #N/A | L5: =K5/J5 -> #N/A | M5: 15 | N5: =G5/W5*60 -> 1444.4681 | O5: =N5/M5 -> 96.297872 | P5: =M5-J5 -> #N/A | Q5: =O5-L5 -> #N/A | R5: =O5/L5 -> #N/A | S5: =R15 -> #N/A | T5: 0.29097222 | U5: 0.35625 | W5: =(U5-T5)*24*60 -> 94 | AF5: =N5-K5 -> #N/A | AG5: =N5/K5 -> #N/A | AH5: =AG15 -> #N/A
B6: =VLOOKUP(D6,廠價表!$C$1:$E$43,2,0) -> #N/A | F6: =VLOOKUP(D6,廠價表!$C$1:$E$43,3,0) -> #N/A | G6: 1180 | H6: =F6*G6 -> #N/A | J6: =VLOOKUP(D6,產線配置圖!$A$3:$C$40,2,0) -> #N/A | K6: =VLOOKUP(D6,產線配置圖!$A$3:$C$40,3,0) -> #N/A | L6: =K6/J6 -> #N/A | M6: 17 | N6: =G6/W6*60 -> 1609.0909 | O6: =N6/M6 -> 94.652406 | P6: =M6-J6 -> #N/A | Q6: =O6-L6 -> #N/A | R6: =O6/L6 -> #N/A | T6: 0.36458333 | U6: 0.39513889 | V6: =(T6-U5)*24*60 -> 12 | W6: =(U6-T6)*24*60 -> 44 | AF6: =N6-K6 -> #N/A | AG6: =N6/K6 -> #N/A
B7: =VLOOKUP(D7,廠價表!$C$1:$E$43,2,0) -> #N/A | F7: =VLOOKUP(D7,廠價表!$C$1:$E$43,3,0) -> #N/A | G7: 3398 | H7: =F7*G7 -> #N/A | J7: =VLOOKUP(D7,產線配置圖!$A$3:$C$40,2,0) -> #N/A | K7: =VLOOKUP(D7,產線配置圖!$A$3:$C$40,3,0) -> #N/A | L7: =K7/J7 -> #N/A | M7: 13 | N7: =G7/W7*60 -> 1960.3846 | O7: =N7/M7 -> 150.79882 | P7: =M7-J7 -> #N/A | Q7: =O7-L7 -> #N/A | R7: =O7/L7 -> #N/A | T7: 0.40138889 | U7: 0.47361111 | V7: =(T7-U6)*24*60 -> 9 | W7: =(U7-T7)*24*60 -> 104 | AF7: =N7-K7 -> #N/A | AG7: =N7/K7 -> #N/A
W8: =(U8-T8)*24*60 -> 0 | X8: 0.48611111 | Y8: 0.52777778 | AF8: =N8-K8 -> 0 | AG8: =N8/K8 -> #DIV/0!
W9: =(U9-T9)*24*60 -> 0 | AF9: =N9-K9 -> 0 | AG9: =N9/K9 -> #DIV/0!
W10: =(U10-T10)*24*60 -> 0 | AF10: =N10-K10 -> 0 | AG10: =N10/K10 -> #DIV/0!
W11: =(U11-T11)*24*60 -> 0 | AF11: =N11-K11 -> 0 | AG11: =N11/K11 -> #DIV/0!
W12: =(U12-T12)*24*60 -> 0
W13: =(U13-T13)*24*60 -> 0
W14: =(U14-T14)*24*60 -> 0
C15: 4度一組 | D15: 平均 | J15: =AVERAGE(J5:J14) -> #N/A | K15: =AVERAGE(K5:K14) -> #N/A | L15: =AVERAGE(L5:L14) -> #N/A | M15: =AVERAGE(M5:M14) -> 15 | N15: =AVERAGE(N5:N14) -> 1671.3145 | O15: =AVERAGE(O5:O14) -> 113.91637 | P15: =M15-J15 -> #N/A | Q15: =O15-L15 -> #N/A | R15: =O15/L15 -> #N/A | Z15: =SUM(Z5:Z14) -> 0 | AA15: =SUM(AA5:AA14) -> 0 | AD15: =SUM(AD5:AD14) -> 0 | AE15: =SUM(AE5:AE14) -> 0 | AF15: =N15-K15 -> #N/A | AG15: =N15/K15 -> #N/A
A16: 自動二線 (ET-600) | B16: =VLOOKUP(D16,廠價表!$C$1:$E$43,2,0) -> #N/A | F16: =VLOOKUP(D16,廠價表!$C$1:$E$43,3,0) -> #N/A | G16: 2263 | H16: =F16*G16 -> #N/A | J16: =VLOOKUP(D16,產線配置圖!$A$3:$C$40,2,0) -> #N/A | K16: =VLOOKUP(D16,產線配置圖!$A$3:$C$40,3,0) -> #N/A | L16: =K16/J16 -> #N/A | M16: 13 | N16: =G16/W16*60 -> 2225.9016 | O16: =N16/M16 -> 171.2232 | P16: =M16-J16 -> #N/A | Q16: =O16-L16 -> #N/A | R16: =O16/L16 -> #N/A | S16: =R26 -> #N/A | T16: 0.29097222 | U16: 0.33333333 | W16: =(U16-T16)*24*60 -> 61 | AF16: =N16-K16 -> #N/A | AG16: =N16/K16 -> #N/A | AH16: =AG26 -> #N/A
B17: =VLOOKUP(D17,廠價表!$C$1:$E$43,2,0) -> #N/A | F17: =VLOOKUP(D17,廠價表!$C$1:$E$43,3,0) -> #N/A | G17: 1180 | H17: =F17*G17 -> #N/A | J17: =VLOOKUP(D17,產線配置圖!$A$3:$C$40,2,0) -> #N/A | K17: =VLOOKUP(D17,產線配置圖!$A$3:$C$40,3,0) -> #N/A | L17: =K17/J17 -> #N/A | M17: 13 | N17: =G17/W17*60 -> 823.25581 | O17: =N17/M17 -> 63.32737 | P17: =M17-J17 -> #N/A | Q17: =O17-L17 -> #N/A | R17: =O17/L17 -> #N/A | T17: 0.34166667 | U17: 0.40138889 | V17: =(T17-U16)*24*60 -> 12 | W17: =(U17-T17)*24*60 -> 86 | AF17: =N17-K17 -> #N/A | AG17: =N17/K17 -> #N/A
B18: =VLOOKUP(D18,廠價表!$C$1:$E$43,2,0) -> #N/A | F18: =VLOOKUP(D18,廠價表!$C$1:$E$43,3,0) -> #N/A | G18: 3398 | H18: =F18*G18 -> #N/A | J18: =VLOOKUP(D18,產線配置圖!$A$3:$C$40,2,0) -> #N/A | K18: =VLOOKUP(D18,產線配置圖!$A$3:$C$40,3,0) -> #N/A | L18: =K18/J18 -> #N/A | M18: 12 | N18: =G18/W18*60 -> 1941.7143 | O18: =N18/M18 -> 161.80952 | P18: =M18-J18 -> #N/A | Q18: =O18-L18 -> #N/A | R18: =O18/L18 -> #N/A | T18: 0.40972222 | U18: 0.48263889 | V18: =(T18-U17)*24*60 -> 12 | W18: =(U18-T18)*24*60 -> 105 | X18: 0.48611111 | Y18: 0.52777778 | AF18: =N18-K18 -> #N/A | AG18: =N18/K18 -> #N/A
V19: =(T19-U18)*24*60 -> -695 | W19: =(U19-T19)*24*60 -> 0 | AF19: =N19-K19 -> 0 | AG19: =N19/K19 -> #DIV/0!
V20: =(T20-U19)*24*60 -> 0 | W20: =(U20-T20)*24*60 -> 0
W21: =(U21-T21)*24*60 -> 0
W22: 0
W23: =(U23-T23)*24*60 -> 0
H24: =F24*G24 -> 0 | W24: =(U24-T24)*24*60 -> 0
H25: =F25*G25 -> 0 | W25: =(U25-T25)*24*60 -> 0
C26: 4度二組A | D26: 平均 | J26: =AVERAGE(J16:J25) -> #N/A | K26: =AVERAGE(K16:K25) -> #N/A | L26: =AVERAGE(L16:L25) -> #N/A | M26: =AVERAGE(M16:M25) -> 12.666667 | N26: =AVERAGE(N16:N25) -> 1663.6239 | O26: =AVERAGE(O16:O25) -> 132.12003 | P26: =M26-J26 -> #N/A | Q26: =O26-L26 -> #N/A | R26: =O26/L26 -> #N/A | Z26: =SUM(Z16:Z25) -> 0 | AA26: =SUM(AA16:AA25) -> 0 | AD26: =SUM(AD16:AD25) -> 0 | AE26: =SUM(AE16:AE25) -> 0 | AF26: =N26-K26 -> #N/A | AG26: =N26/K26 -> #N/A
A27: 手工三線 (ET-55) | B27: =VLOOKUP(D27,廠價表!$C$1:$E$43,2,0) -> #N/A | F27: =VLOOKUP(D27,廠價表!$C$1:$E$43,3,0) -> #N/A | G27: 2263 | H27: =F27*G27 -> #N/A | J27: =VLOOKUP(D27,產線配置圖!$A$3:$C$40,2,0) -> #N/A | K27: =VLOOKUP(D27,產線配置圖!$A$3:$C$40,3,0) -> #N/A | L27: =K27/J27 -> #N/A | M27: 14 | N27: =G27/W27*60 -> 1212.3214 | O27: =N27/M27 -> 86.594388 | P27: =M27-J27 -> #N/A | Q27: =O27-L27 -> #N/A | R27: =O27/L27 -> #N/A | S27: =R37 -> #N/A | T27: 0.29166667 | U27: 0.36944444 | W27: =(U27-T27)*24*60 -> 112 | AF27: =N27-K27 -> #N/A | AG27: =N27/K27 -> #N/A | AH27: =AG37 -> #N/A
B28: =VLOOKUP(D28,廠價表!$C$1:$E$43,2,0) -> #N/A | F28: =VLOOKUP(D28,廠價表!$C$1:$E$43,3,0) -> #N/A | G28: 1180 | H28: =F28*G28 -> #N/A | J28: =VLOOKUP(D28,產線配置圖!$A$3:$C$40,2,0) -> #N/A | K28: =VLOOKUP(D28,產線配置圖!$A$3:$C$40,3,0) -> #N/A | L28: =K28/J28 -> #N/A | M28: 16 | N28: =G28/W28*60 -> 1089.2308 | O28: =N28/M28 -> 68.076923 | P28: =M28-J28 -> #N/A | Q28: =O28-L28 -> #N/A | R28: =O28/L28 -> #N/A | T28: 0.375 | U28: 0.42013889 | V28: =(T28-U27)*24*60 -> 8 | W28: =(U28-T28)*24*60 -> 65 | AF28: =N28-K28 -> #N/A | AG28: =N28/K28 -> #N/A
B29: =VLOOKUP(D29,廠價表!$C$1:$E$43,2,0) -> #N/A | F29: =VLOOKUP(D29,廠價表!$C$1:$E$43,3,0) -> #N/A | G29: 3398 | H29: =F29*G29 -> #N/A | J29: =VLOOKUP(D29,產線配置圖!$A$3:$C$40,2,0) -> #N/A | K29: =VLOOKUP(D29,產線配置圖!$A$3:$C$40,3,0) -> #N/A | L29: =K29/J29 -> #N/A | M29: 14 | N29: =G29/W29*60 -> 3136.6154 | O29: =N29/M29 -> 224.04396 | P29: =M29-J29 -> #N/A | Q29: =O29-L29 -> #N/A | R29: =O29/L29 -> #N/A | T29: 0.43055556 | U29: 0.47569444 | V29: =(T29-U28)*24*60 -> 15 | W29: =(U29-T29)*24*60 -> 65 | AF29: =N29-K29 -> #N/A | AG29: =N29/K29 -> #N/A
T30: 0.53958333 | U30: 0.56944444 | V30: =(T30-U29)*24*60 -> 92 | W30: =(U30-T30)*24*60 -> 43 | X30: 0.49652778 | Y30: 0.53819444 | AF30: =N30-K30 -> 0 | AG30: =N30/K30 -> #DIV/0!
W31: =(U31-T31)*24*60 -> 0 | AF31: =N31-K31 -> 0 | AG31: =N31/K31 -> #DIV/0!
W32: =(U32-T32)*24*60 -> 0
W33: =(U33-T33)*24*60 -> 0
W34: =(U34-T34)*24*60 -> 0
W35: =(U35-T35)*24*60 -> 0
H36: =F36*G36 -> 0 | W36: =(U36-T36)*24*60 -> 0
C37: 4度二組B | D37: 平均 | J37: =AVERAGE(J27:J36) -> #N/A | K37: =AVERAGE(K27:K36) -> #N/A | L37: =AVERAGE(L27:L36) -> #N/A | M37: =AVERAGE(M27:M36) -> 14.666667 | N37: =AVERAGE(N27:N36) -> 1812.7225 | O37: =AVERAGE(O27:O36) -> 126.23842 | P37: =M37-J37 -> #N/A | Q37: =N37-K37 -> #N/A | R37: =O37/L37 -> #N/A | Z37: =SUM(Z27:Z36) -> 0 | AA37: =SUM(AA27:AA36) -> 0 | AD37: =SUM(AD27:AD36) -> 0 | AE37: =SUM(AE27:AE36) -> 0 | AF37: =N37-K37 -> #N/A | AG37: =N37/K37 -> #N/A
A38: 手工四線 (ET-55) | B38: =VLOOKUP(D38,廠價表!$C$1:$E$43,2,0) -> #N/A | F38: =VLOOKUP(D38,廠價表!$C$1:$E$43,3,0) -> #N/A | G38: 2263 | H38: =F38*G38 -> #N/A | J38: =VLOOKUP(D38,產線配置圖!$A$3:$C$40,2,0) -> #N/A | K38: =VLOOKUP(D38,產線配置圖!$A$3:$C$40,3,0) -> #N/A | L38: =K38/J38 -> #N/A | M38: 14 | N38: =G38/W38*60 -> 1967.8261 | O38: =N38/M38 -> 140.55901 | P38: =M38-J38 -> #N/A | Q38: =O38-L38 -> #N/A | R38: =O38/L38 -> #N/A | S38: =R48 -> #N/A | T38: 0.33333333 | U38: 0.38125 | W38: =(U38-T38)*24*60 -> 69 | AF38: =N38-K38 -> #N/A | AG38: =N38/K38 -> #N/A | AH38: =AG48 -> #N/A
B39: =VLOOKUP(D39,廠價表!$C$1:$E$43,2,0) -> #N/A | F39: =VLOOKUP(D39,廠價表!$C$1:$E$43,3,0) -> #N/A | G39: 1180 | H39: =F39*G39 -> #N/A | J39: =VLOOKUP(D39,產線配置圖!$A$3:$C$40,2,0) -> #N/A | K39: =VLOOKUP(D39,產線配置圖!$A$3:$C$40,3,0) -> #N/A | L39: =K39/J39 -> #N/A | M39: 14 | N39: =G39/W39*60 -> 885 | O39: =N39/M39 -> 63.214286 | P39: =M39-J39 -> #N/A | Q39: =O39-L39 -> #N/A | R39: =O39/L39 -> #N/A | T39: 0.38888889 | U39: 0.44444444 | V39: =(T39-U38)*24*60 -> 11 | W39: =(U39-T39)*24*60 -> 80 | AF39: =N39-K39 -> #N/A | AG39: =N39/K39 -> #N/A
B40: =VLOOKUP(D40,廠價表!$C$1:$E$43,2,0) -> #N/A | F40: =VLOOKUP(D40,廠價表!$C$1:$E$43,3,0) -> #N/A | G40: 3398 | H40: =F40*G40 -> #N/A | J40: =VLOOKUP(D40,產線配置圖!$A$3:$C$40,2,0) -> #N/A | K40: =VLOOKUP(D40,產線配置圖!$A$3:$C$40,3,0) -> #N/A | L40: =K40/J40 -> #N/A | M40: 14 | N40: =G40/W40*60 -> 1853.4545 | O40: =N40/M40 -> 132.38961 | P40: =M40-J40 -> #N/A | Q40: =O40-L40 -> #N/A | R40: =O40/L40 -> #N/A | T40: 0.52777778 | U40: 0.60416667 | V40: =(T40-U39)*24*60 -> 120 | W40: =(U40-T40)*24*60 -> 110 | AF40: =N40-K40 -> #N/A | AG40: =N40/K40 -> #N/A
...

Sheet 0801總
B1: 長家廠組合室生產人時性分析
B3: 日期 | D3: 46235 | F3: 訂單量 | G3: ='0801'!E1 -> 50157 | I3: 營業額 | J3: ='0801'!G1 -> 2315009
B4: 項目 | D4: 3 | F4: ➀ | H4: ➁ | J4: ③ | L4: 異常停線 | N4: 短暫停線
B5: 人時性 | D5: 組合室 | F5: 全溫層 | H5: 義大利麵 | J5: 袋裝小吃、義麵 | L5: 合計次數 | M5: 時間 | N5: 合計次數 | O5: 設備次數
D6: 排關平均 | F6: =AVERAGE(D13:J13) -> 125.3878 | H6: =AVERAGE(D13:H13) -> 122.39021 | J6: =AVERAGE(I13:J13) -> 132.88178 | L6: =SUM(D18:J18) -> 2 | M6: =SUM(D19:J19) -> 32 | N6: =SUM(D20:J20) -> 0 | O6: =SUM(D20:J20) -> 0
D7: 實績平均 | F7: =AVERAGE(D14:J14) -> 112.77518 | H7: =AVERAGE(D14:H14) -> 108.65322 | J7: =AVERAGE(I14:J14) -> 123.08009 | L7: =AVERAGE(K14:L14) -> #DIV/0! | M7: =AVERAGE(L14:M14) -> #DIV/0! | N7: =AVERAGE(M14:N14) -> #DIV/0! | O7: =AVERAGE(N14:O14) -> #DIV/0!
D8: 達成率平均 | F8: =F7/F6 -> 0.89941113 | H8: =H7/H6 -> 0.88776072 | J8: =J7/J6 -> 0.92623753 | L8: =AVERAGE(K15:L15) -> #DIV/0! | M8: =AVERAGE(L15:M15) -> #DIV/0! | N8: =AVERAGE(M15:N15) -> #DIV/0! | O8: =AVERAGE(N15:O15) -> #DIV/0!
J9: ※現行日本鮮食廠以達成率80%為基本(即為現行KPI)
B10: 溫層 | D10: 4度C-各編組展開
B11: 編組 | D11: 1 | E11: 2 | F11: 3 | G11: 4 | H11: 5 | I11: 6 | J11: 7
D12: 自動1線 | E12: 自動2線 | F12: 手工3線 | G12: 手工4線 | H12: 手工5線 | I12: 調理包1線 | J12: 調理包2線
B13: 人時性 | C13: 排關 | D13: =VALUE('0801'!L15) -> 136.57969 | E13: =VALUE('0801'!L26) -> 174.51923 | F13: =VALUE('0801'!L37) -> 95.065768 | G13: =VALUE('0801'!L48) -> 99.006944 | H13: =VALUE('0801'!L58) -> 106.77941 | I13: =VALUE('0801'!L69) -> 135.50707 | J13: ='0801'!L79 -> 130.25649
C14: 實績 | D14: =VALUE('0801'!O15) -> 117.50436 | E14: =VALUE('0801'!O26) -> 160.65282 | F14: =VALUE('0801'!O37) -> 84.648002 | G14: =VALUE('0801'!O48) -> 85.922143 | H14: =VALUE('0801'!O58) -> 94.538775 | I14: =VALUE('0801'!O69) -> 130.03636 | J14: ='0801'!O79 -> 116.12382
C15: 達成率 | D15: =D14/D13 -> 0.86033554 | E15: =E14/E13 -> 0.92054508 | F15: =F14/F13 -> 0.89041517 | G15: =G14/G13 -> 0.86783956 | H15: =H14/H13 -> 0.8853652 | I15: =I14/I13 -> 0.95962788 | J15: ='0801'!S70 -> 0.89150122
B16: 作業 時間 | C16: 開始 | D16: ='0801'!T5 -> 0.29236111 | E16: ='0801'!T16 -> 0.29166667 | F16: ='0801'!T27 -> 0.28819444 | G16: ='0801'!T38 -> 0.33333333 | H16: ='0801'!T49 -> 0.29166667 | I16: ='0801'!T59 -> 0.29166667 | J16: ='0801'!T70 -> 0.29305556
C17: 結束 | D17: 0.61458333 | E17: 0.575 | F17: 0.5 | G17: 0.48958333 | H17: 0.61180556 | I17: 0.45486111 | J17: 0.44097222
B18: 產線異常 (5分鐘以上) | C18: 次數 | D18: ='0801'!Z15 -> 2 | E18: ='0801'!Z26 -> 0 | F18: ='0801'!Z37 -> 0 | G18: ='0801'!Z48 -> 0 | H18: ='0801'!Z58 -> 0 | I18: ='0801'!Z69 -> 0 | J18: ='0801'!AA79 -> 0
C19: 時間/分 | D19: ='0801'!AA15 -> 32 | E19: ='0801'!AA26 -> 0 | F19: ='0801'!AA37 -> 0 | G19: ='0801'!AA48 -> 0 | H19: ='0801'!AA58 -> 0 | I19: ='0801'!AA69 -> 0 | J19: ='0801'!AB79 -> 0
B20: 短暫停線 (5分鐘以下) | C20: 次數 | D20: ='0801'!AD15 -> 0 | E20: ='0801'!AD26 -> 0 | F20: ='0801'!AD37 -> 0 | G20: ='0801'!AD48 -> 0 | H20: ='0801'!AD58 -> 0 | I20: ='0801'!AD69 -> 0 | J20: ='0801'!AD79 -> 0
C21: 設備次數 | D21: ='0801'!AE15 -> 0 | E21: ='0801'!AE26 -> 0 | F21: ='0801'!AE37 -> 0 | G21: ='0801'!AE48 -> 0 | H21: ='0801'!AE58 -> 0 | I21: ='0801'!AE69 -> 0 | J21: ='0801'!AE79 -> 0
B22: 配置人數 | D22: =VALUE('0801'!M15) -> 15.75 | E22: =VALUE('0801'!M26) -> 13 | F22: =VALUE('0801'!M37) -> 17.25 | G22: =VALUE('0801'!M48) -> 17 | H22: =VALUE('0801'!M58) -> 16.25 | I22: =VALUE('0801'!M69) -> 12.333333 | J22: ='0801'!M79 -> 8.5
B23: 主要應用設備 | D23: ET-600 | E23: ET-600 | F23: ET-55 | G23: ET-55 | H23: ET-55 | I23: 八爪機 | J23: 八爪機
B24: 次要應用設備 | H24: 封口機 | J24: 封口機
B25: 備註

Sheet 0801
A1: 長家廠4度C日報分析 | D1: 總生產量 | E1: =SUM(G5:G79) -> 50157 | F1: 營業額 | G1: =SUM(H5:H79) -> 2315009 | H1: 出勤人數 | I1: =M15+M26+M48+M58+M69+M79+M37 -> 100.08333 | J1: 產線配置圖 | M1: 生產實績 | P1: 人時性差異分析 | T1: 日報登錄 | Z1: 合計 次數 | AA1: 合計 時間/分 | AB1: 分析說明 | AD1: 合計 次數 | AE1: 合計 設備次數 | AF1: 產能差異分析
A2: 8月1日 星期六 | D2: 人時性 | E2: =AVERAGE(O15,O26,O37,O48,O58,O69,O79) -> 112.77518 | F2: 平均廠價 | G2: =G1/E1 -> 46.155253 | H2: 多次生產數 | I2: =COUNT(I5:I79) -> 0 | Z2: =Z15+Z26+Z37+Z48+Z58+Z69+Z79 -> 2 | AA2: =AA15+AA26+AA37+AA48+AA58+AA69+AA79 -> 32 | AD2: =AD15+AD26+AD37+AD48+AD58+AD69+AD79 -> 0 | AE2: =AE15+AE26+AE37+AE48+AE58+AE69+AE79 -> 0
A3: 線別 | B3: 品類 | D3: 品名 | F3: 廠價 | G3: 生產量 | H3: 營收 | I3: 多次 生產 | J3: 人數 | K3: 產能/時 | L3: 人時性 | M3: 人數 | N3: 產能/時 | O3: 人時性 | P3: 人數 | Q3: 人時性 | R3: 達成率 | S3: 達成率平均 | T3: 生產時間 | V3: 前置、換線時間/分 | W3: 稼動時間/分 | X3: 休息時間 | Z3: 產線異常統計 (5分鐘以上) | AD3: 短暫停線統計 (5分鐘以下) | AF3: 產能/時 | AG3: 達成率 | AH3: 達成率平均
T4: 開始 | U4: 結束 | X4: 開始 | Y4: 結束 | Z4: 次數 | AA4: 時間/分 | AD4: 總次數 | AE4: 設備因素(次數)
A5: 自動一線 (ET-600) | B5: 義大利麵 | D5: 羅馬黑胡椒起司義大利麵 | F5: =VLOOKUP(D5,廠價表!$C$1:$E$43,3,0) -> 50.67 | G5: 1467 | H5: =F5*G5 -> 74332.89 | J5: =VLOOKUP(D5,產線配置圖!$A$3:$C$40,2,0) -> 17 | K5: =VLOOKUP(D5,產線配置圖!$A$3:$C$40,3,0) -> 2250 | L5: =K5/J5 -> 132.35294 | M5: 17 | N5: =G5/W5*60 -> 2000.4545 | O5: =N5/M5 -> 117.6738 | P5: =M5-J5 -> 0 | Q5: =O5-L5 -> -14.679144 | R5: =O5/L5 -> 0.88909091 | S5: =R15 -> 0.86033554 | T5: 0.29236111 | U5: 0.32291667 | W5: =(U5-T5)*24*60 -> 44 | AF5: =N5-K5 -> -249.54545 | AG5: =N5/K5 -> 0.88909091 | AH5: =AG15 -> 0.85727317
B6: 義大利麵 | D6: 香煎魚排佐檸檬奶油義大利麵 | F6: =VLOOKUP(D6,廠價表!$C$1:$E$43,3,0) -> 58.17 | G6: 1217 | H6: =F6*G6 -> 70792.89 | J6: =VLOOKUP(D6,產線配置圖!$A$3:$C$40,2,0) -> 13 | K6: =VLOOKUP(D6,產線配置圖!$A$3:$C$40,3,0) -> 2250 | L6: =K6/J6 -> 173.07692 | M6: 13 | N6: =G6/W6*60 -> 1921.5789 | O6: =N6/M6 -> 147.81377 | P6: =M6-J6 -> 0 | Q6: =O6-L6 -> -25.263158 | R6: =O6/L6 -> 0.85403509 | T6: 0.33125 | U6: 0.35763889 | V6: =(T6-U5)*24*60 -> 12 | W6: =(U6-T6)*24*60 -> 38 | AF6: =N6-K6 -> -328.42105 | AG6: =N6/K6 -> 0.85403509
B7: 義大利麵 | D7: 奶油培根義大利麵 | F7: =VLOOKUP(D7,廠價表!$C$1:$E$43,3,0) -> 49.14 | G7: 5630 | H7: =F7*G7 -> 276658.2 | J7: =VLOOKUP(D7,產線配置圖!$A$3:$C$40,2,0) -> 15 | K7: =VLOOKUP(D7,產線配置圖!$A$3:$C$40,3,0) -> 2250 | L7: =K7/J7 -> 150 | M7: 15 | N7: =G7/W7*60 -> 2072.3926 | O7: =N7/M7 -> 138.15951 | P7: =M7-J7 -> 0 | Q7: =O7-L7 -> -11.840491 | R7: =O7/L7 -> 0.92106339 | T7: 0.36527778 | U7: 0.47847222 | V7: =(T7-U6)*24*60 -> 11 | W7: =(U7-T7)*24*60 -> 163 | AF7: =N7-K7 -> -177.60736 | AG7: =N7/K7 -> 0.92106339
B8: 熱乾麵 | D8: 府城鹽水意麵 | F8: =VLOOKUP(D8,廠價表!$C$1:$E$43,3,0) -> 44.3 | G8: 1792 | H8: =F8*G8 -> 79385.6 | J8: =VLOOKUP(D8,產線配置圖!$A$3:$C$40,2,0) -> 18 | K8: =VLOOKUP(D8,產線配置圖!$A$3:$C$40,3,0) -> 1636 | L8: =K8/J8 -> 90.888889 | M8: 18 | N8: =G8/W8*60 -> 1194.6667 | O8: =N8/M8 -> 66.37037 | P8: =M8-J8 -> 0 | Q8: =O8-L8 -> -24.518519 | R8: =O8/L8 -> 0.73023635 | T8: 0.55208333 | U8: 0.61458333 | V8: =(T8-U7)*24*60 -> 106 | W8: =(U8-T8)*24*60 -> 90 | X8: 0.48611111 | Y8: 0.52777778 | Z8: 2 | AA8: 32 | AB8: 13:30-14:02封膜異常+重檢機異常 | AF8: =N8-K8 -> -441.33333 | AG8: =N8/K8 -> 0.73023635
W9: =(U9-T9)*24*60 -> 0 | AF9: =N9-K9 -> 0 | AG9: =N9/K9 -> #DIV/0!
W10: =(U10-T10)*24*60 -> 0 | AF10: =N10-K10 -> 0 | AG10: =N10/K10 -> #DIV/0!
W11: =(U11-T11)*24*60 -> 0 | AF11: =N11-K11 -> 0 | AG11: =N11/K11 -> #DIV/0!
W12: =(U12-T12)*24*60 -> 0
W13: =(U13-T13)*24*60 -> 0
W14: =(U14-T14)*24*60 -> 0
C15: 4度一組 | D15: 平均 | J15: =AVERAGE(J5:J14) -> 15.75 | K15: =AVERAGE(K5:K14) -> 2096.5 | L15: =AVERAGE(L5:L14) -> 136.57969 | M15: =AVERAGE(M5:M14) -> 15.75 | N15: =AVERAGE(N5:N14) -> 1797.2732 | O15: =AVERAGE(O5:O14) -> 117.50436 | P15: =M15-J15 -> 0 | Q15: =O15-L15 -> -19.075328 | R15: =O15/L15 -> 0.86033554 | Z15: =SUM(Z5:Z14) -> 2 | AA15: =SUM(AA5:AA14) -> 32 | AD15: =SUM(AD5:AD14) -> 0 | AE15: =SUM(AE5:AE14) -> 0 | AF15: =N15-K15 -> -299.2268 | AG15: =N15/K15 -> 0.85727317
A16: 自動二線 (ET-600) | B16: 義大利麵 | D16: 青醬蛤蜊義大利麵 | F16: =VLOOKUP(D16,廠價表!$C$1:$E$43,3,0) -> 50.67 | G16: 3444 | H16: =F16*G16 -> 174507.48 | J16: =VLOOKUP(D16,產線配置圖!$A$3:$C$40,2,0) -> 13 | K16: =VLOOKUP(D16,產線配置圖!$A$3:$C$40,3,0) -> 2250 | L16: =K16/J16 -> 173.07692 | M16: 13 | N16: =G16/W16*60 -> 2108.5714 | O16: =N16/M16 -> 162.1978 | P16: =M16-J16 -> 0 | Q16: =O16-L16 -> -10.879121 | R16: =O16/L16 -> 0.93714286 | S16: =R26 -> 0.92054508 | T16: 0.29166667 | U16: 0.35972222 | W16: =(U16-T16)*24*60 -> 98 | AF16: =N16-K16 -> -141.42857 | AG16: =N16/K16 -> 0.93714286 | AH16: =AG26 -> 0.92026294
B17: 義大利麵 | D17: 白酒清炒鮮蛤義大利麵 | F17: =VLOOKUP(D17,廠價表!$C$1:$E$43,3,0) -> 56.87 | G17: 2453 | H17: =F17*G17 -> 139502.11 | J17: =VLOOKUP(D17,產線配置圖!$A$3:$C$40,2,0) -> 15 | K17: =VLOOKUP(D17,產線配置圖!$A$3:$C$40,3,0) -> 2250 | L17: =K17/J17 -> 150 | M17: 15 | N17: =G17/W17*60 -> 2044.1667 | O17: =N17/M17 -> 136.27778 | P17: =M17-J17 -> 0 | Q17: =O17-L17 -> -13.722222 | R17: =O17/L17 -> 0.90851852 | T17: 0.36597222 | U17: 0.41597222 | V17: =(T17-U16)*24*60 -> 9 | W17: =(U17-T17)*24*60 -> 72 | AF17: =N17-K17 -> -205.83333 | AG17: =N17/K17 -> 0.90851852
B18: 義大利麵 | D18: 義式蕃茄起司義大利麵 | F18: =VLOOKUP(D18,廠價表!$C$1:$E$43,3,0) -> 50.39 | G18: 2588 | H18: =F18*G18 -> 130409.32 | J18: =VLOOKUP(D18,產線配置圖!$A$3:$C$40,2,0) -> 12 | K18: =VLOOKUP(D18,產線配置圖!$A$3:$C$40,3,0) -> 2250 | L18: =K18/J18 -> 187.5 | M18: 12 | N18: =G18/W18*60 -> 2098.3784 | O18: =N18/M18 -> 174.86486 | P18: =M18-J18 -> 0 | Q18: =O18-L18 -> -12.635135 | R18: =O18/L18 -> 0.93261261 | T18: 0.42222222 | U18: 0.47361111 | V18: =(T18-U17)*24*60 -> 9 | W18: =(U18-T18)*24*60 -> 74 | X18: 0.48611111 | Y18: 0.52777778 | AF18: =N18-K18 -> -151.62162 | AG18: =N18/K18 -> 0.93261261
B19: 義大利麵 | D19: 義式蕃茄起司義大利麵 | F19: =VLOOKUP(D19,廠價表!$C$1:$E$43,3,0) -> 50.39 | G19: 1625 | H19: =F19*G19 -> 81883.75 | J19: =VLOOKUP(D19,產線配置圖!$A$3:$C$40,2,0) -> 12 | K19: =VLOOKUP(D19,產線配置圖!$A$3:$C$40,3,0) -> 2250 | L19: =K19/J19 -> 187.5 | M19: 12 | N19: =G19/W19*60 -> 2031.25 | O19: =N19/M19 -> 169.27083 | P19: =M19-J19 -> 0 | Q19: =O19-L19 -> -18.229167 | R19: =O19/L19 -> 0.90277778 | T19: 0.54166667 | U19: 0.575 | V19: =(T19-U18)*24*60 -> 98 | W19: =(U19-T19)*24*60 -> 48 | AF19: =N19-K19 -> -218.75 | AG19: =N19/K19 -> 0.90277778
W20: =(U20-T20)*24*60 -> 0
W21: =(U21-T21)*24*60 -> 0
W22: 0
W23: =(U23-T23)*24*60 -> 0
H24: =F24*G24 -> 0 | W24: =(U24-T24)*24*60 -> 0
H25: =F25*G25 -> 0 | W25: =(U25-T25)*24*60 -> 0
C26: 4度二組A | D26: 平均 | J26: =AVERAGE(J16:J25) -> 13 | K26: =AVERAGE(K16:K25) -> 2250 | L26: =AVERAGE(L16:L25) -> 174.51923 | M26: =AVERAGE(M16:M25) -> 13 | N26: =AVERAGE(N16:N25) -> 2070.5916 | O26: =AVERAGE(O16:O25) -> 160.65282 | P26: =M26-J26 -> 0 | Q26: =O26-L26 -> -13.866411 | R26: =O26/L26 -> 0.92054508 | Z26: =SUM(Z16:Z25) -> 0 | AA26: =SUM(AA16:AA25) -> 0 | AD26: =SUM(AD16:AD25) -> 0 | AE26: =SUM(AE16:AE25) -> 0 | AF26: =N26-K26 -> -179.40838 | AG26: =N26/K26 -> 0.92026294
A27: 手工三線 (ET-55) | B27: 義大利麵 | D27: 蕃茄莎莎海鮮冷義大利麵 | F27: =VLOOKUP(D27,廠價表!$C$1:$E$43,3,0) -> 46.34 | G27: 1960 | H27: =F27*G27 -> 90826.4 | J27: =VLOOKUP(D27,產線配置圖!$A$3:$C$40,2,0) -> 16 | K27: =VLOOKUP(D27,產線配置圖!$A$3:$C$40,3,0) -> 1636 | L27: =K27/J27 -> 102.25 | M27: 16 | N27: =G27/W27*60 -> 1383.5294 | O27: =N27/M27 -> 86.470588 | P27: =M27-J27 -> 0 | Q27: =O27-L27 -> -15.779412 | R27: =O27/L27 -> 0.84567812 | S27: =R37 -> 0.89041517 | T27: 0.28819444 | U27: 0.34722222 | W27: =(U27-T27)*24*60 -> 85 | AF27: =N27-K27 -> -252.47059 | AG27: =N27/K27 -> 0.84567812 | AH27: =AG37 -> 0.89100467
B28: 義大利麵 | D28: 金沙豆腐義大利麵 | F28: =VLOOKUP(D28,廠價表!$C$1:$E$43,3,0) -> 49.91 | G28: 2568 | H28: =F28*G28 -> 128168.88 | J28: =VLOOKUP(D28,產線配置圖!$A$3:$C$40,2,0) -> 18 | K28: 1636 | L28: =K28/J28 -> 90.888889 | M28: 18 | N28: =G28/W28*60 -> 1481.5385 | O28: =N28/M28 -> 82.307692 | P28: =M28-J28 -> 0 | Q28: =O28-L28 -> -8.5811966 | R28: =O28/L28 -> 0.90558586 | T28: 0.35277778 | U28: 0.425 | V28: =(T28-U27)*24*60 -> 8 | W28: =(U28-T28)*24*60 -> 104 | AF28: =N28-K28 -> -154.46154 | AG28: =N28/K28 -> 0.90558586
B29: 義大利麵 | D29: 奶油鮮蝦明太子細扁麵 | F29: =VLOOKUP(D29,廠價表!$C$1:$E$43,3,0) -> 57.21 | G29: 946 | H29: =F29*G29 -> 54120.66 | J29: =VLOOKUP(D29,產線配置圖!$A$3:$C$40,2,0) -> 18 | K29: =VLOOKUP(D29,產線配置圖!$A$3:$C$40,3,0) -> 1636 | L29: =K29/J29 -> 90.888889 | M29: 18 | N29: =G29/W29*60 -> 1419 | O29: =N29/M29 -> 78.833333 | P29: =M29-J29 -> 0 | Q29: =O29-L29 -> -12.055556 | R29: =O29/L29 -> 0.86735941 | T29: 0.43055556 | U29: 0.45833333 | V29: =(T29-U28)*24*60 -> 8 | W29: =(U29-T29)*24*60 -> 40 | AF29: =N29-K29 -> -217 | AG29: =N29/K29 -> 0.86735941
B30: 義大利麵 | D30: 義式蛋蛋青醬鮪魚冷義大利麵 | F30: =VLOOKUP(D30,廠價表!$C$1:$E$43,3,0) -> 45.66 | G30: 1160 | H30: =F30*G30 -> 52965.6 | J30: =VLOOKUP(D30,產線配置圖!$A$3:$C$40,2,0) -> 17 | K30: =VLOOKUP(D30,產線配置圖!$A$3:$C$40,3,0) -> 1636 | L30: =K30/J30 -> 96.235294 | M30: 17 | N30: =G30/W30*60 -> 1546.6667 | O30: =N30/M30 -> 90.980392 | P30: =M30-J30 -> 0 | Q30: =O30-L30 -> -5.254902 | R30: =O30/L30 -> 0.94539527 | T30: 0.46875 | U30: 0.5 | V30: =(T30-U29)*24*60 -> 15 | W30: =(U30-T30)*24*60 -> 45 | X30: 0.49652778 | Y30: 0.53819444 | AF30: =N30-K30 -> -89.333333 | AG30: =N30/K30 -> 0.94539527
W31: =(U31-T31)*24*60 -> 0 | AF31: =N31-K31 -> 0 | AG31: =N31/K31 -> #DIV/0!
W32: =(U32-T32)*24*60 -> 0
W33: =(U33-T33)*24*60 -> 0
W34: =(U34-T34)*24*60 -> 0
W35: =(U35-T35)*24*60 -> 0
H36: =F36*G36 -> 0 | W36: =(U36-T36)*24*60 -> 0
C37: 4度二組B | D37: 平均 | J37: =AVERAGE(J27:J36) -> 17.25 | K37: =AVERAGE(K27:K36) -> 1636 | L37: =AVERAGE(L27:L36) -> 95.065768 | M37: =AVERAGE(M27:M36) -> 17.25 | N37: =AVERAGE(N27:N36) -> 1457.6836 | O37: =AVERAGE(O27:O36) -> 84.648002 | P37: =M37-J37 -> 0 | Q37: =N37-K37 -> -178.31637 | R37: =O37/L37 -> 0.89041517 | Z37: =SUM(Z27:Z36) -> 0 | AA37: =SUM(AA27:AA36) -> 0 | AD37: =SUM(AD27:AD36) -> 0 | AE37: =SUM(AE27:AE36) -> 0 | AF37: =N37-K37 -> -178.31637 | AG37: =N37/K37 -> 0.89100467
A38: 手工四線 (ET-55) | B38: 熱乾麵 | D38: 青花椒麻雞肉拌麵 | F38: =VLOOKUP(D38,廠價表!$C$1:$E$43,3,0) -> 49.91 | G38: 2172 | H38: =F38*G38 -> 108404.52 | J38: =VLOOKUP(D38,產線配置圖!$A$3:$C$40,2,0) -> 16 | K38: =VLOOKUP(D38,產線配置圖!$A$3:$C$40,3,0) -> 1714 | L38: =K38/J38 -> 107.125 | M38: 16 | N38: =G38/W38*60 -> 1551.4286 | O38: =N38/M38 -> 96.964286 | P38: =M38-J38 -> 0 | Q38: =O38-L38 -> -10.160714 | R38: =O38/L38 -> 0.90515086 | S38: =R48 -> 0.86783956 | T38: 0.33333333 | U38: 0.39166667 | W38: =(U38-T38)*24*60 -> 84 | AF38: =N38-K38 -> -162.57143 | AG38: =N38/K38 -> 0.90515086 | AH38: =AG48 -> 0.8654533
B39: 熱乾麵 | D39: 府城鹽水意麵 | F39: =VLOOKUP(D39,廠價表!$C$1:$E$43,3,0) -> 44.3 | G39: 2808 | H39: =F39*G39 -> 124394.4 | J39: =VLOOKUP(D39,產線配置圖!$A$3:$C$40,2,0) -> 18 | K39: =VLOOKUP(D39,產線配置圖!$A$3:$C$40,3,0) -> 1636 | L39: =K39/J39 -> 90.888889 | M39: 18 | N39: =G39/W39*60 -> 1347.84 | O39: =N39/M39 -> 74.88 | P39: =M39-J39 -> 0 | Q39: =O39-L39 -> -16.008889 | R39: =O39/L39 -> 0.82386308 | T39: 0.40277778 | U39: 0.48958333 | V39: =(T39-U38)*24*60 -> 16 | W39: =(U39-T39)*24*60 -> 125 | AF39: =N39-K39 -> -288.16 | AG39: =N39/K39 -> 0.82386308
W40: =(U40-T40)*24*60 -> 0 | AF40: =N40-K40 -> 0 | AG40: =N40/K40 -> #DIV/0!
...

Sheet 0802總
B1: 長家廠組合室生產人時性分析
B3: 日期 | D3: 46236 | F3: 訂單量 | G3: ='0802'!E1 -> 65177 | I3: 營業額 | J3: ='0802'!G1 -> 3016872.8
B4: 項目 | D4: 3 | F4: ➀ | H4: ➁ | J4: ③ | L4: 異常停線 | N4: 短暫停線
B5: 人時性 | D5: 組合室 | F5: 全溫層 | H5: 義大利麵 | J5: 袋裝小吃、義麵 | L5: 合計次數 | M5: 時間 | N5: 合計次數 | O5: 設備次數
D6: 排關平均 | F6: =AVERAGE(D13:J13) -> 126.28367 | H6: =AVERAGE(D13:H13) -> 124.65002 | J6: =AVERAGE(I13:J13) -> 130.3678 | L6: =SUM(D18:J18) -> 7 | M6: =SUM(D19:J19) -> 0 | N6: =SUM(D20:J20) -> 0 | O6: =SUM(D20:J20) -> 0
D7: 實績平均 | F7: =AVERAGE(D14:J14) -> 115.23476 | H7: =AVERAGE(D14:H14) -> 114.93918 | J7: =AVERAGE(I14:J14) -> 115.97372 | L7: =AVERAGE(K14:L14) -> #DIV/0! | M7: =AVERAGE(L14:M14) -> #DIV/0! | N7: =AVERAGE(M14:N14) -> #DIV/0! | O7: =AVERAGE(N14:O14) -> #DIV/0!
D8: 達成率平均 | F8: =F7/F6 -> 0.91250722 | H8: =H7/H6 -> 0.92209515 | J8: =J7/J6 -> 0.88958867 | L8: =AVERAGE(K15:L15) -> #DIV/0! | M8: =AVERAGE(L15:M15) -> #DIV/0! | N8: =AVERAGE(M15:N15) -> #DIV/0! | O8: =AVERAGE(N15:O15) -> #DIV/0!
J9: ※現行日本鮮食廠以達成率80%為基本(即為現行KPI)
B10: 溫層 | D10: 4度C-各編組展開
B11: 編組 | D11: 1 | E11: 2 | F11: 3 | G11: 4 | H11: 5 | I11: 6 | J11: 7
D12: 自動1線 | E12: 自動2線 | F12: 手工3線 | G12: 手工4線 | H12: 手工5線 | I12: 調理包1線 | J12: 調理包2線
B13: 人時性 | C13: 排關 | D13: =VALUE('0802'!L15) -> 151.08597 | E13: =VALUE('0802'!L26) -> 174.51923 | F13: =VALUE('0802'!L37) -> 94.564542 | G13: =VALUE('0802'!L48) -> 96.300926 | H13: =VALUE('0802'!L58) -> 106.77941 | I13: =VALUE('0802'!L69) -> 132.86303 | J13: ='0802'!L79 -> 127.87256
C14: 實績 | D14: =VALUE('0802'!O15) -> 141.27181 | E14: =VALUE('0802'!O26) -> 167.503 | F14: =VALUE('0802'!O37) -> 86.926868 | G14: =VALUE('0802'!O48) -> 86.461162 | H14: =VALUE('0802'!O58) -> 92.533041 | I14: =VALUE('0802'!O69) -> 122.67368 | J14: ='0802'!O79 -> 109.27375
C15: 達成率 | D15: =D14/D13 -> 0.9350425 | E15: =E14/E13 -> 0.95979682 | F15: =F14/F13 -> 0.91923321 | G15: =G14/G13 -> 0.89782275 | H15: =H14/H13 -> 0.8665813 | I15: =I14/I13 -> 0.92330936 | J15: ='0802'!S70 -> 0.85455197
B16: 作業 時間 | C16: 開始 | D16: ='0802'!T5 -> 0.29444444 | E16: ='0802'!T16 -> 0.28819444 | F16: ='0802'!T27 -> 0.29166667 | G16: ='0802'!T38 -> 0.33333333 | H16: ='0802'!T49 -> 0.29166667 | I16: ='0802'!T59 -> 0.28819444 | J16: ='0802'!T70 -> 0.29444444
C17: 結束 | D17: 0.61458333 | E17: 0.575 | F17: 0.5 | G17: 0.48958333 | H17: 0.61180556 | I17: 0.45486111 | J17: 0.44097222
B18: 產線異常 (5分鐘以上) | C18: 次數 | D18: ='0802'!Z15 -> 0 | E18: ='0802'!Z26 -> 0 | F18: ='0802'!Z37 -> 0 | G18: ='0802'!Z48 -> 0 | H18: ='0802'!Z58 -> 0 | I18: ='0802'!Z69 -> 0 | J18: ='0802'!AA79 -> 7
C19: 時間/分 | D19: ='0802'!AA15 -> 0 | E19: ='0802'!AA26 -> 0 | F19: ='0802'!AA37 -> 0 | G19: ='0802'!AA48 -> 0 | H19: ='0802'!AA58 -> 0 | I19: ='0802'!AA69 -> 0 | J19: ='0802'!AB79 -> 0
B20: 短暫停線 (5分鐘以下) | C20: 次數 | D20: ='0802'!AD15 -> 0 | E20: ='0802'!AD26 -> 0 | F20: ='0802'!AD37 -> 0 | G20: ='0802'!AD48 -> 0 | H20: ='0802'!AD58 -> 0 | I20: ='0802'!AD69 -> 0 | J20: ='0802'!AD79 -> 0
C21: 設備次數 | D21: ='0802'!AE15 -> 0 | E21: ='0802'!AE26 -> 0 | F21: ='0802'!AE37 -> 0 | G21: ='0802'!AE48 -> 0 | H21: ='0802'!AE58 -> 0 | I21: ='0802'!AE69 -> 0 | J21: ='0802'!AE79 -> 0
B22: 配置人數 | D22: =VALUE('0802'!M15) -> 15 | E22: =VALUE('0802'!M26) -> 13 | F22: =VALUE('0802'!M37) -> 17.166667 | G22: =VALUE('0802'!M48) -> 17.333333 | H22: =VALUE('0802'!M58) -> 16.5 | I22: =VALUE('0802'!M69) -> 12.6 | J22: ='0802'!M79 -> 12
B23: 主要應用設備 | D23: ET-600 | E23: ET-600 | F23: ET-55 | G23: ET-55 | H23: ET-55 | I23: 八爪機 | J23: 八爪機
B24: 次要應用設備 | H24: 封口機 | J24: 封口機
B25: 備註

Sheet 0802
A1: 長家廠4度C日報分析 | D1: 總生產量 | E1: =SUM(G5:G79) -> 65177 | F1: 營業額 | G1: =SUM(H5:H79) -> 3016872.8 | H1: 出勤人數 | I1: =M15+M26+M48+M58+M69+M79+M37 -> 103.6 | J1: 產線配置圖 | M1: 生產實績 | P1: 人時性差異分析 | T1: 日報登錄 | Z1: 合計 次數 | AA1: 合計 時間/分 | AB1: 分析說明 | AD1: 合計 次數 | AE1: 合計 設備次數 | AF1: 產能差異分析
A2: 8月2日 星期日 | D2: 人時性 | E2: =AVERAGE(O15,O26,O37,O48,O58,O69,O79) -> 115.23476 | F2: 平均廠價 | G2: =G1/E1 -> 46.287383 | H2: 多次生產數 | I2: =COUNT(I5:I79) -> 0 | Z2: =Z15+Z26+Z37+Z48+Z58+Z69+Z79 -> 1 | AA2: =AA15+AA26+AA37+AA48+AA58+AA69+AA79 -> 7 | AD2: =AD15+AD26+AD37+AD48+AD58+AD69+AD79 -> 0 | AE2: =AE15+AE26+AE37+AE48+AE58+AE69+AE79 -> 0
A3: 線別 | B3: 品類 | D3: 品名 | F3: 廠價 | G3: 生產量 | H3: 營收 | I3: 多次 生產 | J3: 人數 | K3: 產能/時 | L3: 人時性 | M3: 人數 | N3: 產能/時 | O3: 人時性 | P3: 人數 | Q3: 人時性 | R3: 達成率 | S3: 達成率平均 | T3: 生產時間 | V3: 前置、換線時間/分 | W3: 稼動時間/分 | X3: 休息時間 | Z3: 產線異常統計 (5分鐘以上) | AD3: 短暫停線統計 (5分鐘以下) | AF3: 產能/時 | AG3: 達成率 | AH3: 達成率平均
T4: 開始 | U4: 結束 | X4: 開始 | Y4: 結束 | Z4: 次數 | AA4: 時間/分 | AD4: 總次數 | AE4: 設備因素(次數)
A5: 自動一線 (ET-600) | B5: 義大利麵 | D5: 羅馬黑胡椒起司義大利麵 | F5: =VLOOKUP(D5,廠價表!$C$1:$E$43,3,0) -> 50.67 | G5: 1991 | H5: =F5*G5 -> 100883.97 | J5: =VLOOKUP(D5,產線配置圖!$A$3:$C$40,2,0) -> 17 | K5: =VLOOKUP(D5,產線配置圖!$A$3:$C$40,3,0) -> 2250 | L5: =K5/J5 -> 132.35294 | M5: 17 | N5: =G5/W5*60 -> 2024.7458 | O5: =N5/M5 -> 119.10269 | P5: =M5-J5 -> 0 | Q5: =O5-L5 -> -13.250249 | R5: =O5/L5 -> 0.89988701 | S5: =R15 -> 0.9350425 | T5: 0.29444444 | U5: 0.33541667 | W5: =(U5-T5)*24*60 -> 59 | AB5: 8:10-8:15注醬機異常 | AF5: =N5-K5 -> -225.25424 | AG5: =N5/K5 -> 0.89988701 | AH5: =AG15 -> 0.93352032
B6: 義大利麵 | D6: 香煎魚排佐檸檬奶油義大利麵 | F6: =VLOOKUP(D6,廠價表!$C$1:$E$43,3,0) -> 58.17 | G6: 1616 | H6: =F6*G6 -> 94002.72 | J6: =VLOOKUP(D6,產線配置圖!$A$3:$C$40,2,0) -> 13 | K6: =VLOOKUP(D6,產線配置圖!$A$3:$C$40,3,0) -> 2250 | L6: =K6/J6 -> 173.07692 | M6: 13 | N6: =G6/W6*60 -> 2154.6667 | O6: =N6/M6 -> 165.74359 | P6: =M6-J6 -> 0 | Q6: =O6-L6 -> -7.3333333 | R6: =O6/L6 -> 0.95762963 | T6: 0.34375 | U6: 0.375 | V6: =(T6-U5)*24*60 -> 12 | W6: =(U6-T6)*24*60 -> 45 | AF6: =N6-K6 -> -95.333333 | AG6: =N6/K6 -> 0.95762963
B7: 義大利麵 | D7: 奶油培根義大利麵 | F7: =VLOOKUP(D7,廠價表!$C$1:$E$43,3,0) -> 49.14 | G7: 4914 | H7: =F7*G7 -> 241473.96 | J7: =VLOOKUP(D7,產線配置圖!$A$3:$C$40,2,0) -> 15 | K7: =VLOOKUP(D7,產線配置圖!$A$3:$C$40,3,0) -> 2250 | L7: =K7/J7 -> 150 | M7: 15 | N7: =G7/W7*60 -> 2167.9412 | O7: =N7/M7 -> 144.52941 | P7: =M7-J7 -> 0 | Q7: =O7-L7 -> -5.4705882 | R7: =O7/L7 -> 0.96352941 | T7: 0.38263889 | U7: 0.47708333 | V7: =(T7-U6)*24*60 -> 11 | W7: =(U7-T7)*24*60 -> 136 | AF7: =N7-K7 -> -82.058824 | AG7: =N7/K7 -> 0.96352941
B8: 義大利麵 | D8: 奶油培根義大利麵 | F8: =VLOOKUP(D8,廠價表!$C$1:$E$43,3,0) -> 49.14 | G8: 1657 | H8: =F8*G8 -> 81424.98 | J8: =VLOOKUP(D8,產線配置圖!$A$3:$C$40,2,0) -> 15 | K8: =VLOOKUP(D8,產線配置圖!$A$3:$C$40,3,0) -> 2250 | L8: =K8/J8 -> 150 | M8: 15 | N8: =G8/W8*60 -> 2071.25 | O8: =N8/M8 -> 138.08333 | P8: =M8-J8 -> 0 | Q8: =O8-L8 -> -11.916667 | R8: =O8/L8 -> 0.92055556 | T8: 0.54513889 | U8: 0.57847222 | V8: =(T8-U7)*24*60 -> 98 | W8: =(U8-T8)*24*60 -> 48 | AF8: =N8-K8 -> -178.75 | AG8: =N8/K8 -> 0.92055556
B9: 義大利麵 | D9: 白酒清炒鮮蛤義大利麵 | F9: =VLOOKUP(D9,廠價表!$C$1:$E$43,3,0) -> 56.87 | G9: 1389 | H9: =F9*G9 -> 78992.43 | J9: =VLOOKUP(D9,產線配置圖!$A$3:$C$40,2,0) -> 15 | K9: =VLOOKUP(D9,產線配置圖!$A$3:$C$40,3,0) -> 2250 | L9: =K9/J9 -> 150 | M9: 15 | N9: =G9/W9*60 -> 2083.5 | O9: =N9/M9 -> 138.9 | P9: =M9-J9 -> 0 | Q9: =O9-L9 -> -11.1 | R9: =O9/L9 -> 0.926 | T9: 0.58541667 | U9: 0.61319444 | V9: =(T9-U8)*24*60 -> 10 | W9: =(U9-T9)*24*60 -> 40 | AF9: =N9-K9 -> -166.5 | AG9: =N9/K9 -> 0.926
W10: =(U10-T10)*24*60 -> 0 | AF10: =N10-K10 -> 0 | AG10: =N10/K10 -> #DIV/0!
W11: =(U11-T11)*24*60 -> 0 | AF11: =N11-K11 -> 0 | AG11: =N11/K11 -> #DIV/0!
W12: =(U12-T12)*24*60 -> 0
W13: =(U13-T13)*24*60 -> 0
W14: =(U14-T14)*24*60 -> 0
C15: 4度一組 | D15: 平均 | J15: =AVERAGE(J5:J14) -> 15 | K15: =AVERAGE(K5:K14) -> 2250 | L15: =AVERAGE(L5:L14) -> 151.08597 | M15: =AVERAGE(M5:M14) -> 15 | N15: =AVERAGE(N5:N14) -> 2100.4207 | O15: =AVERAGE(O5:O14) -> 141.27181 | P15: =M15-J15 -> 0 | Q15: =O15-L15 -> -9.8141675 | R15: =O15/L15 -> 0.9350425 | Z15: =SUM(Z5:Z14) -> 0 | AA15: =SUM(AA5:AA14) -> 0 | AD15: =SUM(AD5:AD14) -> 0 | AE15: =SUM(AE5:AE14) -> 0 | AF15: =N15-K15 -> -149.57928 | AG15: =N15/K15 -> 0.93352032
A16: 自動二線 (ET-600) | B16: 義大利麵 | D16: 青醬蛤蜊義大利麵 | F16: =VLOOKUP(D16,廠價表!$C$1:$E$43,3,0) -> 50.67 | G16: 4037 | H16: =F16*G16 -> 204554.79 | J16: =VLOOKUP(D16,產線配置圖!$A$3:$C$40,2,0) -> 13 | K16: =VLOOKUP(D16,產線配置圖!$A$3:$C$40,3,0) -> 2250 | L16: =K16/J16 -> 173.07692 | M16: 13 | N16: =G16/W16*60 -> 2202 | O16: =N16/M16 -> 169.38462 | P16: =M16-J16 -> 0 | Q16: =O16-L16 -> -3.6923077 | R16: =O16/L16 -> 0.97866667 | S16: =R26 -> 0.95979682 | T16: 0.28819444 | U16: 0.36458333 | W16: =(U16-T16)*24*60 -> 110 | AF16: =N16-K16 -> -48 | AG16: =N16/K16 -> 0.97866667 | AH16: =AG26 -> 0.95957727
B17: 義大利麵 | D17: 白酒清炒鮮蛤義大利麵 | F17: =VLOOKUP(D17,廠價表!$C$1:$E$43,3,0) -> 56.87 | G17: 1920 | H17: =F17*G17 -> 109190.4 | J17: =VLOOKUP(D17,產線配置圖!$A$3:$C$40,2,0) -> 15 | K17: =VLOOKUP(D17,產線配置圖!$A$3:$C$40,3,0) -> 2250 | L17: =K17/J17 -> 150 | M17: 15 | N17: =G17/W17*60 -> 2133.3333 | O17: =N17/M17 -> 142.22222 | P17: =M17-J17 -> 0 | Q17: =O17-L17 -> -7.7777778 | R17: =O17/L17 -> 0.94814815 | T17: 0.37013889 | U17: 0.40763889 | V17: =(T17-U16)*24*60 -> 8 | W17: =(U17-T17)*24*60 -> 54 | AF17: =N17-K17 -> -116.66667 | AG17: =N17/K17 -> 0.94814815
B18: 義大利麵 | D18: 義式蕃茄起司義大利麵 | F18: =VLOOKUP(D18,廠價表!$C$1:$E$43,3,0) -> 50.39 | G18: 3420 | H18: =F18*G18 -> 172333.8 | J18: =VLOOKUP(D18,產線配置圖!$A$3:$C$40,2,0) -> 12 | K18: =VLOOKUP(D18,產線配置圖!$A$3:$C$40,3,0) -> 2250 | L18: =K18/J18 -> 187.5 | M18: 12 | N18: =G18/W18*60 -> 2160 | O18: =N18/M18 -> 180 | P18: =M18-J18 -> 0 | Q18: =O18-L18 -> -7.5 | R18: =O18/L18 -> 0.96 | T18: 0.41319444 | U18: 0.47916667 | V18: =(T18-U17)*24*60 -> 8 | W18: =(U18-T18)*24*60 -> 95 | AF18: =N18-K18 -> -90 | AG18: =N18/K18 -> 0.96
B19: 義大利麵 | D19: 義式蕃茄起司義大利麵 | F19: =VLOOKUP(D19,廠價表!$C$1:$E$43,3,0) -> 50.39 | G19: 4139 | H19: =F19*G19 -> 208564.21 | J19: =VLOOKUP(D19,產線配置圖!$A$3:$C$40,2,0) -> 12 | K19: =VLOOKUP(D19,產線配置圖!$A$3:$C$40,3,0) -> 2250 | L19: =K19/J19 -> 187.5 | M19: 12 | N19: =G19/W19*60 -> 2140.8621 | O19: =N19/M19 -> 178.40517 | P19: =M19-J19 -> 0 | Q19: =O19-L19 -> -9.0948276 | R19: =O19/L19 -> 0.95149425 | T19: 0.54166667 | U19: 0.62222222 | V19: =(T19-U18)*24*60 -> 90 | W19: =(U19-T19)*24*60 -> 116 | AF19: =N19-K19 -> -109.13793 | AG19: =N19/K19 -> 0.95149425
W20: =(U20-T20)*24*60 -> 0
W21: =(U21-T21)*24*60 -> 0
W22: 0
W23: =(U23-T23)*24*60 -> 0
H24: =F24*G24 -> 0 | W24: =(U24-T24)*24*60 -> 0
H25: =F25*G25 -> 0 | W25: =(U25-T25)*24*60 -> 0
C26: 4度二組A | D26: 平均 | J26: =AVERAGE(J16:J25) -> 13 | K26: =AVERAGE(K16:K25) -> 2250 | L26: =AVERAGE(L16:L25) -> 174.51923 | M26: =AVERAGE(M16:M25) -> 13 | N26: =AVERAGE(N16:N25) -> 2159.0489 | O26: =AVERAGE(O16:O25) -> 167.503 | P26: =M26-J26 -> 0 | Q26: =O26-L26 -> -7.0162283 | R26: =O26/L26 -> 0.95979682 | Z26: =SUM(Z16:Z25) -> 0 | AA26: =SUM(AA16:AA25) -> 0 | AD26: =SUM(AD16:AD25) -> 0 | AE26: =SUM(AE16:AE25) -> 0 | AF26: =N26-K26 -> -90.951149 | AG26: =N26/K26 -> 0.95957727
A27: 手工三線 (ET-55) | B27: 義大利麵 | D27: 蕃茄莎莎海鮮冷義大利麵 | F27: =VLOOKUP(D27,廠價表!$C$1:$E$43,3,0) -> 46.34 | G27: 1327 | H27: =F27*G27 -> 61493.18 | J27: =VLOOKUP(D27,產線配置圖!$A$3:$C$40,2,0) -> 16 | K27: =VLOOKUP(D27,產線配置圖!$A$3:$C$40,3,0) -> 1636 | L27: =K27/J27 -> 102.25 | M27: 16 | N27: =G27/W27*60 -> 1561.1765 | O27: =N27/M27 -> 97.573529 | P27: =M27-J27 -> 0 | Q27: =O27-L27 -> -4.6764706 | R27: =O27/L27 -> 0.95426435 | S27: =R37 -> 0.91923321 | T27: 0.29166667 | U27: 0.32708333 | W27: =(U27-T27)*24*60 -> 51 | AF27: =N27-K27 -> -74.823529 | AG27: =N27/K27 -> 0.95426435 | AH27: =AG37 -> 0.91014
B28: 義大利麵 | D28: 義式蛋蛋青醬鮪魚冷義大利麵 | F28: =VLOOKUP(D28,廠價表!$C$1:$E$43,3,0) -> 45.66 | G28: 1440 | H28: =F28*G28 -> 65750.4 | J28: =VLOOKUP(D28,產線配置圖!$A$3:$C$40,2,0) -> 17 | K28: =VLOOKUP(D28,產線配置圖!$A$3:$C$40,3,0) -> 1636 | L28: =K28/J28 -> 96.235294 | M28: 17 | N28: =G28/W28*60 -> 1515.7895 | O28: =N28/M28 -> 89.164087 | P28: =M28-J28 -> 0 | Q28: =O28-L28 -> -7.0712074 | R28: =O28/L28 -> 0.92652168 | T28: 0.33194444 | U28: 0.37152778 | V28: =(T28-U27)*24*60 -> 7 | W28: =(U28-T28)*24*60 -> 57 | AF28: =N28-K28 -> -120.21053 | AG28: =N28/K28 -> 0.92652168
B29: 義大利麵 | D29: 奶油鮮蝦明太子細扁麵 | F29: =VLOOKUP(D29,廠價表!$C$1:$E$43,3,0) -> 57.21 | G29: 1323 | H29: =F29*G29 -> 75688.83 | J29: =VLOOKUP(D29,產線配置圖!$A$3:$C$40,2,0) -> 18 | K29: =VLOOKUP(D29,產線配置圖!$A$3:$C$40,3,0) -> 1636 | L29: =K29/J29 -> 90.888889 | M29: 17 | N29: =G29/W29*60 -> 1443.2727 | O29: =N29/M29 -> 84.898396 | P29: =M29-J29 -> -1 | Q29: =O29-L29 -> -5.9904932 | R29: =O29/L29 -> 0.93408993 | T29: 0.37847222 | U29: 0.41666667 | V29: =(T29-U28)*24*60 -> 10 | W29: =(U29-T29)*24*60 -> 55 | AF29: =N29-K29 -> -192.72727 | AG29: =N29/K29 -> 0.88219604
B30: 義大利麵 | D30: 金沙豆腐義大利麵 | F30: =VLOOKUP(D30,廠價表!$C$1:$E$43,3,0) -> 49.91 | G30: 1494 | H30: =F30*G30 -> 74565.54 | J30: =VLOOKUP(D30,產線配置圖!$A$3:$C$40,2,0) -> 18 | K30: 1636 | L30: =K30/J30 -> 90.888889 | M30: 18 | N30: =G30/W30*60 -> 1494 | O30: =N30/M30 -> 83 | P30: =M30-J30 -> 0 | Q30: =O30-L30 -> -7.8888889 | R30: =O30/L30 -> 0.91320293 | T30: 0.42361111 | U30: 0.46527778 | V30: =(T30-U29)*24*60 -> 10 | W30: =(U30-T30)*24*60 -> 60 | AF30: =N30-K30 -> -142 | AG30: =N30/K30 -> 0.91320293
B31: 義大利麵 | D31: 金沙豆腐義大利麵 | F31: =VLOOKUP(D31,廠價表!$C$1:$E$43,3,0) -> 49.91 | G31: 1500 | H31: =F31*G31 -> 74865 | J31: =VLOOKUP(D31,產線配置圖!$A$3:$C$40,2,0) -> 18 | K31: 1636 | L31: =K31/J31 -> 90.888889 | M31: 18 | N31: =G31/W31*60 -> 1475.4098 | O31: =N31/M31 -> 81.967213 | P31: =M31-J31 -> 0 | Q31: =O31-L31 -> -8.9216758 | R31: =O31/L31 -> 0.90183975 | T31: 0.52777778 | U31: 0.57013889 | V31: =(T31-U30)*24*60 -> 90 | W31: =(U31-T31)*24*60 -> 61 | AF31: =N31-K31 -> -160.59016 | AG31: =N31/K31 -> 0.90183975
B32: 義大利麵 | D32: 黑松露野菇義大利麵 | F32: =VLOOKUP(D32,廠價表!$C$1:$E$43,3,0) -> 50.289 | G32: 1011 | H32: =F32*G32 -> 50842.179 | J32: =VLOOKUP(D32,產線配置圖!$A$3:$C$40,2,0) -> 17 | K32: =VLOOKUP(D32,產線配置圖!$A$3:$C$40,3,0) -> 1636 | L32: =K32/J32 -> 96.235294 | M32: 17 | N32: =G32/W32*60 -> 1444.2857 | O32: =N32/M32 -> 84.957983 | P32: =M32-J32 -> 0 | Q32: =O32-L32 -> -11.277311 | R32: =O32/L32 -> 0.88281523 | T32: 0.57708333 | U32: 0.60625 | V32: =(T32-U31)*24*60 -> 10 | W32: =(U32-T32)*24*60 -> 42
W33: =(U33-T33)*24*60 -> 0
W34: =(U34-T34)*24*60 -> 0
W35: =(U35-T35)*24*60 -> 0
W36: =(U36-T36)*24*60 -> 0
C37: 4度二組B | D37: 平均 | J37: =AVERAGE(J27:J36) -> 17.333333 | K37: =AVERAGE(K27:K36) -> 1636 | L37: =AVERAGE(L27:L36) -> 94.564542 | M37: =AVERAGE(M27:M36) -> 17.166667 | N37: =AVERAGE(N27:N36) -> 1488.989 | O37: =AVERAGE(O27:O36) -> 86.926868 | P37: =M37-J37 -> -0.16666667 | Q37: =N37-K37 -> -147.01096 | R37: =O37/L37 -> 0.91923321 | Z37: =SUM(Z27:Z36) -> 0 | AA37: =SUM(AA27:AA36) -> 0 | AD37: =SUM(AD27:AD36) -> 0 | AE37: =SUM(AE27:AE36) -> 0 | AF37: =N37-K37 -> -147.01096 | AG37: =N37/K37 -> 0.91014
A38: 手工四線 (ET-55) | B38: 熱乾麵 | D38: 青花椒麻雞肉拌麵 | F38: =VLOOKUP(D38,廠價表!$C$1:$E$43,3,0) -> 49.91 | G38: 2974 | H38: =F38*G38 -> 148432.34 | J38: =VLOOKUP(D38,產線配置圖!$A$3:$C$40,2,0) -> 16 | K38: =VLOOKUP(D38,產線配置圖!$A$3:$C$40,3,0) -> 1714 | L38: =K38/J38 -> 107.125 | M38: 16 | N38: =G38/W38*60 -> 1487 | O38: =N38/M38 -> 92.9375 | P38: =M38-J38 -> 0 | Q38: =O38-L38 -> -14.1875 | R38: =O38/L38 -> 0.86756126 | S38: =R48 -> 0.89782275 | T38: 0.33333333 | U38: 0.41666667 | W38: =(U38-T38)*24*60 -> 120 | AF38: =N38-K38 -> -227 | AG38: =N38/K38 -> 0.86756126 | AH38: =AG48 -> 0.8991231
B39: 熱乾麵 | D39: 府城鹽水意麵 | F39: =VLOOKUP(D39,廠價表!$C$1:$E$43,3,0) -> 44.3 | G39: 2169 | H39: =F39*G39 -> 96086.7 | J39: =VLOOKUP(D39,產線配置圖!$A$3:$C$40,2,0) -> 18 | K39: =VLOOKUP(D39,產線配置圖!$A$3:$C$40,3,0) -> 1636 | L39: =K39/J39 -> 90.888889 | M39: 18 | N39: =G39/W39*60 -> 1531.0588 | O39: =N39/M39 -> 85.058824 | P39: =M39-J39 -> 0 | Q39: =O39-L39 -> -5.8300654 | R39: =O39/L39 -> 0.93585503 | T39: 0.42708333 | U39: 0.48611111 | V39: =(T39-U38)*24*60 -> 15 | W39: =(U39-T39)*24*60 -> 85 | AF39: =N39-K39 -> -104.94118 | AG39: =N39/K39 -> 0.93585503
B40: 熱乾麵 | D40: 府城鹽水意麵 | F40: =VLOOKUP(D40,廠價表!$C$1:$E$43,3,0) -> 44.3 | G40: 3931 | H40: =F40*G40 -> 174143.3 | J40: =VLOOKUP(D40,產線配置圖!$A$3:$C$40,2,0) -> 18 | K40: =VLOOKUP(D40,產線配置圖!$A$3:$C$40,3,0) -> 1636 | L40: =K40/J40 -> 90.888889 | M40: 18 | N40: =G40/W40*60 -> 1464.9689 | O40: =N40/M40 -> 81.387164 | P40: =M40-J40 -> 0 | Q40: =O40-L40 -> -9.5017253 | R40: =O40/L40 -> 0.89545779 | T40: 0.54513889 | U40: 0.65694444 | V40: =(T40-U39)*24*60 -> 85 | W40: =(U40-T40)*24*60 -> 161 | AF40: =N40-K40 -> -171.03106 | AG40: =N40/K40 -> 0.89545779
...

Sheet 0803總
B1: 長家廠組合室生產人時性分析
B3: 日期 | D3: 46237 | F3: 訂單量 | G3: ='0803'!E1 -> 65714 | I3: 營業額 | J3: ='0803'!G1 -> 3028007.2
B4: 項目 | D4: 3 | F4: ➀ | H4: ➁ | J4: ③ | L4: 異常停線 | N4: 短暫停線
B5: 人時性 | D5: 組合室 | F5: 全溫層 | H5: 義大利麵 | J5: 袋裝小吃、義麵 | L5: 合計次數 | M5: 時間 | N5: 合計次數 | O5: 設備次數
D6: 排關平均 | F6: =AVERAGE(D13:J13) -> 126.99526 | H6: =AVERAGE(D13:H13) -> 124.64065 | J6: =AVERAGE(I13:J13) -> 132.88178 | L6: =SUM(D18:J18) -> 0 | M6: =SUM(D19:J19) -> 0 | N6: =SUM(D20:J20) -> 0 | O6: =SUM(D20:J20) -> 0
D7: 實績平均 | F7: =AVERAGE(D14:J14) -> 114.26601 | H7: =AVERAGE(D14:H14) -> 113.97518 | J7: =AVERAGE(I14:J14) -> 114.99308 | L7: =AVERAGE(K14:L14) -> #DIV/0! | M7: =AVERAGE(L14:M14) -> #DIV/0! | N7: =AVERAGE(M14:N14) -> #DIV/0! | O7: =AVERAGE(N14:O14) -> #DIV/0!
D8: 達成率平均 | F8: =F7/F6 -> 0.89976597 | H8: =H7/H6 -> 0.91443031 | J8: =J7/J6 -> 0.86537879 | L8: =AVERAGE(K15:L15) -> #DIV/0! | M8: =AVERAGE(L15:M15) -> #DIV/0! | N8: =AVERAGE(M15:N15) -> #DIV/0! | O8: =AVERAGE(N15:O15) -> #DIV/0!
J9: ※現行日本鮮食廠以達成率80%為基本(即為現行KPI)
B10: 溫層 | D10: 4度C-各編組展開
B11: 編組 | D11: 1 | E11: 2 | F11: 3 | G11: 4 | H11: 5 | I11: 6 | J11: 7
D12: 自動1線 | E12: 自動2線 | F12: 手工3線 | G12: 手工4線 | H12: 手工5線 | I12: 調理包1線 | J12: 調理包2線
B13: 人時性 | C13: 排關 | D13: =VALUE('0803'!L15) -> 151.35747 | E13: =VALUE('0803'!L26) -> 174.23077 | F13: =VALUE('0803'!L37) -> 94.551062 | G13: =VALUE('0803'!L48) -> 96.284518 | H13: =VALUE('0803'!L58) -> 106.77941 | I13: =VALUE('0803'!L69) -> 135.50707 | J13: ='0803'!L79 -> 130.25649
C14: 實績 | D14: =VALUE('0803'!O15) -> 138.93629 | E14: =VALUE('0803'!O26) -> 163.76634 | F14: =VALUE('0803'!O37) -> 83.53162 | G14: =VALUE('0803'!O48) -> 90.0093 | H14: =VALUE('0803'!O58) -> 93.632375 | I14: =VALUE('0803'!O69) -> 121.82747 | J14: ='0803'!O79 -> 108.15868
C15: 達成率 | D15: =D14/D13 -> 0.91793481 | E15: =E14/E13 -> 0.93993924 | F15: =F14/F13 -> 0.88345512 | G15: =G14/G13 -> 0.9348263 | H15: =H14/H13 -> 0.87687667 | I15: =I14/I13 -> 0.89904884 | J15: ='0803'!S70 -> 0.83035152
B16: 作業 時間 | C16: 開始 | D16: ='0803'!T5 -> 0.29305556 | E16: ='0803'!T16 -> 0.28819444 | F16: ='0803'!T27 -> 0.29513889 | G16: ='0803'!T38 -> 0.33333333 | H16: ='0803'!T49 -> 0.29097222 | I16: ='0803'!T59 -> 0.28819444 | J16: ='0803'!T70 -> 0.29166667
C17: 結束 | D17: 0.57777778 | E17: 0.63888889 | F17: 0.65625 | G17: 0.6875 | H17: 0.64930556 | I17: 0.51388889 | J17: 0.46527778
B18: 產線異常 (5分鐘以上) | C18: 次數 | D18: ='0803'!Z15 -> 0 | E18: ='0803'!Z26 -> 0 | F18: ='0803'!Z37 -> 0 | G18: ='0803'!Z48 -> 0 | H18: ='0803'!Z58 -> 0 | I18: ='0803'!Z69 -> 0 | J18: ='0803'!AA79 -> 0
C19: 時間/分 | D19: ='0803'!AA15 -> 0 | E19: ='0803'!AA26 -> 0 | F19: ='0803'!AA37 -> 0 | G19: ='0803'!AA48 -> 0 | H19: ='0803'!AA58 -> 0 | I19: ='0803'!AA69 -> 0 | J19: ='0803'!AB79 -> 0
B20: 短暫停線 (5分鐘以下) | C20: 次數 | D20: ='0803'!AD15 -> 0 | E20: ='0803'!AD26 -> 0 | F20: ='0803'!AD37 -> 0 | G20: ='0803'!AD48 -> 0 | H20: ='0803'!AD58 -> 0 | I20: ='0803'!AD69 -> 0 | J20: ='0803'!AD79 -> 0
C21: 設備次數 | D21: ='0803'!AE15 -> 0 | E21: ='0803'!AE26 -> 0 | F21: ='0803'!AE37 -> 0 | G21: ='0803'!AE48 -> 0 | H21: ='0803'!AE58 -> 0 | I21: ='0803'!AE69 -> 0 | J21: ='0803'!AE79 -> 0
B22: 配置人數 | D22: =VALUE('0803'!M15) -> 15 | E22: =VALUE('0803'!M26) -> 13 | F22: =VALUE('0803'!M37) -> 16.875 | G22: =VALUE('0803'!M48) -> 16 | H22: =VALUE('0803'!M58) -> 16.5 | I22: =VALUE('0803'!M69) -> 12.333333 | J22: ='0803'!M79 -> 11
B23: 主要應用設備 | D23: ET-600 | E23: ET-600 | F23: ET-55 | G23: ET-55 | H23: ET-55 | I23: 八爪機 | J23: 八爪機
B24: 次要應用設備 | H24: 封口機 | J24: 封口機
B25: 備註

Sheet 0803
A1: 長家廠4度C日報分析 | D1: 總生產量 | E1: =SUM(G5:G79) -> 65714 | F1: 營業額 | G1: =SUM(H5:H79) -> 3028007.2 | H1: 出勤人數 | I1: =M15+M26+M48+M58+M69+M79+M37 -> 100.70833 | J1: 產線配置圖 | M1: 生產實績 | P1: 人時性差異分析 | T1: 日報登錄 | Z1: 合計 次數 | AA1: 合計 時間/分 | AB1: 分析說明 | AD1: 合計 次數 | AE1: 合計 設備次數 | AF1: 產能差異分析
A2: 8月3日 星期一 | D2: 人時性 | E2: =AVERAGE(O15,O26,O37,O48,O58,O69,O79) -> 114.26601 | F2: 平均廠價 | G2: =G1/E1 -> 46.07857 | H2: 多次生產數 | I2: =COUNT(I5:I79) -> 0 | Z2: =Z15+Z26+Z37+Z48+Z58+Z69+Z79 -> 0 | AA2: =AA15+AA26+AA37+AA48+AA58+AA69+AA79 -> 0 | AD2: =AD15+AD26+AD37+AD48+AD58+AD69+AD79 -> 0 | AE2: =AE15+AE26+AE37+AE48+AE58+AE69+AE79 -> 0
A3: 線別 | B3: 品類 | D3: 品名 | F3: 廠價 | G3: 生產量 | H3: 營收 | I3: 多次 生產 | J3: 人數 | K3: 產能/時 | L3: 人時性 | M3: 人數 | N3: 產能/時 | O3: 人時性 | P3: 人數 | Q3: 人時性 | R3: 達成率 | S3: 達成率平均 | T3: 生產時間 | V3: 前置、換線時間/分 | W3: 稼動時間/分 | X3: 休息時間 | Z3: 產線異常統計 (5分鐘以上) | AD3: 短暫停線統計 (5分鐘以下) | AF3: 產能/時 | AG3: 達成率 | AH3: 達成率平均
T4: 開始 | U4: 結束 | X4: 開始 | Y4: 結束 | Z4: 次數 | AA4: 時間/分 | AD4: 總次數 | AE4: 設備因素(次數)
A5: 自動一線 (ET-600) | B5: 義大利麵 | D5: 羅馬黑胡椒起司義大利麵 | F5: =VLOOKUP(D5,廠價表!$C$1:$E$43,3,0) -> 50.67 | G5: 2188 | H5: =F5*G5 -> 110865.96 | J5: =VLOOKUP(D5,產線配置圖!$A$3:$C$40,2,0) -> 17 | K5: =VLOOKUP(D5,產線配置圖!$A$3:$C$40,3,0) -> 2250 | L5: =K5/J5 -> 132.35294 | M5: 17 | N5: =G5/W5*60 -> 2051.25 | O5: =N5/M5 -> 120.66176 | P5: =M5-J5 -> 0 | Q5: =O5-L5 -> -11.691176 | R5: =O5/L5 -> 0.91166667 | S5: =R15 -> 0.91793481 | T5: 0.29305556 | U5: 0.3375 | W5: =(U5-T5)*24*60 -> 64 | AB5: 8:10-8:15注醬機異常 | AF5: =N5-K5 -> -198.75 | AG5: =N5/K5 -> 0.91166667 | AH5: =AG15 -> 0.91950252
B6: 義大利麵 | D6: 香煎魚排佐檸檬奶油義大利麵 | F6: =VLOOKUP(D6,廠價表!$C$1:$E$43,3,0) -> 58.17 | G6: 1832 | H6: =F6*G6 -> 106567.44 | J6: =VLOOKUP(D6,產線配置圖!$A$3:$C$40,2,0) -> 13 | K6: =VLOOKUP(D6,產線配置圖!$A$3:$C$40,3,0) -> 2250 | L6: =K6/J6 -> 173.07692 | M6: 13 | N6: =G6/W6*60 -> 1962.8571 | O6: =N6/M6 -> 150.98901 | P6: =M6-J6 -> 0 | Q6: =O6-L6 -> -22.087912 | R6: =O6/L6 -> 0.87238095 | T6: 0.34513889 | U6: 0.38402778 | V6: =(T6-U5)*24*60 -> 11 | W6: =(U6-T6)*24*60 -> 56 | AF6: =N6-K6 -> -287.14286 | AG6: =N6/K6 -> 0.87238095
B7: 義大利麵 | D7: 奶油培根義大利麵 | F7: =VLOOKUP(D7,廠價表!$C$1:$E$43,3,0) -> 49.14 | G7: 4619 | H7: =F7*G7 -> 226977.66 | J7: =VLOOKUP(D7,產線配置圖!$A$3:$C$40,2,0) -> 15 | K7: =VLOOKUP(D7,產線配置圖!$A$3:$C$40,3,0) -> 2250 | L7: =K7/J7 -> 150 | M7: 15 | N7: =G7/W7*60 -> 2148.3721 | O7: =N7/M7 -> 143.22481 | P7: =M7-J7 -> 0 | Q7: =O7-L7 -> -6.7751938 | R7: =O7/L7 -> 0.95483204 | T7: 0.38958333 | U7: 0.47916667 | V7: =(T7-U6)*24*60 -> 8 | W7: =(U7-T7)*24*60 -> 129 | AF7: =N7-K7 -> -101.62791 | AG7: =N7/K7 -> 0.95483204
B8: 義大利麵 | D8: 奶油培根義大利麵 | F8: =VLOOKUP(D8,廠價表!$C$1:$E$43,3,0) -> 49.14 | G8: 1620 | H8: =F8*G8 -> 79606.8 | J8: =VLOOKUP(D8,產線配置圖!$A$3:$C$40,2,0) -> 15 | K8: =VLOOKUP(D8,產線配置圖!$A$3:$C$40,3,0) -> 2250 | L8: =K8/J8 -> 150 | M8: 15 | N8: =G8/W8*60 -> 2113.0435 | O8: =N8/M8 -> 140.86957 | P8: =M8-J8 -> 0 | Q8: =O8-L8 -> -9.1304348 | R8: =O8/L8 -> 0.93913043 | T8: 0.54583333 | U8: 0.57777778 | V8: =(T8-U7)*24*60 -> 96 | W8: =(U8-T8)*24*60 -> 46 | AF8: =N8-K8 -> -136.95652 | AG8: =N8/K8 -> 0.93913043
W9: =(U9-T9)*24*60 -> 0 | AF9: =N9-K9 -> 0 | AG9: =N9/K9 -> #DIV/0!
W10: =(U10-T10)*24*60 -> 0 | AF10: =N10-K10 -> 0 | AG10: =N10/K10 -> #DIV/0!
W11: =(U11-T11)*24*60 -> 0 | AF11: =N11-K11 -> 0 | AG11: =N11/K11 -> #DIV/0!
W12: =(U12-T12)*24*60 -> 0
W13: =(U13-T13)*24*60 -> 0
W14: =(U14-T14)*24*60 -> 0
C15: 4度一組 | D15: 平均 | J15: =AVERAGE(J5:J14) -> 15 | K15: =AVERAGE(K5:K14) -> 2250 | L15: =AVERAGE(L5:L14) -> 151.35747 | M15: =AVERAGE(M5:M14) -> 15 | N15: =AVERAGE(N5:N14) -> 2068.8807 | O15: =AVERAGE(O5:O14) -> 138.93629 | P15: =M15-J15 -> 0 | Q15: =O15-L15 -> -12.421179 | R15: =O15/L15 -> 0.91793481 | Z15: =SUM(Z5:Z14) -> 0 | AA15: =SUM(AA5:AA14) -> 0 | AD15: =SUM(AD5:AD14) -> 0 | AE15: =SUM(AE5:AE14) -> 0 | AF15: =N15-K15 -> -181.11932 | AG15: =N15/K15 -> 0.91950252
A16: 自動二線 (ET-600) | B16: 義大利麵 | D16: 青醬蛤蜊義大利麵 | F16: =VLOOKUP(D16,廠價表!$C$1:$E$43,3,0) -> 50.67 | G16: 2510 | H16: =F16*G16 -> 127181.7 | J16: =VLOOKUP(D16,產線配置圖!$A$3:$C$40,2,0) -> 13 | K16: =VLOOKUP(D16,產線配置圖!$A$3:$C$40,3,0) -> 2250 | L16: =K16/J16 -> 173.07692 | M16: 13 | N16: =G16/W16*60 -> 2151.4286 | O16: =N16/M16 -> 165.49451 | P16: =M16-J16 -> 0 | Q16: =O16-L16 -> -7.5824176 | R16: =O16/L16 -> 0.95619048 | S16: =R26 -> 0.93993924 | T16: 0.28819444 | U16: 0.33680556 | W16: =(U16-T16)*24*60 -> 70 | AF16: =N16-K16 -> -98.571429 | AG16: =N16/K16 -> 0.95619048 | AH16: =AG26 -> 0.94144371
B17: 義大利麵 | D17: 白酒清炒鮮蛤義大利麵 | F17: =VLOOKUP(D17,廠價表!$C$1:$E$43,3,0) -> 56.87 | G17: 3400 | H17: =F17*G17 -> 193358 | J17: =VLOOKUP(D17,產線配置圖!$A$3:$C$40,2,0) -> 15 | K17: =VLOOKUP(D17,產線配置圖!$A$3:$C$40,3,0) -> 2250 | L17: =K17/J17 -> 150 | M17: 15 | N17: =G17/W17*60 -> 2170.2128 | O17: =N17/M17 -> 144.68085 | P17: =M17-J17 -> 0 | Q17: =O17-L17 -> -5.3191489 | R17: =O17/L17 -> 0.96453901 | T17: 0.34236111 | U17: 0.40763889 | V17: =(T17-U16)*24*60 -> 8 | W17: =(U17-T17)*24*60 -> 94 | AF17: =N17-K17 -> -79.787234 | AG17: =N17/K17 -> 0.96453901
B18: 義大利麵 | D18: 義式蕃茄起司義大利麵 | F18: =VLOOKUP(D18,廠價表!$C$1:$E$43,3,0) -> 50.39 | G18: 3123 | H18: =F18*G18 -> 157367.97 | J18: =VLOOKUP(D18,產線配置圖!$A$3:$C$40,2,0) -> 12 | K18: =VLOOKUP(D18,產線配置圖!$A$3:$C$40,3,0) -> 2250 | L18: =K18/J18 -> 187.5 | M18: 12 | N18: =G18/W18*60 -> 2082 | O18: =N18/M18 -> 173.5 | P18: =M18-J18 -> 0 | Q18: =O18-L18 -> -14 | R18: =O18/L18 -> 0.92533333 | T18: 0.41319444 | U18: 0.47569444 | V18: =(T18-U17)*24*60 -> 8 | W18: =(U18-T18)*24*60 -> 90 | AF18: =N18-K18 -> -168 | AG18: =N18/K18 -> 0.92533333
B19: 義大利麵 | D19: 義式蕃茄起司義大利麵 | F19: =VLOOKUP(D19,廠價表!$C$1:$E$43,3,0) -> 50.39 | G19: 2982 | H19: =F19*G19 -> 150262.98 | J19: =VLOOKUP(D19,產線配置圖!$A$3:$C$40,2,0) -> 12 | K19: =VLOOKUP(D19,產線配置圖!$A$3:$C$40,3,0) -> 2250 | L19: =K19/J19 -> 187.5 | M19: 12 | N19: =G19/W19*60 -> 2033.1818 | O19: =N19/M19 -> 169.43182 | P19: =M19-J19 -> 0 | Q19: =O19-L19 -> -18.068182 | R19: =O19/L19 -> 0.90363636 | T19: 0.54166667 | U19: 0.60277778 | V19: =(T19-U18)*24*60 -> 95 | W19: =(U19-T19)*24*60 -> 88 | AF19: =N19-K19 -> -216.81818 | AG19: =N19/K19 -> 0.90363636
B20: 義大利麵 | D20: 青醬蛤蜊義大利麵 | F20: =VLOOKUP(D20,廠價表!$C$1:$E$43,3,0) -> 50.67 | G20: 1544 | H20: =F20*G20 -> 78234.48 | J20: =VLOOKUP(D20,產線配置圖!$A$3:$C$40,2,0) -> 13 | K20: =VLOOKUP(D20,產線配置圖!$A$3:$C$40,3,0) -> 2250 | L20: =K20/J20 -> 173.07692 | M20: 13 | N20: =G20/W20*60 -> 2154.4186 | O20: =N20/M20 -> 165.72451 | P20: =M20-J20 -> 0 | Q20: =O20-L20 -> -7.352415 | R20: =O20/L20 -> 0.95751938 | T20: 0.60902778 | U20: 0.63888889 | V20: =(T20-U19)*24*60 -> 9 | W20: =(U20-T20)*24*60 -> 43
W21: =(U21-T21)*24*60 -> 0
W22: 0
W23: =(U23-T23)*24*60 -> 0
H24: =F24*G24 -> 0 | W24: =(U24-T24)*24*60 -> 0
H25: =F25*G25 -> 0 | W25: =(U25-T25)*24*60 -> 0
C26: 4度二組A | D26: 平均 | J26: =AVERAGE(J16:J25) -> 13 | K26: =AVERAGE(K16:K25) -> 2250 | L26: =AVERAGE(L16:L25) -> 174.23077 | M26: =AVERAGE(M16:M25) -> 13 | N26: =AVERAGE(N16:N25) -> 2118.2484 | O26: =AVERAGE(O16:O25) -> 163.76634 | P26: =M26-J26 -> 0 | Q26: =O26-L26 -> -10.464433 | R26: =O26/L26 -> 0.93993924 | Z26: =SUM(Z16:Z25) -> 0 | AA26: =SUM(AA16:AA25) -> 0 | AD26: =SUM(AD16:AD25) -> 0 | AE26: =SUM(AE16:AE25) -> 0 | AF26: =N26-K26 -> -131.75165 | AG26: =N26/K26 -> 0.94144371
A27: 手工三線 (ET-55) | B27: 義大利麵 | D27: 蕃茄莎莎海鮮冷義大利麵 | F27: =VLOOKUP(D27,廠價表!$C$1:$E$43,3,0) -> 46.34 | G27: 1531 | H27: =F27*G27 -> 70946.54 | J27: =VLOOKUP(D27,產線配置圖!$A$3:$C$40,2,0) -> 16 | K27: =VLOOKUP(D27,產線配置圖!$A$3:$C$40,3,0) -> 1636 | L27: =K27/J27 -> 102.25 | M27: 16 | N27: =G27/W27*60 -> 1391.8182 | O27: =N27/M27 -> 86.988636 | P27: =M27-J27 -> 0 | Q27: =O27-L27 -> -15.261364 | R27: =O27/L27 -> 0.85074461 | S27: =R37 -> 0.88345512 | T27: 0.29513889 | U27: 0.34097222 | W27: =(U27-T27)*24*60 -> 66 | AF27: =N27-K27 -> -244.18182 | AG27: =N27/K27 -> 0.85074461 | AH27: =AG37 -> 0.8650739
B28: 義大利麵 | D28: 義式蛋蛋青醬鮪魚冷義大利麵 | F28: =VLOOKUP(D28,廠價表!$C$1:$E$43,3,0) -> 45.66 | G28: 1308 | H28: =F28*G28 -> 59723.28 | J28: =VLOOKUP(D28,產線配置圖!$A$3:$C$40,2,0) -> 17 | K28: =VLOOKUP(D28,產線配置圖!$A$3:$C$40,3,0) -> 1636 | L28: =K28/J28 -> 96.235294 | M28: 16 | N28: =G28/W28*60 -> 1376.8421 | O28: =N28/M28 -> 86.052632 | P28: =M28-J28 -> -1 | Q28: =O28-L28 -> -10.182663 | R28: =O28/L28 -> 0.89418994 | T28: 0.34791667 | U28: 0.3875 | V28: =(T28-U27)*24*60 -> 10 | W28: =(U28-T28)*24*60 -> 57 | AF28: =N28-K28 -> -259.15789 | AG28: =N28/K28 -> 0.84159053
B29: 義大利麵 | D29: 奶油鮮蝦明太子細扁麵 | F29: =VLOOKUP(D29,廠價表!$C$1:$E$43,3,0) -> 57.21 | G29: 942 | H29: =F29*G29 -> 53891.82 | J29: =VLOOKUP(D29,產線配置圖!$A$3:$C$40,2,0) -> 18 | K29: =VLOOKUP(D29,產線配置圖!$A$3:$C$40,3,0) -> 1636 | L29: =K29/J29 -> 90.888889 | M29: 17 | N29: =G29/W29*60 -> 1487.3684 | O29: =N29/M29 -> 87.49226 | P29: =M29-J29 -> -1 | Q29: =O29-L29 -> -3.3966288 | R29: =O29/L29 -> 0.96262878 | T29: 0.39236111 | U29: 0.41875 | V29: =(T29-U28)*24*60 -> 7 | W29: =(U29-T29)*24*60 -> 38 | AF29: =N29-K29 -> -148.63158 | AG29: =N29/K29 -> 0.9091494
B30: 義大利麵 | D30: 金沙豆腐義大利麵 | F30: =VLOOKUP(D30,廠價表!$C$1:$E$43,3,0) -> 49.91 | G30: 1672 | H30: =F30*G30 -> 83449.52 | J30: =VLOOKUP(D30,產線配置圖!$A$3:$C$40,2,0) -> 18 | K30: 1636 | L30: =K30/J30 -> 90.888889 | M30: 18 | N30: =G30/W30*60 -> 1433.1429 | O30: =N30/M30 -> 79.619048 | P30: =M30-J30 -> 0 | Q30: =O30-L30 -> -11.269841 | R30: =O30/L30 -> 0.87600419 | T30: 0.42361111 | U30: 0.47222222 | V30: =(T30-U29)*24*60 -> 7 | W30: =(U30-T30)*24*60 -> 70 | AF30: =N30-K30 -> -202.85714 | AG30: =N30/K30 -> 0.87600419
