Workbook

Sheet 廠價表
A1: check | B1: 溫層 | C1: 品名 | D1: 類別 | E1: 廠價
B2: 4度C | C2: 奶油鮮蝦明太子細扁麵 | D2: 義大利麵 | E2: 57.21
B3: 4度C | C3: 白酒清炒鮮蛤義大利麵 | D3: 義大利麵 | E3: 56.87
B4: 4度C | C4: 義式蕃茄起司義大利麵 | D4: 義大利麵 | E4: 50.39
B5: 4度C | C5: 焗烤起司雙饗筆尖麵 | D5: 義大利麵 | E5: 49.97
B6: 4度C | C6: 奶油培根義大利麵 | D6: 義大利麵 | E6: 49.14
B7: 4度C | C7: 焦糖拿鐵烤雞細扁麵 | D7: 義大利麵 | E7: 57.21
B8: 4度C | C8: 義式辣味嫩烤雞腿排義大利麵 | D8: 義大利麵 | E8: 56.61
B9: 4度C | C9: 金沙豆腐義大利麵 | D9: 義大利麵 | E9: 49.91
B10: 4度C | D10: 義大利麵
B11: 4度C | C11: 蒜香奶油蝦蝦義大利麵 | D11: 義大利麵 | E11: 57.21
B12: 4度C | C12: 鱈魚粉紅青醬筆尖麵 | D12: 義大利麵 | E12: 43.89
B13: 4度C | C13: 香煎魚排佐檸檬奶油義大利麵 | D13: 義大利麵 | E13: 58.17
B14: 4度C | C14: 青醬蛤蜊義大利麵 | D14: 義大利麵 | E14: 50.67
B15: 4度C | C15: 焗烤明太子筆尖麵 | D15: 義大利麵 | E15: 57.3
B16: 4度C | C16: 羅馬黑胡椒起司義大利麵 | D16: 義大利麵 | E16: 50.67
B17: 4度C | C17: 義式蛋蛋青醬鮪魚冷義大利麵 | D17: 義大利麵 | E17: 45.66
B18: 4度C | C18: 黑松露野菇義大利麵 | D18: 義大利麵 | E18: 50.289
B19: 4度C | C19: 青花椒麻雞肉拌麵 | D19: 熱乾麵 | E19: 49.91
B20: 4度C | C20: 府城鹽水意麵 | D20: 熱乾麵 | E20: 44.3
B21: 4度C | C21: 沙茶豬肉炒麵 | D21: 熱乾麵 | E21: 49.52
B22: 4度C | C22: 蕃茄莎莎海鮮冷義大利麵 | D22: 義大利麵 | E22: 46.34
... B26: 4度C | C26: 麻辣雞心 | D26: 小吃、微波 | E26: 28.26
B28: 4度C | C28: 鮮奶油白醬醬杯 | D28: 冷麵醬杯
B46: 冷凍 | C46: 青醬蛤蜊義大利麵 | D46: 冷凍調理麵 | E46: 29.38
B47: 冷凍 | C47: 經典肉醬義大利麵 | D47: 冷凍調理麵 | E47: 29.38
B48: 冷凍 | C48: 奶油蘑菇培根義大利麵 | D48: 冷凍調理麵 | E48: 29.38
B49: 冷凍 | C49: 清炒蛤蜊義大利麵 | D49: 冷凍調理麵 | E49: 29.38
B50: 冷凍 | C50: 青醬乳酪筆尖麵 | D50: 冷凍調理麵 | E50: 29.38
B51: 冷凍 | C51: 辣蕃茄義大利麵 | D51: 冷凍調理麵 | E51: 29.38
B52: 冷凍 | D52: 冷凍調理麵
B53: 冷凍 | C53: 韓式起司義大利麵 | D53: 冷凍調理麵 | E53: 29.38
B54: 冷凍 | D54: 冷凍調理麵
B55: 冷凍 | C55: 和風明太子細扁麵 | D55: 冷凍調理麵 | E55: 29.38

Sheet 產線配置圖
A1: 品項 | B1: 人數 | C1: 產能 | E1: 人時 | G1: 備註
A2: 義大利麵
A3: 白酒清炒鮮蛤義大利麵 | B3: 15 | C3: 2250 | D3: ET-600 | E3: =C3/B3 -> 150
A4: 白酒清炒鮮蛤義大利麵-手 | B4: 15 | C4: 1716 | D4: ET-55 | E4: =C4/B4 -> 114.4
A5: 青醬蛤蜊義大利麵 | B5: 14 | C5: 2250 | E5: =C5/B5 -> 160.71429
A6: 青醬蛤蜊義大利麵-手 | B6: 16 | C6: 1714 | E6: =C6/B6 -> 107.125
A7: 義式蕃茄起司義大利麵 | B7: 13 | C7: 2250 | E7: =C7/B7 -> 173.07692
A8: 奶油培根義大利麵 | B8: 15 | C8: 2250 | E8: =C8/B8 -> 150
A9: 蒜香奶油蝦蝦義大利麵 | B9: 17 | C9: 2250 | E9: =C9/B9 -> 132.35294
A10: 蒜香奶油蝦蝦義大利麵-手 | B10: 17 | C10: 1716 | E10: =C10/B10 -> 100.94118
A11: 鱈魚粉紅青醬筆尖麵 | B11: 17 | C11: 1636 | E11: =C11/B11 -> 96.235294
A12: 香煎魚排佐檸檬奶油義大利麵 | B12: 15 | C12: 2250 | E12: =C12/B12 -> 150
A13: 黑松露野菇義大利麵 | B13: 17 | C13: 1636 | E13: =C13/B13 -> 96.235294 | J13: 黑松露野菇義大利麵 | K13: 17 | L13: 1565 | N13: =L13/K13 -> 92.058824
A14: 青花椒麻雞肉拌麵 | B14: 15 | C14: 1714 | E14: =C14/B14 -> 114.26667 | J14: 青花椒麻雞肉拌麵 | K14: 14 | L14: 1714 | N14: =L14/K14 -> 122.42857
A15: 焗烤起司雙饗筆尖麵 | B15: 16 | C15: 1800 | E15: =C15/B15 -> 112.5 | G15: 目前使用手工 | J15: 焗烤起司雙饗筆尖麵 | K15: 15 | L15: 1800 | N15: =L15/K15 -> 120
A16: 沙茶豬肉炒麵 | B16: 17 | C16: 1800 | E16: =C16/B16 -> 105.88235 | J16: 沙茶豬肉炒麵 | K16: 16 | L16: 1500 | N16: =L16/K16 -> 93.75
A17: 府城鹽水意麵 | B17: 18 | C17: 1636 | E17: =C17/B17 -> 90.888889 | J17: 府城鹽水意麵 | K17: 16 | L17: 1636 | N17: =L17/K17 -> 102.25
A18: 義式辣味嫩烤雞腿排義大利麵 | B18: 15 | C18: 2250 | E18: =C18/B18 -> 150 | J18: 焗烤起司肉醬筆尖麵 | K18: 12 | L18: 1440 | N18: =L18/K18 -> 120
A19: 焗烤起司肉醬筆尖麵 | B19: 13 | C19: 1440 | E19: =C19/B19 -> 110.76923 | G19: 目前使用雙排 | J19: 整條德式香腸義大利麵 | K19: 16 | L19: 1565 | N19: =L19/K19 -> 97.8125
A20: 羅馬黑胡椒起司義大利麵 | B20: 16 | C20: 2250 | E20: =C20/B20 -> 140.625
A21: 奶油鮮蝦明太子細扁麵 | B21: 18 | C21: 1636 | E21: =C21/B21 -> 90.888889
A22: 焦糖拿鐵烤雞細扁麵 | B22: 18 | C22: 1565 | E22: =C22/B22 -> 86.944444
A23: 義式蛋蛋青醬鮪魚冷義大利麵 | B23: 17 | C23: 1500 | E23: =C23/B23 -> 88.235294
A24: 蕃茄莎莎海鮮冷義大利麵 | B24: 16 | C24: 1500 | E24: =C24/B24 -> 93.75
A25: 金沙豆腐義大利麵 | B25: 16 | C25: 2250 | E25: =C25/B25 -> 140.625
A26: 調理包
A27: 小滷青蔬 | B27: 15 | C27: 1636 | E27: =C27/B27 -> 109.06667 | G27: 夏季+1人補料
A28: 起司馬鈴薯 | B28: 11 | C28: 1636 | E28: =C28/B28 -> 148.72727
A29: 麻辣雞心 | B29: 11 | C29: 1636 | E29: =C29/B29 -> 148.72727
A30: 韓式炒冬粉 | B30: 11 | C30: 1636 | E30: =C30/B30 -> 148.72727
E34: 更新日期07/03

Sheet 範本總
B1: 長家廠組合室生產人時性分析
B3: 日期 | D3: 46015 | F3: 訂單量 | G3: =範本!E1 -> 43309 | I3: 營業額 | J3: =範本!G1 -> #N/A
B4: 項目 | D4: 3 | F4: ➀ | H4: ➁ | J4: ③ | L4: 異常停線 | N4: 短暫停線
B5: 人時性 | D5: 組合室 | F5: 全溫層 | H5: 義大利麵 | J5: 袋裝小吃、義麵 | L5: 合計次數 | M5: 時間 | N5: 合計次數 | O5: 設備次數
D6: 排關平均 | F6: =AVERAGE(D13:J13) -> #N/A | H6: =AVERAGE(D13:H13) -> #N/A | J6: =AVERAGE(I13:J13) -> #N/A | L6: =範本!Z2 -> 0 | M6: =範本!AA2 -> 0 | N6: =範本!AD2 -> 0 | O6: =範本!AE2 -> 0
D7: 實績平均 | F7: =AVERAGE(D14:J14) -> 116.11475 | H7: =AVERAGE(D14:H14) -> 117.36075 | J7: =AVERAGE(I14:J14) -> 112.99975
D8: 達成率平均 | F8: =AVERAGE(D15:J15) -> #N/A | H8: =AVERAGE(D15:H15) -> #N/A | J8: =AVERAGE(I15:J15) -> #N/A
J9: ※現行日本鮮食廠以達成率80%為基本(即為現行KPI)
B10: 溫層 | D10: 4度C-各編組展開
B11: 編組 | D11: 1 | E11: 2 | F11: 3 | G11: 4 | H11: 5 | I11: 6 | J11: 7
D12: 自動1線 | E12: 自動2線 | F12: 手工3線 | G12: 手工4線 | H12: 手工5線 | I12: 調理包1線 | J12: 調理包2線
B13: 人時性 | C13: 排關 | D13: =VALUE(範本!L15) -> #N/A | E13: =VALUE(範本!L26) -> #N/A | F13: =VALUE(範本!L37) -> #N/A | G13: =VALUE(範本!L48) -> #N/A | H13: =VALUE(範本!L58) -> #N/A | I13: =VALUE(範本!L69) -> #N/A | J13: =範本!L79 -> #N/A
C14: 實績 | D14: =VALUE(範本!O15) -> 113.91637 | E14: =VALUE(範本!O26) -> 132.12003 | F14: =VALUE(範本!O37) -> 126.23842 | G14: =VALUE(範本!O48) -> 112.0543 | H14: =VALUE(範本!O58) -> 102.47462 | I14: =VALUE(範本!O69) -> 155.46443 | J14: =範本!O79 -> 70.535065
C15: 達成率 | D15: =D14/D13 -> #N/A | E15: =E14/E13 -> #N/A | F15: =F14/F13 -> #N/A | G15: =G14/G13 -> #N/A | H15: =H14/H13 -> #N/A | I15: =I14/I13 -> #N/A | J15: =範本!S70 -> #N/A
B16: 作業 時間 | C16: 開始 | D16: =範本!T5 -> 0.29097222 | E16: =範本!T16 -> 0.29097222 | F16: =範本!T27 -> 0.29166667 | G16: =範本!T38 -> 0.33333333 | H16: =範本!T49 -> 0.29166667 | I16: =範本!T59 -> 0.29166667 | J16: =範本!T70 -> 0.34722222
C17: 結束 | D17: 0.47361111 | E17: 0.48263889 | F17: 0.56944444 | G17: 0.60416667 | H17: 0.58333333 | I17: 0.48819444 | J17: 0.46875
B18: 產線異常 (5分鐘以上) | C18: 次數
C19: 時間/分
B20: 短暫停線 (5分鐘以下) | C20: 次數
C21: 設備次數
B22: 配置人數 | D22: =VALUE(範本!M15) -> 15 | E22: =VALUE(範本!M26) -> 12.666667 | F22: =VALUE(範本!M37) -> 14.666667 | G22: =VALUE(範本!M48) -> 14 | H22: =VALUE(範本!M58) -> 17.666667 | I22: =VALUE(範本!M69) -> 12.333333 | J22: =範本!M79 -> 11
B23: 主要應用設備 | D23: ET-600 | E23: ET-600 | F23: ET-55 | G23: ET-55 | H23: ET-55 | I23: 八爪機
B24: 次要應用設備 | H24: 封口機
B25: 備註

Sheet 範本
A1: 長家廠4度C日報分析 | D1: 總生產量 | E1: =SUM(G5:G79) -> 43309 | F1: 營業額 | G1: =SUM(H5:H79) -> #N/A | H1: 出勤人數 | I1: =M15+M26+M48+M58+M69+M79+M37 -> 97.333333 | J1: 產線配置圖 | M1: 生產實績 | P1: 人時性差異分析 | T1: 日報登錄 | Z1: 合計 次數 | AA1: 合計 時間/分 | AB1: 分析說明 | AD1: 合計 次數 | AE1: 合計 設備次數 | AF1: 產能差異分析
A2: 12月24日 星期三 | D2: 人時性 | E2: =AVERAGE(O15,O26,O37,O48,O58,O69,O79) -> 116.11475 | F2: 平均廠價 | G2: =G1/E1 -> #N/A | H2: 多次生產數 | I2: =COUNT(I5:I79) -> 0 | Z2: =Z15+Z26+Z37+Z48+Z58+Z69+Z79 -> 0 | AA2: =AA15+AA26+AA37+AA48+AA58+AA69+AA79 -> 0 | AD2: =AD15+AD26+AD37+AD48+AD58+AD69+AD79 -> 0 | AE2: =AE15+AE26+AE37+AE48+AE58+AE69+AE79 -> 0
A3: 線別 | B3: 品類 | D3: 品名 | F3: 廠價 | G3: 生產量 | H3: 營收 | I3: 多次 生產 | J3: 人數 | K3: 產能/時 | L3: 人時性 | M3: 人數 | N3: 產能/時 | O3: 人時性 | P3: 人數 | Q3: 人時性 | R3: 達成率 | S3: 達成率平均 | T3: 生產時間 | V3: 前置、換線時間/分 | W3: 稼動時間/分 | X3: 休息時間 | Z3: 產線異常統計 (5分鐘以上) | AD3: 短暫停線統計 (5分鐘以下) | AF3: 產能/時 | AG3: 達成率 | AH3: 達成率平均
T4: 開始 | U4: 結束 | X4: 開始 | Y4: 結束 | Z4: 次數 | AA4: 時間/分 | AD4: 總次數 | AE4: 設備因素(次數)
A5: 自動一線 (ET-600) | B5: =VLOOKUP(D5,廠價表!$C$1:$E$43,2,0) -> #N/A | F5: =VLOOKUP(D5,廠價表!$C$1:$E$43,3,0) -> #N/A | G5: 2263 | H5: =F5*G5 -> #N/A | J5: =VLOOKUP(D5,產線配置圖!$A$3:$C$40,2,0) -> #N/A | K5: =VLOOKUP(D5,產線配置圖!$A$3:$C$40,3,0) -> #N/A | L5: =K5/J5 -> #N/A | M5: 15 | N5: =G5/W5*60 -> 1444.4681 | O5: =N5/M5 -> 96.297872 | P5: =M5-J5 -> #N/A | Q5: =O5-L5 -> #N/A | R5: =O5/L5 -> #N/A | S5: =R15 -> #N/A | T5: 0.29097222 | U5: 0.35625 | W5: =(U5-T5)*24*60 -> 94 | AF5: =N5-K5 -> #N/A | AG5: =N5/K5 -> #N/A | AH5: =AG15 -> #N/A
B6: =VLOOKUP(D6,廠價表!$C$1:$E$43,2,0) -> #N/A | F6: =VLOOKUP(D6,廠價表!$C$1:$E$43,3,0) -> #N/A | G6: 1180 | H6: =F6*G6 -> #N/A | J6: =VLOOKUP(D6,產線配置圖!$A$3:$C$40,2,0) -> #N/A | K6: =VLOOKUP(D6,產線配置圖!$A$3:$C$40,3,0) -> #N/A | L6: =K6/J6 -> #N/A | M6: 17 | N6: =G6/W6*60 -> 1609.0909 | O6: =N6/M6 -> 94.652406 | P6: =M6-J6 -> #N/A | Q6: =O6-L6 -> #N/A | R6: =O6/L6 -> #N/A | T6: 0.36458333 | U6: 0.39513889 | V6: =(T6-U5)*24*60 -> 12 | W6: =(U6-T6)*24*60 -> 44 | AF6: =N6-K6 -> #N/A | AG6: =N6/K6 -> #N/A
B7: =VLOOKUP(D7,廠價表!$C$1:$E$43,2,0) -> #N/A | F7: =VLOOKUP(D7,廠價表!$C$1:$E$43,3,0) -> #N/A | G7: 3398 | H7: =F7*G7 -> #N/A | J7: =VLOOKUP(D7,產線配置圖!$A$3:$C$40,2,0) -> #N/A | K7: =VLOOKUP(D7,產線配置圖!$A$3:$C$40,3,0) -> #N/A | L7: =K7/J7 -> #N/A | M7: 13 | N7: =G7/W7*60 -> 1960.3846 | O7: =N7/M7 -> 150.79882 | P7: =M7-J7 -> #N/A | Q7: =O7-L7 -> #N/A | R7: =O7/L7 -> #N/A | T7: 0.40138889 | U7: 0.47361111 | V7: =(T7-U6)*24*60 -> 9 | W7: =(U7-T7)*24*60 -> 104 | AF7: =N7-K7 -> #N/A | AG7: =N7/K7 -> #N/A
W8: =(U8-T8)*24*60 -> 0 | X8: 0.48611111 | Y8: 0.52777778 | AF8: =N8-K8 -> 0 | AG8: =N8/K8 -> #DIV/0!
W9: =(U9-T9)*24*60 -> 0 | AF9: =N9-K9 -> 0 | AG9: =N9/K9 -> #DIV/0!
W10: =(U10-T10)*24*60 -> 0 | AF10: =N10-K10 -> 0 | AG10: =N10/K10 -> #DIV/0!
W11: =(U11-T11)*24*60 -> 0 | AF11: =N11-K11 -> 0 | AG11: =N11/K11 -> #DIV/0!
W12: =(U12-T12)*24*60 -> 0
W13: =(U13-T13)*24*60 -> 0
W14: =(U14-T14)*24*60 -> 0
C15: 4度一組 | D15: 平均 | J15: =AVERAGE(J5:J14) -> #N/A | K15: =AVERAGE(K5:K14) -> #N/A | L15: =AVERAGE(L5:L14) -> #N/A | M15: =AVERAGE(M5:M14) -> 15 | N15: =AVERAGE(N5:N14) -> 1671.3145 | O15: =AVERAGE(O5:O14) -> 113.91637 | P15: =M15-J15 -> #N/A | Q15: =O15-L15 -> #N/A | R15: =O15/L15 -> #N/A | Z15: =SUM(Z5:Z14) -> 0 | AA15: =SUM(AA5:AA14) -> 0 | AD15: =SUM(AD5:AD14) -> 0 | AE15: =SUM(AE5:AE14) -> 0 | AF15: =N15-K15 -> #N/A | AG15: =N15/K15 -> #N/A
A16: 自動二線 (ET-600) | B16: =VLOOKUP(D16,廠價表!$C$1:$E$43,2,0) -> #N/A | F16: =VLOOKUP(D16,廠價表!$C$1:$E$43,3,0) -> #N/A | G16: 2263 | H16: =F16*G16 -> #N/A | J16: =VLOOKUP(D16,產線配置圖!$A$3:$C$40,2,0) -> #N/A | K16: =VLOOKUP(D16,產線配置圖!$A$3:$C$40,3,0) -> #N/A | L16: =K16/J16 -> #N/A | M16: 13 | N16: =G16/W16*60 -> 2225.9016 | O16: =N16/M16 -> 171.2232 | P16: =M16-J16 -> #N/A | Q16: =O16-L16 -> #N/A | R16: =O16/L16 -> #N/A | S16: =R26 -> #N/A | T16: 0.29097222 | U16: 0.33333333 | W16: =(U16-T16)*24*60 -> 61 | AF16: =N16-K16 -> #N/A | AG16: =N16/K16 -> #N/A | AH16: =AG26 -> #N/A
B17: =VLOOKUP(D17,廠價表!$C$1:$E$43,2,0) -> #N/A | F17: =VLOOKUP(D17,廠價表!$C$1:$E$43,3,0) -> #N/A | G17: 1180 | H17: =F17*G17 -> #N/A | J17: =VLOOKUP(D17,產線配置圖!$A$3:$C$40,2,0) -> #N/A | K17: =VLOOKUP(D17,產線配置圖!$A$3:$C$40,3,0) -> #N/A | L17: =K17/J17 -> #N/A | M17: 13 | N17: =G17/W17*60 -> 823.25581 | O17: =N17/M17 -> 63.32737 | P17: =M17-J17 -> #N/A | Q17: =O17-L17 -> #N/A | R17: =O17/L17 -> #N/A | T17: 0.34166667 | U17: 0.40138889 | V17: =(T17-U16)*24*60 -> 12 | W17: =(U17-T17)*24*60 -> 86 | AF17: =N17-K17 -> #N/A | AG17: =N17/K17 -> #N/A
B18: =VLOOKUP(D18,廠價表!$C$1:$E$43,2,0) -> #N/A | F18: =VLOOKUP(D18,廠價表!$C$1:$E$43,3,0) -> #N/A | G18: 3398 | H18: =F18*G18 -> #N/A | J18: =VLOOKUP(D18,產線配置圖!$A$3:$C$40,2,0) -> #N/A | K18: =VLOOKUP(D18,產線配置圖!$A$3:$C$40,3,0) -> #N/A | L18: =K18/J18 -> #N/A | M18: 12 | N18: =G18/W18*60 -> 1941.7143 | O18: =N18/M18 -> 161.80952 | P18: =M18-J18 -> #N/A | Q18: =O18-L18 -> #N/A | R18: =O18/L18 -> #N/A | T18: 0.40972222 | U18: 0.48263889 | V18: =(T18-U17)*24*60 -> 12 | W18: =(U18-T18)*24*60 -> 105 | X18: 0.48611111 | Y18: 0.52777778 | AF18: =N18-K18 -> #N/A | AG18: =N18/K18 -> #N/A
V19: =(T19-U18)*24*60 -> -695 | W19: =(U19-T19)*24*60 -> 0 | AF19: =N19-K19 -> 0 | AG19: =N19/K19 -> #DIV/0!
V20: =(T20-U19)*24*60 -> 0 | W20: =(U20-T20)*24*60 -> 0
W21: =(U21-T21)*24*60 -> 0
W22: 0
W23: =(U23-T23)*24*60 -> 0
H24: =F24*G24 -> 0 | W24: =(U24-T24)*24*60 -> 0
H25: =F25*G25 -> 0 | W25: =(U25-T25)*24*60 -> 0
C26: 4度二組A | D26: 平均 | J26: =AVERAGE(J16:J25) -> #N/A | K26: =AVERAGE(K16:K25) -> #N/A | L26: =AVERAGE(L16:L25) -> #N/A | M26: =AVERAGE(M16:M25) -> 12.666667 | N26: =AVERAGE(N16:N25) -> 1663.6239 | O26: =AVERAGE(O16:O25) -> 132.12003 | P26: =M26-J26 -> #N/A | Q26: =O26-L26 -> #N/A | R26: =O26/L26 -> #N/A | Z26: =SUM(Z16:Z25) -> 0 | AA26: =SUM(AA16:AA25) -> 0 | AD26: =SUM(AD16:AD25) -> 0 | AE26: =SUM(AE16:AE25) -> 0 | AF26: =N26-K26 -> #N/A | AG26: =N26/K26 -> #N/A
A27: 手工三線 (ET-55) | B27: =VLOOKUP(D27,廠價表!$C$1:$E$43,2,0) -> #N/A | F27: =VLOOKUP(D27,廠價表!$C$1:$E$43,3,0) -> #N/A | G27: 2263 | H27: =F27*G27 -> #N/A | J27: =VLOOKUP(D27,產線配置圖!$A$3:$C$40,2,0) -> #N/A | K27: =VLOOKUP(D27,產線配置圖!$A$3:$C$40,3,0) -> #N/A | L27: =K27/J27 -> #N/A | M27: 14 | N27: =G27/W27*60 -> 1212.3214 | O27: =N27/M27 -> 86.594388 | P27: =M27-J27 -> #N/A | Q27: =O27-L27 -> #N/A | R27: =O27/L27 -> #N/A | S27: =R37 -> #N/A | T27: 0.29166667 | U27: 0.36944444 | W27: =(U27-T27)*24*60 -> 112 | AF27: =N27-K27 -> #N/A | AG27: =N27/K27 -> #N/A | AH27: =AG37 -> #N/A
B28: =VLOOKUP(D28,廠價表!$C$1:$E$43,2,0) -> #N/A | F28: =VLOOKUP(D28,廠價表!$C$1:$E$43,3,0) -> #N/A | G28: 1180 | H28: =F28*G28 -> #N/A | J28: =VLOOKUP(D28,產線配置圖!$A$3:$C$40,2,0) -> #N/A | K28: =VLOOKUP(D28,產線配置圖!$A$3:$C$40,3,0) -> #N/A | L28: =K28/J28 -> #N/A | M28: 16 | N28: =G28/W28*60 -> 1089.2308 | O28: =N28/M28 -> 68.076923 | P28: =M28-J28 -> #N/A | Q28: =O28-L28 -> #N/A | R28: =O28/L28 -> #N/A | T28: 0.375 | U28: 0.42013889 | V28: =(T28-U27)*24*60 -> 8 | W28: =(U28-T28)*24*60 -> 65 | AF28: =N28-K28 -> #N/A | AG28: =N28/K28 -> #N/A
B29: =VLOOKUP(D29,廠價表!$C$1:$E$43,2,0) -> #N/A | F29: =VLOOKUP(D29,廠價表!$C$1:$E$43,3,0) -> #N/A | G29: 3398 | H29: =F29*G29 -> #N/A | J29: =VLOOKUP(D29,產線配置圖!$A$3:$C$40,2,0) -> #N/A | K29: =VLOOKUP(D29,產線配置圖!$A$3:$C$40,3,0) -> #N/A | L29: =K29/J29 -> #N/A | M29: 14 | N29: =G29/W29*60 -> 3136.6154 | O29: =N29/M29 -> 224.04396 | P29: =M29-J29 -> #N/A | Q29: =O29-L29 -> #N/A | R29: =O29/L29 -> #N/A | T29: 0.43055556 | U29: 0.47569444 | V29: =(T29-U28)*24*60 -> 15 | W29: =(U29-T29)*24*60 -> 65 | AF29: =N29-K29 -> #N/A | AG29: =N29/K29 -> #N/A
T30: 0.53958333 | U30: 0.56944444 | V30: =(T30-U29)*24*60 -> 92 | W30: =(U30-T30)*24*60 -> 43 | X30: 0.49652778 | Y30: 0.53819444 | AF30: =N30-K30 -> 0 | AG30: =N30/K30 -> #DIV/0!
W31: =(U31-T31)*24*60 -> 0 | AF31: =N31-K31 -> 0 | AG31: =N31/K31 -> #DIV/0!
W32: =(U32-T32)*24*60 -> 0
W33: =(U33-T33)*24*60 -> 0
W34: =(U34-T34)*24*60 -> 0
W35: =(U35-T35)*24*60 -> 0
H36: =F36*G36 -> 0 | W36: =(U36-T36)*24*60 -> 0
C37: 4度二組B | D37: 平均 | J37: =AVERAGE(J27:J36) -> #N/A | K37: =AVERAGE(K27:K36) -> #N/A | L37: =AVERAGE(L27:L36) -> #N/A | M37: =AVERAGE(M27:M36) -> 14.666667 | N37: =AVERAGE(N27:N36) -> 1812.7225 | O37: =AVERAGE(O27:O36) -> 126.23842 | P37: =M37-J37 -> #N/A | Q37: =N37-K37 -> #N/A | R37: =O37/L37 -> #N/A | Z37: =SUM(Z27:Z36) -> 0 | AA37: =SUM(AA27:AA36) -> 0 | AD37: =SUM(AD27:AD36) -> 0 | AE37: =SUM(AE27:AE36) -> 0 | AF37: =N37-K37 -> #N/A | AG37: =N37/K37 -> #N/A
A38: 手工四線 (ET-55) | B38: =VLOOKUP(D38,廠價表!$C$1:$E$43,2,0) -> #N/A | F38: =VLOOKUP(D38,廠價表!$C$1:$E$43,3,0) -> #N/A | G38: 2263 | H38: =F38*G38 -> #N/A | J38: =VLOOKUP(D38,產線配置圖!$A$3:$C$40,2,0) -> #N/A | K38: =VLOOKUP(D38,產線配置圖!$A$3:$C$40,3,0) -> #N/A | L38: =K38/J38 -> #N/A | M38: 14 | N38: =G38/W38*60 -> 1967.8261 | O38: =N38/M38 -> 140.55901 | P38: =M38-J38 -> #N/A | Q38: =O38-L38 -> #N/A | R38: =O38/L38 -> #N/A | S38: =R48 -> #N/A | T38: 0.33333333 | U38: 0.38125 | W38: =(U38-T38)*24*60 -> 69 | AF38: =N38-K38 -> #N/A | AG38: =N38/K38 -> #N/A | AH38: =AG48 -> #N/A
B39: =VLOOKUP(D39,廠價表!$C$1:$E$43,2,0) -> #N/A | F39: =VLOOKUP(D39,廠價表!$C$1:$E$43,3,0) -> #N/A | G39: 1180 | H39: =F39*G39 -> #N/A | J39: =VLOOKUP(D39,產線配置圖!$A$3:$C$40,2,0) -> #N/A | K39: =VLOOKUP(D39,產線配置圖!$A$3:$C$40,3,0) -> #N/A | L39: =K39/J39 -> #N/A | M39: 14 | N39: =G39/W39*60 -> 885 | O39: =N39/M39 -> 63.214286 | P39: =M39-J39 -> #N/A | Q39: =O39-L39 -> #N/A | R39: =O39/L39 -> #N/A | T39: 0.38888889 | U39: 0.44444444 | V39: =(T39-U38)*24*60 -> 11 | W39: =(U39-T39)*24*60 -> 80 | AF39: =N39-K39 -> #N/A | AG39: =N39/K39 -> #N/A
B40: =VLOOKUP(D40,廠價表!$C$1:$E$43,2,0) -> #N/A | F40: =VLOOKUP(D40,廠價表!$C$1:$E$43,3,0) -> #N/A | G40: 3398 | H40: =F40*G40 -> #N/A | J40: =VLOOKUP(D40,產線配置圖!$A$3:$C$40,2,0) -> #N/A | K40: =VLOOKUP(D40,產線配置圖!$A$3:$C$40,3,0) -> #N/A | L40: =K40/J40 -> #N/A | M40: 14 | N40: =G40/W40*60 -> 1853.4545 | O40: =N40/M40 -> 132.38961 | P40: =M40-J40 -> #N/A | Q40: =O40-L40 -> #N/A | R40: =O40/L40 -> #N/A | T40: 0.52777778 | U40: 0.60416667 | V40: =(T40-U39)*24*60 -> 120 | W40: =(U40-T40)*24*60 -> 110 | AF40: =N40-K40 -> #N/A | AG40: =N40/K40 -> #N/A
...

Sheet 0701總
B1: 長家廠組合室生產人時性分析
B3: 日期 | D3: 46204 | F3: 訂單量 | G3: ='0701'!E1 -> 64738 | I3: 營業額 | J3: ='0701'!G1 -> 3010182.4
B4: 項目 | D4: 3 | F4: ➀ | H4: ➁ | J4: ③ | L4: 異常停線 | N4: 短暫停線
B5: 人時性 | D5: 組合室 | F5: 全溫層 | H5: 義大利麵 | J5: 袋裝小吃、義麵 | L5: 合計次數 | M5: 時間 | N5: 合計次數 | O5: 設備次數
D6: 排關平均 | F6: =AVERAGE(D13:J13) -> 121.72738 | H6: =AVERAGE(D13:H13) -> 121.15704 | J6: =AVERAGE(I13:J13) -> 123.15322 | L6: =SUM(D18:J18) -> 1 | M6: =SUM(D19:J19) -> 9 | N6: =SUM(D20:J20) -> 1 | O6: =SUM(D20:J20) -> 1
D7: 實績平均 | F7: =AVERAGE(D14:J14) -> 108.40728 | H7: =AVERAGE(D14:H14) -> 106.54982 | J7: =AVERAGE(I14:J14) -> 113.05094 | L7: =AVERAGE(K14:L14) -> #DIV/0! | M7: =AVERAGE(L14:M14) -> #DIV/0! | N7: =AVERAGE(M14:N14) -> #DIV/0! | O7: =AVERAGE(N14:O14) -> #DIV/0!
D8: 達成率平均 | F8: =F7/F6 -> 0.89057439 | H8: =H7/H6 -> 0.87943568 | J8: =J7/J6 -> 0.9179698 | L8: =AVERAGE(K15:L15) -> #DIV/0! | M8: =AVERAGE(L15:M15) -> #DIV/0! | N8: =AVERAGE(M15:N15) -> #DIV/0! | O8: =AVERAGE(N15:O15) -> #DIV/0!
J9: ※現行日本鮮食廠以達成率80%為基本(即為現行KPI)
B10: 溫層 | D10: 4度C-各編組展開
B11: 編組 | D11: 1 | E11: 2 | F11: 3 | G11: 4 | H11: 5 | I11: 6 | J11: 7
D12: 自動1線 | E12: 自動2線 | F12: 手工3線 | G12: 手工4線 | H12: 手工5線 | I12: 調理包1線 | J12: 調理包2線
B13: 人時性 | C13: 排關 | D13: =VALUE('0701'!L15) -> 150 | E13: =VALUE('0701'!L26) -> 158.32256 | F13: =VALUE('0701'!L37) -> 88.57598 | G13: =VALUE('0701'!L48) -> 104.21607 | H13: =VALUE('0701'!L58) -> 104.67059 | I13: =VALUE('0701'!L69) -> 138.81212 | J13: ='0701'!L79 -> 107.49432
C14: 實績 | D14: =VALUE('0701'!O15) -> 132.90076 | E14: =VALUE('0701'!O26) -> 133.8214 | F14: =VALUE('0701'!O37) -> 84.392772 | G14: =VALUE('0701'!O48) -> 85.224943 | H14: =VALUE('0701'!O58) -> 96.409242 | I14: =VALUE('0701'!O69) -> 133.72964 | J14: ='0701'!O79 -> 92.372238
C15: 達成率 | D15: =D14/D13 -> 0.88600506 | E15: =E14/E13 -> 0.84524531 | F15: =F14/F13 -> 0.95277266 | G15: =G14/G13 -> 0.81777162 | H15: =H14/H13 -> 0.9210729 | I15: =I14/I13 -> 0.96338587 | J15: ='0701'!S70 -> 0.85932205
B16: 作業 時間 | C16: 開始 | D16: ='0701'!T5 -> 0.30486111 | E16: ='0701'!T16 -> 0.29166667 | F16: ='0701'!T27 -> 0.29166667 | G16: ='0701'!T38 -> 0.33333333 | H16: ='0701'!T49 -> 0.29097222 | I16: ='0701'!T59 -> 0.29166667 | J16: ='0701'!T70 -> 0.22430556
C17: 結束 | D17: 0.61111111 | E17: 0.61875 | F17: 0.59375 | G17: 0.67916667 | H17: 0.63055556 | I17: 0.60416667 | J17: 0.67708333
B18: 產線異常 (5分鐘以上) | C18: 次數 | D18: ='0701'!Z15 -> 0 | E18: ='0701'!Z26 -> 1 | F18: ='0701'!Z37 -> 0 | G18: ='0701'!Z48 -> 0 | H18: ='0701'!Z58 -> 0 | I18: ='0701'!Z69 -> 0 | J18: ='0701'!AA79 -> 0
C19: 時間/分 | D19: ='0701'!AA15 -> 0 | E19: ='0701'!AA26 -> 9 | F19: ='0701'!AA37 -> 0 | G19: ='0701'!AA48 -> 0 | H19: ='0701'!AA58 -> 0 | I19: ='0701'!AA69 -> 0 | J19: ='0701'!AB79 -> 0
B20: 短暫停線 (5分鐘以下) | C20: 次數 | D20: ='0701'!AD15 -> 1 | E20: ='0701'!AD26 -> 0 | F20: ='0701'!AD37 -> 0 | G20: ='0701'!AD48 -> 0 | H20: ='0701'!AD58 -> 0 | I20: ='0701'!AD69 -> 0 | J20: ='0701'!AD79 -> 0
C21: 設備次數 | D21: ='0701'!AE15 -> 1 | E21: ='0701'!AE26 -> 0 | F21: ='0701'!AE37 -> 0 | G21: ='0701'!AE48 -> 0 | H21: ='0701'!AE58 -> 0 | I21: ='0701'!AE69 -> 0 | J21: ='0701'!AE79 -> 0
B22: 配置人數 | D22: =VALUE('0701'!M15) -> 15 | E22: =VALUE('0701'!M26) -> 14.333333 | F22: =VALUE('0701'!M37) -> 17 | G22: =VALUE('0701'!M48) -> 16.6 | H22: =VALUE('0701'!M58) -> 16.6 | I22: =VALUE('0701'!M69) -> 11.75 | J22: ='0701'!M79 -> 14
B23: 主要應用設備 | D23: ET-600 | E23: ET-600 | F23: ET-55 | G23: ET-55 | H23: ET-55 | I23: 八爪機 | J23: 八爪機
B24: 次要應用設備 | H24: 封口機 | J24: 封口機
B25: 備註

Sheet 0701
A1: 長家廠4度C日報分析 | D1: 總生產量 | E1: =SUM(G5:G79) -> 64738 | F1: 營業額 | G1: =SUM(H5:H79) -> 3010182.4 | H1: 出勤人數 | I1: =M15+M26+M48+M58+M69+M79+M37 -> 105.28333 | J1: 產線配置圖 | M1: 生產實績 | P1: 人時性差異分析 | T1: 日報登錄 | Z1: 合計 次數 | AA1: 合計 時間/分 | AB1: 分析說明 | AD1: 合計 次數 | AE1: 合計 設備次數 | AF1: 產能差異分析
A2: 07月01日 星期三 | D2: 人時性 | E2: =AVERAGE(O15,O26,O37,O48,O58,O69,O79) -> 108.40728 | F2: 平均廠價 | G2: =G1/E1 -> 46.497921 | H2: 多次生產數 | I2: =COUNT(I5:I79) -> 0 | Z2: =Z15+Z26+Z37+Z48+Z58+Z69+Z79 -> 1 | AA2: =AA15+AA26+AA37+AA48+AA58+AA69+AA79 -> 9 | AD2: =AD15+AD26+AD37+AD48+AD58+AD69+AD79 -> 1 | AE2: =AE15+AE26+AE37+AE48+AE58+AE69+AE79 -> 1
A3: 線別 | B3: 品類 | D3: 46204 | F3: 廠價 | G3: 生產量 | H3: 營收 | I3: 多次 生產 | J3: 人數 | K3: 產能/時 | L3: 人時性 | M3: 人數 | N3: 產能/時 | O3: 人時性 | P3: 人數 | Q3: 人時性 | R3: 達成率 | S3: 達成率平均 | T3: 生產時間 | V3: 前置、換線時間/分 | W3: 稼動時間/分 | X3: 休息時間 | Z3: 產線異常統計 (5分鐘以上) | AD3: 短暫停線統計 (5分鐘以下) | AF3: 產能/時 | AG3: 達成率 | AH3: 達成率平均
T4: 開始 | U4: 結束 | X4: 開始 | Y4: 結束 | Z4: 次數 | AA4: 時間/分 | AD4: 總次數 | AE4: 設備因素(次數)
A5: 自動一線 (ET-600) | B5: 義大利麵 | D5: 白酒清炒鮮蛤義大利麵 | F5: =VLOOKUP(D5,廠價表!$C$1:$E$43,3,0) -> 56.87 | G5: 2856 | H5: =F5*G5 -> 162420.72 | J5: =VLOOKUP(D5,產線配置圖!$A$3:$C$40,2,0) -> 15 | K5: =VLOOKUP(D5,產線配置圖!$A$3:$C$40,3,0) -> 2250 | L5: =K5/J5 -> 150 | M5: 15 | N5: =G5/W5*60 -> 2089.7561 | O5: =N5/M5 -> 139.31707 | P5: =M5-J5 -> 0 | Q5: =O5-L5 -> -10.682927 | R5: =O5/L5 -> 0.92878049 | S5: =R15 -> 0.88600506 | T5: 0.30486111 | U5: 0.36180556 | W5: =(U5-T5)*24*60 -> 82 | AB5: 7:00-7:16更換熱轉印印字頭 | AF5: =N5-K5 -> -160.2439 | AG5: =N5/K5 -> 0.92878049 | AH5: =AG15 -> 0.88600506
B6: 義大利麵 | D6: 香煎魚排佐檸檬奶油義大利麵 | F6: =VLOOKUP(D6,廠價表!$C$1:$E$43,3,0) -> 58.17 | G6: 2363 | H6: =F6*G6 -> 137455.71 | J6: =VLOOKUP(D6,產線配置圖!$A$3:$C$40,2,0) -> 15 | K6: =VLOOKUP(D6,產線配置圖!$A$3:$C$40,3,0) -> 2250 | L6: =K6/J6 -> 150 | M6: 15 | N6: =G6/W6*60 -> 1794.6835 | O6: =N6/M6 -> 119.64557 | P6: =M6-J6 -> 0 | Q6: =O6-L6 -> -30.35443 | R6: =O6/L6 -> 0.79763713 | T6: 0.36875 | U6: 0.42361111 | V6: =(T6-U5)*24*60 -> 10 | W6: =(U6-T6)*24*60 -> 79 | AB6: 9:22-9:26玉取機停麵 | AD6: 1 | AE6: 1 | AF6: =N6-K6 -> -455.31646 | AG6: =N6/K6 -> 0.79763713
B7: 義大利麵 | D7: 奶油培根義大利麵 | F7: =VLOOKUP(D7,廠價表!$C$1:$E$43,3,0) -> 49.14 | G7: 2355 | H7: =F7*G7 -> 115724.7 | J7: =VLOOKUP(D7,產線配置圖!$A$3:$C$40,2,0) -> 15 | K7: =VLOOKUP(D7,產線配置圖!$A$3:$C$40,3,0) -> 2250 | L7: =K7/J7 -> 150 | M7: 15 | N7: =G7/W7*60 -> 2018.5714 | O7: =N7/M7 -> 134.57143 | P7: =M7-J7 -> 0 | Q7: =O7-L7 -> -15.428571 | R7: =O7/L7 -> 0.89714286 | T7: 0.43055556 | U7: 0.47916667 | V7: =(T7-U6)*24*60 -> 10 | W7: =(U7-T7)*24*60 -> 70 | AF7: =N7-K7 -> -231.42857 | AG7: =N7/K7 -> 0.89714286
B8: 義大利麵 | D8: 奶油培根義大利麵 | F8: =VLOOKUP(D8,廠價表!$C$1:$E$43,3,0) -> 49.14 | G8: 3003 | H8: =F8*G8 -> 147567.42 | J8: =VLOOKUP(D8,產線配置圖!$A$3:$C$40,2,0) -> 15 | K8: =VLOOKUP(D8,產線配置圖!$A$3:$C$40,3,0) -> 2250 | L8: =K8/J8 -> 150 | M8: 15 | N8: =G8/W8*60 -> 2071.0345 | O8: =N8/M8 -> 138.06897 | P8: =M8-J8 -> 0 | Q8: =O8-L8 -> -11.931034 | R8: =O8/L8 -> 0.92045977 | T8: 0.55069444 | U8: 0.61111111 | V8: =(T8-U7)*24*60 -> 103 | W8: =(U8-T8)*24*60 -> 87 | X8: 0.48611111 | Y8: 0.52777778 | AF8: =N8-K8 -> -178.96552 | AG8: =N8/K8 -> 0.92045977
W9: =(U9-T9)*24*60 -> 0 | AF9: =N9-K9 -> 0 | AG9: =N9/K9 -> #DIV/0!
W10: =(U10-T10)*24*60 -> 0 | AF10: =N10-K10 -> 0 | AG10: =N10/K10 -> #DIV/0!
W11: =(U11-T11)*24*60 -> 0 | AF11: =N11-K11 -> 0 | AG11: =N11/K11 -> #DIV/0!
W12: =(U12-T12)*24*60 -> 0
W13: =(U13-T13)*24*60 -> 0
W14: =(U14-T14)*24*60 -> 0
C15: 4度一組 | D15: 平均 | J15: =AVERAGE(J5:J14) -> 15 | K15: =AVERAGE(K5:K14) -> 2250 | L15: =AVERAGE(L5:L14) -> 150 | M15: =AVERAGE(M5:M14) -> 15 | N15: =AVERAGE(N5:N14) -> 1993.5114 | O15: =AVERAGE(O5:O14) -> 132.90076 | P15: =M15-J15 -> 0 | Q15: =O15-L15 -> -17.099241 | R15: =O15/L15 -> 0.88600506 | Z15: =SUM(Z5:Z14) -> 0 | AA15: =SUM(AA5:AA14) -> 0 | AD15: =SUM(AD5:AD14) -> 1 | AE15: =SUM(AE5:AE14) -> 1 | AF15: =N15-K15 -> -256.48861 | AG15: =N15/K15 -> 0.88600506
A16: 自動二線 (ET-600) | B16: 義大利麵 | D16: 青醬蛤蜊義大利麵 | F16: =VLOOKUP(D16,廠價表!$C$1:$E$43,3,0) -> 50.67 | G16: 2146 | H16: =F16*G16 -> 108737.82 | J16: =VLOOKUP(D16,產線配置圖!$A$3:$C$40,2,0) -> 14 | K16: =VLOOKUP(D16,產線配置圖!$A$3:$C$40,3,0) -> 2250 | L16: =K16/J16 -> 160.71429 | M16: 14 | N16: =G16/W16*60 -> 2043.8095 | O16: =N16/M16 -> 145.98639 | P16: =M16-J16 -> 0 | Q16: =O16-L16 -> -14.727891 | R16: =O16/L16 -> 0.90835979 | S16: =R26 -> 0.84524531 | T16: 0.29166667 | U16: 0.33541667 | W16: =(U16-T16)*24*60 -> 63 | AF16: =N16-K16 -> -206.19048 | AG16: =N16/K16 -> 0.90835979 | AH16: =AG26 -> 0.84267829
B17: 義大利麵 | D17: 蒜香奶油蝦蝦義大利麵 | F17: =VLOOKUP(D17,廠價表!$C$1:$E$43,3,0) -> 57.21 | G17: 1666 | H17: =F17*G17 -> 95311.86 | J17: =VLOOKUP(D17,產線配置圖!$A$3:$C$40,2,0) -> 17 | K17: =VLOOKUP(D17,產線配置圖!$A$3:$C$40,3,0) -> 2250 | L17: =K17/J17 -> 132.35294 | M17: 17 | N17: =G17/W17*60 -> 1922.3077 | O17: =N17/M17 -> 113.07692 | P17: =M17-J17 -> 0 | Q17: =O17-L17 -> -19.276018 | R17: =O17/L17 -> 0.85435897 | T17: 0.34375 | U17: 0.37986111 | V17: =(T17-U16)*24*60 -> 12 | W17: =(U17-T17)*24*60 -> 52 | AF17: =N17-K17 -> -327.69231 | AG17: =N17/K17 -> 0.85435897
B18: 義大利麵 | D18: 義式辣味嫩烤雞腿排義大利麵 | F18: =VLOOKUP(D18,廠價表!$C$1:$E$43,3,0) -> 56.61 | G18: 948 | H18: =F18*G18 -> 53666.28 | J18: =VLOOKUP(D18,產線配置圖!$A$3:$C$40,2,0) -> 15 | K18: =VLOOKUP(D18,產線配置圖!$A$3:$C$40,3,0) -> 2250 | L18: =K18/J18 -> 150 | M18: 15 | N18: =G18/W18*60 -> 1672.9412 | O18: =N18/M18 -> 111.52941 | P18: =M18-J18 -> 0 | Q18: =O18-L18 -> -38.470588 | R18: =O18/L18 -> 0.74352941 | T18: 0.38819444 | U18: 0.41180556 | V18: =(T18-U17)*24*60 -> 12 | W18: =(U18-T18)*24*60 -> 34 | X18: 0.48611111 | Y18: 0.52777778 | AB18: 9:22-9:26玉取機停麵 | AF18: =N18-K18 -> -577.05882 | AG18: =N18/K18 -> 0.74352941
B19: 義大利麵 | D19: 義式蕃茄起司義大利麵 | F19: =VLOOKUP(D19,廠價表!$C$1:$E$43,3,0) -> 50.39 | G19: 2988 | H19: =F19*G19 -> 150565.32 | J19: =VLOOKUP(D19,產線配置圖!$A$3:$C$40,2,0) -> 13 | K19: =VLOOKUP(D19,產線配置圖!$A$3:$C$40,3,0) -> 2250 | L19: =K19/J19 -> 173.07692 | M19: 13 | N19: =G19/W19*60 -> 2109.1765 | O19: =N19/M19 -> 162.24434 | P19: =M19-J19 -> 0 | Q19: =O19-L19 -> -10.832579 | R19: =O19/L19 -> 0.93741176 | T19: 0.42013889 | U19: 0.47916667 | V19: =(T19-U18)*24*60 -> 12 | W19: =(U19-T19)*24*60 -> 85 | AF19: =N19-K19 -> -140.82353 | AG19: =N19/K19 -> 0.93741176
B20: 義大利麵 | D20: 義式蕃茄起司義大利麵 | F20: =VLOOKUP(D20,廠價表!$C$1:$E$43,3,0) -> 50.39 | G20: 1462 | H20: =F20*G20 -> 73670.18 | J20: =VLOOKUP(D20,產線配置圖!$A$3:$C$40,2,0) -> 13 | K20: =VLOOKUP(D20,產線配置圖!$A$3:$C$40,3,0) -> 2250 | L20: =K20/J20 -> 173.07692 | M20: 13 | N20: =G20/W20*60 -> 1993.6364 | O20: =N20/M20 -> 153.35664 | P20: =M20-J20 -> 0 | Q20: =O20-L20 -> -19.72028 | R20: =O20/L20 -> 0.88606061 | T20: 0.54930556 | U20: 0.57986111 | V20: =(T20-U19)*24*60 -> 101 | W20: =(U20-T20)*24*60 -> 44
B21: 義大利麵 | D21: 青醬蛤蜊義大利麵 | F21: =VLOOKUP(D21,廠價表!$C$1:$E$43,3,0) -> 50.67 | G21: 1144 | H21: =F21*G21 -> 57966.48 | J21: =VLOOKUP(D21,產線配置圖!$A$3:$C$40,2,0) -> 14 | K21: =VLOOKUP(D21,產線配置圖!$A$3:$C$40,3,0) -> 2250 | L21: =K21/J21 -> 160.71429 | M21: 14 | N21: =G21/W21*60 -> 1634.2857 | O21: =N21/M21 -> 116.73469 | P21: =M21-J21 -> 0 | Q21: =O21-L21 -> -43.979592 | R21: =O21/L21 -> 0.72634921 | T21: 0.58958333 | U21: 0.61875 | V21: =(T21-U20)*24*60 -> 14 | W21: =(U21-T21)*24*60 -> 42 | Z21: 1 | AA21: 9 | AB21: 14:42-14:51封口機異常(加工膠帶脫落)
W22: 0
W23: =(U23-T23)*24*60 -> 0
H24: =F24*G24 -> 0 | W24: =(U24-T24)*24*60 -> 0
H25: =F25*G25 -> 0 | W25: =(U25-T25)*24*60 -> 0
C26: 4度二組A | D26: 平均 | J26: =AVERAGE(J16:J25) -> 14.333333 | K26: =AVERAGE(K16:K25) -> 2250 | L26: =AVERAGE(L16:L25) -> 158.32256 | M26: =AVERAGE(M16:M25) -> 14.333333 | N26: =AVERAGE(N16:N25) -> 1896.0262 | O26: =AVERAGE(O16:O25) -> 133.8214 | P26: =M26-J26 -> 0 | Q26: =O26-L26 -> -24.501158 | R26: =O26/L26 -> 0.84524531 | Z26: =SUM(Z16:Z25) -> 1 | AA26: =SUM(AA16:AA25) -> 9 | AD26: =SUM(AD16:AD25) -> 0 | AE26: =SUM(AE16:AE25) -> 0 | AF26: =N26-K26 -> -353.97384 | AG26: =N26/K26 -> 0.84267829
A27: 手工三線 (ET-55) | B27: 義大利麵 | D27: 義式蛋蛋青醬鮪魚冷義大利麵 | F27: =VLOOKUP(D27,廠價表!$C$1:$E$43,3,0) -> 45.66 | G27: 1800 | H27: =F27*G27 -> 82188 | J27: =VLOOKUP(D27,產線配置圖!$A$3:$C$40,2,0) -> 17 | K27: =VLOOKUP(D27,產線配置圖!$A$3:$C$40,3,0) -> 1500 | L27: =K27/J27 -> 88.235294 | M27: 17 | N27: =G27/W27*60 -> 1440 | O27: =N27/M27 -> 84.705882 | P27: =M27-J27 -> 0 | Q27: =O27-L27 -> -3.5294118 | R27: =O27/L27 -> 0.96 | S27: =R37 -> 0.95277266 | T27: 0.29166667 | U27: 0.34375 | W27: =(U27-T27)*24*60 -> 75 | AF27: =N27-K27 -> -60 | AG27: =N27/K27 -> 0.96 | AH27: =AG37 -> 0.92544888
B28: 義大利麵 | D28: 奶油鮮蝦明太子細扁麵 | F28: =VLOOKUP(D28,廠價表!$C$1:$E$43,3,0) -> 57.21 | G28: 2304 | H28: =F28*G28 -> 131811.84 | J28: =VLOOKUP(D28,產線配置圖!$A$3:$C$40,2,0) -> 18 | K28: =VLOOKUP(D28,產線配置圖!$A$3:$C$40,3,0) -> 1636 | L28: =K28/J28 -> 90.888889 | M28: 17 | N28: =G28/W28*60 -> 1486.4516 | O28: =N28/M28 -> 87.43833 | P28: =M28-J28 -> -1 | Q28: =O28-L28 -> -3.4505587 | R28: =O28/L28 -> 0.96203542 | T28: 0.35208333 | U28: 0.41666667 | V28: =(T28-U27)*24*60 -> 12 | W28: =(U28-T28)*24*60 -> 93 | AF28: =N28-K28 -> -149.54839 | AG28: =N28/K28 -> 0.90858901
B29: 義大利麵 | D29: 焦糖拿鐵烤雞細扁麵 | F29: =VLOOKUP(D29,廠價表!$C$1:$E$43,3,0) -> 57.21 | G29: 1592 | H29: =F29*G29 -> 91078.32 | J29: =VLOOKUP(D29,產線配置圖!$A$3:$C$40,2,0) -> 18 | K29: =VLOOKUP(D29,產線配置圖!$A$3:$C$40,3,0) -> 1565 | L29: =K29/J29 -> 86.944444 | M29: 17 | N29: =G29/W29*60 -> 1404.7059 | O29: =N29/M29 -> 82.629758 | P29: =M29-J29 -> -1 | Q29: =O29-L29 -> -4.3146867 | R29: =O29/L29 -> 0.95037421 | T29: 0.42152778 | U29: 0.46875 | V29: =(T29-U28)*24*60 -> 7 | W29: =(U29-T29)*24*60 -> 68 | AF29: =N29-K29 -> -160.29412 | AG29: =N29/K29 -> 0.89757564
B30: 義大利麵 | D30: 義式蛋蛋青醬鮪魚冷義大利麵 | F30: =VLOOKUP(D30,廠價表!$C$1:$E$43,3,0) -> 45.66 | G30: 2299 | H30: =F30*G30 -> 104972.34 | J30: =VLOOKUP(D30,產線配置圖!$A$3:$C$40,2,0) -> 17 | K30: =VLOOKUP(D30,產線配置圖!$A$3:$C$40,3,0) -> 1500 | L30: =K30/J30 -> 88.235294 | M30: 17 | N30: =G30/W30*60 -> 1407.551 | O30: =N30/M30 -> 82.797119 | P30: =M30-J30 -> 0 | Q30: =O30-L30 -> -5.4381753 | R30: =O30/L30 -> 0.93836735 | T30: 0.52569444 | U30: 0.59375 | V30: =(T30-U29)*24*60 -> 82 | W30: =(U30-T30)*24*60 -> 98 | X30: 0.49652778 | Y30: 0.53819444 | AF30: =N30-K30 -> -92.44898 | AG30: =N30/K30 -> 0.93836735
W31: =(U31-T31)*24*60 -> 0 | AF31: =N31-K31 -> 0 | AG31: =N31/K31 -> #DIV/0!
W32: =(U32-T32)*24*60 -> 0
W33: =(U33-T33)*24*60 -> 0
W34: =(U34-T34)*24*60 -> 0
W35: =(U35-T35)*24*60 -> 0
H36: =F36*G36 -> 0 | W36: =(U36-T36)*24*60 -> 0
C37: 4度二組B | D37: 平均 | J37: =AVERAGE(J27:J36) -> 17.5 | K37: =AVERAGE(K27:K36) -> 1550.25 | L37: =AVERAGE(L27:L36) -> 88.57598 | M37: =AVERAGE(M27:M36) -> 17 | N37: =AVERAGE(N27:N36) -> 1434.6771 | O37: =AVERAGE(O27:O36) -> 84.392772 | P37: =M37-J37 -> -0.5 | Q37: =N37-K37 -> -115.57287 | R37: =O37/L37 -> 0.95277266 | Z37: =SUM(Z27:Z36) -> 0 | AA37: =SUM(AA27:AA36) -> 0 | AD37: =SUM(AD27:AD36) -> 0 | AE37: =SUM(AE27:AE36) -> 0 | AF37: =N37-K37 -> -115.57287 | AG37: =N37/K37 -> 0.92544888
A38: 手工四線 (ET-55) | B38: 義大利麵 | D38: 焗烤起司肉醬筆尖麵 | F38: 50.67 | G38: 1160 | H38: =F38*G38 -> 58777.2 | J38: =VLOOKUP(D38,產線配置圖!$A$3:$C$40,2,0) -> 13 | K38: =VLOOKUP(D38,產線配置圖!$A$3:$C$40,3,0) -> 1440 | L38: =K38/J38 -> 110.76923 | M38: 13 | N38: =G38/W38*60 -> 1160 | O38: =N38/M38 -> 89.230769 | P38: =M38-J38 -> 0 | Q38: =O38-L38 -> -21.538462 | R38: =O38/L38 -> 0.80555556 | S38: =R48 -> 0.81777162 | T38: 0.33333333 | U38: 0.375 | W38: =(U38-T38)*24*60 -> 60 | AF38: =N38-K38 -> -280 | AG38: =N38/K38 -> 0.80555556 | AH38: =AG48 -> 0.86567536
B39: 熱乾麵 | D39: 青花椒麻雞肉拌麵 | F39: =VLOOKUP(D39,廠價表!$C$1:$E$43,3,0) -> 49.91 | G39: 1975 | H39: =F39*G39 -> 98572.25 | J39: =VLOOKUP(D39,產線配置圖!$A$3:$C$40,2,0) -> 15 | K39: =VLOOKUP(D39,產線配置圖!$A$3:$C$40,3,0) -> 1714 | L39: =K39/J39 -> 114.26667 | M39: 17 | N39: =G39/W39*60 -> 1538.961 | O39: =N39/M39 -> 90.52712 | P39: =M39-J39 -> 2 | Q39: =O39-L39 -> -23.739547 | R39: =O39/L39 -> 0.79224434 | T39: 0.38055556 | U39: 0.43402778 | V39: =(T39-U38)*24*60 -> 8 | W39: =(U39-T39)*24*60 -> 77 | AB39: 加兩名新人熟悉作業 | AF39: =N39-K39 -> -175.03896 | AG39: =N39/K39 -> 0.89787692
B40: 熱乾麵 | D40: 府城鹽水意麵 | F40: =VLOOKUP(D40,廠價表!$C$1:$E$43,3,0) -> 44.3 | G40: 2286 | H40: =F40*G40 -> 101269.8 | J40: =VLOOKUP(D40,產線配置圖!$A$3:$C$40,2,0) -> 18 | K40: =VLOOKUP(D40,產線配置圖!$A$3:$C$40,3,0) -> 1636 | L40: =K40/J40 -> 90.888889 | M40: 19 | N40: =G40/W40*60 -> 1524 | O40: =N40/M40 -> 80.210526 | P40: =M40-J40 -> 1 | Q40: =O40-L40 -> -10.678363 | R40: =O40/L40 -> 0.8825119 | T40: 0.44097222 | U40: 0.50347222 | V40: =(T40-U39)*24*60 -> 10 | W40: =(U40-T40)*24*60 -> 90 | AB40: 加一名新人熟悉作業 | AF40: =N40-K40 -> -112 | AG40: =N40/K40 -> 0.93154034
...

Sheet 0702總
B1: 長家廠組合室生產人時性分析
B3: 日期 | D3: 46205 | F3: 訂單量 | G3: ='0702'!E1 -> 62631 | I3: 營業額 | J3: ='0702'!G1 -> 2923029.5
B4: 項目 | D4: 3 | F4: ➀ | H4: ➁ | J4: ③ | L4: 異常停線 | N4: 短暫停線
B5: 人時性 | D5: 組合室 | F5: 全溫層 | H5: 義大利麵 | J5: 袋裝小吃、義麵 | L5: 合計次數 | M5: 時間 | N5: 合計次數 | O5: 設備次數
D6: 排關平均 | F6: =AVERAGE(D13:J13) -> 121.15875 | H6: =AVERAGE(D13:H13) -> 120.14264 | J6: =AVERAGE(I13:J13) -> 123.69904 | L6: =SUM(D18:J18) -> 0 | M6: =SUM(D19:J19) -> 0 | N6: =SUM(D20:J20) -> 0 | O6: =SUM(D20:J20) -> 0
D7: 實績平均 | F7: =AVERAGE(D14:J14) -> 108.68309 | H7: =AVERAGE(D14:H14) -> 109.91731 | J7: =AVERAGE(I14:J14) -> 105.59753 | L7: =AVERAGE(K14:L14) -> #DIV/0! | M7: =AVERAGE(L14:M14) -> #DIV/0! | N7: =AVERAGE(M14:N14) -> #DIV/0! | O7: =AVERAGE(N14:O14) -> #DIV/0!
D8: 達成率平均 | F8: =F7/F6 -> 0.89703043 | H8: =H7/H6 -> 0.9148901 | J8: =J7/J6 -> 0.85366494 | L8: =AVERAGE(K15:L15) -> #DIV/0! | M8: =AVERAGE(L15:M15) -> #DIV/0! | N8: =AVERAGE(M15:N15) -> #DIV/0! | O8: =AVERAGE(N15:O15) -> #DIV/0!
J9: ※現行日本鮮食廠以達成率80%為基本(即為現行KPI)
B10: 溫層 | D10: 4度C-各編組展開
B11: 編組 | D11: 1 | E11: 2 | F11: 3 | G11: 4 | H11: 5 | I11: 6 | J11: 7
D12: 自動1線 | E12: 自動2線 | F12: 手工3線 | G12: 手工4線 | H12: 手工5線 | I12: 調理包1線 | J12: 調理包2線
B13: 人時性 | C13: 排關 | D13: =VALUE('0702'!L15) -> 150 | E13: =VALUE('0702'!L26) -> 158.32256 | F13: =VALUE('0702'!L37) -> 89.038562 | G13: =VALUE('0702'!L48) -> 98.681481 | H13: =VALUE('0702'!L58) -> 104.67059 | I13: =VALUE('0702'!L69) -> 138.81212 | J13: ='0702'!L79 -> 108.58596
C14: 實績 | D14: =VALUE('0702'!O15) -> 136.05149 | E14: =VALUE('0702'!O26) -> 139.69092 | F14: =VALUE('0702'!O37) -> 82.417618 | G14: =VALUE('0702'!O48) -> 93.809626 | H14: =VALUE('0702'!O58) -> 97.61689 | I14: =VALUE('0702'!O69) -> 128.5303 | J14: ='0702'!O79 -> 82.664761
C15: 達成率 | D15: =D14/D13 -> 0.90700996 | E15: =E14/E13 -> 0.8823185 | F15: =F14/F13 -> 0.92563959 | G15: =G14/G13 -> 0.9506305 | H15: =H14/H13 -> 0.93261051 | I15: =I14/I13 -> 0.92592997 | J15: ='0702'!S70 -> 0.7612841
B16: 作業 時間 | C16: 開始 | D16: ='0702'!T5 -> 0.29375 | E16: ='0702'!T16 -> 0.29027778 | F16: ='0702'!T27 -> 0.28819444 | G16: ='0702'!T38 -> 0.33333333 | H16: ='0702'!T49 -> 0.29027778 | I16: ='0702'!T59 -> 0.28819444 | J16: ='0702'!T70 -> 0.29166667
C17: 結束 | D17: 0.59166667 | E17: 0.60625 | F17: 0.64583333 | G17: 0.58333333 | H17: 0.61111111 | I17: 0.59375 | J17: 0.71875
B18: 產線異常 (5分鐘以上) | C18: 次數 | D18: ='0702'!Z15 -> 0 | E18: ='0702'!Z26 -> 0 | F18: ='0702'!Z37 -> 0 | G18: ='0702'!Z48 -> 0 | H18: ='0702'!Z58 -> 0 | I18: ='0702'!Z69 -> 0 | J18: ='0702'!AA79 -> 0
C19: 時間/分 | D19: ='0702'!AA15 -> 0 | E19: ='0702'!AA26 -> 0 | F19: ='0702'!AA37 -> 0 | G19: ='0702'!AA48 -> 0 | H19: ='0702'!AA58 -> 0 | I19: ='0702'!AA69 -> 0 | J19: ='0702'!AB79 -> 0
B20: 短暫停線 (5分鐘以下) | C20: 次數 | D20: ='0702'!AD15 -> 0 | E20: ='0702'!AD26 -> 0 | F20: ='0702'!AD37 -> 0 | G20: ='0702'!AD48 -> 0 | H20: ='0702'!AD58 -> 0 | I20: ='0702'!AD69 -> 0 | J20: ='0702'!AD79 -> 0
C21: 設備次數 | D21: ='0702'!AE15 -> 0 | E21: ='0702'!AE26 -> 0 | F21: ='0702'!AE37 -> 0 | G21: ='0702'!AE48 -> 0 | H21: ='0702'!AE58 -> 0 | I21: ='0702'!AE69 -> 0 | J21: ='0702'!AE79 -> 0
B22: 配置人數 | D22: =VALUE('0702'!M15) -> 15 | E22: =VALUE('0702'!M26) -> 14.333333 | F22: =VALUE('0702'!M37) -> 17.2 | G22: =VALUE('0702'!M48) -> 16.333333 | H22: =VALUE('0702'!M58) -> 16.6 | I22: =VALUE('0702'!M69) -> 12 | J22: ='0702'!M79 -> 13.166667
B23: 主要應用設備 | D23: ET-600 | E23: ET-600 | F23: ET-55 | G23: ET-55 | H23: ET-55 | I23: 八爪機 | J23: 八爪機
B24: 次要應用設備 | H24: 封口機 | J24: 封口機
B25: 備註

Sheet 0702
A1: 長家廠4度C日報分析 | D1: 總生產量 | E1: =SUM(G5:G79) -> 62631 | F1: 營業額 | G1: =SUM(H5:H79) -> 2923029.5 | H1: 出勤人數 | I1: =M15+M26+M48+M58+M69+M79+M37 -> 104.63333 | J1: 產線配置圖 | M1: 生產實績 | P1: 人時性差異分析 | T1: 日報登錄 | Z1: 合計 次數 | AA1: 合計 時間/分 | AB1: 分析說明 | AD1: 合計 次數 | AE1: 合計 設備次數 | AF1: 產能差異分析
A2: 07月02日 星期四 | D2: 人時性 | E2: =AVERAGE(O15,O26,O37,O48,O58,O69,O79) -> 108.68309 | F2: 平均廠價 | G2: =G1/E1 -> 46.670651 | H2: 多次生產數 | I2: =COUNT(I5:I79) -> 0 | Z2: =Z15+Z26+Z37+Z48+Z58+Z69+Z79 -> 0 | AA2: =AA15+AA26+AA37+AA48+AA58+AA69+AA79 -> 0 | AD2: =AD15+AD26+AD37+AD48+AD58+AD69+AD79 -> 0 | AE2: =AE15+AE26+AE37+AE48+AE58+AE69+AE79 -> 0
A3: 線別 | B3: 品類 | D3: 品名 | F3: 廠價 | G3: 生產量 | H3: 營收 | I3: 多次 生產 | J3: 人數 | K3: 產能/時 | L3: 人時性 | M3: 人數 | N3: 產能/時 | O3: 人時性 | P3: 人數 | Q3: 人時性 | R3: 達成率 | S3: 達成率平均 | T3: 生產時間 | V3: 前置、換線時間/分 | W3: 稼動時間/分 | X3: 休息時間 | Z3: 產線異常統計 (5分鐘以上) | AD3: 短暫停線統計 (5分鐘以下) | AF3: 產能/時 | AG3: 達成率 | AH3: 達成率平均
T4: 開始 | U4: 結束 | X4: 開始 | Y4: 結束 | Z4: 次數 | AA4: 時間/分 | AD4: 總次數 | AE4: 設備因素(次數)
A5: 自動一線 (ET-600) | B5: 義大利麵 | D5: 白酒清炒鮮蛤義大利麵 | F5: =VLOOKUP(D5,廠價表!$C$1:$E$43,3,0) -> 56.87 | G5: 2765 | H5: =F5*G5 -> 157245.55 | J5: =VLOOKUP(D5,產線配置圖!$A$3:$C$40,2,0) -> 15 | K5: =VLOOKUP(D5,產線配置圖!$A$3:$C$40,3,0) -> 2250 | L5: =K5/J5 -> 150 | M5: 15 | N5: =G5/W5*60 -> 2048.1481 | O5: =N5/M5 -> 136.54321 | P5: =M5-J5 -> 0 | Q5: =O5-L5 -> -13.45679 | R5: =O5/L5 -> 0.91028807 | S5: =R15 -> 0.90700996 | T5: 0.29375 | U5: 0.35 | W5: =(U5-T5)*24*60 -> 81 | AF5: =N5-K5 -> -201.85185 | AG5: =N5/K5 -> 0.91028807 | AH5: =AG15 -> 0.90700996
B6: 義大利麵 | D6: 香煎魚排佐檸檬奶油義大利麵 | F6: =VLOOKUP(D6,廠價表!$C$1:$E$43,3,0) -> 58.17 | G6: 2330 | H6: =F6*G6 -> 135536.1 | J6: =VLOOKUP(D6,產線配置圖!$A$3:$C$40,2,0) -> 15 | K6: =VLOOKUP(D6,產線配置圖!$A$3:$C$40,3,0) -> 2250 | L6: =K6/J6 -> 150 | M6: 15 | N6: =G6/W6*60 -> 2086.5672 | O6: =N6/M6 -> 139.10448 | P6: =M6-J6 -> 0 | Q6: =O6-L6 -> -10.895522 | R6: =O6/L6 -> 0.92736318 | T6: 0.36111111 | U6: 0.40763889 | V6: =(T6-U5)*24*60 -> 16 | W6: =(U6-T6)*24*60 -> 67 | AF6: =N6-K6 -> -163.43284 | AG6: =N6/K6 -> 0.92736318
B7: 義大利麵 | D7: 奶油培根義大利麵 | F7: =VLOOKUP(D7,廠價表!$C$1:$E$43,3,0) -> 49.14 | G7: 3190 | H7: =F7*G7 -> 156756.6 | J7: =VLOOKUP(D7,產線配置圖!$A$3:$C$40,2,0) -> 15 | K7: =VLOOKUP(D7,產線配置圖!$A$3:$C$40,3,0) -> 2250 | L7: =K7/J7 -> 150 | M7: 15 | N7: =G7/W7*60 -> 2150.5618 | O7: =N7/M7 -> 143.37079 | P7: =M7-J7 -> 0 | Q7: =O7-L7 -> -6.6292135 | R7: =O7/L7 -> 0.95580524 | T7: 0.41666667 | U7: 0.47847222 | V7: =(T7-U6)*24*60 -> 13 | W7: =(U7-T7)*24*60 -> 89 | AF7: =N7-K7 -> -99.438202 | AG7: =N7/K7 -> 0.95580524
B8: 義大利麵 | D8: 奶油培根義大利麵 | F8: =VLOOKUP(D8,廠價表!$C$1:$E$43,3,0) -> 49.14 | G8: 2003 | H8: =F8*G8 -> 98427.42 | J8: =VLOOKUP(D8,產線配置圖!$A$3:$C$40,2,0) -> 15 | K8: =VLOOKUP(D8,產線配置圖!$A$3:$C$40,3,0) -> 2250 | L8: =K8/J8 -> 150 | M8: 15 | N8: =G8/W8*60 -> 1877.8125 | O8: =N8/M8 -> 125.1875 | P8: =M8-J8 -> 0 | Q8: =O8-L8 -> -24.8125 | R8: =O8/L8 -> 0.83458333 | T8: 0.54722222 | U8: 0.59166667 | V8: =(T8-U7)*24*60 -> 99 | W8: =(U8-T8)*24*60 -> 64 | AF8: =N8-K8 -> -372.1875 | AG8: =N8/K8 -> 0.83458333
W9: =(U9-T9)*24*60 -> 0 | AF9: =N9-K9 -> 0 | AG9: =N9/K9 -> #DIV/0!
W10: =(U10-T10)*24*60 -> 0 | AF10: =N10-K10 -> 0 | AG10: =N10/K10 -> #DIV/0!
W11: =(U11-T11)*24*60 -> 0 | AF11: =N11-K11 -> 0 | AG11: =N11/K11 -> #DIV/0!
W12: =(U12-T12)*24*60 -> 0
W13: =(U13-T13)*24*60 -> 0
W14: =(U14-T14)*24*60 -> 0
C15: 4度一組 | D15: 平均 | J15: =AVERAGE(J5:J14) -> 15 | K15: =AVERAGE(K5:K14) -> 2250 | L15: =AVERAGE(L5:L14) -> 150 | M15: =AVERAGE(M5:M14) -> 15 | N15: =AVERAGE(N5:N14) -> 2040.7724 | O15: =AVERAGE(O5:O14) -> 136.05149 | P15: =M15-J15 -> 0 | Q15: =O15-L15 -> -13.948506 | R15: =O15/L15 -> 0.90700996 | Z15: =SUM(Z5:Z14) -> 0 | AA15: =SUM(AA5:AA14) -> 0 | AD15: =SUM(AD5:AD14) -> 0 | AE15: =SUM(AE5:AE14) -> 0 | AF15: =N15-K15 -> -209.2276 | AG15: =N15/K15 -> 0.90700996
A16: 自動二線 (ET-600) | B16: 義大利麵 | D16: 青醬蛤蜊義大利麵 | F16: =VLOOKUP(D16,廠價表!$C$1:$E$43,3,0) -> 50.67 | G16: 2109 | H16: =F16*G16 -> 106863.03 | J16: =VLOOKUP(D16,產線配置圖!$A$3:$C$40,2,0) -> 14 | K16: =VLOOKUP(D16,產線配置圖!$A$3:$C$40,3,0) -> 2250 | L16: =K16/J16 -> 160.71429 | M16: 14 | N16: =G16/W16*60 -> 2040.9677 | O16: =N16/M16 -> 145.78341 | P16: =M16-J16 -> 0 | Q16: =O16-L16 -> -14.930876 | R16: =O16/L16 -> 0.90709677 | S16: =R26 -> 0.8823185 | T16: 0.29027778 | U16: 0.33333333 | W16: =(U16-T16)*24*60 -> 62 | AF16: =N16-K16 -> -209.03226 | AG16: =N16/K16 -> 0.90709677 | AH16: =AG26 -> 0.87905376
B17: 義大利麵 | D17: 蒜香奶油蝦蝦義大利麵 | F17: =VLOOKUP(D17,廠價表!$C$1:$E$43,3,0) -> 57.21 | G17: 1656 | H17: =F17*G17 -> 94739.76 | J17: =VLOOKUP(D17,產線配置圖!$A$3:$C$40,2,0) -> 17 | K17: =VLOOKUP(D17,產線配置圖!$A$3:$C$40,3,0) -> 2250 | L17: =K17/J17 -> 132.35294 | M17: 17 | N17: =G17/W17*60 -> 1874.717 | O17: =N17/M17 -> 110.27747 | P17: =M17-J17 -> 0 | Q17: =O17-L17 -> -22.075472 | R17: =O17/L17 -> 0.83320755 | T17: 0.34166667 | U17: 0.37847222 | V17: =(T17-U16)*24*60 -> 12 | W17: =(U17-T17)*24*60 -> 53 | AF17: =N17-K17 -> -375.28302 | AG17: =N17/K17 -> 0.83320755
B18: 義大利麵 | D18: 義式辣味嫩烤雞腿排義大利麵 | F18: =VLOOKUP(D18,廠價表!$C$1:$E$43,3,0) -> 56.61 | G18: 937 | H18: =F18*G18 -> 53043.57 | J18: =VLOOKUP(D18,產線配置圖!$A$3:$C$40,2,0) -> 15 | K18: =VLOOKUP(D18,產線配置圖!$A$3:$C$40,3,0) -> 2250 | L18: =K18/J18 -> 150 | M18: 15 | N18: =G18/W18*60 -> 1813.5484 | O18: =N18/M18 -> 120.90323 | P18: =M18-J18 -> 0 | Q18: =O18-L18 -> -29.096774 | R18: =O18/L18 -> 0.80602151 | T18: 0.39027778 | U18: 0.41180556 | V18: =(T18-U17)*24*60 -> 17 | W18: =(U18-T18)*24*60 -> 31 | AF18: =N18-K18 -> -436.45161 | AG18: =N18/K18 -> 0.80602151
B19: 義大利麵 | D19: 義式蕃茄起司義大利麵 | F19: =VLOOKUP(D19,廠價表!$C$1:$E$43,3,0) -> 50.39 | G19: 3097 | H19: =F19*G19 -> 156057.83 | J19: =VLOOKUP(D19,產線配置圖!$A$3:$C$40,2,0) -> 13 | K19: =VLOOKUP(D19,產線配置圖!$A$3:$C$40,3,0) -> 2250 | L19: =K19/J19 -> 173.07692 | M19: 13 | N19: =G19/W19*60 -> 2186.1176 | O19: =N19/M19 -> 168.1629 | P19: =M19-J19 -> 0 | Q19: =O19-L19 -> -4.9140271 | R19: =O19/L19 -> 0.97160784 | T19: 0.41875 | U19: 0.47777778 | V19: =(T19-U18)*24*60 -> 10 | W19: =(U19-T19)*24*60 -> 85 | AF19: =N19-K19 -> -63.882353 | AG19: =N19/K19 -> 0.97160784
B20: 義大利麵 | D20: 義式蕃茄起司義大利麵 | F20: =VLOOKUP(D20,廠價表!$C$1:$E$43,3,0) -> 50.39 | G20: 1173 | H20: =F20*G20 -> 59107.47 | J20: =VLOOKUP(D20,產線配置圖!$A$3:$C$40,2,0) -> 13 | K20: =VLOOKUP(D20,產線配置圖!$A$3:$C$40,3,0) -> 2250 | L20: =K20/J20 -> 173.07692 | M20: 13 | N20: =G20/W20*60 -> 1955 | O20: =N20/M20 -> 150.38462 | P20: =M20-J20 -> 0 | Q20: =O20-L20 -> -22.692308 | R20: =O20/L20 -> 0.86888889 | T20: 0.55208333 | U20: 0.57708333 | V20: =(T20-U19)*24*60 -> 107 | W20: =(U20-T20)*24*60 -> 36
B21: 義大利麵 | D21: 青醬蛤蜊義大利麵 | F21: =VLOOKUP(D21,廠價表!$C$1:$E$43,3,0) -> 50.67 | G21: 1065 | H21: =F21*G21 -> 53963.55 | J21: =VLOOKUP(D21,產線配置圖!$A$3:$C$40,2,0) -> 14 | K21: =VLOOKUP(D21,產線配置圖!$A$3:$C$40,3,0) -> 2250 | L21: =K21/J21 -> 160.71429 | M21: 14 | N21: =G21/W21*60 -> 1996.875 | O21: =N21/M21 -> 142.63393 | P21: =M21-J21 -> 0 | Q21: =O21-L21 -> -18.080357 | R21: =O21/L21 -> 0.8875 | T21: 0.58402778 | U21: 0.60625 | V21: =(T21-U20)*24*60 -> 10 | W21: =(U21-T21)*24*60 -> 32
W22: 0
W23: =(U23-T23)*24*60 -> 0
W24: =(U24-T24)*24*60 -> 0
H25: =F25*G25 -> 0 | W25: =(U25-T25)*24*60 -> 0
C26: 4度二組A | D26: 平均 | J26: =AVERAGE(J16:J25) -> 14.333333 | K26: =AVERAGE(K16:K25) -> 2250 | L26: =AVERAGE(L16:L25) -> 158.32256 | M26: =AVERAGE(M16:M25) -> 14.333333 | N26: =AVERAGE(N16:N25) -> 1977.871 | O26: =AVERAGE(O16:O25) -> 139.69092 | P26: =M26-J26 -> 0 | Q26: =O26-L26 -> -18.631636 | R26: =O26/L26 -> 0.8823185 | Z26: =SUM(Z16:Z25) -> 0 | AA26: =SUM(AA16:AA25) -> 0 | AD26: =SUM(AD16:AD25) -> 0 | AE26: =SUM(AE16:AE25) -> 0 | AF26: =N26-K26 -> -272.12904 | AG26: =N26/K26 -> 0.87905376
A27: 手工三線 (ET-55) | B27: 義大利麵 | D27: 義式蛋蛋青醬鮪魚冷義大利麵 | F27: =VLOOKUP(D27,廠價表!$C$1:$E$43,3,0) -> 45.66 | G27: 1773 | H27: =F27*G27 -> 80955.18 | J27: =VLOOKUP(D27,產線配置圖!$A$3:$C$40,2,0) -> 17 | K27: =VLOOKUP(D27,產線配置圖!$A$3:$C$40,3,0) -> 1500 | L27: =K27/J27 -> 88.235294 | M27: 17 | N27: =G27/W27*60 -> 1477.5 | O27: =N27/M27 -> 86.911765 | P27: =M27-J27 -> 0 | Q27: =O27-L27 -> -1.3235294 | R27: =O27/L27 -> 0.985 | S27: =R37 -> 0.92563959 | T27: 0.28819444 | U27: 0.33819444 | W27: =(U27-T27)*24*60 -> 72 | AF27: =N27-K27 -> -22.5 | AG27: =N27/K27 -> 0.985 | AH27: =AG37 -> 0.90411448
B28: 義大利麵 | D28: 奶油鮮蝦明太子細扁麵 | F28: =VLOOKUP(D28,廠價表!$C$1:$E$43,3,0) -> 57.21 | G28: 2270 | H28: =F28*G28 -> 129866.7 | J28: =VLOOKUP(D28,產線配置圖!$A$3:$C$40,2,0) -> 18 | K28: =VLOOKUP(D28,產線配置圖!$A$3:$C$40,3,0) -> 1636 | L28: =K28/J28 -> 90.888889 | M28: 17 | N28: =G28/W28*60 -> 1480.4348 | O28: =N28/M28 -> 87.084399 | P28: =M28-J28 -> -1 | Q28: =O28-L28 -> -3.8044899 | R28: =O28/L28 -> 0.95814131 | T28: 0.34375 | U28: 0.40763889 | V28: =(T28-U27)*24*60 -> 8 | W28: =(U28-T28)*24*60 -> 92 | AF28: =N28-K28 -> -155.56522 | AG28: =N28/K28 -> 0.90491124
B29: 義大利麵 | D29: 焦糖拿鐵烤雞細扁麵 | F29: =VLOOKUP(D29,廠價表!$C$1:$E$43,3,0) -> 57.21 | G29: 1681 | H29: =F29*G29 -> 96170.01 | J29: =VLOOKUP(D29,產線配置圖!$A$3:$C$40,2,0) -> 18 | K29: =VLOOKUP(D29,產線配置圖!$A$3:$C$40,3,0) -> 1565 | L29: =K29/J29 -> 86.944444 | M29: 18 | N29: =G29/W29*60 -> 1440.8571 | O29: =N29/M29 -> 80.047619 | P29: =M29-J29 -> 0 | Q29: =O29-L29 -> -6.8968254 | R29: =O29/L29 -> 0.92067549 | T29: 0.41319444 | U29: 0.46180556 | V29: =(T29-U28)*24*60 -> 8 | W29: =(U29-T29)*24*60 -> 70 | AF29: =N29-K29 -> -124.14286 | AG29: =N29/K29 -> 0.92067549
B30: 義大利麵 | D30: 義式蛋蛋青醬鮪魚冷義大利麵 | F30: =VLOOKUP(D30,廠價表!$C$1:$E$43,3,0) -> 45.66 | G30: 2400 | H30: =F30*G30 -> 109584 | J30: =VLOOKUP(D30,產線配置圖!$A$3:$C$40,2,0) -> 17 | K30: =VLOOKUP(D30,產線配置圖!$A$3:$C$40,3,0) -> 1500 | L30: =K30/J30 -> 88.235294 | M30: 17 | N30: =G30/W30*60 -> 1440 | O30: =N30/M30 -> 84.705882 | P30: =M30-J30 -> 0 | Q30: =O30-L30 -> -3.5294118 | R30: =O30/L30 -> 0.96 | T30: 0.51736111 | U30: 0.58680556 | V30: =(T30-U29)*24*60 -> 80 | W30: =(U30-T30)*24*60 -> 100 | AF30: =N30-K30 -> -60 | AG30: =N30/K30 -> 0.96
B31: 熱乾麵 | D31: 府城鹽水意麵 | F31: =VLOOKUP(D31,廠價表!$C$1:$E$43,3,0) -> 44.3 | G31: 1600 | H31: =F31*G31 -> 70880 | J31: =VLOOKUP(D31,產線配置圖!$A$3:$C$40,2,0) -> 18 | K31: =VLOOKUP(D31,產線配置圖!$A$3:$C$40,3,0) -> 1636 | L31: =K31/J31 -> 90.888889 | M31: 17 | N31: =G31/W31*60 -> 1246.7532 | O31: =N31/M31 -> 73.338426 | P31: =M31-J31 -> -1 | Q31: =O31-L31 -> -17.550463 | R31: =O31/L31 -> 0.806902 | T31: 0.59236111 | U31: 0.64583333 | V31: =(T31-U30)*24*60 -> 8 | W31: =(U31-T31)*24*60 -> 77 | AF31: =N31-K31 -> -389.24675 | AG31: =N31/K31 -> 0.76207411
W32: =(U32-T32)*24*60 -> 0
W33: =(U33-T33)*24*60 -> 0
W34: =(U34-T34)*24*60 -> 0
W35: =(U35-T35)*24*60 -> 0
H36: =F36*G36 -> 0 | W36: =(U36-T36)*24*60 -> 0
C37: 4度二組B | D37: 平均 | J37: =AVERAGE(J27:J36) -> 17.6 | K37: =AVERAGE(K27:K36) -> 1567.4 | L37: =AVERAGE(L27:L36) -> 89.038562 | M37: =AVERAGE(M27:M36) -> 17.2 | N37: =AVERAGE(N27:N36) -> 1417.109 | O37: =AVERAGE(O27:O36) -> 82.417618 | P37: =M37-J37 -> -0.4 | Q37: =N37-K37 -> -150.29097 | R37: =O37/L37 -> 0.92563959 | Z37: =SUM(Z27:Z36) -> 0 | AA37: =SUM(AA27:AA36) -> 0 | AD37: =SUM(AD27:AD36) -> 0 | AE37: =SUM(AE27:AE36) -> 0 | AF37: =N37-K37 -> -150.29097 | AG37: =N37/K37 -> 0.90411448
A38: 手工四線 (ET-55) | B38: 熱乾麵 | D38: 青花椒麻雞肉拌麵 | F38: =VLOOKUP(D38,廠價表!$C$1:$E$43,3,0) -> 49.91 | G38: 2842 | H38: =F38*G38 -> 141844.22 | J38: =VLOOKUP(D38,產線配置圖!$A$3:$C$40,2,0) -> 15 | K38: =VLOOKUP(D38,產線配置圖!$A$3:$C$40,3,0) -> 1714 | L38: =K38/J38 -> 114.26667 | M38: 15 | N38: =G38/W38*60 -> 1624 | O38: =N38/M38 -> 108.26667 | P38: =M38-J38 -> 0 | Q38: =O38-L38 -> -6 | R38: =O38/L38 -> 0.94749125 | S38: =R48 -> 0.9506305 | T38: 0.33333333 | U38: 0.40625 | W38: =(U38-T38)*24*60 -> 105 | AF38: =N38-K38 -> -90 | AG38: =N38/K38 -> 0.94749125 | AH38: =AG48 -> 0.91611664
B39: 熱乾麵 | D39: 府城鹽水意麵 | F39: =VLOOKUP(D39,廠價表!$C$1:$E$43,3,0) -> 44.3 | G39: 2380 | H39: =F39*G39 -> 105434 | J39: =VLOOKUP(D39,產線配置圖!$A$3:$C$40,2,0) -> 18 | K39: =VLOOKUP(D39,產線配置圖!$A$3:$C$40,3,0) -> 1636 | L39: =K39/J39 -> 90.888889 | M39: 17 | N39: =G39/W39*60 -> 1442.4242 | O39: =N39/M39 -> 84.848485 | P39: =M39-J39 -> -1 | Q39: =O39-L39 -> -6.040404 | R39: =O39/L39 -> 0.93354079 | T39: 0.42430556 | U39: 0.49305556 | V39: =(T39-U38)*24*60 -> 26 | W39: =(U39-T39)*24*60 -> 99 | AF39: =N39-K39 -> -193.57576 | AG39: =N39/K39 -> 0.88167741
B40: 熱乾麵 | D40: 府城鹽水意麵 | F40: =VLOOKUP(D40,廠價表!$C$1:$E$43,3,0) -> 44.3 | G40: 1126 | H40: =F40*G40 -> 49881.8 | J40: =VLOOKUP(D40,產線配置圖!$A$3:$C$40,2,0) -> 18 | K40: =VLOOKUP(D40,產線配置圖!$A$3:$C$40,3,0) -> 1636 | L40: =K40/J40 -> 90.888889 | M40: 17 | N40: =G40/W40*60 -> 1501.3333 | O40: =N40/M40 -> 88.313725 | P40: =M40-J40 -> -1 | Q40: =O40-L40 -> -2.5751634 | R40: =O40/L40 -> 0.97166691 | T40: 0.55208333 | U40: 0.58333333 | V40: =(T40-U39)*24*60 -> 85 | W40: =(U40-T40)*24*60 -> 45 | AF40: =N40-K40 -> -134.66667 | AG40: =N40/K40 -> 0.91768541
...

Sheet 0703總
B1: 長家廠組合室生產人時性分析
B3: 日期 | D3: 46206 | F3: 訂單量 | G3: ='0703'!E1 -> 52244 | I3: 營業額 | J3: ='0703'!G1 -> 2423657.1
B4: 項目 | D4: 3 | F4: ➀ | H4: ➁ | J4: ③ | L4: 異常停線 | N4: 短暫停線
B5: 人時性 | D5: 組合室 | F5: 全溫層 | H5: 義大利麵 | J5: 袋裝小吃、義麵 | L5: 合計次數 | M5: 時間 | N5: 合計次數 | O5: 設備次數
D6: 排關平均 | F6: =AVERAGE(D13:J13) -> 122.16478 | H6: =AVERAGE(D13:H13) -> 120.91845 | J6: =AVERAGE(I13:J13) -> 125.28062 | L6: =SUM(D18:J18) -> 13 | M6: =SUM(D19:J19) -> 0 | N6: =SUM(D20:J20) -> 0 | O6: =SUM(D20:J20) -> 0
D7: 實績平均 | F7: =AVERAGE(D14:J14) -> 110.30961 | H7: =AVERAGE(D14:H14) -> 110.28999 | J7: =AVERAGE(I14:J14) -> 110.35868 | L7: =AVERAGE(K14:L14) -> #DIV/0! | M7: =AVERAGE(L14:M14) -> #DIV/0! | N7: =AVERAGE(M14:N14) -> #DIV/0! | O7: =AVERAGE(N14:O14) -> #DIV/0!
D8: 達成率平均 | F8: =F7/F6 -> 0.90295754 | H8: =H7/H6 -> 0.91210222 | J8: =J7/J6 -> 0.88089187 | L8: =AVERAGE(K15:L15) -> #DIV/0! | M8: =AVERAGE(L15:M15) -> #DIV/0! | N8: =AVERAGE(M15:N15) -> #DIV/0! | O8: =AVERAGE(N15:O15) -> #DIV/0!
J9: ※現行日本鮮食廠以達成率80%為基本(即為現行KPI)
B10: 溫層 | D10: 4度C-各編組展開
B11: 編組 | D11: 1 | E11: 2 | F11: 3 | G11: 4 | H11: 5 | I11: 6 | J11: 7
D12: 自動1線 | E12: 自動2線 | F12: 手工3線 | G12: 手工4線 | H12: 手工5線 | I12: 調理包1線 | J12: 調理包2線
B13: 人時性 | C13: 排關 | D13: =VALUE('0703'!L15) -> 150 | E13: =VALUE('0703'!L26) -> 154.03604 | F13: =VALUE('0703'!L37) -> 93.307843 | G13: =VALUE('0703'!L48) -> 102.57778 | H13: =VALUE('0703'!L58) -> 104.67059 | I13: =VALUE('0703'!L69) -> 138.81212 | J13: ='0703'!L79 -> 111.74913
C14: 實績 | D14: =VALUE('0703'!O15) -> 139.38823 | E14: =VALUE('0703'!O26) -> 136.99117 | F14: =VALUE('0703'!O37) -> 88.150269 | G14: =VALUE('0703'!O48) -> 93.100083 | H14: =VALUE('0703'!O58) -> 93.820171 | I14: =VALUE('0703'!O69) -> 127.74587 | J14: ='0703'!O79 -> 92.971497
C15: 達成率 | D15: =D14/D13 -> 0.92925489 | E15: =E14/E13 -> 0.88934497 | F15: =F14/F13 -> 0.94472518 | G15: =G14/G13 -> 0.90760479 | H15: =H14/H13 -> 0.89633748 | I15: =I14/I13 -> 0.92027891 | J15: ='0703'!S70 -> 0.83196621
B16: 作業 時間 | C16: 開始 | D16: ='0703'!T5 -> 0.29375 | E16: ='0703'!T16 -> 0.29166667 | F16: ='0703'!T27 -> 0.28819444 | G16: ='0703'!T38 -> 0.33333333 | H16: ='0703'!T49 -> 0.29166667 | I16: ='0703'!T59 -> 0.28819444 | J16: ='0703'!T70 -> 0.29166667
C17: 結束 | D17: 0.47569444 | E17: 0.48125 | F17: 0.58680556 | G17: 0.50277778 | H17: 0.58680556 | I17: 0.56597222 | J17: 0.625
B18: 產線異常 (5分鐘以上) | C18: 次數 | D18: ='0703'!Z15 -> 0 | E18: ='0703'!Z26 -> 0 | F18: ='0703'!Z37 -> 0 | G18: ='0703'!Z48 -> 0 | H18: ='0703'!Z58 -> 0 | I18: ='0703'!Z69 -> 0 | J18: ='0703'!AA79 -> 13
C19: 時間/分 | D19: ='0703'!AA15 -> 0 | E19: ='0703'!AA26 -> 0 | F19: ='0703'!AA37 -> 0 | G19: ='0703'!AA48 -> 0 | H19: ='0703'!AA58 -> 0 | I19: ='0703'!AA69 -> 0 | J19: ='0703'!AB79 -> 0
B20: 短暫停線 (5分鐘以下) | C20: 次數 | D20: ='0703'!AD15 -> 0 | E20: ='0703'!AD26 -> 0 | F20: ='0703'!AD37 -> 0 | G20: ='0703'!AD48 -> 0 | H20: ='0703'!AD58 -> 0 | I20: ='0703'!AD69 -> 0 | J20: ='0703'!AD79 -> 0
C21: 設備次數 | D21: ='0703'!AE15 -> 0 | E21: ='0703'!AE26 -> 0 | F21: ='0703'!AE37 -> 0 | G21: ='0703'!AE48 -> 0 | H21: ='0703'!AE58 -> 0 | I21: ='0703'!AE69 -> 0 | J21: ='0703'!AE79 -> 0
B22: 配置人數 | D22: =VALUE('0703'!M15) -> 15 | E22: =VALUE('0703'!M26) -> 14.5 | F22: =VALUE('0703'!M37) -> 17 | G22: =VALUE('0703'!M48) -> 16.5 | H22: =VALUE('0703'!M58) -> 16.6 | I22: =VALUE('0703'!M69) -> 12 | J22: ='0703'!M79 -> 13.75
B23: 主要應用設備 | D23: ET-600 | E23: ET-600 | F23: ET-55 | G23: ET-55 | H23: ET-55 | I23: 八爪機 | J23: 八爪機
B24: 次要應用設備 | H24: 封口機 | J24: 封口機
B25: 備註

Sheet 0703
A1: 長家廠4度C日報分析 | D1: 總生產量 | E1: =SUM(G5:G79) -> 52244 | F1: 營業額 | G1: =SUM(H5:H79) -> 2423657.1 | H1: 出勤人數 | I1: =M15+M26+M48+M58+M69+M79+M37 -> 105.35 | J1: 產線配置圖 | M1: 生產實績 | P1: 人時性差異分析 | T1: 日報登錄 | Z1: 合計 次數 | AA1: 合計 時間/分 | AB1: 分析說明 | AD1: 合計 次數 | AE1: 合計 設備次數 | AF1: 產能差異分析
A2: 07月03 日 星期五 | D2: 人時性 | E2: =AVERAGE(O15,O26,O37,O48,O58,O69,O79) -> 110.30961 | F2: 平均廠價 | G2: =G1/E1 -> 46.391108 | H2: 多次生產數 | I2: =COUNT(I5:I79) -> 0 | Z2: =Z15+Z26+Z37+Z48+Z58+Z69+Z79 -> 1 | AA2: =AA15+AA26+AA37+AA48+AA58+AA69+AA79 -> 13 | AD2: =AD15+AD26+AD37+AD48+AD58+AD69+AD79 -> 0 | AE2: =AE15+AE26+AE37+AE48+AE58+AE69+AE79 -> 0
A3: 線別 | B3: 品類 | D3: 品名 | F3: 廠價 | G3: 生產量 | H3: 營收 | I3: 多次 生產 | J3: 人數 | K3: 產能/時 | L3: 人時性 | M3: 人數 | N3: 產能/時 | O3: 人時性 | P3: 人數 | Q3: 人時性 | R3: 達成率 | S3: 達成率平均 | T3: 生產時間 | V3: 前置、換線時間/分 | W3: 稼動時間/分 | X3: 休息時間 | Z3: 產線異常統計 (5分鐘以上) | AD3: 短暫停線統計 (5分鐘以下) | AF3: 產能/時 | AG3: 達成率 | AH3: 達成率平均
T4: 開始 | U4: 結束 | X4: 開始 | Y4: 結束 | Z4: 次數 | AA4: 時間/分 | AD4: 總次數 | AE4: 設備因素(次數)
A5: 自動一線 (ET-600) | B5: 義大利麵 | D5: 白酒清炒鮮蛤義大利麵 | F5: =VLOOKUP(D5,廠價表!$C$1:$E$43,3,0) -> 56.87 | G5: 2128 | H5: =F5*G5 -> 121019.36 | J5: =VLOOKUP(D5,產線配置圖!$A$3:$C$40,2,0) -> 15 | K5: =VLOOKUP(D5,產線配置圖!$A$3:$C$40,3,0) -> 2250 | L5: =K5/J5 -> 150 | M5: 15 | N5: =G5/W5*60 -> 2093.1148 | O5: =N5/M5 -> 139.54098 | P5: =M5-J5 -> 0 | Q5: =O5-L5 -> -10.459016 | R5: =O5/L5 -> 0.93027322 | S5: =R15 -> 0.92925489 | T5: 0.29375 | U5: 0.33611111 | W5: =(U5-T5)*24*60 -> 61 | AF5: =N5-K5 -> -156.88525 | AG5: =N5/K5 -> 0.93027322 | AH5: =AG15 -> 0.92925489
B6: 義大利麵 | D6: 香煎魚排佐檸檬奶油義大利麵 | F6: =VLOOKUP(D6,廠價表!$C$1:$E$43,3,0) -> 58.17 | G6: 1797 | H6: =F6*G6 -> 104531.49 | J6: =VLOOKUP(D6,產線配置圖!$A$3:$C$40,2,0) -> 15 | K6: =VLOOKUP(D6,產線配置圖!$A$3:$C$40,3,0) -> 2250 | L6: =K6/J6 -> 150 | M6: 15 | N6: =G6/W6*60 -> 2114.1176 | O6: =N6/M6 -> 140.94118 | P6: =M6-J6 -> 0 | Q6: =O6-L6 -> -9.0588235 | R6: =O6/L6 -> 0.93960784 | T6: 0.34375 | U6: 0.37916667 | V6: =(T6-U5)*24*60 -> 11 | W6: =(U6-T6)*24*60 -> 51 | AF6: =N6-K6 -> -135.88235 | AG6: =N6/K6 -> 0.93960784
B7: 義大利麵 | D7: 奶油培根義大利麵 | F7: =VLOOKUP(D7,廠價表!$C$1:$E$43,3,0) -> 49.14 | G7: 4337 | H7: =F7*G7 -> 213120.18 | J7: =VLOOKUP(D7,產線配置圖!$A$3:$C$40,2,0) -> 15 | K7: =VLOOKUP(D7,產線配置圖!$A$3:$C$40,3,0) -> 2250 | L7: =K7/J7 -> 150 | M7: 15 | N7: =G7/W7*60 -> 2065.2381 | O7: =N7/M7 -> 137.68254 | P7: =M7-J7 -> 0 | Q7: =O7-L7 -> -12.31746 | R7: =O7/L7 -> 0.9178836 | T7: 0.38819444 | U7: 0.47569444 | V7: =(T7-U6)*24*60 -> 13 | W7: =(U7-T7)*24*60 -> 126 | AF7: =N7-K7 -> -184.7619 | AG7: =N7/K7 -> 0.9178836
W8: =(U8-T8)*24*60 -> 0 | AF8: =N8-K8 -> 0 | AG8: =N8/K8 -> #DIV/0!
W9: =(U9-T9)*24*60 -> 0 | AF9: =N9-K9 -> 0 | AG9: =N9/K9 -> #DIV/0!
W10: =(U10-T10)*24*60 -> 0 | AF10: =N10-K10 -> 0 | AG10: =N10/K10 -> #DIV/0!
W11: =(U11-T11)*24*60 -> 0 | AF11: =N11-K11 -> 0 | AG11: =N11/K11 -> #DIV/0!
W12: =(U12-T12)*24*60 -> 0
W13: =(U13-T13)*24*60 -> 0
W14: =(U14-T14)*24*60 -> 0
C15: 4度一組 | D15: 平均 | J15: =AVERAGE(J5:J14) -> 15 | K15: =AVERAGE(K5:K14) -> 2250 | L15: =AVERAGE(L5:L14) -> 150 | M15: =AVERAGE(M5:M14) -> 15 | N15: =AVERAGE(N5:N14) -> 2090.8235 | O15: =AVERAGE(O5:O14) -> 139.38823 | P15: =M15-J15 -> 0 | Q15: =O15-L15 -> -10.611767 | R15: =O15/L15 -> 0.92925489 | Z15: =SUM(Z5:Z14) -> 0 | AA15: =SUM(AA5:AA14) -> 0 | AD15: =SUM(AD5:AD14) -> 0 | AE15: =SUM(AE5:AE14) -> 0 | AF15: =N15-K15 -> -159.1765 | AG15: =N15/K15 -> 0.92925489
A16: 自動二線 (ET-600) | B16: 義大利麵 | D16: 青醬蛤蜊義大利麵 | F16: =VLOOKUP(D16,廠價表!$C$1:$E$43,3,0) -> 50.67 | G16: 2855 | H16: =F16*G16 -> 144662.85 | J16: =VLOOKUP(D16,產線配置圖!$A$3:$C$40,2,0) -> 14 | K16: =VLOOKUP(D16,產線配置圖!$A$3:$C$40,3,0) -> 2250 | L16: =K16/J16 -> 160.71429 | M16: 14 | N16: =G16/W16*60 -> 2224.6753 | O16: =N16/M16 -> 158.90538 | P16: =M16-J16 -> 0 | Q16: =O16-L16 -> -1.8089054 | R16: =O16/L16 -> 0.98874459 | S16: =R26 -> 0.88934497 | T16: 0.29166667 | U16: 0.34513889 | W16: =(U16-T16)*24*60 -> 77 | AF16: =N16-K16 -> -25.324675 | AG16: =N16/K16 -> 0.98874459 | AH16: =AG26 -> 0.87339128
B17: 義大利麵 | D17: 蒜香奶油蝦蝦義大利麵 | F17: =VLOOKUP(D17,廠價表!$C$1:$E$43,3,0) -> 57.21 | G17: 1212 | H17: =F17*G17 -> 69338.52 | J17: =VLOOKUP(D17,產線配置圖!$A$3:$C$40,2,0) -> 17 | K17: =VLOOKUP(D17,產線配置圖!$A$3:$C$40,3,0) -> 2250 | L17: =K17/J17 -> 132.35294 | M17: 16 | N17: =G17/W17*60 -> 1818 | O17: =N17/M17 -> 113.625 | P17: =M17-J17 -> -1 | Q17: =O17-L17 -> -18.727941 | R17: =O17/L17 -> 0.8585 | T17: 0.35347222 | U17: 0.38125 | V17: =(T17-U16)*24*60 -> 12 | W17: =(U17-T17)*24*60 -> 40 | AF17: =N17-K17 -> -432 | AG17: =N17/K17 -> 0.808
B18: 義大利麵 | D18: 義式辣味嫩烤雞腿排義大利麵 | F18: =VLOOKUP(D18,廠價表!$C$1:$E$43,3,0) -> 56.61 | G18: 593 | H18: =F18*G18 -> 33569.73 | J18: =VLOOKUP(D18,產線配置圖!$A$3:$C$40,2,0) -> 15 | K18: =VLOOKUP(D18,產線配置圖!$A$3:$C$40,3,0) -> 2250 | L18: =K18/J18 -> 150 | M18: 15 | N18: =G18/W18*60 -> 1779 | O18: =N18/M18 -> 118.6 | P18: =M18-J18 -> 0 | Q18: =O18-L18 -> -31.4 | R18: =O18/L18 -> 0.79066667 | T18: 0.3875 | U18: 0.40138889 | V18: =(T18-U17)*24*60 -> 9 | W18: =(U18-T18)*24*60 -> 20 | AB18: 生產數量少 | AF18: =N18-K18 -> -471 | AG18: =N18/K18 -> 0.79066667
B19: 義大利麵 | D19: 義式蕃茄起司義大利麵 | F19: =VLOOKUP(D19,廠價表!$C$1:$E$43,3,0) -> 50.39 | G19: 3534 | H19: =F19*G19 -> 178078.26 | J19: =VLOOKUP(D19,產線配置圖!$A$3:$C$40,2,0) -> 13 | K19: =VLOOKUP(D19,產線配置圖!$A$3:$C$40,3,0) -> 2250 | L19: =K19/J19 -> 173.07692 | M19: 13 | N19: =G19/W19*60 -> 2038.8462 | O19: =N19/M19 -> 156.83432 | P19: =M19-J19 -> 0 | Q19: =O19-L19 -> -16.242604 | R19: =O19/L19 -> 0.90615385 | T19: 0.40902778 | U19: 0.48125 | V19: =(T19-U18)*24*60 -> 11 | W19: =(U19-T19)*24*60 -> 104 | AF19: =N19-K19 -> -211.15385 | AG19: =N19/K19 -> 0.90615385
W20: =(U20-T20)*24*60 -> 0
W21: =(U21-T21)*24*60 -> 0
W22: 0
W23: =(U23-T23)*24*60 -> 0
H24: =F24*G24 -> 0 | W24: =(U24-T24)*24*60 -> 0
H25: =F25*G25 -> 0 | W25: =(U25-T25)*24*60 -> 0
C26: 4度二組A | D26: 平均 | J26: =AVERAGE(J16:J25) -> 14.75 | K26: =AVERAGE(K16:K25) -> 2250 | L26: =AVERAGE(L16:L25) -> 154.03604 | M26: =AVERAGE(M16:M25) -> 14.5 | N26: =AVERAGE(N16:N25) -> 1965.1304 | O26: =AVERAGE(O16:O25) -> 136.99117 | P26: =M26-J26 -> -0.25 | Q26: =O26-L26 -> -17.044863 | R26: =O26/L26 -> 0.88934497 | Z26: =SUM(Z16:Z25) -> 0 | AA26: =SUM(AA16:AA25) -> 0 | AD26: =SUM(AD16:AD25) -> 0 | AE26: =SUM(AE16:AE25) -> 0 | AF26: =N26-K26 -> -284.86963 | AG26: =N26/K26 -> 0.87339128
A27: 手工三線 (ET-55) | B27: 義大利麵 | D27: 義式蛋蛋青醬鮪魚冷義大利麵 | F27: =VLOOKUP(D27,廠價表!$C$1:$E$43,3,0) -> 45.66 | G27: 2313 | H27: =F27*G27 -> 105611.58 | J27: =VLOOKUP(D27,產線配置圖!$A$3:$C$40,2,0) -> 17 | K27: 1636 | L27: =K27/J27 -> 96.235294 | M27: 17 | N27: =G27/W27*60 -> 1595.1724 | O27: =N27/M27 -> 93.833671 | P27: =M27-J27 -> 0 | Q27: =O27-L27 -> -2.4016227 | R27: =O27/L27 -> 0.97504426 | S27: =R37 -> 0.94472518 | T27: 0.28819444 | U27: 0.34861111 | W27: =(U27-T27)*24*60 -> 87 | AF27: =N27-K27 -> -40.827586 | AG27: =N27/K27 -> 0.97504426 | AH27: =AG37 -> 0.92400701
B28: 義大利麵 | D28: 奶油鮮蝦明太子細扁麵 | F28: =VLOOKUP(D28,廠價表!$C$1:$E$43,3,0) -> 57.21 | G28: 1804 | H28: =F28*G28 -> 103206.84 | J28: =VLOOKUP(D28,產線配置圖!$A$3:$C$40,2,0) -> 18 | K28: =VLOOKUP(D28,產線配置圖!$A$3:$C$40,3,0) -> 1636 | L28: =K28/J28 -> 90.888889 | M28: 17 | N28: =G28/W28*60 -> 1443.2 | O28: =N28/M28 -> 84.894118 | P28: =M28-J28 -> -1 | Q28: =O28-L28 -> -5.9947712 | R28: =O28/L28 -> 0.93404286 | T28: 0.35416667 | U28: 0.40625 | V28: =(T28-U27)*24*60 -> 8 | W28: =(U28-T28)*24*60 -> 75 | AF28: =N28-K28 -> -192.8 | AG28: =N28/K28 -> 0.88215159
