Workbook

Sheet 廠價表
A1: check | B1: 溫層 | C1: 品名 | D1: 類別 | E1: 廠價
B2: 4度C | C2: 白酒蛤蜊義大利麵 | D2: 義大利麵 | E2: 57.21
B3: 4度C | C3: 白酒清炒鮮蛤義大利麵 | D3: 義大利麵 | E3: 56.87
B4: 4度C | C4: 義式蕃茄起司義大利麵 | D4: 義大利麵 | E4: 50.39
B5: 4度C | C5: 焗烤起司雙饗筆尖麵 | D5: 義大利麵 | E5: 49.97
B6: 4度C | C6: 奶油培根義大利麵 | D6: 義大利麵 | E6: 49.14
B7: 4度C | C7: 燻火腿貓耳朵麵 | D7: 義大利麵 | E7: 58.17
B8: 4度C | C8: 義式辣味嫩烤雞腿排義大利麵 | D8: 義大利麵 | E8: 56.61
B9: 4度C | C9: 焗烤起司肉醬筆尖麵 | D9: 義大利麵 | E9: 50.67
B10: 4度C | C10: 辣味香菜雞肉義大利麵 | D10: 義大利麵 | E10: 56.28
B11: 4度C | C11: 蒜香奶油蝦蝦義大利麵 | D11: 義大利麵 | E11: 57.21
B12: 4度C | C12: 義式辣味嫩烤雞腿排義大利麵 | D12: 義大利麵 | E12: 56.61
B13: 4度C | C13: 香煎魚排佐檸檬奶油義大利麵 | D13: 義大利麵 | E13: 58.17
... B21: 4度C | C21: 沙茶豬肉炒麵 | D21: 熱乾麵 | E21: 49.52
B23: 4度C | D23: 小吃、微波
B24: 4度C | C24: 小滷青蔬 | D24: 小吃、微波 | E24: 26.99
B25: 4度C | C25: 起司馬鈴薯 | D25: 小吃、微波 | E25: 28.26
B26: 4度C | C26: 麻辣雞心 | D26: 小吃、微波 | E26: 28.26
B46: 冷凍 | C46: 青醬蛤蜊義大利麵 | D46: 冷凍調理麵 | E46: 29.38
B47: 冷凍 | C47: 經典肉醬義大利麵 | D47: 冷凍調理麵 | E47: 29.38
B48: 冷凍 | C48: 奶油蘑菇培根義大利麵 | D48: 冷凍調理麵 | E48: 29.38
B49: 冷凍 | C49: 清炒蛤蜊義大利麵 | D49: 冷凍調理麵 | E49: 29.38
B50: 冷凍 | C50: 青醬乳酪筆尖麵 | D50: 冷凍調理麵 | E50: 29.38
B51: 冷凍 | C51: 辣蕃茄義大利麵 | D51: 冷凍調理麵 | E51: 29.38
B52: 冷凍 | D52: 冷凍調理麵
B53: 冷凍 | C53: 韓式起司義大利麵 | D53: 冷凍調理麵 | E53: 29.38
B54: 冷凍 | D54: 冷凍調理麵
B55: 冷凍 | C55: 和風明太子細扁麵 | D55: 冷凍調理麵 | E55: 29.38

Sheet 產線配置圖
A1: 品項 | B1: 人數 | C1: 產能 | F1: 46125
A2: 義大利麵
A3: 白酒清炒鮮蛤義大利麵 | B3: 14 | C3: 2118 | D3: ET-600 | E3: 新品 | F3: +2
A4: 白酒蛤蜊義大利麵 | B4: 15 | C4: 1565 | D4: ET-55
A5: 青醬蛤蜊義大利麵 | B5: 12 | C5: 2118 | F5: +2
A6: 義式蕃茄起司義大利麵 | B6: 11 | C6: 2118 | F6: +2
A7: 焗烤起司雙饗筆尖麵 | B7: 16 | C7: 1800
A8: 奶油培根義大利麵 | B8: 13 | C8: 2118 | F8: +2
A9: 辣味香菜雞肉義大利麵 | B9: 15 | C9: 1800
A10: 青花椒麻雞肉拌麵 | B10: 15 | C10: 1714
A11: 濃拿坡里義大利麵 | B11: 16 | C11: 1406
A12: 青醬蛤蜊義大利麵-手 | B12: 15 | C12: 1714
A13: 蒜香奶油蝦蝦義大利麵 | B13: 14 | C13: 2118 | F13: +2
A14: 沙茶豬肉炒麵 | B14: 17 | C14: 1440
A15: 府城鹽水意麵 | B15: 18 | C15: 1565
A16: 焗烤起司肉醬筆尖麵-降 | B16: 10 | C16: 1125
A17: 焗烤起司肉醬筆尖麵 | B17: 13 | C17: 1440
A18: 義式辣味嫩烤雞腿排義大利麵 | B18: 16 | C18: 2000
A19: 香煎魚排佐檸檬奶油義大利麵 | B19: 17 | C19: 2000
A20: 黑松露野菇義大利麵 | B20: 18 | C20: 1565
A24: 調理包
A25: 小滷青蔬 | B25: 13 | C25: 1565
A26: 起司馬鈴薯 | B26: 12 | C26: 1565
A27: 麻辣雞心 | B27: 9 | C27: 1636
E32: 更新日期04/08

Sheet 範本總
B1: 長家廠組合室生產人時性分析
B3: 日期 | D3: 46015 | F3: 訂單量 | G3: =範本!E1 -> 43309 | I3: 營業額 | J3: =範本!G1 -> #N/A
B4: 項目 | D4: 3 | F4: ➀ | H4: ➁ | J4: ③ | L4: 異常停線 | N4: 短暫停線
B5: 人時性 | D5: 組合室 | F5: 全溫層 | H5: 義大利麵 | J5: 袋裝小吃、義麵 | L5: 合計次數 | M5: 時間 | N5: 合計次數 | O5: 設備次數
D6: 排關平均 | F6: =AVERAGE(D13:J13) -> #N/A | H6: =AVERAGE(D13:H13) -> #N/A | J6: =AVERAGE(I13:J13) -> #N/A | L6: =範本!Z2 -> 0 | M6: =範本!AA2 -> 0 | N6: =範本!AD2 -> 0 | O6: =範本!AE2 -> 0
D7: 實績平均 | F7: =AVERAGE(D14:J14) -> 116.11475 | H7: =AVERAGE(D14:H14) -> 117.36075 | J7: =AVERAGE(I14:J14) -> 112.99975
D8: 達成率平均 | F8: =AVERAGE(D15:J15) -> #N/A | H8: =AVERAGE(D15:H15) -> #N/A | J8: =AVERAGE(I15:J15) -> #N/A
J9: ※現行日本鮮食廠以達成率80%為基本(即為現行KPI)
B10: 溫層 | D10: 4度C-各編組展開
B11: 編組 | D11: 1 | E11: 2 | F11: 3 | G11: 4 | H11: 5 | I11: 6 | J11: 7
D12: 自動1線 | E12: 自動2線 | F12: 手工3線 | G12: 手工4線 | H12: 手工5線 | I12: 調理包1線 | J12: 調理包2線
B13: 人時性 | C13: 排關 | D13: =VALUE(範本!L15) -> #N/A | E13: =VALUE(範本!L26) -> #N/A | F13: =VALUE(範本!L37) -> #N/A | G13: =VALUE(範本!L48) -> #N/A | H13: =VALUE(範本!L58) -> #N/A | I13: =VALUE(範本!L69) -> #N/A | J13: =範本!L79 -> #N/A
C14: 實績 | D14: =VALUE(範本!O15) -> 113.91637 | E14: =VALUE(範本!O26) -> 132.12003 | F14: =VALUE(範本!O37) -> 126.23842 | G14: =VALUE(範本!O48) -> 112.0543 | H14: =VALUE(範本!O58) -> 102.47462 | I14: =VALUE(範本!O69) -> 155.46443 | J14: =範本!O79 -> 70.535065
C15: 達成率 | D15: =D14/D13 -> #N/A | E15: =E14/E13 -> #N/A | F15: =F14/F13 -> #N/A | G15: =G14/G13 -> #N/A | H15: =H14/H13 -> #N/A | I15: =I14/I13 -> #N/A | J15: =範本!S70 -> #N/A
B16: 作業 時間 | C16: 開始 | D16: =範本!T5 -> 0.29097222 | E16: =範本!T16 -> 0.29097222 | F16: =範本!T27 -> 0.29166667 | G16: =範本!T38 -> 0.33333333 | H16: =範本!T49 -> 0.29166667 | I16: =範本!T59 -> 0.29166667 | J16: =範本!T70 -> 0.34722222
C17: 結束 | D17: 0.47361111 | E17: 0.48263889 | F17: 0.56944444 | G17: 0.60416667 | H17: 0.58333333 | I17: 0.48819444 | J17: 0.46875
B18: 產線異常 (5分鐘以上) | C18: 次數
C19: 時間/分
B20: 短暫停線 (5分鐘以下) | C20: 次數
C21: 設備次數
B22: 配置人數 | D22: =VALUE(範本!M15) -> 15 | E22: =VALUE(範本!M26) -> 12.666667 | F22: =VALUE(範本!M37) -> 14.666667 | G22: =VALUE(範本!M48) -> 14 | H22: =VALUE(範本!M58) -> 17.666667 | I22: =VALUE(範本!M69) -> 12.333333 | J22: =範本!M79 -> 11
B23: 主要應用設備 | D23: ET-600 | E23: ET-600 | F23: ET-55 | G23: ET-55 | H23: ET-55 | I23: 八爪機
B24: 次要應用設備 | H24: 封口機
B25: 備註

Sheet 範本
A1: 長家廠4度C日報分析 | D1: 總生產量 | E1: =SUM(G5:G79) -> 43309 | F1: 營業額 | G1: =SUM(H5:H79) -> #N/A | H1: 出勤人數 | I1: =M15+M26+M48+M58+M69+M79+M37 -> 97.333333 | J1: 產線配置圖 | M1: 生產實績 | P1: 人時性差異分析 | T1: 日報登錄 | Z1: 合計 次數 | AA1: 合計 時間/分 | AB1: 分析說明 | AD1: 合計 次數 | AE1: 合計 設備次數 | AF1: 產能差異分析
A2: 12月24日 星期三 | D2: 人時性 | E2: =AVERAGE(O15,O26,O37,O48,O58,O69,O79) -> 116.11475 | F2: 平均廠價 | G2: =G1/E1 -> #N/A | H2: 多次生產數 | I2: =COUNT(I5:I79) -> 0 | Z2: =Z15+Z26+Z37+Z48+Z58+Z69+Z79 -> 0 | AA2: =AA15+AA26+AA37+AA48+AA58+AA69+AA79 -> 0 | AD2: =AD15+AD26+AD37+AD48+AD58+AD69+AD79 -> 0 | AE2: =AE15+AE26+AE37+AE48+AE58+AE69+AE79 -> 0
A3: 線別 | B3: 品類 | D3: 品名 | F3: 廠價 | G3: 生產量 | H3: 營收 | I3: 多次 生產 | J3: 人數 | K3: 產能/時 | L3: 人時性 | M3: 人數 | N3: 產能/時 | O3: 人時性 | P3: 人數 | Q3: 人時性 | R3: 達成率 | S3: 達成率平均 | T3: 生產時間 | V3: 前置、換線時間/分 | W3: 稼動時間/分 | X3: 休息時間 | Z3: 產線異常統計 (5分鐘以上) | AD3: 短暫停線統計 (5分鐘以下) | AF3: 產能/時 | AG3: 達成率 | AH3: 達成率平均
T4: 開始 | U4: 結束 | X4: 開始 | Y4: 結束 | Z4: 次數 | AA4: 時間/分 | AD4: 總次數 | AE4: 設備因素(次數)
A5: 自動一線 (ET-600) | B5: =VLOOKUP(D5,廠價表!$C$1:$E$43,2,0) -> #N/A | F5: =VLOOKUP(D5,廠價表!$C$1:$E$43,3,0) -> #N/A | G5: 2263 | H5: =F5*G5 -> #N/A | J5: =VLOOKUP(D5,產線配置圖!$A$3:$C$38,2,0) -> #N/A | K5: =VLOOKUP(D5,產線配置圖!$A$3:$C$38,3,0) -> #N/A | L5: =K5/J5 -> #N/A | M5: 15 | N5: =G5/W5*60 -> 1444.4681 | O5: =N5/M5 -> 96.297872 | P5: =M5-J5 -> #N/A | Q5: =O5-L5 -> #N/A | R5: =O5/L5 -> #N/A | S5: =R15 -> #N/A | T5: 0.29097222 | U5: 0.35625 | W5: =(U5-T5)*24*60 -> 94 | AF5: =N5-K5 -> #N/A | AG5: =N5/K5 -> #N/A | AH5: =AG15 -> #N/A
B6: =VLOOKUP(D6,廠價表!$C$1:$E$43,2,0) -> #N/A | F6: =VLOOKUP(D6,廠價表!$C$1:$E$43,3,0) -> #N/A | G6: 1180 | H6: =F6*G6 -> #N/A | J6: =VLOOKUP(D6,產線配置圖!$A$3:$C$38,2,0) -> #N/A | K6: =VLOOKUP(D6,產線配置圖!$A$3:$C$38,3,0) -> #N/A | L6: =K6/J6 -> #N/A | M6: 17 | N6: =G6/W6*60 -> 1609.0909 | O6: =N6/M6 -> 94.652406 | P6: =M6-J6 -> #N/A | Q6: =O6-L6 -> #N/A | R6: =O6/L6 -> #N/A | T6: 0.36458333 | U6: 0.39513889 | V6: =(T6-U5)*24*60 -> 12 | W6: =(U6-T6)*24*60 -> 44 | AF6: =N6-K6 -> #N/A | AG6: =N6/K6 -> #N/A
B7: =VLOOKUP(D7,廠價表!$C$1:$E$43,2,0) -> #N/A | F7: =VLOOKUP(D7,廠價表!$C$1:$E$43,3,0) -> #N/A | G7: 3398 | H7: =F7*G7 -> #N/A | J7: =VLOOKUP(D7,產線配置圖!$A$3:$C$38,2,0) -> #N/A | K7: =VLOOKUP(D7,產線配置圖!$A$3:$C$38,3,0) -> #N/A | L7: =K7/J7 -> #N/A | M7: 13 | N7: =G7/W7*60 -> 1960.3846 | O7: =N7/M7 -> 150.79882 | P7: =M7-J7 -> #N/A | Q7: =O7-L7 -> #N/A | R7: =O7/L7 -> #N/A | T7: 0.40138889 | U7: 0.47361111 | V7: =(T7-U6)*24*60 -> 9 | W7: =(U7-T7)*24*60 -> 104 | AF7: =N7-K7 -> #N/A | AG7: =N7/K7 -> #N/A
W8: =(U8-T8)*24*60 -> 0 | X8: 0.48611111 | Y8: 0.52777778 | AF8: =N8-K8 -> 0 | AG8: =N8/K8 -> #DIV/0!
W9: =(U9-T9)*24*60 -> 0 | AF9: =N9-K9 -> 0 | AG9: =N9/K9 -> #DIV/0!
W10: =(U10-T10)*24*60 -> 0 | AF10: =N10-K10 -> 0 | AG10: =N10/K10 -> #DIV/0!
W11: =(U11-T11)*24*60 -> 0 | AF11: =N11-K11 -> 0 | AG11: =N11/K11 -> #DIV/0!
W12: =(U12-T12)*24*60 -> 0
W13: =(U13-T13)*24*60 -> 0
W14: =(U14-T14)*24*60 -> 0
C15: 4度一組 | D15: 平均 | J15: =AVERAGE(J5:J14) -> #N/A | K15: =AVERAGE(K5:K14) -> #N/A | L15: =AVERAGE(L5:L14) -> #N/A | M15: =AVERAGE(M5:M14) -> 15 | N15: =AVERAGE(N5:N14) -> 1671.3145 | O15: =AVERAGE(O5:O14) -> 113.91637 | P15: =M15-J15 -> #N/A | Q15: =O15-L15 -> #N/A | R15: =O15/L15 -> #N/A | Z15: =SUM(Z5:Z14) -> 0 | AA15: =SUM(AA5:AA14) -> 0 | AD15: =SUM(AD5:AD14) -> 0 | AE15: =SUM(AE5:AE14) -> 0 | AF15: =N15-K15 -> #N/A | AG15: =N15/K15 -> #N/A
A16: 自動二線 (ET-600) | B16: =VLOOKUP(D16,廠價表!$C$1:$E$43,2,0) -> #N/A | F16: =VLOOKUP(D16,廠價表!$C$1:$E$43,3,0) -> #N/A | G16: 2263 | H16: =F16*G16 -> #N/A | J16: =VLOOKUP(D16,產線配置圖!$A$3:$C$38,2,0) -> #N/A | K16: =VLOOKUP(D16,產線配置圖!$A$3:$C$38,3,0) -> #N/A | L16: =K16/J16 -> #N/A | M16: 13 | N16: =G16/W16*60 -> 2225.9016 | O16: =N16/M16 -> 171.2232 | P16: =M16-J16 -> #N/A | Q16: =O16-L16 -> #N/A | R16: =O16/L16 -> #N/A | S16: =R26 -> #N/A | T16: 0.29097222 | U16: 0.33333333 | W16: =(U16-T16)*24*60 -> 61 | AF16: =N16-K16 -> #N/A | AG16: =N16/K16 -> #N/A | AH16: =AG26 -> #N/A
B17: =VLOOKUP(D17,廠價表!$C$1:$E$43,2,0) -> #N/A | F17: =VLOOKUP(D17,廠價表!$C$1:$E$43,3,0) -> #N/A | G17: 1180 | H17: =F17*G17 -> #N/A | J17: =VLOOKUP(D17,產線配置圖!$A$3:$C$38,2,0) -> #N/A | K17: =VLOOKUP(D17,產線配置圖!$A$3:$C$38,3,0) -> #N/A | L17: =K17/J17 -> #N/A | M17: 13 | N17: =G17/W17*60 -> 823.25581 | O17: =N17/M17 -> 63.32737 | P17: =M17-J17 -> #N/A | Q17: =O17-L17 -> #N/A | R17: =O17/L17 -> #N/A | T17: 0.34166667 | U17: 0.40138889 | V17: =(T17-U16)*24*60 -> 12 | W17: =(U17-T17)*24*60 -> 86 | AF17: =N17-K17 -> #N/A | AG17: =N17/K17 -> #N/A
B18: =VLOOKUP(D18,廠價表!$C$1:$E$43,2,0) -> #N/A | F18: =VLOOKUP(D18,廠價表!$C$1:$E$43,3,0) -> #N/A | G18: 3398 | H18: =F18*G18 -> #N/A | J18: =VLOOKUP(D18,產線配置圖!$A$3:$C$38,2,0) -> #N/A | K18: =VLOOKUP(D18,產線配置圖!$A$3:$C$38,3,0) -> #N/A | L18: =K18/J18 -> #N/A | M18: 12 | N18: =G18/W18*60 -> 1941.7143 | O18: =N18/M18 -> 161.80952 | P18: =M18-J18 -> #N/A | Q18: =O18-L18 -> #N/A | R18: =O18/L18 -> #N/A | T18: 0.40972222 | U18: 0.48263889 | V18: =(T18-U17)*24*60 -> 12 | W18: =(U18-T18)*24*60 -> 105 | X18: 0.48611111 | Y18: 0.52777778 | AF18: =N18-K18 -> #N/A | AG18: =N18/K18 -> #N/A
V19: =(T19-U18)*24*60 -> -695 | W19: =(U19-T19)*24*60 -> 0 | AF19: =N19-K19 -> 0 | AG19: =N19/K19 -> #DIV/0!
V20: =(T20-U19)*24*60 -> 0 | W20: =(U20-T20)*24*60 -> 0
W21: =(U21-T21)*24*60 -> 0
W22: 0
W23: =(U23-T23)*24*60 -> 0
H24: =F24*G24 -> 0 | W24: =(U24-T24)*24*60 -> 0
H25: =F25*G25 -> 0 | W25: =(U25-T25)*24*60 -> 0
C26: 4度二組A | D26: 平均 | J26: =AVERAGE(J16:J25) -> #N/A | K26: =AVERAGE(K16:K25) -> #N/A | L26: =AVERAGE(L16:L25) -> #N/A | M26: =AVERAGE(M16:M25) -> 12.666667 | N26: =AVERAGE(N16:N25) -> 1663.6239 | O26: =AVERAGE(O16:O25) -> 132.12003 | P26: =M26-J26 -> #N/A | Q26: =O26-L26 -> #N/A | R26: =O26/L26 -> #N/A | Z26: =SUM(Z16:Z25) -> 0 | AA26: =SUM(AA16:AA25) -> 0 | AD26: =SUM(AD16:AD25) -> 0 | AE26: =SUM(AE16:AE25) -> 0 | AF26: =N26-K26 -> #N/A | AG26: =N26/K26 -> #N/A
A27: 手工三線 (ET-55) | B27: =VLOOKUP(D27,廠價表!$C$1:$E$43,2,0) -> #N/A | F27: =VLOOKUP(D27,廠價表!$C$1:$E$43,3,0) -> #N/A | G27: 2263 | H27: =F27*G27 -> #N/A | J27: =VLOOKUP(D27,產線配置圖!$A$3:$C$38,2,0) -> #N/A | K27: =VLOOKUP(D27,產線配置圖!$A$3:$C$38,3,0) -> #N/A | L27: =K27/J27 -> #N/A | M27: 14 | N27: =G27/W27*60 -> 1212.3214 | O27: =N27/M27 -> 86.594388 | P27: =M27-J27 -> #N/A | Q27: =O27-L27 -> #N/A | R27: =O27/L27 -> #N/A | S27: =R37 -> #N/A | T27: 0.29166667 | U27: 0.36944444 | W27: =(U27-T27)*24*60 -> 112 | AF27: =N27-K27 -> #N/A | AG27: =N27/K27 -> #N/A | AH27: =AG37 -> #N/A
B28: =VLOOKUP(D28,廠價表!$C$1:$E$43,2,0) -> #N/A | F28: =VLOOKUP(D28,廠價表!$C$1:$E$43,3,0) -> #N/A | G28: 1180 | H28: =F28*G28 -> #N/A | J28: =VLOOKUP(D28,產線配置圖!$A$3:$C$38,2,0) -> #N/A | K28: =VLOOKUP(D28,產線配置圖!$A$3:$C$38,3,0) -> #N/A | L28: =K28/J28 -> #N/A | M28: 16 | N28: =G28/W28*60 -> 1089.2308 | O28: =N28/M28 -> 68.076923 | P28: =M28-J28 -> #N/A | Q28: =O28-L28 -> #N/A | R28: =O28/L28 -> #N/A | T28: 0.375 | U28: 0.42013889 | V28: =(T28-U27)*24*60 -> 8 | W28: =(U28-T28)*24*60 -> 65 | AF28: =N28-K28 -> #N/A | AG28: =N28/K28 -> #N/A
B29: =VLOOKUP(D29,廠價表!$C$1:$E$43,2,0) -> #N/A | F29: =VLOOKUP(D29,廠價表!$C$1:$E$43,3,0) -> #N/A | G29: 3398 | H29: =F29*G29 -> #N/A | J29: =VLOOKUP(D29,產線配置圖!$A$3:$C$38,2,0) -> #N/A | K29: =VLOOKUP(D29,產線配置圖!$A$3:$C$38,3,0) -> #N/A | L29: =K29/J29 -> #N/A | M29: 14 | N29: =G29/W29*60 -> 3136.6154 | O29: =N29/M29 -> 224.04396 | P29: =M29-J29 -> #N/A | Q29: =O29-L29 -> #N/A | R29: =O29/L29 -> #N/A | T29: 0.43055556 | U29: 0.47569444 | V29: =(T29-U28)*24*60 -> 15 | W29: =(U29-T29)*24*60 -> 65 | AF29: =N29-K29 -> #N/A | AG29: =N29/K29 -> #N/A
T30: 0.53958333 | U30: 0.56944444 | V30: =(T30-U29)*24*60 -> 92 | W30: =(U30-T30)*24*60 -> 43 | X30: 0.49652778 | Y30: 0.53819444 | AF30: =N30-K30 -> 0 | AG30: =N30/K30 -> #DIV/0!
W31: =(U31-T31)*24*60 -> 0 | AF31: =N31-K31 -> 0 | AG31: =N31/K31 -> #DIV/0!
W32: =(U32-T32)*24*60 -> 0
W33: =(U33-T33)*24*60 -> 0
W34: =(U34-T34)*24*60 -> 0
W35: =(U35-T35)*24*60 -> 0
H36: =F36*G36 -> 0 | W36: =(U36-T36)*24*60 -> 0
C37: 4度二組B | D37: 平均 | J37: =AVERAGE(J27:J36) -> #N/A | K37: =AVERAGE(K27:K36) -> #N/A | L37: =AVERAGE(L27:L36) -> #N/A | M37: =AVERAGE(M27:M36) -> 14.666667 | N37: =AVERAGE(N27:N36) -> 1812.7225 | O37: =AVERAGE(O27:O36) -> 126.23842 | P37: =M37-J37 -> #N/A | Q37: =N37-K37 -> #N/A | R37: =O37/L37 -> #N/A | Z37: =SUM(Z27:Z36) -> 0 | AA37: =SUM(AA27:AA36) -> 0 | AD37: =SUM(AD27:AD36) -> 0 | AE37: =SUM(AE27:AE36) -> 0 | AF37: =N37-K37 -> #N/A | AG37: =N37/K37 -> #N/A
A38: 手工四線 (ET-55) | B38: =VLOOKUP(D38,廠價表!$C$1:$E$43,2,0) -> #N/A | F38: =VLOOKUP(D38,廠價表!$C$1:$E$43,3,0) -> #N/A | G38: 2263 | H38: =F38*G38 -> #N/A | J38: =VLOOKUP(D38,產線配置圖!$A$3:$C$38,2,0) -> #N/A | K38: =VLOOKUP(D38,產線配置圖!$A$3:$C$38,3,0) -> #N/A | L38: =K38/J38 -> #N/A | M38: 14 | N38: =G38/W38*60 -> 1967.8261 | O38: =N38/M38 -> 140.55901 | P38: =M38-J38 -> #N/A | Q38: =O38-L38 -> #N/A | R38: =O38/L38 -> #N/A | S38: =R48 -> #N/A | T38: 0.33333333 | U38: 0.38125 | W38: =(U38-T38)*24*60 -> 69 | AF38: =N38-K38 -> #N/A | AG38: =N38/K38 -> #N/A | AH38: =AG48 -> #N/A
B39: =VLOOKUP(D39,廠價表!$C$1:$E$43,2,0) -> #N/A | F39: =VLOOKUP(D39,廠價表!$C$1:$E$43,3,0) -> #N/A | G39: 1180 | H39: =F39*G39 -> #N/A | J39: =VLOOKUP(D39,產線配置圖!$A$3:$C$38,2,0) -> #N/A | K39: =VLOOKUP(D39,產線配置圖!$A$3:$C$38,3,0) -> #N/A | L39: =K39/J39 -> #N/A | M39: 14 | N39: =G39/W39*60 -> 885 | O39: =N39/M39 -> 63.214286 | P39: =M39-J39 -> #N/A | Q39: =O39-L39 -> #N/A | R39: =O39/L39 -> #N/A | T39: 0.38888889 | U39: 0.44444444 | V39: =(T39-U38)*24*60 -> 11 | W39: =(U39-T39)*24*60 -> 80 | AF39: =N39-K39 -> #N/A | AG39: =N39/K39 -> #N/A
B40: =VLOOKUP(D40,廠價表!$C$1:$E$43,2,0) -> #N/A | F40: =VLOOKUP(D40,廠價表!$C$1:$E$43,3,0) -> #N/A | G40: 3398 | H40: =F40*G40 -> #N/A | J40: =VLOOKUP(D40,產線配置圖!$A$3:$C$38,2,0) -> #N/A | K40: =VLOOKUP(D40,產線配置圖!$A$3:$C$38,3,0) -> #N/A | L40: =K40/J40 -> #N/A | M40: 14 | N40: =G40/W40*60 -> 1853.4545 | O40: =N40/M40 -> 132.38961 | P40: =M40-J40 -> #N/A | Q40: =O40-L40 -> #N/A | R40: =O40/L40 -> #N/A | T40: 0.52777778 | U40: 0.60416667 | V40: =(T40-U39)*24*60 -> 120 | W40: =(U40-T40)*24*60 -> 110 | AF40: =N40-K40 -> #N/A | AG40: =N40/K40 -> #N/A
...

Sheet 0401總
B1: 長家廠組合室生產人時性分析
B3: 日期 | D3: 46113 | F3: 訂單量 | G3: ='0401'!E1 -> 49874 | I3: 營業額 | J3: ='0401'!G1 -> 2342819
B4: 項目 | D4: 3 | F4: ➀ | H4: ➁ | J4: ③ | L4: 異常停線 | N4: 短暫停線
B5: 人時性 | D5: 組合室 | F5: 全溫層 | H5: 義大利麵 | J5: 袋裝小吃、義麵 | L5: 合計次數 | M5: 時間 | N5: 合計次數 | O5: 設備次數
D6: 排關平均 | F6: =AVERAGE(D13:I13) -> 131.23173 | H6: =AVERAGE(D13:H13) -> 126.76023 | J6: =AVERAGE(I13) -> 153.58921 | L6: =SUM(D18:J18) -> 4 | M6: =SUM(D19:J19) -> 23 | N6: =SUM(D20:J20) -> 0 | O6: =SUM(D20:J20) -> 0
D7: 實績平均 | F7: =AVERAGE(D14:I14) -> 115.01846 | H7: =AVERAGE(D14:H14) -> 113.76339 | J7: =AVERAGE(I14) -> 121.29381 | L7: =AVERAGE(K14:L14) -> #DIV/0! | M7: =AVERAGE(L14:M14) -> #DIV/0! | N7: =AVERAGE(M14:N14) -> #DIV/0! | O7: =AVERAGE(N14:O14) -> #DIV/0!
D8: 達成率平均 | F8: =F7/F6 -> 0.87645315 | H8: =H7/H6 -> 0.89746911 | J8: =J7/J6 -> 0.7897287 | L8: =AVERAGE(K15:L15) -> #DIV/0! | M8: =AVERAGE(L15:M15) -> #DIV/0! | N8: =AVERAGE(M15:N15) -> #DIV/0! | O8: =AVERAGE(N15:O15) -> #DIV/0!
J9: ※現行日本鮮食廠以達成率80%為基本(即為現行KPI)
B10: 溫層 | D10: 4度C-各編組展開
B11: 編組 | D11: 1 | E11: 2 | F11: 3 | G11: 4 | H11: 5 | I11: 6 | J11: 7
D12: 自動1線 | E12: 自動2線 | F12: 手工3線 | G12: 手工4線 | H12: 手工5線 | I12: 調理包1線 | J12: 調理包2線
B13: 人時性 | C13: 排關 | D13: =VALUE('0401'!L15) -> 159.04396 | E13: =VALUE('0401'!L26) -> 170.39773 | F13: =VALUE('0401'!L37) -> 98.529836 | G13: =VALUE('0401'!L48) -> 96.051852 | H13: =VALUE('0401'!L58) -> 109.77778 | I13: =VALUE('0401'!L69) -> 153.58921 | J13: ='0401'!L79 -> 0
C14: 實績 | D14: =VALUE('0401'!O15) -> 153.60715 | E14: =VALUE('0401'!O26) -> 156.94801 | F14: =VALUE('0401'!O37) -> 69.58389 | G14: =VALUE('0401'!O48) -> 84.564579 | H14: =VALUE('0401'!O58) -> 104.11332 | I14: =VALUE('0401'!O69) -> 121.29381 | J14: ='0401'!O79 -> 0
C15: 達成率 | D15: =D14/D13 -> 0.96581572 | E15: =E14/E13 -> 0.92106866 | F15: =F14/F13 -> 0.70622152 | G15: =G14/G13 -> 0.8804055 | H15: =H14/H13 -> 0.9484007 | I15: =I14/I13 -> 0.7897287 | J15: ='0401'!S70 -> 0
B16: 作業 時間 | C16: 開始 | D16: ='0401'!T5 -> 0.29166667 | E16: ='0401'!T16 -> 0.29027778 | F16: ='0401'!T27 -> 0.29166667 | G16: ='0401'!T38 -> 0.33333333 | H16: ='0401'!T49 -> 0.29166667 | I16: ='0401'!T59 -> 0.29166667 | J16: ='0401'!T70 -> 0
C17: 結束 | D17: 0.56111111 | E17: 0.56805556 | F17: 0.60208333 | G17: 0.63194444 | H17: 0.59027778 | I17: 0.66666667 | J17: 0
B18: 產線異常 (5分鐘以上) | C18: 次數 | D18: ='0401'!Z15 -> 0 | E18: ='0401'!Z26 -> 0 | F18: ='0401'!Z37 -> 4 | G18: ='0401'!Z48 -> 0 | H18: ='0401'!Z58 -> 0 | I18: ='0401'!Z69 -> 0 | J18: ='0401'!AA79 -> 0
C19: 時間/分 | D19: ='0401'!AA15 -> 0 | E19: ='0401'!AA26 -> 0 | F19: ='0401'!AA37 -> 23 | G19: ='0401'!AA48 -> 0 | H19: ='0401'!AA58 -> 0 | I19: ='0401'!AA69 -> 0 | J19: ='0401'!AB79 -> 0
B20: 短暫停線 (5分鐘以下) | C20: 次數 | D20: ='0401'!AD15 -> 0 | E20: ='0401'!AD26 -> 0 | F20: ='0401'!AD37 -> 0 | G20: ='0401'!AD48 -> 0 | H20: ='0401'!AD58 -> 0 | I20: ='0401'!AD69 -> 0 | J20: ='0401'!AD79 -> 0
C21: 設備次數 | D21: ='0401'!AE15 -> 0 | E21: ='0401'!AE26 -> 0 | F21: ='0401'!AE37 -> 0 | G21: ='0401'!AE48 -> 0 | H21: ='0401'!AE58 -> 0 | I21: ='0401'!AE69 -> 0 | J21: ='0401'!AE79 -> 0
B22: 配置人數 | D22: =VALUE('0401'!M15) -> 13.333333 | E22: =VALUE('0401'!M26) -> 12.25 | F22: =VALUE('0401'!M37) -> 14.25 | G22: =VALUE('0401'!M48) -> 17 | H22: =VALUE('0401'!M58) -> 15.666667 | I22: =VALUE('0401'!M69) -> 11.75 | J22: ='0401'!M79 -> 0
B23: 主要應用設備 | D23: ET-600 | E23: ET-600 | F23: ET-55 | G23: ET-55 | H23: ET-55 | I23: 八爪機 | J23: 八爪機
B24: 次要應用設備 | H24: 封口機 | J24: 封口機
B25: 備註

Sheet 0401
A1: 長家廠4度C日報分析 | D1: 總生產量 | E1: =SUM(G5:G79) -> 49874 | F1: 營業額 | G1: =SUM(H5:H79) -> 2342819 | H1: 出勤人數 | I1: =M15+M26+M48+M58+M69+M79+M37 -> 84.25 | J1: 產線配置圖 | M1: 生產實績 | P1: 人時性差異分析 | T1: 日報登錄 | Z1: 合計 次數 | AA1: 合計 時間/分 | AB1: 分析說明 | AD1: 合計 次數 | AE1: 合計 設備次數 | AF1: 產能差異分析
A2: 04月01日 星期三 | D2: 人時性 | E2: =AVERAGE(O15,O26,O37,O48,O58,O69,O79) -> 115.01846 | F2: 平均廠價 | G2: =G1/E1 -> 46.974757 | H2: 多次生產數 | I2: =COUNT(I5:I79) -> 0 | Z2: =Z15+Z26+Z37+Z48+Z58+Z69+Z79 -> 4 | AA2: =AA15+AA26+AA37+AA48+AA58+AA69+AA79 -> 23 | AD2: =AD15+AD26+AD37+AD48+AD58+AD69+AD79 -> 0 | AE2: =AE15+AE26+AE37+AE48+AE58+AE69+AE79 -> 0
A3: 線別 | B3: 品類 | D3: 品名 | F3: 廠價 | G3: 生產量 | H3: 營收 | I3: 多次 生產 | J3: 人數 | K3: 產能/時 | L3: 人時性 | M3: 人數 | N3: 產能/時 | O3: 人時性 | P3: 人數 | Q3: 人時性 | R3: 達成率 | S3: 達成率平均 | T3: 生產時間 | V3: 前置、換線時間/分 | W3: 稼動時間/分 | X3: 休息時間 | Z3: 產線異常統計 (5分鐘以上) | AD3: 短暫停線統計 (5分鐘以下) | AF3: 產能/時 | AG3: 達成率 | AH3: 達成率平均
T4: 開始 | U4: 結束 | X4: 開始 | Y4: 結束 | Z4: 次數 | AA4: 時間/分 | AD4: 總次數 | AE4: 設備因素(次數)
A5: 自動一線 (ET-600) | B5: 義大利麵 | D5: 蒜香奶油蝦蝦義大利麵 | F5: =VLOOKUP(D5,廠價表!$C$1:$E$43,3,0) -> 57.21 | G5: 3654 | H5: =F5*G5 -> 209045.34 | J5: =VLOOKUP(D5,產線配置圖!$A$3:$C$38,2,0) -> 14 | K5: =VLOOKUP(D5,產線配置圖!$A$3:$C$38,3,0) -> 2118 | L5: =K5/J5 -> 151.28571 | M5: 14 | N5: =G5/W5*60 -> 1993.0909 | O5: =N5/M5 -> 142.36364 | P5: =M5-J5 -> 0 | Q5: =O5-L5 -> -8.9220779 | R5: =O5/L5 -> 0.94102498 | S5: =R15 -> 0.96581572 | T5: 0.29166667 | U5: 0.36805556 | W5: =(U5-T5)*24*60 -> 110 | AF5: =N5-K5 -> -124.90909 | AG5: =N5/K5 -> 0.94102498 | AH5: =AG15 -> 0.96522546
B6: 義大利麵 | D6: 奶油培根義大利麵 | F6: =VLOOKUP(D6,廠價表!$C$1:$E$43,3,0) -> 49.14 | G6: 5197 | H6: =F6*G6 -> 255380.58 | J6: =VLOOKUP(D6,產線配置圖!$A$3:$C$38,2,0) -> 13 | K6: =VLOOKUP(D6,產線配置圖!$A$3:$C$38,3,0) -> 2118 | L6: =K6/J6 -> 162.92308 | M6: 13 | N6: =G6/W6*60 -> 2092.7517 | O6: =N6/M6 -> 160.9809 | P6: =M6-J6 -> 0 | Q6: =O6-L6 -> -1.9421786 | R6: =O6/L6 -> 0.98807917 | T6: 0.375 | U6: 0.47847222 | V6: =(T6-U5)*24*60 -> 10 | W6: =(U6-T6)*24*60 -> 149 | AF6: =N6-K6 -> -25.248322 | AG6: =N6/K6 -> 0.98807917
B7: 義大利麵 | D7: 奶油培根義大利麵 | F7: =VLOOKUP(D7,廠價表!$C$1:$E$43,3,0) -> 49.14 | G7: 853 | H7: =F7*G7 -> 41916.42 | J7: =VLOOKUP(D7,產線配置圖!$A$3:$C$38,2,0) -> 13 | K7: =VLOOKUP(D7,產線配置圖!$A$3:$C$38,3,0) -> 2118 | L7: =K7/J7 -> 162.92308 | M7: 13 | N7: =G7/W7*60 -> 2047.2 | O7: =N7/M7 -> 157.47692 | P7: =M7-J7 -> 0 | Q7: =O7-L7 -> -5.4461538 | R7: =O7/L7 -> 0.96657224 | T7: 0.54375 | U7: 0.56111111 | V7: =(T7-U6)*24*60 -> 94 | W7: =(U7-T7)*24*60 -> 25 | AF7: =N7-K7 -> -70.8 | AG7: =N7/K7 -> 0.96657224
W8: =(U8-T8)*24*60 -> 0 | X8: 0.48611111 | Y8: 0.52777778 | AF8: =N8-K8 -> 0 | AG8: =N8/K8 -> #DIV/0!
W9: =(U9-T9)*24*60 -> 0 | AF9: =N9-K9 -> 0 | AG9: =N9/K9 -> #DIV/0!
W10: =(U10-T10)*24*60 -> 0 | AF10: =N10-K10 -> 0 | AG10: =N10/K10 -> #DIV/0!
W11: =(U11-T11)*24*60 -> 0 | AF11: =N11-K11 -> 0 | AG11: =N11/K11 -> #DIV/0!
W12: =(U12-T12)*24*60 -> 0
W13: =(U13-T13)*24*60 -> 0
W14: =(U14-T14)*24*60 -> 0
C15: 4度一組 | D15: 平均 | J15: =AVERAGE(J5:J14) -> 13.333333 | K15: =AVERAGE(K5:K14) -> 2118 | L15: =AVERAGE(L5:L14) -> 159.04396 | M15: =AVERAGE(M5:M14) -> 13.333333 | N15: =AVERAGE(N5:N14) -> 2044.3475 | O15: =AVERAGE(O5:O14) -> 153.60715 | P15: =M15-J15 -> 0 | Q15: =O15-L15 -> -5.4368035 | R15: =O15/L15 -> 0.96581572 | Z15: =SUM(Z5:Z14) -> 0 | AA15: =SUM(AA5:AA14) -> 0 | AD15: =SUM(AD5:AD14) -> 0 | AE15: =SUM(AE5:AE14) -> 0 | AF15: =N15-K15 -> -73.652471 | AG15: =N15/K15 -> 0.96522546
A16: 自動二線 (ET-600) | B16: 義大利麵 | D16: 辣味香菜雞肉義大利麵 | F16: =VLOOKUP(D16,廠價表!$C$1:$E$43,3,0) -> 56.28 | G16: 717 | H16: =F16*G16 -> 40352.76 | J16: =VLOOKUP(D16,產線配置圖!$A$3:$C$38,2,0) -> 15 | K16: =VLOOKUP(D16,產線配置圖!$A$3:$C$38,3,0) -> 1800 | L16: =K16/J16 -> 120 | M16: 15 | N16: =G16/W16*60 -> 1483.4483 | O16: =N16/M16 -> 98.896552 | P16: =M16-J16 -> 0 | Q16: =O16-L16 -> -21.103448 | R16: =O16/L16 -> 0.82413793 | S16: =R26 -> 0.92106866 | T16: 0.29027778 | U16: 0.31041667 | W16: =(U16-T16)*24*60 -> 29 | AF16: =N16-K16 -> -316.55172 | AG16: =N16/K16 -> 0.82413793 | AH16: =AG26 -> 0.9160624
B17: 義大利麵 | D17: 青醬蛤蜊義大利麵 | F17: =VLOOKUP(D17,廠價表!$C$1:$E$43,3,0) -> 50.67 | G17: 3803 | H17: =F17*G17 -> 192698.01 | J17: =VLOOKUP(D17,產線配置圖!$A$3:$C$38,2,0) -> 12 | K17: =VLOOKUP(D17,產線配置圖!$A$3:$C$38,3,0) -> 2118 | L17: =K17/J17 -> 176.5 | M17: 12 | N17: =G17/W17*60 -> 2019.292 | O17: =N17/M17 -> 168.27434 | P17: =M17-J17 -> 0 | Q17: =O17-L17 -> -8.2256637 | R17: =O17/L17 -> 0.95339567 | T17: 0.31736111 | U17: 0.39583333 | V17: =(T17-U16)*24*60 -> 10 | W17: =(U17-T17)*24*60 -> 113 | AF17: =N17-K17 -> -98.707965 | AG17: =N17/K17 -> 0.95339567
B18: 義大利麵 | D18: 義式蕃茄起司義大利麵 | F18: =VLOOKUP(D18,廠價表!$C$1:$E$43,3,0) -> 50.39 | G18: 3712 | H18: =F18*G18 -> 187047.68 | J18: =VLOOKUP(D18,產線配置圖!$A$3:$C$38,2,0) -> 11 | K18: =VLOOKUP(D18,產線配置圖!$A$3:$C$38,3,0) -> 2118 | L18: =K18/J18 -> 192.54545 | M18: 11 | N18: =G18/W18*60 -> 2024.7273 | O18: =N18/M18 -> 184.06612 | P18: =M18-J18 -> 0 | Q18: =O18-L18 -> -8.4793388 | R18: =O18/L18 -> 0.95596189 | T18: 0.40277778 | U18: 0.47916667 | V18: =(T18-U17)*24*60 -> 10 | W18: =(U18-T18)*24*60 -> 110 | X18: 0.48611111 | Y18: 0.52777778 | AF18: =N18-K18 -> -93.272727 | AG18: =N18/K18 -> 0.95596189
B19: 義大利麵 | D19: 義式蕃茄起司義大利麵 | F19: =VLOOKUP(D19,廠價表!$C$1:$E$43,3,0) -> 50.39 | G19: 1230 | H19: =F19*G19 -> 61979.7 | J19: =VLOOKUP(D19,產線配置圖!$A$3:$C$38,2,0) -> 11 | K19: =VLOOKUP(D19,產線配置圖!$A$3:$C$38,3,0) -> 2118 | L19: =K19/J19 -> 192.54545 | M19: 11 | N19: =G19/W19*60 -> 1942.1053 | O19: =N19/M19 -> 176.55502 | P19: =M19-J19 -> 0 | Q19: =O19-L19 -> -15.990431 | R19: =O19/L19 -> 0.91695244 | T19: 0.54166667 | U19: 0.56805556 | V19: =(T19-U18)*24*60 -> 90 | W19: =(U19-T19)*24*60 -> 38 | AF19: =N19-K19 -> -175.89474 | AG19: =N19/K19 -> 0.91695244
W20: =(U20-T20)*24*60 -> 0
W21: =(U21-T21)*24*60 -> 0
W22: 0
W23: =(U23-T23)*24*60 -> 0
H24: =F24*G24 -> 0 | W24: =(U24-T24)*24*60 -> 0
H25: =F25*G25 -> 0 | W25: =(U25-T25)*24*60 -> 0
C26: 4度二組A | D26: 平均 | J26: =AVERAGE(J16:J25) -> 12.25 | K26: =AVERAGE(K16:K25) -> 2038.5 | L26: =AVERAGE(L16:L25) -> 170.39773 | M26: =AVERAGE(M16:M25) -> 12.25 | N26: =AVERAGE(N16:N25) -> 1867.3932 | O26: =AVERAGE(O16:O25) -> 156.94801 | P26: =M26-J26 -> 0 | Q26: =O26-L26 -> -13.44972 | R26: =O26/L26 -> 0.92106866 | Z26: =SUM(Z16:Z25) -> 0 | AA26: =SUM(AA16:AA25) -> 0 | AD26: =SUM(AD16:AD25) -> 0 | AE26: =SUM(AE16:AE25) -> 0 | AF26: =N26-K26 -> -171.10679 | AG26: =N26/K26 -> 0.9160624
A27: 手工三線 (ET-55) | B27: 熱乾麵 | D27: 沙茶豬肉炒麵 | F27: =VLOOKUP(D27,廠價表!$C$1:$E$43,3,0) -> 49.52 | G27: 2250 | H27: =F27*G27 -> 111420 | J27: =VLOOKUP(D27,產線配置圖!$A$3:$C$38,2,0) -> 17 | K27: =VLOOKUP(D27,產線配置圖!$A$3:$C$38,3,0) -> 1440 | L27: =K27/J27 -> 84.705882 | M27: 16 | N27: =G27/W27*60 -> 1323.5294 | O27: =N27/M27 -> 82.720588 | P27: =M27-J27 -> -1 | Q27: =O27-L27 -> -1.9852941 | R27: =O27/L27 -> 0.9765625 | S27: =R37 -> 0.70622152 | T27: 0.29166667 | U27: 0.3625 | W27: =(U27-T27)*24*60 -> 102 | AF27: =N27-K27 -> -116.47059 | AG27: =N27/K27 -> 0.91911765 | AH27: =AG37 -> 0.69603303
B28: 義大利麵 | D28: 焗烤起司肉醬筆尖麵 | F28: =VLOOKUP(D28,廠價表!$C$1:$E$43,3,0) -> 50.67 | G28: 1390 | H28: =F28*G28 -> 70431.3 | J28: =VLOOKUP(D28,產線配置圖!$A$3:$C$38,2,0) -> 13 | K28: =VLOOKUP(D28,產線配置圖!$A$3:$C$38,3,0) -> 1440 | L28: =K28/J28 -> 110.76923 | M28: 13 | N28: =G28/W28*60 -> 981.17647 | O28: =N28/M28 -> 75.475113 | P28: =M28-J28 -> 0 | Q28: =O28-L28 -> -35.294118 | R28: =O28/L28 -> 0.68137255 | T28: 0.375 | U28: 0.43402778 | V28: =(T28-U27)*24*60 -> 18 | W28: =(U28-T28)*24*60 -> 85 | Z28: 3 | AA28: 15 | AB28: L型封膜異常 | AF28: =N28-K28 -> -458.82353 | AG28: =N28/K28 -> 0.68137255
B29: 義大利麵 | D29: 濃拿坡里義大利麵 | F29: =VLOOKUP(D29,廠價表!$C$1:$E$43,3,0) -> 56.43 | G29: 1145 | H29: =F29*G29 -> 64612.35 | J29: =VLOOKUP(D29,產線配置圖!$A$3:$C$38,2,0) -> 16 | K29: =VLOOKUP(D29,產線配置圖!$A$3:$C$38,3,0) -> 1406 | L29: =K29/J29 -> 87.875 | M29: 15 | N29: =G29/W29*60 -> 892.20779 | O29: =N29/M29 -> 59.480519 | P29: =M29-J29 -> -1 | Q29: =O29-L29 -> -28.394481 | R29: =O29/L29 -> 0.67687647 | T29: 0.43958333 | U29: 0.49305556 | V29: =(T29-U28)*24*60 -> 8 | W29: =(U29-T29)*24*60 -> 77 | AB29: L型封膜異常 | AF29: =N29-K29 -> -513.79221 | AG29: =N29/K29 -> 0.63457169
B30: 義大利麵 | D30: 焗烤起司肉醬筆尖麵 | F30: =VLOOKUP(D30,廠價表!$C$1:$E$43,3,0) -> 50.67 | G30: 920 | H30: =F30*G30 -> 46616.4 | J30: =VLOOKUP(D30,產線配置圖!$A$3:$C$38,2,0) -> 13 | K30: =VLOOKUP(D30,產線配置圖!$A$3:$C$38,3,0) -> 1440 | L30: =K30/J30 -> 110.76923 | M30: 13 | N30: =G30/W30*60 -> 788.57143 | O30: =N30/M30 -> 60.659341 | P30: =M30-J30 -> 0 | Q30: =O30-L30 -> -50.10989 | R30: =O30/L30 -> 0.54761905 | T30: 0.55347222 | U30: 0.60208333 | V30: =(T30-U29)*24*60 -> 87 | W30: =(U30-T30)*24*60 -> 70 | X30: 0.49652778 | Y30: 0.53819444 | Z30: 1 | AA30: 8 | AB30: L型封膜異常 | AF30: =N30-K30 -> -651.42857 | AG30: =N30/K30 -> 0.54761905
W31: =(U31-T31)*24*60 -> 0 | AF31: =N31-K31 -> 0 | AG31: =N31/K31 -> #DIV/0!
W32: =(U32-T32)*24*60 -> 0
W33: =(U33-T33)*24*60 -> 0
W34: =(U34-T34)*24*60 -> 0
W35: =(U35-T35)*24*60 -> 0
H36: =F36*G36 -> 0 | W36: =(U36-T36)*24*60 -> 0
C37: 4度二組B | D37: 平均 | J37: =AVERAGE(J27:J36) -> 14.75 | K37: =AVERAGE(K27:K36) -> 1431.5 | L37: =AVERAGE(L27:L36) -> 98.529836 | M37: =AVERAGE(M27:M36) -> 14.25 | N37: =AVERAGE(N27:N36) -> 996.37128 | O37: =AVERAGE(O27:O36) -> 69.58389 | P37: =M37-J37 -> -0.5 | Q37: =N37-K37 -> -435.12872 | R37: =O37/L37 -> 0.70622152 | Z37: =SUM(Z27:Z36) -> 4 | AA37: =SUM(AA27:AA36) -> 23 | AD37: =SUM(AD27:AD36) -> 0 | AE37: =SUM(AE27:AE36) -> 0 | AF37: =N37-K37 -> -435.12872 | AG37: =N37/K37 -> 0.69603303
A38: 手工四線 (ET-55) | B38: 熱乾麵 | D38: 青花椒麻雞肉拌麵 | F38: =VLOOKUP(D38,廠價表!$C$1:$E$43,3,0) -> 49.91 | G38: 2453 | H38: =F38*G38 -> 122429.23 | J38: =VLOOKUP(D38,產線配置圖!$A$3:$C$38,2,0) -> 15 | K38: =VLOOKUP(D38,產線配置圖!$A$3:$C$38,3,0) -> 1714 | L38: =K38/J38 -> 114.26667 | M38: 15 | N38: =G38/W38*60 -> 1401.7143 | O38: =N38/M38 -> 93.447619 | P38: =M38-J38 -> 0 | Q38: =O38-L38 -> -20.819048 | R38: =O38/L38 -> 0.81780297 | S38: =R48 -> 0.8804055 | T38: 0.33333333 | U38: 0.40625 | W38: =(U38-T38)*24*60 -> 105 | AF38: =N38-K38 -> -312.28571 | AG38: =N38/K38 -> 0.81780297 | AH38: =AG48 -> 0.88483576
B39: 熱乾麵 | D39: 府城鹽水意麵 | F39: =VLOOKUP(D39,廠價表!$C$1:$E$43,3,0) -> 44.3 | G39: 2557 | H39: =F39*G39 -> 113275.1 | J39: =VLOOKUP(D39,產線配置圖!$A$3:$C$38,2,0) -> 18 | K39: =VLOOKUP(D39,產線配置圖!$A$3:$C$38,3,0) -> 1565 | L39: =K39/J39 -> 86.944444 | M39: 18 | N39: =G39/W39*60 -> 1369.8214 | O39: =N39/M39 -> 76.10119 | P39: =M39-J39 -> 0 | Q39: =O39-L39 -> -10.843254 | R39: =O39/L39 -> 0.87528526 | T39: 0.41180556 | U39: 0.48958333 | V39: =(T39-U38)*24*60 -> 8 | W39: =(U39-T39)*24*60 -> 112 | AF39: =N39-K39 -> -195.17857 | AG39: =N39/K39 -> 0.87528526
B40: 熱乾麵 | D40: 府城鹽水意麵 | F40: =VLOOKUP(D40,廠價表!$C$1:$E$43,3,0) -> 44.3 | G40: 2903 | H40: =F40*G40 -> 128602.9 | J40: =VLOOKUP(D40,產線配置圖!$A$3:$C$38,2,0) -> 18 | K40: =VLOOKUP(D40,產線配置圖!$A$3:$C$38,3,0) -> 1565 | L40: =K40/J40 -> 86.944444 | M40: 18 | N40: =G40/W40*60 -> 1514.6087 | O40: =N40/M40 -> 84.144928 | P40: =M40-J40 -> 0 | Q40: =O40-L40 -> -2.7995169 | R40: =O40/L40 -> 0.96780108 | T40: 0.55208333 | U40: 0.63194444 | V40: =(T40-U39)*24*60 -> 90 | W40: =(U40-T40)*24*60 -> 115 | AF40: =N40-K40 -> -50.391304 | AG40: =N40/K40 -> 0.96780108
...

Sheet 0402總
B1: 長家廠組合室生產人時性分析
B3: 日期 | D3: 46114 | F3: 訂單量 | G3: ='0402'!E1 -> 45514 | I3: 營業額 | J3: ='0402'!G1 -> 2150791.6
B4: 項目 | D4: 3 | F4: ➀ | H4: ➁ | J4: ③ | L4: 異常停線 | N4: 短暫停線
B5: 人時性 | D5: 組合室 | F5: 全溫層 | H5: 義大利麵 | J5: 袋裝小吃、義麵 | L5: 合計次數 | M5: 時間 | N5: 合計次數 | O5: 設備次數
D6: 排關平均 | F6: =AVERAGE(D13:I13) -> 130.44767 | H6: =AVERAGE(D13:H13) -> 125.81936 | J6: =AVERAGE(I13) -> 153.58921 | L6: =SUM(D18:J18) -> 2 | M6: =SUM(D19:J19) -> 20 | N6: =SUM(D20:J20) -> 0 | O6: =SUM(D20:J20) -> 0
D7: 實績平均 | F7: =AVERAGE(D14:I14) -> 112.93395 | H7: =AVERAGE(D14:H14) -> 111.55095 | J7: =AVERAGE(I14) -> 119.84895 | L7: =AVERAGE(K14:L14) -> #DIV/0! | M7: =AVERAGE(L14:M14) -> #DIV/0! | N7: =AVERAGE(M14:N14) -> #DIV/0! | O7: =AVERAGE(N14:O14) -> #DIV/0!
D8: 達成率平均 | F8: =F7/F6 -> 0.86574141 | H8: =H7/H6 -> 0.88659605 | J8: =J7/J6 -> 0.78032145 | L8: =AVERAGE(K15:L15) -> #DIV/0! | M8: =AVERAGE(L15:M15) -> #DIV/0! | N8: =AVERAGE(M15:N15) -> #DIV/0! | O8: =AVERAGE(N15:O15) -> #DIV/0!
J9: ※現行日本鮮食廠以達成率80%為基本(即為現行KPI)
B10: 溫層 | D10: 4度C-各編組展開
B11: 編組 | D11: 1 | E11: 2 | F11: 3 | G11: 4 | H11: 5 | I11: 6 | J11: 7
D12: 自動1線 | E12: 自動2線 | F12: 手工3線 | G12: 手工4線 | H12: 手工5線 | I12: 調理包1線 | J12: 調理包2線
B13: 人時性 | C13: 排關 | D13: =VALUE('0402'!L15) -> 157.1044 | E13: =VALUE('0402'!L26) -> 170.39773 | F13: =VALUE('0402'!L37) -> 95.765045 | G13: =VALUE('0402'!L48) -> 96.051852 | H13: =VALUE('0402'!L58) -> 109.77778 | I13: =VALUE('0402'!L69) -> 153.58921 | J13: ='0402'!L79 -> 0
C14: 實績 | D14: =VALUE('0402'!O15) -> 148.61614 | E14: =VALUE('0402'!O26) -> 147.61267 | F14: =VALUE('0402'!O37) -> 76.987958 | G14: =VALUE('0402'!O48) -> 86.465383 | H14: =VALUE('0402'!O58) -> 98.072586 | I14: =VALUE('0402'!O69) -> 119.84895 | J14: ='0402'!O79 -> 0
C15: 達成率 | D15: =D14/D13 -> 0.94597063 | E15: =E14/E13 -> 0.86628307 | F15: =F14/F13 -> 0.80392545 | G15: =G14/G13 -> 0.90019486 | H15: =H14/H13 -> 0.89337376 | I15: =I14/I13 -> 0.78032145 | J15: ='0402'!S70 -> 0
B16: 作業 時間 | C16: 開始 | D16: ='0402'!T5 -> 0.29166667 | E16: ='0402'!T16 -> 0.29236111 | F16: ='0402'!T27 -> 0.3125 | G16: ='0402'!T38 -> 0.33333333 | H16: ='0402'!T49 -> 0.29097222 | I16: ='0402'!T59 -> 0.29166667 | J16: ='0402'!T70 -> 0
C17: 結束 | D17: 0.48611111 | E17: 0.56527778 | F17: 0.61319444 | G17: 0.61458333 | H17: 0.59305556 | I17: 0.57291667 | J17: 0
B18: 產線異常 (5分鐘以上) | C18: 次數 | D18: ='0402'!Z15 -> 0 | E18: ='0402'!Z26 -> 0 | F18: ='0402'!Z37 -> 2 | G18: ='0402'!Z48 -> 0 | H18: ='0402'!Z58 -> 0 | I18: ='0402'!Z69 -> 0 | J18: ='0402'!AA79 -> 0
C19: 時間/分 | D19: ='0402'!AA15 -> 0 | E19: ='0402'!AA26 -> 0 | F19: ='0402'!AA37 -> 20 | G19: ='0402'!AA48 -> 0 | H19: ='0402'!AA58 -> 0 | I19: ='0402'!AA69 -> 0 | J19: ='0402'!AB79 -> 0
B20: 短暫停線 (5分鐘以下) | C20: 次數 | D20: ='0402'!AD15 -> 0 | E20: ='0402'!AD26 -> 0 | F20: ='0402'!AD37 -> 0 | G20: ='0402'!AD48 -> 0 | H20: ='0402'!AD58 -> 0 | I20: ='0402'!AD69 -> 0 | J20: ='0402'!AD79 -> 0
C21: 設備次數 | D21: ='0402'!AE15 -> 0 | E21: ='0402'!AE26 -> 0 | F21: ='0402'!AE37 -> 0 | G21: ='0402'!AE48 -> 0 | H21: ='0402'!AE58 -> 0 | I21: ='0402'!AE69 -> 0 | J21: ='0402'!AE79 -> 0
B22: 配置人數 | D22: =VALUE('0402'!M15) -> 13 | E22: =VALUE('0402'!M26) -> 12.25 | F22: =VALUE('0402'!M37) -> 14.2 | G22: =VALUE('0402'!M48) -> 16.333333 | H22: =VALUE('0402'!M58) -> 15 | I22: =VALUE('0402'!M69) -> 11.75 | J22: ='0402'!M79 -> 0
B23: 主要應用設備 | D23: ET-600 | E23: ET-600 | F23: ET-55 | G23: ET-55 | H23: ET-55 | I23: 八爪機 | J23: 八爪機
B24: 次要應用設備 | H24: 封口機 | J24: 封口機
B25: 備註

Sheet 0402
A1: 長家廠4度C日報分析 | D1: 總生產量 | E1: =SUM(G5:G79) -> 45514 | F1: 營業額 | G1: =SUM(H5:H79) -> 2150791.6 | H1: 出勤人數 | I1: =M15+M26+M48+M58+M69+M79+M37 -> 82.533333 | J1: 產線配置圖 | M1: 生產實績 | P1: 人時性差異分析 | T1: 日報登錄 | Z1: 合計 次數 | AA1: 合計 時間/分 | AB1: 分析說明 | AD1: 合計 次數 | AE1: 合計 設備次數 | AF1: 產能差異分析
A2: 04月02日 星期四 | D2: 人時性 | E2: =AVERAGE(O15,O26,O37,O48,O58,O69,O79) -> 112.93395 | F2: 平均廠價 | G2: =G1/E1 -> 47.255606 | H2: 多次生產數 | I2: =COUNT(I5:I79) -> 0 | Z2: =Z15+Z26+Z37+Z48+Z58+Z69+Z79 -> 2 | AA2: =AA15+AA26+AA37+AA48+AA58+AA69+AA79 -> 20 | AD2: =AD15+AD26+AD37+AD48+AD58+AD69+AD79 -> 0 | AE2: =AE15+AE26+AE37+AE48+AE58+AE69+AE79 -> 0
A3: 線別 | B3: 品類 | D3: 品名 | F3: 廠價 | G3: 生產量 | H3: 營收 | I3: 多次 生產 | J3: 人數 | K3: 產能/時 | L3: 人時性 | M3: 人數 | N3: 產能/時 | O3: 人時性 | P3: 人數 | Q3: 人時性 | R3: 達成率 | S3: 達成率平均 | T3: 生產時間 | V3: 前置、換線時間/分 | W3: 稼動時間/分 | X3: 休息時間 | Z3: 產線異常統計 (5分鐘以上) | AD3: 短暫停線統計 (5分鐘以下) | AF3: 產能/時 | AG3: 達成率 | AH3: 達成率平均
T4: 開始 | U4: 結束 | X4: 開始 | Y4: 結束 | Z4: 次數 | AA4: 時間/分 | AD4: 總次數 | AE4: 設備因素(次數)
A5: 自動一線 (ET-600) | B5: 義大利麵 | D5: 蒜香奶油蝦蝦義大利麵 | F5: =VLOOKUP(D5,廠價表!$C$1:$E$43,3,0) -> 57.21 | G5: 2988 | H5: =F5*G5 -> 170943.48 | J5: =VLOOKUP(D5,產線配置圖!$A$3:$C$38,2,0) -> 14 | K5: =VLOOKUP(D5,產線配置圖!$A$3:$C$38,3,0) -> 2118 | L5: =K5/J5 -> 151.28571 | M5: 13 | N5: =G5/W5*60 -> 1907.234 | O5: =N5/M5 -> 146.71031 | P5: =M5-J5 -> -1 | Q5: =O5-L5 -> -4.5754033 | R5: =O5/L5 -> 0.96975654 | S5: =R15 -> 0.94597063 | T5: 0.29166667 | U5: 0.35694444 | W5: =(U5-T5)*24*60 -> 94 | AF5: =N5-K5 -> -210.76596 | AG5: =N5/K5 -> 0.90048822 | AH5: =AG15 -> 0.91218597
B6: 義大利麵 | D6: 奶油培根義大利麵 | F6: =VLOOKUP(D6,廠價表!$C$1:$E$43,3,0) -> 49.14 | G6: 5479 | H6: =F6*G6 -> 269238.06 | J6: =VLOOKUP(D6,產線配置圖!$A$3:$C$38,2,0) -> 13 | K6: =VLOOKUP(D6,產線配置圖!$A$3:$C$38,3,0) -> 2118 | L6: =K6/J6 -> 162.92308 | M6: 13 | N6: =G6/W6*60 -> 1956.7857 | O6: =N6/M6 -> 150.52198 | P6: =M6-J6 -> 0 | Q6: =O6-L6 -> -12.401099 | R6: =O6/L6 -> 0.92388372 | T6: 0.36944444 | U6: 0.48611111 | V6: =(T6-U5)*24*60 -> 18 | W6: =(U6-T6)*24*60 -> 168 | AF6: =N6-K6 -> -161.21429 | AG6: =N6/K6 -> 0.92388372
W7: =(U7-T7)*24*60 -> 0 | AF7: =N7-K7 -> 0 | AG7: =N7/K7 -> #DIV/0!
W8: =(U8-T8)*24*60 -> 0 | X8: 0.48611111 | Y8: 0.52777778 | AF8: =N8-K8 -> 0 | AG8: =N8/K8 -> #DIV/0!
W9: =(U9-T9)*24*60 -> 0 | AF9: =N9-K9 -> 0 | AG9: =N9/K9 -> #DIV/0!
W10: =(U10-T10)*24*60 -> 0 | AF10: =N10-K10 -> 0 | AG10: =N10/K10 -> #DIV/0!
W11: =(U11-T11)*24*60 -> 0 | AF11: =N11-K11 -> 0 | AG11: =N11/K11 -> #DIV/0!
W12: =(U12-T12)*24*60 -> 0
W13: =(U13-T13)*24*60 -> 0
W14: =(U14-T14)*24*60 -> 0
C15: 4度一組 | D15: 平均 | J15: =AVERAGE(J5:J14) -> 13.5 | K15: =AVERAGE(K5:K14) -> 2118 | L15: =AVERAGE(L5:L14) -> 157.1044 | M15: =AVERAGE(M5:M14) -> 13 | N15: =AVERAGE(N5:N14) -> 1932.0099 | O15: =AVERAGE(O5:O14) -> 148.61614 | P15: =M15-J15 -> -0.5 | Q15: =O15-L15 -> -8.4882511 | R15: =O15/L15 -> 0.94597063 | Z15: =SUM(Z5:Z14) -> 0 | AA15: =SUM(AA5:AA14) -> 0 | AD15: =SUM(AD5:AD14) -> 0 | AE15: =SUM(AE5:AE14) -> 0 | AF15: =N15-K15 -> -185.99012 | AG15: =N15/K15 -> 0.91218597
A16: 自動二線 (ET-600) | B16: 義大利麵 | D16: 辣味香菜雞肉義大利麵 | F16: =VLOOKUP(D16,廠價表!$C$1:$E$43,3,0) -> 56.28 | G16: 631 | H16: =F16*G16 -> 35512.68 | J16: =VLOOKUP(D16,產線配置圖!$A$3:$C$38,2,0) -> 15 | K16: =VLOOKUP(D16,產線配置圖!$A$3:$C$38,3,0) -> 1800 | L16: =K16/J16 -> 120 | M16: 15 | N16: =G16/W16*60 -> 1305.5172 | O16: =N16/M16 -> 87.034483 | P16: =M16-J16 -> 0 | Q16: =O16-L16 -> -32.965517 | R16: =O16/L16 -> 0.72528736 | S16: =R26 -> 0.86628307 | T16: 0.29236111 | U16: 0.3125 | W16: =(U16-T16)*24*60 -> 29 | AB16: 生產數量少 | AF16: =N16-K16 -> -494.48276 | AG16: =N16/K16 -> 0.72528736 | AH16: =AG26 -> 0.85773151
B17: 義大利麵 | D17: 青醬蛤蜊義大利麵 | F17: =VLOOKUP(D17,廠價表!$C$1:$E$43,3,0) -> 50.67 | G17: 3560 | H17: =F17*G17 -> 180385.2 | J17: =VLOOKUP(D17,產線配置圖!$A$3:$C$38,2,0) -> 12 | K17: =VLOOKUP(D17,產線配置圖!$A$3:$C$38,3,0) -> 2118 | L17: =K17/J17 -> 176.5 | M17: 12 | N17: =G17/W17*60 -> 1810.1695 | O17: =N17/M17 -> 150.84746 | P17: =M17-J17 -> 0 | Q17: =O17-L17 -> -25.652542 | R17: =O17/L17 -> 0.85465982 | T17: 0.31805556 | U17: 0.4 | V17: =(T17-U16)*24*60 -> 8 | W17: =(U17-T17)*24*60 -> 118 | AF17: =N17-K17 -> -307.83051 | AG17: =N17/K17 -> 0.85465982
B18: 義大利麵 | D18: 義式蕃茄起司義大利麵 | F18: =VLOOKUP(D18,廠價表!$C$1:$E$43,3,0) -> 50.39 | G18: 3631 | H18: =F18*G18 -> 182966.09 | J18: =VLOOKUP(D18,產線配置圖!$A$3:$C$38,2,0) -> 11 | K18: =VLOOKUP(D18,產線配置圖!$A$3:$C$38,3,0) -> 2118 | L18: =K18/J18 -> 192.54545 | M18: 11 | N18: =G18/W18*60 -> 2094.8077 | O18: =N18/M18 -> 190.43706 | P18: =M18-J18 -> 0 | Q18: =O18-L18 -> -2.1083916 | R18: =O18/L18 -> 0.9890499 | T18: 0.40694444 | U18: 0.47916667 | V18: =(T18-U17)*24*60 -> 10 | W18: =(U18-T18)*24*60 -> 104 | X18: 0.48611111 | Y18: 0.52777778 | AF18: =N18-K18 -> -23.192308 | AG18: =N18/K18 -> 0.9890499
B19: 義大利麵 | D19: 義式蕃茄起司義大利麵 | F19: =VLOOKUP(D19,廠價表!$C$1:$E$43,3,0) -> 50.39 | G19: 862 | H19: =F19*G19 -> 43436.18 | J19: =VLOOKUP(D19,產線配置圖!$A$3:$C$38,2,0) -> 11 | K19: =VLOOKUP(D19,產線配置圖!$A$3:$C$38,3,0) -> 2118 | L19: =K19/J19 -> 192.54545 | M19: 11 | N19: =G19/W19*60 -> 1783.4483 | O19: =N19/M19 -> 162.13166 | P19: =M19-J19 -> 0 | Q19: =O19-L19 -> -30.413793 | R19: =O19/L19 -> 0.84204357 | T19: 0.54513889 | U19: 0.56527778 | V19: =(T19-U18)*24*60 -> 95 | W19: =(U19-T19)*24*60 -> 29 | AF19: =N19-K19 -> -334.55172 | AG19: =N19/K19 -> 0.84204357
W20: =(U20-T20)*24*60 -> 0
W21: =(U21-T21)*24*60 -> 0
W22: 0
W23: =(U23-T23)*24*60 -> 0
H24: =F24*G24 -> 0 | W24: =(U24-T24)*24*60 -> 0
H25: =F25*G25 -> 0 | W25: =(U25-T25)*24*60 -> 0
C26: 4度二組A | D26: 平均 | J26: =AVERAGE(J16:J25) -> 12.25 | K26: =AVERAGE(K16:K25) -> 2038.5 | L26: =AVERAGE(L16:L25) -> 170.39773 | M26: =AVERAGE(M16:M25) -> 12.25 | N26: =AVERAGE(N16:N25) -> 1748.4857 | O26: =AVERAGE(O16:O25) -> 147.61267 | P26: =M26-J26 -> 0 | Q26: =O26-L26 -> -22.785061 | R26: =O26/L26 -> 0.86628307 | Z26: =SUM(Z16:Z25) -> 0 | AA26: =SUM(AA16:AA25) -> 0 | AD26: =SUM(AD16:AD25) -> 0 | AE26: =SUM(AE16:AE25) -> 0 | AF26: =N26-K26 -> -290.01432 | AG26: =N26/K26 -> 0.85773151
A27: 手工三線 (ET-55) | B27: 義大利麵 | D27: 濃拿坡里義大利麵 | F27: =VLOOKUP(D27,廠價表!$C$1:$E$43,3,0) -> 56.43 | G27: 1164 | H27: =F27*G27 -> 65684.52 | J27: =VLOOKUP(D27,產線配置圖!$A$3:$C$38,2,0) -> 16 | K27: =VLOOKUP(D27,產線配置圖!$A$3:$C$38,3,0) -> 1406 | L27: =K27/J27 -> 87.875 | M27: 15 | N27: =G27/W27*60 -> 1027.0588 | O27: =N27/M27 -> 68.470588 | P27: =M27-J27 -> -1 | Q27: =O27-L27 -> -19.404412 | R27: =O27/L27 -> 0.77918166 | S27: =R37 -> 0.80392545 | T27: 0.3125 | U27: 0.35972222 | W27: =(U27-T27)*24*60 -> 68 | Z27: 1 | AA27: 10 | AB27: L型封膜異常 | AF27: =N27-K27 -> -378.94118 | AG27: =N27/K27 -> 0.7304828 | AH27: =AG37 -> 0.76248144
B28: 義大利麵 | D28: 焗烤起司肉醬筆尖麵 | F28: =VLOOKUP(D28,廠價表!$C$1:$E$43,3,0) -> 50.67 | G28: 1327 | H28: =F28*G28 -> 67239.09 | J28: =VLOOKUP(D28,產線配置圖!$A$3:$C$38,2,0) -> 13 | K28: =VLOOKUP(D28,產線配置圖!$A$3:$C$38,3,0) -> 1440 | L28: =K28/J28 -> 110.76923 | M28: 13 | N28: =G28/W28*60 -> 982.96296 | O28: =N28/M28 -> 75.612536 | P28: =M28-J28 -> 0 | Q28: =O28-L28 -> -35.156695 | R28: =O28/L28 -> 0.68261317 | T28: 0.36805556 | U28: 0.42430556 | V28: =(T28-U27)*24*60 -> 12 | W28: =(U28-T28)*24*60 -> 81 | Z28: 1 | AA28: 10 | AB28: L型封膜異常 | AF28: =N28-K28 -> -457.03704 | AG28: =N28/K28 -> 0.68261317
B29: 熱乾麵 | D29: 沙茶豬肉炒麵 | F29: =VLOOKUP(D29,廠價表!$C$1:$E$43,3,0) -> 49.52 | G29: 891 | H29: =F29*G29 -> 44122.32 | J29: =VLOOKUP(D29,產線配置圖!$A$3:$C$38,2,0) -> 17 | K29: =VLOOKUP(D29,產線配置圖!$A$3:$C$38,3,0) -> 1440 | L29: =K29/J29 -> 84.705882 | M29: 15 | N29: =G29/W29*60 -> 1188 | O29: =N29/M29 -> 79.2 | P29: =M29-J29 -> -2 | Q29: =O29-L29 -> -5.5058824 | R29: =O29/L29 -> 0.935 | T29: 0.43055556 | U29: 0.46180556 | V29: =(T29-U28)*24*60 -> 9 | W29: =(U29-T29)*24*60 -> 45 | AF29: =N29-K29 -> -252 | AG29: =N29/K29 -> 0.825
B30: 義大利麵 | D30: 焗烤起司肉醬筆尖麵 | F30: =VLOOKUP(D30,廠價表!$C$1:$E$43,3,0) -> 50.67 | G30: 792 | H30: =F30*G30 -> 40130.64 | J30: =VLOOKUP(D30,產線配置圖!$A$3:$C$38,2,0) -> 13 | K30: =VLOOKUP(D30,產線配置圖!$A$3:$C$38,3,0) -> 1440 | L30: =K30/J30 -> 110.76923 | M30: 13 | N30: =G30/W30*60 -> 1033.0435 | O30: =N30/M30 -> 79.464883 | P30: =M30-J30 -> 0 | Q30: =O30-L30 -> -31.304348 | R30: =O30/L30 -> 0.7173913 | T30: 0.52430556 | U30: 0.55625 | V30: =(T30-U29)*24*60 -> 90 | W30: =(U30-T30)*24*60 -> 46 | X30: 0.49652778 | Y30: 0.53819444 | AB30: L型封膜異常 | AF30: =N30-K30 -> -406.95652 | AG30: =N30/K30 -> 0.7173913
B31: 熱乾麵 | D31: 沙茶豬肉炒麵 | F31: =VLOOKUP(D31,廠價表!$C$1:$E$43,3,0) -> 49.52 | G31: 1500 | H31: =F31*G31 -> 74280 | J31: =VLOOKUP(D31,產線配置圖!$A$3:$C$38,2,0) -> 17 | K31: =VLOOKUP(D31,產線配置圖!$A$3:$C$38,3,0) -> 1440 | L31: =K31/J31 -> 84.705882 | M31: 15 | N31: =G31/W31*60 -> 1232.8767 | O31: =N31/M31 -> 82.191781 | P31: =M31-J31 -> -2 | Q31: =O31-L31 -> -2.5141015 | R31: =O31/L31 -> 0.97031963 | T31: 0.5625 | U31: 0.61319444 | V31: =(T31-U30)*24*60 -> 9 | W31: =(U31-T31)*24*60 -> 73 | AF31: =N31-K31 -> -207.12329 | AG31: =N31/K31 -> 0.85616438
W32: =(U32-T32)*24*60 -> 0
W33: =(U33-T33)*24*60 -> 0
W34: =(U34-T34)*24*60 -> 0
W35: =(U35-T35)*24*60 -> 0
H36: =F36*G36 -> 0 | W36: =(U36-T36)*24*60 -> 0
C37: 4度二組B | D37: 平均 | J37: =AVERAGE(J27:J36) -> 15.2 | K37: =AVERAGE(K27:K36) -> 1433.2 | L37: =AVERAGE(L27:L36) -> 95.765045 | M37: =AVERAGE(M27:M36) -> 14.2 | N37: =AVERAGE(N27:N36) -> 1092.7884 | O37: =AVERAGE(O27:O36) -> 76.987958 | P37: =M37-J37 -> -1 | Q37: =N37-K37 -> -340.4116 | R37: =O37/L37 -> 0.80392545 | Z37: =SUM(Z27:Z36) -> 2 | AA37: =SUM(AA27:AA36) -> 20 | AD37: =SUM(AD27:AD36) -> 0 | AE37: =SUM(AE27:AE36) -> 0 | AF37: =N37-K37 -> -340.4116 | AG37: =N37/K37 -> 0.76248144
A38: 手工四線 (ET-55) | B38: 熱乾麵 | D38: 青花椒麻雞肉拌麵 | F38: =VLOOKUP(D38,廠價表!$C$1:$E$43,3,0) -> 49.91 | G38: 2516 | H38: =F38*G38 -> 125573.56 | J38: =VLOOKUP(D38,產線配置圖!$A$3:$C$38,2,0) -> 15 | K38: =VLOOKUP(D38,產線配置圖!$A$3:$C$38,3,0) -> 1714 | L38: =K38/J38 -> 114.26667 | M38: 15 | N38: =G38/W38*60 -> 1509.6 | O38: =N38/M38 -> 100.64 | P38: =M38-J38 -> 0 | Q38: =O38-L38 -> -13.626667 | R38: =O38/L38 -> 0.88074679 | S38: =R48 -> 0.90019486 | T38: 0.33333333 | U38: 0.40277778 | W38: =(U38-T38)*24*60 -> 100 | AF38: =N38-K38 -> -204.4 | AG38: =N38/K38 -> 0.88074679 | AH38: =AG48 -> 0.86879739
B39: 熱乾麵 | D39: 府城鹽水意麵 | F39: =VLOOKUP(D39,廠價表!$C$1:$E$43,3,0) -> 44.3 | G39: 2562 | H39: =F39*G39 -> 113496.6 | J39: =VLOOKUP(D39,產線配置圖!$A$3:$C$38,2,0) -> 18 | K39: =VLOOKUP(D39,產線配置圖!$A$3:$C$38,3,0) -> 1565 | L39: =K39/J39 -> 86.944444 | M39: 17 | N39: =G39/W39*60 -> 1397.4545 | O39: =N39/M39 -> 82.203209 | P39: =M39-J39 -> -1 | Q39: =O39-L39 -> -4.7412359 | R39: =O39/L39 -> 0.94546821 | T39: 0.41111111 | U39: 0.4875 | V39: =(T39-U38)*24*60 -> 12 | W39: =(U39-T39)*24*60 -> 110 | AF39: =N39-K39 -> -167.54545 | AG39: =N39/K39 -> 0.8929422
B40: 熱乾麵 | D40: 府城鹽水意麵 | F40: =VLOOKUP(D40,廠價表!$C$1:$E$43,3,0) -> 44.3 | G40: 2169 | H40: =F40*G40 -> 96086.7 | J40: =VLOOKUP(D40,產線配置圖!$A$3:$C$38,2,0) -> 18 | K40: =VLOOKUP(D40,產線配置圖!$A$3:$C$38,3,0) -> 1565 | L40: =K40/J40 -> 86.944444 | M40: 17 | N40: =G40/W40*60 -> 1301.4 | O40: =N40/M40 -> 76.552941 | P40: =M40-J40 -> -1 | Q40: =O40-L40 -> -10.391503 | R40: =O40/L40 -> 0.88048111 | T40: 0.54513889 | U40: 0.61458333 | V40: =(T40-U39)*24*60 -> 83 | W40: =(U40-T40)*24*60 -> 100 | AF40: =N40-K40 -> -263.6 | AG40: =N40/K40 -> 0.8315655
...

Sheet 0403總
B1: 長家廠組合室生產人時性分析
B3: 日期 | D3: 46115 | F3: 訂單量 | G3: ='0403'!E1 -> 43154 | I3: 營業額 | J3: ='0403'!G1 -> 2050535.5
B4: 項目 | D4: 3 | F4: ➀ | H4: ➁ | J4: ③ | L4: 異常停線 | N4: 短暫停線
B5: 人時性 | D5: 組合室 | F5: 全溫層 | H5: 義大利麵 | J5: 袋裝小吃、義麵 | L5: 合計次數 | M5: 時間 | N5: 合計次數 | O5: 設備次數
D6: 排關平均 | F6: =AVERAGE(D13:I13) -> 131.20662 | H6: =AVERAGE(D13:H13) -> 126.7301 | J6: =AVERAGE(I13) -> 153.58921 | L6: =SUM(D18:J18) -> 4 | M6: =SUM(D19:J19) -> 17 | N6: =SUM(D20:J20) -> 0 | O6: =SUM(D20:J20) -> 0
D7: 實績平均 | F7: =AVERAGE(D14:I14) -> 110.42054 | H7: =AVERAGE(D14:H14) -> 110.26536 | J7: =AVERAGE(I14) -> 111.1964 | L7: =AVERAGE(K14:L14) -> #DIV/0! | M7: =AVERAGE(L14:M14) -> #DIV/0! | N7: =AVERAGE(M14:N14) -> #DIV/0! | O7: =AVERAGE(N14:O14) -> #DIV/0!
D8: 達成率平均 | F8: =F7/F6 -> 0.84157749 | H8: =H7/H6 -> 0.87008029 | J8: =J7/J6 -> 0.72398578 | L8: =AVERAGE(K15:L15) -> #DIV/0! | M8: =AVERAGE(L15:M15) -> #DIV/0! | N8: =AVERAGE(M15:N15) -> #DIV/0! | O8: =AVERAGE(N15:O15) -> #DIV/0!
J9: ※現行日本鮮食廠以達成率80%為基本(即為現行KPI)
B10: 溫層 | D10: 4度C-各編組展開
B11: 編組 | D11: 1 | E11: 2 | F11: 3 | G11: 4 | H11: 5 | I11: 6 | J11: 7
D12: 自動1線 | E12: 自動2線 | F12: 手工3線 | G12: 手工4線 | H12: 手工5線 | I12: 調理包1線 | J12: 調理包2線
B13: 人時性 | C13: 排關 | D13: =VALUE('0403'!L15) -> 157.1044 | E13: =VALUE('0403'!L26) -> 170.39773 | F13: =VALUE('0403'!L37) -> 95.765045 | G13: =VALUE('0403'!L48) -> 100.60556 | H13: =VALUE('0403'!L58) -> 109.77778 | I13: =VALUE('0403'!L69) -> 153.58921 | J13: ='0403'!L79 -> 0
C14: 實績 | D14: =VALUE('0403'!O15) -> 143.16145 | E14: =VALUE('0403'!O26) -> 143.58312 | F14: =VALUE('0403'!O37) -> 66.581404 | G14: =VALUE('0403'!O48) -> 90.403801 | H14: =VALUE('0403'!O58) -> 107.59704 | I14: =VALUE('0403'!O69) -> 111.1964 | J14: ='0403'!O79 -> 0
C15: 達成率 | D15: =D14/D13 -> 0.91125047 | E15: =E14/E13 -> 0.84263516 | F15: =F14/F13 -> 0.6952579 | G15: =G14/G13 -> 0.89859651 | H15: =H14/H13 -> 0.98013496 | I15: =I14/I13 -> 0.72398578 | J15: ='0403'!S70 -> 0
B16: 作業 時間 | C16: 開始 | D16: ='0403'!T5 -> 0.29166667 | E16: ='0403'!T16 -> 0.29236111 | F16: ='0403'!T27 -> 0.29930556 | G16: ='0403'!T38 -> 0.33333333 | H16: ='0403'!T49 -> 0.29166667 | I16: ='0403'!T59 -> 0.29166667 | J16: ='0403'!T70 -> 0
C17: 結束 | D17: 0.49305556 | E17: 0.56666667 | F17: 0.625 | G17: 0.49305556 | H17: 0.64583333 | I17: 0.58333333 | J17: 0
B18: 產線異常 (5分鐘以上) | C18: 次數 | D18: ='0403'!Z15 -> 0 | E18: ='0403'!Z26 -> 0 | F18: ='0403'!Z37 -> 4 | G18: ='0403'!Z48 -> 0 | H18: ='0403'!Z58 -> 0 | I18: ='0403'!Z69 -> 0 | J18: ='0403'!AA79 -> 0
C19: 時間/分 | D19: ='0403'!AA15 -> 0 | E19: ='0403'!AA26 -> 0 | F19: ='0403'!AA37 -> 17 | G19: ='0403'!AA48 -> 0 | H19: ='0403'!AA58 -> 0 | I19: ='0403'!AA69 -> 0 | J19: ='0403'!AB79 -> 0
B20: 短暫停線 (5分鐘以下) | C20: 次數 | D20: ='0403'!AD15 -> 0 | E20: ='0403'!AD26 -> 0 | F20: ='0403'!AD37 -> 0 | G20: ='0403'!AD48 -> 0 | H20: ='0403'!AD58 -> 0 | I20: ='0403'!AD69 -> 0 | J20: ='0403'!AD79 -> 0
C21: 設備次數 | D21: ='0403'!AE15 -> 0 | E21: ='0403'!AE26 -> 0 | F21: ='0403'!AE37 -> 0 | G21: ='0403'!AE48 -> 0 | H21: ='0403'!AE58 -> 0 | I21: ='0403'!AE69 -> 0 | J21: ='0403'!AE79 -> 0
B22: 配置人數 | D22: =VALUE('0403'!M15) -> 13 | E22: =VALUE('0403'!M26) -> 12.25 | F22: =VALUE('0403'!M37) -> 14 | G22: =VALUE('0403'!M48) -> 16 | H22: =VALUE('0403'!M58) -> 15 | I22: =VALUE('0403'!M69) -> 11.5 | J22: ='0403'!M79 -> 0
B23: 主要應用設備 | D23: ET-600 | E23: ET-600 | F23: ET-55 | G23: ET-55 | H23: ET-55 | I23: 八爪機 | J23: 八爪機
B24: 次要應用設備 | H24: 封口機 | J24: 封口機
B25: 備註

Sheet 0403
A1: 長家廠4度C日報分析 | D1: 總生產量 | E1: =SUM(G5:G79) -> 43154 | F1: 營業額 | G1: =SUM(H5:H79) -> 2050535.5 | H1: 出勤人數 | I1: =M15+M26+M48+M58+M69+M79+M37 -> 81.75 | J1: 產線配置圖 | M1: 生產實績 | P1: 人時性差異分析 | T1: 日報登錄 | Z1: 合計 次數 | AA1: 合計 時間/分 | AB1: 分析說明 | AD1: 合計 次數 | AE1: 合計 設備次數 | AF1: 產能差異分析
A2: 04月03日 星期五 | D2: 人時性 | E2: =AVERAGE(O15,O26,O37,O48,O58,O69,O79) -> 110.42054 | F2: 平均廠價 | G2: =G1/E1 -> 47.516696 | H2: 多次生產數 | I2: =COUNT(I5:I79) -> 0 | Z2: =Z15+Z26+Z37+Z48+Z58+Z69+Z79 -> 4 | AA2: =AA15+AA26+AA37+AA48+AA58+AA69+AA79 -> 17 | AD2: =AD15+AD26+AD37+AD48+AD58+AD69+AD79 -> 0 | AE2: =AE15+AE26+AE37+AE48+AE58+AE69+AE79 -> 0
A3: 線別 | B3: 品類 | D3: 品名 | F3: 廠價 | G3: 生產量 | H3: 營收 | I3: 多次 生產 | J3: 人數 | K3: 產能/時 | L3: 人時性 | M3: 人數 | N3: 產能/時 | O3: 人時性 | P3: 人數 | Q3: 人時性 | R3: 達成率 | S3: 達成率平均 | T3: 生產時間 | V3: 前置、換線時間/分 | W3: 稼動時間/分 | X3: 休息時間 | Z3: 產線異常統計 (5分鐘以上) | AD3: 短暫停線統計 (5分鐘以下) | AF3: 產能/時 | AG3: 達成率 | AH3: 達成率平均
T4: 開始 | U4: 結束 | X4: 開始 | Y4: 結束 | Z4: 次數 | AA4: 時間/分 | AD4: 總次數 | AE4: 設備因素(次數)
A5: 自動一線 (ET-600) | B5: 義大利麵 | D5: 蒜香奶油蝦蝦義大利麵 | F5: =VLOOKUP(D5,廠價表!$C$1:$E$43,3,0) -> 57.21 | G5: 3182 | H5: =F5*G5 -> 182042.22 | J5: =VLOOKUP(D5,產線配置圖!$A$3:$C$38,2,0) -> 14 | K5: =VLOOKUP(D5,產線配置圖!$A$3:$C$38,3,0) -> 2118 | L5: =K5/J5 -> 151.28571 | M5: 13 | N5: =G5/W5*60 -> 1835.7692 | O5: =N5/M5 -> 141.21302 | P5: =M5-J5 -> -1 | Q5: =O5-L5 -> -10.072697 | R5: =O5/L5 -> 0.93341938 | S5: =R15 -> 0.91125047 | T5: 0.29166667 | U5: 0.36388889 | W5: =(U5-T5)*24*60 -> 104 | AF5: =N5-K5 -> -282.23077 | AG5: =N5/K5 -> 0.86674657 | AH5: =AG15 -> 0.87870581
B6: 義大利麵 | D6: 奶油培根義大利麵 | F6: =VLOOKUP(D6,廠價表!$C$1:$E$43,3,0) -> 49.14 | G6: 5282 | H6: =F6*G6 -> 259557.48 | J6: =VLOOKUP(D6,產線配置圖!$A$3:$C$38,2,0) -> 13 | K6: =VLOOKUP(D6,產線配置圖!$A$3:$C$38,3,0) -> 2118 | L6: =K6/J6 -> 162.92308 | M6: 13 | N6: =G6/W6*60 -> 1886.4286 | O6: =N6/M6 -> 145.10989 | P6: =M6-J6 -> 0 | Q6: =O6-L6 -> -17.813187 | R6: =O6/L6 -> 0.89066505 | T6: 0.37638889 | U6: 0.49305556 | V6: =(T6-U5)*24*60 -> 18 | W6: =(U6-T6)*24*60 -> 168 | AF6: =N6-K6 -> -231.57143 | AG6: =N6/K6 -> 0.89066505
W7: =(U7-T7)*24*60 -> 0 | AF7: =N7-K7 -> 0 | AG7: =N7/K7 -> #DIV/0!
W8: =(U8-T8)*24*60 -> 0 | X8: 0.48611111 | Y8: 0.52777778 | AF8: =N8-K8 -> 0 | AG8: =N8/K8 -> #DIV/0!
W9: =(U9-T9)*24*60 -> 0 | AF9: =N9-K9 -> 0 | AG9: =N9/K9 -> #DIV/0!
W10: =(U10-T10)*24*60 -> 0 | AF10: =N10-K10 -> 0 | AG10: =N10/K10 -> #DIV/0!
W11: =(U11-T11)*24*60 -> 0 | AF11: =N11-K11 -> 0 | AG11: =N11/K11 -> #DIV/0!
W12: =(U12-T12)*24*60 -> 0
W13: =(U13-T13)*24*60 -> 0
W14: =(U14-T14)*24*60 -> 0
C15: 4度一組 | D15: 平均 | J15: =AVERAGE(J5:J14) -> 13.5 | K15: =AVERAGE(K5:K14) -> 2118 | L15: =AVERAGE(L5:L14) -> 157.1044 | M15: =AVERAGE(M5:M14) -> 13 | N15: =AVERAGE(N5:N14) -> 1861.0989 | O15: =AVERAGE(O5:O14) -> 143.16145 | P15: =M15-J15 -> -0.5 | Q15: =O15-L15 -> -13.942942 | R15: =O15/L15 -> 0.91125047 | Z15: =SUM(Z5:Z14) -> 0 | AA15: =SUM(AA5:AA14) -> 0 | AD15: =SUM(AD5:AD14) -> 0 | AE15: =SUM(AE5:AE14) -> 0 | AF15: =N15-K15 -> -256.9011 | AG15: =N15/K15 -> 0.87870581
A16: 自動二線 (ET-600) | B16: 義大利麵 | D16: 辣味香菜雞肉義大利麵 | F16: =VLOOKUP(D16,廠價表!$C$1:$E$43,3,0) -> 56.28 | G16: 729 | H16: =F16*G16 -> 41028.12 | J16: =VLOOKUP(D16,產線配置圖!$A$3:$C$38,2,0) -> 15 | K16: =VLOOKUP(D16,產線配置圖!$A$3:$C$38,3,0) -> 1800 | L16: =K16/J16 -> 120 | M16: 15 | N16: =G16/W16*60 -> 1041.4286 | O16: =N16/M16 -> 69.428571 | P16: =M16-J16 -> 0 | Q16: =O16-L16 -> -50.571429 | R16: =O16/L16 -> 0.57857143 | S16: =R26 -> 0.84263516 | T16: 0.29236111 | U16: 0.32152778 | W16: =(U16-T16)*24*60 -> 42 | AB16: 生產數量少 | AF16: =N16-K16 -> -758.57143 | AG16: =N16/K16 -> 0.57857143 | AH16: =AG26 -> 0.82920331
B17: 義大利麵 | D17: 青醬蛤蜊義大利麵 | F17: =VLOOKUP(D17,廠價表!$C$1:$E$43,3,0) -> 50.67 | G17: 3485 | H17: =F17*G17 -> 176584.95 | J17: =VLOOKUP(D17,產線配置圖!$A$3:$C$38,2,0) -> 12 | K17: =VLOOKUP(D17,產線配置圖!$A$3:$C$38,3,0) -> 2118 | L17: =K17/J17 -> 176.5 | M17: 12 | N17: =G17/W17*60 -> 1991.4286 | O17: =N17/M17 -> 165.95238 | P17: =M17-J17 -> 0 | Q17: =O17-L17 -> -10.547619 | R17: =O17/L17 -> 0.94024012 | T17: 0.32777778 | U17: 0.40069444 | V17: =(T17-U16)*24*60 -> 9 | W17: =(U17-T17)*24*60 -> 105 | AF17: =N17-K17 -> -126.57143 | AG17: =N17/K17 -> 0.94024012
B18: 義大利麵 | D18: 義式蕃茄起司義大利麵 | F18: =VLOOKUP(D18,廠價表!$C$1:$E$43,3,0) -> 50.39 | G18: 3228 | H18: =F18*G18 -> 162658.92 | J18: =VLOOKUP(D18,產線配置圖!$A$3:$C$38,2,0) -> 11 | K18: =VLOOKUP(D18,產線配置圖!$A$3:$C$38,3,0) -> 2118 | L18: =K18/J18 -> 192.54545 | M18: 11 | N18: =G18/W18*60 -> 1936.8 | O18: =N18/M18 -> 176.07273 | P18: =M18-J18 -> 0 | Q18: =O18-L18 -> -16.472727 | R18: =O18/L18 -> 0.91444759 | T18: 0.40972222 | U18: 0.47916667 | V18: =(T18-U17)*24*60 -> 13 | W18: =(U18-T18)*24*60 -> 100 | X18: 0.48611111 | Y18: 0.52777778 | AF18: =N18-K18 -> -181.2 | AG18: =N18/K18 -> 0.91444759
B19: 義大利麵 | D19: 義式蕃茄起司義大利麵 | F19: =VLOOKUP(D19,廠價表!$C$1:$E$43,3,0) -> 50.39 | G19: 1075 | H19: =F19*G19 -> 54169.25 | J19: =VLOOKUP(D19,產線配置圖!$A$3:$C$38,2,0) -> 11 | K19: =VLOOKUP(D19,產線配置圖!$A$3:$C$38,3,0) -> 2118 | L19: =K19/J19 -> 192.54545 | M19: 11 | N19: =G19/W19*60 -> 1791.6667 | O19: =N19/M19 -> 162.87879 | P19: =M19-J19 -> 0 | Q19: =O19-L19 -> -29.666667 | R19: =O19/L19 -> 0.84592383 | T19: 0.54166667 | U19: 0.56666667 | V19: =(T19-U18)*24*60 -> 90 | W19: =(U19-T19)*24*60 -> 36 | AF19: =N19-K19 -> -326.33333 | AG19: =N19/K19 -> 0.84592383
W20: =(U20-T20)*24*60 -> 0
W21: =(U21-T21)*24*60 -> 0
W22: 0
W23: =(U23-T23)*24*60 -> 0
H24: =F24*G24 -> 0 | W24: =(U24-T24)*24*60 -> 0
H25: =F25*G25 -> 0 | W25: =(U25-T25)*24*60 -> 0
C26: 4度二組A | D26: 平均 | J26: =AVERAGE(J16:J25) -> 12.25 | K26: =AVERAGE(K16:K25) -> 2038.5 | L26: =AVERAGE(L16:L25) -> 170.39773 | M26: =AVERAGE(M16:M25) -> 12.25 | N26: =AVERAGE(N16:N25) -> 1690.331 | O26: =AVERAGE(O16:O25) -> 143.58312 | P26: =M26-J26 -> 0 | Q26: =O26-L26 -> -26.81461 | R26: =O26/L26 -> 0.84263516 | Z26: =SUM(Z16:Z25) -> 0 | AA26: =SUM(AA16:AA25) -> 0 | AD26: =SUM(AD16:AD25) -> 0 | AE26: =SUM(AE16:AE25) -> 0 | AF26: =N26-K26 -> -348.16905 | AG26: =N26/K26 -> 0.82920331
A27: 手工三線 (ET-55) | B27: 義大利麵 | D27: 濃拿坡里義大利麵 | F27: =VLOOKUP(D27,廠價表!$C$1:$E$43,3,0) -> 56.43 | G27: 1150 | H27: =F27*G27 -> 64894.5 | J27: =VLOOKUP(D27,產線配置圖!$A$3:$C$38,2,0) -> 16 | K27: =VLOOKUP(D27,產線配置圖!$A$3:$C$38,3,0) -> 1406 | L27: =K27/J27 -> 87.875 | M27: 14 | N27: =G27/W27*60 -> 1029.8507 | O27: =N27/M27 -> 73.560768 | P27: =M27-J27 -> -2 | Q27: =O27-L27 -> -14.314232 | R27: =O27/L27 -> 0.83710689 | S27: =R37 -> 0.6952579 | T27: 0.29930556 | U27: 0.34583333 | W27: =(U27-T27)*24*60 -> 67 | AF27: =N27-K27 -> -376.14925 | AG27: =N27/K27 -> 0.73246853 | AH27: =AG37 -> 0.65387872
B28: 義大利麵 | D28: 焗烤起司肉醬筆尖麵 | F28: =VLOOKUP(D28,廠價表!$C$1:$E$43,3,0) -> 50.67 | G28: 1316 | H28: =F28*G28 -> 66681.72 | J28: =VLOOKUP(D28,產線配置圖!$A$3:$C$38,2,0) -> 13 | K28: =VLOOKUP(D28,產線配置圖!$A$3:$C$38,3,0) -> 1440 | L28: =K28/J28 -> 110.76923 | M28: 13 | N28: =G28/W28*60 -> 560 | O28: =N28/M28 -> 43.076923 | P28: =M28-J28 -> 0 | Q28: =O28-L28 -> -67.692308 | R28: =O28/L28 -> 0.38888889 | T28: 0.35277778 | U28: 0.45069444 | V28: =(T28-U27)*24*60 -> 10 | W28: =(U28-T28)*24*60 -> 141 | AB28: 9:45-10:49封膜異常全檢 | AF28: =N28-K28 -> -880 | AG28: =N28/K28 -> 0.38888889
B29: 熱乾麵 | D29: 沙茶豬肉炒麵 | F29: =VLOOKUP(D29,廠價表!$C$1:$E$43,3,0) -> 49.52 | G29: 1196 | H29: =F29*G29 -> 59225.92 | J29: =VLOOKUP(D29,產線配置圖!$A$3:$C$38,2,0) -> 17 | K29: =VLOOKUP(D29,產線配置圖!$A$3:$C$38,3,0) -> 1440 | L29: =K29/J29 -> 84.705882 | M29: 15 | N29: =G29/W29*60 -> 1104 | O29: =N29/M29 -> 73.6 | P29: =M29-J29 -> -2 | Q29: =O29-L29 -> -11.105882 | R29: =O29/L29 -> 0.86888889 | T29: 0.42361111 | U29: 0.46875 | V29: =(T29-U28)*24*60 -> -39 | W29: =(U29-T29)*24*60 -> 65 | AB29: 沙茶先開線 | AF29: =N29-K29 -> -336 | AG29: =N29/K29 -> 0.76666667
B30: 義大利麵 | D30: 焗烤起司肉醬筆尖麵 | F30: =VLOOKUP(D30,廠價表!$C$1:$E$43,3,0) -> 50.67 | G30: 883 | H30: =F30*G30 -> 44741.61 | J30: =VLOOKUP(D30,產線配置圖!$A$3:$C$38,2,0) -> 13 | K30: =VLOOKUP(D30,產線配置圖!$A$3:$C$38,3,0) -> 1440 | L30: =K30/J30 -> 110.76923 | M30: 13 | N30: =G30/W30*60 -> 963.27273 | O30: =N30/M30 -> 74.097902 | P30: =M30-J30 -> 0 | Q30: =O30-L30 -> -36.671329 | R30: =O30/L30 -> 0.66893939 | T30: 0.53125 | U30: 0.56944444 | V30: =(T30-U29)*24*60 -> 90 | W30: =(U30-T30)*24*60 -> 55 | X30: 0.49652778 | Y30: 0.53819444 | Z30: 4 | AA30: 17 | AB30: L型封膜異常 | AF30: =N30-K30 -> -476.72727 | AG30: =N30/K30 -> 0.66893939
B31: 熱乾麵 | D31: 沙茶豬肉炒麵 | F31: =VLOOKUP(D31,廠價表!$C$1:$E$43,3,0) -> 49.52 | G31: 1200 | H31: =F31*G31 -> 59424 | J31: =VLOOKUP(D31,產線配置圖!$A$3:$C$38,2,0) -> 17 | K31: =VLOOKUP(D31,產線配置圖!$A$3:$C$38,3,0) -> 1440 | L31: =K31/J31 -> 84.705882 | M31: 15 | N31: =G31/W31*60 -> 1028.5714 | O31: =N31/M31 -> 68.571429 | P31: =M31-J31 -> -2 | Q31: =O31-L31 -> -16.134454 | R31: =O31/L31 -> 0.80952381 | T31: 0.57638889 | U31: 0.625 | V31: =(T31-U30)*24*60 -> 10 | W31: =(U31-T31)*24*60 -> 70 | AF31: =N31-K31 -> -411.42857 | AG31: =N31/K31 -> 0.71428571
W32: =(U32-T32)*24*60 -> 0
W33: =(U33-T33)*24*60 -> 0
W34: =(U34-T34)*24*60 -> 0
W35: =(U35-T35)*24*60 -> 0
H36: =F36*G36 -> 0 | W36: =(U36-T36)*24*60 -> 0
C37: 4度二組B | D37: 平均 | J37: =AVERAGE(J27:J36) -> 15.2 | K37: =AVERAGE(K27:K36) -> 1433.2 | L37: =AVERAGE(L27:L36) -> 95.765045 | M37: =AVERAGE(M27:M36) -> 14 | N37: =AVERAGE(N27:N36) -> 937.13898 | O37: =AVERAGE(O27:O36) -> 66.581404 | P37: =M37-J37 -> -1.2 | Q37: =N37-K37 -> -496.06102 | R37: =O37/L37 -> 0.6952579 | Z37: =SUM(Z27:Z36) -> 4 | AA37: =SUM(AA27:AA36) -> 17 | AD37: =SUM(AD27:AD36) -> 0 | AE37: =SUM(AE27:AE36) -> 0 | AF37: =N37-K37 -> -496.06102 | AG37: =N37/K37 -> 0.65387872
A38: 手工四線 (ET-55) | B38: 熱乾麵 | D38: 青花椒麻雞肉拌麵 | F38: =VLOOKUP(D38,廠價表!$C$1:$E$43,3,0) -> 49.91 | G38: 2609 | H38: =F38*G38 -> 130215.19 | J38: =VLOOKUP(D38,產線配置圖!$A$3:$C$38,2,0) -> 15 | K38: =VLOOKUP(D38,產線配置圖!$A$3:$C$38,3,0) -> 1714 | L38: =K38/J38 -> 114.26667 | M38: 15 | N38: =G38/W38*60 -> 1423.0909 | O38: =N38/M38 -> 94.872727 | P38: =M38-J38 -> 0 | Q38: =O38-L38 -> -19.393939 | R38: =O38/L38 -> 0.83027474 | S38: =R48 -> 0.89859651 | T38: 0.33333333 | U38: 0.40972222 | W38: =(U38-T38)*24*60 -> 110 | AF38: =N38-K38 -> -290.90909 | AG38: =N38/K38 -> 0.83027474 | AH38: =AG48 -> 0.87953149
B39: 熱乾麵 | D39: 府城鹽水意麵 | F39: =VLOOKUP(D39,廠價表!$C$1:$E$43,3,0) -> 44.3 | G39: 2727 | H39: =F39*G39 -> 120806.1 | J39: =VLOOKUP(D39,產線配置圖!$A$3:$C$38,2,0) -> 18 | K39: =VLOOKUP(D39,產線配置圖!$A$3:$C$38,3,0) -> 1565 | L39: =K39/J39 -> 86.944444 | M39: 17 | N39: =G39/W39*60 -> 1460.8929 | O39: =N39/M39 -> 85.934874 | P39: =M39-J39 -> -1 | Q39: =O39-L39 -> -1.0095705 | R39: =O39/L39 -> 0.98838833 | T39: 0.41527778 | U39: 0.49305556 | V39: =(T39-U38)*24*60 -> 8 | W39: =(U39-T39)*24*60 -> 112 | AF39: =N39-K39 -> -104.10714 | AG39: =N39/K39 -> 0.93347786
W40: =(U40-T40)*24*60 -> 0 | AF40: =N40-K40 -> 0 | AG40: =N40/K40 -> #DIV/0!
...

Sheet 0404總
B1: 長家廠組合室生產人時性分析
B3: 日期 | D3: 46116 | F3: 訂單量 | G3: ='0404'!E1 -> 43984 | I3: 營業額 | J3: ='0404'!G1 -> 2083766.3
B4: 項目 | D4: 3 | F4: ➀ | H4: ➁ | J4: ③ | L4: 異常停線 | N4: 短暫停線
B5: 人時性 | D5: 組合室 | F5: 全溫層 | H5: 義大利麵 | J5: 袋裝小吃、義麵 | L5: 合計次數 | M5: 時間 | N5: 合計次數 | O5: 設備次數
D6: 排關平均 | F6: =AVERAGE(D13:I13) -> 129.64059 | H6: =AVERAGE(D13:H13) -> 126.7301 | J6: =AVERAGE(I13) -> 144.19302 | L6: =SUM(D18:J18) -> 0 | M6: =SUM(D19:J19) -> 0 | N6: =SUM(D20:J20) -> 0 | O6: =SUM(D20:J20) -> 0
D7: 實績平均 | F7: =AVERAGE(D14:I14) -> 116.61973 | H7: =AVERAGE(D14:H14) -> 113.63426 | J7: =AVERAGE(I14) -> 131.54708 | L7: =AVERAGE(K14:L14) -> #DIV/0! | M7: =AVERAGE(L14:M14) -> #DIV/0! | N7: =AVERAGE(M14:N14) -> #DIV/0! | O7: =AVERAGE(N14:O14) -> #DIV/0!
D8: 達成率平均 | F8: =F7/F6 -> 0.89956186 | H8: =H7/H6 -> 0.89666351 | J8: =J7/J6 -> 0.91229855 | L8: =AVERAGE(K15:L15) -> #DIV/0! | M8: =AVERAGE(L15:M15) -> #DIV/0! | N8: =AVERAGE(M15:N15) -> #DIV/0! | O8: =AVERAGE(N15:O15) -> #DIV/0!
J9: ※現行日本鮮食廠以達成率80%為基本(即為現行KPI)
B10: 溫層 | D10: 4度C-各編組展開
B11: 編組 | D11: 1 | E11: 2 | F11: 3 | G11: 4 | H11: 5 | I11: 6 | J11: 7
D12: 自動1線 | E12: 自動2線 | F12: 手工3線 | G12: 手工4線 | H12: 手工5線 | I12: 調理包1線 | J12: 調理包2線
B13: 人時性 | C13: 排關 | D13: =VALUE('0404'!L15) -> 157.1044 | E13: =VALUE('0404'!L26) -> 170.39773 | F13: =VALUE('0404'!L37) -> 95.765045 | G13: =VALUE('0404'!L48) -> 100.60556 | H13: =VALUE('0404'!L58) -> 109.77778 | I13: =VALUE('0404'!L69) -> 144.19302 | J13: ='0404'!L79 -> 0
C14: 實績 | D14: =VALUE('0404'!O15) -> 149.68906 | E14: =VALUE('0404'!O26) -> 150.75449 | F14: =VALUE('0404'!O37) -> 72.907864 | G14: =VALUE('0404'!O48) -> 91.124359 | H14: =VALUE('0404'!O58) -> 103.69551 | I14: =VALUE('0404'!O69) -> 131.54708 | J14: ='0404'!O79 -> 0
