Workbook

Sheet 廠價表
A1: check | B1: 溫層 | C1: 品名 | D1: 類別 | E1: 廠價
B2: 4度C | C2: 白酒蛤蜊義大利麵 | D2: 義大利麵 | E2: 57.21
B3: 4度C | C3: 南洋紅咖哩豬義大利麵 | D3: 義大利麵 | E3: 56.43
B4: 4度C | C4: 義式蕃茄起司義大利麵 | D4: 義大利麵 | E4: 50.39
B5: 4度C | C5: 焗烤起司雙饗筆尖麵 | D5: 義大利麵 | E5: 49.97
B6: 4度C | C6: 奶油培根義大利麵 | D6: 義大利麵 | E6: 49.14
B7: 4度C | C7: 燻火腿貓耳朵麵 | D7: 義大利麵 | E7: 58.17
B8: 4度C | C8: 惡魔乳酪生義大利麵 | D8: 義大利麵 | E8: 57.3
B9: 4度C | C9: 焗烤起司肉醬筆尖麵 | D9: 義大利麵 | E9: 50.67
B10: 4度C | C10: 辣味香菜雞肉義大利麵 | D10: 義大利麵 | E10: 56.28
B11: 4度C | C11: 蒜香奶油蝦蝦義大利麵 | D11: 義大利麵 | E11: 57.21
B12: 4度C | C12: 剝皮辣椒雞奶油扁麵 | D12: 義大利麵 | E12: 56.87
B13: 4度C | C13: 奶油蒜香雞義大利麵 | D13: 義大利麵 | E13: 55.13
... B49: 冷凍 | C49: 辣蕃茄義大利麵 | D49: 冷凍調理麵 | E49: 29.38
B50: 冷凍 | D50: 冷凍調理麵
B51: 冷凍 | C51: 韓式起司義大利麵 | D51: 冷凍調理麵 | E51: 29.38
B52: 冷凍 | D52: 冷凍調理麵
B53: 冷凍 | C53: 和風明太子細扁麵 | D53: 冷凍調理麵 | E53: 29.38

Sheet 產線配置圖
A1: 品項 | B1: 人數 | C1: 產能
A2: 義大利麵
A3: 白酒蛤蜊義大利麵 | B3: 12 | C3: 2105 | D3: ET-600
A4: 白酒蛤蜊義大利麵-手 | B4: 15 | C4: 1565 | D4: ET-55
A5: 青醬蛤蜊義大利麵 | B5: 12 | C5: 2100
A6: 義式蕃茄起司義大利麵 | B6: 11 | C6: 2100
A7: 焗烤起司雙饗筆尖麵 | B7: 16 | C7: 1714
A8: 奶油培根義大利麵 | B8: 13 | C8: 2100
A9: 剝皮辣椒雞奶油扁麵 | B9: 17 | C9: 1565
A10: 青花椒麻雞肉拌麵 | B10: 15 | C10: 1565
A11: 濃拿坡里義大利麵 | B11: 16 | C11: 1406
A12: 奶油起司蝦仁通心粉 | B12: 16 | C12: 1636
A13: 剝皮辣椒雞奶油扁麵-降速生產(3線) | B13: 16 | C13: 1440
A14: 辣味香菜雞肉義大利麵 | B14: 15 | C14: 1800
A15: 惡魔乳酪生義大利麵 | B15: 14 | C15: 1500
A16: 沙茶豬肉炒麵 | B16: 17 | C16: 1440
... A20: 蒜香奶油蝦蝦義大利麵 | B20: 15 | C20: 2000
A24: 調理包
A25: 小滷青蔬 | B25: 13 | C25: 1565
A26: 起司馬鈴薯 | B26: 12 | C26: 1565
A27: 台式綜合甜不辣 | B27: 12 | C27: 1565
A28: 三杯菇菇米血 | B28: 12 | C28: 1565
A29: 麻辣雞心 | B29: 9 | C29: 1636
E32: 更新日期03/04

Sheet 範本總
B1: 長家廠組合室生產人時性分析
B3: 日期 | D3: 46015 | F3: 訂單量 | G3: =範本!E1 -> 43309 | I3: 營業額 | J3: =範本!G1 -> #N/A
B4: 項目 | D4: 3 | F4: ➀ | H4: ➁ | J4: ③ | L4: 異常停線 | N4: 短暫停線
B5: 人時性 | D5: 組合室 | F5: 全溫層 | H5: 義大利麵 | J5: 袋裝小吃、義麵 | L5: 合計次數 | M5: 時間 | N5: 合計次數 | O5: 設備次數
D6: 排關平均 | F6: =AVERAGE(D13:J13) -> #N/A | H6: =AVERAGE(D13:H13) -> #N/A | J6: =AVERAGE(I13:J13) -> #N/A | L6: =範本!Z2 -> 0 | M6: =範本!AA2 -> 0 | N6: =範本!AD2 -> 0 | O6: =範本!AE2 -> 0
D7: 實績平均 | F7: =AVERAGE(D14:J14) -> 116.11475 | H7: =AVERAGE(D14:H14) -> 117.36075 | J7: =AVERAGE(I14:J14) -> 112.99975
D8: 達成率平均 | F8: =AVERAGE(D15:J15) -> #N/A | H8: =AVERAGE(D15:H15) -> #N/A | J8: =AVERAGE(I15:J15) -> #N/A
J9: ※現行日本鮮食廠以達成率80%為基本(即為現行KPI)
B10: 溫層 | D10: 4度C-各編組展開
B11: 編組 | D11: 1 | E11: 2 | F11: 3 | G11: 4 | H11: 5 | I11: 6 | J11: 7
D12: 自動1線 | E12: 自動2線 | F12: 手工3線 | G12: 手工4線 | H12: 手工5線 | I12: 調理包1線 | J12: 調理包2線
B13: 人時性 | C13: 排關 | D13: =VALUE(範本!L15) -> #N/A | E13: =VALUE(範本!L26) -> #N/A | F13: =VALUE(範本!L37) -> #N/A | G13: =VALUE(範本!L48) -> #N/A | H13: =VALUE(範本!L58) -> #N/A | I13: =VALUE(範本!L69) -> #N/A | J13: =範本!L79 -> #N/A
C14: 實績 | D14: =VALUE(範本!O15) -> 113.91637 | E14: =VALUE(範本!O26) -> 132.12003 | F14: =VALUE(範本!O37) -> 126.23842 | G14: =VALUE(範本!O48) -> 112.0543 | H14: =VALUE(範本!O58) -> 102.47462 | I14: =VALUE(範本!O69) -> 155.46443 | J14: =範本!O79 -> 70.535065
C15: 達成率 | D15: =D14/D13 -> #N/A | E15: =E14/E13 -> #N/A | F15: =F14/F13 -> #N/A | G15: =G14/G13 -> #N/A | H15: =H14/H13 -> #N/A | I15: =I14/I13 -> #N/A | J15: =範本!S70 -> #N/A
B16: 作業 時間 | C16: 開始 | D16: =範本!T5 -> 0.29097222 | E16: =範本!T16 -> 0.29097222 | F16: =範本!T27 -> 0.29166667 | G16: =範本!T38 -> 0.33333333 | H16: =範本!T49 -> 0.29166667 | I16: =範本!T59 -> 0.29166667 | J16: =範本!T70 -> 0.34722222
C17: 結束 | D17: 0.47361111 | E17: 0.48263889 | F17: 0.56944444 | G17: 0.60416667 | H17: 0.58333333 | I17: 0.48819444 | J17: 0.46875
B18: 產線異常 (5分鐘以上) | C18: 次數
C19: 時間/分
B20: 短暫停線 (5分鐘以下) | C20: 次數
C21: 設備次數
B22: 配置人數 | D22: =VALUE(範本!M15) -> 15 | E22: =VALUE(範本!M26) -> 12.666667 | F22: =VALUE(範本!M37) -> 14.666667 | G22: =VALUE(範本!M48) -> 14 | H22: =VALUE(範本!M58) -> 17.666667 | I22: =VALUE(範本!M69) -> 12.333333 | J22: =範本!M79 -> 11
B23: 主要應用設備 | D23: ET-600 | E23: ET-600 | F23: ET-55 | G23: ET-55 | H23: ET-55 | I23: 八爪機
B24: 次要應用設備 | H24: 封口機
B25: 備註

Sheet 範本
A1: 長家廠4度C日報分析 | D1: 總生產量 | E1: =SUM(G5:G79) -> 43309 | F1: 營業額 | G1: =SUM(H5:H79) -> #N/A | H1: 出勤人數 | I1: =M15+M26+M48+M58+M69+M79+M37 -> 97.333333 | J1: 產線配置圖 | M1: 生產實績 | P1: 人時性差異分析 | T1: 日報登錄 | Z1: 合計 次數 | AA1: 合計 時間/分 | AB1: 分析說明 | AD1: 合計 次數 | AE1: 合計 設備次數 | AF1: 產能差異分析
A2: 12月24日 星期三 | D2: 人時性 | E2: =AVERAGE(O15,O26,O37,O48,O58,O69,O79) -> 116.11475 | F2: 平均廠價 | G2: =G1/E1 -> #N/A | H2: 多次生產數 | I2: =COUNT(I5:I79) -> 0 | Z2: =Z15+Z26+Z37+Z48+Z58+Z69+Z79 -> 0 | AA2: =AA15+AA26+AA37+AA48+AA58+AA69+AA79 -> 0 | AD2: =AD15+AD26+AD37+AD48+AD58+AD69+AD79 -> 0 | AE2: =AE15+AE26+AE37+AE48+AE58+AE69+AE79 -> 0
A3: 線別 | B3: 品類 | D3: 品名 | F3: 廠價 | G3: 生產量 | H3: 營收 | I3: 多次 生產 | J3: 人數 | K3: 產能/時 | L3: 人時性 | M3: 人數 | N3: 產能/時 | O3: 人時性 | P3: 人數 | Q3: 人時性 | R3: 達成率 | S3: 達成率平均 | T3: 生產時間 | V3: 前置、換線時間/分 | W3: 稼動時間/分 | X3: 休息時間 | Z3: 產線異常統計 (5分鐘以上) | AD3: 短暫停線統計 (5分鐘以下) | AF3: 產能/時 | AG3: 達成率 | AH3: 達成率平均
T4: 開始 | U4: 結束 | X4: 開始 | Y4: 結束 | Z4: 次數 | AA4: 時間/分 | AD4: 總次數 | AE4: 設備因素(次數)
A5: 自動一線 (ET-600) | B5: =VLOOKUP(D5,廠價表!$C$1:$E$41,2,0) -> #N/A | F5: =VLOOKUP(D5,廠價表!$C$1:$E$41,3,0) -> #N/A | G5: 2263 | H5: =F5*G5 -> #N/A | J5: =VLOOKUP(D5,產線配置圖!$A$3:$C$38,2,0) -> #N/A | K5: =VLOOKUP(D5,產線配置圖!$A$3:$C$38,3,0) -> #N/A | L5: =K5/J5 -> #N/A | M5: 15 | N5: =G5/W5*60 -> 1444.4681 | O5: =N5/M5 -> 96.297872 | P5: =M5-J5 -> #N/A | Q5: =O5-L5 -> #N/A | R5: =O5/L5 -> #N/A | S5: =R15 -> #N/A | T5: 0.29097222 | U5: 0.35625 | W5: =(U5-T5)*24*60 -> 94 | AF5: =N5-K5 -> #N/A | AG5: =N5/K5 -> #N/A | AH5: =AG15 -> #N/A
B6: =VLOOKUP(D6,廠價表!$C$1:$E$41,2,0) -> #N/A | F6: =VLOOKUP(D6,廠價表!$C$1:$E$41,3,0) -> #N/A | G6: 1180 | H6: =F6*G6 -> #N/A | J6: =VLOOKUP(D6,產線配置圖!$A$3:$C$38,2,0) -> #N/A | K6: =VLOOKUP(D6,產線配置圖!$A$3:$C$38,3,0) -> #N/A | L6: =K6/J6 -> #N/A | M6: 17 | N6: =G6/W6*60 -> 1609.0909 | O6: =N6/M6 -> 94.652406 | P6: =M6-J6 -> #N/A | Q6: =O6-L6 -> #N/A | R6: =O6/L6 -> #N/A | T6: 0.36458333 | U6: 0.39513889 | V6: =(T6-U5)*24*60 -> 12 | W6: =(U6-T6)*24*60 -> 44 | AF6: =N6-K6 -> #N/A | AG6: =N6/K6 -> #N/A
B7: =VLOOKUP(D7,廠價表!$C$1:$E$41,2,0) -> #N/A | F7: =VLOOKUP(D7,廠價表!$C$1:$E$41,3,0) -> #N/A | G7: 3398 | H7: =F7*G7 -> #N/A | J7: =VLOOKUP(D7,產線配置圖!$A$3:$C$38,2,0) -> #N/A | K7: =VLOOKUP(D7,產線配置圖!$A$3:$C$38,3,0) -> #N/A | L7: =K7/J7 -> #N/A | M7: 13 | N7: =G7/W7*60 -> 1960.3846 | O7: =N7/M7 -> 150.79882 | P7: =M7-J7 -> #N/A | Q7: =O7-L7 -> #N/A | R7: =O7/L7 -> #N/A | T7: 0.40138889 | U7: 0.47361111 | V7: =(T7-U6)*24*60 -> 9 | W7: =(U7-T7)*24*60 -> 104 | AF7: =N7-K7 -> #N/A | AG7: =N7/K7 -> #N/A
W8: =(U8-T8)*24*60 -> 0 | X8: 0.48611111 | Y8: 0.52777778 | AF8: =N8-K8 -> 0 | AG8: =N8/K8 -> #DIV/0!
W9: =(U9-T9)*24*60 -> 0 | AF9: =N9-K9 -> 0 | AG9: =N9/K9 -> #DIV/0!
W10: =(U10-T10)*24*60 -> 0 | AF10: =N10-K10 -> 0 | AG10: =N10/K10 -> #DIV/0!
W11: =(U11-T11)*24*60 -> 0 | AF11: =N11-K11 -> 0 | AG11: =N11/K11 -> #DIV/0!
W12: =(U12-T12)*24*60 -> 0
W13: =(U13-T13)*24*60 -> 0
W14: =(U14-T14)*24*60 -> 0
C15: 4度一組 | D15: 平均 | J15: =AVERAGE(J5:J14) -> #N/A | K15: =AVERAGE(K5:K14) -> #N/A | L15: =AVERAGE(L5:L14) -> #N/A | M15: =AVERAGE(M5:M14) -> 15 | N15: =AVERAGE(N5:N14) -> 1671.3145 | O15: =AVERAGE(O5:O14) -> 113.91637 | P15: =M15-J15 -> #N/A | Q15: =O15-L15 -> #N/A | R15: =O15/L15 -> #N/A | Z15: =SUM(Z5:Z14) -> 0 | AA15: =SUM(AA5:AA14) -> 0 | AD15: =SUM(AD5:AD14) -> 0 | AE15: =SUM(AE5:AE14) -> 0 | AF15: =N15-K15 -> #N/A | AG15: =N15/K15 -> #N/A
A16: 自動二線 (ET-600) | B16: =VLOOKUP(D16,廠價表!$C$1:$E$41,2,0) -> #N/A | F16: =VLOOKUP(D16,廠價表!$C$1:$E$41,3,0) -> #N/A | G16: 2263 | H16: =F16*G16 -> #N/A | J16: =VLOOKUP(D16,產線配置圖!$A$3:$C$38,2,0) -> #N/A | K16: =VLOOKUP(D16,產線配置圖!$A$3:$C$38,3,0) -> #N/A | L16: =K16/J16 -> #N/A | M16: 13 | N16: =G16/W16*60 -> 2225.9016 | O16: =N16/M16 -> 171.2232 | P16: =M16-J16 -> #N/A | Q16: =O16-L16 -> #N/A | R16: =O16/L16 -> #N/A | S16: =R26 -> #N/A | T16: 0.29097222 | U16: 0.33333333 | W16: =(U16-T16)*24*60 -> 61 | AF16: =N16-K16 -> #N/A | AG16: =N16/K16 -> #N/A | AH16: =AG26 -> #N/A
B17: =VLOOKUP(D17,廠價表!$C$1:$E$41,2,0) -> #N/A | F17: =VLOOKUP(D17,廠價表!$C$1:$E$41,3,0) -> #N/A | G17: 1180 | H17: =F17*G17 -> #N/A | J17: =VLOOKUP(D17,產線配置圖!$A$3:$C$38,2,0) -> #N/A | K17: =VLOOKUP(D17,產線配置圖!$A$3:$C$38,3,0) -> #N/A | L17: =K17/J17 -> #N/A | M17: 13 | N17: =G17/W17*60 -> 823.25581 | O17: =N17/M17 -> 63.32737 | P17: =M17-J17 -> #N/A | Q17: =O17-L17 -> #N/A | R17: =O17/L17 -> #N/A | T17: 0.34166667 | U17: 0.40138889 | V17: =(T17-U16)*24*60 -> 12 | W17: =(U17-T17)*24*60 -> 86 | AF17: =N17-K17 -> #N/A | AG17: =N17/K17 -> #N/A
B18: =VLOOKUP(D18,廠價表!$C$1:$E$41,2,0) -> #N/A | F18: =VLOOKUP(D18,廠價表!$C$1:$E$41,3,0) -> #N/A | G18: 3398 | H18: =F18*G18 -> #N/A | J18: =VLOOKUP(D18,產線配置圖!$A$3:$C$38,2,0) -> #N/A | K18: =VLOOKUP(D18,產線配置圖!$A$3:$C$38,3,0) -> #N/A | L18: =K18/J18 -> #N/A | M18: 12 | N18: =G18/W18*60 -> 1941.7143 | O18: =N18/M18 -> 161.80952 | P18: =M18-J18 -> #N/A | Q18: =O18-L18 -> #N/A | R18: =O18/L18 -> #N/A | T18: 0.40972222 | U18: 0.48263889 | V18: =(T18-U17)*24*60 -> 12 | W18: =(U18-T18)*24*60 -> 105 | X18: 0.48611111 | Y18: 0.52777778 | AF18: =N18-K18 -> #N/A | AG18: =N18/K18 -> #N/A
V19: =(T19-U18)*24*60 -> -695 | W19: =(U19-T19)*24*60 -> 0 | AF19: =N19-K19 -> 0 | AG19: =N19/K19 -> #DIV/0!
V20: =(T20-U19)*24*60 -> 0 | W20: =(U20-T20)*24*60 -> 0
W21: =(U21-T21)*24*60 -> 0
W22: 0
W23: =(U23-T23)*24*60 -> 0
H24: =F24*G24 -> 0 | W24: =(U24-T24)*24*60 -> 0
H25: =F25*G25 -> 0 | W25: =(U25-T25)*24*60 -> 0
C26: 4度二組A | D26: 平均 | J26: =AVERAGE(J16:J25) -> #N/A | K26: =AVERAGE(K16:K25) -> #N/A | L26: =AVERAGE(L16:L25) -> #N/A | M26: =AVERAGE(M16:M25) -> 12.666667 | N26: =AVERAGE(N16:N25) -> 1663.6239 | O26: =AVERAGE(O16:O25) -> 132.12003 | P26: =M26-J26 -> #N/A | Q26: =O26-L26 -> #N/A | R26: =O26/L26 -> #N/A | Z26: =SUM(Z16:Z25) -> 0 | AA26: =SUM(AA16:AA25) -> 0 | AD26: =SUM(AD16:AD25) -> 0 | AE26: =SUM(AE16:AE25) -> 0 | AF26: =N26-K26 -> #N/A | AG26: =N26/K26 -> #N/A
A27: 手工三線 (ET-55) | B27: =VLOOKUP(D27,廠價表!$C$1:$E$41,2,0) -> #N/A | F27: =VLOOKUP(D27,廠價表!$C$1:$E$41,3,0) -> #N/A | G27: 2263 | H27: =F27*G27 -> #N/A | J27: =VLOOKUP(D27,產線配置圖!$A$3:$C$38,2,0) -> #N/A | K27: =VLOOKUP(D27,產線配置圖!$A$3:$C$38,3,0) -> #N/A | L27: =K27/J27 -> #N/A | M27: 14 | N27: =G27/W27*60 -> 1212.3214 | O27: =N27/M27 -> 86.594388 | P27: =M27-J27 -> #N/A | Q27: =O27-L27 -> #N/A | R27: =O27/L27 -> #N/A | S27: =R37 -> #N/A | T27: 0.29166667 | U27: 0.36944444 | W27: =(U27-T27)*24*60 -> 112 | AF27: =N27-K27 -> #N/A | AG27: =N27/K27 -> #N/A | AH27: =AG37 -> #N/A
B28: =VLOOKUP(D28,廠價表!$C$1:$E$41,2,0) -> #N/A | F28: =VLOOKUP(D28,廠價表!$C$1:$E$41,3,0) -> #N/A | G28: 1180 | H28: =F28*G28 -> #N/A | J28: =VLOOKUP(D28,產線配置圖!$A$3:$C$38,2,0) -> #N/A | K28: =VLOOKUP(D28,產線配置圖!$A$3:$C$38,3,0) -> #N/A | L28: =K28/J28 -> #N/A | M28: 16 | N28: =G28/W28*60 -> 1089.2308 | O28: =N28/M28 -> 68.076923 | P28: =M28-J28 -> #N/A | Q28: =O28-L28 -> #N/A | R28: =O28/L28 -> #N/A | T28: 0.375 | U28: 0.42013889 | V28: =(T28-U27)*24*60 -> 8 | W28: =(U28-T28)*24*60 -> 65 | AF28: =N28-K28 -> #N/A | AG28: =N28/K28 -> #N/A
B29: =VLOOKUP(D29,廠價表!$C$1:$E$41,2,0) -> #N/A | F29: =VLOOKUP(D29,廠價表!$C$1:$E$41,3,0) -> #N/A | G29: 3398 | H29: =F29*G29 -> #N/A | J29: =VLOOKUP(D29,產線配置圖!$A$3:$C$38,2,0) -> #N/A | K29: =VLOOKUP(D29,產線配置圖!$A$3:$C$38,3,0) -> #N/A | L29: =K29/J29 -> #N/A | M29: 14 | N29: =G29/W29*60 -> 3136.6154 | O29: =N29/M29 -> 224.04396 | P29: =M29-J29 -> #N/A | Q29: =O29-L29 -> #N/A | R29: =O29/L29 -> #N/A | T29: 0.43055556 | U29: 0.47569444 | V29: =(T29-U28)*24*60 -> 15 | W29: =(U29-T29)*24*60 -> 65 | AF29: =N29-K29 -> #N/A | AG29: =N29/K29 -> #N/A
T30: 0.53958333 | U30: 0.56944444 | V30: =(T30-U29)*24*60 -> 92 | W30: =(U30-T30)*24*60 -> 43 | X30: 0.49652778 | Y30: 0.53819444 | AF30: =N30-K30 -> 0 | AG30: =N30/K30 -> #DIV/0!
W31: =(U31-T31)*24*60 -> 0 | AF31: =N31-K31 -> 0 | AG31: =N31/K31 -> #DIV/0!
W32: =(U32-T32)*24*60 -> 0
W33: =(U33-T33)*24*60 -> 0
W34: =(U34-T34)*24*60 -> 0
W35: =(U35-T35)*24*60 -> 0
H36: =F36*G36 -> 0 | W36: =(U36-T36)*24*60 -> 0
C37: 4度二組B | D37: 平均 | J37: =AVERAGE(J27:J36) -> #N/A | K37: =AVERAGE(K27:K36) -> #N/A | L37: =AVERAGE(L27:L36) -> #N/A | M37: =AVERAGE(M27:M36) -> 14.666667 | N37: =AVERAGE(N27:N36) -> 1812.7225 | O37: =AVERAGE(O27:O36) -> 126.23842 | P37: =M37-J37 -> #N/A | Q37: =N37-K37 -> #N/A | R37: =O37/L37 -> #N/A | Z37: =SUM(Z27:Z36) -> 0 | AA37: =SUM(AA27:AA36) -> 0 | AD37: =SUM(AD27:AD36) -> 0 | AE37: =SUM(AE27:AE36) -> 0 | AF37: =N37-K37 -> #N/A | AG37: =N37/K37 -> #N/A
A38: 手工四線 (ET-55) | B38: =VLOOKUP(D38,廠價表!$C$1:$E$41,2,0) -> #N/A | F38: =VLOOKUP(D38,廠價表!$C$1:$E$41,3,0) -> #N/A | G38: 2263 | H38: =F38*G38 -> #N/A | J38: =VLOOKUP(D38,產線配置圖!$A$3:$C$38,2,0) -> #N/A | K38: =VLOOKUP(D38,產線配置圖!$A$3:$C$38,3,0) -> #N/A | L38: =K38/J38 -> #N/A | M38: 14 | N38: =G38/W38*60 -> 1967.8261 | O38: =N38/M38 -> 140.55901 | P38: =M38-J38 -> #N/A | Q38: =O38-L38 -> #N/A | R38: =O38/L38 -> #N/A | S38: =R48 -> #N/A | T38: 0.33333333 | U38: 0.38125 | W38: =(U38-T38)*24*60 -> 69 | AF38: =N38-K38 -> #N/A | AG38: =N38/K38 -> #N/A | AH38: =AG48 -> #N/A
B39: =VLOOKUP(D39,廠價表!$C$1:$E$41,2,0) -> #N/A | F39: =VLOOKUP(D39,廠價表!$C$1:$E$41,3,0) -> #N/A | G39: 1180 | H39: =F39*G39 -> #N/A | J39: =VLOOKUP(D39,產線配置圖!$A$3:$C$38,2,0) -> #N/A | K39: =VLOOKUP(D39,產線配置圖!$A$3:$C$38,3,0) -> #N/A | L39: =K39/J39 -> #N/A | M39: 14 | N39: =G39/W39*60 -> 885 | O39: =N39/M39 -> 63.214286 | P39: =M39-J39 -> #N/A | Q39: =O39-L39 -> #N/A | R39: =O39/L39 -> #N/A | T39: 0.38888889 | U39: 0.44444444 | V39: =(T39-U38)*24*60 -> 11 | W39: =(U39-T39)*24*60 -> 80 | AF39: =N39-K39 -> #N/A | AG39: =N39/K39 -> #N/A
B40: =VLOOKUP(D40,廠價表!$C$1:$E$41,2,0) -> #N/A | F40: =VLOOKUP(D40,廠價表!$C$1:$E$41,3,0) -> #N/A | G40: 3398 | H40: =F40*G40 -> #N/A | J40: =VLOOKUP(D40,產線配置圖!$A$3:$C$38,2,0) -> #N/A | K40: =VLOOKUP(D40,產線配置圖!$A$3:$C$38,3,0) -> #N/A | L40: =K40/J40 -> #N/A | M40: 14 | N40: =G40/W40*60 -> 1853.4545 | O40: =N40/M40 -> 132.38961 | P40: =M40-J40 -> #N/A | Q40: =O40-L40 -> #N/A | R40: =O40/L40 -> #N/A | T40: 0.52777778 | U40: 0.60416667 | V40: =(T40-U39)*24*60 -> 120 | W40: =(U40-T40)*24*60 -> 110 | AF40: =N40-K40 -> #N/A | AG40: =N40/K40 -> #N/A
...

Sheet 0301總
B1: 長家廠組合室生產人時性分析
B3: 日期 | D3: 46082 | F3: 訂單量 | G3: ='0301'!E1 -> 61259 | I3: 營業額 | J3: ='0301'!G1 -> 2919228.6
B4: 項目 | D4: 3 | F4: ➀ | H4: ➁ | J4: ③ | L4: 異常停線 | N4: 短暫停線
B5: 人時性 | D5: 組合室 | F5: 全溫層 | H5: 義大利麵 | J5: 袋裝小吃、義麵 | L5: 合計次數 | M5: 時間 | N5: 合計次數 | O5: 設備次數
D6: 排關平均 | F6: =AVERAGE(D13:J13) -> 122.70262 | H6: =AVERAGE(D13:H13,J13) -> 121.97428 | J6: =AVERAGE(I13) -> 127.07265 | L6: =SUM(D18:J18) -> 0 | M6: =SUM(D19:J19) -> 0 | N6: =SUM(D20:J20) -> 0 | O6: =SUM(D20:J20) -> 0
D7: 實績平均 | F7: =AVERAGE(D14:J14) -> 108.01117 | H7: =AVERAGE(D14:H14,J14) -> 107.28982 | J7: =AVERAGE(I14) -> 112.33929 | L7: =AVERAGE(K14:L14) -> #DIV/0! | M7: =AVERAGE(L14:M14) -> #DIV/0! | N7: =AVERAGE(M14:N14) -> #DIV/0! | O7: =AVERAGE(N14:O14) -> #DIV/0!
D8: 達成率平均 | F8: =F7/F6 -> 0.88026786 | H8: =H7/H6 -> 0.87961018 | J8: =J7/J6 -> 0.88405559 | L8: =AVERAGE(K15:L15) -> #DIV/0! | M8: =AVERAGE(L15:M15) -> #DIV/0! | N8: =AVERAGE(M15:N15) -> #DIV/0! | O8: =AVERAGE(N15:O15) -> #DIV/0!
J9: ※現行日本鮮食廠以達成率80%為基本(即為現行KPI)
B10: 溫層 | D10: 4度C-各編組展開
B11: 編組 | D11: 1 | E11: 2 | F11: 3 | G11: 4 | H11: 5 | I11: 6 | J11: 7
D12: 自動1線 | E12: 自動2線 | F12: 手工3線 | G12: 手工4線 | H12: 手工5線 | I12: 調理包1線 | J12: 調理包2線
B13: 人時性 | C13: 排關 | D13: =VALUE('0301'!L15) -> 158.69872 | E13: =VALUE('0301'!L26) -> 183.05871 | F13: =VALUE('0301'!L37) -> 93.436275 | G13: =VALUE('0301'!L48) -> 92.058824 | H13: =VALUE('0301'!L58) -> 100.30147 | I13: =VALUE('0301'!L69) -> 127.07265 | J13: ='0301'!L79 -> 104.29167
C14: 實績 | D14: =VALUE('0301'!O15) -> 133.94323 | E14: =VALUE('0301'!O26) -> 147.83973 | F14: =VALUE('0301'!O37) -> 90.259802 | G14: =VALUE('0301'!O48) -> 80.817163 | H14: =VALUE('0301'!O58) -> 99.076319 | I14: =VALUE('0301'!O69) -> 112.33929 | J14: ='0301'!O79 -> 91.802648
C15: 達成率 | D15: =D14/D13 -> 0.84400955 | E15: =E14/E13 -> 0.80760827 | F15: =F14/F13 -> 0.96600386 | G15: =G14/G13 -> 0.87788611 | H15: =H14/H13 -> 0.98778531 | I15: =I14/I13 -> 0.88405559 | J15: ='0301'!S70 -> 0.88024913
B16: 作業 時間 | C16: 開始 | D16: ='0301'!T5 -> 0.29166667 | E16: ='0301'!T16 -> 0.29722222 | F16: ='0301'!T27 -> 0.28819444 | G16: ='0301'!T38 -> 0.33333333 | H16: ='0301'!T49 -> 0.29166667 | I16: ='0301'!T59 -> 0.29166667 | J16: ='0301'!T70 -> 0.35486111
C17: 結束 | D17: 0.62916667 | E17: 0.61805556 | F17: 0.55138889 | G17: 0.65486111 | H17: 0.64166667 | I17: 0.51388889 | J17: 0.61666667
B18: 產線異常 (5分鐘以上) | C18: 次數 | D18: ='0301'!Z15 -> 0 | E18: ='0301'!Z26 -> 0 | F18: ='0301'!Z37 -> 0 | G18: ='0301'!Z48 -> 0 | H18: ='0301'!Z58 -> 0 | I18: ='0301'!Z69 -> 0 | J18: ='0301'!AA79 -> 0
C19: 時間/分 | D19: ='0301'!AA15 -> 0 | E19: ='0301'!AA26 -> 0 | F19: ='0301'!AA37 -> 0 | G19: ='0301'!AA48 -> 0 | H19: ='0301'!AA58 -> 0 | I19: ='0301'!AA69 -> 0 | J19: ='0301'!AB79 -> 0
B20: 短暫停線 (5分鐘以下) | C20: 次數 | D20: ='0301'!AD15 -> 0 | E20: ='0301'!AD26 -> 0 | F20: ='0301'!AD37 -> 0 | G20: ='0301'!AD48 -> 0 | H20: ='0301'!AD58 -> 0 | I20: ='0301'!AD69 -> 0 | J20: ='0301'!AD79 -> 0
C21: 設備次數 | D21: ='0301'!AE15 -> 0 | E21: ='0301'!AE26 -> 0 | F21: ='0301'!AE37 -> 0 | G21: ='0301'!AE48 -> 0 | H21: ='0301'!AE58 -> 0 | I21: ='0301'!AE69 -> 0 | J21: ='0301'!AE79 -> 0
B22: 配置人數 | D22: =VALUE('0301'!M15) -> 15.4 | E22: =VALUE('0301'!M26) -> 15 | F22: =VALUE('0301'!M37) -> 15.5 | G22: =VALUE('0301'!M48) -> 17 | H22: =VALUE('0301'!M58) -> 16.5 | I22: =VALUE('0301'!M69) -> 13.333333 | J22: ='0301'!M79 -> 12
B23: 主要應用設備 | D23: ET-600 | E23: ET-600 | F23: ET-55 | G23: ET-55 | H23: ET-55 | I23: 八爪機 | J23: 八爪機
B24: 次要應用設備 | H24: 封口機 | J24: 封口機
B25: 備註

Sheet 0301
A1: 長家廠4度C日報分析 | D1: 總生產量 | E1: =SUM(G5:G79) -> 61259 | F1: 營業額 | G1: =SUM(H5:H79) -> 2919228.6 | H1: 出勤人數 | I1: =M15+M26+M48+M58+M69+M79+M37 -> 104.73333 | J1: 產線配置圖 | M1: 生產實績 | P1: 人時性差異分析 | T1: 日報登錄 | Z1: 合計 次數 | AA1: 合計 時間/分 | AB1: 分析說明 | AD1: 合計 次數 | AE1: 合計 設備次數 | AF1: 產能差異分析
A2: 03月01日 星期日 | D2: 人時性 | E2: =AVERAGE(O15,O26,O37,O48,O58,O69,O79) -> 108.01117 | F2: 平均廠價 | G2: =G1/E1 -> 47.653873 | H2: 多次生產數 | I2: =COUNT(I5:I79) -> 0 | Z2: =Z15+Z26+Z37+Z48+Z58+Z69+Z79 -> 0 | AA2: =AA15+AA26+AA37+AA48+AA58+AA69+AA79 -> 0 | AD2: =AD15+AD26+AD37+AD48+AD58+AD69+AD79 -> 0 | AE2: =AE15+AE26+AE37+AE48+AE58+AE69+AE79 -> 0
A3: 線別 | B3: 品類 | D3: 品名 | F3: 廠價 | G3: 生產量 | H3: 營收 | I3: 多次 生產 | J3: 人數 | K3: 產能/時 | L3: 人時性 | M3: 人數 | N3: 產能/時 | O3: 人時性 | P3: 人數 | Q3: 人時性 | R3: 達成率 | S3: 達成率平均 | T3: 生產時間 | V3: 前置、換線時間/分 | W3: 稼動時間/分 | X3: 休息時間 | Z3: 產線異常統計 (5分鐘以上) | AD3: 短暫停線統計 (5分鐘以下) | AF3: 產能/時 | AG3: 達成率 | AH3: 達成率平均
T4: 開始 | U4: 結束 | X4: 開始 | Y4: 結束 | Z4: 次數 | AA4: 時間/分 | AD4: 總次數 | AE4: 設備因素(次數)
A5: 自動一線 (ET-600) | B5: 義大利麵 | D5: 白酒蛤蜊義大利麵 | F5: =VLOOKUP(D5,廠價表!$C$1:$E$41,3,0) -> 57.21 | G5: 2306 | H5: =F5*G5 -> 131926.26 | J5: =VLOOKUP(D5,產線配置圖!$A$3:$C$38,2,0) -> 12 | K5: =VLOOKUP(D5,產線配置圖!$A$3:$C$38,3,0) -> 2105 | L5: =K5/J5 -> 175.41667 | M5: 16 | N5: =G5/W5*60 -> 2161.875 | O5: =N5/M5 -> 135.11719 | P5: =M5-J5 -> 4 | Q5: =O5-L5 -> -40.299479 | R5: =O5/L5 -> 0.77026425 | S5: =R15 -> 0.84400955 | T5: 0.29166667 | U5: 0.33611111 | W5: =(U5-T5)*24*60 -> 64 | AB5: 新進學生加入，教育訓練 | AF5: =N5-K5 -> 56.875 | AG5: =N5/K5 -> 1.027019 | AH5: =AG15 -> 1.0017296
B6: 義大利麵 | D6: 青醬蛤蜊義大利麵 | F6: =VLOOKUP(D6,廠價表!$C$1:$E$41,3,0) -> 50.67 | G6: 1547 | H6: =F6*G6 -> 78386.49 | J6: =VLOOKUP(D6,產線配置圖!$A$3:$C$38,2,0) -> 12 | K6: =VLOOKUP(D6,產線配置圖!$A$3:$C$38,3,0) -> 2100 | L6: =K6/J6 -> 175 | M6: 15 | N6: =G6/W6*60 -> 2109.5455 | O6: =N6/M6 -> 140.63636 | P6: =M6-J6 -> 3 | Q6: =O6-L6 -> -34.363636 | R6: =O6/L6 -> 0.80363636 | T6: 0.34722222 | U6: 0.37777778 | V6: =(T6-U5)*24*60 -> 16 | W6: =(U6-T6)*24*60 -> 44 | AB6: 新進學生加入，教育訓練 | AF6: =N6-K6 -> 9.5454545 | AG6: =N6/K6 -> 1.0045455
B7: 義大利麵 | D7: 辣味香菜雞肉義大利麵 | F7: =VLOOKUP(D7,廠價表!$C$1:$E$41,3,0) -> 56.28 | G7: 1462 | H7: =F7*G7 -> 82281.36 | J7: =VLOOKUP(D7,產線配置圖!$A$3:$C$38,2,0) -> 15 | K7: =VLOOKUP(D7,產線配置圖!$A$3:$C$38,3,0) -> 1800 | L7: =K7/J7 -> 120 | M7: 17 | N7: =G7/W7*60 -> 1827.5 | O7: =N7/M7 -> 107.5 | P7: =M7-J7 -> 2 | Q7: =O7-L7 -> -12.5 | R7: =O7/L7 -> 0.89583333 | T7: 0.38472222 | U7: 0.41805556 | V7: =(T7-U6)*24*60 -> 10 | W7: =(U7-T7)*24*60 -> 48 | AB7: 新進學生加入，教育訓練 | AF7: =N7-K7 -> 27.5 | AG7: =N7/K7 -> 1.0152778
B8: 義大利麵 | D8: 奶油培根義大利麵 | F8: =VLOOKUP(D8,廠價表!$C$1:$E$41,3,0) -> 49.14 | G8: 2345 | H8: =F8*G8 -> 115233.3 | J8: =VLOOKUP(D8,產線配置圖!$A$3:$C$38,2,0) -> 13 | K8: =VLOOKUP(D8,產線配置圖!$A$3:$C$38,3,0) -> 2100 | L8: =K8/J8 -> 161.53846 | M8: 16 | N8: =G8/W8*60 -> 2131.8182 | O8: =N8/M8 -> 133.23864 | P8: =M8-J8 -> 3 | Q8: =O8-L8 -> -28.299825 | R8: =O8/L8 -> 0.82481061 | T8: 0.42638889 | U8: 0.47222222 | V8: =(T8-U7)*24*60 -> 12 | W8: =(U8-T8)*24*60 -> 66 | X8: 0.48611111 | Y8: 0.52777778 | AB8: 新進學生加入，教育訓練 | AF8: =N8-K8 -> 31.818182 | AG8: =N8/K8 -> 1.0151515
B9: 義大利麵 | D9: 奶油培根義大利麵 | F9: =VLOOKUP(D9,廠價表!$C$1:$E$41,3,0) -> 49.14 | G9: 4515 | H9: =F9*G9 -> 221867.1 | J9: =VLOOKUP(D9,產線配置圖!$A$3:$C$38,2,0) -> 13 | K9: =VLOOKUP(D9,產線配置圖!$A$3:$C$38,3,0) -> 2100 | L9: =K9/J9 -> 161.53846 | M9: 13 | N9: =G9/W9*60 -> 1991.9118 | O9: =N9/M9 -> 153.22398 | P9: =M9-J9 -> 0 | Q9: =O9-L9 -> -8.3144796 | R9: =O9/L9 -> 0.94852941 | T9: 0.53472222 | U9: 0.62916667 | V9: =(T9-U8)*24*60 -> 90 | W9: =(U9-T9)*24*60 -> 136 | AF9: =N9-K9 -> -108.08824 | AG9: =N9/K9 -> 0.94852941
W10: =(U10-T10)*24*60 -> 0 | AF10: =N10-K10 -> 0 | AG10: =N10/K10 -> #DIV/0!
W11: =(U11-T11)*24*60 -> 0 | AF11: =N11-K11 -> 0 | AG11: =N11/K11 -> #DIV/0!
W12: =(U12-T12)*24*60 -> 0
W13: =(U13-T13)*24*60 -> 0
W14: =(U14-T14)*24*60 -> 0
C15: 4度一組 | D15: 平均 | J15: =AVERAGE(J5:J14) -> 13 | K15: =AVERAGE(K5:K14) -> 2041 | L15: =AVERAGE(L5:L14) -> 158.69872 | M15: =AVERAGE(M5:M14) -> 15.4 | N15: =AVERAGE(N5:N14) -> 2044.5301 | O15: =AVERAGE(O5:O14) -> 133.94323 | P15: =M15-J15 -> 2.4 | Q15: =O15-L15 -> -24.755484 | R15: =O15/L15 -> 0.84400955 | Z15: =SUM(Z5:Z14) -> 0 | AA15: =SUM(AA5:AA14) -> 0 | AD15: =SUM(AD5:AD14) -> 0 | AE15: =SUM(AE5:AE14) -> 0 | AF15: =N15-K15 -> 3.5300802 | AG15: =N15/K15 -> 1.0017296
A16: 自動二線 (ET-600) | B16: 義大利麵 | D16: 白酒蛤蜊義大利麵 | F16: =VLOOKUP(D16,廠價表!$C$1:$E$41,3,0) -> 57.21 | G16: 2095 | H16: =F16*G16 -> 119854.95 | J16: =VLOOKUP(D16,產線配置圖!$A$3:$C$38,2,0) -> 12 | K16: =VLOOKUP(D16,產線配置圖!$A$3:$C$38,3,0) -> 2105 | L16: =K16/J16 -> 175.41667 | M16: 15 | N16: =G16/W16*60 -> 2371.6981 | O16: =N16/M16 -> 158.11321 | P16: =M16-J16 -> 3 | Q16: =O16-L16 -> -17.303459 | R16: =O16/L16 -> 0.90135795 | S16: =R26 -> 0.80760827 | T16: 0.29722222 | U16: 0.33402778 | W16: =(U16-T16)*24*60 -> 53 | AB16: 新進學生加入，教育訓練 | AF16: =N16-K16 -> 266.69811 | AG16: =N16/K16 -> 1.1266974 | AH16: =AG26 -> 1.0553699
B17: 義大利麵 | D17: 青醬蛤蜊義大利麵 | F17: =VLOOKUP(D17,廠價表!$C$1:$E$41,3,0) -> 50.67 | G17: 3085 | H17: =F17*G17 -> 156316.95 | J17: =VLOOKUP(D17,產線配置圖!$A$3:$C$38,2,0) -> 12 | K17: =VLOOKUP(D17,產線配置圖!$A$3:$C$38,3,0) -> 2100 | L17: =K17/J17 -> 175 | M17: 15 | N17: =G17/W17*60 -> 2230.1205 | O17: =N17/M17 -> 148.6747 | P17: =M17-J17 -> 3 | Q17: =O17-L17 -> -26.325301 | R17: =O17/L17 -> 0.84956971 | T17: 0.34375 | U17: 0.40138889 | V17: =(T17-U16)*24*60 -> 14 | W17: =(U17-T17)*24*60 -> 83 | AB17: 新進學生加入，教育訓練 | AF17: =N17-K17 -> 130.12048 | AG17: =N17/K17 -> 1.0619621
B18: 義大利麵 | D18: 義式蕃茄起司義大利麵 | F18: =VLOOKUP(D18,廠價表!$C$1:$E$41,3,0) -> 50.39 | G18: 2587 | H18: =F18*G18 -> 130358.93 | J18: =VLOOKUP(D18,產線配置圖!$A$3:$C$38,2,0) -> 11 | K18: =VLOOKUP(D18,產線配置圖!$A$3:$C$38,3,0) -> 2100 | L18: =K18/J18 -> 190.90909 | M18: 15 | N18: =G18/W18*60 -> 2249.5652 | O18: =N18/M18 -> 149.97101 | P18: =M18-J18 -> 4 | Q18: =O18-L18 -> -40.938076 | R18: =O18/L18 -> 0.78556246 | T18: 0.42430556 | U18: 0.47222222 | V18: =(T18-U17)*24*60 -> 33 | W18: =(U18-T18)*24*60 -> 69 | X18: 0.48611111 | Y18: 0.52777778 | AB18: 新進學生加入，教育訓練 | AF18: =N18-K18 -> 149.56522 | AG18: =N18/K18 -> 1.0712215
B19: 義大利麵 | D19: 義式蕃茄起司義大利麵 | F19: =VLOOKUP(D19,廠價表!$C$1:$E$41,3,0) -> 50.39 | G19: 4038 | H19: =F19*G19 -> 203474.82 | J19: =VLOOKUP(D19,產線配置圖!$A$3:$C$38,2,0) -> 11 | K19: =VLOOKUP(D19,產線配置圖!$A$3:$C$38,3,0) -> 2100 | L19: =K19/J19 -> 190.90909 | M19: 15 | N19: =G19/W19*60 -> 2019 | O19: =N19/M19 -> 134.6 | P19: =M19-J19 -> 4 | Q19: =O19-L19 -> -56.309091 | R19: =O19/L19 -> 0.70504762 | T19: 0.53472222 | U19: 0.61805556 | V19: =(T19-U18)*24*60 -> 90 | W19: =(U19-T19)*24*60 -> 120 | AB19: 新進學生加入，教育訓練 | AF19: =N19-K19 -> -81 | AG19: =N19/K19 -> 0.96142857
W20: =(U20-T20)*24*60 -> 0
W21: =(U21-T21)*24*60 -> 0
W22: 0
W23: =(U23-T23)*24*60 -> 0
H24: =F24*G24 -> 0 | W24: =(U24-T24)*24*60 -> 0
H25: =F25*G25 -> 0 | W25: =(U25-T25)*24*60 -> 0
C26: 4度二組A | D26: 平均 | J26: =AVERAGE(J16:J25) -> 11.5 | K26: =AVERAGE(K16:K25) -> 2101.25 | L26: =AVERAGE(L16:L25) -> 183.05871 | M26: =AVERAGE(M16:M25) -> 15 | N26: =AVERAGE(N16:N25) -> 2217.596 | O26: =AVERAGE(O16:O25) -> 147.83973 | P26: =M26-J26 -> 3.5 | Q26: =O26-L26 -> -35.218982 | R26: =O26/L26 -> 0.80760827 | Z26: =SUM(Z16:Z25) -> 0 | AA26: =SUM(AA16:AA25) -> 0 | AD26: =SUM(AD16:AD25) -> 0 | AE26: =SUM(AE16:AE25) -> 0 | AF26: =N26-K26 -> 116.34595 | AG26: =N26/K26 -> 1.0553699
A27: 手工三線 (ET-55) | B27: 義大利麵 | D27: 惡魔乳酪生義大利麵 | F27: =VLOOKUP(D27,廠價表!$C$1:$E$41,3,0) -> 57.3 | G27: 1186 | H27: =F27*G27 -> 67957.8 | J27: 15 | K27: =VLOOKUP(D27,產線配置圖!$A$3:$C$38,3,0) -> 1500 | L27: =K27/J27 -> 100 | M27: 15 | N27: =G27/W27*60 -> 1482.5 | O27: =N27/M27 -> 98.833333 | P27: =M27-J27 -> 0 | Q27: =O27-L27 -> -1.1666667 | R27: =O27/L27 -> 0.98833333 | S27: =R37 -> 0.96600386 | T27: 0.28819444 | U27: 0.32152778 | W27: =(U27-T27)*24*60 -> 48 | AF27: =N27-K27 -> -17.5 | AG27: =N27/K27 -> 0.98833333 | AH27: =AG37 -> 0.93891575
B28: 熱乾麵 | D28: 青花椒麻雞肉拌麵 | F28: =VLOOKUP(D28,廠價表!$C$1:$E$41,3,0) -> 49.91 | G28: 3190 | H28: =F28*G28 -> 159212.9 | J28: =VLOOKUP(D28,產線配置圖!$A$3:$C$38,2,0) -> 15 | K28: =VLOOKUP(D28,產線配置圖!$A$3:$C$38,3,0) -> 1565 | L28: =K28/J28 -> 104.33333 | M28: 15 | N28: =G28/W28*60 -> 1439.0977 | O28: =N28/M28 -> 95.93985 | P28: =M28-J28 -> 0 | Q28: =O28-L28 -> -8.3934837 | R28: =O28/L28 -> 0.91955127 | T28: 0.32638889 | U28: 0.41875 | V28: =(T28-U27)*24*60 -> 7 | W28: =(U28-T28)*24*60 -> 133 | AF28: =N28-K28 -> -125.90226 | AG28: =N28/K28 -> 0.91955127
B29: 熱乾麵 | D29: 沙茶豬肉炒麵 | F29: =VLOOKUP(D29,廠價表!$C$1:$E$41,3,0) -> 49.52 | G29: 1150 | H29: =F29*G29 -> 56948 | J29: =VLOOKUP(D29,產線配置圖!$A$3:$C$38,2,0) -> 17 | K29: =VLOOKUP(D29,產線配置圖!$A$3:$C$38,3,0) -> 1440 | L29: =K29/J29 -> 84.705882 | M29: 16 | N29: =G29/W29*60 -> 1326.9231 | O29: =N29/M29 -> 82.932692 | P29: =M29-J29 -> -1 | Q29: =O29-L29 -> -1.77319 | R29: =O29/L29 -> 0.97906651 | T29: 0.425 | U29: 0.46111111 | V29: =(T29-U28)*24*60 -> 9 | W29: =(U29-T29)*24*60 -> 52 | AF29: =N29-K29 -> -113.07692 | AG29: =N29/K29 -> 0.92147436
B30: 熱乾麵 | D30: 沙茶豬肉炒麵 | F30: =VLOOKUP(D30,廠價表!$C$1:$E$41,3,0) -> 49.52 | G30: 800 | H30: =F30*G30 -> 39616 | J30: =VLOOKUP(D30,產線配置圖!$A$3:$C$38,2,0) -> 17 | K30: =VLOOKUP(D30,產線配置圖!$A$3:$C$38,3,0) -> 1440 | L30: =K30/J30 -> 84.705882 | M30: 16 | N30: =G30/W30*60 -> 1333.3333 | O30: =N30/M30 -> 83.333333 | P30: =M30-J30 -> -1 | Q30: =O30-L30 -> -1.372549 | R30: =O30/L30 -> 0.9837963 | T30: 0.52638889 | U30: 0.55138889 | V30: =(T30-U29)*24*60 -> 94 | W30: =(U30-T30)*24*60 -> 36 | X30: 0.49652778 | Y30: 0.53819444 | AF30: =N30-K30 -> -106.66667 | AG30: =N30/K30 -> 0.92592593
W31: =(U31-T31)*24*60 -> 0 | AF31: =N31-K31 -> 0 | AG31: =N31/K31 -> #DIV/0!
W32: =(U32-T32)*24*60 -> 0
W33: =(U33-T33)*24*60 -> 0
W34: =(U34-T34)*24*60 -> 0
W35: =(U35-T35)*24*60 -> 0
H36: =F36*G36 -> 0 | W36: =(U36-T36)*24*60 -> 0
C37: 4度二組B | D37: 平均 | J37: =AVERAGE(J27:J36) -> 16 | K37: =AVERAGE(K27:K36) -> 1486.25 | L37: =AVERAGE(L27:L36) -> 93.436275 | M37: =AVERAGE(M27:M36) -> 15.5 | N37: =AVERAGE(N27:N36) -> 1395.4635 | O37: =AVERAGE(O27:O36) -> 90.259802 | P37: =M37-J37 -> -0.5 | Q37: =N37-K37 -> -90.786461 | R37: =O37/L37 -> 0.96600386 | Z37: =SUM(Z27:Z36) -> 0 | AA37: =SUM(AA27:AA36) -> 0 | AD37: =SUM(AD27:AD36) -> 0 | AE37: =SUM(AE27:AE36) -> 0 | AF37: =N37-K37 -> -90.786461 | AG37: =N37/K37 -> 0.93891575
A38: 手工四線 (ET-55) | B38: 義大利麵 | D38: 剝皮辣椒雞奶油扁麵 | F38: =VLOOKUP(D38,廠價表!$C$1:$E$41,3,0) -> 56.87 | G38: 1543 | H38: =F38*G38 -> 87750.41 | J38: =VLOOKUP(D38,產線配置圖!$A$3:$C$38,2,0) -> 17 | K38: =VLOOKUP(D38,產線配置圖!$A$3:$C$38,3,0) -> 1565 | L38: =K38/J38 -> 92.058824 | M38: 17 | N38: =G38/W38*60 -> 1303.9437 | O38: =N38/M38 -> 76.702568 | P38: =M38-J38 -> 0 | Q38: =O38-L38 -> -15.356255 | R38: =O38/L38 -> 0.83319084 | S38: =R48 -> 0.87788611 | T38: 0.33333333 | U38: 0.38263889 | W38: =(U38-T38)*24*60 -> 71 | AF38: =N38-K38 -> -261.05634 | AG38: =N38/K38 -> 0.83319084 | AH38: =AG48 -> 0.87788611
B39: 熱乾麵 | D39: 府城鹽水意麵 | F39: =VLOOKUP(D39,廠價表!$C$1:$E$41,3,0) -> 44.3 | G39: 3488 | H39: =F39*G39 -> 154518.4 | J39: =VLOOKUP(D39,產線配置圖!$A$3:$C$38,2,0) -> 17 | K39: 1565 | L39: =K39/J39 -> 92.058824 | M39: 17 | N39: =G39/W39*60 -> 1395.2 | O39: =N39/M39 -> 82.070588 | P39: =M39-J39 -> 0 | Q39: =O39-L39 -> -9.9882353 | R39: =O39/L39 -> 0.8915016 | T39: 0.38888889 | U39: 0.49305556 | V39: =(T39-U38)*24*60 -> 9 | W39: =(U39-T39)*24*60 -> 150 | AF39: =N39-K39 -> -169.8 | AG39: =N39/K39 -> 0.8915016
B40: 熱乾麵 | D40: 府城鹽水意麵 | F40: =VLOOKUP(D40,廠價表!$C$1:$E$41,3,0) -> 44.3 | G40: 3746 | H40: =F40*G40 -> 165947.8 | J40: =VLOOKUP(D40,產線配置圖!$A$3:$C$38,2,0) -> 17 | K40: 1565 | L40: =K40/J40 -> 92.058824 | M40: 17 | N40: =G40/W40*60 -> 1422.5316 | O40: =N40/M40 -> 83.678332 | P40: =M40-J40 -> 0 | Q40: =O40-L40 -> -8.3804914 | R40: =O40/L40 -> 0.90896591 | T40: 0.54513889 | U40: 0.65486111 | V40: =(T40-U39)*24*60 -> 75 | W40: =(U40-T40)*24*60 -> 158 | AF40: =N40-K40 -> -142.46835 | AG40: =N40/K40 -> 0.90896591
...

Sheet 0302總 
B1: 長家廠組合室生產人時性分析
B3: 日期 | D3: 46083 | F3: 訂單量 | G3: ='0302'!E1 -> 57654 | I3: 營業額 | J3: ='0302'!G1 -> 2739861.8
B4: 項目 | D4: 3 | F4: ➀ | H4: ➁ | J4: ③ | L4: 異常停線 | N4: 短暫停線
B5: 人時性 | D5: 組合室 | F5: 全溫層 | H5: 義大利麵 | J5: 袋裝小吃、義麵 | L5: 合計次數 | M5: 時間 | N5: 合計次數 | O5: 設備次數
D6: 排關平均 | F6: =AVERAGE(D13:J13) -> 123.81979 | H6: =AVERAGE(D13:H13,J13) -> 123.13832 | J6: =AVERAGE(I13) -> 127.90865 | L6: =SUM(D18:J18) -> 0 | M6: =SUM(D19:J19) -> 0 | N6: =SUM(D20:J20) -> 7 | O6: =SUM(D20:J20) -> 7
D7: 實績平均 | F7: =AVERAGE(D14:J14) -> 109.39194 | H7: =AVERAGE(D14:H14,J14) -> 109.80813 | J7: =AVERAGE(I14) -> 106.89479 | L7: =AVERAGE(K14:L14) -> #DIV/0! | M7: =AVERAGE(L14:M14) -> #DIV/0! | N7: =AVERAGE(M14:N14) -> #DIV/0! | O7: =AVERAGE(N14:O14) -> #DIV/0!
D8: 達成率平均 | F8: =F7/F6 -> 0.88347701 | H8: =H7/H6 -> 0.89174625 | J8: =J7/J6 -> 0.83571197 | L8: =AVERAGE(K15:L15) -> #DIV/0! | M8: =AVERAGE(L15:M15) -> #DIV/0! | N8: =AVERAGE(M15:N15) -> #DIV/0! | O8: =AVERAGE(N15:O15) -> #DIV/0!
J9: ※現行日本鮮食廠以達成率80%為基本(即為現行KPI)
B10: 溫層 | D10: 4度C-各編組展開
B11: 編組 | D11: 1 | E11: 2 | F11: 3 | G11: 4 | H11: 5 | I11: 6 | J11: 7
D12: 自動1線 | E12: 自動2線 | F12: 手工3線 | G12: 手工4線 | H12: 手工5線 | I12: 調理包1線 | J12: 調理包2線
B13: 人時性 | C13: 排關 | D13: =VALUE('0302'!L15) -> 158.69872 | E13: =VALUE('0302'!L26) -> 183.05871 | F13: =VALUE('0302'!L37) -> 95.221989 | G13: =VALUE('0302'!L48) -> 92.058824 | H13: =VALUE('0302'!L58) -> 105.5 | I13: =VALUE('0302'!L69) -> 127.90865 | J13: ='0302'!L79 -> 104.29167
C14: 實績 | D14: =VALUE('0302'!O15) -> 128.34914 | E14: =VALUE('0302'!O26) -> 159.08016 | F14: =VALUE('0302'!O37) -> 91.581589 | G14: =VALUE('0302'!O48) -> 81.604239 | H14: =VALUE('0302'!O58) -> 102.69918 | I14: =VALUE('0302'!O69) -> 106.89479 | J14: ='0302'!O79 -> 95.534503
C15: 達成率 | D15: =D14/D13 -> 0.80875977 | E15: =E14/E13 -> 0.86901166 | F15: =F14/F13 -> 0.96176933 | G15: =G14/G13 -> 0.88643582 | H15: =H14/H13 -> 0.9734519 | I15: =I14/I13 -> 0.83571197 | J15: ='0302'!S70 -> 0.91603199
B16: 作業 時間 | C16: 開始 | D16: ='0302'!T5 -> 0.29166667 | E16: ='0302'!T16 -> 0.29027778 | F16: ='0302'!T27 -> 0.28819444 | G16: ='0302'!T38 -> 0.33333333 | H16: ='0302'!T49 -> 0.29166667 | I16: ='0302'!T59 -> 0.28819444 | J16: ='0302'!T70 -> 0.33333333
C17: 結束 | D17: 0.62986111 | E17: 0.60208333 | F17: 0.575 | G17: 0.64444444 | H17: 0.58402778 | I17: 0.56944444 | J17: 0.59722222
B18: 產線異常 (5分鐘以上) | C18: 次數 | D18: ='0302'!Z15 -> 0 | E18: ='0302'!Z26 -> 0 | F18: ='0302'!Z37 -> 0 | G18: ='0302'!Z48 -> 0 | H18: ='0302'!Z58 -> 0 | I18: ='0302'!Z69 -> 0 | J18: ='0302'!AA79 -> 0
C19: 時間/分 | D19: ='0302'!AA15 -> 0 | E19: ='0302'!AA26 -> 0 | F19: ='0302'!AA37 -> 0 | G19: ='0302'!AA48 -> 0 | H19: ='0302'!AA58 -> 0 | I19: ='0302'!AA69 -> 0 | J19: ='0302'!AB79 -> 0
B20: 短暫停線 (5分鐘以下) | C20: 次數 | D20: ='0302'!AD15 -> 2 | E20: ='0302'!AD26 -> 5 | F20: ='0302'!AD37 -> 0 | G20: ='0302'!AD48 -> 0 | H20: ='0302'!AD58 -> 0 | I20: ='0302'!AD69 -> 0 | J20: ='0302'!AD79 -> 0
C21: 設備次數 | D21: ='0302'!AE15 -> 2 | E21: ='0302'!AE26 -> 6 | F21: ='0302'!AE37 -> 0 | G21: ='0302'!AE48 -> 0 | H21: ='0302'!AE58 -> 0 | I21: ='0302'!AE69 -> 0 | J21: ='0302'!AE79 -> 0
B22: 配置人數 | D22: =VALUE('0302'!M15) -> 14.2 | E22: =VALUE('0302'!M26) -> 12.5 | F22: =VALUE('0302'!M37) -> 14.75 | G22: =VALUE('0302'!M48) -> 16.666667 | H22: =VALUE('0302'!M58) -> 16 | I22: =VALUE('0302'!M69) -> 13 | J22: ='0302'!M79 -> 11.333333
B23: 主要應用設備 | D23: ET-600 | E23: ET-600 | F23: ET-55 | G23: ET-55 | H23: ET-55 | I23: 八爪機 | J23: 八爪機
B24: 次要應用設備 | H24: 封口機 | J24: 封口機
B25: 備註

Sheet 0302
A1: 長家廠4度C日報分析 | D1: 總生產量 | E1: =SUM(G5:G79) -> 57654 | F1: 營業額 | G1: =SUM(H5:H79) -> 2739861.8 | H1: 出勤人數 | I1: =M15+M26+M48+M58+M69+M79+M37 -> 98.45 | J1: 產線配置圖 | M1: 生產實績 | P1: 人時性差異分析 | T1: 日報登錄 | Z1: 合計 次數 | AA1: 合計 時間/分 | AB1: 分析說明 | AD1: 合計 次數 | AE1: 合計 設備次數 | AF1: 產能差異分析
A2: 03月02日 星期一 | D2: 人時性 | E2: =AVERAGE(O15,O26,O37,O48,O58,O69,O79) -> 109.39194 | F2: 平均廠價 | G2: =G1/E1 -> 47.522493 | H2: 多次生產數 | I2: =COUNT(I5:I79) -> 0 | Z2: =Z15+Z26+Z37+Z48+Z58+Z69+Z79 -> 0 | AA2: =AA15+AA26+AA37+AA48+AA58+AA69+AA79 -> 0 | AD2: =AD15+AD26+AD37+AD48+AD58+AD69+AD79 -> 7 | AE2: =AE15+AE26+AE37+AE48+AE58+AE69+AE79 -> 8
A3: 線別 | B3: 品類 | D3: 品名 | F3: 廠價 | G3: 生產量 | H3: 營收 | I3: 多次 生產 | J3: 人數 | K3: 產能/時 | L3: 人時性 | M3: 人數 | N3: 產能/時 | O3: 人時性 | P3: 人數 | Q3: 人時性 | R3: 達成率 | S3: 達成率平均 | T3: 生產時間 | V3: 前置、換線時間/分 | W3: 稼動時間/分 | X3: 休息時間 | Z3: 產線異常統計 (5分鐘以上) | AD3: 短暫停線統計 (5分鐘以下) | AF3: 產能/時 | AG3: 達成率 | AH3: 達成率平均
T4: 開始 | U4: 結束 | X4: 開始 | Y4: 結束 | Z4: 次數 | AA4: 時間/分 | AD4: 總次數 | AE4: 設備因素(次數)
A5: 自動一線 (ET-600) | B5: 義大利麵 | D5: 白酒蛤蜊義大利麵 | F5: =VLOOKUP(D5,廠價表!$C$1:$E$41,3,0) -> 57.21 | G5: 2173 | H5: =F5*G5 -> 124317.33 | J5: =VLOOKUP(D5,產線配置圖!$A$3:$C$38,2,0) -> 12 | K5: =VLOOKUP(D5,產線配置圖!$A$3:$C$38,3,0) -> 2105 | L5: =K5/J5 -> 175.41667 | M5: 15 | N5: =G5/W5*60 -> 2102.9032 | O5: =N5/M5 -> 140.19355 | P5: =M5-J5 -> 3 | Q5: =O5-L5 -> -35.223118 | R5: =O5/L5 -> 0.79920313 | S5: =R15 -> 0.80875977 | T5: 0.29166667 | U5: 0.33472222 | W5: =(U5-T5)*24*60 -> 62 | AB5: 新進學生加入，教育訓練 | AD5: 1 | AE5: 1 | AF5: =N5-K5 -> -2.0967742 | AG5: =N5/K5 -> 0.99900391 | AH5: =AG15 -> 0.89065148
B6: 義大利麵 | D6: 青醬蛤蜊義大利麵 | F6: =VLOOKUP(D6,廠價表!$C$1:$E$41,3,0) -> 50.67 | G6: 1153 | H6: =F6*G6 -> 58422.51 | J6: =VLOOKUP(D6,產線配置圖!$A$3:$C$38,2,0) -> 12 | K6: =VLOOKUP(D6,產線配置圖!$A$3:$C$38,3,0) -> 2100 | L6: =K6/J6 -> 175 | M6: 14 | N6: =G6/W6*60 -> 1572.2727 | O6: =N6/M6 -> 112.30519 | P6: =M6-J6 -> 2 | Q6: =O6-L6 -> -62.694805 | R6: =O6/L6 -> 0.64174397 | T6: 0.34166667 | U6: 0.37222222 | V6: =(T6-U5)*24*60 -> 10 | W6: =(U6-T6)*24*60 -> 44 | AB6: 新進學生加入，教育訓練 | AD6: 1 | AE6: 1 | AF6: =N6-K6 -> -527.72727 | AG6: =N6/K6 -> 0.7487013
B7: 義大利麵 | D7: 辣味香菜雞肉義大利麵 | F7: =VLOOKUP(D7,廠價表!$C$1:$E$41,3,0) -> 56.28 | G7: 1536 | H7: =F7*G7 -> 86446.08 | J7: =VLOOKUP(D7,產線配置圖!$A$3:$C$38,2,0) -> 15 | K7: =VLOOKUP(D7,產線配置圖!$A$3:$C$38,3,0) -> 1800 | L7: =K7/J7 -> 120 | M7: 15 | N7: =G7/W7*60 -> 1772.3077 | O7: =N7/M7 -> 118.15385 | P7: =M7-J7 -> 0 | Q7: =O7-L7 -> -1.8461538 | R7: =O7/L7 -> 0.98461538 | T7: 0.37847222 | U7: 0.41458333 | V7: =(T7-U6)*24*60 -> 9 | W7: =(U7-T7)*24*60 -> 52 | AB7: 新進學生加入，教育訓練 | AF7: =N7-K7 -> -27.692308 | AG7: =N7/K7 -> 0.98461538
B8: 義大利麵 | D8: 奶油培根義大利麵 | F8: =VLOOKUP(D8,廠價表!$C$1:$E$41,3,0) -> 49.14 | G8: 1945 | H8: =F8*G8 -> 95577.3 | J8: =VLOOKUP(D8,產線配置圖!$A$3:$C$38,2,0) -> 13 | K8: =VLOOKUP(D8,產線配置圖!$A$3:$C$38,3,0) -> 2100 | L8: =K8/J8 -> 161.53846 | M8: 14 | N8: =G8/W8*60 -> 1643.662 | O8: =N8/M8 -> 117.40443 | P8: =M8-J8 -> 1 | Q8: =O8-L8 -> -44.134035 | R8: =O8/L8 -> 0.72678931 | T8: 0.42847222 | U8: 0.47777778 | V8: =(T8-U7)*24*60 -> 20 | W8: =(U8-T8)*24*60 -> 71 | X8: 0.48611111 | Y8: 0.52777778 | AB8: 新進學生加入，教育訓練 | AF8: =N8-K8 -> -456.33803 | AG8: =N8/K8 -> 0.78269618
B9: 義大利麵 | D9: 奶油培根義大利麵 | F9: =VLOOKUP(D9,廠價表!$C$1:$E$41,3,0) -> 49.14 | G9: 4229 | H9: =F9*G9 -> 207813.06 | J9: =VLOOKUP(D9,產線配置圖!$A$3:$C$38,2,0) -> 13 | K9: =VLOOKUP(D9,產線配置圖!$A$3:$C$38,3,0) -> 2100 | L9: =K9/J9 -> 161.53846 | M9: 13 | N9: =G9/W9*60 -> 1997.9528 | O9: =N9/M9 -> 153.68867 | P9: =M9-J9 -> 0 | Q9: =O9-L9 -> -7.849788 | R9: =O9/L9 -> 0.95140607 | T9: 0.54166667 | U9: 0.62986111 | V9: =(T9-U8)*24*60 -> 92 | W9: =(U9-T9)*24*60 -> 127 | AF9: =N9-K9 -> -102.04724 | AG9: =N9/K9 -> 0.95140607
W10: =(U10-T10)*24*60 -> 0 | AF10: =N10-K10 -> 0 | AG10: =N10/K10 -> #DIV/0!
W11: =(U11-T11)*24*60 -> 0 | AF11: =N11-K11 -> 0 | AG11: =N11/K11 -> #DIV/0!
W12: =(U12-T12)*24*60 -> 0
W13: =(U13-T13)*24*60 -> 0
W14: =(U14-T14)*24*60 -> 0
C15: 4度一組 | D15: 平均 | J15: =AVERAGE(J5:J14) -> 13 | K15: =AVERAGE(K5:K14) -> 2041 | L15: =AVERAGE(L5:L14) -> 158.69872 | M15: =AVERAGE(M5:M14) -> 14.2 | N15: =AVERAGE(N5:N14) -> 1817.8197 | O15: =AVERAGE(O5:O14) -> 128.34914 | P15: =M15-J15 -> 1.2 | Q15: =O15-L15 -> -30.34958 | R15: =O15/L15 -> 0.80875977 | Z15: =SUM(Z5:Z14) -> 0 | AA15: =SUM(AA5:AA14) -> 0 | AD15: =SUM(AD5:AD14) -> 2 | AE15: =SUM(AE5:AE14) -> 2 | AF15: =N15-K15 -> -223.18033 | AG15: =N15/K15 -> 0.89065148
A16: 自動二線 (ET-600) | B16: 義大利麵 | D16: 白酒蛤蜊義大利麵 | F16: =VLOOKUP(D16,廠價表!$C$1:$E$41,3,0) -> 57.21 | G16: 1931 | H16: =F16*G16 -> 110472.51 | J16: =VLOOKUP(D16,產線配置圖!$A$3:$C$38,2,0) -> 12 | K16: =VLOOKUP(D16,產線配置圖!$A$3:$C$38,3,0) -> 2105 | L16: =K16/J16 -> 175.41667 | M16: 15 | N16: =G16/W16*60 -> 2032.6316 | O16: =N16/M16 -> 135.50877 | P16: =M16-J16 -> 3 | Q16: =O16-L16 -> -39.907895 | R16: =O16/L16 -> 0.77249656 | S16: =R26 -> 0.86901166 | T16: 0.29027778 | U16: 0.32986111 | W16: =(U16-T16)*24*60 -> 57 | AB16: 新進學生加入，教育訓練 | AD16: 1 | AE16: 1 | AF16: =N16-K16 -> -72.368421 | AG16: =N16/K16 -> 0.9656207 | AH16: =AG26 -> 0.93628423
B17: 義大利麵 | D17: 青醬蛤蜊義大利麵 | F17: =VLOOKUP(D17,廠價表!$C$1:$E$41,3,0) -> 50.67 | G17: 3055 | H17: =F17*G17 -> 154796.85 | J17: =VLOOKUP(D17,產線配置圖!$A$3:$C$38,2,0) -> 12 | K17: =VLOOKUP(D17,產線配置圖!$A$3:$C$38,3,0) -> 2100 | L17: =K17/J17 -> 175 | M17: 13 | N17: =G17/W17*60 -> 2131.3953 | O17: =N17/M17 -> 163.95349 | P17: =M17-J17 -> 1 | Q17: =O17-L17 -> -11.046512 | R17: =O17/L17 -> 0.93687708 | T17: 0.33611111 | U17: 0.39583333 | V17: =(T17-U16)*24*60 -> 9 | W17: =(U17-T17)*24*60 -> 86 | AB17: 新進學生加入，教育訓練 | AD17: 3 | AE17: 4 | AF17: =N17-K17 -> 31.395349 | AG17: =N17/K17 -> 1.0149502
B18: 義大利麵 | D18: 義式蕃茄起司義大利麵 | F18: =VLOOKUP(D18,廠價表!$C$1:$E$41,3,0) -> 50.39 | G18: 3334 | H18: =F18*G18 -> 168000.26 | J18: =VLOOKUP(D18,產線配置圖!$A$3:$C$38,2,0) -> 11 | K18: =VLOOKUP(D18,產線配置圖!$A$3:$C$38,3,0) -> 2100 | L18: =K18/J18 -> 190.90909 | M18: 11 | N18: =G18/W18*60 -> 1818.5455 | O18: =N18/M18 -> 165.32231 | P18: =M18-J18 -> 0 | Q18: =O18-L18 -> -25.586777 | R18: =O18/L18 -> 0.86597403 | T18: 0.40277778 | U18: 0.47916667 | V18: =(T18-U17)*24*60 -> 10 | W18: =(U18-T18)*24*60 -> 110 | X18: 0.48611111 | Y18: 0.52777778 | AB18: 新進學生加入，教育訓練 | AD18: 1 | AE18: 1 | AF18: =N18-K18 -> -281.45455 | AG18: =N18/K18 -> 0.86597403
B19: 義大利麵 | D19: 義式蕃茄起司義大利麵 | F19: =VLOOKUP(D19,廠價表!$C$1:$E$41,3,0) -> 50.39 | G19: 2736 | H19: =F19*G19 -> 137867.04 | J19: =VLOOKUP(D19,產線配置圖!$A$3:$C$38,2,0) -> 11 | K19: =VLOOKUP(D19,產線配置圖!$A$3:$C$38,3,0) -> 2100 | L19: =K19/J19 -> 190.90909 | M19: 11 | N19: =G19/W19*60 -> 1886.8966 | O19: =N19/M19 -> 171.53605 | P19: =M19-J19 -> 0 | Q19: =O19-L19 -> -19.373041 | R19: =O19/L19 -> 0.89852217 | T19: 0.54166667 | U19: 0.60208333 | V19: =(T19-U18)*24*60 -> 90 | W19: =(U19-T19)*24*60 -> 87 | AB19: 新進學生加入，教育訓練 | AF19: =N19-K19 -> -213.10345 | AG19: =N19/K19 -> 0.89852217
W20: =(U20-T20)*24*60 -> 0
W21: =(U21-T21)*24*60 -> 0
W22: 0
W23: =(U23-T23)*24*60 -> 0
H24: =F24*G24 -> 0 | W24: =(U24-T24)*24*60 -> 0
H25: =F25*G25 -> 0 | W25: =(U25-T25)*24*60 -> 0
C26: 4度二組A | D26: 平均 | J26: =AVERAGE(J16:J25) -> 11.5 | K26: =AVERAGE(K16:K25) -> 2101.25 | L26: =AVERAGE(L16:L25) -> 183.05871 | M26: =AVERAGE(M16:M25) -> 12.5 | N26: =AVERAGE(N16:N25) -> 1967.3672 | O26: =AVERAGE(O16:O25) -> 159.08016 | P26: =M26-J26 -> 1 | Q26: =O26-L26 -> -23.978556 | R26: =O26/L26 -> 0.86901166 | Z26: =SUM(Z16:Z25) -> 0 | AA26: =SUM(AA16:AA25) -> 0 | AD26: =SUM(AD16:AD25) -> 5 | AE26: =SUM(AE16:AE25) -> 6 | AF26: =N26-K26 -> -133.88277 | AG26: =N26/K26 -> 0.93628423
A27: 手工三線 (ET-55) | B27: 義大利麵 | D27: 惡魔乳酪生義大利麵 | F27: =VLOOKUP(D27,廠價表!$C$1:$E$41,3,0) -> 57.3 | G27: 1246 | H27: =F27*G27 -> 71395.8 | J27: =VLOOKUP(D27,產線配置圖!$A$3:$C$38,2,0) -> 14 | K27: =VLOOKUP(D27,產線配置圖!$A$3:$C$38,3,0) -> 1500 | L27: =K27/J27 -> 107.14286 | M27: 14 | N27: =G27/W27*60 -> 1495.2 | O27: =N27/M27 -> 106.8 | P27: =M27-J27 -> 0 | Q27: =O27-L27 -> -0.34285714 | R27: =O27/L27 -> 0.9968 | S27: =R37 -> 0.96176933 | T27: 0.28819444 | U27: 0.32291667 | W27: =(U27-T27)*24*60 -> 50 | AF27: =N27-K27 -> -4.8 | AG27: =N27/K27 -> 0.9968 | AH27: =AG37 -> 0.90632386
B28: 熱乾麵 | D28: 青花椒麻雞肉拌麵 | F28: =VLOOKUP(D28,廠價表!$C$1:$E$41,3,0) -> 49.91 | G28: 3059 | H28: =F28*G28 -> 152674.69 | J28: =VLOOKUP(D28,產線配置圖!$A$3:$C$38,2,0) -> 15 | K28: =VLOOKUP(D28,產線配置圖!$A$3:$C$38,3,0) -> 1565 | L28: =K28/J28 -> 104.33333 | M28: 15 | N28: =G28/W28*60 -> 1401.0687 | O28: =N28/M28 -> 93.40458 | P28: =M28-J28 -> 0 | Q28: =O28-L28 -> -10.928753 | R28: =O28/L28 -> 0.89525157 | T28: 0.32777778 | U28: 0.41875 | V28: =(T28-U27)*24*60 -> 7 | W28: =(U28-T28)*24*60 -> 131 | AF28: =N28-K28 -> -163.9313 | AG28: =N28/K28 -> 0.89525157
B29: 熱乾麵 | D29: 沙茶豬肉炒麵 | F29: =VLOOKUP(D29,廠價表!$C$1:$E$41,3,0) -> 49.52 | G29: 1187 | H29: =F29*G29 -> 58780.24 | J29: =VLOOKUP(D29,產線配置圖!$A$3:$C$38,2,0) -> 17 | K29: =VLOOKUP(D29,產線配置圖!$A$3:$C$38,3,0) -> 1440 | L29: =K29/J29 -> 84.705882 | M29: 15 | N29: =G29/W29*60 -> 1249.4737 | O29: =N29/M29 -> 83.298246 | P29: =M29-J29 -> -2 | Q29: =O29-L29 -> -1.4076367 | R29: =O29/L29 -> 0.98338207 | T29: 0.42569444 | U29: 0.46527778 | V29: =(T29-U28)*24*60 -> 10 | W29: =(U29-T29)*24*60 -> 57 | AF29: =N29-K29 -> -190.52632 | AG29: =N29/K29 -> 0.86769006
B30: 熱乾麵 | D30: 沙茶豬肉炒麵 | F30: =VLOOKUP(D30,廠價表!$C$1:$E$41,3,0) -> 49.52 | G30: 1408 | H30: =F30*G30 -> 69724.16 | J30: =VLOOKUP(D30,產線配置圖!$A$3:$C$38,2,0) -> 17 | K30: =VLOOKUP(D30,產線配置圖!$A$3:$C$38,3,0) -> 1440 | L30: =K30/J30 -> 84.705882 | M30: 15 | N30: =G30/W30*60 -> 1242.3529 | O30: =N30/M30 -> 82.823529 | P30: =M30-J30 -> -2 | Q30: =O30-L30 -> -1.8823529 | R30: =O30/L30 -> 0.97777778 | T30: 0.52777778 | U30: 0.575 | V30: =(T30-U29)*24*60 -> 90 | W30: =(U30-T30)*24*60 -> 68 | X30: 0.49652778 | Y30: 0.53819444 | AF30: =N30-K30 -> -197.64706 | AG30: =N30/K30 -> 0.8627451
W31: =(U31-T31)*24*60 -> 0 | AF31: =N31-K31 -> 0 | AG31: =N31/K31 -> #DIV/0!
W32: =(U32-T32)*24*60 -> 0
W33: =(U33-T33)*24*60 -> 0
W34: =(U34-T34)*24*60 -> 0
W35: =(U35-T35)*24*60 -> 0
H36: =F36*G36 -> 0 | W36: =(U36-T36)*24*60 -> 0
C37: 4度二組B | D37: 平均 | J37: =AVERAGE(J27:J36) -> 15.75 | K37: =AVERAGE(K27:K36) -> 1486.25 | L37: =AVERAGE(L27:L36) -> 95.221989 | M37: =AVERAGE(M27:M36) -> 14.75 | N37: =AVERAGE(N27:N36) -> 1347.0238 | O37: =AVERAGE(O27:O36) -> 91.581589 | P37: =M37-J37 -> -1 | Q37: =N37-K37 -> -139.22617 | R37: =O37/L37 -> 0.96176933 | Z37: =SUM(Z27:Z36) -> 0 | AA37: =SUM(AA27:AA36) -> 0 | AD37: =SUM(AD27:AD36) -> 0 | AE37: =SUM(AE27:AE36) -> 0 | AF37: =N37-K37 -> -139.22617 | AG37: =N37/K37 -> 0.90632386
A38: 手工四線 (ET-55) | B38: 義大利麵 | D38: 剝皮辣椒雞奶油扁麵 | F38: =VLOOKUP(D38,廠價表!$C$1:$E$41,3,0) -> 56.87 | G38: 1557 | H38: =F38*G38 -> 88546.59 | J38: =VLOOKUP(D38,產線配置圖!$A$3:$C$38,2,0) -> 17 | K38: =VLOOKUP(D38,產線配置圖!$A$3:$C$38,3,0) -> 1565 | L38: =K38/J38 -> 92.058824 | M38: 16 | N38: =G38/W38*60 -> 1213.2468 | O38: =N38/M38 -> 75.827922 | P38: =M38-J38 -> -1 | Q38: =O38-L38 -> -16.230901 | R38: =O38/L38 -> 0.82368989 | S38: =R48 -> 0.88643582 | T38: 0.33333333 | U38: 0.38680556 | W38: =(U38-T38)*24*60 -> 77 | AF38: =N38-K38 -> -351.75325 | AG38: =N38/K38 -> 0.77523754 | AH38: =AG48 -> 0.87028504
B39: 熱乾麵 | D39: 府城鹽水意麵 | F39: =VLOOKUP(D39,廠價表!$C$1:$E$41,3,0) -> 44.3 | G39: 3469 | H39: =F39*G39 -> 153676.7 | J39: =VLOOKUP(D39,產線配置圖!$A$3:$C$38,2,0) -> 17 | K39: 1565 | L39: =K39/J39 -> 92.058824 | M39: 17 | N39: =G39/W39*60 -> 1435.4483 | O39: =N39/M39 -> 84.438134 | P39: =M39-J39 -> 0 | Q39: =O39-L39 -> -7.6206897 | R39: =O39/L39 -> 0.91721935 | T39: 0.39236111 | U39: 0.49305556 | V39: =(T39-U38)*24*60 -> 8 | W39: =(U39-T39)*24*60 -> 145 | AF39: =N39-K39 -> -129.55172 | AG39: =N39/K39 -> 0.91721935
B40: 熱乾麵 | D40: 府城鹽水意麵 | F40: =VLOOKUP(D40,廠價表!$C$1:$E$41,3,0) -> 44.3 | G40: 3186 | H40: =F40*G40 -> 141139.8 | J40: =VLOOKUP(D40,產線配置圖!$A$3:$C$38,2,0) -> 17 | K40: 1565 | L40: =K40/J40 -> 92.058824 | M40: 17 | N40: =G40/W40*60 -> 1437.2932 | O40: =N40/M40 -> 84.546661 | P40: =M40-J40 -> 0 | Q40: =O40-L40 -> -7.5121628 | R40: =O40/L40 -> 0.91839823 | T40: 0.55208333 | U40: 0.64444444 | V40: =(T40-U39)*24*60 -> 85 | W40: =(U40-T40)*24*60 -> 133 | AF40: =N40-K40 -> -127.70677 | AG40: =N40/K40 -> 0.91839823
...

Sheet 0303總
B1: 長家廠組合室生產人時性分析
B3: 日期 | D3: 46084 | F3: 訂單量 | G3: ='0303'!E1 -> 73597 | I3: 營業額 | J3: ='0303'!G1 -> 3405506.5
B4: 項目 | D4: 3 | F4: ➀ | H4: ➁ | J4: ③ | L4: 異常停線 | N4: 短暫停線
B5: 人時性 | D5: 組合室 | F5: 全溫層 | H5: 義大利麵 | J5: 袋裝小吃、義麵 | L5: 合計次數 | M5: 時間 | N5: 合計次數 | O5: 設備次數
D6: 排關平均 | F6: =AVERAGE(D13:J13) -> 124.78755 | H6: =AVERAGE(D13:H13,J13) -> 118.70824 | J6: =AVERAGE(I13) -> 161.26335 | L6: =SUM(D18:J18) -> 0 | M6: =SUM(D19:J19) -> 0 | N6: =SUM(D20:J20) -> 0 | O6: =SUM(D20:J20) -> 0
D7: 實績平均 | F7: =AVERAGE(D14:J14) -> 111.17817 | H7: =AVERAGE(D14:H14,J14) -> 106.52189 | J7: =AVERAGE(I14) -> 139.11583 | L7: =AVERAGE(K14:L14) -> #DIV/0! | M7: =AVERAGE(L14:M14) -> #DIV/0! | N7: =AVERAGE(M14:N14) -> #DIV/0! | O7: =AVERAGE(N14:O14) -> #DIV/0!
D8: 達成率平均 | F8: =F7/F6 -> 0.89093964 | H8: =H7/H6 -> 0.897342 | J8: =J7/J6 -> 0.8626624 | L8: =AVERAGE(K15:L15) -> #DIV/0! | M8: =AVERAGE(L15:M15) -> #DIV/0! | N8: =AVERAGE(M15:N15) -> #DIV/0! | O8: =AVERAGE(N15:O15) -> #DIV/0!
J9: ※現行日本鮮食廠以達成率80%為基本(即為現行KPI)
B10: 溫層 | D10: 4度C-各編組展開
B11: 編組 | D11: 1 | E11: 2 | F11: 3 | G11: 4 | H11: 5 | I11: 6 | J11: 7
D12: 自動1線 | E12: 自動2線 | F12: 手工3線 | G12: 手工4線 | H12: 手工5線 | I12: 調理包1線 | J12: 調理包2線
B13: 人時性 | C13: 排關 | D13: =VALUE('0303'!L15) -> 136.33173 | E13: =VALUE('0303'!L26) -> 181.5303 | F13: =VALUE('0303'!L37) -> 93.443627 | G13: =VALUE('0303'!L48) -> 90.220588 | H13: =VALUE('0303'!L58) -> 106.43155 | I13: =VALUE('0303'!L69) -> 161.26335 | J13: ='0303'!L79 -> 104.29167
C14: 實績 | D14: =VALUE('0303'!O15) -> 116.10398 | E14: =VALUE('0303'!O26) -> 157.94342 | F14: =VALUE('0303'!O37) -> 92.537984 | G14: =VALUE('0303'!O48) -> 77.743713 | H14: =VALUE('0303'!O58) -> 102.10084 | I14: =VALUE('0303'!O69) -> 139.11583 | J14: ='0303'!O79 -> 92.701429
C15: 達成率 | D15: =D14/D13 -> 0.85162843 | E15: =E14/E13 -> 0.8700664 | F15: =F14/F13 -> 0.99030813 | G15: =G14/G13 -> 0.86170701 | H15: =H14/H13 -> 0.95930993 | I15: =I14/I13 -> 0.8626624 | J15: ='0303'!S70 -> 0.88886707
B16: 作業 時間 | C16: 開始 | D16: ='0303'!T5 -> 0.29166667 | E16: ='0303'!T16 -> 0.29097222 | F16: ='0303'!T27 -> 0.29027778 | G16: ='0303'!T38 -> 0.33472222 | H16: ='0303'!T49 -> 0.29166667 | I16: ='0303'!T59 -> 0.25 | J16: ='0303'!T70 -> 0.33333333
C17: 結束 | D17: 0.61597222 | E17: 0.65694444 | F17: 0.64236111 | G17: 0.70902778 | H17: 0.60347222 | I17: 0.58611111 | J17: 0.58333333
B18: 產線異常 (5分鐘以上) | C18: 次數 | D18: ='0303'!Z15 -> 0 | E18: ='0303'!Z26 -> 0 | F18: ='0303'!Z37 -> 0 | G18: ='0303'!Z48 -> 0 | H18: ='0303'!Z58 -> 0 | I18: ='0303'!Z69 -> 0 | J18: ='0303'!AA79 -> 0
C19: 時間/分 | D19: ='0303'!AA15 -> 0 | E19: ='0303'!AA26 -> 0 | F19: ='0303'!AA37 -> 0 | G19: ='0303'!AA48 -> 0 | H19: ='0303'!AA58 -> 0 | I19: ='0303'!AA69 -> 0 | J19: ='0303'!AB79 -> 0
B20: 短暫停線 (5分鐘以下) | C20: 次數 | D20: ='0303'!AD15 -> 0 | E20: ='0303'!AD26 -> 0 | F20: ='0303'!AD37 -> 0 | G20: ='0303'!AD48 -> 0 | H20: ='0303'!AD58 -> 0 | I20: ='0303'!AD69 -> 0 | J20: ='0303'!AD79 -> 0
C21: 設備次數 | D21: ='0303'!AE15 -> 0 | E21: ='0303'!AE26 -> 0 | F21: ='0303'!AE37 -> 0 | G21: ='0303'!AE48 -> 0 | H21: ='0303'!AE58 -> 0 | I21: ='0303'!AE69 -> 0 | J21: ='0303'!AE79 -> 0
B22: 配置人數 | D22: =VALUE('0303'!M15) -> 15.75 | E22: =VALUE('0303'!M26) -> 13.2 | F22: =VALUE('0303'!M37) -> 16.333333 | G22: =VALUE('0303'!M48) -> 16.5 | H22: =VALUE('0303'!M58) -> 16.25 | I22: =VALUE('0303'!M69) -> 10.375 | J22: ='0303'!M79 -> 12
B23: 主要應用設備 | D23: ET-600 | E23: ET-600 | F23: ET-55 | G23: ET-55 | H23: ET-55 | I23: 八爪機 | J23: 八爪機
B24: 次要應用設備 | H24: 封口機 | J24: 封口機
B25: 備註

Sheet 0303
A1: 長家廠4度C日報分析 | D1: 總生產量 | E1: =SUM(G5:G79) -> 73597 | F1: 營業額 | G1: =SUM(H5:H79) -> 3405506.5 | H1: 出勤人數 | I1: =M15+M26+M48+M58+M69+M79+M37 -> 100.40833 | J1: 產線配置圖 | M1: 生產實績 | P1: 人時性差異分析 | T1: 日報登錄 | Z1: 合計 次數 | AA1: 合計 時間/分 | AB1: 分析說明 | AD1: 合計 次數 | AE1: 合計 設備次數 | AF1: 產能差異分析
A2: 03月03日 星期二 | D2: 人時性 | E2: =AVERAGE(O15,O26,O37,O48,O58,O69,O79) -> 111.17817 | F2: 平均廠價 | G2: =G1/E1 -> 46.272355 | H2: 多次生產數 | I2: =COUNT(I5:I79) -> 0 | Z2: =Z15+Z26+Z37+Z48+Z58+Z69+Z79 -> 0 | AA2: =AA15+AA26+AA37+AA48+AA58+AA69+AA79 -> 0 | AD2: =AD15+AD26+AD37+AD48+AD58+AD69+AD79 -> 0 | AE2: =AE15+AE26+AE37+AE48+AE58+AE69+AE79 -> 0
A3: 線別 | B3: 品類 | D3: 品名 | F3: 廠價 | G3: 生產量 | H3: 營收 | I3: 多次 生產 | J3: 人數 | K3: 產能/時 | L3: 人時性 | M3: 人數 | N3: 產能/時 | O3: 人時性 | P3: 人數 | Q3: 人時性 | R3: 達成率 | S3: 達成率平均 | T3: 生產時間 | V3: 前置、換線時間/分 | W3: 稼動時間/分 | X3: 休息時間 | Z3: 產線異常統計 (5分鐘以上) | AD3: 短暫停線統計 (5分鐘以下) | AF3: 產能/時 | AG3: 達成率 | AH3: 達成率平均
T4: 開始 | U4: 結束 | X4: 開始 | Y4: 結束 | Z4: 次數 | AA4: 時間/分 | AD4: 總次數 | AE4: 設備因素(次數)
A5: 自動一線 (ET-600) | B5: 義大利麵 | D5: 奶油起司蝦仁通心粉 | F5: =VLOOKUP(D5,廠價表!$C$1:$E$41,3,0) -> 47.71 | G5: 2684 | H5: =F5*G5 -> 128053.64 | J5: =VLOOKUP(D5,產線配置圖!$A$3:$C$38,2,0) -> 16 | K5: =VLOOKUP(D5,產線配置圖!$A$3:$C$38,3,0) -> 1636 | L5: =K5/J5 -> 102.25 | M5: 17 | N5: =G5/W5*60 -> 1660.2062 | O5: =N5/M5 -> 97.659187 | P5: =M5-J5 -> 1 | Q5: =O5-L5 -> -4.5908126 | R5: =O5/L5 -> 0.95510208 | S5: =R15 -> 0.85162843 | T5: 0.29166667 | U5: 0.35902778 | W5: =(U5-T5)*24*60 -> 97 | AB5: 新進學生加入，教育訓練 | AF5: =N5-K5 -> 24.206186 | AG5: =N5/K5 -> 1.014796 | AH5: =AG15 -> 0.9436762
B6: 義大利麵 | D6: 辣味香菜雞肉義大利麵 | F6: =VLOOKUP(D6,廠價表!$C$1:$E$41,3,0) -> 56.28 | G6: 1295 | H6: =F6*G6 -> 72882.6 | J6: =VLOOKUP(D6,產線配置圖!$A$3:$C$38,2,0) -> 15 | K6: =VLOOKUP(D6,產線配置圖!$A$3:$C$38,3,0) -> 1800 | L6: =K6/J6 -> 120 | M6: 18 | N6: =G6/W6*60 -> 1850 | O6: =N6/M6 -> 102.77778 | P6: =M6-J6 -> 3 | Q6: =O6-L6 -> -17.222222 | R6: =O6/L6 -> 0.85648148 | T6: 0.38055556 | U6: 0.40972222 | V6: =(T6-U5)*24*60 -> 31 | W6: =(U6-T6)*24*60 -> 42 | AB6: 新進學生加入，教育訓練 | AF6: =N6-K6 -> 50 | AG6: =N6/K6 -> 1.0277778
B7: 義大利麵 | D7: 奶油培根義大利麵 | F7: =VLOOKUP(D7,廠價表!$C$1:$E$41,3,0) -> 49.14 | G7: 2636 | H7: =F7*G7 -> 129533.04 | J7: =VLOOKUP(D7,產線配置圖!$A$3:$C$38,2,0) -> 13 | K7: =VLOOKUP(D7,產線配置圖!$A$3:$C$38,3,0) -> 2100 | L7: =K7/J7 -> 161.53846 | M7: 14 | N7: =G7/W7*60 -> 1839.0698 | O7: =N7/M7 -> 131.36213 | P7: =M7-J7 -> 1 | Q7: =O7-L7 -> -30.176335 | R7: =O7/L7 -> 0.81319411 | T7: 0.41805556 | U7: 0.47777778 | V7: =(T7-U6)*24*60 -> 12 | W7: =(U7-T7)*24*60 -> 86 | AB7: 新進學生加入，教育訓練 | AF7: =N7-K7 -> -260.93023 | AG7: =N7/K7 -> 0.87574751
B8: 義大利麵 | D8: 奶油培根義大利麵 | F8: =VLOOKUP(D8,廠價表!$C$1:$E$41,3,0) -> 49.14 | G8: 3311 | H8: =F8*G8 -> 162702.54 | J8: =VLOOKUP(D8,產線配置圖!$A$3:$C$38,2,0) -> 13 | K8: =VLOOKUP(D8,產線配置圖!$A$3:$C$38,3,0) -> 2100 | L8: =K8/J8 -> 161.53846 | M8: 14 | N8: =G8/W8*60 -> 1856.6355 | O8: =N8/M8 -> 132.61682 | P8: =M8-J8 -> 1 | Q8: =O8-L8 -> -28.921639 | R8: =O8/L8 -> 0.82096128 | T8: 0.54166667 | U8: 0.61597222 | V8: =(T8-U7)*24*60 -> 92 | W8: =(U8-T8)*24*60 -> 107 | X8: 0.48611111 | Y8: 0.52777778 | AB8: 新進學生加入，教育訓練 | AF8: =N8-K8 -> -243.36449 | AG8: =N8/K8 -> 0.88411215
W9: =(U9-T9)*24*60 -> 0
W10: =(U10-T10)*24*60 -> 0
W11: =(U11-T11)*24*60 -> 0
W12: =(U12-T12)*24*60 -> 0
W13: =(U13-T13)*24*60 -> 0
W14: =(U14-T14)*24*60 -> 0
C15: 4度一組 | D15: 平均 | J15: =AVERAGE(J5:J14) -> 14.25 | K15: =AVERAGE(K5:K14) -> 1909 | L15: =AVERAGE(L5:L14) -> 136.33173 | M15: =AVERAGE(M5:M14) -> 15.75 | N15: =AVERAGE(N5:N14) -> 1801.4779 | O15: =AVERAGE(O5:O14) -> 116.10398 | P15: =M15-J15 -> 1.5 | Q15: =O15-L15 -> -20.227752 | R15: =O15/L15 -> 0.85162843 | Z15: =SUM(Z5:Z14) -> 0 | AA15: =SUM(AA5:AA14) -> 0 | AD15: =SUM(AD5:AD14) -> 0 | AE15: =SUM(AE5:AE14) -> 0 | AF15: =N15-K15 -> -107.52213 | AG15: =N15/K15 -> 0.9436762
A16: 自動二線 (ET-600) | B16: 義大利麵 | D16: 白酒蛤蜊義大利麵 | F16: =VLOOKUP(D16,廠價表!$C$1:$E$41,3,0) -> 57.21 | G16: 2434 | H16: =F16*G16 -> 139249.14 | J16: =VLOOKUP(D16,產線配置圖!$A$3:$C$38,2,0) -> 12 | K16: =VLOOKUP(D16,產線配置圖!$A$3:$C$38,3,0) -> 2105 | L16: =K16/J16 -> 175.41667 | M16: 15 | N16: =G16/W16*60 -> 2434 | O16: =N16/M16 -> 162.26667 | P16: =M16-J16 -> 3 | Q16: =O16-L16 -> -13.15 | R16: =O16/L16 -> 0.92503563 | S16: =R26 -> 0.8700664 | T16: 0.29097222 | U16: 0.33263889 | W16: =(U16-T16)*24*60 -> 60 | AB16: 新進學生加入，教育訓練 | AF16: =N16-K16 -> 329 | AG16: =N16/K16 -> 1.1562945 | AH16: =AG26 -> 0.99228266
B17: 義大利麵 | D17: 青醬蛤蜊義大利麵 | F17: =VLOOKUP(D17,廠價表!$C$1:$E$41,3,0) -> 50.67 | G17: 4073 | H17: =F17*G17 -> 206378.91 | J17: =VLOOKUP(D17,產線配置圖!$A$3:$C$38,2,0) -> 12 | K17: =VLOOKUP(D17,產線配置圖!$A$3:$C$38,3,0) -> 2100 | L17: =K17/J17 -> 175 | M17: 15 | N17: =G17/W17*60 -> 2327.4286 | O17: =N17/M17 -> 155.1619 | P17: =M17-J17 -> 3 | Q17: =O17-L17 -> -19.838095 | R17: =O17/L17 -> 0.88663946 | T17: 0.34166667 | U17: 0.41458333 | V17: =(T17-U16)*24*60 -> 13 | W17: =(U17-T17)*24*60 -> 105 | AB17: 新進學生加入，教育訓練 | AF17: =N17-K17 -> 227.42857 | AG17: =N17/K17 -> 1.1082993
B18: 義大利麵 | D18: 義式蕃茄起司義大利麵 | F18: =VLOOKUP(D18,廠價表!$C$1:$E$41,3,0) -> 50.39 | G18: 2376 | H18: =F18*G18 -> 119726.64 | J18: =VLOOKUP(D18,產線配置圖!$A$3:$C$38,2,0) -> 11 | K18: =VLOOKUP(D18,產線配置圖!$A$3:$C$38,3,0) -> 2100 | L18: =K18/J18 -> 190.90909 | M18: 12 | N18: =G18/W18*60 -> 1900.8 | O18: =N18/M18 -> 158.4 | P18: =M18-J18 -> 1 | Q18: =O18-L18 -> -32.509091 | R18: =O18/L18 -> 0.82971429 | T18: 0.425 | U18: 0.47708333 | V18: =(T18-U17)*24*60 -> 15 | W18: =(U18-T18)*24*60 -> 75 | X18: 0.48611111 | Y18: 0.52777778 | AB18: 新進學生加入，教育訓練 | AF18: =N18-K18 -> -199.2 | AG18: =N18/K18 -> 0.90514286
B19: 義大利麵 | D19: 義式蕃茄起司義大利麵 | F19: =VLOOKUP(D19,廠價表!$C$1:$E$41,3,0) -> 50.39 | G19: 3408 | H19: =F19*G19 -> 171729.12 | J19: =VLOOKUP(D19,產線配置圖!$A$3:$C$38,2,0) -> 11 | K19: =VLOOKUP(D19,產線配置圖!$A$3:$C$38,3,0) -> 2100 | L19: =K19/J19 -> 190.90909 | M19: 12 | N19: =G19/W19*60 -> 1842.1622 | O19: =N19/M19 -> 153.51351 | P19: =M19-J19 -> 1 | Q19: =O19-L19 -> -37.395577 | R19: =O19/L19 -> 0.8041184 | T19: 0.54166667 | U19: 0.61875 | V19: =(T19-U18)*24*60 -> 93 | W19: =(U19-T19)*24*60 -> 111 | AB19: 新進學生加入，教育訓練 | AF19: =N19-K19 -> -257.83784 | AG19: =N19/K19 -> 0.87722008
B20: 義大利麵 | D20: 白酒蛤蜊義大利麵 | F20: =VLOOKUP(D20,廠價表!$C$1:$E$41,3,0) -> 57.21 | G20: 1283 | H20: =F20*G20 -> 73400.43 | J20: =VLOOKUP(D20,產線配置圖!$A$3:$C$38,2,0) -> 12 | K20: =VLOOKUP(D20,產線配置圖!$A$3:$C$38,3,0) -> 2105 | L20: =K20/J20 -> 175.41667 | M20: 12 | N20: =G20/W20*60 -> 1924.5 | O20: =N20/M20 -> 160.375 | P20: =M20-J20 -> 0 | Q20: =O20-L20 -> -15.041667 | R20: =O20/L20 -> 0.91425178 | T20: 0.62916667 | U20: 0.65694444 | V20: =(T20-U19)*24*60 -> 15 | W20: =(U20-T20)*24*60 -> 40
W21: =(U21-T21)*24*60 -> 0
W22: 0
W23: =(U23-T23)*24*60 -> 0
H24: =F24*G24 -> 0 | W24: =(U24-T24)*24*60 -> 0
H25: =F25*G25 -> 0 | W25: =(U25-T25)*24*60 -> 0
C26: 4度二組A | D26: 平均 | J26: =AVERAGE(J16:J25) -> 11.6 | K26: =AVERAGE(K16:K25) -> 2102 | L26: =AVERAGE(L16:L25) -> 181.5303 | M26: =AVERAGE(M16:M25) -> 13.2 | N26: =AVERAGE(N16:N25) -> 2085.7781 | O26: =AVERAGE(O16:O25) -> 157.94342 | P26: =M26-J26 -> 1.6 | Q26: =O26-L26 -> -23.586886 | R26: =O26/L26 -> 0.8700664 | Z26: =SUM(Z16:Z25) -> 0 | AA26: =SUM(AA16:AA25) -> 0 | AD26: =SUM(AD16:AD25) -> 0 | AE26: =SUM(AE16:AE25) -> 0 | AF26: =N26-K26 -> -16.221853 | AG26: =N26/K26 -> 0.99228266
A27: 手工三線 (ET-55) | B27: 義大利麵 | D27: 燻火腿貓耳朵麵 | F27: =VLOOKUP(D27,廠價表!$C$1:$E$41,3,0) -> 58.17 | G27: 6421 | H27: =F27*G27 -> 373509.57 | J27: =VLOOKUP(D27,產線配置圖!$A$3:$C$38,2,0) -> 16 | K27: =VLOOKUP(D27,產線配置圖!$A$3:$C$38,3,0) -> 1565 | L27: =K27/J27 -> 97.8125 | M27: 16 | N27: =G27/W27*60 -> 1559.7571 | O27: =N27/M27 -> 97.484818 | P27: =M27-J27 -> 0 | Q27: =O27-L27 -> -0.32768219 | R27: =O27/L27 -> 0.99664989 | S27: =R37 -> 0.99030813 | T27: 0.29027778 | U27: 0.46180556 | W27: =(U27-T27)*24*60 -> 247 | AF27: =N27-K27 -> -5.242915 | AG27: =N27/K27 -> 0.99664989 | AH27: =AG37 -> 0.99014652
B28: 義大利麵 | D28: 燻火腿貓耳朵麵 | F28: =VLOOKUP(D28,廠價表!$C$1:$E$41,3,0) -> 58.17 | G28: 3000 | H28: =F28*G28 -> 174510 | J28: =VLOOKUP(D28,產線配置圖!$A$3:$C$38,2,0) -> 16 | K28: =VLOOKUP(D28,產線配置圖!$A$3:$C$38,3,0) -> 1565 | L28: =K28/J28 -> 97.8125 | M28: 16 | N28: =G28/W28*60 -> 1551.7241 | O28: =N28/M28 -> 96.982759 | P28: =M28-J28 -> 0 | Q28: =O28-L28 -> -0.82974138 | R28: =O28/L28 -> 0.99151702 | T28: 0.52430556 | U28: 0.60486111 | V28: =(T28-U27)*24*60 -> 90 | W28: =(U28-T28)*24*60 -> 116 | AF28: =N28-K28 -> -13.275862 | AG28: =N28/K28 -> 0.99151702
B29: 熱乾麵 | D29: 沙茶豬肉炒麵 | F29: =VLOOKUP(D29,廠價表!$C$1:$E$41,3,0) -> 49.52 | G29: 1013 | H29: =F29*G29 -> 50163.76 | J29: =VLOOKUP(D29,產線配置圖!$A$3:$C$38,2,0) -> 17 | K29: =VLOOKUP(D29,產線配置圖!$A$3:$C$38,3,0) -> 1440 | L29: =K29/J29 -> 84.705882 | M29: 17 | N29: =G29/W29*60 -> 1413.4884 | O29: =N29/M29 -> 83.146375 | P29: =M29-J29 -> 0 | Q29: =O29-L29 -> -1.5595075 | R29: =O29/L29 -> 0.98158915 | T29: 0.6125 | U29: 0.64236111 | V29: =(T29-U28)*24*60 -> 11 | W29: =(U29-T29)*24*60 -> 43 | AF29: =N29-K29 -> -26.511628 | AG29: =N29/K29 -> 0.98158915
W30: =(U30-T30)*24*60 -> 0 | X30: 0.46875 | Y30: 0.51041667 | AF30: =N30-K30 -> 0 | AG30: =N30/K30 -> #DIV/0!
W31: =(U31-T31)*24*60 -> 0 | AF31: =N31-K31 -> 0 | AG31: =N31/K31 -> #DIV/0!
W32: =(U32-T32)*24*60 -> 0
W33: =(U33-T33)*24*60 -> 0
W34: =(U34-T34)*24*60 -> 0
W35: =(U35-T35)*24*60 -> 0
H36: =F36*G36 -> 0 | W36: =(U36-T36)*24*60 -> 0
C37: 4度二組B | D37: 平均 | J37: =AVERAGE(J27:J36) -> 16.333333 | K37: =AVERAGE(K27:K36) -> 1523.3333 | L37: =AVERAGE(L27:L36) -> 93.443627 | M37: =AVERAGE(M27:M36) -> 16.333333 | N37: =AVERAGE(N27:N36) -> 1508.3232 | O37: =AVERAGE(O27:O36) -> 92.537984 | P37: =M37-J37 -> 0 | Q37: =N37-K37 -> -15.010135 | R37: =O37/L37 -> 0.99030813 | Z37: =SUM(Z27:Z36) -> 0 | AA37: =SUM(AA27:AA36) -> 0 | AD37: =SUM(AD27:AD36) -> 0 | AE37: =SUM(AE27:AE36) -> 0 | AF37: =N37-K37 -> -15.010135 | AG37: =N37/K37 -> 0.99014652
A38: 手工四線 (ET-55) | B38: 熱乾麵 | D38: 沙茶豬肉炒麵 | F38: =VLOOKUP(D38,廠價表!$C$1:$E$41,3,0) -> 49.52 | G38: 1549 | H38: =F38*G38 -> 76706.48 | J38: =VLOOKUP(D38,產線配置圖!$A$3:$C$38,2,0) -> 17 | K38: =VLOOKUP(D38,產線配置圖!$A$3:$C$38,3,0) -> 1440 | L38: =K38/J38 -> 84.705882 | M38: 15 | N38: =G38/W38*60 -> 1056.1364 | O38: =N38/M38 -> 70.409091 | P38: =M38-J38 -> -2 | Q38: =O38-L38 -> -14.296791 | R38: =O38/L38 -> 0.83121843 | S38: =R48 -> 0.86170701 | T38: 0.33472222 | U38: 0.39583333 | W38: =(U38-T38)*24*60 -> 88 | AF38: =N38-K38 -> -383.86364 | AG38: =N38/K38 -> 0.73342803 | AH38: =AG48 -> 0.83875376
B39: 義大利麵 | D39: 剝皮辣椒雞奶油扁麵 | F39: =VLOOKUP(D39,廠價表!$C$1:$E$41,3,0) -> 56.87 | G39: 1400 | H39: =F39*G39 -> 79618 | J39: =VLOOKUP(D39,產線配置圖!$A$3:$C$38,2,0) -> 17 | K39: =VLOOKUP(D39,產線配置圖!$A$3:$C$38,3,0) -> 1565 | L39: =K39/J39 -> 92.058824 | M39: 17 | N39: =G39/W39*60 -> 1272.7273 | O39: =N39/M39 -> 74.86631 | P39: =M39-J39 -> 0 | Q39: =O39-L39 -> -17.192513 | R39: =O39/L39 -> 0.81324426 | T39: 0.40555556 | U39: 0.45138889 | V39: =(T39-U38)*24*60 -> 14 | W39: =(U39-T39)*24*60 -> 66 | AF39: =N39-K39 -> -292.27273 | AG39: =N39/K39 -> 0.81324426
