Workbook

Sheet 廠價表
A1: check | B1: 溫層 | C1: 品名 | D1: 類別 | E1: 廠價
B2: 4度C | C2: 奶油鮮蝦明太子細扁麵 | D2: 義大利麵 | E2: 57.21
B3: 4度C | C3: 白酒清炒鮮蛤義大利麵 | D3: 義大利麵 | E3: 56.87
B4: 4度C | C4: 義式蕃茄起司義大利麵 | D4: 義大利麵 | E4: 50.39
B5: 4度C | C5: 焗烤起司雙饗筆尖麵 | D5: 義大利麵 | E5: 49.97
B6: 4度C | C6: 奶油培根義大利麵 | D6: 義大利麵 | E6: 49.14
B7: 4度C | C7: 香煎魚排佐檸檬奶油義大利麵 | D7: 義大利麵 | E7: 58.17
B8: 4度C | C8: 青醬蛤蜊義大利麵 | D8: 義大利麵 | E8: 50.67
B9: 4度C | C9: 金沙豆腐義大利麵 | D9: 義大利麵 | E9: 49.91
B10: 4度C | C10: 黑松露野菇義大利麵 | D10: 義大利麵 | E10: 50.289
B11: 4度C | C11: 燻鴨佐白蘭地義大利麵 | D11: 義大利麵 | E11: 61.65
B12: 4度C | C12: 拿坡里燻腸義大利麵 | D12: 義大利麵 | E12: 52.21
B13: 4度C | C13: 羅馬黑胡椒起司義大利麵 | D13: 義大利麵 | E13: 50.67
... B19: 4度C | C19: 番茄蘑菇義大利麵 | D19: 義大利麵 | E19: 43.89
B20: 4度C | D20: 義大利麵
B21: 4度C | D21: 義大利麵
B22: 4度C | D22: 義大利麵
B23: 4度C | C23: 韓式炒冬粉 | D23: 小吃、微波 | E23: 28.26
B24: 4度C | C24: 小滷青蔬 | D24: 小吃、微波 | E24: 26.99
B25: 4度C | C25: 起司馬鈴薯 | D25: 小吃、微波 | E25: 28.26
B26: 4度C | C26: 麻辣雞心 | D26: 小吃、微波 | E26: 28.26
B46: 冷凍 | C46: 青醬蛤蜊義大利麵 | D46: 冷凍調理麵 | E46: 29.38
B47: 冷凍 | C47: 經典肉醬義大利麵 | D47: 冷凍調理麵 | E47: 29.38
B48: 冷凍 | C48: 奶油蘑菇培根義大利麵 | D48: 冷凍調理麵 | E48: 29.38
B49: 冷凍 | C49: 清炒蛤蜊義大利麵 | D49: 冷凍調理麵 | E49: 29.38
B50: 冷凍 | C50: 青醬乳酪筆尖麵 | D50: 冷凍調理麵 | E50: 29.38
B51: 冷凍 | C51: 辣蕃茄義大利麵 | D51: 冷凍調理麵 | E51: 29.38
B52: 冷凍 | D52: 冷凍調理麵
B53: 冷凍 | C53: 韓式起司義大利麵 | D53: 冷凍調理麵 | E53: 29.38
B54: 冷凍 | D54: 冷凍調理麵
B55: 冷凍 | C55: 和風明太子細扁麵 | D55: 冷凍調理麵 | E55: 29.38

Sheet 產線配置圖
A1: 品項 | B1: 人數 | C1: 產能 | E1: 人時 | G1: 備註
A2: 義大利麵
A3: 白酒清炒鮮蛤義大利麵 | B3: 14 | C3: 2250 | D3: ET-600 | E3: =C3/B3 -> 160.71429
A4: 白酒清炒鮮蛤義大利麵-手 | B4: 15 | C4: 1716 | D4: ET-55 | E4: =C4/B4 -> 114.4
A5: 青醬蛤蜊義大利麵 | B5: 14 | C5: 2250 | E5: =C5/B5 -> 160.71429
A6: 青醬蛤蜊義大利麵-手 | B6: 16 | C6: 1714 | E6: =C6/B6 -> 107.125
A7: 義式蕃茄起司義大利麵 | B7: 12 | C7: 2250 | E7: =C7/B7 -> 187.5
A8: 奶油培根義大利麵 | B8: 14 | C8: 2250 | E8: =C8/B8 -> 160.71429
A9: 燻鴨佐白蘭地義大利麵 | B9: 18 | C9: 1636 | E9: =C9/B9 -> 90.888889
A10: 蒜香奶油蝦蝦義大利麵-手 | B10: 17 | C10: 1716 | E10: =C10/B10 -> 100.94118
A11: 拿坡里燻腸義大利麵 | B11: 18 | C11: 1636 | E11: =C11/B11 -> 90.888889
A12: 香煎魚排佐檸檬奶油義大利麵 | B12: 13 | C12: 2250 | E12: =C12/B12 -> 173.07692
A13: 黑松露野菇義大利麵 | B13: 17 | C13: 1636 | E13: =C13/B13 -> 96.235294 | J13: 黑松露野菇義大利麵 | K13: 17 | L13: 1565 | N13: =L13/K13 -> 92.058824
A14: 青花椒麻雞肉拌麵 | B14: 16 | C14: 1714 | E14: =C14/B14 -> 107.125 | J14: 青花椒麻雞肉拌麵 | K14: 14 | L14: 1714 | N14: =L14/K14 -> 122.42857
A15: 焗烤起司雙饗筆尖麵 | B15: 16 | C15: 1800 | E15: =C15/B15 -> 112.5 | G15: 目前使用手工 | J15: 焗烤起司雙饗筆尖麵 | K15: 15 | L15: 1800 | N15: =L15/K15 -> 120
A16: 沙茶豬肉炒麵 | B16: 17 | C16: 1800 | E16: =C16/B16 -> 105.88235 | J16: 沙茶豬肉炒麵 | K16: 16 | L16: 1500 | N16: =L16/K16 -> 93.75
A17: 府城鹽水意麵 | B17: 18 | C17: 1636 | E17: =C17/B17 -> 90.888889 | J17: 府城鹽水意麵 | K17: 16 | L17: 1636 | N17: =L17/K17 -> 102.25
A18: 羅馬黑胡椒起司義大利麵 | B18: 17 | C18: 2250 | E18: =C18/B18 -> 132.35294 | J18: 焗烤起司肉醬筆尖麵 | K18: 12 | L18: 1440 | N18: =L18/K18 -> 120
A19: 羅馬黑胡椒起司義大利麵-自動 | B19: 14 | C19: 2250 | E19: =C19/B19 -> 160.71429 | G19: 目前使用雙排 | J19: 整條德式香腸義大利麵 | K19: 16 | L19: 1565 | N19: =L19/K19 -> 97.8125
A20: 義式蛋蛋青醬鮪魚冷義大利麵 | B20: 17 | C20: 1636 | E20: =C20/B20 -> 96.235294
A21: 蕃茄莎莎海鮮冷義大利麵 | B21: 16 | C21: 1636 | E21: =C21/B21 -> 102.25
A22: 金沙豆腐義大利麵 | B22: 18 | C22: 1636 | E22: =C22/B22 -> 90.888889
A23: 奶油鮮蝦明太子細扁麵 | B23: 18 | C23: 1636
A24: 番茄蘑菇義大利麵 | B24: 11 | C24: 1565
A26: 調理包
A27: 小滷青蔬 | B27: 15 | C27: 1636 | E27: =C27/B27 -> 109.06667 | G27: 夏季+1人補料
A28: 起司馬鈴薯 | B28: 11 | C28: 1636 | E28: =C28/B28 -> 148.72727
A29: 麻辣雞心 | B29: 11 | C29: 1636 | E29: =C29/B29 -> 148.72727
A30: 韓式炒冬粉 | B30: 11 | C30: 1636 | E30: =C30/B30 -> 148.72727
E34: 更新日期07/03

Sheet 範本總
B1: 長家廠組合室生產人時性分析
B3: 日期 | D3: 46015 | F3: 訂單量 | G3: =範本!E1 -> 43309 | I3: 營業額 | J3: =範本!G1 -> #N/A
B4: 項目 | D4: 3 | F4: ➀ | H4: ➁ | J4: ③ | L4: 異常停線 | N4: 短暫停線
B5: 人時性 | D5: 組合室 | F5: 全溫層 | H5: 義大利麵 | J5: 袋裝小吃、義麵 | L5: 合計次數 | M5: 時間 | N5: 合計次數 | O5: 設備次數
D6: 排關平均 | F6: =AVERAGE(D13:J13) -> #N/A | H6: =AVERAGE(D13:H13) -> #N/A | J6: =AVERAGE(I13:J13) -> #N/A | L6: =範本!Z2 -> 0 | M6: =範本!AA2 -> 0 | N6: =範本!AD2 -> 0 | O6: =範本!AE2 -> 0
D7: 實績平均 | F7: =AVERAGE(D14:J14) -> 116.11475 | H7: =AVERAGE(D14:H14) -> 117.36075 | J7: =AVERAGE(I14:J14) -> 112.99975
D8: 達成率平均 | F8: =AVERAGE(D15:J15) -> #N/A | H8: =AVERAGE(D15:H15) -> #N/A | J8: =AVERAGE(I15:J15) -> #N/A
J9: ※現行日本鮮食廠以達成率80%為基本(即為現行KPI)
B10: 溫層 | D10: 4度C-各編組展開
B11: 編組 | D11: 1 | E11: 2 | F11: 3 | G11: 4 | H11: 5 | I11: 6 | J11: 7
D12: 自動1線 | E12: 自動2線 | F12: 手工3線 | G12: 手工4線 | H12: 手工5線 | I12: 調理包1線 | J12: 調理包2線
B13: 人時性 | C13: 排關 | D13: =VALUE(範本!L15) -> #N/A | E13: =VALUE(範本!L26) -> #N/A | F13: =VALUE(範本!L37) -> #N/A | G13: =VALUE(範本!L48) -> #N/A | H13: =VALUE(範本!L58) -> #N/A | I13: =VALUE(範本!L69) -> #N/A | J13: =範本!L79 -> #N/A
C14: 實績 | D14: =VALUE(範本!O15) -> 113.91637 | E14: =VALUE(範本!O26) -> 132.12003 | F14: =VALUE(範本!O37) -> 126.23842 | G14: =VALUE(範本!O48) -> 112.0543 | H14: =VALUE(範本!O58) -> 102.47462 | I14: =VALUE(範本!O69) -> 155.46443 | J14: =範本!O79 -> 70.535065
C15: 達成率 | D15: =D14/D13 -> #N/A | E15: =E14/E13 -> #N/A | F15: =F14/F13 -> #N/A | G15: =G14/G13 -> #N/A | H15: =H14/H13 -> #N/A | I15: =I14/I13 -> #N/A | J15: =範本!S70 -> #N/A
B16: 作業 時間 | C16: 開始 | D16: =範本!T5 -> 0.29097222 | E16: =範本!T16 -> 0.29097222 | F16: =範本!T27 -> 0.29166667 | G16: =範本!T38 -> 0.33333333 | H16: =範本!T49 -> 0.29166667 | I16: =範本!T59 -> 0.29166667 | J16: =範本!T70 -> 0.34722222
C17: 結束 | D17: 0.47361111 | E17: 0.48263889 | F17: 0.56944444 | G17: 0.60416667 | H17: 0.58333333 | I17: 0.48819444 | J17: 0.46875
B18: 產線異常 (5分鐘以上) | C18: 次數
C19: 時間/分
B20: 短暫停線 (5分鐘以下) | C20: 次數
C21: 設備次數
B22: 配置人數 | D22: =VALUE(範本!M15) -> 15 | E22: =VALUE(範本!M26) -> 12.666667 | F22: =VALUE(範本!M37) -> 14.666667 | G22: =VALUE(範本!M48) -> 14 | H22: =VALUE(範本!M58) -> 17.666667 | I22: =VALUE(範本!M69) -> 12.333333 | J22: =範本!M79 -> 11
B23: 主要應用設備 | D23: ET-600 | E23: ET-600 | F23: ET-55 | G23: ET-55 | H23: ET-55 | I23: 八爪機
B24: 次要應用設備 | H24: 封口機
B25: 備註

Sheet 範本
A1: 長家廠4度C日報分析 | D1: 總生產量 | E1: =SUM(G5:G79) -> 43309 | F1: 營業額 | G1: =SUM(H5:H79) -> #N/A | H1: 出勤人數 | I1: =M15+M26+M48+M58+M69+M79+M37 -> 97.333333 | J1: 產線配置圖 | M1: 生產實績 | P1: 人時性差異分析 | T1: 日報登錄 | Z1: 合計 次數 | AA1: 合計 時間/分 | AB1: 分析說明 | AD1: 合計 次數 | AE1: 合計 設備次數 | AF1: 產能差異分析
A2: 12月24日 星期三 | D2: 人時性 | E2: =AVERAGE(O15,O26,O37,O48,O58,O69,O79) -> 116.11475 | F2: 平均廠價 | G2: =G1/E1 -> #N/A | H2: 多次生產數 | I2: =COUNT(I5:I79) -> 0 | Z2: =Z15+Z26+Z37+Z48+Z58+Z69+Z79 -> 0 | AA2: =AA15+AA26+AA37+AA48+AA58+AA69+AA79 -> 0 | AD2: =AD15+AD26+AD37+AD48+AD58+AD69+AD79 -> 0 | AE2: =AE15+AE26+AE37+AE48+AE58+AE69+AE79 -> 0
A3: 線別 | B3: 品類 | D3: 品名 | F3: 廠價 | G3: 生產量 | H3: 營收 | I3: 多次 生產 | J3: 人數 | K3: 產能/時 | L3: 人時性 | M3: 人數 | N3: 產能/時 | O3: 人時性 | P3: 人數 | Q3: 人時性 | R3: 達成率 | S3: 達成率平均 | T3: 生產時間 | V3: 前置、換線時間/分 | W3: 稼動時間/分 | X3: 休息時間 | Z3: 產線異常統計 (5分鐘以上) | AD3: 短暫停線統計 (5分鐘以下) | AF3: 產能/時 | AG3: 達成率 | AH3: 達成率平均
T4: 開始 | U4: 結束 | X4: 開始 | Y4: 結束 | Z4: 次數 | AA4: 時間/分 | AD4: 總次數 | AE4: 設備因素(次數)
A5: 自動一線 (ET-600) | B5: =VLOOKUP(D5,廠價表!$C$1:$E$43,2,0) -> #N/A | F5: =VLOOKUP(D5,廠價表!$C$1:$E$43,3,0) -> #N/A | G5: 2263 | H5: =F5*G5 -> #N/A | J5: =VLOOKUP(D5,產線配置圖!$A$3:$C$40,2,0) -> #N/A | K5: =VLOOKUP(D5,產線配置圖!$A$3:$C$40,3,0) -> #N/A | L5: =K5/J5 -> #N/A | M5: 15 | N5: =G5/W5*60 -> 1444.4681 | O5: =N5/M5 -> 96.297872 | P5: =M5-J5 -> #N/A | Q5: =O5-L5 -> #N/A | R5: =O5/L5 -> #N/A | S5: =R15 -> #N/A | T5: 0.29097222 | U5: 0.35625 | W5: =(U5-T5)*24*60 -> 94 | AF5: =N5-K5 -> #N/A | AG5: =N5/K5 -> #N/A | AH5: =AG15 -> #N/A
B6: =VLOOKUP(D6,廠價表!$C$1:$E$43,2,0) -> #N/A | F6: =VLOOKUP(D6,廠價表!$C$1:$E$43,3,0) -> #N/A | G6: 1180 | H6: =F6*G6 -> #N/A | J6: =VLOOKUP(D6,產線配置圖!$A$3:$C$40,2,0) -> #N/A | K6: =VLOOKUP(D6,產線配置圖!$A$3:$C$40,3,0) -> #N/A | L6: =K6/J6 -> #N/A | M6: 17 | N6: =G6/W6*60 -> 1609.0909 | O6: =N6/M6 -> 94.652406 | P6: =M6-J6 -> #N/A | Q6: =O6-L6 -> #N/A | R6: =O6/L6 -> #N/A | T6: 0.36458333 | U6: 0.39513889 | V6: =(T6-U5)*24*60 -> 12 | W6: =(U6-T6)*24*60 -> 44 | AF6: =N6-K6 -> #N/A | AG6: =N6/K6 -> #N/A
B7: =VLOOKUP(D7,廠價表!$C$1:$E$43,2,0) -> #N/A | F7: =VLOOKUP(D7,廠價表!$C$1:$E$43,3,0) -> #N/A | G7: 3398 | H7: =F7*G7 -> #N/A | J7: =VLOOKUP(D7,產線配置圖!$A$3:$C$40,2,0) -> #N/A | K7: =VLOOKUP(D7,產線配置圖!$A$3:$C$40,3,0) -> #N/A | L7: =K7/J7 -> #N/A | M7: 13 | N7: =G7/W7*60 -> 1960.3846 | O7: =N7/M7 -> 150.79882 | P7: =M7-J7 -> #N/A | Q7: =O7-L7 -> #N/A | R7: =O7/L7 -> #N/A | T7: 0.40138889 | U7: 0.47361111 | V7: =(T7-U6)*24*60 -> 9 | W7: =(U7-T7)*24*60 -> 104 | AF7: =N7-K7 -> #N/A | AG7: =N7/K7 -> #N/A
W8: =(U8-T8)*24*60 -> 0 | X8: 0.48611111 | Y8: 0.52777778 | AF8: =N8-K8 -> 0 | AG8: =N8/K8 -> #DIV/0!
W9: =(U9-T9)*24*60 -> 0 | AF9: =N9-K9 -> 0 | AG9: =N9/K9 -> #DIV/0!
W10: =(U10-T10)*24*60 -> 0 | AF10: =N10-K10 -> 0 | AG10: =N10/K10 -> #DIV/0!
W11: =(U11-T11)*24*60 -> 0 | AF11: =N11-K11 -> 0 | AG11: =N11/K11 -> #DIV/0!
W12: =(U12-T12)*24*60 -> 0
W13: =(U13-T13)*24*60 -> 0
W14: =(U14-T14)*24*60 -> 0
C15: 4度一組 | D15: 平均 | J15: =AVERAGE(J5:J14) -> #N/A | K15: =AVERAGE(K5:K14) -> #N/A | L15: =AVERAGE(L5:L14) -> #N/A | M15: =AVERAGE(M5:M14) -> 15 | N15: =AVERAGE(N5:N14) -> 1671.3145 | O15: =AVERAGE(O5:O14) -> 113.91637 | P15: =M15-J15 -> #N/A | Q15: =O15-L15 -> #N/A | R15: =O15/L15 -> #N/A | Z15: =SUM(Z5:Z14) -> 0 | AA15: =SUM(AA5:AA14) -> 0 | AD15: =SUM(AD5:AD14) -> 0 | AE15: =SUM(AE5:AE14) -> 0 | AF15: =N15-K15 -> #N/A | AG15: =N15/K15 -> #N/A
A16: 自動二線 (ET-600) | B16: =VLOOKUP(D16,廠價表!$C$1:$E$43,2,0) -> #N/A | F16: =VLOOKUP(D16,廠價表!$C$1:$E$43,3,0) -> #N/A | G16: 2263 | H16: =F16*G16 -> #N/A | J16: =VLOOKUP(D16,產線配置圖!$A$3:$C$40,2,0) -> #N/A | K16: =VLOOKUP(D16,產線配置圖!$A$3:$C$40,3,0) -> #N/A | L16: =K16/J16 -> #N/A | M16: 13 | N16: =G16/W16*60 -> 2225.9016 | O16: =N16/M16 -> 171.2232 | P16: =M16-J16 -> #N/A | Q16: =O16-L16 -> #N/A | R16: =O16/L16 -> #N/A | S16: =R26 -> #N/A | T16: 0.29097222 | U16: 0.33333333 | W16: =(U16-T16)*24*60 -> 61 | AF16: =N16-K16 -> #N/A | AG16: =N16/K16 -> #N/A | AH16: =AG26 -> #N/A
B17: =VLOOKUP(D17,廠價表!$C$1:$E$43,2,0) -> #N/A | F17: =VLOOKUP(D17,廠價表!$C$1:$E$43,3,0) -> #N/A | G17: 1180 | H17: =F17*G17 -> #N/A | J17: =VLOOKUP(D17,產線配置圖!$A$3:$C$40,2,0) -> #N/A | K17: =VLOOKUP(D17,產線配置圖!$A$3:$C$40,3,0) -> #N/A | L17: =K17/J17 -> #N/A | M17: 13 | N17: =G17/W17*60 -> 823.25581 | O17: =N17/M17 -> 63.32737 | P17: =M17-J17 -> #N/A | Q17: =O17-L17 -> #N/A | R17: =O17/L17 -> #N/A | T17: 0.34166667 | U17: 0.40138889 | V17: =(T17-U16)*24*60 -> 12 | W17: =(U17-T17)*24*60 -> 86 | AF17: =N17-K17 -> #N/A | AG17: =N17/K17 -> #N/A
B18: =VLOOKUP(D18,廠價表!$C$1:$E$43,2,0) -> #N/A | F18: =VLOOKUP(D18,廠價表!$C$1:$E$43,3,0) -> #N/A | G18: 3398 | H18: =F18*G18 -> #N/A | J18: =VLOOKUP(D18,產線配置圖!$A$3:$C$40,2,0) -> #N/A | K18: =VLOOKUP(D18,產線配置圖!$A$3:$C$40,3,0) -> #N/A | L18: =K18/J18 -> #N/A | M18: 12 | N18: =G18/W18*60 -> 1941.7143 | O18: =N18/M18 -> 161.80952 | P18: =M18-J18 -> #N/A | Q18: =O18-L18 -> #N/A | R18: =O18/L18 -> #N/A | T18: 0.40972222 | U18: 0.48263889 | V18: =(T18-U17)*24*60 -> 12 | W18: =(U18-T18)*24*60 -> 105 | X18: 0.48611111 | Y18: 0.52777778 | AF18: =N18-K18 -> #N/A | AG18: =N18/K18 -> #N/A
V19: =(T19-U18)*24*60 -> -695 | W19: =(U19-T19)*24*60 -> 0 | AF19: =N19-K19 -> 0 | AG19: =N19/K19 -> #DIV/0!
V20: =(T20-U19)*24*60 -> 0 | W20: =(U20-T20)*24*60 -> 0
W21: =(U21-T21)*24*60 -> 0
W22: 0
W23: =(U23-T23)*24*60 -> 0
H24: =F24*G24 -> 0 | W24: =(U24-T24)*24*60 -> 0
H25: =F25*G25 -> 0 | W25: =(U25-T25)*24*60 -> 0
C26: 4度二組A | D26: 平均 | J26: =AVERAGE(J16:J25) -> #N/A | K26: =AVERAGE(K16:K25) -> #N/A | L26: =AVERAGE(L16:L25) -> #N/A | M26: =AVERAGE(M16:M25) -> 12.666667 | N26: =AVERAGE(N16:N25) -> 1663.6239 | O26: =AVERAGE(O16:O25) -> 132.12003 | P26: =M26-J26 -> #N/A | Q26: =O26-L26 -> #N/A | R26: =O26/L26 -> #N/A | Z26: =SUM(Z16:Z25) -> 0 | AA26: =SUM(AA16:AA25) -> 0 | AD26: =SUM(AD16:AD25) -> 0 | AE26: =SUM(AE16:AE25) -> 0 | AF26: =N26-K26 -> #N/A | AG26: =N26/K26 -> #N/A
A27: 手工三線 (ET-55) | B27: =VLOOKUP(D27,廠價表!$C$1:$E$43,2,0) -> #N/A | F27: =VLOOKUP(D27,廠價表!$C$1:$E$43,3,0) -> #N/A | G27: 2263 | H27: =F27*G27 -> #N/A | J27: =VLOOKUP(D27,產線配置圖!$A$3:$C$40,2,0) -> #N/A | K27: =VLOOKUP(D27,產線配置圖!$A$3:$C$40,3,0) -> #N/A | L27: =K27/J27 -> #N/A | M27: 14 | N27: =G27/W27*60 -> 1212.3214 | O27: =N27/M27 -> 86.594388 | P27: =M27-J27 -> #N/A | Q27: =O27-L27 -> #N/A | R27: =O27/L27 -> #N/A | S27: =R37 -> #N/A | T27: 0.29166667 | U27: 0.36944444 | W27: =(U27-T27)*24*60 -> 112 | AF27: =N27-K27 -> #N/A | AG27: =N27/K27 -> #N/A | AH27: =AG37 -> #N/A
B28: =VLOOKUP(D28,廠價表!$C$1:$E$43,2,0) -> #N/A | F28: =VLOOKUP(D28,廠價表!$C$1:$E$43,3,0) -> #N/A | G28: 1180 | H28: =F28*G28 -> #N/A | J28: =VLOOKUP(D28,產線配置圖!$A$3:$C$40,2,0) -> #N/A | K28: =VLOOKUP(D28,產線配置圖!$A$3:$C$40,3,0) -> #N/A | L28: =K28/J28 -> #N/A | M28: 16 | N28: =G28/W28*60 -> 1089.2308 | O28: =N28/M28 -> 68.076923 | P28: =M28-J28 -> #N/A | Q28: =O28-L28 -> #N/A | R28: =O28/L28 -> #N/A | T28: 0.375 | U28: 0.42013889 | V28: =(T28-U27)*24*60 -> 8 | W28: =(U28-T28)*24*60 -> 65 | AF28: =N28-K28 -> #N/A | AG28: =N28/K28 -> #N/A
B29: =VLOOKUP(D29,廠價表!$C$1:$E$43,2,0) -> #N/A | F29: =VLOOKUP(D29,廠價表!$C$1:$E$43,3,0) -> #N/A | G29: 3398 | H29: =F29*G29 -> #N/A | J29: =VLOOKUP(D29,產線配置圖!$A$3:$C$40,2,0) -> #N/A | K29: =VLOOKUP(D29,產線配置圖!$A$3:$C$40,3,0) -> #N/A | L29: =K29/J29 -> #N/A | M29: 14 | N29: =G29/W29*60 -> 3136.6154 | O29: =N29/M29 -> 224.04396 | P29: =M29-J29 -> #N/A | Q29: =O29-L29 -> #N/A | R29: =O29/L29 -> #N/A | T29: 0.43055556 | U29: 0.47569444 | V29: =(T29-U28)*24*60 -> 15 | W29: =(U29-T29)*24*60 -> 65 | AF29: =N29-K29 -> #N/A | AG29: =N29/K29 -> #N/A
T30: 0.53958333 | U30: 0.56944444 | V30: =(T30-U29)*24*60 -> 92 | W30: =(U30-T30)*24*60 -> 43 | X30: 0.49652778 | Y30: 0.53819444 | AF30: =N30-K30 -> 0 | AG30: =N30/K30 -> #DIV/0!
W31: =(U31-T31)*24*60 -> 0 | AF31: =N31-K31 -> 0 | AG31: =N31/K31 -> #DIV/0!
W32: =(U32-T32)*24*60 -> 0
W33: =(U33-T33)*24*60 -> 0
W34: =(U34-T34)*24*60 -> 0
W35: =(U35-T35)*24*60 -> 0
H36: =F36*G36 -> 0 | W36: =(U36-T36)*24*60 -> 0
C37: 4度二組B | D37: 平均 | J37: =AVERAGE(J27:J36) -> #N/A | K37: =AVERAGE(K27:K36) -> #N/A | L37: =AVERAGE(L27:L36) -> #N/A | M37: =AVERAGE(M27:M36) -> 14.666667 | N37: =AVERAGE(N27:N36) -> 1812.7225 | O37: =AVERAGE(O27:O36) -> 126.23842 | P37: =M37-J37 -> #N/A | Q37: =N37-K37 -> #N/A | R37: =O37/L37 -> #N/A | Z37: =SUM(Z27:Z36) -> 0 | AA37: =SUM(AA27:AA36) -> 0 | AD37: =SUM(AD27:AD36) -> 0 | AE37: =SUM(AE27:AE36) -> 0 | AF37: =N37-K37 -> #N/A | AG37: =N37/K37 -> #N/A
A38: 手工四線 (ET-55) | B38: =VLOOKUP(D38,廠價表!$C$1:$E$43,2,0) -> #N/A | F38: =VLOOKUP(D38,廠價表!$C$1:$E$43,3,0) -> #N/A | G38: 2263 | H38: =F38*G38 -> #N/A | J38: =VLOOKUP(D38,產線配置圖!$A$3:$C$40,2,0) -> #N/A | K38: =VLOOKUP(D38,產線配置圖!$A$3:$C$40,3,0) -> #N/A | L38: =K38/J38 -> #N/A | M38: 14 | N38: =G38/W38*60 -> 1967.8261 | O38: =N38/M38 -> 140.55901 | P38: =M38-J38 -> #N/A | Q38: =O38-L38 -> #N/A | R38: =O38/L38 -> #N/A | S38: =R48 -> #N/A | T38: 0.33333333 | U38: 0.38125 | W38: =(U38-T38)*24*60 -> 69 | AF38: =N38-K38 -> #N/A | AG38: =N38/K38 -> #N/A | AH38: =AG48 -> #N/A
B39: =VLOOKUP(D39,廠價表!$C$1:$E$43,2,0) -> #N/A | F39: =VLOOKUP(D39,廠價表!$C$1:$E$43,3,0) -> #N/A | G39: 1180 | H39: =F39*G39 -> #N/A | J39: =VLOOKUP(D39,產線配置圖!$A$3:$C$40,2,0) -> #N/A | K39: =VLOOKUP(D39,產線配置圖!$A$3:$C$40,3,0) -> #N/A | L39: =K39/J39 -> #N/A | M39: 14 | N39: =G39/W39*60 -> 885 | O39: =N39/M39 -> 63.214286 | P39: =M39-J39 -> #N/A | Q39: =O39-L39 -> #N/A | R39: =O39/L39 -> #N/A | T39: 0.38888889 | U39: 0.44444444 | V39: =(T39-U38)*24*60 -> 11 | W39: =(U39-T39)*24*60 -> 80 | AF39: =N39-K39 -> #N/A | AG39: =N39/K39 -> #N/A
B40: =VLOOKUP(D40,廠價表!$C$1:$E$43,2,0) -> #N/A | F40: =VLOOKUP(D40,廠價表!$C$1:$E$43,3,0) -> #N/A | G40: 3398 | H40: =F40*G40 -> #N/A | J40: =VLOOKUP(D40,產線配置圖!$A$3:$C$40,2,0) -> #N/A | K40: =VLOOKUP(D40,產線配置圖!$A$3:$C$40,3,0) -> #N/A | L40: =K40/J40 -> #N/A | M40: 14 | N40: =G40/W40*60 -> 1853.4545 | O40: =N40/M40 -> 132.38961 | P40: =M40-J40 -> #N/A | Q40: =O40-L40 -> #N/A | R40: =O40/L40 -> #N/A | T40: 0.52777778 | U40: 0.60416667 | V40: =(T40-U39)*24*60 -> 120 | W40: =(U40-T40)*24*60 -> 110 | AF40: =N40-K40 -> #N/A | AG40: =N40/K40 -> #N/A
...

Sheet 1001總
B1: 長家廠組合室生產人時性分析
B3: 日期 | D3: 46296 | F3: 訂單量 | G3: =範本!E1 -> 43309 | I3: 營業額 | J3: =範本!G1 -> #N/A
B4: 項目 | D4: 3 | F4: ➀ | H4: ➁ | J4: ③ | L4: 異常停線 | N4: 短暫停線
B5: 人時性 | D5: 組合室 | F5: 全溫層 | H5: 義大利麵 | J5: 袋裝小吃、義麵 | L5: 合計次數 | M5: 時間 | N5: 合計次數 | O5: 設備次數
D6: 排關平均 | F6: =AVERAGE(D13:J13) -> 126.6107 | H6: =AVERAGE(D13:H13) -> 124.64367 | J6: =AVERAGE(I13:J13) -> 131.52826 | L6: =範本!Z2 -> 0 | M6: =範本!AA2 -> 0 | N6: =範本!AD2 -> 0 | O6: =範本!AE2 -> 0
D7: 實績平均 | F7: =AVERAGE(D14:J14) -> 112.96093 | H7: =AVERAGE(D14:H14) -> 111.92406 | J7: =AVERAGE(I14:J14) -> 115.5531
D8: 達成率平均 | F8: =AVERAGE(D15:J15) -> 0.89664475 | H8: =AVERAGE(D15:H15) -> 0.90303963 | J8: =AVERAGE(I15:J15) -> 0.88065755
J9: ※現行日本鮮食廠以達成率80%為基本(即為現行KPI)
B10: 溫層 | D10: 4度C-各編組展開
B11: 編組 | D11: 1 | E11: 2 | F11: 3 | G11: 4 | H11: 5 | I11: 6 | J11: 7
D12: 自動1線 | E12: 自動2線 | F12: 手工3線 | G12: 手工4線 | H12: 手工5線 | I12: 調理包1線 | J12: 調理包2線
B13: 人時性 | C13: 排關 | D13: =VALUE('1001'!L15) -> 163.80495 | E13: =VALUE('1001'!L26) -> 169.64286 | F13: =VALUE('1001'!L37) -> 90.888889 | G13: =VALUE('1001'!L48) -> 99.006944 | H13: =VALUE('1001'!L58) -> 99.874728 | I13: =VALUE('1001'!L69) -> 140.79515 | J13: ='1001'!L79 -> 122.26136
C14: 實績 | D14: =VALUE('1001'!O15) -> 145.41056 | E14: =VALUE('1001'!O26) -> 148.59794 | F14: =VALUE('1001'!O37) -> 84.788652 | G14: =VALUE('1001'!O48) -> 93.037436 | H14: =VALUE('1001'!O58) -> 87.785714 | I14: =VALUE('1001'!O69) -> 119.76473 | J14: ='1001'!O79 -> 111.34148
C15: 達成率 | D15: =D14/D13 -> 0.88770555 | E15: =E14/E13 -> 0.87594574 | F15: =F14/F13 -> 0.93288248 | G15: =G14/G13 -> 0.93970616 | H15: =H14/H13 -> 0.87895823 | I15: =I14/I13 -> 0.85063103 | J15: ='1001'!S70 -> 0.91068407
B16: 作業 時間 | C16: 開始 | D16: ='1001'!T5 -> 0.29166667 | E16: ='1001'!T16 -> 0.29166667 | F16: ='1001'!T27 -> 0.29166667 | G16: ='1001'!T38 -> 0.33333333 | H16: ='1001'!T49 -> 0.29166667 | I16: ='1001'!T59 -> 0.29513889 | J16: ='1001'!T70 -> 0.33333333
C17: 結束 | D17: 0.59513889 | E17: 0.55833333 | F17: 0.5625 | G17: 0.47777778 | H17: 0.59722222 | I17: 0.61111111 | J17: 0.48472222
B18: 產線異常 (5分鐘以上) | C18: 次數 | D18: ='1001'!Z15 -> 0 | E18: ='1001'!Z26 -> 0 | F18: ='1001'!Z37 -> 0 | G18: ='1001'!Z48 -> 0 | H18: ='1001'!Z58 -> 0 | I18: ='1001'!Z69 -> 0 | J18: ='1001'!AA79 -> 0
C19: 時間/分 | D19: ='1001'!AA15 -> 0 | E19: ='1001'!AA26 -> 0 | F19: ='1001'!AA37 -> 0 | G19: ='1001'!AA48 -> 0 | H19: ='1001'!AA58 -> 0 | I19: ='1001'!AA69 -> 0 | J19: ='1001'!AB79 -> 0
B20: 短暫停線 (5分鐘以下) | C20: 次數 | D20: ='1001'!AD15 -> 0 | E20: ='1001'!AD26 -> 0 | F20: ='1001'!AD37 -> 0 | G20: ='1001'!AD48 -> 0 | H20: ='1001'!AD58 -> 0 | I20: ='1001'!AD69 -> 0 | J20: ='1001'!AD79 -> 0
C21: 設備次數 | D21: ='1001'!AE15 -> 0 | E21: ='1001'!AE26 -> 0 | F21: ='1001'!AE37 -> 0 | G21: ='1001'!AE48 -> 0 | H21: ='1001'!AE58 -> 0 | I21: ='1001'!AE69 -> 0 | J21: ='1001'!AE79 -> 0
B22: 配置人數 | D22: =VALUE(範本!M15) -> 15 | E22: =VALUE(範本!M26) -> 12.666667 | F22: =VALUE(範本!M37) -> 14.666667 | G22: =VALUE(範本!M48) -> 14 | H22: =VALUE(範本!M58) -> 17.666667 | I22: =VALUE(範本!M69) -> 12.333333 | J22: =範本!M79 -> 11
B23: 主要應用設備 | D23: ET-600 | E23: ET-600 | F23: ET-55 | G23: ET-55 | H23: ET-55 | I23: 八爪機
B24: 次要應用設備 | H24: 封口機
B25: 備註

Sheet 1001
A1: 長家廠4度C日報分析 | D1: 總生產量 | E1: =SUM(G5:G79) -> 52428 | F1: 營業額 | G1: =SUM(H5:H79) -> 2482994.3 | H1: 出勤人數 | I1: =M15+M26+M48+M58+M69+M79+M37 -> 98.383333 | J1: 產線配置圖 | M1: 生產實績 | P1: 人時性差異分析 | T1: 日報登錄 | Z1: 合計 次數 | AA1: 合計 時間/分 | AB1: 分析說明 | AD1: 合計 次數 | AE1: 合計 設備次數 | AF1: 產能差異分析
A2: 10月1日 星期四 | D2: 人時性 | E2: =AVERAGE(O15,O26,O37,O48,O58,O69,O79) -> 112.96093 | F2: 平均廠價 | G2: =G1/E1 -> 47.360081 | H2: 多次生產數 | I2: =COUNT(I5:I79) -> 0 | Z2: =Z15+Z26+Z37+Z48+Z58+Z69+Z79 -> 0 | AA2: =AA15+AA26+AA37+AA48+AA58+AA69+AA79 -> 0 | AD2: =AD15+AD26+AD37+AD48+AD58+AD69+AD79 -> 0 | AE2: =AE15+AE26+AE37+AE48+AE58+AE69+AE79 -> 0
A3: 線別 | B3: 品類 | D3: 品名 | F3: 廠價 | G3: 生產量 | H3: 營收 | I3: 多次 生產 | J3: 人數 | K3: 產能/時 | L3: 人時性 | M3: 人數 | N3: 產能/時 | O3: 人時性 | P3: 人數 | Q3: 人時性 | R3: 達成率 | S3: 達成率平均 | T3: 生產時間 | V3: 前置、換線時間/分 | W3: 稼動時間/分 | X3: 休息時間 | Z3: 產線異常統計 (5分鐘以上) | AD3: 短暫停線統計 (5分鐘以下) | AF3: 產能/時 | AG3: 達成率 | AH3: 達成率平均
T4: 開始 | U4: 結束 | X4: 開始 | Y4: 結束 | Z4: 次數 | AA4: 時間/分 | AD4: 總次數 | AE4: 設備因素(次數)
A5: 自動一線 (ET-600) | B5: 義大利麵 | D5: 白酒清炒鮮蛤義大利麵 | F5: =VLOOKUP(D5,廠價表!$C$1:$E$43,3,0) -> 56.87 | G5: 4607 | H5: =F5*G5 -> 262000.09 | J5: =VLOOKUP(D5,產線配置圖!$A$3:$C$40,2,0) -> 14 | K5: =VLOOKUP(D5,產線配置圖!$A$3:$C$40,3,0) -> 2250 | L5: =K5/J5 -> 160.71429 | M5: 14 | N5: =G5/W5*60 -> 2176.5354 | O5: =N5/M5 -> 155.46682 | P5: =M5-J5 -> 0 | Q5: =O5-L5 -> -5.2474691 | R5: =O5/L5 -> 0.96734908 | S5: =R15 -> 0.88770555 | T5: 0.29166667 | U5: 0.37986111 | W5: =(U5-T5)*24*60 -> 127 | AF5: =N5-K5 -> -73.464567 | AG5: =N5/K5 -> 0.96734908 | AH5: =AG15 -> 0.88819989
B6: 義大利麵 | D6: 香煎魚排佐檸檬奶油義大利麵 | F6: =VLOOKUP(D6,廠價表!$C$1:$E$43,3,0) -> 58.17 | G6: 1293 | H6: =F6*G6 -> 75213.81 | J6: =VLOOKUP(D6,產線配置圖!$A$3:$C$40,2,0) -> 13 | K6: =VLOOKUP(D6,產線配置圖!$A$3:$C$40,3,0) -> 2250 | L6: =K6/J6 -> 173.07692 | M6: 13 | N6: =G6/W6*60 -> 1939.5 | O6: =N6/M6 -> 149.19231 | P6: =M6-J6 -> 0 | Q6: =O6-L6 -> -23.884615 | R6: =O6/L6 -> 0.862 | T6: 0.38541667 | U6: 0.41319444 | V6: =(T6-U5)*24*60 -> 8 | W6: =(U6-T6)*24*60 -> 40 | AF6: =N6-K6 -> -310.5 | AG6: =N6/K6 -> 0.862
B7: 義大利麵 | D7: 奶油培根義大利麵 | F7: =VLOOKUP(D7,廠價表!$C$1:$E$43,3,0) -> 49.14 | G7: 2169 | H7: =F7*G7 -> 106584.66 | J7: =VLOOKUP(D7,產線配置圖!$A$3:$C$40,2,0) -> 14 | K7: =VLOOKUP(D7,產線配置圖!$A$3:$C$40,3,0) -> 2250 | L7: =K7/J7 -> 160.71429 | M7: 14 | N7: =G7/W7*60 -> 1859.1429 | O7: =N7/M7 -> 132.79592 | P7: =M7-J7 -> 0 | Q7: =O7-L7 -> -27.918367 | R7: =O7/L7 -> 0.82628571 | T7: 0.42013889 | U7: 0.46875 | V7: =(T7-U6)*24*60 -> 10 | W7: =(U7-T7)*24*60 -> 70 | AF7: =N7-K7 -> -390.85714 | AG7: =N7/K7 -> 0.82628571
B8: 義大利麵 | D8: 奶油培根義大利麵 | F8: =VLOOKUP(D8,廠價表!$C$1:$E$43,3,0) -> 49.14 | G8: 2927 | H8: =F8*G8 -> 143832.78 | J8: =VLOOKUP(D8,產線配置圖!$A$3:$C$40,2,0) -> 14 | K8: =VLOOKUP(D8,產線配置圖!$A$3:$C$40,3,0) -> 2250 | L8: =K8/J8 -> 160.71429 | M8: 14 | N8: =G8/W8*60 -> 2018.6207 | O8: =N8/M8 -> 144.18719 | P8: =M8-J8 -> 0 | Q8: =O8-L8 -> -16.527094 | R8: =O8/L8 -> 0.89716475 | T8: 0.53472222 | U8: 0.59513889 | V8: =(T8-U7)*24*60 -> 95 | W8: =(U8-T8)*24*60 -> 87 | AF8: =N8-K8 -> -231.37931 | AG8: =N8/K8 -> 0.89716475
W9: =(U9-T9)*24*60 -> 0 | AF9: =N9-K9 -> 0 | AG9: =N9/K9 -> #DIV/0!
W10: =(U10-T10)*24*60 -> 0 | AF10: =N10-K10 -> 0 | AG10: =N10/K10 -> #DIV/0!
W11: =(U11-T11)*24*60 -> 0 | AF11: =N11-K11 -> 0 | AG11: =N11/K11 -> #DIV/0!
W12: =(U12-T12)*24*60 -> 0
W13: =(U13-T13)*24*60 -> 0
W14: =(U14-T14)*24*60 -> 0
C15: 4度一組 | D15: 平均 | J15: =AVERAGE(J5:J14) -> 13.75 | K15: =AVERAGE(K5:K14) -> 2250 | L15: =AVERAGE(L5:L14) -> 163.80495 | M15: =AVERAGE(M5:M14) -> 13.75 | N15: =AVERAGE(N5:N14) -> 1998.4497 | O15: =AVERAGE(O5:O14) -> 145.41056 | P15: =M15-J15 -> 0 | Q15: =O15-L15 -> -18.394386 | R15: =O15/L15 -> 0.88770555 | Z15: =SUM(Z5:Z14) -> 0 | AA15: =SUM(AA5:AA14) -> 0 | AD15: =SUM(AD5:AD14) -> 0 | AE15: =SUM(AE5:AE14) -> 0 | AF15: =N15-K15 -> -251.55026 | AG15: =N15/K15 -> 0.88819989
A16: 自動二線 (ET-600) | B16: 義大利麵 | D16: 青醬蛤蜊義大利麵 | F16: =VLOOKUP(D16,廠價表!$C$1:$E$43,3,0) -> 50.67 | G16: 3755 | H16: =F16*G16 -> 190265.85 | J16: =VLOOKUP(D16,產線配置圖!$A$3:$C$40,2,0) -> 14 | K16: =VLOOKUP(D16,產線配置圖!$A$3:$C$40,3,0) -> 2250 | L16: =K16/J16 -> 160.71429 | M16: 14 | N16: =G16/W16*60 -> 2125.4717 | O16: =N16/M16 -> 151.81941 | P16: =M16-J16 -> 0 | Q16: =O16-L16 -> -8.8948787 | R16: =O16/L16 -> 0.94465409 | S16: =R26 -> 0.87594574 | T16: 0.29166667 | U16: 0.36527778 | W16: =(U16-T16)*24*60 -> 106 | AF16: =N16-K16 -> -124.5283 | AG16: =N16/K16 -> 0.94465409 | AH16: =AG26 -> 0.87666613
B17: 義大利麵 | D17: 義式蕃茄起司義大利麵 | F17: =VLOOKUP(D17,廠價表!$C$1:$E$43,3,0) -> 50.39 | G17: 4563 | H17: =F17*G17 -> 229929.57 | J17: =VLOOKUP(D17,產線配置圖!$A$3:$C$40,2,0) -> 12 | K17: =VLOOKUP(D17,產線配置圖!$A$3:$C$40,3,0) -> 2250 | L17: =K17/J17 -> 187.5 | M17: 12 | N17: =G17/W17*60 -> 1941.7021 | O17: =N17/M17 -> 161.80851 | P17: =M17-J17 -> 0 | Q17: =O17-L17 -> -25.691489 | R17: =O17/L17 -> 0.86297872 | T17: 0.37291667 | U17: 0.47083333 | V17: =(T17-U16)*24*60 -> 11 | W17: =(U17-T17)*24*60 -> 141 | AF17: =N17-K17 -> -308.29787 | AG17: =N17/K17 -> 0.86297872
B18: 義大利麵 | D18: 白酒清炒鮮蛤義大利麵 | F18: =VLOOKUP(D18,廠價表!$C$1:$E$43,3,0) -> 56.87 | G18: 956 | H18: =F18*G18 -> 54367.72 | J18: =VLOOKUP(D18,產線配置圖!$A$3:$C$40,2,0) -> 14 | K18: =VLOOKUP(D18,產線配置圖!$A$3:$C$40,3,0) -> 2250 | L18: =K18/J18 -> 160.71429 | M18: 14 | N18: =G18/W18*60 -> 1850.3226 | O18: =N18/M18 -> 132.1659 | P18: =M18-J18 -> 0 | Q18: =O18-L18 -> -28.548387 | R18: =O18/L18 -> 0.82236559 | T18: 0.53680556 | U18: 0.55833333 | V18: =(T18-U17)*24*60 -> 95 | W18: =(U18-T18)*24*60 -> 31 | AF18: =N18-K18 -> -399.67742 | AG18: =N18/K18 -> 0.82236559
W19: =(U19-T19)*24*60 -> 0 | AF19: =N19-K19 -> 0 | AG19: =N19/K19 -> #DIV/0!
W20: =(U20-T20)*24*60 -> 0
W21: =(U21-T21)*24*60 -> 0
W22: 0
W23: =(U23-T23)*24*60 -> 0
H24: =F24*G24 -> 0 | W24: =(U24-T24)*24*60 -> 0
H25: =F25*G25 -> 0 | W25: =(U25-T25)*24*60 -> 0
C26: 4度二組A | D26: 平均 | J26: =AVERAGE(J16:J25) -> 13.333333 | K26: =AVERAGE(K16:K25) -> 2250 | L26: =AVERAGE(L16:L25) -> 169.64286 | M26: =AVERAGE(M16:M25) -> 13.333333 | N26: =AVERAGE(N16:N25) -> 1972.4988 | O26: =AVERAGE(O16:O25) -> 148.59794 | P26: =M26-J26 -> 0 | Q26: =O26-L26 -> -21.044918 | R26: =O26/L26 -> 0.87594574 | Z26: =SUM(Z16:Z25) -> 0 | AA26: =SUM(AA16:AA25) -> 0 | AD26: =SUM(AD16:AD25) -> 0 | AE26: =SUM(AE16:AE25) -> 0 | AF26: =N26-K26 -> -277.5012 | AG26: =N26/K26 -> 0.87666613
A27: 手工三線 (ET-55) | B27: 義大利麵 | D27: 燻鴨佐白蘭地義大利麵 | F27: =VLOOKUP(D27,廠價表!$C$1:$E$43,3,0) -> 61.65 | G27: 2936 | H27: =F27*G27 -> 181004.4 | J27: =VLOOKUP(D27,產線配置圖!$A$3:$C$40,2,0) -> 18 | K27: =VLOOKUP(D27,產線配置圖!$A$3:$C$40,3,0) -> 1636 | L27: =K27/J27 -> 90.888889 | M27: 16 | N27: =G27/W27*60 -> 1409.28 | O27: =N27/M27 -> 88.08 | P27: =M27-J27 -> -2 | Q27: =O27-L27 -> -2.8088889 | R27: =O27/L27 -> 0.96909535 | S27: =R37 -> 0.93288248 | T27: 0.29166667 | U27: 0.37847222 | W27: =(U27-T27)*24*60 -> 125 | AF27: =N27-K27 -> -226.72 | AG27: =N27/K27 -> 0.86141809 | AH27: =AG37 -> 0.86310946
B28: 義大利麵 | D28: 拿坡里燻腸義大利麵 | F28: =VLOOKUP(D28,廠價表!$C$1:$E$43,3,0) -> 52.21 | G28: 2805 | H28: =F28*G28 -> 146449.05 | J28: =VLOOKUP(D28,產線配置圖!$A$3:$C$40,2,0) -> 18 | K28: =VLOOKUP(D28,產線配置圖!$A$3:$C$40,3,0) -> 1636 | L28: =K28/J28 -> 90.888889 | M28: 17 | N28: =G28/W28*60 -> 1476.3158 | O28: =N28/M28 -> 86.842105 | P28: =M28-J28 -> -1 | Q28: =O28-L28 -> -4.0467836 | R28: =O28/L28 -> 0.95547549 | T28: 0.38333333 | U28: 0.4625 | V28: =(T28-U27)*24*60 -> 7 | W28: =(U28-T28)*24*60 -> 114 | AF28: =N28-K28 -> -159.68421 | AG28: =N28/K28 -> 0.90239351
B29: 義大利麵 | D29: 拿坡里燻腸義大利麵 | F29: =VLOOKUP(D29,廠價表!$C$1:$E$43,3,0) -> 52.21 | G29: 1238 | H29: =F29*G29 -> 64635.98 | J29: =VLOOKUP(D29,產線配置圖!$A$3:$C$40,2,0) -> 18 | K29: =VLOOKUP(D29,產線配置圖!$A$3:$C$40,3,0) -> 1636 | L29: =K29/J29 -> 90.888889 | M29: 17 | N29: =G29/W29*60 -> 1350.5455 | O29: =N29/M29 -> 79.44385 | P29: =M29-J29 -> -1 | Q29: =O29-L29 -> -11.445039 | R29: =O29/L29 -> 0.87407659 | T29: 0.52430556 | U29: 0.5625 | V29: =(T29-U28)*24*60 -> 89 | W29: =(U29-T29)*24*60 -> 55 | AF29: =N29-K29 -> -285.45455 | AG29: =N29/K29 -> 0.82551678
W30: =(U30-T30)*24*60 -> 0 | AF30: =N30-K30 -> 0 | AG30: =N30/K30 -> #DIV/0!
W31: =(U31-T31)*24*60 -> 0 | AF31: =N31-K31 -> 0 | AG31: =N31/K31 -> #DIV/0!
W32: =(U32-T32)*24*60 -> 0
W33: =(U33-T33)*24*60 -> 0
W34: =(U34-T34)*24*60 -> 0
W35: =(U35-T35)*24*60 -> 0
H36: =F36*G36 -> 0 | W36: =(U36-T36)*24*60 -> 0
C37: 4度二組B | D37: 平均 | J37: =AVERAGE(J27:J36) -> 18 | K37: =AVERAGE(K27:K36) -> 1636 | L37: =AVERAGE(L27:L36) -> 90.888889 | M37: =AVERAGE(M27:M36) -> 16.666667 | N37: =AVERAGE(N27:N36) -> 1412.0471 | O37: =AVERAGE(O27:O36) -> 84.788652 | P37: =M37-J37 -> -1.3333333 | Q37: =N37-K37 -> -223.95292 | R37: =O37/L37 -> 0.93288248 | Z37: =SUM(Z27:Z36) -> 0 | AA37: =SUM(AA27:AA36) -> 0 | AD37: =SUM(AD27:AD36) -> 0 | AE37: =SUM(AE27:AE36) -> 0 | AF37: =N37-K37 -> -223.95292 | AG37: =N37/K37 -> 0.86310946
A38: 手工四線 (ET-55) | B38: 熱乾麵 | D38: 青花椒麻雞肉拌麵 | F38: =VLOOKUP(D38,廠價表!$C$1:$E$43,3,0) -> 49.91 | G38: 2031 | H38: =F38*G38 -> 101367.21 | J38: =VLOOKUP(D38,產線配置圖!$A$3:$C$40,2,0) -> 16 | K38: =VLOOKUP(D38,產線配置圖!$A$3:$C$40,3,0) -> 1714 | L38: =K38/J38 -> 107.125 | M38: 16 | N38: =G38/W38*60 -> 1582.5974 | O38: =N38/M38 -> 98.912338 | P38: =M38-J38 -> 0 | Q38: =O38-L38 -> -8.2126623 | R38: =O38/L38 -> 0.92333571 | S38: =R48 -> 0.93970616 | T38: 0.33333333 | U38: 0.38680556 | W38: =(U38-T38)*24*60 -> 77 | AF38: =N38-K38 -> -131.4026 | AG38: =N38/K38 -> 0.92333571 | AH38: =AG48 -> 0.94075314
B39: 熱乾麵 | D39: 府城鹽水意麵 | F39: =VLOOKUP(D39,廠價表!$C$1:$E$43,3,0) -> 44.3 | G39: 3164 | H39: =F39*G39 -> 140165.2 | J39: =VLOOKUP(D39,產線配置圖!$A$3:$C$40,2,0) -> 18 | K39: =VLOOKUP(D39,產線配置圖!$A$3:$C$40,3,0) -> 1636 | L39: =K39/J39 -> 90.888889 | M39: 18 | N39: =G39/W39*60 -> 1568.9256 | O39: =N39/M39 -> 87.162534 | P39: =M39-J39 -> 0 | Q39: =O39-L39 -> -3.7263545 | R39: =O39/L39 -> 0.95900099 | T39: 0.39375 | U39: 0.47777778 | V39: =(T39-U38)*24*60 -> 10 | W39: =(U39-T39)*24*60 -> 121 | AF39: =N39-K39 -> -67.07438 | AG39: =N39/K39 -> 0.95900099
W40: =(U40-T40)*24*60 -> 0 | AF40: =N40-K40 -> 0 | AG40: =N40/K40 -> #DIV/0!
...

Sheet 1002總
B1: 長家廠組合室生產人時性分析
B3: 日期 | D3: 46297 | F3: 訂單量 | G3: =範本!E1 -> 43309 | I3: 營業額 | J3: =範本!G1 -> #N/A
B4: 項目 | D4: 3 | F4: ➀ | H4: ➁ | J4: ③ | L4: 異常停線 | N4: 短暫停線
B5: 人時性 | D5: 組合室 | F5: 全溫層 | H5: 義大利麵 | J5: 袋裝小吃、義麵 | L5: 合計次數 | M5: 時間 | N5: 合計次數 | O5: 設備次數
D6: 排關平均 | F6: =AVERAGE(D13:J13) -> 130.93755 | H6: =AVERAGE(D13:H13) -> 127.0956 | J6: =AVERAGE(I13:J13) -> 140.54242 | L6: =範本!Z2 -> 0 | M6: =範本!AA2 -> 0 | N6: =範本!AD2 -> 0 | O6: =範本!AE2 -> 0
D7: 實績平均 | F7: =AVERAGE(D14:J14) -> 114.46453 | H7: =AVERAGE(D14:H14) -> 108.89261 | J7: =AVERAGE(I14:J14) -> 128.39431
D8: 達成率平均 | F8: =AVERAGE(D15:J15) -> 0.87855005 | H8: =AVERAGE(D15:H15) -> 0.86465192 | J8: =AVERAGE(I15:J15) -> 0.91329539
J9: ※現行日本鮮食廠以達成率80%為基本(即為現行KPI)
B10: 溫層 | D10: 4度C-各編組展開
B11: 編組 | D11: 1 | E11: 2 | F11: 3 | G11: 4 | H11: 5 | I11: 6 | J11: 7
D12: 自動1線 | E12: 自動2線 | F12: 手工3線 | G12: 手工4線 | H12: 手工5線 | I12: 調理包1線 | J12: 調理包2線
B13: 人時性 | C13: 排關 | D13: =VALUE('1002'!L15) -> 164.83516 | E13: =VALUE('1002'!L26) -> 174.10714 | F13: =VALUE('1002'!L37) -> 93.161111 | G13: =VALUE('1002'!L48) -> 99.006944 | H13: =VALUE('1002'!L58) -> 104.36765 | I13: =VALUE('1002'!L69) -> 138.81212 | J13: ='1002'!L79 -> 142.27273
C14: 實績 | D14: =VALUE('1002'!O15) -> 135.46971 | E14: =VALUE('1002'!O26) -> 146.55215 | F14: =VALUE('1002'!O37) -> 85.599074 | G14: =VALUE('1002'!O48) -> 89.499118 | H14: =VALUE('1002'!O58) -> 87.342996 | I14: =VALUE('1002'!O69) -> 123.76298 | J14: ='1002'!O79 -> 133.02564
C15: 達成率 | D15: =D14/D13 -> 0.82184959 | E15: =E14/E13 -> 0.84173544 | F15: =F14/F13 -> 0.91882839 | G15: =G14/G13 -> 0.90396809 | H15: =H14/H13 -> 0.83687808 | I15: =I14/I13 -> 0.89158628 | J15: ='1002'!S70 -> 0.93500451
B16: 作業 時間 | C16: 開始 | D16: ='1002'!T5 -> 0.29166667 | E16: ='1002'!T16 -> 0.29236111 | F16: ='1002'!T27 -> 0.29166667 | G16: ='1002'!T38 -> 0.33333333 | H16: ='1002'!T49 -> 0.29166667 | I16: ='1002'!T59 -> 0.29375 | J16: ='1002'!T70 -> 0.29166667
C17: 結束 | D17: 0.48125 | E17: 0.45486111 | F17: 0.61666667 | G17: 0.48263889 | H17: 0.46805556 | I17: 0.50347222 | J17: 0.38194444
B18: 產線異常 (5分鐘以上) | C18: 次數 | D18: ='1002'!Z15 -> 0 | E18: ='1002'!Z26 -> 0 | F18: ='1002'!Z37 -> 0 | G18: ='1002'!Z48 -> 0 | H18: ='1002'!Z58 -> 1 | I18: ='1002'!Z69 -> 0 | J18: ='1002'!AA79 -> 0
C19: 時間/分 | D19: ='1002'!AA15 -> 0 | E19: ='1002'!AA26 -> 0 | F19: ='1002'!AA37 -> 0 | G19: ='1002'!AA48 -> 0 | H19: ='1002'!AA58 -> 26 | I19: ='1002'!AA69 -> 0 | J19: ='1002'!AB79 -> 0
B20: 短暫停線 (5分鐘以下) | C20: 次數 | D20: ='1002'!AD15 -> 0 | E20: ='1002'!AD26 -> 0 | F20: ='1002'!AD37 -> 0 | G20: ='1002'!AD48 -> 0 | H20: ='1002'!AD58 -> 0 | I20: ='1002'!AD69 -> 0 | J20: ='1002'!AD79 -> 0
C21: 設備次數 | D21: ='1002'!AE15 -> 0 | E21: ='1002'!AE26 -> 0 | F21: ='1002'!AE37 -> 0 | G21: ='1002'!AE48 -> 0 | H21: ='1002'!AE58 -> 0 | I21: ='1002'!AE69 -> 0 | J21: ='1002'!AE79 -> 0
B22: 配置人數 | D22: =VALUE(範本!M15) -> 15 | E22: =VALUE(範本!M26) -> 12.666667 | F22: =VALUE(範本!M37) -> 14.666667 | G22: =VALUE(範本!M48) -> 14 | H22: =VALUE(範本!M58) -> 17.666667 | I22: =VALUE(範本!M69) -> 12.333333 | J22: =範本!M79 -> 11
B23: 主要應用設備 | D23: ET-600 | E23: ET-600 | F23: ET-55 | G23: ET-55 | H23: ET-55 | I23: 八爪機
B24: 次要應用設備 | H24: 封口機
B25: 備註

Sheet 1002
A1: 長家廠4度C日報分析 | D1: 總生產量 | E1: =SUM(G5:G79) -> 43337 | F1: 營業額 | G1: =SUM(H5:H79) -> 2052134.3 | H1: 出勤人數 | I1: =M15+M26+M48+M58+M69+M79+M37 -> 97.716667 | J1: 產線配置圖 | M1: 生產實績 | P1: 人時性差異分析 | T1: 日報登錄 | Z1: 合計 次數 | AA1: 合計 時間/分 | AB1: 分析說明 | AD1: 合計 次數 | AE1: 合計 設備次數 | AF1: 產能差異分析
A2: 10月2日 星期五 | D2: 人時性 | E2: =AVERAGE(O15,O26,O37,O48,O58,O69,O79) -> 114.46453 | F2: 平均廠價 | G2: =G1/E1 -> 47.352939 | H2: 多次生產數 | I2: =COUNT(I5:I79) -> 0 | Z2: =Z15+Z26+Z37+Z48+Z58+Z69+Z79 -> 1 | AA2: =AA15+AA26+AA37+AA48+AA58+AA69+AA79 -> 26 | AD2: =AD15+AD26+AD37+AD48+AD58+AD69+AD79 -> 0 | AE2: =AE15+AE26+AE37+AE48+AE58+AE69+AE79 -> 0
A3: 線別 | B3: 品類 | D3: 品名 | F3: 廠價 | G3: 生產量 | H3: 營收 | I3: 多次 生產 | J3: 人數 | K3: 產能/時 | L3: 人時性 | M3: 人數 | N3: 產能/時 | O3: 人時性 | P3: 人數 | Q3: 人時性 | R3: 達成率 | S3: 達成率平均 | T3: 生產時間 | V3: 前置、換線時間/分 | W3: 稼動時間/分 | X3: 休息時間 | Z3: 產線異常統計 (5分鐘以上) | AD3: 短暫停線統計 (5分鐘以下) | AF3: 產能/時 | AG3: 達成率 | AH3: 達成率平均
T4: 開始 | U4: 結束 | X4: 開始 | Y4: 結束 | Z4: 次數 | AA4: 時間/分 | AD4: 總次數 | AE4: 設備因素(次數)
A5: 自動一線 (ET-600) | B5: 義大利麵 | D5: 白酒清炒鮮蛤義大利麵 | F5: =VLOOKUP(D5,廠價表!$C$1:$E$43,3,0) -> 56.87 | G5: 2541 | H5: =F5*G5 -> 144506.67 | J5: =VLOOKUP(D5,產線配置圖!$A$3:$C$40,2,0) -> 14 | K5: =VLOOKUP(D5,產線配置圖!$A$3:$C$40,3,0) -> 2250 | L5: =K5/J5 -> 160.71429 | M5: 14 | N5: =G5/W5*60 -> 1905.75 | O5: =N5/M5 -> 136.125 | P5: =M5-J5 -> 0 | Q5: =O5-L5 -> -24.589286 | R5: =O5/L5 -> 0.847 | S5: =R15 -> 0.82184959 | T5: 0.29166667 | U5: 0.34722222 | W5: =(U5-T5)*24*60 -> 80 | AF5: =N5-K5 -> -344.25 | AG5: =N5/K5 -> 0.847 | AH5: =AG15 -> 0.82305853
B6: 義大利麵 | D6: 香煎魚排佐檸檬奶油義大利麵 | F6: =VLOOKUP(D6,廠價表!$C$1:$E$43,3,0) -> 58.17 | G6: 1133 | H6: =F6*G6 -> 65906.61 | J6: =VLOOKUP(D6,產線配置圖!$A$3:$C$40,2,0) -> 13 | K6: =VLOOKUP(D6,產線配置圖!$A$3:$C$40,3,0) -> 2250 | L6: =K6/J6 -> 173.07692 | M6: 13 | N6: =G6/W6*60 -> 1743.0769 | O6: =N6/M6 -> 134.08284 | P6: =M6-J6 -> 0 | Q6: =O6-L6 -> -38.994083 | R6: =O6/L6 -> 0.77470085 | T6: 0.35486111 | U6: 0.38194444 | V6: =(T6-U5)*24*60 -> 11 | W6: =(U6-T6)*24*60 -> 39 | AB6: 生產數量少 | AF6: =N6-K6 -> -506.92308 | AG6: =N6/K6 -> 0.77470085
B7: 義大利麵 | D7: 奶油培根義大利麵 | F7: =VLOOKUP(D7,廠價表!$C$1:$E$43,3,0) -> 49.14 | G7: 4195 | H7: =F7*G7 -> 206142.3 | J7: =VLOOKUP(D7,產線配置圖!$A$3:$C$40,2,0) -> 14 | K7: =VLOOKUP(D7,產線配置圖!$A$3:$C$40,3,0) -> 2250 | L7: =K7/J7 -> 160.71429 | M7: 14 | N7: =G7/W7*60 -> 1906.8182 | O7: =N7/M7 -> 136.2013 | P7: =M7-J7 -> 0 | Q7: =O7-L7 -> -24.512987 | R7: =O7/L7 -> 0.84747475 | T7: 0.38958333 | U7: 0.48125 | V7: =(T7-U6)*24*60 -> 11 | W7: =(U7-T7)*24*60 -> 132 | AF7: =N7-K7 -> -343.18182 | AG7: =N7/K7 -> 0.84747475
W8: =(U8-T8)*24*60 -> 0 | AF8: =N8-K8 -> 0 | AG8: =N8/K8 -> #DIV/0!
W9: =(U9-T9)*24*60 -> 0 | AF9: =N9-K9 -> 0 | AG9: =N9/K9 -> #DIV/0!
W10: =(U10-T10)*24*60 -> 0 | AF10: =N10-K10 -> 0 | AG10: =N10/K10 -> #DIV/0!
W11: =(U11-T11)*24*60 -> 0 | AF11: =N11-K11 -> 0 | AG11: =N11/K11 -> #DIV/0!
W12: =(U12-T12)*24*60 -> 0
W13: =(U13-T13)*24*60 -> 0
W14: =(U14-T14)*24*60 -> 0
C15: 4度一組 | D15: 平均 | J15: =AVERAGE(J5:J14) -> 13.666667 | K15: =AVERAGE(K5:K14) -> 2250 | L15: =AVERAGE(L5:L14) -> 164.83516 | M15: =AVERAGE(M5:M14) -> 13.666667 | N15: =AVERAGE(N5:N14) -> 1851.8817 | O15: =AVERAGE(O5:O14) -> 135.46971 | P15: =M15-J15 -> 0 | Q15: =O15-L15 -> -29.365452 | R15: =O15/L15 -> 0.82184959 | Z15: =SUM(Z5:Z14) -> 0 | AA15: =SUM(AA5:AA14) -> 0 | AD15: =SUM(AD5:AD14) -> 0 | AE15: =SUM(AE5:AE14) -> 0 | AF15: =N15-K15 -> -398.1183 | AG15: =N15/K15 -> 0.82305853
A16: 自動二線 (ET-600) | B16: 義大利麵 | D16: 青醬蛤蜊義大利麵 | F16: =VLOOKUP(D16,廠價表!$C$1:$E$43,3,0) -> 50.67 | G16: 3303 | H16: =F16*G16 -> 167363.01 | J16: =VLOOKUP(D16,產線配置圖!$A$3:$C$40,2,0) -> 14 | K16: =VLOOKUP(D16,產線配置圖!$A$3:$C$40,3,0) -> 2250 | L16: =K16/J16 -> 160.71429 | M16: 14 | N16: =G16/W16*60 -> 1962.1782 | O16: =N16/M16 -> 140.15559 | P16: =M16-J16 -> 0 | Q16: =O16-L16 -> -20.558699 | R16: =O16/L16 -> 0.87207921 | S16: =R26 -> 0.84173544 | T16: 0.29236111 | U16: 0.3625 | W16: =(U16-T16)*24*60 -> 101 | AF16: =N16-K16 -> -287.82178 | AG16: =N16/K16 -> 0.87207921 | AH16: =AG26 -> 0.84390285
B17: 義大利麵 | D17: 義式蕃茄起司義大利麵 | F17: =VLOOKUP(D17,廠價表!$C$1:$E$43,3,0) -> 50.39 | G17: 3579 | H17: =F17*G17 -> 180345.81 | J17: =VLOOKUP(D17,產線配置圖!$A$3:$C$40,2,0) -> 12 | K17: =VLOOKUP(D17,產線配置圖!$A$3:$C$40,3,0) -> 2250 | L17: =K17/J17 -> 187.5 | M17: 12 | N17: =G17/W17*60 -> 1835.3846 | O17: =N17/M17 -> 152.94872 | P17: =M17-J17 -> 0 | Q17: =O17-L17 -> -34.551282 | R17: =O17/L17 -> 0.8157265 | T17: 0.37361111 | U17: 0.45486111 | V17: =(T17-U16)*24*60 -> 16 | W17: =(U17-T17)*24*60 -> 117 | AF17: =N17-K17 -> -414.61538 | AG17: =N17/K17 -> 0.8157265
W18: =(U18-T18)*24*60 -> 0 | AF18: =N18-K18 -> 0 | AG18: =N18/K18 -> #DIV/0!
W19: =(U19-T19)*24*60 -> 0 | AF19: =N19-K19 -> 0 | AG19: =N19/K19 -> #DIV/0!
W20: =(U20-T20)*24*60 -> 0
W21: =(U21-T21)*24*60 -> 0
W22: 0
W23: =(U23-T23)*24*60 -> 0
H24: =F24*G24 -> 0 | W24: =(U24-T24)*24*60 -> 0
H25: =F25*G25 -> 0 | W25: =(U25-T25)*24*60 -> 0
C26: 4度二組A | D26: 平均 | J26: =AVERAGE(J16:J25) -> 13 | K26: =AVERAGE(K16:K25) -> 2250 | L26: =AVERAGE(L16:L25) -> 174.10714 | M26: =AVERAGE(M16:M25) -> 13 | N26: =AVERAGE(N16:N25) -> 1898.7814 | O26: =AVERAGE(O16:O25) -> 146.55215 | P26: =M26-J26 -> 0 | Q26: =O26-L26 -> -27.55499 | R26: =O26/L26 -> 0.84173544 | Z26: =SUM(Z16:Z25) -> 0 | AA26: =SUM(AA16:AA25) -> 0 | AD26: =SUM(AD16:AD25) -> 0 | AE26: =SUM(AE16:AE25) -> 0 | AF26: =N26-K26 -> -351.21858 | AG26: =N26/K26 -> 0.84390285
A27: 手工三線 (ET-55) | B27: 義大利麵 | D27: 燻鴨佐白蘭地義大利麵 | F27: =VLOOKUP(D27,廠價表!$C$1:$E$43,3,0) -> 61.65 | G27: 3504 | H27: =F27*G27 -> 216021.6 | J27: =VLOOKUP(D27,產線配置圖!$A$3:$C$40,2,0) -> 18 | K27: =VLOOKUP(D27,產線配置圖!$A$3:$C$40,3,0) -> 1636 | L27: =K27/J27 -> 90.888889 | M27: 16 | N27: =G27/W27*60 -> 1401.6 | O27: =N27/M27 -> 87.6 | P27: =M27-J27 -> -2 | Q27: =O27-L27 -> -3.2888889 | R27: =O27/L27 -> 0.96381418 | S27: =R37 -> 0.91882839 | T27: 0.29166667 | U27: 0.39583333 | W27: =(U27-T27)*24*60 -> 150 | AF27: =N27-K27 -> -234.4 | AG27: =N27/K27 -> 0.85672372 | AH27: =AG37 -> 0.8771619
B28: 義大利麵 | D28: 蕃茄莎莎海鮮冷義大利麵 | F28: =VLOOKUP(D28,廠價表!$C$1:$E$43,3,0) -> 46.34 | G28: 779 | H28: =F28*G28 -> 36098.86 | J28: =VLOOKUP(D28,產線配置圖!$A$3:$C$40,2,0) -> 16 | K28: =VLOOKUP(D28,產線配置圖!$A$3:$C$40,3,0) -> 1636 | L28: =K28/J28 -> 102.25 | M28: 16 | N28: =G28/W28*60 -> 1558 | O28: =N28/M28 -> 97.375 | P28: =M28-J28 -> 0 | Q28: =O28-L28 -> -4.875 | R28: =O28/L28 -> 0.95232274 | T28: 0.40138889 | U28: 0.42222222 | V28: =(T28-U27)*24*60 -> 8 | W28: =(U28-T28)*24*60 -> 30 | AF28: =N28-K28 -> -78 | AG28: =N28/K28 -> 0.95232274
B29: 義大利麵 | D29: 拿坡里燻腸義大利麵 | F29: =VLOOKUP(D29,廠價表!$C$1:$E$43,3,0) -> 52.21 | G29: 1619 | H29: =F29*G29 -> 84527.99 | J29: =VLOOKUP(D29,產線配置圖!$A$3:$C$40,2,0) -> 18 | K29: =VLOOKUP(D29,產線配置圖!$A$3:$C$40,3,0) -> 1636 | L29: =K29/J29 -> 90.888889 | M29: 17 | N29: =G29/W29*60 -> 1428.5294 | O29: =N29/M29 -> 84.031142 | P29: =M29-J29 -> -1 | Q29: =O29-L29 -> -6.857747 | R29: =O29/L29 -> 0.92454802 | T29: 0.42847222 | U29: 0.47569444 | V29: =(T29-U28)*24*60 -> 9 | W29: =(U29-T29)*24*60 -> 68 | AF29: =N29-K29 -> -207.47059 | AG29: =N29/K29 -> 0.87318424
B30: 義大利麵 | D30: 拿坡里燻腸義大利麵 | F30: =VLOOKUP(D30,廠價表!$C$1:$E$43,3,0) -> 52.21 | G30: 1769 | H30: =F30*G30 -> 92359.49 | J30: =VLOOKUP(D30,產線配置圖!$A$3:$C$40,2,0) -> 18 | K30: =VLOOKUP(D30,產線配置圖!$A$3:$C$40,3,0) -> 1636 | L30: =K30/J30 -> 90.888889 | M30: 18 | N30: =G30/W30*60 -> 1516.2857 | O30: =N30/M30 -> 84.238095 | P30: =M30-J30 -> 0 | Q30: =O30-L30 -> -6.6507937 | R30: =O30/L30 -> 0.92682501 | T30: 0.53472222 | U30: 0.58333333 | V30: =(T30-U29)*24*60 -> 85 | W30: =(U30-T30)*24*60 -> 70 | AF30: =N30-K30 -> -119.71429 | AG30: =N30/K30 -> 0.92682501
B31: 熱乾麵 | D31: 府城鹽水意麵 | F31: =VLOOKUP(D31,廠價表!$C$1:$E$43,3,0) -> 44.3 | G31: 826 | H31: =F31*G31 -> 36591.8 | J31: =VLOOKUP(D31,產線配置圖!$A$3:$C$40,2,0) -> 18 | K31: =VLOOKUP(D31,產線配置圖!$A$3:$C$40,3,0) -> 1636 | L31: =K31/J31 -> 90.888889 | M31: 17 | N31: =G31/W31*60 -> 1270.7692 | O31: =N31/M31 -> 74.751131 | P31: =M31-J31 -> -1 | Q31: =O31-L31 -> -16.137758 | R31: =O31/L31 -> 0.82244521 | T31: 0.58958333 | U31: 0.61666667 | V31: =(T31-U30)*24*60 -> 9 | W31: =(U31-T31)*24*60 -> 39 | AF31: =N31-K31 -> -365.23077 | AG31: =N31/K31 -> 0.77675381
W32: =(U32-T32)*24*60 -> 0
W33: =(U33-T33)*24*60 -> 0
W34: =(U34-T34)*24*60 -> 0
W35: =(U35-T35)*24*60 -> 0
H36: =F36*G36 -> 0 | W36: =(U36-T36)*24*60 -> 0
C37: 4度二組B | D37: 平均 | J37: =AVERAGE(J27:J36) -> 17.6 | K37: =AVERAGE(K27:K36) -> 1636 | L37: =AVERAGE(L27:L36) -> 93.161111 | M37: =AVERAGE(M27:M36) -> 16.8 | N37: =AVERAGE(N27:N36) -> 1435.0369 | O37: =AVERAGE(O27:O36) -> 85.599074 | P37: =M37-J37 -> -0.8 | Q37: =N37-K37 -> -200.96313 | R37: =O37/L37 -> 0.91882839 | Z37: =SUM(Z27:Z36) -> 0 | AA37: =SUM(AA27:AA36) -> 0 | AD37: =SUM(AD27:AD36) -> 0 | AE37: =SUM(AE27:AE36) -> 0 | AF37: =N37-K37 -> -200.96313 | AG37: =N37/K37 -> 0.8771619
A38: 手工四線 (ET-55) | B38: 熱乾麵 | D38: 青花椒麻雞肉拌麵 | F38: =VLOOKUP(D38,廠價表!$C$1:$E$43,3,0) -> 49.91 | G38: 1712 | H38: =F38*G38 -> 85445.92 | J38: =VLOOKUP(D38,產線配置圖!$A$3:$C$40,2,0) -> 16 | K38: =VLOOKUP(D38,產線配置圖!$A$3:$C$40,3,0) -> 1714 | L38: =K38/J38 -> 107.125 | M38: 16 | N38: =G38/W38*60 -> 1467.4286 | O38: =N38/M38 -> 91.714286 | P38: =M38-J38 -> 0 | Q38: =O38-L38 -> -15.410714 | R38: =O38/L38 -> 0.85614269 | S38: =R48 -> 0.90396809 | T38: 0.33333333 | U38: 0.38194444 | W38: =(U38-T38)*24*60 -> 70 | AF38: =N38-K38 -> -246.57143 | AG38: =N38/K38 -> 0.85614269 | AH38: =AG48 -> 0.90702677
B39: 熱乾麵 | D39: 府城鹽水意麵 | F39: =VLOOKUP(D39,廠價表!$C$1:$E$43,3,0) -> 44.3 | G39: 3535 | H39: =F39*G39 -> 156600.5 | J39: =VLOOKUP(D39,產線配置圖!$A$3:$C$40,2,0) -> 18 | K39: =VLOOKUP(D39,產線配置圖!$A$3:$C$40,3,0) -> 1636 | L39: =K39/J39 -> 90.888889 | M39: 18 | N39: =G39/W39*60 -> 1571.1111 | O39: =N39/M39 -> 87.283951 | P39: =M39-J39 -> 0 | Q39: =O39-L39 -> -3.6049383 | R39: =O39/L39 -> 0.96033686 | T39: 0.38888889 | U39: 0.48263889 | V39: =(T39-U38)*24*60 -> 10 | W39: =(U39-T39)*24*60 -> 135 | AF39: =N39-K39 -> -64.888889 | AG39: =N39/K39 -> 0.96033686
W40: =(U40-T40)*24*60 -> 0 | AF40: =N40-K40 -> 0 | AG40: =N40/K40 -> #DIV/0!
...

Sheet 1003總
B1: 長家廠組合室生產人時性分析
B3: 日期 | D3: 46298 | F3: 訂單量 | G3: =範本!E1 -> 43309 | I3: 營業額 | J3: =範本!G1 -> #N/A
B4: 項目 | D4: 3 | F4: ➀ | H4: ➁ | J4: ③ | L4: 異常停線 | N4: 短暫停線
B5: 人時性 | D5: 組合室 | F5: 全溫層 | H5: 義大利麵 | J5: 袋裝小吃、義麵 | L5: 合計次數 | M5: 時間 | N5: 合計次數 | O5: 設備次數
D6: 排關平均 | F6: =AVERAGE(D13:J13) -> 131.0187 | H6: =AVERAGE(D13:H13) -> 127.20921 | J6: =AVERAGE(I13:J13) -> 140.54242 | L6: =範本!Z2 -> 0 | M6: =範本!AA2 -> 0 | N6: =範本!AD2 -> 0 | O6: =範本!AE2 -> 0
D7: 實績平均 | F7: =AVERAGE(D14:J14) -> 115.29074 | H7: =AVERAGE(D14:H14) -> 113.00563 | J7: =AVERAGE(I14:J14) -> 121.00352
D8: 達成率平均 | F8: =AVERAGE(D15:J15) -> 0.88617582 | H8: =AVERAGE(D15:H15) -> 0.89651687 | J8: =AVERAGE(I15:J15) -> 0.86032317
J9: ※現行日本鮮食廠以達成率80%為基本(即為現行KPI)
B10: 溫層 | D10: 4度C-各編組展開
B11: 編組 | D11: 1 | E11: 2 | F11: 3 | G11: 4 | H11: 5 | I11: 6 | J11: 7
D12: 自動1線 | E12: 自動2線 | F12: 手工3線 | G12: 手工4線 | H12: 手工5線 | I12: 調理包1線 | J12: 調理包2線
B13: 人時性 | C13: 排關 | D13: =VALUE('1003'!L15) -> 164.83516 | E13: =VALUE('1003'!L26) -> 174.10714 | F13: =VALUE('1003'!L37) -> 93.729167 | G13: =VALUE('1003'!L48) -> 99.006944 | H13: =VALUE('1003'!L58) -> 104.36765 | I13: =VALUE('1003'!L69) -> 138.81212 | J13: ='1003'!L79 -> 142.27273
C14: 實績 | D14: =VALUE('1003'!O15) -> 143.18287 | E14: =VALUE('1003'!O26) -> 147.89961 | F14: =VALUE('1003'!O37) -> 85.012413 | G14: =VALUE('1003'!O48) -> 90.981019 | H14: =VALUE('1003'!O58) -> 97.952228 | I14: =VALUE('1003'!O69) -> 112.0737 | J14: ='1003'!O79 -> 129.93333
C15: 達成率 | D15: =D14/D13 -> 0.86864277 | E15: =E14/E13 -> 0.84947467 | F15: =F14/F13 -> 0.90700063 | G15: =G14/G13 -> 0.91893573 | H15: =H14/H13 -> 0.93853058 | I15: =I14/I13 -> 0.80737691 | J15: ='1003'!S70 -> 0.91326944
B16: 作業 時間 | C16: 開始 | D16: ='1003'!T5 -> 0.29166667 | E16: ='1003'!T16 -> 0.29166667 | F16: ='1003'!T27 -> 0.29166667 | G16: ='1003'!T38 -> 0.33333333 | H16: ='1003'!T49 -> 0.29166667 | I16: ='1003'!T59 -> 0.29166667 | J16: ='1003'!T70 -> 0.29166667
C17: 結束 | D17: 0.48333333 | E17: 0.46180556 | F17: 0.57986111 | G17: 0.49305556 | H17: 0.46388889 | I17: 0.51041667 | J17: 0.36111111
B18: 產線異常 (5分鐘以上) | C18: 次數 | D18: ='1003'!Z15 -> 0 | E18: ='1003'!Z26 -> 0 | F18: ='1003'!Z37 -> 0 | G18: ='1003'!Z48 -> 0 | H18: ='1003'!Z58 -> 0 | I18: ='1003'!Z69 -> 0 | J18: ='1003'!AA79 -> 0
C19: 時間/分 | D19: ='1003'!AA15 -> 0 | E19: ='1003'!AA26 -> 0 | F19: ='1003'!AA37 -> 0 | G19: ='1003'!AA48 -> 0 | H19: ='1003'!AA58 -> 0 | I19: ='1003'!AA69 -> 0 | J19: ='1003'!AB79 -> 0
B20: 短暫停線 (5分鐘以下) | C20: 次數 | D20: ='1003'!AD15 -> 0 | E20: ='1003'!AD26 -> 0 | F20: ='1003'!AD37 -> 0 | G20: ='1003'!AD48 -> 0 | H20: ='1003'!AD58 -> 0 | I20: ='1003'!AD69 -> 0 | J20: ='1003'!AD79 -> 0
C21: 設備次數 | D21: ='1003'!AE15 -> 0 | E21: ='1003'!AE26 -> 0 | F21: ='1003'!AE37 -> 0 | G21: ='1003'!AE48 -> 0 | H21: ='1003'!AE58 -> 0 | I21: ='1003'!AE69 -> 0 | J21: ='1003'!AE79 -> 0
B22: 配置人數 | D22: =VALUE(範本!M15) -> 15 | E22: =VALUE(範本!M26) -> 12.666667 | F22: =VALUE(範本!M37) -> 14.666667 | G22: =VALUE(範本!M48) -> 14 | H22: =VALUE(範本!M58) -> 17.666667 | I22: =VALUE(範本!M69) -> 12.333333 | J22: =範本!M79 -> 11
B23: 主要應用設備 | D23: ET-600 | E23: ET-600 | F23: ET-55 | G23: ET-55 | H23: ET-55 | I23: 八爪機
B24: 次要應用設備 | H24: 封口機
B25: 備註

Sheet 1003
A1: 長家廠4度C日報分析 | D1: 總生產量 | E1: =SUM(G5:G79) -> 43958 | F1: 營業額 | G1: =SUM(H5:H79) -> 2056079.4 | H1: 出勤人數 | I1: =M15+M26+M48+M58+M69+M79+M37 -> 97.166667 | J1: 產線配置圖 | M1: 生產實績 | P1: 人時性差異分析 | T1: 日報登錄 | Z1: 合計 次數 | AA1: 合計 時間/分 | AB1: 分析說明 | AD1: 合計 次數 | AE1: 合計 設備次數 | AF1: 產能差異分析
A2: 10月3日 星期六 | D2: 人時性 | E2: =AVERAGE(O15,O26,O37,O48,O58,O69,O79) -> 115.29074 | F2: 平均廠價 | G2: =G1/E1 -> 46.773724 | H2: 多次生產數 | I2: =COUNT(I5:I79) -> 0 | Z2: =Z15+Z26+Z37+Z48+Z58+Z69+Z79 -> 0 | AA2: =AA15+AA26+AA37+AA48+AA58+AA69+AA79 -> 0 | AD2: =AD15+AD26+AD37+AD48+AD58+AD69+AD79 -> 0 | AE2: =AE15+AE26+AE37+AE48+AE58+AE69+AE79 -> 0
A3: 線別 | B3: 品類 | D3: 品名 | F3: 廠價 | G3: 生產量 | H3: 營收 | I3: 多次 生產 | J3: 人數 | K3: 產能/時 | L3: 人時性 | M3: 人數 | N3: 產能/時 | O3: 人時性 | P3: 人數 | Q3: 人時性 | R3: 達成率 | S3: 達成率平均 | T3: 生產時間 | V3: 前置、換線時間/分 | W3: 稼動時間/分 | X3: 休息時間 | Z3: 產線異常統計 (5分鐘以上) | AD3: 短暫停線統計 (5分鐘以下) | AF3: 產能/時 | AG3: 達成率 | AH3: 達成率平均
T4: 開始 | U4: 結束 | X4: 開始 | Y4: 結束 | Z4: 次數 | AA4: 時間/分 | AD4: 總次數 | AE4: 設備因素(次數)
A5: 自動一線 (ET-600) | B5: 義大利麵 | D5: 白酒清炒鮮蛤義大利麵 | F5: =VLOOKUP(D5,廠價表!$C$1:$E$43,3,0) -> 56.87 | G5: 2618 | H5: =F5*G5 -> 148885.66 | J5: =VLOOKUP(D5,產線配置圖!$A$3:$C$40,2,0) -> 14 | K5: =VLOOKUP(D5,產線配置圖!$A$3:$C$40,3,0) -> 2250 | L5: =K5/J5 -> 160.71429 | M5: 14 | N5: =G5/W5*60 -> 1892.5301 | O5: =N5/M5 -> 135.18072 | P5: =M5-J5 -> 0 | Q5: =O5-L5 -> -25.533563 | R5: =O5/L5 -> 0.8411245 | S5: =R15 -> 0.86864277 | T5: 0.29166667 | U5: 0.34930556 | W5: =(U5-T5)*24*60 -> 83 | AF5: =N5-K5 -> -357.46988 | AG5: =N5/K5 -> 0.8411245 | AH5: =AG15 -> 0.86860227
B6: 義大利麵 | D6: 香煎魚排佐檸檬奶油義大利麵 | F6: =VLOOKUP(D6,廠價表!$C$1:$E$43,3,0) -> 58.17 | G6: 979 | H6: =F6*G6 -> 56948.43 | J6: =VLOOKUP(D6,產線配置圖!$A$3:$C$40,2,0) -> 13 | K6: =VLOOKUP(D6,產線配置圖!$A$3:$C$40,3,0) -> 2250 | L6: =K6/J6 -> 173.07692 | M6: 13 | N6: =G6/W6*60 -> 1958 | O6: =N6/M6 -> 150.61538 | P6: =M6-J6 -> 0 | Q6: =O6-L6 -> -22.461538 | R6: =O6/L6 -> 0.87022222 | T6: 0.35694444 | U6: 0.37777778 | V6: =(T6-U5)*24*60 -> 11 | W6: =(U6-T6)*24*60 -> 30 | AF6: =N6-K6 -> -292 | AG6: =N6/K6 -> 0.87022222
B7: 義大利麵 | D7: 奶油培根義大利麵 | F7: =VLOOKUP(D7,廠價表!$C$1:$E$43,3,0) -> 49.14 | G7: 4763 | H7: =F7*G7 -> 234053.82 | J7: =VLOOKUP(D7,產線配置圖!$A$3:$C$40,2,0) -> 14 | K7: =VLOOKUP(D7,產線配置圖!$A$3:$C$40,3,0) -> 2250 | L7: =K7/J7 -> 160.71429 | M7: 14 | N7: =G7/W7*60 -> 2012.5352 | O7: =N7/M7 -> 143.75252 | P7: =M7-J7 -> 0 | Q7: =O7-L7 -> -16.961771 | R7: =O7/L7 -> 0.89446009 | T7: 0.38472222 | U7: 0.48333333 | V7: =(T7-U6)*24*60 -> 10 | W7: =(U7-T7)*24*60 -> 142 | AF7: =N7-K7 -> -237.46479 | AG7: =N7/K7 -> 0.89446009
W8: =(U8-T8)*24*60 -> 0 | AF8: =N8-K8 -> 0 | AG8: =N8/K8 -> #DIV/0!
W9: =(U9-T9)*24*60 -> 0 | AF9: =N9-K9 -> 0 | AG9: =N9/K9 -> #DIV/0!
W10: =(U10-T10)*24*60 -> 0
W11: =(U11-T11)*24*60 -> 0
W12: =(U12-T12)*24*60 -> 0
W13: =(U13-T13)*24*60 -> 0
W14: =(U14-T14)*24*60 -> 0
C15: 4度一組 | D15: 平均 | J15: =AVERAGE(J5:J14) -> 13.666667 | K15: =AVERAGE(K5:K14) -> 2250 | L15: =AVERAGE(L5:L14) -> 164.83516 | M15: =AVERAGE(M5:M14) -> 13.666667 | N15: =AVERAGE(N5:N14) -> 1954.3551 | O15: =AVERAGE(O5:O14) -> 143.18287 | P15: =M15-J15 -> 0 | Q15: =O15-L15 -> -21.652291 | R15: =O15/L15 -> 0.86864277 | Z15: =SUM(Z5:Z14) -> 0 | AA15: =SUM(AA5:AA14) -> 0 | AD15: =SUM(AD5:AD14) -> 0 | AE15: =SUM(AE5:AE14) -> 0 | AF15: =N15-K15 -> -295.64489 | AG15: =N15/K15 -> 0.86860227
A16: 自動二線 (ET-600) | B16: 義大利麵 | D16: 青醬蛤蜊義大利麵 | F16: =VLOOKUP(D16,廠價表!$C$1:$E$43,3,0) -> 50.67 | G16: 3439 | H16: =F16*G16 -> 174254.13 | J16: =VLOOKUP(D16,產線配置圖!$A$3:$C$40,2,0) -> 14 | K16: =VLOOKUP(D16,產線配置圖!$A$3:$C$40,3,0) -> 2250 | L16: =K16/J16 -> 160.71429 | M16: 14 | N16: =G16/W16*60 -> 1928.4112 | O16: =N16/M16 -> 137.74366 | P16: =M16-J16 -> 0 | Q16: =O16-L16 -> -22.970628 | R16: =O16/L16 -> 0.85707165 | S16: =R26 -> 0.84947467 | T16: 0.29166667 | U16: 0.36597222 | W16: =(U16-T16)*24*60 -> 107 | AF16: =N16-K16 -> -321.58879 | AG16: =N16/K16 -> 0.85707165 | AH16: =AG26 -> 0.85001731
B17: 義大利麵 | D17: 義式蕃茄起司義大利麵 | F17: =VLOOKUP(D17,廠價表!$C$1:$E$43,3,0) -> 50.39 | G17: 3983 | H17: =F17*G17 -> 200703.37 | J17: =VLOOKUP(D17,產線配置圖!$A$3:$C$40,2,0) -> 12 | K17: =VLOOKUP(D17,產線配置圖!$A$3:$C$40,3,0) -> 2250 | L17: =K17/J17 -> 187.5 | M17: 12 | N17: =G17/W17*60 -> 1896.6667 | O17: =N17/M17 -> 158.05556 | P17: =M17-J17 -> 0 | Q17: =O17-L17 -> -29.444444 | R17: =O17/L17 -> 0.84296296 | T17: 0.37430556 | U17: 0.46180556 | V17: =(T17-U16)*24*60 -> 12 | W17: =(U17-T17)*24*60 -> 126 | AF17: =N17-K17 -> -353.33333 | AG17: =N17/K17 -> 0.84296296
W18: =(U18-T18)*24*60 -> 0 | AF18: =N18-K18 -> 0 | AG18: =N18/K18 -> #DIV/0!
W19: =(U19-T19)*24*60 -> 0 | AF19: =N19-K19 -> 0 | AG19: =N19/K19 -> #DIV/0!
W20: =(U20-T20)*24*60 -> 0
W21: =(U21-T21)*24*60 -> 0
W22: 0
W23: =(U23-T23)*24*60 -> 0
H24: =F24*G24 -> 0 | W24: =(U24-T24)*24*60 -> 0
H25: =F25*G25 -> 0 | W25: =(U25-T25)*24*60 -> 0
C26: 4度二組A | D26: 平均 | J26: =AVERAGE(J16:J25) -> 13 | K26: =AVERAGE(K16:K25) -> 2250 | L26: =AVERAGE(L16:L25) -> 174.10714 | M26: =AVERAGE(M16:M25) -> 13 | N26: =AVERAGE(N16:N25) -> 1912.5389 | O26: =AVERAGE(O16:O25) -> 147.89961 | P26: =M26-J26 -> 0 | Q26: =O26-L26 -> -26.207536 | R26: =O26/L26 -> 0.84947467 | Z26: =SUM(Z16:Z25) -> 0 | AA26: =SUM(AA16:AA25) -> 0 | AD26: =SUM(AD16:AD25) -> 0 | AE26: =SUM(AE16:AE25) -> 0 | AF26: =N26-K26 -> -337.46106 | AG26: =N26/K26 -> 0.85001731
A27: 手工三線 (ET-55) | B27: 義大利麵 | D27: 燻鴨佐白蘭地義大利麵 | F27: =VLOOKUP(D27,廠價表!$C$1:$E$43,3,0) -> 61.65 | G27: 1821 | H27: =F27*G27 -> 112264.65 | J27: =VLOOKUP(D27,產線配置圖!$A$3:$C$40,2,0) -> 18 | K27: =VLOOKUP(D27,產線配置圖!$A$3:$C$40,3,0) -> 1636 | L27: =K27/J27 -> 90.888889 | M27: 17 | N27: =G27/W27*60 -> 1456.8 | O27: =N27/M27 -> 85.694118 | P27: =M27-J27 -> -1 | Q27: =O27-L27 -> -5.1947712 | R27: =O27/L27 -> 0.94284482 | S27: =R37 -> 0.90700063 | T27: 0.29166667 | U27: 0.34375 | W27: =(U27-T27)*24*60 -> 75 | AF27: =N27-K27 -> -179.2 | AG27: =N27/K27 -> 0.89046455 | AH27: =AG37 -> 0.88380594
B28: 義大利麵 | D28: 蕃茄莎莎海鮮冷義大利麵 | F28: =VLOOKUP(D28,廠價表!$C$1:$E$43,3,0) -> 46.34 | G28: 679 | H28: =F28*G28 -> 31464.86 | J28: =VLOOKUP(D28,產線配置圖!$A$3:$C$40,2,0) -> 16 | K28: =VLOOKUP(D28,產線配置圖!$A$3:$C$40,3,0) -> 1636 | L28: =K28/J28 -> 102.25 | M28: 16 | N28: =G28/W28*60 -> 1358 | O28: =N28/M28 -> 84.875 | P28: =M28-J28 -> 0 | Q28: =O28-L28 -> -17.375 | R28: =O28/L28 -> 0.83007335 | T28: 0.35 | U28: 0.37083333 | V28: =(T28-U27)*24*60 -> 9 | W28: =(U28-T28)*24*60 -> 30 | AF28: =N28-K28 -> -278 | AG28: =N28/K28 -> 0.83007335
B29: 義大利麵 | D29: 拿坡里燻腸義大利麵 | F29: =VLOOKUP(D29,廠價表!$C$1:$E$43,3,0) -> 52.21 | G29: 3629 | H29: =F29*G29 -> 189470.09 | J29: =VLOOKUP(D29,產線配置圖!$A$3:$C$40,2,0) -> 18 | K29: =VLOOKUP(D29,產線配置圖!$A$3:$C$40,3,0) -> 1636 | L29: =K29/J29 -> 90.888889 | M29: 18 | N29: =G29/W29*60 -> 1577.8261 | O29: =N29/M29 -> 87.657005 | P29: =M29-J29 -> 0 | Q29: =O29-L29 -> -3.2318841 | R29: =O29/L29 -> 0.96444137 | T29: 0.37638889 | U29: 0.47222222 | V29: =(T29-U28)*24*60 -> 8 | W29: =(U29-T29)*24*60 -> 138 | AF29: =N29-K29 -> -58.173913 | AG29: =N29/K29 -> 0.96444137
B30: 熱乾麵 | D30: 府城鹽水意麵 | F30: =VLOOKUP(D30,廠價表!$C$1:$E$43,3,0) -> 44.3 | G30: 1391 | H30: =F30*G30 -> 61621.3 | J30: =VLOOKUP(D30,產線配置圖!$A$3:$C$40,2,0) -> 18 | K30: =VLOOKUP(D30,產線配置圖!$A$3:$C$40,3,0) -> 1636 | L30: =K30/J30 -> 90.888889 | M30: 17 | N30: =G30/W30*60 -> 1391 | O30: =N30/M30 -> 81.823529 | P30: =M30-J30 -> -1 | Q30: =O30-L30 -> -9.0653595 | R30: =O30/L30 -> 0.90025888 | T30: 0.53819444 | U30: 0.57986111 | V30: =(T30-U29)*24*60 -> 95 | W30: =(U30-T30)*24*60 -> 60 | AF30: =N30-K30 -> -245 | AG30: =N30/K30 -> 0.8502445
W31: =(U31-T31)*24*60 -> 0 | AF31: =N31-K31 -> 0 | AG31: =N31/K31 -> #DIV/0!
W32: =(U32-T32)*24*60 -> 0
W33: =(U33-T33)*24*60 -> 0
W34: =(U34-T34)*24*60 -> 0
W35: =(U35-T35)*24*60 -> 0
H36: =F36*G36 -> 0 | W36: =(U36-T36)*24*60 -> 0
C37: 4度二組B | D37: 平均 | J37: =AVERAGE(J27:J36) -> 17.5 | K37: =AVERAGE(K27:K36) -> 1636 | L37: =AVERAGE(L27:L36) -> 93.729167 | M37: =AVERAGE(M27:M36) -> 17 | N37: =AVERAGE(N27:N36) -> 1445.9065 | O37: =AVERAGE(O27:O36) -> 85.012413 | P37: =M37-J37 -> -0.5 | Q37: =N37-K37 -> -190.09348 | R37: =O37/L37 -> 0.90700063 | Z37: =SUM(Z27:Z36) -> 0 | AA37: =SUM(AA27:AA36) -> 0 | AD37: =SUM(AD27:AD36) -> 0 | AE37: =SUM(AE27:AE36) -> 0 | AF37: =N37-K37 -> -190.09348 | AG37: =N37/K37 -> 0.88380594
A38: 手工四線 (ET-55) | B38: 熱乾麵 | D38: 青花椒麻雞肉拌麵 | F38: =VLOOKUP(D38,廠價表!$C$1:$E$43,3,0) -> 49.91 | G38: 1815 | H38: =F38*G38 -> 90586.65 | J38: =VLOOKUP(D38,產線配置圖!$A$3:$C$40,2,0) -> 16 | K38: =VLOOKUP(D38,產線配置圖!$A$3:$C$40,3,0) -> 1714 | L38: =K38/J38 -> 107.125 | M38: 15 | N38: =G38/W38*60 -> 1452 | O38: =N38/M38 -> 96.8 | P38: =M38-J38 -> -1 | Q38: =O38-L38 -> -10.325 | R38: =O38/L38 -> 0.90361727 | S38: =R48 -> 0.91893573 | T38: 0.33333333 | U38: 0.38541667 | W38: =(U38-T38)*24*60 -> 75 | AF38: =N38-K38 -> -262 | AG38: =N38/K38 -> 0.84714119 | AH38: =AG48 -> 0.8910199
B39: 熱乾麵 | D39: 府城鹽水意麵 | F39: =VLOOKUP(D39,廠價表!$C$1:$E$43,3,0) -> 44.3 | G39: 3679 | H39: =F39*G39 -> 162979.7 | J39: =VLOOKUP(D39,產線配置圖!$A$3:$C$40,2,0) -> 18 | K39: =VLOOKUP(D39,產線配置圖!$A$3:$C$40,3,0) -> 1636 | L39: =K39/J39 -> 90.888889 | M39: 18 | N39: =G39/W39*60 -> 1532.9167 | O39: =N39/M39 -> 85.162037 | P39: =M39-J39 -> 0 | Q39: =O39-L39 -> -5.7268519 | R39: =O39/L39 -> 0.93699063 | T39: 0.39305556 | U39: 0.49305556 | V39: =(T39-U38)*24*60 -> 11 | W39: =(U39-T39)*24*60 -> 144 | AF39: =N39-K39 -> -103.08333 | AG39: =N39/K39 -> 0.93699063
W40: =(U40-T40)*24*60 -> 0 | AF40: =N40-K40 -> 0 | AG40: =N40/K40 -> #DIV/0!
...

Sheet 1004總
B1: 長家廠組合室生產人時性分析
B3: 日期 | D3: 46299 | F3: 訂單量 | G3: =範本!E1 -> 43309 | I3: 營業額 | J3: =範本!G1 -> #N/A
B4: 項目 | D4: 3 | F4: ➀ | H4: ➁ | J4: ③ | L4: 異常停線 | N4: 短暫停線
B5: 人時性 | D5: 組合室 | F5: 全溫層 | H5: 義大利麵 | J5: 袋裝小吃、義麵 | L5: 合計次數 | M5: 時間 | N5: 合計次數 | O5: 設備次數
D6: 排關平均 | F6: =AVERAGE(D13:J13) -> 130.40006 | H6: =AVERAGE(D13:H13) -> 127.00412 | J6: =AVERAGE(I13:J13) -> 138.8899 | L6: =範本!Z2 -> 0 | M6: =範本!AA2 -> 0 | N6: =範本!AD2 -> 0 | O6: =範本!AE2 -> 0
D7: 實績平均 | F7: =AVERAGE(D14:J14) -> 113.47509 | H7: =AVERAGE(D14:H14) -> 115.70771 | J7: =AVERAGE(I14:J14) -> 107.89354
D8: 達成率平均 | F8: =AVERAGE(D15:J15) -> 0.87366662 | H8: =AVERAGE(D15:H15) -> 0.9129482 | J8: =AVERAGE(I15:J15) -> 0.77546266
J9: ※現行日本鮮食廠以達成率80%為基本(即為現行KPI)
B10: 溫層 | D10: 4度C-各編組展開
B11: 編組 | D11: 1 | E11: 2 | F11: 3 | G11: 4 | H11: 5 | I11: 6 | J11: 7
D12: 自動1線 | E12: 自動2線 | F12: 手工3線 | G12: 手工4線 | H12: 手工5線 | I12: 調理包1線 | J12: 調理包2線
B13: 人時性 | C13: 排關 | D13: =VALUE('1004'!L15) -> 163.80495 | E13: =VALUE('1004'!L26) -> 174.10714 | F13: =VALUE('1004'!L37) -> 93.729167 | G13: =VALUE('1004'!L48) -> 96.300926 | H13: =VALUE('1004'!L58) -> 107.07843 | I13: =VALUE('1004'!L69) -> 135.50707 | J13: ='1004'!L79 -> 142.27273
C14: 實績 | D14: =VALUE('1004'!O15) -> 142.55032 | E14: =VALUE('1004'!O26) -> 163.62768 | F14: =VALUE('1004'!O37) -> 87.965745 | G14: =VALUE('1004'!O48) -> 90.055236 | H14: =VALUE('1004'!O58) -> 94.339583 | I14: =VALUE('1004'!O69) -> 97.485586 | J14: ='1004'!O79 -> 118.30149
C15: 達成率 | D15: =D14/D13 -> 0.87024429 | E15: =E14/E13 -> 0.93981029 | F15: =F14/F13 -> 0.93850984 | G15: =G14/G13 -> 0.93514403 | H15: =H14/H13 -> 0.88103255 | I15: =I14/I13 -> 0.71941328 | J15: ='1004'!S70 -> 0.83151204
B16: 作業 時間 | C16: 開始 | D16: ='1004'!T5 -> 0.29861111 | E16: ='1004'!T16 -> 0.30208333 | F16: ='1004'!T27 -> 0.29166667 | G16: ='1004'!T38 -> 0.33333333 | H16: ='1004'!T49 -> 0.29166667 | I16: ='1004'!T59 -> 0.29166667 | J16: ='1004'!T70 -> 0.29861111
C17: 結束 | D17: 0.65972222 | E17: 0.625 | F17: 0.59722222 | G17: 0.65 | H17: 0.59236111 | I17: 0.47569444 | J17: 0.40763889
B18: 產線異常 (5分鐘以上) | C18: 次數 | D18: ='1004'!Z15 -> 0 | E18: ='1004'!Z26 -> 0 | F18: ='1004'!Z37 -> 0 | G18: ='1004'!Z48 -> 0 | H18: ='1004'!Z58 -> 0 | I18: ='1004'!Z69 -> 0 | J18: ='1004'!AA79 -> 0
C19: 時間/分 | D19: ='1004'!AA15 -> 0 | E19: ='1004'!AA26 -> 0 | F19: ='1004'!AA37 -> 0 | G19: ='1004'!AA48 -> 0 | H19: ='1004'!AA58 -> 0 | I19: ='1004'!AA69 -> 0 | J19: ='1004'!AB79 -> 0
B20: 短暫停線 (5分鐘以下) | C20: 次數 | D20: ='1004'!AD15 -> 0 | E20: ='1004'!AD26 -> 0 | F20: ='1004'!AD37 -> 0 | G20: ='1004'!AD48 -> 0 | H20: ='1004'!AD58 -> 0 | I20: ='1004'!AD69 -> 0 | J20: ='1004'!AD79 -> 0
C21: 設備次數 | D21: ='1004'!AE15 -> 0 | E21: ='1004'!AE26 -> 0 | F21: ='1004'!AE37 -> 0 | G21: ='1004'!AE48 -> 0 | H21: ='1004'!AE58 -> 0 | I21: ='1004'!AE69 -> 0 | J21: ='1004'!AE79 -> 0
B22: 配置人數 | D22: =VALUE(範本!M15) -> 15 | E22: =VALUE(範本!M26) -> 12.666667 | F22: =VALUE(範本!M37) -> 14.666667 | G22: =VALUE(範本!M48) -> 14 | H22: =VALUE(範本!M58) -> 17.666667 | I22: =VALUE(範本!M69) -> 12.333333 | J22: =範本!M79 -> 11
B23: 主要應用設備 | D23: ET-600 | E23: ET-600 | F23: ET-55 | G23: ET-55 | H23: ET-55 | I23: 八爪機
B24: 次要應用設備 | H24: 封口機
B25: 備註

Sheet 1004
A1: 長家廠4度C日報分析 | D1: 總生產量 | E1: =SUM(G5:G79) -> 58995 | F1: 營業額 | G1: =SUM(H5:H79) -> 2846561.5 | H1: 出勤人數 | I1: =M15+M26+M48+M58+M69+M79+M37 -> 99.916667 | J1: 產線配置圖 | M1: 生產實績 | P1: 人時性差異分析 | T1: 日報登錄 | Z1: 合計 次數 | AA1: 合計 時間/分 | AB1: 分析說明 | AD1: 合計 次數 | AE1: 合計 設備次數 | AF1: 產能差異分析
A2: 10月4日 星期日 | D2: 人時性 | E2: =AVERAGE(O15,O26,O37,O48,O58,O69,O79) -> 113.47509 | F2: 平均廠價 | G2: =G1/E1 -> 48.250895 | H2: 多次生產數 | I2: =COUNT(I5:I79) -> 0 | Z2: =Z15+Z26+Z37+Z48+Z58+Z69+Z79 -> 0 | AA2: =AA15+AA26+AA37+AA48+AA58+AA69+AA79 -> 0 | AD2: =AD15+AD26+AD37+AD48+AD58+AD69+AD79 -> 0 | AE2: =AE15+AE26+AE37+AE48+AE58+AE69+AE79 -> 0
A3: 線別 | B3: 品類 | D3: 品名 | F3: 廠價 | G3: 生產量 | H3: 營收 | I3: 多次 生產 | J3: 人數 | K3: 產能/時 | L3: 人時性 | M3: 人數 | N3: 產能/時 | O3: 人時性 | P3: 人數 | Q3: 人時性 | R3: 達成率 | S3: 達成率平均 | T3: 生產時間 | V3: 前置、換線時間/分 | W3: 稼動時間/分 | X3: 休息時間 | Z3: 產線異常統計 (5分鐘以上) | AD3: 短暫停線統計 (5分鐘以下) | AF3: 產能/時 | AG3: 達成率 | AH3: 達成率平均
T4: 開始 | U4: 結束 | X4: 開始 | Y4: 結束 | Z4: 次數 | AA4: 時間/分 | AD4: 總次數 | AE4: 設備因素(次數)
A5: 自動一線 (ET-600) | B5: 義大利麵 | D5: 白酒清炒鮮蛤義大利麵 | F5: =VLOOKUP(D5,廠價表!$C$1:$E$43,3,0) -> 56.87 | G5: 4293 | H5: =F5*G5 -> 244142.91 | J5: =VLOOKUP(D5,產線配置圖!$A$3:$C$40,2,0) -> 14 | K5: =VLOOKUP(D5,產線配置圖!$A$3:$C$40,3,0) -> 2250 | L5: =K5/J5 -> 160.71429 | M5: 14 | N5: =G5/W5*60 -> 2111.3115 | O5: =N5/M5 -> 150.80796 | P5: =M5-J5 -> 0 | Q5: =O5-L5 -> -9.9063232 | R5: =O5/L5 -> 0.93836066 | S5: =R15 -> 0.87024429 | T5: 0.29861111 | U5: 0.38333333 | W5: =(U5-T5)*24*60 -> 122 | AF5: =N5-K5 -> -138.68852 | AG5: =N5/K5 -> 0.93836066 | AH5: =AG15 -> 0.86990854
