Workbook

Sheet 廠價表
A1: check | B1: 溫層 | C1: 品名 | D1: 類別 | E1: 廠價
B2: 4度C | C2: 白酒蛤蜊義大利麵 | D2: 義大利麵 | E2: 57.21
B3: 4度C | C3: 白酒清炒鮮蛤義大利麵 | D3: 義大利麵 | E3: 56.87
B4: 4度C | C4: 義式蕃茄起司義大利麵 | D4: 義大利麵 | E4: 50.39
B5: 4度C | C5: 焗烤起司雙饗筆尖麵 | D5: 義大利麵 | E5: 49.97
B6: 4度C | C6: 奶油培根義大利麵 | D6: 義大利麵 | E6: 49.14
B7: 4度C | C7: 燻火腿貓耳朵麵 | D7: 義大利麵 | E7: 58.17
B8: 4度C | C8: 義式辣味嫩烤雞腿排義大利麵 | D8: 義大利麵 | E8: 56.61
B9: 4度C | C9: 焗烤起司肉醬筆尖麵 | D9: 義大利麵 | E9: 50.67
B10: 4度C | C10: 辣味香菜雞肉義大利麵 | D10: 義大利麵 | E10: 56.28
B11: 4度C | C11: 蒜香奶油蝦蝦義大利麵 | D11: 義大利麵 | E11: 57.21
B12: 4度C | C12: 義式辣味嫩烤雞腿排義大利麵 | D12: 義大利麵 | E12: 56.61
B13: 4度C | C13: 香煎魚排佐檸檬奶油義大利麵 | D13: 義大利麵 | E13: 58.17
... B21: 4度C | C21: 沙茶豬肉炒麵 | D21: 熱乾麵 | E21: 49.52
B23: 4度C | D23: 小吃、微波
B24: 4度C | C24: 小滷青蔬 | D24: 小吃、微波 | E24: 26.99
B25: 4度C | C25: 起司馬鈴薯 | D25: 小吃、微波 | E25: 28.26
B26: 4度C | C26: 麻辣雞心 | D26: 小吃、微波 | E26: 28.26
B46: 冷凍 | C46: 青醬蛤蜊義大利麵 | D46: 冷凍調理麵 | E46: 29.38
B47: 冷凍 | C47: 經典肉醬義大利麵 | D47: 冷凍調理麵 | E47: 29.38
B48: 冷凍 | C48: 奶油蘑菇培根義大利麵 | D48: 冷凍調理麵 | E48: 29.38
B49: 冷凍 | C49: 清炒蛤蜊義大利麵 | D49: 冷凍調理麵 | E49: 29.38
B50: 冷凍 | C50: 青醬乳酪筆尖麵 | D50: 冷凍調理麵 | E50: 29.38
B51: 冷凍 | C51: 辣蕃茄義大利麵 | D51: 冷凍調理麵 | E51: 29.38
B52: 冷凍 | D52: 冷凍調理麵
B53: 冷凍 | C53: 韓式起司義大利麵 | D53: 冷凍調理麵 | E53: 29.38
B54: 冷凍 | D54: 冷凍調理麵
B55: 冷凍 | C55: 和風明太子細扁麵 | D55: 冷凍調理麵 | E55: 29.38

Sheet 產線配置圖
A1: 品項 | B1: 人數 | C1: 產能 | E1: 人時 | G1: 備註
A2: 義大利麵
A3: 白酒清炒鮮蛤義大利麵 | B3: 15 | C3: 2250 | D3: ET-600 | E3: =C3/B3 -> 150
A4: 白酒清炒鮮蛤義大利麵-手 | B4: 17 | C4: 1716 | D4: ET-55 | E4: =C4/B4 -> 100.94118
A5: 青醬蛤蜊義大利麵 | B5: 13 | C5: 2250 | E5: =C5/B5 -> 173.07692
A6: 青醬蛤蜊義大利麵-手 | B6: 16 | C6: 1714 | E6: =C6/B6 -> 107.125
A7: 義式蕃茄起司義大利麵 | B7: 12 | C7: 2250 | E7: =C7/B7 -> 187.5
A8: 奶油培根義大利麵 | B8: 15 | C8: 2250 | E8: =C8/B8 -> 150
A9: 蒜香奶油蝦蝦義大利麵-自 | B9: 14 | C9: 2118 | E9: =C9/B9 -> 151.28571
A10: 蒜香奶油蝦蝦義大利麵 | B10: 17 | C10: 1716 | E10: =C10/B10 -> 100.94118
A11: 義式辣味嫩烤雞腿排義大利麵 | B11: 15 | C11: 2250 | E11: =C11/B11 -> 150
A12: 香煎魚排佐檸檬奶油義大利麵 | B12: 15 | C12: 2250 | E12: =C12/B12 -> 150
A13: 黑松露野菇義大利麵 | B13: 19 | C13: 1565 | E13: =C13/B13 -> 82.368421 | J13: 黑松露野菇義大利麵 | K13: 17 | L13: 1565 | N13: =L13/K13 -> 92.058824
A14: 青花椒麻雞肉拌麵 | B14: 15 | C14: 1714 | E14: =C14/B14 -> 114.26667 | J14: 青花椒麻雞肉拌麵 | K14: 14 | L14: 1714 | N14: =L14/K14 -> 122.42857
A15: 焗烤起司雙饗筆尖麵 | B15: 16 | C15: 1800 | E15: =C15/B15 -> 112.5 | G15: 目前使用手工 | J15: 焗烤起司雙饗筆尖麵 | K15: 15 | L15: 1800 | N15: =L15/K15 -> 120
A16: 沙茶豬肉炒麵 | B16: 17 | C16: 1500 | E16: =C16/B16 -> 88.235294 | J16: 沙茶豬肉炒麵 | K16: 16 | L16: 1500 | N16: =L16/K16 -> 93.75
A17: 府城鹽水意麵 | B17: 17 | C17: 1636 | E17: =C17/B17 -> 96.235294 | J17: 府城鹽水意麵 | K17: 16 | L17: 1636 | N17: =L17/K17 -> 102.25
A18: 焗烤起司肉醬筆尖麵-降 | B18: 10 | C18: 1125 | E18: =C18/B18 -> 112.5 | J18: 焗烤起司肉醬筆尖麵 | K18: 12 | L18: 1440 | N18: =L18/K18 -> 120
A19: 焗烤起司肉醬筆尖麵 | B19: 13 | C19: 1440 | E19: =C19/B19 -> 110.76923 | G19: 目前使用雙排 | J19: 整條德式香腸義大利麵 | K19: 16 | L19: 1565 | N19: =L19/K19 -> 97.8125
A20: 整條德式香腸義大利麵 | B20: 17 | C20: 1565 | E20: =C20/B20 -> 92.058824
A26: 調理包
A27: 小滷青蔬 | B27: 15 | C27: 1565 | E27: =C27/B27 -> 104.33333 | G27: 夏季+1人補料
A28: 起司馬鈴薯 | B28: 12 | C28: 1565 | E28: =C28/B28 -> 130.41667
A29: 麻辣雞心 | B29: 9 | C29: 1636 | E29: =C29/B29 -> 181.77778
E34: 更新日期05/03

Sheet 範本總
B1: 長家廠組合室生產人時性分析
B3: 日期 | D3: 46015 | F3: 訂單量 | G3: =範本!E1 -> 43309 | I3: 營業額 | J3: =範本!G1 -> #N/A
B4: 項目 | D4: 3 | F4: ➀ | H4: ➁ | J4: ③ | L4: 異常停線 | N4: 短暫停線
B5: 人時性 | D5: 組合室 | F5: 全溫層 | H5: 義大利麵 | J5: 袋裝小吃、義麵 | L5: 合計次數 | M5: 時間 | N5: 合計次數 | O5: 設備次數
D6: 排關平均 | F6: =AVERAGE(D13:J13) -> #N/A | H6: =AVERAGE(D13:H13) -> #N/A | J6: =AVERAGE(I13:J13) -> #N/A | L6: =範本!Z2 -> 0 | M6: =範本!AA2 -> 0 | N6: =範本!AD2 -> 0 | O6: =範本!AE2 -> 0
D7: 實績平均 | F7: =AVERAGE(D14:J14) -> 116.11475 | H7: =AVERAGE(D14:H14) -> 117.36075 | J7: =AVERAGE(I14:J14) -> 112.99975
D8: 達成率平均 | F8: =AVERAGE(D15:J15) -> #N/A | H8: =AVERAGE(D15:H15) -> #N/A | J8: =AVERAGE(I15:J15) -> #N/A
J9: ※現行日本鮮食廠以達成率80%為基本(即為現行KPI)
B10: 溫層 | D10: 4度C-各編組展開
B11: 編組 | D11: 1 | E11: 2 | F11: 3 | G11: 4 | H11: 5 | I11: 6 | J11: 7
D12: 自動1線 | E12: 自動2線 | F12: 手工3線 | G12: 手工4線 | H12: 手工5線 | I12: 調理包1線 | J12: 調理包2線
B13: 人時性 | C13: 排關 | D13: =VALUE(範本!L15) -> #N/A | E13: =VALUE(範本!L26) -> #N/A | F13: =VALUE(範本!L37) -> #N/A | G13: =VALUE(範本!L48) -> #N/A | H13: =VALUE(範本!L58) -> #N/A | I13: =VALUE(範本!L69) -> #N/A | J13: =範本!L79 -> #N/A
C14: 實績 | D14: =VALUE(範本!O15) -> 113.91637 | E14: =VALUE(範本!O26) -> 132.12003 | F14: =VALUE(範本!O37) -> 126.23842 | G14: =VALUE(範本!O48) -> 112.0543 | H14: =VALUE(範本!O58) -> 102.47462 | I14: =VALUE(範本!O69) -> 155.46443 | J14: =範本!O79 -> 70.535065
C15: 達成率 | D15: =D14/D13 -> #N/A | E15: =E14/E13 -> #N/A | F15: =F14/F13 -> #N/A | G15: =G14/G13 -> #N/A | H15: =H14/H13 -> #N/A | I15: =I14/I13 -> #N/A | J15: =範本!S70 -> #N/A
B16: 作業 時間 | C16: 開始 | D16: =範本!T5 -> 0.29097222 | E16: =範本!T16 -> 0.29097222 | F16: =範本!T27 -> 0.29166667 | G16: =範本!T38 -> 0.33333333 | H16: =範本!T49 -> 0.29166667 | I16: =範本!T59 -> 0.29166667 | J16: =範本!T70 -> 0.34722222
C17: 結束 | D17: 0.47361111 | E17: 0.48263889 | F17: 0.56944444 | G17: 0.60416667 | H17: 0.58333333 | I17: 0.48819444 | J17: 0.46875
B18: 產線異常 (5分鐘以上) | C18: 次數
C19: 時間/分
B20: 短暫停線 (5分鐘以下) | C20: 次數
C21: 設備次數
B22: 配置人數 | D22: =VALUE(範本!M15) -> 15 | E22: =VALUE(範本!M26) -> 12.666667 | F22: =VALUE(範本!M37) -> 14.666667 | G22: =VALUE(範本!M48) -> 14 | H22: =VALUE(範本!M58) -> 17.666667 | I22: =VALUE(範本!M69) -> 12.333333 | J22: =範本!M79 -> 11
B23: 主要應用設備 | D23: ET-600 | E23: ET-600 | F23: ET-55 | G23: ET-55 | H23: ET-55 | I23: 八爪機
B24: 次要應用設備 | H24: 封口機
B25: 備註

Sheet 範本
A1: 長家廠4度C日報分析 | D1: 總生產量 | E1: =SUM(G5:G79) -> 43309 | F1: 營業額 | G1: =SUM(H5:H79) -> #N/A | H1: 出勤人數 | I1: =M15+M26+M48+M58+M69+M79+M37 -> 97.333333 | J1: 產線配置圖 | M1: 生產實績 | P1: 人時性差異分析 | T1: 日報登錄 | Z1: 合計 次數 | AA1: 合計 時間/分 | AB1: 分析說明 | AD1: 合計 次數 | AE1: 合計 設備次數 | AF1: 產能差異分析
A2: 12月24日 星期三 | D2: 人時性 | E2: =AVERAGE(O15,O26,O37,O48,O58,O69,O79) -> 116.11475 | F2: 平均廠價 | G2: =G1/E1 -> #N/A | H2: 多次生產數 | I2: =COUNT(I5:I79) -> 0 | Z2: =Z15+Z26+Z37+Z48+Z58+Z69+Z79 -> 0 | AA2: =AA15+AA26+AA37+AA48+AA58+AA69+AA79 -> 0 | AD2: =AD15+AD26+AD37+AD48+AD58+AD69+AD79 -> 0 | AE2: =AE15+AE26+AE37+AE48+AE58+AE69+AE79 -> 0
A3: 線別 | B3: 品類 | D3: 品名 | F3: 廠價 | G3: 生產量 | H3: 營收 | I3: 多次 生產 | J3: 人數 | K3: 產能/時 | L3: 人時性 | M3: 人數 | N3: 產能/時 | O3: 人時性 | P3: 人數 | Q3: 人時性 | R3: 達成率 | S3: 達成率平均 | T3: 生產時間 | V3: 前置、換線時間/分 | W3: 稼動時間/分 | X3: 休息時間 | Z3: 產線異常統計 (5分鐘以上) | AD3: 短暫停線統計 (5分鐘以下) | AF3: 產能/時 | AG3: 達成率 | AH3: 達成率平均
T4: 開始 | U4: 結束 | X4: 開始 | Y4: 結束 | Z4: 次數 | AA4: 時間/分 | AD4: 總次數 | AE4: 設備因素(次數)
A5: 自動一線 (ET-600) | B5: =VLOOKUP(D5,廠價表!$C$1:$E$43,2,0) -> #N/A | F5: =VLOOKUP(D5,廠價表!$C$1:$E$43,3,0) -> #N/A | G5: 2263 | H5: =F5*G5 -> #N/A | J5: =VLOOKUP(D5,產線配置圖!$A$3:$C$40,2,0) -> #N/A | K5: =VLOOKUP(D5,產線配置圖!$A$3:$C$40,3,0) -> #N/A | L5: =K5/J5 -> #N/A | M5: 15 | N5: =G5/W5*60 -> 1444.4681 | O5: =N5/M5 -> 96.297872 | P5: =M5-J5 -> #N/A | Q5: =O5-L5 -> #N/A | R5: =O5/L5 -> #N/A | S5: =R15 -> #N/A | T5: 0.29097222 | U5: 0.35625 | W5: =(U5-T5)*24*60 -> 94 | AF5: =N5-K5 -> #N/A | AG5: =N5/K5 -> #N/A | AH5: =AG15 -> #N/A
B6: =VLOOKUP(D6,廠價表!$C$1:$E$43,2,0) -> #N/A | F6: =VLOOKUP(D6,廠價表!$C$1:$E$43,3,0) -> #N/A | G6: 1180 | H6: =F6*G6 -> #N/A | J6: =VLOOKUP(D6,產線配置圖!$A$3:$C$40,2,0) -> #N/A | K6: =VLOOKUP(D6,產線配置圖!$A$3:$C$40,3,0) -> #N/A | L6: =K6/J6 -> #N/A | M6: 17 | N6: =G6/W6*60 -> 1609.0909 | O6: =N6/M6 -> 94.652406 | P6: =M6-J6 -> #N/A | Q6: =O6-L6 -> #N/A | R6: =O6/L6 -> #N/A | T6: 0.36458333 | U6: 0.39513889 | V6: =(T6-U5)*24*60 -> 12 | W6: =(U6-T6)*24*60 -> 44 | AF6: =N6-K6 -> #N/A | AG6: =N6/K6 -> #N/A
B7: =VLOOKUP(D7,廠價表!$C$1:$E$43,2,0) -> #N/A | F7: =VLOOKUP(D7,廠價表!$C$1:$E$43,3,0) -> #N/A | G7: 3398 | H7: =F7*G7 -> #N/A | J7: =VLOOKUP(D7,產線配置圖!$A$3:$C$40,2,0) -> #N/A | K7: =VLOOKUP(D7,產線配置圖!$A$3:$C$40,3,0) -> #N/A | L7: =K7/J7 -> #N/A | M7: 13 | N7: =G7/W7*60 -> 1960.3846 | O7: =N7/M7 -> 150.79882 | P7: =M7-J7 -> #N/A | Q7: =O7-L7 -> #N/A | R7: =O7/L7 -> #N/A | T7: 0.40138889 | U7: 0.47361111 | V7: =(T7-U6)*24*60 -> 9 | W7: =(U7-T7)*24*60 -> 104 | AF7: =N7-K7 -> #N/A | AG7: =N7/K7 -> #N/A
W8: =(U8-T8)*24*60 -> 0 | X8: 0.48611111 | Y8: 0.52777778 | AF8: =N8-K8 -> 0 | AG8: =N8/K8 -> #DIV/0!
W9: =(U9-T9)*24*60 -> 0 | AF9: =N9-K9 -> 0 | AG9: =N9/K9 -> #DIV/0!
W10: =(U10-T10)*24*60 -> 0 | AF10: =N10-K10 -> 0 | AG10: =N10/K10 -> #DIV/0!
W11: =(U11-T11)*24*60 -> 0 | AF11: =N11-K11 -> 0 | AG11: =N11/K11 -> #DIV/0!
W12: =(U12-T12)*24*60 -> 0
W13: =(U13-T13)*24*60 -> 0
W14: =(U14-T14)*24*60 -> 0
C15: 4度一組 | D15: 平均 | J15: =AVERAGE(J5:J14) -> #N/A | K15: =AVERAGE(K5:K14) -> #N/A | L15: =AVERAGE(L5:L14) -> #N/A | M15: =AVERAGE(M5:M14) -> 15 | N15: =AVERAGE(N5:N14) -> 1671.3145 | O15: =AVERAGE(O5:O14) -> 113.91637 | P15: =M15-J15 -> #N/A | Q15: =O15-L15 -> #N/A | R15: =O15/L15 -> #N/A | Z15: =SUM(Z5:Z14) -> 0 | AA15: =SUM(AA5:AA14) -> 0 | AD15: =SUM(AD5:AD14) -> 0 | AE15: =SUM(AE5:AE14) -> 0 | AF15: =N15-K15 -> #N/A | AG15: =N15/K15 -> #N/A
A16: 自動二線 (ET-600) | B16: =VLOOKUP(D16,廠價表!$C$1:$E$43,2,0) -> #N/A | F16: =VLOOKUP(D16,廠價表!$C$1:$E$43,3,0) -> #N/A | G16: 2263 | H16: =F16*G16 -> #N/A | J16: =VLOOKUP(D16,產線配置圖!$A$3:$C$40,2,0) -> #N/A | K16: =VLOOKUP(D16,產線配置圖!$A$3:$C$40,3,0) -> #N/A | L16: =K16/J16 -> #N/A | M16: 13 | N16: =G16/W16*60 -> 2225.9016 | O16: =N16/M16 -> 171.2232 | P16: =M16-J16 -> #N/A | Q16: =O16-L16 -> #N/A | R16: =O16/L16 -> #N/A | S16: =R26 -> #N/A | T16: 0.29097222 | U16: 0.33333333 | W16: =(U16-T16)*24*60 -> 61 | AF16: =N16-K16 -> #N/A | AG16: =N16/K16 -> #N/A | AH16: =AG26 -> #N/A
B17: =VLOOKUP(D17,廠價表!$C$1:$E$43,2,0) -> #N/A | F17: =VLOOKUP(D17,廠價表!$C$1:$E$43,3,0) -> #N/A | G17: 1180 | H17: =F17*G17 -> #N/A | J17: =VLOOKUP(D17,產線配置圖!$A$3:$C$40,2,0) -> #N/A | K17: =VLOOKUP(D17,產線配置圖!$A$3:$C$40,3,0) -> #N/A | L17: =K17/J17 -> #N/A | M17: 13 | N17: =G17/W17*60 -> 823.25581 | O17: =N17/M17 -> 63.32737 | P17: =M17-J17 -> #N/A | Q17: =O17-L17 -> #N/A | R17: =O17/L17 -> #N/A | T17: 0.34166667 | U17: 0.40138889 | V17: =(T17-U16)*24*60 -> 12 | W17: =(U17-T17)*24*60 -> 86 | AF17: =N17-K17 -> #N/A | AG17: =N17/K17 -> #N/A
B18: =VLOOKUP(D18,廠價表!$C$1:$E$43,2,0) -> #N/A | F18: =VLOOKUP(D18,廠價表!$C$1:$E$43,3,0) -> #N/A | G18: 3398 | H18: =F18*G18 -> #N/A | J18: =VLOOKUP(D18,產線配置圖!$A$3:$C$40,2,0) -> #N/A | K18: =VLOOKUP(D18,產線配置圖!$A$3:$C$40,3,0) -> #N/A | L18: =K18/J18 -> #N/A | M18: 12 | N18: =G18/W18*60 -> 1941.7143 | O18: =N18/M18 -> 161.80952 | P18: =M18-J18 -> #N/A | Q18: =O18-L18 -> #N/A | R18: =O18/L18 -> #N/A | T18: 0.40972222 | U18: 0.48263889 | V18: =(T18-U17)*24*60 -> 12 | W18: =(U18-T18)*24*60 -> 105 | X18: 0.48611111 | Y18: 0.52777778 | AF18: =N18-K18 -> #N/A | AG18: =N18/K18 -> #N/A
V19: =(T19-U18)*24*60 -> -695 | W19: =(U19-T19)*24*60 -> 0 | AF19: =N19-K19 -> 0 | AG19: =N19/K19 -> #DIV/0!
V20: =(T20-U19)*24*60 -> 0 | W20: =(U20-T20)*24*60 -> 0
W21: =(U21-T21)*24*60 -> 0
W22: 0
W23: =(U23-T23)*24*60 -> 0
H24: =F24*G24 -> 0 | W24: =(U24-T24)*24*60 -> 0
H25: =F25*G25 -> 0 | W25: =(U25-T25)*24*60 -> 0
C26: 4度二組A | D26: 平均 | J26: =AVERAGE(J16:J25) -> #N/A | K26: =AVERAGE(K16:K25) -> #N/A | L26: =AVERAGE(L16:L25) -> #N/A | M26: =AVERAGE(M16:M25) -> 12.666667 | N26: =AVERAGE(N16:N25) -> 1663.6239 | O26: =AVERAGE(O16:O25) -> 132.12003 | P26: =M26-J26 -> #N/A | Q26: =O26-L26 -> #N/A | R26: =O26/L26 -> #N/A | Z26: =SUM(Z16:Z25) -> 0 | AA26: =SUM(AA16:AA25) -> 0 | AD26: =SUM(AD16:AD25) -> 0 | AE26: =SUM(AE16:AE25) -> 0 | AF26: =N26-K26 -> #N/A | AG26: =N26/K26 -> #N/A
A27: 手工三線 (ET-55) | B27: =VLOOKUP(D27,廠價表!$C$1:$E$43,2,0) -> #N/A | F27: =VLOOKUP(D27,廠價表!$C$1:$E$43,3,0) -> #N/A | G27: 2263 | H27: =F27*G27 -> #N/A | J27: =VLOOKUP(D27,產線配置圖!$A$3:$C$40,2,0) -> #N/A | K27: =VLOOKUP(D27,產線配置圖!$A$3:$C$40,3,0) -> #N/A | L27: =K27/J27 -> #N/A | M27: 14 | N27: =G27/W27*60 -> 1212.3214 | O27: =N27/M27 -> 86.594388 | P27: =M27-J27 -> #N/A | Q27: =O27-L27 -> #N/A | R27: =O27/L27 -> #N/A | S27: =R37 -> #N/A | T27: 0.29166667 | U27: 0.36944444 | W27: =(U27-T27)*24*60 -> 112 | AF27: =N27-K27 -> #N/A | AG27: =N27/K27 -> #N/A | AH27: =AG37 -> #N/A
B28: =VLOOKUP(D28,廠價表!$C$1:$E$43,2,0) -> #N/A | F28: =VLOOKUP(D28,廠價表!$C$1:$E$43,3,0) -> #N/A | G28: 1180 | H28: =F28*G28 -> #N/A | J28: =VLOOKUP(D28,產線配置圖!$A$3:$C$40,2,0) -> #N/A | K28: =VLOOKUP(D28,產線配置圖!$A$3:$C$40,3,0) -> #N/A | L28: =K28/J28 -> #N/A | M28: 16 | N28: =G28/W28*60 -> 1089.2308 | O28: =N28/M28 -> 68.076923 | P28: =M28-J28 -> #N/A | Q28: =O28-L28 -> #N/A | R28: =O28/L28 -> #N/A | T28: 0.375 | U28: 0.42013889 | V28: =(T28-U27)*24*60 -> 8 | W28: =(U28-T28)*24*60 -> 65 | AF28: =N28-K28 -> #N/A | AG28: =N28/K28 -> #N/A
B29: =VLOOKUP(D29,廠價表!$C$1:$E$43,2,0) -> #N/A | F29: =VLOOKUP(D29,廠價表!$C$1:$E$43,3,0) -> #N/A | G29: 3398 | H29: =F29*G29 -> #N/A | J29: =VLOOKUP(D29,產線配置圖!$A$3:$C$40,2,0) -> #N/A | K29: =VLOOKUP(D29,產線配置圖!$A$3:$C$40,3,0) -> #N/A | L29: =K29/J29 -> #N/A | M29: 14 | N29: =G29/W29*60 -> 3136.6154 | O29: =N29/M29 -> 224.04396 | P29: =M29-J29 -> #N/A | Q29: =O29-L29 -> #N/A | R29: =O29/L29 -> #N/A | T29: 0.43055556 | U29: 0.47569444 | V29: =(T29-U28)*24*60 -> 15 | W29: =(U29-T29)*24*60 -> 65 | AF29: =N29-K29 -> #N/A | AG29: =N29/K29 -> #N/A
T30: 0.53958333 | U30: 0.56944444 | V30: =(T30-U29)*24*60 -> 92 | W30: =(U30-T30)*24*60 -> 43 | X30: 0.49652778 | Y30: 0.53819444 | AF30: =N30-K30 -> 0 | AG30: =N30/K30 -> #DIV/0!
W31: =(U31-T31)*24*60 -> 0 | AF31: =N31-K31 -> 0 | AG31: =N31/K31 -> #DIV/0!
W32: =(U32-T32)*24*60 -> 0
W33: =(U33-T33)*24*60 -> 0
W34: =(U34-T34)*24*60 -> 0
W35: =(U35-T35)*24*60 -> 0
H36: =F36*G36 -> 0 | W36: =(U36-T36)*24*60 -> 0
C37: 4度二組B | D37: 平均 | J37: =AVERAGE(J27:J36) -> #N/A | K37: =AVERAGE(K27:K36) -> #N/A | L37: =AVERAGE(L27:L36) -> #N/A | M37: =AVERAGE(M27:M36) -> 14.666667 | N37: =AVERAGE(N27:N36) -> 1812.7225 | O37: =AVERAGE(O27:O36) -> 126.23842 | P37: =M37-J37 -> #N/A | Q37: =N37-K37 -> #N/A | R37: =O37/L37 -> #N/A | Z37: =SUM(Z27:Z36) -> 0 | AA37: =SUM(AA27:AA36) -> 0 | AD37: =SUM(AD27:AD36) -> 0 | AE37: =SUM(AE27:AE36) -> 0 | AF37: =N37-K37 -> #N/A | AG37: =N37/K37 -> #N/A
A38: 手工四線 (ET-55) | B38: =VLOOKUP(D38,廠價表!$C$1:$E$43,2,0) -> #N/A | F38: =VLOOKUP(D38,廠價表!$C$1:$E$43,3,0) -> #N/A | G38: 2263 | H38: =F38*G38 -> #N/A | J38: =VLOOKUP(D38,產線配置圖!$A$3:$C$40,2,0) -> #N/A | K38: =VLOOKUP(D38,產線配置圖!$A$3:$C$40,3,0) -> #N/A | L38: =K38/J38 -> #N/A | M38: 14 | N38: =G38/W38*60 -> 1967.8261 | O38: =N38/M38 -> 140.55901 | P38: =M38-J38 -> #N/A | Q38: =O38-L38 -> #N/A | R38: =O38/L38 -> #N/A | S38: =R48 -> #N/A | T38: 0.33333333 | U38: 0.38125 | W38: =(U38-T38)*24*60 -> 69 | AF38: =N38-K38 -> #N/A | AG38: =N38/K38 -> #N/A | AH38: =AG48 -> #N/A
B39: =VLOOKUP(D39,廠價表!$C$1:$E$43,2,0) -> #N/A | F39: =VLOOKUP(D39,廠價表!$C$1:$E$43,3,0) -> #N/A | G39: 1180 | H39: =F39*G39 -> #N/A | J39: =VLOOKUP(D39,產線配置圖!$A$3:$C$40,2,0) -> #N/A | K39: =VLOOKUP(D39,產線配置圖!$A$3:$C$40,3,0) -> #N/A | L39: =K39/J39 -> #N/A | M39: 14 | N39: =G39/W39*60 -> 885 | O39: =N39/M39 -> 63.214286 | P39: =M39-J39 -> #N/A | Q39: =O39-L39 -> #N/A | R39: =O39/L39 -> #N/A | T39: 0.38888889 | U39: 0.44444444 | V39: =(T39-U38)*24*60 -> 11 | W39: =(U39-T39)*24*60 -> 80 | AF39: =N39-K39 -> #N/A | AG39: =N39/K39 -> #N/A
B40: =VLOOKUP(D40,廠價表!$C$1:$E$43,2,0) -> #N/A | F40: =VLOOKUP(D40,廠價表!$C$1:$E$43,3,0) -> #N/A | G40: 3398 | H40: =F40*G40 -> #N/A | J40: =VLOOKUP(D40,產線配置圖!$A$3:$C$40,2,0) -> #N/A | K40: =VLOOKUP(D40,產線配置圖!$A$3:$C$40,3,0) -> #N/A | L40: =K40/J40 -> #N/A | M40: 14 | N40: =G40/W40*60 -> 1853.4545 | O40: =N40/M40 -> 132.38961 | P40: =M40-J40 -> #N/A | Q40: =O40-L40 -> #N/A | R40: =O40/L40 -> #N/A | T40: 0.52777778 | U40: 0.60416667 | V40: =(T40-U39)*24*60 -> 120 | W40: =(U40-T40)*24*60 -> 110 | AF40: =N40-K40 -> #N/A | AG40: =N40/K40 -> #N/A
...

Sheet 0501總
B1: 長家廠組合室生產人時性分析
B3: 日期 | D3: 46144 | F3: 訂單量 | G3: ='0501'!E1 -> 44888 | I3: 營業額 | J3: ='0501'!G1 -> 2177171.2
B4: 項目 | D4: 3 | F4: ➀ | H4: ➁ | J4: ③ | L4: 異常停線 | N4: 短暫停線
B5: 人時性 | D5: 組合室 | F5: 全溫層 | H5: 義大利麵 | J5: 袋裝小吃、義麵 | L5: 合計次數 | M5: 時間 | N5: 合計次數 | O5: 設備次數
D6: 排關平均 | F6: =AVERAGE(D13:I13) -> 123.81075 | H6: =AVERAGE(D13:H13) -> 125.09791 | J6: =AVERAGE(I13) -> 117.375 | L6: =SUM(D18:J18) -> 2 | M6: =SUM(D19:J19) -> 48 | N6: =SUM(D20:J20) -> 0 | O6: =SUM(D20:J20) -> 0
D7: 實績平均 | F7: =AVERAGE(D14:I14) -> 115.43089 | H7: =AVERAGE(D14:H14) -> 116.95395 | J7: =AVERAGE(I14) -> 107.81558 | L7: =AVERAGE(K14:L14) -> #DIV/0! | M7: =AVERAGE(L14:M14) -> #DIV/0! | N7: =AVERAGE(M14:N14) -> #DIV/0! | O7: =AVERAGE(N14:O14) -> #DIV/0!
D8: 達成率平均 | F8: =F7/F6 -> 0.93231715 | H8: =H7/H6 -> 0.93489935 | J8: =J7/J6 -> 0.91855663 | L8: =AVERAGE(K15:L15) -> #DIV/0! | M8: =AVERAGE(L15:M15) -> #DIV/0! | N8: =AVERAGE(M15:N15) -> #DIV/0! | O8: =AVERAGE(N15:O15) -> #DIV/0!
J9: ※現行日本鮮食廠以達成率80%為基本(即為現行KPI)
B10: 溫層 | D10: 4度C-各編組展開
B11: 編組 | D11: 1 | E11: 2 | F11: 3 | G11: 4 | H11: 5 | I11: 6 | J11: 7
D12: 自動1線 | E12: 自動2線 | F12: 手工3線 | G12: 手工4線 | H12: 手工5線 | I12: 調理包1線 | J12: 調理包2線
B13: 人時性 | C13: 排關 | D13: =VALUE('0501'!L15) -> 150 | E13: =VALUE('0501'!L26) -> 170.19231 | F13: =VALUE('0501'!L37) -> 96.50212 | G13: =VALUE('0501'!L48) -> 105.25098 | H13: =VALUE('0501'!L58) -> 103.54412 | I13: =VALUE('0501'!L69) -> 117.375 | J13: ='0501'!L79 -> 0
C14: 實績 | D14: =VALUE('0501'!O15) -> 137.51321 | E14: =VALUE('0501'!O26) -> 156.72951 | F14: =VALUE('0501'!O37) -> 95.037332 | G14: =VALUE('0501'!O48) -> 101.34152 | H14: =VALUE('0501'!O58) -> 94.148171 | I14: =VALUE('0501'!O69) -> 107.81558 | J14: ='0501'!O79 -> 0
C15: 達成率 | D15: =D14/D13 -> 0.91675477 | E15: =E14/E13 -> 0.92089658 | F15: =F14/F13 -> 0.98482119 | G15: =G14/G13 -> 0.96285581 | H15: =H14/H13 -> 0.90925659 | I15: =I14/I13 -> 0.91855663 | J15: ='0501'!S70 -> 0
B16: 作業 時間 | C16: 開始 | D16: ='0501'!T5 -> 0.29166667 | E16: ='0501'!T16 -> 0.29027778 | F16: ='0501'!T27 -> 0.29166667 | G16: ='0501'!T38 -> 0.33333333 | H16: ='0501'!T49 -> 0.29166667 | I16: ='0501'!T59 -> 0.29166667 | J16: ='0501'!T70 -> 0
C17: 結束 | D17: 0.56944444 | E17: 0.47569444 | F17: 0.625 | G17: 0.49305556 | H17: 0.60069444 | I17: 0.46180556 | J17: 0
B18: 產線異常 (5分鐘以上) | C18: 次數 | D18: ='0501'!Z15 -> 0 | E18: ='0501'!Z26 -> 0 | F18: ='0501'!Z37 -> 2 | G18: ='0501'!Z48 -> 0 | H18: ='0501'!Z58 -> 0 | I18: ='0501'!Z69 -> 0 | J18: ='0501'!AA79 -> 0
C19: 時間/分 | D19: ='0501'!AA15 -> 0 | E19: ='0501'!AA26 -> 0 | F19: ='0501'!AA37 -> 48 | G19: ='0501'!AA48 -> 0 | H19: ='0501'!AA58 -> 0 | I19: ='0501'!AA69 -> 0 | J19: ='0501'!AB79 -> 0
B20: 短暫停線 (5分鐘以下) | C20: 次數 | D20: ='0501'!AD15 -> 0 | E20: ='0501'!AD26 -> 0 | F20: ='0501'!AD37 -> 0 | G20: ='0501'!AD48 -> 0 | H20: ='0501'!AD58 -> 0 | I20: ='0501'!AD69 -> 0 | J20: ='0501'!AD79 -> 0
C21: 設備次數 | D21: ='0501'!AE15 -> 0 | E21: ='0501'!AE26 -> 0 | F21: ='0501'!AE37 -> 0 | G21: ='0501'!AE48 -> 0 | H21: ='0501'!AE58 -> 0 | I21: ='0501'!AE69 -> 0 | J21: ='0501'!AE79 -> 0
B22: 配置人數 | D22: =VALUE('0501'!M15) -> 15 | E22: =VALUE('0501'!M26) -> 13.333333 | F22: =VALUE('0501'!M37) -> 13.4 | G22: =VALUE('0501'!M48) -> 15 | H22: =VALUE('0501'!M58) -> 15.5 | I22: =VALUE('0501'!M69) -> 12.5 | J22: ='0501'!M79 -> 0
B23: 主要應用設備 | D23: ET-600 | E23: ET-600 | F23: ET-55 | G23: ET-55 | H23: ET-55 | I23: 八爪機 | J23: 八爪機
B24: 次要應用設備 | H24: 封口機 | J24: 封口機
B25: 備註

Sheet 0501
A1: 長家廠4度C日報分析 | D1: 總生產量 | E1: =SUM(G5:G79) -> 44888 | F1: 營業額 | G1: =SUM(H5:H79) -> 2177171.2 | H1: 出勤人數 | I1: =M15+M26+M48+M58+M69+M79+M37 -> 84.733333 | J1: 產線配置圖 | M1: 生產實績 | P1: 人時性差異分析 | T1: 日報登錄 | Z1: 合計 次數 | AA1: 合計 時間/分 | AB1: 分析說明 | AD1: 合計 次數 | AE1: 合計 設備次數 | AF1: 產能差異分析
A2: 05月01日 星期五 | D2: 人時性 | E2: =AVERAGE(O15,O26,O37,O48,O58,O69,O79) -> 115.43089 | F2: 平均廠價 | G2: =G1/E1 -> 48.502298 | H2: 多次生產數 | I2: =COUNT(I5:I79) -> 0 | Z2: =Z15+Z26+Z37+Z48+Z58+Z69+Z79 -> 2 | AA2: =AA15+AA26+AA37+AA48+AA58+AA69+AA79 -> 48 | AD2: =AD15+AD26+AD37+AD48+AD58+AD69+AD79 -> 0 | AE2: =AE15+AE26+AE37+AE48+AE58+AE69+AE79 -> 0
A3: 線別 | B3: 品類 | D3: 品名 | F3: 廠價 | G3: 生產量 | H3: 營收 | I3: 多次 生產 | J3: 人數 | K3: 產能/時 | L3: 人時性 | M3: 人數 | N3: 產能/時 | O3: 人時性 | P3: 人數 | Q3: 人時性 | R3: 達成率 | S3: 達成率平均 | T3: 生產時間 | V3: 前置、換線時間/分 | W3: 稼動時間/分 | X3: 休息時間 | Z3: 產線異常統計 (5分鐘以上) | AD3: 短暫停線統計 (5分鐘以下) | AF3: 產能/時 | AG3: 達成率 | AH3: 達成率平均
T4: 開始 | U4: 結束 | X4: 開始 | Y4: 結束 | Z4: 次數 | AA4: 時間/分 | AD4: 總次數 | AE4: 設備因素(次數)
A5: 自動一線 (ET-600) | B5: 義大利麵 | D5: 白酒清炒鮮蛤義大利麵 | F5: =VLOOKUP(D5,廠價表!$C$1:$E$43,3,0) -> 56.87 | G5: 2425 | H5: =F5*G5 -> 137909.75 | J5: =VLOOKUP(D5,產線配置圖!$A$3:$C$40,2,0) -> 15 | K5: =VLOOKUP(D5,產線配置圖!$A$3:$C$40,3,0) -> 2250 | L5: =K5/J5 -> 150 | M5: 15 | N5: =G5/W5*60 -> 2139.7059 | O5: =N5/M5 -> 142.64706 | P5: =M5-J5 -> 0 | Q5: =O5-L5 -> -7.3529412 | R5: =O5/L5 -> 0.95098039 | S5: =R15 -> 0.91675477 | T5: 0.29166667 | U5: 0.33888889 | W5: =(U5-T5)*24*60 -> 68 | AF5: =N5-K5 -> -110.29412 | AG5: =N5/K5 -> 0.95098039 | AH5: =AG15 -> 0.91675477
B6: 義大利麵 | D6: 奶油培根義大利麵 | F6: =VLOOKUP(D6,廠價表!$C$1:$E$43,3,0) -> 49.14 | G6: 4724 | H6: =F6*G6 -> 232137.36 | J6: =VLOOKUP(D6,產線配置圖!$A$3:$C$40,2,0) -> 15 | K6: =VLOOKUP(D6,產線配置圖!$A$3:$C$40,3,0) -> 2250 | L6: =K6/J6 -> 150 | M6: 15 | N6: =G6/W6*60 -> 2131.1278 | O6: =N6/M6 -> 142.07519 | P6: =M6-J6 -> 0 | Q6: =O6-L6 -> -7.924812 | R6: =O6/L6 -> 0.94716792 | T6: 0.34722222 | U6: 0.43958333 | V6: =(T6-U5)*24*60 -> 12 | W6: =(U6-T6)*24*60 -> 133 | AF6: =N6-K6 -> -118.87218 | AG6: =N6/K6 -> 0.94716792
B7: 義大利麵 | D7: 香煎魚排佐檸檬奶油義大利麵 | F7: =VLOOKUP(D7,廠價表!$C$1:$E$43,3,0) -> 58.17 | G7: 1697 | H7: =F7*G7 -> 98714.49 | J7: =VLOOKUP(D7,產線配置圖!$A$3:$C$40,2,0) -> 15 | K7: =VLOOKUP(D7,產線配置圖!$A$3:$C$40,3,0) -> 2250 | L7: =K7/J7 -> 150 | M7: 15 | N7: =G7/W7*60 -> 2077.9592 | O7: =N7/M7 -> 138.53061 | P7: =M7-J7 -> 0 | Q7: =O7-L7 -> -11.469388 | R7: =O7/L7 -> 0.92353741 | T7: 0.44513889 | U7: 0.47916667 | V7: =(T7-U6)*24*60 -> 8 | W7: =(U7-T7)*24*60 -> 49 | X7: 0.49305556 | Y7: 0.53472222 | AF7: =N7-K7 -> -172.04082 | AG7: =N7/K7 -> 0.92353741
B8: 義大利麵 | D8: 香煎魚排佐檸檬奶油義大利麵 | F8: =VLOOKUP(D8,廠價表!$C$1:$E$43,3,0) -> 58.17 | G8: 1268 | H8: =F8*G8 -> 73759.56 | J8: =VLOOKUP(D8,產線配置圖!$A$3:$C$40,2,0) -> 15 | K8: =VLOOKUP(D8,產線配置圖!$A$3:$C$40,3,0) -> 2250 | L8: =K8/J8 -> 150 | M8: 15 | N8: =G8/W8*60 -> 1902 | O8: =N8/M8 -> 126.8 | P8: =M8-J8 -> 0 | Q8: =O8-L8 -> -23.2 | R8: =O8/L8 -> 0.84533333 | T8: 0.54166667 | U8: 0.56944444 | V8: =(T8-U7)*24*60 -> 90 | W8: =(U8-T8)*24*60 -> 40 | AF8: =N8-K8 -> -348 | AG8: =N8/K8 -> 0.84533333
W9: =(U9-T9)*24*60 -> 0 | AF9: =N9-K9 -> 0 | AG9: =N9/K9 -> #DIV/0!
W10: =(U10-T10)*24*60 -> 0 | AF10: =N10-K10 -> 0 | AG10: =N10/K10 -> #DIV/0!
W11: =(U11-T11)*24*60 -> 0 | AF11: =N11-K11 -> 0 | AG11: =N11/K11 -> #DIV/0!
W12: =(U12-T12)*24*60 -> 0
W13: =(U13-T13)*24*60 -> 0
W14: =(U14-T14)*24*60 -> 0
C15: 4度一組 | D15: 平均 | J15: =AVERAGE(J5:J14) -> 15 | K15: =AVERAGE(K5:K14) -> 2250 | L15: =AVERAGE(L5:L14) -> 150 | M15: =AVERAGE(M5:M14) -> 15 | N15: =AVERAGE(N5:N14) -> 2062.6982 | O15: =AVERAGE(O5:O14) -> 137.51321 | P15: =M15-J15 -> 0 | Q15: =O15-L15 -> -12.486785 | R15: =O15/L15 -> 0.91675477 | Z15: =SUM(Z5:Z14) -> 0 | AA15: =SUM(AA5:AA14) -> 0 | AD15: =SUM(AD5:AD14) -> 0 | AE15: =SUM(AE5:AE14) -> 0 | AF15: =N15-K15 -> -187.30178 | AG15: =N15/K15 -> 0.91675477
A16: 自動二線 (ET-600) | B16: 義大利麵 | D16: 青醬蛤蜊義大利麵 | F16: =VLOOKUP(D16,廠價表!$C$1:$E$43,3,0) -> 50.67 | G16: 3118 | H16: =F16*G16 -> 157989.06 | J16: =VLOOKUP(D16,產線配置圖!$A$3:$C$40,2,0) -> 13 | K16: =VLOOKUP(D16,產線配置圖!$A$3:$C$40,3,0) -> 2250 | L16: =K16/J16 -> 173.07692 | M16: 13 | N16: =G16/W16*60 -> 2102.0225 | O16: =N16/M16 -> 161.69404 | P16: =M16-J16 -> 0 | Q16: =O16-L16 -> -11.382887 | R16: =O16/L16 -> 0.93423221 | S16: =R26 -> 0.92089658 | T16: 0.29027778 | U16: 0.35208333 | W16: =(U16-T16)*24*60 -> 89 | AF16: =N16-K16 -> -147.97753 | AG16: =N16/K16 -> 0.93423221 | AH16: =AG26 -> 0.91936678
B17: 義大利麵 | D17: 義式辣味嫩烤雞腿排義大利麵 | F17: =VLOOKUP(D17,廠價表!$C$1:$E$43,3,0) -> 56.61 | G17: 1741 | H17: =F17*G17 -> 98558.01 | J17: =VLOOKUP(D17,產線配置圖!$A$3:$C$40,2,0) -> 15 | K17: =VLOOKUP(D17,產線配置圖!$A$3:$C$40,3,0) -> 2250 | L17: =K17/J17 -> 150 | M17: 15 | N17: =G17/W17*60 -> 2008.8462 | O17: =N17/M17 -> 133.92308 | P17: =M17-J17 -> 0 | Q17: =O17-L17 -> -16.076923 | R17: =O17/L17 -> 0.89282051 | T17: 0.35833333 | U17: 0.39444444 | V17: =(T17-U16)*24*60 -> 9 | W17: =(U17-T17)*24*60 -> 52 | AF17: =N17-K17 -> -241.15385 | AG17: =N17/K17 -> 0.89282051
B18: 義大利麵 | D18: 義式蕃茄起司義大利麵 | F18: =VLOOKUP(D18,廠價表!$C$1:$E$43,3,0) -> 50.39 | G18: 3666 | H18: =F18*G18 -> 184729.74 | J18: =VLOOKUP(D18,產線配置圖!$A$3:$C$40,2,0) -> 12 | K18: =VLOOKUP(D18,產線配置圖!$A$3:$C$40,3,0) -> 2250 | L18: =K18/J18 -> 187.5 | M18: 12 | N18: =G18/W18*60 -> 2094.8571 | O18: =N18/M18 -> 174.57143 | P18: =M18-J18 -> 0 | Q18: =O18-L18 -> -12.928571 | R18: =O18/L18 -> 0.93104762 | T18: 0.40277778 | U18: 0.47569444 | V18: =(T18-U17)*24*60 -> 12 | W18: =(U18-T18)*24*60 -> 105 | AF18: =N18-K18 -> -155.14286 | AG18: =N18/K18 -> 0.93104762
W19: =(U19-T19)*24*60 -> 0 | AF19: =N19-K19 -> 0 | AG19: =N19/K19 -> #DIV/0!
W20: =(U20-T20)*24*60 -> 0
W21: =(U21-T21)*24*60 -> 0
W22: 0
W23: =(U23-T23)*24*60 -> 0
H24: =F24*G24 -> 0 | W24: =(U24-T24)*24*60 -> 0
H25: =F25*G25 -> 0 | W25: =(U25-T25)*24*60 -> 0
C26: 4度二組A | D26: 平均 | J26: =AVERAGE(J16:J25) -> 13.333333 | K26: =AVERAGE(K16:K25) -> 2250 | L26: =AVERAGE(L16:L25) -> 170.19231 | M26: =AVERAGE(M16:M25) -> 13.333333 | N26: =AVERAGE(N16:N25) -> 2068.5753 | O26: =AVERAGE(O16:O25) -> 156.72951 | P26: =M26-J26 -> 0 | Q26: =O26-L26 -> -13.462794 | R26: =O26/L26 -> 0.92089658 | Z26: =SUM(Z16:Z25) -> 0 | AA26: =SUM(AA16:AA25) -> 0 | AD26: =SUM(AD16:AD25) -> 0 | AE26: =SUM(AE16:AE25) -> 0 | AF26: =N26-K26 -> -181.42474 | AG26: =N26/K26 -> 0.91936678
A27: 手工三線 (ET-55) | B27: 義大利麵 | D27: 焗烤起司肉醬筆尖麵 | F27: =VLOOKUP(D27,廠價表!$C$1:$E$43,3,0) -> 50.67 | G27: 997 | H27: =F27*G27 -> 50517.99 | J27: =VLOOKUP(D27,產線配置圖!$A$3:$C$40,2,0) -> 13 | K27: =VLOOKUP(D27,產線配置圖!$A$3:$C$40,3,0) -> 1440 | L27: =K27/J27 -> 110.76923 | M27: 13 | N27: =G27/W27*60 -> 747.75 | O27: =N27/M27 -> 57.519231 | P27: =M27-J27 -> 0 | Q27: =O27-L27 -> -53.25 | R27: =O27/L27 -> 0.51927083 | S27: =R37 -> 0.98482119 | T27: 0.29166667 | U27: 0.34722222 | W27: =(U27-T27)*24*60 -> 80 | Z27: 2 | AA27: 48 | AB27: (07:00-07:35/07:45-07:58)製作1659盒、665盒封膜異常 | AF27: =N27-K27 -> -692.25 | AG27: =N27/K27 -> 0.51927083 | AH27: =AG37 -> 0.64644987
B28: 義大利麵 | D28: 黑松露野菇義大利麵 | F28: =VLOOKUP(D28,廠價表!$C$1:$E$43,3,0) -> 50.289 | G28: 3890 | H28: =F28*G28 -> 195624.21 | J28: =VLOOKUP(D28,產線配置圖!$A$3:$C$40,2,0) -> 19 | K28: =VLOOKUP(D28,產線配置圖!$A$3:$C$40,3,0) -> 1565 | L28: =K28/J28 -> 82.368421 | M28: 18 | N28: =G28/W28*60 -> 1372.9412 | O28: =N28/M28 -> 76.27451 | P28: =M28-J28 -> -1 | Q28: =O28-L28 -> -6.0939112 | R28: =O28/L28 -> 0.92601641 | T28: 0.35763889 | U28: 0.47569444 | V28: =(T28-U27)*24*60 -> 15 | W28: =(U28-T28)*24*60 -> 170 | X28: 0.47916667 | Y28: 0.53125 | AF28: =N28-K28 -> -192.05882 | AG28: =N28/K28 -> 0.87727871
B29: 義大利麵 | D29: 焗烤起司肉醬筆尖麵 | F29: =VLOOKUP(D29,廠價表!$C$1:$E$43,3,0) -> 50.67 | G29: 665 | H29: =F29*G29 -> 33695.55 | J29: =VLOOKUP(D29,產線配置圖!$A$3:$C$40,2,0) -> 13 | K29: =VLOOKUP(D29,產線配置圖!$A$3:$C$40,3,0) -> 1440 | L29: =K29/J29 -> 110.76923 | M29: 2 | N29: =G29/W29*60 -> 399 | O29: =N29/M29 -> 199.5 | P29: =M29-J29 -> -11 | Q29: =O29-L29 -> 88.730769 | R29: =O29/L29 -> 1.8010417 | T29: 0.36111111 | U29: 0.43055556 | V29: =(T29-U28)*24*60 -> -165 | W29: =(U29-T29)*24*60 -> 100 | AB29: 補封膜665盒 | AF29: =N29-K29 -> -1041 | AG29: =N29/K29 -> 0.27708333
B30: 義大利麵 | D30: 黑松露野菇義大利麵 | F30: =VLOOKUP(D30,廠價表!$C$1:$E$43,3,0) -> 50.289 | G30: 1100 | H30: =F30*G30 -> 55317.9 | J30: =VLOOKUP(D30,產線配置圖!$A$3:$C$40,2,0) -> 19 | K30: =VLOOKUP(D30,產線配置圖!$A$3:$C$40,3,0) -> 1565 | L30: =K30/J30 -> 82.368421 | M30: 18 | N30: =G30/W30*60 -> 1375 | O30: =N30/M30 -> 76.388889 | P30: =M30-J30 -> -1 | Q30: =O30-L30 -> -5.9795322 | R30: =O30/L30 -> 0.92740504 | T30: 0.53680556 | U30: 0.57013889 | V30: =(T30-U29)*24*60 -> 153 | W30: =(U30-T30)*24*60 -> 48 | AF30: =N30-K30 -> -190 | AG30: =N30/K30 -> 0.87859425
B31: 熱乾麵 | D31: 府城鹽水意麵 | F31: =VLOOKUP(D31,廠價表!$C$1:$E$43,3,0) -> 44.3 | G31: 1083 | H31: =F31*G31 -> 47976.9 | J31: =VLOOKUP(D31,產線配置圖!$A$3:$C$40,2,0) -> 17 | K31: =VLOOKUP(D31,產線配置圖!$A$3:$C$40,3,0) -> 1636 | L31: =K31/J31 -> 96.235294 | M31: 16 | N31: =G31/W31*60 -> 1048.0645 | O31: =N31/M31 -> 65.504032 | P31: =M31-J31 -> -1 | Q31: =O31-L31 -> -30.731262 | R31: =O31/L31 -> 0.68066537 | T31: 0.58194444 | U31: 0.625 | V31: =(T31-U30)*24*60 -> 17 | W31: =(U31-T31)*24*60 -> 62 | AB31: 生產數量少 | AF31: =N31-K31 -> -587.93548 | AG31: =N31/K31 -> 0.64062623
W32: =(U32-T32)*24*60 -> 0
W33: =(U33-T33)*24*60 -> 0
W34: =(U34-T34)*24*60 -> 0
W35: =(U35-T35)*24*60 -> 0
H36: =F36*G36 -> 0 | W36: =(U36-T36)*24*60 -> 0
C37: 4度二組B | D37: 平均 | J37: =AVERAGE(J27:J36) -> 16.2 | K37: =AVERAGE(K27:K36) -> 1529.2 | L37: =AVERAGE(L27:L36) -> 96.50212 | M37: =AVERAGE(M27:M36) -> 13.4 | N37: =AVERAGE(N27:N36) -> 988.55114 | O37: =AVERAGE(O27:O36) -> 95.037332 | P37: =M37-J37 -> -2.8 | Q37: =N37-K37 -> -540.64886 | R37: =O37/L37 -> 0.98482119 | Z37: =SUM(Z27:Z36) -> 2 | AA37: =SUM(AA27:AA36) -> 48 | AD37: =SUM(AD27:AD36) -> 0 | AE37: =SUM(AE27:AE36) -> 0 | AF37: =N37-K37 -> -540.64886 | AG37: =N37/K37 -> 0.64644987
A38: 手工四線 (ET-55) | B38: 熱乾麵 | D38: 青花椒麻雞肉拌麵 | F38: =VLOOKUP(D38,廠價表!$C$1:$E$43,3,0) -> 49.91 | G38: 2432 | H38: =F38*G38 -> 121381.12 | J38: =VLOOKUP(D38,產線配置圖!$A$3:$C$40,2,0) -> 15 | K38: =VLOOKUP(D38,產線配置圖!$A$3:$C$40,3,0) -> 1714 | L38: =K38/J38 -> 114.26667 | M38: 14 | N38: =G38/W38*60 -> 1536 | O38: =N38/M38 -> 109.71429 | P38: =M38-J38 -> -1 | Q38: =O38-L38 -> -4.552381 | R38: =O38/L38 -> 0.96016003 | S38: =R48 -> 0.96285581 | T38: 0.33333333 | U38: 0.39930556 | W38: =(U38-T38)*24*60 -> 95 | AF38: =N38-K38 -> -178 | AG38: =N38/K38 -> 0.89614936 | AH38: =AG48 -> 0.90253731
B39: 熱乾麵 | D39: 府城鹽水意麵 | F39: =VLOOKUP(D39,廠價表!$C$1:$E$43,3,0) -> 44.3 | G39: 2975 | H39: =F39*G39 -> 131792.5 | J39: =VLOOKUP(D39,產線配置圖!$A$3:$C$40,2,0) -> 17 | K39: =VLOOKUP(D39,產線配置圖!$A$3:$C$40,3,0) -> 1636 | L39: =K39/J39 -> 96.235294 | M39: 16 | N39: =G39/W39*60 -> 1487.5 | O39: =N39/M39 -> 92.96875 | P39: =M39-J39 -> -1 | Q39: =O39-L39 -> -3.2665441 | R39: =O39/L39 -> 0.96605669 | T39: 0.40972222 | U39: 0.49305556 | V39: =(T39-U38)*24*60 -> 15 | W39: =(U39-T39)*24*60 -> 120 | AF39: =N39-K39 -> -148.5 | AG39: =N39/K39 -> 0.90922983
W40: =(U40-T40)*24*60 -> 0 | AF40: =N40-K40 -> 0 | AG40: =N40/K40 -> #DIV/0!
...

Sheet 0502總
B1: 長家廠組合室生產人時性分析
B3: 日期 | D3: 46144 | F3: 訂單量 | G3: ='0502'!E1 -> 45987 | I3: 營業額 | J3: ='0502'!G1 -> 2245600.5
B4: 項目 | D4: 3 | F4: ➀ | H4: ➁ | J4: ③ | L4: 異常停線 | N4: 短暫停線
B5: 人時性 | D5: 組合室 | F5: 全溫層 | H5: 義大利麵 | J5: 袋裝小吃、義麵 | L5: 合計次數 | M5: 時間 | N5: 合計次數 | O5: 設備次數
D6: 排關平均 | F6: =AVERAGE(D13:I13) -> 123.62042 | H6: =AVERAGE(D13:H13) -> 124.86951 | J6: =AVERAGE(I13) -> 117.375 | L6: =SUM(D18:J18) -> 3 | M6: =SUM(D19:J19) -> 47 | N6: =SUM(D20:J20) -> 0 | O6: =SUM(D20:J20) -> 0
D7: 實績平均 | F7: =AVERAGE(D14:I14) -> 106.08858 | H7: =AVERAGE(D14:H14) -> 105.75235 | J7: =AVERAGE(I14) -> 107.76974 | L7: =AVERAGE(K14:L14) -> #DIV/0! | M7: =AVERAGE(L14:M14) -> #DIV/0! | N7: =AVERAGE(M14:N14) -> #DIV/0! | O7: =AVERAGE(N14:O14) -> #DIV/0!
D8: 達成率平均 | F8: =F7/F6 -> 0.85818005 | H8: =H7/H6 -> 0.8469029 | J8: =J7/J6 -> 0.91816608 | L8: =AVERAGE(K15:L15) -> #DIV/0! | M8: =AVERAGE(L15:M15) -> #DIV/0! | N8: =AVERAGE(M15:N15) -> #DIV/0! | O8: =AVERAGE(N15:O15) -> #DIV/0!
J9: ※現行日本鮮食廠以達成率80%為基本(即為現行KPI)
B10: 溫層 | D10: 4度C-各編組展開
B11: 編組 | D11: 1 | E11: 2 | F11: 3 | G11: 4 | H11: 5 | I11: 6 | J11: 7
D12: 自動1線 | E12: 自動2線 | F12: 手工3線 | G12: 手工4線 | H12: 手工5線 | I12: 調理包1線 | J12: 調理包2線
B13: 人時性 | C13: 排關 | D13: =VALUE('0502'!L15) -> 150 | E13: =VALUE('0502'!L26) -> 169.61538 | F13: =VALUE('0502'!L37) -> 96.457649 | G13: =VALUE('0502'!L48) -> 105.25098 | H13: =VALUE('0502'!L58) -> 103.02353 | I13: =VALUE('0502'!L69) -> 117.375 | J13: ='0502'!L79 -> 0
C14: 實績 | D14: =VALUE('0502'!O15) -> 137.09487 | E14: =VALUE('0502'!O26) -> 122.53058 | F14: =VALUE('0502'!O37) -> 86.502407 | G14: =VALUE('0502'!O48) -> 92.988917 | H14: =VALUE('0502'!O58) -> 89.644973 | I14: =VALUE('0502'!O69) -> 107.76974 | J14: ='0502'!O79 -> 0
C15: 達成率 | D15: =D14/D13 -> 0.91396578 | E15: =E14/E13 -> 0.72240253 | F15: =F14/F13 -> 0.89679157 | G15: =G14/G13 -> 0.88349692 | H15: =H14/H13 -> 0.87014077 | I15: =I14/I13 -> 0.91816608 | J15: ='0502'!S70 -> 0
B16: 作業 時間 | C16: 開始 | D16: ='0502'!T5 -> 0.29166667 | E16: ='0502'!T16 -> 0.29166667 | F16: ='0502'!T27 -> 0.29166667 | G16: ='0502'!T38 -> 0.33333333 | H16: ='0502'!T49 -> 0.29166667 | I16: ='0502'!T59 -> 0.29166667 | J16: ='0502'!T70 -> 0
C17: 結束 | D17: 0.60347222 | E17: 0.59444444 | F17: 0.58472222 | G17: 0.46875 | H17: 0.61805556 | I17: 0.43402778 | J17: 0
B18: 產線異常 (5分鐘以上) | C18: 次數 | D18: ='0502'!Z15 -> 1 | E18: ='0502'!Z26 -> 2 | F18: ='0502'!Z37 -> 0 | G18: ='0502'!Z48 -> 0 | H18: ='0502'!Z58 -> 0 | I18: ='0502'!Z69 -> 0 | J18: ='0502'!AA79 -> 0
C19: 時間/分 | D19: ='0502'!AA15 -> 10 | E19: ='0502'!AA26 -> 37 | F19: ='0502'!AA37 -> 0 | G19: ='0502'!AA48 -> 0 | H19: ='0502'!AA58 -> 0 | I19: ='0502'!AA69 -> 0 | J19: ='0502'!AB79 -> 0
B20: 短暫停線 (5分鐘以下) | C20: 次數 | D20: ='0502'!AD15 -> 0 | E20: ='0502'!AD26 -> 0 | F20: ='0502'!AD37 -> 0 | G20: ='0502'!AD48 -> 0 | H20: ='0502'!AD58 -> 0 | I20: ='0502'!AD69 -> 0 | J20: ='0502'!AD79 -> 0
C21: 設備次數 | D21: ='0502'!AE15 -> 0 | E21: ='0502'!AE26 -> 0 | F21: ='0502'!AE37 -> 0 | G21: ='0502'!AE48 -> 0 | H21: ='0502'!AE58 -> 0 | I21: ='0502'!AE69 -> 0 | J21: ='0502'!AE79 -> 0
B22: 配置人數 | D22: =VALUE('0502'!M15) -> 15 | E22: =VALUE('0502'!M26) -> 13.4 | F22: =VALUE('0502'!M37) -> 16.333333 | G22: =VALUE('0502'!M48) -> 16 | H22: =VALUE('0502'!M58) -> 16.2 | I22: =VALUE('0502'!M69) -> 13.5 | J22: ='0502'!M79 -> 0
B23: 主要應用設備 | D23: ET-600 | E23: ET-600 | F23: ET-55 | G23: ET-55 | H23: ET-55 | I23: 八爪機 | J23: 八爪機
B24: 次要應用設備 | H24: 封口機 | J24: 封口機
B25: 備註

Sheet 0502
A1: 長家廠4度C日報分析 | D1: 總生產量 | E1: =SUM(G5:G79) -> 45987 | F1: 營業額 | G1: =SUM(H5:H79) -> 2245600.5 | H1: 出勤人數 | I1: =M15+M26+M48+M58+M69+M79+M37 -> 90.433333 | J1: 產線配置圖 | M1: 生產實績 | P1: 人時性差異分析 | T1: 日報登錄 | Z1: 合計 次數 | AA1: 合計 時間/分 | AB1: 分析說明 | AD1: 合計 次數 | AE1: 合計 設備次數 | AF1: 產能差異分析
A2: 05月02日 星期六 | D2: 人時性 | E2: =AVERAGE(O15,O26,O37,O48,O58,O69,O79) -> 106.08858 | F2: 平均廠價 | G2: =G1/E1 -> 48.831201 | H2: 多次生產數 | I2: =COUNT(I5:I79) -> 0 | Z2: =Z15+Z26+Z37+Z48+Z58+Z69+Z79 -> 3 | AA2: =AA15+AA26+AA37+AA48+AA58+AA69+AA79 -> 47 | AD2: =AD15+AD26+AD37+AD48+AD58+AD69+AD79 -> 0 | AE2: =AE15+AE26+AE37+AE48+AE58+AE69+AE79 -> 0
A3: 線別 | B3: 品類 | D3: 品名 | F3: 廠價 | G3: 生產量 | H3: 營收 | I3: 多次 生產 | J3: 人數 | K3: 產能/時 | L3: 人時性 | M3: 人數 | N3: 產能/時 | O3: 人時性 | P3: 人數 | Q3: 人時性 | R3: 達成率 | S3: 達成率平均 | T3: 生產時間 | V3: 前置、換線時間/分 | W3: 稼動時間/分 | X3: 休息時間 | Z3: 產線異常統計 (5分鐘以上) | AD3: 短暫停線統計 (5分鐘以下) | AF3: 產能/時 | AG3: 達成率 | AH3: 達成率平均
T4: 開始 | U4: 結束 | X4: 開始 | Y4: 結束 | Z4: 次數 | AA4: 時間/分 | AD4: 總次數 | AE4: 設備因素(次數)
A5: 自動一線 (ET-600) | B5: 義大利麵 | D5: 白酒清炒鮮蛤義大利麵 | F5: =VLOOKUP(D5,廠價表!$C$1:$E$43,3,0) -> 56.87 | G5: 2788 | H5: =F5*G5 -> 158553.56 | J5: =VLOOKUP(D5,產線配置圖!$A$3:$C$40,2,0) -> 15 | K5: =VLOOKUP(D5,產線配置圖!$A$3:$C$40,3,0) -> 2250 | L5: =K5/J5 -> 150 | M5: 15 | N5: =G5/W5*60 -> 1900.9091 | O5: =N5/M5 -> 126.72727 | P5: =M5-J5 -> 0 | Q5: =O5-L5 -> -23.272727 | R5: =O5/L5 -> 0.84484848 | S5: =R15 -> 0.91396578 | T5: 0.29166667 | U5: 0.35277778 | W5: =(U5-T5)*24*60 -> 88 | Z5: 1 | AA5: 10 | AB5: 7:05-7:15包裝機異常 | AF5: =N5-K5 -> -349.09091 | AG5: =N5/K5 -> 0.84484848 | AH5: =AG15 -> 0.91396578
B6: 義大利麵 | D6: 奶油培根義大利麵 | F6: =VLOOKUP(D6,廠價表!$C$1:$E$43,3,0) -> 49.14 | G6: 3915 | H6: =F6*G6 -> 192383.1 | J6: =VLOOKUP(D6,產線配置圖!$A$3:$C$40,2,0) -> 15 | K6: =VLOOKUP(D6,產線配置圖!$A$3:$C$40,3,0) -> 2250 | L6: =K6/J6 -> 150 | M6: 15 | N6: =G6/W6*60 -> 2097.3214 | O6: =N6/M6 -> 139.82143 | P6: =M6-J6 -> 0 | Q6: =O6-L6 -> -10.178571 | R6: =O6/L6 -> 0.93214286 | T6: 0.35972222 | U6: 0.4375 | V6: =(T6-U5)*24*60 -> 10 | W6: =(U6-T6)*24*60 -> 112 | AF6: =N6-K6 -> -152.67857 | AG6: =N6/K6 -> 0.93214286
B7: 義大利麵 | D7: 香煎魚排佐檸檬奶油義大利麵 | F7: =VLOOKUP(D7,廠價表!$C$1:$E$43,3,0) -> 58.17 | G7: 1793 | H7: =F7*G7 -> 104298.81 | J7: =VLOOKUP(D7,產線配置圖!$A$3:$C$40,2,0) -> 15 | K7: =VLOOKUP(D7,產線配置圖!$A$3:$C$40,3,0) -> 2250 | L7: =K7/J7 -> 150 | M7: 15 | N7: =G7/W7*60 -> 2151.6 | O7: =N7/M7 -> 143.44 | P7: =M7-J7 -> 0 | Q7: =O7-L7 -> -6.56 | R7: =O7/L7 -> 0.95626667 | T7: 0.44444444 | U7: 0.47916667 | V7: =(T7-U6)*24*60 -> 10 | W7: =(U7-T7)*24*60 -> 50 | AF7: =N7-K7 -> -98.4 | AG7: =N7/K7 -> 0.95626667
B8: 義大利麵 | D8: 香煎魚排佐檸檬奶油義大利麵 | F8: =VLOOKUP(D8,廠價表!$C$1:$E$43,3,0) -> 58.17 | G8: 1459 | H8: =F8*G8 -> 84870.03 | J8: =VLOOKUP(D8,產線配置圖!$A$3:$C$40,2,0) -> 15 | K8: =VLOOKUP(D8,產線配置圖!$A$3:$C$40,3,0) -> 2250 | L8: =K8/J8 -> 150 | M8: 15 | N8: =G8/W8*60 -> 2035.814 | O8: =N8/M8 -> 135.72093 | P8: =M8-J8 -> 0 | Q8: =O8-L8 -> -14.27907 | R8: =O8/L8 -> 0.9048062 | T8: 0.54166667 | U8: 0.57152778 | W8: =(U8-T8)*24*60 -> 43 | X8: 0.48611111 | Y8: 0.52777778 | AF8: =N8-K8 -> -214.18605 | AG8: =N8/K8 -> 0.9048062
B9: 義大利麵 | D9: 奶油培根義大利麵 | F9: =VLOOKUP(D9,廠價表!$C$1:$E$43,3,0) -> 49.14 | G9: 1188 | H9: =F9*G9 -> 58378.32 | J9: =VLOOKUP(D9,產線配置圖!$A$3:$C$40,2,0) -> 15 | K9: =VLOOKUP(D9,產線配置圖!$A$3:$C$40,3,0) -> 2250 | L9: =K9/J9 -> 150 | M9: 15 | N9: =G9/W9*60 -> 2096.4706 | O9: =N9/M9 -> 139.76471 | P9: =M9-J9 -> 0 | Q9: =O9-L9 -> -10.235294 | R9: =O9/L9 -> 0.93176471 | T9: 0.57986111 | U9: 0.60347222 | W9: =(U9-T9)*24*60 -> 34 | AF9: =N9-K9 -> -153.52941 | AG9: =N9/K9 -> 0.93176471
W10: =(U10-T10)*24*60 -> 0 | AF10: =N10-K10 -> 0 | AG10: =N10/K10 -> #DIV/0!
W11: =(U11-T11)*24*60 -> 0 | AF11: =N11-K11 -> 0 | AG11: =N11/K11 -> #DIV/0!
W12: =(U12-T12)*24*60 -> 0
W13: =(U13-T13)*24*60 -> 0
W14: =(U14-T14)*24*60 -> 0
C15: 4度一組 | D15: 平均 | J15: =AVERAGE(J5:J14) -> 15 | K15: =AVERAGE(K5:K14) -> 2250 | L15: =AVERAGE(L5:L14) -> 150 | M15: =AVERAGE(M5:M14) -> 15 | N15: =AVERAGE(N5:N14) -> 2056.423 | O15: =AVERAGE(O5:O14) -> 137.09487 | P15: =M15-J15 -> 0 | Q15: =O15-L15 -> -12.905133 | R15: =O15/L15 -> 0.91396578 | Z15: =SUM(Z5:Z14) -> 1 | AA15: =SUM(AA5:AA14) -> 10 | AD15: =SUM(AD5:AD14) -> 0 | AE15: =SUM(AE5:AE14) -> 0 | AF15: =N15-K15 -> -193.57699 | AG15: =N15/K15 -> 0.91396578
A16: 自動二線 (ET-600) | B16: 義大利麵 | D16: 青醬蛤蜊義大利麵 | F16: =VLOOKUP(D16,廠價表!$C$1:$E$43,3,0) -> 50.67 | G16: 3178 | H16: =F16*G16 -> 161029.26 | J16: =VLOOKUP(D16,產線配置圖!$A$3:$C$40,2,0) -> 13 | K16: =VLOOKUP(D16,產線配置圖!$A$3:$C$40,3,0) -> 2250 | L16: =K16/J16 -> 173.07692 | M16: 13 | N16: =G16/W16*60 -> 2118.6667 | O16: =N16/M16 -> 162.97436 | P16: =M16-J16 -> 0 | Q16: =O16-L16 -> -10.102564 | R16: =O16/L16 -> 0.94162963 | S16: =R26 -> 0.72240253 | T16: 0.29166667 | U16: 0.35416667 | W16: =(U16-T16)*24*60 -> 90 | Z16: 1 | AA16: 5 | AB16: 8:40-8:45包裝機異常，收72盒 | AF16: =N16-K16 -> -131.33333 | AG16: =N16/K16 -> 0.94162963 | AH16: =AG26 -> 0.70743475
B17: 義大利麵 | D17: 義式辣味嫩烤雞腿排義大利麵 | F17: =VLOOKUP(D17,廠價表!$C$1:$E$43,3,0) -> 56.61 | G17: 1390 | H17: =F17*G17 -> 78687.9 | J17: =VLOOKUP(D17,產線配置圖!$A$3:$C$40,2,0) -> 15 | K17: =VLOOKUP(D17,產線配置圖!$A$3:$C$40,3,0) -> 2250 | L17: =K17/J17 -> 150 | M17: 15 | N17: =G17/W17*60 -> 1463.1579 | O17: =N17/M17 -> 97.54386 | P17: =M17-J17 -> 0 | Q17: =O17-L17 -> -52.45614 | R17: =O17/L17 -> 0.6502924 | T17: 0.36458333 | U17: 0.40416667 | V17: =(T17-U16)*24*60 -> 15 | W17: =(U17-T17)*24*60 -> 57 | Z17: 1 | AA17: 32 | AB17: 9:20-9:52包裝機異常，收381盒 | AF17: =N17-K17 -> -786.84211 | AG17: =N17/K17 -> 0.6502924
B18: 義大利麵 | D18: 義式蕃茄起司義大利麵 | F18: =VLOOKUP(D18,廠價表!$C$1:$E$43,3,0) -> 50.39 | G18: 3562 | H18: =F18*G18 -> 179489.18 | J18: =VLOOKUP(D18,產線配置圖!$A$3:$C$40,2,0) -> 12 | K18: =VLOOKUP(D18,產線配置圖!$A$3:$C$40,3,0) -> 2250 | L18: =K18/J18 -> 187.5 | M18: 12 | N18: =G18/W18*60 -> 2180.8163 | O18: =N18/M18 -> 181.73469 | P18: =M18-J18 -> 0 | Q18: =O18-L18 -> -5.7653061 | R18: =O18/L18 -> 0.9692517 | T18: 0.41111111 | U18: 0.47916667 | V18: =(T18-U17)*24*60 -> 10 | W18: =(U18-T18)*24*60 -> 98 | X18: 0.48611111 | Y18: 0.52777778 | AF18: =N18-K18 -> -69.183673 | AG18: =N18/K18 -> 0.9692517
B19: 義大利麵 | D19: 義式蕃茄起司義大利麵 | F19: =VLOOKUP(D19,廠價表!$C$1:$E$43,3,0) -> 50.39 | G19: 456 | H19: =F19*G19 -> 22977.84 | J19: =VLOOKUP(D19,產線配置圖!$A$3:$C$40,2,0) -> 12 | K19: =VLOOKUP(D19,產線配置圖!$A$3:$C$40,3,0) -> 2250 | L19: =K19/J19 -> 187.5 | M19: 12 | N19: =G19/W19*60 -> 1440 | O19: =N19/M19 -> 120 | P19: =M19-J19 -> 0 | Q19: =O19-L19 -> -67.5 | R19: =O19/L19 -> 0.64 | T19: 0.54166667 | U19: 0.55486111 | V19: =(T19-U18)*24*60 -> 90 | W19: =(U19-T19)*24*60 -> 19 | AB19: 生產數量少 | AF19: =N19-K19 -> -810 | AG19: =N19/K19 -> 0.64
B20: 義大利麵 | D20: 義式辣味嫩烤雞腿排義大利麵 | F20: =VLOOKUP(D20,廠價表!$C$1:$E$43,3,0) -> 56.61 | G20: 630 | H20: =F20*G20 -> 35664.3 | J20: =VLOOKUP(D20,產線配置圖!$A$3:$C$40,2,0) -> 15 | K20: =VLOOKUP(D20,產線配置圖!$A$3:$C$40,3,0) -> 2250 | L20: =K20/J20 -> 150 | M20: 15 | N20: =G20/W20*60 -> 756 | O20: =N20/M20 -> 50.4 | P20: =M20-J20 -> 0 | Q20: =O20-L20 -> -99.6 | R20: =O20/L20 -> 0.336 | T20: 0.55972222 | U20: 0.59444444 | V20: =(T20-U19)*24*60 -> 7 | W20: =(U20-T20)*24*60 -> 50 | AB20: 381盒補封膜
W21: =(U21-T21)*24*60 -> 0
W22: 0
W23: =(U23-T23)*24*60 -> 0
H24: =F24*G24 -> 0 | W24: =(U24-T24)*24*60 -> 0
H25: =F25*G25 -> 0 | W25: =(U25-T25)*24*60 -> 0
C26: 4度二組A | D26: 平均 | J26: =AVERAGE(J16:J25) -> 13.4 | K26: =AVERAGE(K16:K25) -> 2250 | L26: =AVERAGE(L16:L25) -> 169.61538 | M26: =AVERAGE(M16:M25) -> 13.4 | N26: =AVERAGE(N16:N25) -> 1591.7282 | O26: =AVERAGE(O16:O25) -> 122.53058 | P26: =M26-J26 -> 0 | Q26: =O26-L26 -> -47.084802 | R26: =O26/L26 -> 0.72240253 | Z26: =SUM(Z16:Z25) -> 2 | AA26: =SUM(AA16:AA25) -> 37 | AD26: =SUM(AD16:AD25) -> 0 | AE26: =SUM(AE16:AE25) -> 0 | AF26: =N26-K26 -> -658.27182 | AG26: =N26/K26 -> 0.70743475
A27: 手工三線 (ET-55) | B27: 義大利麵 | D27: 焗烤起司肉醬筆尖麵 | F27: =VLOOKUP(D27,廠價表!$C$1:$E$43,3,0) -> 50.67 | G27: 1809 | H27: =F27*G27 -> 91662.03 | J27: =VLOOKUP(D27,產線配置圖!$A$3:$C$40,2,0) -> 13 | K27: =VLOOKUP(D27,產線配置圖!$A$3:$C$40,3,0) -> 1440 | L27: =K27/J27 -> 110.76923 | M27: 13 | N27: =G27/W27*60 -> 1307.7108 | O27: =N27/M27 -> 100.59314 | P27: =M27-J27 -> 0 | Q27: =O27-L27 -> -10.176089 | R27: =O27/L27 -> 0.90813253 | S27: =R37 -> 0.89679157 | T27: 0.29166667 | U27: 0.34930556 | W27: =(U27-T27)*24*60 -> 83 | AF27: =N27-K27 -> -132.28916 | AG27: =N27/K27 -> 0.90813253 | AH27: =AG37 -> 0.89765729
B28: 義大利麵 | D28: 黑松露野菇義大利麵 | F28: =VLOOKUP(D28,廠價表!$C$1:$E$43,3,0) -> 50.289 | G28: 3227 | H28: =F28*G28 -> 162282.6 | J28: =VLOOKUP(D28,產線配置圖!$A$3:$C$40,2,0) -> 19 | K28: =VLOOKUP(D28,產線配置圖!$A$3:$C$40,3,0) -> 1565 | L28: =K28/J28 -> 82.368421 | M28: 19 | N28: =G28/W28*60 -> 1489.3846 | O28: =N28/M28 -> 78.388664 | P28: =M28-J28 -> 0 | Q28: =O28-L28 -> -3.9797571 | R28: =O28/L28 -> 0.95168346 | T28: 0.35972222 | U28: 0.45 | V28: =(T28-U27)*24*60 -> 15 | W28: =(U28-T28)*24*60 -> 130 | X28: 0.45486111 | Y28: 0.49652778 | AF28: =N28-K28 -> -75.615385 | AG28: =N28/K28 -> 0.95168346
B29: 熱乾麵 | D29: 府城鹽水意麵 | F29: =VLOOKUP(D29,廠價表!$C$1:$E$43,3,0) -> 44.3 | G29: 2350 | H29: =F29*G29 -> 104105 | J29: =VLOOKUP(D29,產線配置圖!$A$3:$C$40,2,0) -> 17 | K29: =VLOOKUP(D29,產線配置圖!$A$3:$C$40,3,0) -> 1636 | L29: =K29/J29 -> 96.235294 | M29: 17 | N29: =G29/W29*60 -> 1368.932 | O29: =N29/M29 -> 80.525414 | P29: =M29-J29 -> 0 | Q29: =O29-L29 -> -15.70988 | R29: =O29/L29 -> 0.83675552 | T29: 0.51319444 | U29: 0.58472222 | V29: =(T29-U28)*24*60 -> 91 | W29: =(U29-T29)*24*60 -> 103 | AF29: =N29-K29 -> -267.06796 | AG29: =N29/K29 -> 0.83675552
W30: =(U30-T30)*24*60 -> 0 | AF30: =N30-K30 -> 0 | AG30: =N30/K30 -> #DIV/0!
W31: =(U31-T31)*24*60 -> 0 | AF31: =N31-K31 -> 0 | AG31: =N31/K31 -> #DIV/0!
W32: =(U32-T32)*24*60 -> 0
W33: =(U33-T33)*24*60 -> 0
W34: =(U34-T34)*24*60 -> 0
W35: =(U35-T35)*24*60 -> 0
H36: =F36*G36 -> 0 | W36: =(U36-T36)*24*60 -> 0
C37: 4度二組B | D37: 平均 | J37: =AVERAGE(J27:J36) -> 16.333333 | K37: =AVERAGE(K27:K36) -> 1547 | L37: =AVERAGE(L27:L36) -> 96.457649 | M37: =AVERAGE(M27:M36) -> 16.333333 | N37: =AVERAGE(N27:N36) -> 1388.6758 | O37: =AVERAGE(O27:O36) -> 86.502407 | P37: =M37-J37 -> 0 | Q37: =N37-K37 -> -158.32417 | R37: =O37/L37 -> 0.89679157 | Z37: =SUM(Z27:Z36) -> 0 | AA37: =SUM(AA27:AA36) -> 0 | AD37: =SUM(AD27:AD36) -> 0 | AE37: =SUM(AE27:AE36) -> 0 | AF37: =N37-K37 -> -158.32417 | AG37: =N37/K37 -> 0.89765729
A38: 手工四線 (ET-55) | B38: 熱乾麵 | D38: 青花椒麻雞肉拌麵 | F38: =VLOOKUP(D38,廠價表!$C$1:$E$43,3,0) -> 49.91 | G38: 2488 | H38: =F38*G38 -> 124176.08 | J38: =VLOOKUP(D38,產線配置圖!$A$3:$C$40,2,0) -> 15 | K38: =VLOOKUP(D38,產線配置圖!$A$3:$C$40,3,0) -> 1714 | L38: =K38/J38 -> 114.26667 | M38: 15 | N38: =G38/W38*60 -> 1622.6087 | O38: =N38/M38 -> 108.17391 | P38: =M38-J38 -> 0 | Q38: =O38-L38 -> -6.0927536 | R38: =O38/L38 -> 0.94667952 | S38: =R48 -> 0.88349692 | T38: 0.33333333 | U38: 0.39722222 | W38: =(U38-T38)*24*60 -> 92 | AF38: =N38-K38 -> -91.391304 | AG38: =N38/K38 -> 0.94667952 | AH38: =AG48 -> 0.87918668
B39: 熱乾麵 | D39: 府城鹽水意麵 | F39: =VLOOKUP(D39,廠價表!$C$1:$E$43,3,0) -> 44.3 | G39: 1984 | H39: =F39*G39 -> 87891.2 | J39: =VLOOKUP(D39,產線配置圖!$A$3:$C$40,2,0) -> 17 | K39: =VLOOKUP(D39,產線配置圖!$A$3:$C$40,3,0) -> 1636 | L39: =K39/J39 -> 96.235294 | M39: 17 | N39: =G39/W39*60 -> 1322.6667 | O39: =N39/M39 -> 77.803922 | P39: =M39-J39 -> 0 | Q39: =O39-L39 -> -18.431373 | R39: =O39/L39 -> 0.80847596 | T39: 0.40625 | U39: 0.46875 | V39: =(T39-U38)*24*60 -> 13 | W39: =(U39-T39)*24*60 -> 90 | AF39: =N39-K39 -> -313.33333 | AG39: =N39/K39 -> 0.80847596
W40: =(U40-T40)*24*60 -> 0 | AF40: =N40-K40 -> 0 | AG40: =N40/K40 -> #DIV/0!
...

Sheet 0503總
B1: 長家廠組合室生產人時性分析
B3: 日期 | D3: 46145 | F3: 訂單量 | G3: ='0503'!E1 -> 64004 | I3: 營業額 | J3: ='0503'!G1 -> 3124634.1
B4: 項目 | D4: 3 | F4: ➀ | H4: ➁ | J4: ③ | L4: 異常停線 | N4: 短暫停線
B5: 人時性 | D5: 組合室 | F5: 全溫層 | H5: 義大利麵 | J5: 袋裝小吃、義麵 | L5: 合計次數 | M5: 時間 | N5: 合計次數 | O5: 設備次數
D6: 排關平均 | F6: =AVERAGE(D13:I13) -> 124.51529 | H6: =AVERAGE(D13:H13) -> 125.94334 | J6: =AVERAGE(I13) -> 117.375 | L6: =SUM(D18:J18) -> 1 | M6: =SUM(D19:J19) -> 55 | N6: =SUM(D20:J20) -> 0 | O6: =SUM(D20:J20) -> 0
D7: 實績平均 | F7: =AVERAGE(D14:I14) -> 108.37876 | H7: =AVERAGE(D14:H14) -> 110.06857 | J7: =AVERAGE(I14) -> 99.929701 | L7: =AVERAGE(K14:L14) -> #DIV/0! | M7: =AVERAGE(L14:M14) -> #DIV/0! | N7: =AVERAGE(M14:N14) -> #DIV/0! | O7: =AVERAGE(N14:O14) -> #DIV/0!
D8: 達成率平均 | F8: =F7/F6 -> 0.87040525 | H8: =H7/H6 -> 0.87395307 | J8: =J7/J6 -> 0.85137125 | L8: =AVERAGE(K15:L15) -> #DIV/0! | M8: =AVERAGE(L15:M15) -> #DIV/0! | N8: =AVERAGE(M15:N15) -> #DIV/0! | O8: =AVERAGE(N15:O15) -> #DIV/0!
J9: ※現行日本鮮食廠以達成率80%為基本(即為現行KPI)
B10: 溫層 | D10: 4度C-各編組展開
B11: 編組 | D11: 1 | E11: 2 | F11: 3 | G11: 4 | H11: 5 | I11: 6 | J11: 7
D12: 自動1線 | E12: 自動2線 | F12: 手工3線 | G12: 手工4線 | H12: 手工5線 | I12: 調理包1線 | J12: 調理包2線
B13: 人時性 | C13: 排關 | D13: =VALUE('0503'!L15) -> 150 | E13: =VALUE('0503'!L26) -> 174.23077 | F13: =VALUE('0503'!L37) -> 100.21667 | G13: =VALUE('0503'!L48) -> 102.24575 | H13: =VALUE('0503'!L58) -> 103.02353 | I13: =VALUE('0503'!L69) -> 117.375 | J13: ='0503'!L79 -> 0
C14: 實績 | D14: =VALUE('0503'!O15) -> 133.49132 | E14: =VALUE('0503'!O26) -> 164.69594 | F14: =VALUE('0503'!O37) -> 78.987765 | G14: =VALUE('0503'!O48) -> 77.269613 | H14: =VALUE('0503'!O58) -> 95.898219 | I14: =VALUE('0503'!O69) -> 99.929701 | J14: ='0503'!O79 -> 0
C15: 達成率 | D15: =D14/D13 -> 0.88994215 | E15: =E14/E13 -> 0.9452747 | F15: =F14/F13 -> 0.78816992 | G15: =G14/G13 -> 0.75572444 | H15: =H14/H13 -> 0.93083803 | I15: =I14/I13 -> 0.85137125 | J15: ='0503'!S70 -> 0
B16: 作業 時間 | C16: 開始 | D16: ='0503'!T5 -> 0.29166667 | E16: ='0503'!T16 -> 0.29166667 | F16: ='0503'!T27 -> 0.29166667 | G16: ='0503'!T38 -> 0.33333333 | H16: ='0503'!T49 -> 0.29166667 | I16: ='0503'!T59 -> 0.29166667 | J16: ='0503'!T70 -> 0
C17: 結束 | D17: 0.68055556 | E17: 0.62986111 | F17: 0.66458333 | G17: 0.69791667 | H17: 0.67013889 | I17: 0.52083333 | J17: 0
B18: 產線異常 (5分鐘以上) | C18: 次數 | D18: ='0503'!Z15 -> 0 | E18: ='0503'!Z26 -> 0 | F18: ='0503'!Z37 -> 0 | G18: ='0503'!Z48 -> 1 | H18: ='0503'!Z58 -> 0 | I18: ='0503'!Z69 -> 0 | J18: ='0503'!AA79 -> 0
C19: 時間/分 | D19: ='0503'!AA15 -> 0 | E19: ='0503'!AA26 -> 0 | F19: ='0503'!AA37 -> 0 | G19: ='0503'!AA48 -> 55 | H19: ='0503'!AA58 -> 0 | I19: ='0503'!AA69 -> 0 | J19: ='0503'!AB79 -> 0
B20: 短暫停線 (5分鐘以下) | C20: 次數 | D20: ='0503'!AD15 -> 0 | E20: ='0503'!AD26 -> 0 | F20: ='0503'!AD37 -> 0 | G20: ='0503'!AD48 -> 0 | H20: ='0503'!AD58 -> 0 | I20: ='0503'!AD69 -> 0 | J20: ='0503'!AD79 -> 0
C21: 設備次數 | D21: ='0503'!AE15 -> 0 | E21: ='0503'!AE26 -> 0 | F21: ='0503'!AE37 -> 0 | G21: ='0503'!AE48 -> 0 | H21: ='0503'!AE58 -> 0 | I21: ='0503'!AE69 -> 0 | J21: ='0503'!AE79 -> 0
B22: 配置人數 | D22: =VALUE('0503'!M15) -> 15 | E22: =VALUE('0503'!M26) -> 12.8 | F22: =VALUE('0503'!M37) -> 15.8 | G22: =VALUE('0503'!M48) -> 16.333333 | H22: =VALUE('0503'!M58) -> 16.6 | I22: =VALUE('0503'!M69) -> 12.5 | J22: ='0503'!M79 -> 0
B23: 主要應用設備 | D23: ET-600 | E23: ET-600 | F23: ET-55 | G23: ET-55 | H23: ET-55 | I23: 八爪機 | J23: 八爪機
B24: 次要應用設備 | H24: 封口機 | J24: 封口機
B25: 備註

Sheet 0503
A1: 長家廠4度C日報分析 | D1: 總生產量 | E1: =SUM(G5:G79) -> 64004 | F1: 營業額 | G1: =SUM(H5:H79) -> 3124634.1 | H1: 出勤人數 | I1: =M15+M26+M48+M58+M69+M79+M37 -> 89.033333 | J1: 產線配置圖 | M1: 生產實績 | P1: 人時性差異分析 | T1: 日報登錄 | Z1: 合計 次數 | AA1: 合計 時間/分 | AB1: 分析說明 | AD1: 合計 次數 | AE1: 合計 設備次數 | AF1: 產能差異分析
A2: 05月03日 星期日 | D2: 人時性 | E2: =AVERAGE(O15,O26,O37,O48,O58,O69,O79) -> 108.37876 | F2: 平均廠價 | G2: =G1/E1 -> 48.819357 | H2: 多次生產數 | I2: =COUNT(I5:I79) -> 0 | Z2: =Z15+Z26+Z37+Z48+Z58+Z69+Z79 -> 1 | AA2: =AA15+AA26+AA37+AA48+AA58+AA69+AA79 -> 55 | AD2: =AD15+AD26+AD37+AD48+AD58+AD69+AD79 -> 0 | AE2: =AE15+AE26+AE37+AE48+AE58+AE69+AE79 -> 0
A3: 線別 | B3: 品類 | D3: 品名 | F3: 廠價 | G3: 生產量 | H3: 營收 | I3: 多次 生產 | J3: 人數 | K3: 產能/時 | L3: 人時性 | M3: 人數 | N3: 產能/時 | O3: 人時性 | P3: 人數 | Q3: 人時性 | R3: 達成率 | S3: 達成率平均 | T3: 生產時間 | V3: 前置、換線時間/分 | W3: 稼動時間/分 | X3: 休息時間 | Z3: 產線異常統計 (5分鐘以上) | AD3: 短暫停線統計 (5分鐘以下) | AF3: 產能/時 | AG3: 達成率 | AH3: 達成率平均
T4: 開始 | U4: 結束 | X4: 開始 | Y4: 結束 | Z4: 次數 | AA4: 時間/分 | AD4: 總次數 | AE4: 設備因素(次數)
A5: 自動一線 (ET-600) | B5: 義大利麵 | D5: 白酒清炒鮮蛤義大利麵 | F5: =VLOOKUP(D5,廠價表!$C$1:$E$43,3,0) -> 56.87 | G5: 2843 | H5: =F5*G5 -> 161681.41 | J5: =VLOOKUP(D5,產線配置圖!$A$3:$C$40,2,0) -> 15 | K5: =VLOOKUP(D5,產線配置圖!$A$3:$C$40,3,0) -> 2250 | L5: =K5/J5 -> 150 | M5: 15 | N5: =G5/W5*60 -> 2055.1807 | O5: =N5/M5 -> 137.01205 | P5: =M5-J5 -> 0 | Q5: =O5-L5 -> -12.987952 | R5: =O5/L5 -> 0.91341365 | S5: =R15 -> 0.88994215 | T5: 0.29166667 | U5: 0.34930556 | W5: =(U5-T5)*24*60 -> 83 | AF5: =N5-K5 -> -194.81928 | AG5: =N5/K5 -> 0.91341365 | AH5: =AG15 -> 0.88994215
B6: 義大利麵 | D6: 奶油培根義大利麵 | F6: =VLOOKUP(D6,廠價表!$C$1:$E$43,3,0) -> 49.14 | G6: 4473 | H6: =F6*G6 -> 219803.22 | J6: =VLOOKUP(D6,產線配置圖!$A$3:$C$40,2,0) -> 15 | K6: =VLOOKUP(D6,產線配置圖!$A$3:$C$40,3,0) -> 2250 | L6: =K6/J6 -> 150 | M6: 15 | N6: =G6/W6*60 -> 2096.7187 | O6: =N6/M6 -> 139.78125 | P6: =M6-J6 -> 0 | Q6: =O6-L6 -> -10.21875 | R6: =O6/L6 -> 0.931875 | T6: 0.35625 | U6: 0.44513889 | V6: =(T6-U5)*24*60 -> 10 | W6: =(U6-T6)*24*60 -> 128 | AF6: =N6-K6 -> -153.28125 | AG6: =N6/K6 -> 0.931875
B7: 義大利麵 | D7: 香煎魚排佐檸檬奶油義大利麵 | F7: =VLOOKUP(D7,廠價表!$C$1:$E$43,3,0) -> 58.17 | G7: 1350 | H7: =F7*G7 -> 78529.5 | J7: =VLOOKUP(D7,產線配置圖!$A$3:$C$40,2,0) -> 15 | K7: =VLOOKUP(D7,產線配置圖!$A$3:$C$40,3,0) -> 2250 | L7: =K7/J7 -> 150 | M7: 15 | N7: =G7/W7*60 -> 2076.9231 | O7: =N7/M7 -> 138.46154 | P7: =M7-J7 -> 0 | Q7: =O7-L7 -> -11.538462 | R7: =O7/L7 -> 0.92307692 | T7: 0.45138889 | U7: 0.47847222 | V7: =(T7-U6)*24*60 -> 9 | W7: =(U7-T7)*24*60 -> 39 | X7: 0.49305556 | Y7: 0.53472222 | AF7: =N7-K7 -> -173.07692 | AG7: =N7/K7 -> 0.92307692
B8: 義大利麵 | D8: 香煎魚排佐檸檬奶油義大利麵 | F8: =VLOOKUP(D8,廠價表!$C$1:$E$43,3,0) -> 58.17 | G8: 2554 | H8: =F8*G8 -> 148566.18 | J8: =VLOOKUP(D8,產線配置圖!$A$3:$C$40,2,0) -> 15 | K8: =VLOOKUP(D8,產線配置圖!$A$3:$C$40,3,0) -> 2250 | L8: =K8/J8 -> 150 | M8: 15 | N8: =G8/W8*60 -> 1990.1299 | O8: =N8/M8 -> 132.67532 | P8: =M8-J8 -> 0 | Q8: =O8-L8 -> -17.324675 | R8: =O8/L8 -> 0.88450216 | T8: 0.54166667 | U8: 0.59513889 | V8: =(T8-U7)*24*60 -> 91 | W8: =(U8-T8)*24*60 -> 77 | AF8: =N8-K8 -> -259.87013 | AG8: =N8/K8 -> 0.88450216
B9: 義大利麵 | D9: 奶油培根義大利麵 | F9: =VLOOKUP(D9,廠價表!$C$1:$E$43,3,0) -> 49.14 | G9: 2692 | H9: =F9*G9 -> 132284.88 | J9: =VLOOKUP(D9,產線配置圖!$A$3:$C$40,2,0) -> 15 | K9: =VLOOKUP(D9,產線配置圖!$A$3:$C$40,3,0) -> 2250 | L9: =K9/J9 -> 150 | M9: 15 | N9: =G9/W9*60 -> 2153.6 | O9: =N9/M9 -> 143.57333 | P9: =M9-J9 -> 0 | Q9: =O9-L9 -> -6.4266667 | R9: =O9/L9 -> 0.95715556 | T9: 0.60069444 | U9: 0.65277778 | V9: =(T9-U8)*24*60 -> 8 | W9: =(U9-T9)*24*60 -> 75 | AF9: =N9-K9 -> -96.4 | AG9: =N9/K9 -> 0.95715556
B10: 義大利麵 | D10: 香煎魚排佐檸檬奶油義大利麵 | F10: =VLOOKUP(D10,廠價表!$C$1:$E$43,3,0) -> 58.17 | G10: 985 | H10: =F10*G10 -> 57297.45 | J10: =VLOOKUP(D10,產線配置圖!$A$3:$C$40,2,0) -> 15 | K10: =VLOOKUP(D10,產線配置圖!$A$3:$C$40,3,0) -> 2250 | L10: =K10/J10 -> 150 | M10: 15 | N10: =G10/W10*60 -> 1641.6667 | O10: =N10/M10 -> 109.44444 | P10: =M10-J10 -> 0 | Q10: =O10-L10 -> -40.555556 | R10: =O10/L10 -> 0.72962963 | T10: 0.65555556 | U10: 0.68055556 | V10: =(T10-U9)*24*60 -> 4 | W10: =(U10-T10)*24*60 -> 36 | AB10: 生產數量少 | AF10: =N10-K10 -> -608.33333 | AG10: =N10/K10 -> 0.72962963
W11: =(U11-T11)*24*60 -> 0 | AF11: =N11-K11 -> 0 | AG11: =N11/K11 -> #DIV/0!
W12: =(U12-T12)*24*60 -> 0
W13: =(U13-T13)*24*60 -> 0
W14: =(U14-T14)*24*60 -> 0
C15: 4度一組 | D15: 平均 | J15: =AVERAGE(J5:J14) -> 15 | K15: =AVERAGE(K5:K14) -> 2250 | L15: =AVERAGE(L5:L14) -> 150 | M15: =AVERAGE(M5:M14) -> 15 | N15: =AVERAGE(N5:N14) -> 2002.3698 | O15: =AVERAGE(O5:O14) -> 133.49132 | P15: =M15-J15 -> 0 | Q15: =O15-L15 -> -16.508677 | R15: =O15/L15 -> 0.88994215 | Z15: =SUM(Z5:Z14) -> 0 | AA15: =SUM(AA5:AA14) -> 0 | AD15: =SUM(AD5:AD14) -> 0 | AE15: =SUM(AE5:AE14) -> 0 | AF15: =N15-K15 -> -247.63015 | AG15: =N15/K15 -> 0.88994215
A16: 自動二線 (ET-600) | B16: 義大利麵 | D16: 青醬蛤蜊義大利麵 | F16: =VLOOKUP(D16,廠價表!$C$1:$E$43,3,0) -> 50.67 | G16: 2835 | H16: =F16*G16 -> 143649.45 | J16: =VLOOKUP(D16,產線配置圖!$A$3:$C$40,2,0) -> 13 | K16: =VLOOKUP(D16,產線配置圖!$A$3:$C$40,3,0) -> 2250 | L16: =K16/J16 -> 173.07692 | M16: 13 | N16: =G16/W16*60 -> 2126.25 | O16: =N16/M16 -> 163.55769 | P16: =M16-J16 -> 0 | Q16: =O16-L16 -> -9.5192308 | R16: =O16/L16 -> 0.945 | S16: =R26 -> 0.9452747 | T16: 0.29166667 | U16: 0.34722222 | W16: =(U16-T16)*24*60 -> 80 | AF16: =N16-K16 -> -123.75 | AG16: =N16/K16 -> 0.945 | AH16: =AG26 -> 0.9307968
B17: 義大利麵 | D17: 義式辣味嫩烤雞腿排義大利麵 | F17: =VLOOKUP(D17,廠價表!$C$1:$E$43,3,0) -> 56.61 | G17: 2841 | H17: =F17*G17 -> 160829.01 | J17: =VLOOKUP(D17,產線配置圖!$A$3:$C$40,2,0) -> 15 | K17: =VLOOKUP(D17,產線配置圖!$A$3:$C$40,3,0) -> 2250 | L17: =K17/J17 -> 150 | M17: 15 | N17: =G17/W17*60 -> 2130.75 | O17: =N17/M17 -> 142.05 | P17: =M17-J17 -> 0 | Q17: =O17-L17 -> -7.95 | R17: =O17/L17 -> 0.947 | T17: 0.35416667 | U17: 0.40972222 | V17: =(T17-U16)*24*60 -> 10 | W17: =(U17-T17)*24*60 -> 80 | AF17: =N17-K17 -> -119.25 | AG17: =N17/K17 -> 0.947
B18: 義大利麵 | D18: 義式蕃茄起司義大利麵 | F18: =VLOOKUP(D18,廠價表!$C$1:$E$43,3,0) -> 50.39 | G18: 3211 | H18: =F18*G18 -> 161802.29 | J18: =VLOOKUP(D18,產線配置圖!$A$3:$C$40,2,0) -> 12 | K18: =VLOOKUP(D18,產線配置圖!$A$3:$C$40,3,0) -> 2250 | L18: =K18/J18 -> 187.5 | M18: 12 | N18: =G18/W18*60 -> 2140.6667 | O18: =N18/M18 -> 178.38889 | P18: =M18-J18 -> 0 | Q18: =O18-L18 -> -9.1111111 | R18: =O18/L18 -> 0.95140741 | T18: 0.41666667 | U18: 0.47916667 | V18: =(T18-U17)*24*60 -> 10 | W18: =(U18-T18)*24*60 -> 90 | X18: 0.49305556 | Y18: 0.53472222 | AF18: =N18-K18 -> -109.33333 | AG18: =N18/K18 -> 0.95140741
B19: 義大利麵 | D19: 義式蕃茄起司義大利麵 | F19: =VLOOKUP(D19,廠價表!$C$1:$E$43,3,0) -> 50.39 | G19: 2636 | H19: =F19*G19 -> 132828.04 | J19: =VLOOKUP(D19,產線配置圖!$A$3:$C$40,2,0) -> 12 | K19: =VLOOKUP(D19,產線配置圖!$A$3:$C$40,3,0) -> 2250 | L19: =K19/J19 -> 187.5 | M19: 12 | N19: =G19/W19*60 -> 2137.2973 | O19: =N19/M19 -> 178.10811 | P19: =M19-J19 -> 0 | Q19: =O19-L19 -> -9.3918919 | R19: =O19/L19 -> 0.94990991 | T19: 0.54375 | U19: 0.59513889 | V19: =(T19-U18)*24*60 -> 93 | W19: =(U19-T19)*24*60 -> 74 | AF19: =N19-K19 -> -112.7027 | AG19: =N19/K19 -> 0.94990991
B20: 義大利麵 | D20: 青醬蛤蜊義大利麵 | F20: =VLOOKUP(D20,廠價表!$C$1:$E$43,3,0) -> 50.67 | G20: 1291 | H20: =F20*G20 -> 65414.97 | J20: =VLOOKUP(D20,產線配置圖!$A$3:$C$40,2,0) -> 13 | K20: =VLOOKUP(D20,產線配置圖!$A$3:$C$40,3,0) -> 2250 | L20: =K20/J20 -> 173.07692 | M20: 12 | N20: =G20/W20*60 -> 1936.5 | O20: =N20/M20 -> 161.375 | P20: =M20-J20 -> -1 | Q20: =O20-L20 -> -11.701923 | R20: =O20/L20 -> 0.93238889 | T20: 0.60208333 | U20: 0.62986111 | V20: =(T20-U19)*24*60 -> 10 | W20: =(U20-T20)*24*60 -> 40
W21: =(U21-T21)*24*60 -> 0
W22: 0
W23: =(U23-T23)*24*60 -> 0
H24: =F24*G24 -> 0 | W24: =(U24-T24)*24*60 -> 0
H25: =F25*G25 -> 0 | W25: =(U25-T25)*24*60 -> 0
C26: 4度二組A | D26: 平均 | J26: =AVERAGE(J16:J25) -> 13 | K26: =AVERAGE(K16:K25) -> 2250 | L26: =AVERAGE(L16:L25) -> 174.23077 | M26: =AVERAGE(M16:M25) -> 12.8 | N26: =AVERAGE(N16:N25) -> 2094.2928 | O26: =AVERAGE(O16:O25) -> 164.69594 | P26: =M26-J26 -> -0.2 | Q26: =O26-L26 -> -9.5348314 | R26: =O26/L26 -> 0.9452747 | Z26: =SUM(Z16:Z25) -> 0 | AA26: =SUM(AA16:AA25) -> 0 | AD26: =SUM(AD16:AD25) -> 0 | AE26: =SUM(AE16:AE25) -> 0 | AF26: =N26-K26 -> -155.70721 | AG26: =N26/K26 -> 0.9307968
A27: 手工三線 (ET-55) | B27: 義大利麵 | D27: 焗烤起司肉醬筆尖麵 | F27: =VLOOKUP(D27,廠價表!$C$1:$E$43,3,0) -> 50.67 | G27: 1206 | H27: =F27*G27 -> 61108.02 | J27: =VLOOKUP(D27,產線配置圖!$A$3:$C$40,2,0) -> 13 | K27: =VLOOKUP(D27,產線配置圖!$A$3:$C$40,3,0) -> 1440 | L27: =K27/J27 -> 110.76923 | M27: 13 | N27: =G27/W27*60 -> 1247.5862 | O27: =N27/M27 -> 95.96817 | P27: =M27-J27 -> 0 | Q27: =O27-L27 -> -14.801061 | R27: =O27/L27 -> 0.86637931 | S27: =R37 -> 0.78816992 | T27: 0.29166667 | U27: 0.33194444 | W27: =(U27-T27)*24*60 -> 58 | AF27: =N27-K27 -> -192.41379 | AG27: =N27/K27 -> 0.86637931 | AH27: =AG37 -> 0.79051398
B28: 義大利麵 | D28: 黑松露野菇義大利麵 | F28: =VLOOKUP(D28,廠價表!$C$1:$E$43,3,0) -> 50.289 | G28: 4928 | H28: =F28*G28 -> 247824.19 | J28: =VLOOKUP(D28,產線配置圖!$A$3:$C$40,2,0) -> 19 | K28: =VLOOKUP(D28,產線配置圖!$A$3:$C$40,3,0) -> 1565 | L28: =K28/J28 -> 82.368421 | M28: 19 | N28: =G28/W28*60 -> 1388.169 | O28: =N28/M28 -> 73.061527 | P28: =M28-J28 -> 0 | Q28: =O28-L28 -> -9.306894 | R28: =O28/L28 -> 0.88700895 | T28: 0.33819444 | U28: 0.48611111 | V28: =(T28-U27)*24*60 -> 9 | W28: =(U28-T28)*24*60 -> 213 | X28: 0.48958333 | Y28: 0.54166667 | AF28: =N28-K28 -> -176.83099 | AG28: =N28/K28 -> 0.88700895
B29: 義大利麵 | D29: 蒜香奶油蝦蝦義大利麵 | F29: =VLOOKUP(D29,廠價表!$C$1:$E$43,3,0) -> 57.21 | G29: 1541 | H29: =F29*G29 -> 88160.61 | J29: =VLOOKUP(D29,產線配置圖!$A$3:$C$40,2,0) -> 17 | K29: =VLOOKUP(D29,產線配置圖!$A$3:$C$40,3,0) -> 1716 | L29: =K29/J29 -> 100.94118 | M29: 17 | N29: =G29/W29*60 -> 1400.9091 | O29: =N29/M29 -> 82.406417 | P29: =M29-J29 -> 0 | Q29: =O29-L29 -> -18.534759 | R29: =O29/L29 -> 0.81638059 | T29: 0.54791667 | U29: 0.59375 | V29: =(T29-U28)*24*60 -> 89 | W29: =(U29-T29)*24*60 -> 66 | AF29: =N29-K29 -> -315.09091 | AG29: =N29/K29 -> 0.81638059
B30: 熱乾麵 | D30: 府城鹽水意麵 | F30: =VLOOKUP(D30,廠價表!$C$1:$E$43,3,0) -> 44.3 | G30: 500 | H30: =F30*G30 -> 22150 | J30: =VLOOKUP(D30,產線配置圖!$A$3:$C$40,2,0) -> 17 | K30: =VLOOKUP(D30,產線配置圖!$A$3:$C$40,3,0) -> 1636 | L30: =K30/J30 -> 96.235294 | M30: 17 | N30: =G30/W30*60 -> 1111.1111 | O30: =N30/M30 -> 65.359477 | P30: =M30-J30 -> 0 | Q30: =O30-L30 -> -30.875817 | R30: =O30/L30 -> 0.67916327 | T30: 0.59930556 | U30: 0.61805556 | V30: =(T30-U29)*24*60 -> 8 | W30: =(U30-T30)*24*60 -> 27 | AB30: 生產數量少/協助四線補足DC出貨量(因早上煮麵機稼動量不足) | AF30: =N30-K30 -> -524.88889 | AG30: =N30/K30 -> 0.67916327
B31: 義大利麵 | D31: 焗烤起司肉醬筆尖麵 | F31: =VLOOKUP(D31,廠價表!$C$1:$E$43,3,0) -> 50.67 | G31: 982 | H31: =F31*G31 -> 49757.94 | J31: =VLOOKUP(D31,產線配置圖!$A$3:$C$40,2,0) -> 13 | K31: =VLOOKUP(D31,產線配置圖!$A$3:$C$40,3,0) -> 1440 | L31: =K31/J31 -> 110.76923 | M31: 13 | N31: =G31/W31*60 -> 1015.8621 | O31: =N31/M31 -> 78.143236 | P31: =M31-J31 -> 0 | Q31: =O31-L31 -> -32.625995 | R31: =O31/L31 -> 0.70545977 | T31: 0.62430556 | U31: 0.66458333 | V31: =(T31-U30)*24*60 -> 9 | W31: =(U31-T31)*24*60 -> 58 | AB31: 生產數量少 | AF31: =N31-K31 -> -424.13793 | AG31: =N31/K31 -> 0.70545977
W32: =(U32-T32)*24*60 -> 0
W33: =(U33-T33)*24*60 -> 0
W34: =(U34-T34)*24*60 -> 0
W35: =(U35-T35)*24*60 -> 0
H36: =F36*G36 -> 0 | W36: =(U36-T36)*24*60 -> 0
