Workbook

Sheet 廠價表
A1: check | B1: 溫層 | C1: 品名 | D1: 類別 | E1: 廠價
B2: 4度C | C2: 奶油鮮蝦明太子細扁麵 | D2: 義大利麵 | E2: 57.21
B3: 4度C | C3: 白酒清炒鮮蛤義大利麵 | D3: 義大利麵 | E3: 56.87
B4: 4度C | C4: 義式蕃茄起司義大利麵 | D4: 義大利麵 | E4: 50.39
B5: 4度C | C5: 焗烤起司雙饗筆尖麵 | D5: 義大利麵 | E5: 49.97
B6: 4度C | C6: 奶油培根義大利麵 | D6: 義大利麵 | E6: 49.14
B7: 4度C | C7: 焦糖拿鐵烤雞細扁麵 | D7: 義大利麵 | E7: 57.21
B8: 4度C | D8: 義大利麵 | E8: 56.61
B9: 4度C | C9: 焗烤起司肉醬筆尖麵 | D9: 義大利麵 | E9: 50.67
B10: 4度C | D10: 義大利麵
B11: 4度C | C11: 蒜香奶油蝦蝦義大利麵 | D11: 義大利麵 | E11: 57.21
B12: 4度C | C12: 義式辣味嫩烤雞腿排義大利麵 | D12: 義大利麵 | E12: 56.61
B13: 4度C | C13: 香煎魚排佐檸檬奶油義大利麵 | D13: 義大利麵 | E13: 58.17
B14: 4度C | C14: 青醬蛤蜊義大利麵 | D14: 義大利麵 | E14: 50.67
B15: 4度C | C15: 焗烤明太子筆尖麵 | D15: 義大利麵 | E15: 57.3
B16: 4度C | C16: 整條德式香腸義大利麵 | D16: 義大利麵 | E16: 57.21
B17: 4度C | C17: 義式蛋蛋青醬鮪魚冷義大利麵 | D17: 義大利麵 | E17: 45.66
B18: 4度C | C18: 黑松露野菇義大利麵 | D18: 義大利麵 | E18: 50.289
B19: 4度C | C19: 青花椒麻雞肉拌麵 | D19: 熱乾麵 | E19: 49.91
B20: 4度C | C20: 府城鹽水意麵 | D20: 熱乾麵 | E20: 44.3
B21: 4度C | C21: 沙茶豬肉炒麵 | D21: 熱乾麵 | E21: 49.52
B22: 4度C | C22: 蕃茄莎莎海鮮冷義大利麵 | D22: 義大利麵 | E22: 46.34
... B26: 4度C | C26: 麻辣雞心 | D26: 小吃、微波 | E26: 28.26
B28: 4度C | C28: 鮮奶油白醬醬杯 | D28: 冷麵醬杯
B46: 冷凍 | C46: 青醬蛤蜊義大利麵 | D46: 冷凍調理麵 | E46: 29.38
B47: 冷凍 | C47: 經典肉醬義大利麵 | D47: 冷凍調理麵 | E47: 29.38
B48: 冷凍 | C48: 奶油蘑菇培根義大利麵 | D48: 冷凍調理麵 | E48: 29.38
B49: 冷凍 | C49: 清炒蛤蜊義大利麵 | D49: 冷凍調理麵 | E49: 29.38
B50: 冷凍 | C50: 青醬乳酪筆尖麵 | D50: 冷凍調理麵 | E50: 29.38
B51: 冷凍 | C51: 辣蕃茄義大利麵 | D51: 冷凍調理麵 | E51: 29.38
B52: 冷凍 | D52: 冷凍調理麵
B53: 冷凍 | C53: 韓式起司義大利麵 | D53: 冷凍調理麵 | E53: 29.38
B54: 冷凍 | D54: 冷凍調理麵
B55: 冷凍 | C55: 和風明太子細扁麵 | D55: 冷凍調理麵 | E55: 29.38

Sheet 產線配置圖
A1: 品項 | B1: 人數 | C1: 產能 | E1: 人時 | G1: 備註
A2: 義大利麵
A3: 白酒清炒鮮蛤義大利麵 | B3: 15 | C3: 2250 | D3: ET-600 | E3: =C3/B3 -> 150
A4: 白酒清炒鮮蛤義大利麵-手 | B4: 17 | C4: 1716 | D4: ET-55 | E4: =C4/B4 -> 100.94118
A5: 青醬蛤蜊義大利麵 | B5: 14 | C5: 2250 | E5: =C5/B5 -> 160.71429
A6: 青醬蛤蜊義大利麵-手 | B6: 16 | C6: 1714 | E6: =C6/B6 -> 107.125
A7: 義式蕃茄起司義大利麵 | B7: 13 | C7: 2250 | E7: =C7/B7 -> 173.07692
A8: 奶油培根義大利麵 | B8: 15 | C8: 2250 | E8: =C8/B8 -> 150
A9: 蒜香奶油蝦蝦義大利麵 | B9: 17 | C9: 2250 | E9: =C9/B9 -> 132.35294
A10: 蒜香奶油蝦蝦義大利麵-手 | B10: 17 | C10: 1716 | E10: =C10/B10 -> 100.94118
A11: 義式辣味嫩烤雞腿排義大利麵 | B11: 15 | C11: 2250 | E11: =C11/B11 -> 150
A12: 香煎魚排佐檸檬奶油義大利麵 | B12: 15 | C12: 2250 | E12: =C12/B12 -> 150
A13: 黑松露野菇義大利麵 | B13: 18 | C13: 1565 | E13: =C13/B13 -> 86.944444 | J13: 黑松露野菇義大利麵 | K13: 17 | L13: 1565 | N13: =L13/K13 -> 92.058824
A14: 青花椒麻雞肉拌麵 | B14: 15 | C14: 1714 | E14: =C14/B14 -> 114.26667 | J14: 青花椒麻雞肉拌麵 | K14: 14 | L14: 1714 | N14: =L14/K14 -> 122.42857
A15: 焗烤起司雙饗筆尖麵 | B15: 16 | C15: 1800 | E15: =C15/B15 -> 112.5 | G15: 目前使用手工 | J15: 焗烤起司雙饗筆尖麵 | K15: 15 | L15: 1800 | N15: =L15/K15 -> 120
A16: 沙茶豬肉炒麵 | B16: 17 | C16: 1800 | E16: =C16/B16 -> 105.88235 | J16: 沙茶豬肉炒麵 | K16: 16 | L16: 1500 | N16: =L16/K16 -> 93.75
A17: 府城鹽水意麵 | B17: 17 | C17: 1636 | E17: =C17/B17 -> 96.235294 | J17: 府城鹽水意麵 | K17: 16 | L17: 1636 | N17: =L17/K17 -> 102.25
A18: 焗烤起司肉醬筆尖麵-降 | B18: 10 | C18: 1125 | E18: =C18/B18 -> 112.5 | J18: 焗烤起司肉醬筆尖麵 | K18: 12 | L18: 1440 | N18: =L18/K18 -> 120
A19: 焗烤起司肉醬筆尖麵 | B19: 13 | C19: 1440 | E19: =C19/B19 -> 110.76923 | G19: 目前使用雙排 | J19: 整條德式香腸義大利麵 | K19: 16 | L19: 1565 | N19: =L19/K19 -> 97.8125
A20: 整條德式香腸義大利麵 | B20: 18 | C20: 1565 | E20: =C20/B20 -> 86.944444
A21: 奶油鮮蝦明太子細扁麵 | B21: 18 | C21: 1636 | E21: =C21/B21 -> 90.888889
A22: 焦糖拿鐵烤雞細扁麵 | B22: 18 | C22: 1565 | E22: =C22/B22 -> 86.944444
A23: 義式蛋蛋青醬鮪魚冷義大利麵 | B23: 17 | C23: 1500 | E23: =C23/B23 -> 88.235294
A24: 鮮奶油白醬醬杯 | B24: 4 | C24: 1500 | E24: =C24/B24 -> 375
A25: 蕃茄莎莎海鮮冷義大利麵 | B25: 16 | C25: 1800 | E25: =C25/B25 -> 112.5
A26: 調理包
A27: 小滷青蔬 | B27: 15 | C27: 1565 | E27: =C27/B27 -> 104.33333 | G27: 夏季+1人補料
A28: 起司馬鈴薯 | B28: 12 | C28: 1565 | E28: =C28/B28 -> 130.41667
A29: 麻辣雞心 | B29: 11 | C29: 1636 | E29: =C29/B29 -> 148.72727
A30: 韓式炒冬粉 | B30: 11 | C30: 1565 | E30: =C30/B30 -> 142.27273
E34: 更新日期05/28

Sheet 範本總
B1: 長家廠組合室生產人時性分析
B3: 日期 | D3: 46015 | F3: 訂單量 | G3: =範本!E1 -> 43309 | I3: 營業額 | J3: =範本!G1 -> #N/A
B4: 項目 | D4: 3 | F4: ➀ | H4: ➁ | J4: ③ | L4: 異常停線 | N4: 短暫停線
B5: 人時性 | D5: 組合室 | F5: 全溫層 | H5: 義大利麵 | J5: 袋裝小吃、義麵 | L5: 合計次數 | M5: 時間 | N5: 合計次數 | O5: 設備次數
D6: 排關平均 | F6: =AVERAGE(D13:J13) -> #N/A | H6: =AVERAGE(D13:H13) -> #N/A | J6: =AVERAGE(I13:J13) -> #N/A | L6: =範本!Z2 -> 0 | M6: =範本!AA2 -> 0 | N6: =範本!AD2 -> 0 | O6: =範本!AE2 -> 0
D7: 實績平均 | F7: =AVERAGE(D14:J14) -> 116.11475 | H7: =AVERAGE(D14:H14) -> 117.36075 | J7: =AVERAGE(I14:J14) -> 112.99975
D8: 達成率平均 | F8: =AVERAGE(D15:J15) -> #N/A | H8: =AVERAGE(D15:H15) -> #N/A | J8: =AVERAGE(I15:J15) -> #N/A
J9: ※現行日本鮮食廠以達成率80%為基本(即為現行KPI)
B10: 溫層 | D10: 4度C-各編組展開
B11: 編組 | D11: 1 | E11: 2 | F11: 3 | G11: 4 | H11: 5 | I11: 6 | J11: 7
D12: 自動1線 | E12: 自動2線 | F12: 手工3線 | G12: 手工4線 | H12: 手工5線 | I12: 調理包1線 | J12: 調理包2線
B13: 人時性 | C13: 排關 | D13: =VALUE(範本!L15) -> #N/A | E13: =VALUE(範本!L26) -> #N/A | F13: =VALUE(範本!L37) -> #N/A | G13: =VALUE(範本!L48) -> #N/A | H13: =VALUE(範本!L58) -> #N/A | I13: =VALUE(範本!L69) -> #N/A | J13: =範本!L79 -> #N/A
C14: 實績 | D14: =VALUE(範本!O15) -> 113.91637 | E14: =VALUE(範本!O26) -> 132.12003 | F14: =VALUE(範本!O37) -> 126.23842 | G14: =VALUE(範本!O48) -> 112.0543 | H14: =VALUE(範本!O58) -> 102.47462 | I14: =VALUE(範本!O69) -> 155.46443 | J14: =範本!O79 -> 70.535065
C15: 達成率 | D15: =D14/D13 -> #N/A | E15: =E14/E13 -> #N/A | F15: =F14/F13 -> #N/A | G15: =G14/G13 -> #N/A | H15: =H14/H13 -> #N/A | I15: =I14/I13 -> #N/A | J15: =範本!S70 -> #N/A
B16: 作業 時間 | C16: 開始 | D16: =範本!T5 -> 0.29097222 | E16: =範本!T16 -> 0.29097222 | F16: =範本!T27 -> 0.29166667 | G16: =範本!T38 -> 0.33333333 | H16: =範本!T49 -> 0.29166667 | I16: =範本!T59 -> 0.29166667 | J16: =範本!T70 -> 0.34722222
C17: 結束 | D17: 0.47361111 | E17: 0.48263889 | F17: 0.56944444 | G17: 0.60416667 | H17: 0.58333333 | I17: 0.48819444 | J17: 0.46875
B18: 產線異常 (5分鐘以上) | C18: 次數
C19: 時間/分
B20: 短暫停線 (5分鐘以下) | C20: 次數
C21: 設備次數
B22: 配置人數 | D22: =VALUE(範本!M15) -> 15 | E22: =VALUE(範本!M26) -> 12.666667 | F22: =VALUE(範本!M37) -> 14.666667 | G22: =VALUE(範本!M48) -> 14 | H22: =VALUE(範本!M58) -> 17.666667 | I22: =VALUE(範本!M69) -> 12.333333 | J22: =範本!M79 -> 11
B23: 主要應用設備 | D23: ET-600 | E23: ET-600 | F23: ET-55 | G23: ET-55 | H23: ET-55 | I23: 八爪機
B24: 次要應用設備 | H24: 封口機
B25: 備註

Sheet 範本
A1: 長家廠4度C日報分析 | D1: 總生產量 | E1: =SUM(G5:G79) -> 43309 | F1: 營業額 | G1: =SUM(H5:H79) -> #N/A | H1: 出勤人數 | I1: =M15+M26+M48+M58+M69+M79+M37 -> 97.333333 | J1: 產線配置圖 | M1: 生產實績 | P1: 人時性差異分析 | T1: 日報登錄 | Z1: 合計 次數 | AA1: 合計 時間/分 | AB1: 分析說明 | AD1: 合計 次數 | AE1: 合計 設備次數 | AF1: 產能差異分析
A2: 12月24日 星期三 | D2: 人時性 | E2: =AVERAGE(O15,O26,O37,O48,O58,O69,O79) -> 116.11475 | F2: 平均廠價 | G2: =G1/E1 -> #N/A | H2: 多次生產數 | I2: =COUNT(I5:I79) -> 0 | Z2: =Z15+Z26+Z37+Z48+Z58+Z69+Z79 -> 0 | AA2: =AA15+AA26+AA37+AA48+AA58+AA69+AA79 -> 0 | AD2: =AD15+AD26+AD37+AD48+AD58+AD69+AD79 -> 0 | AE2: =AE15+AE26+AE37+AE48+AE58+AE69+AE79 -> 0
A3: 線別 | B3: 品類 | D3: 品名 | F3: 廠價 | G3: 生產量 | H3: 營收 | I3: 多次 生產 | J3: 人數 | K3: 產能/時 | L3: 人時性 | M3: 人數 | N3: 產能/時 | O3: 人時性 | P3: 人數 | Q3: 人時性 | R3: 達成率 | S3: 達成率平均 | T3: 生產時間 | V3: 前置、換線時間/分 | W3: 稼動時間/分 | X3: 休息時間 | Z3: 產線異常統計 (5分鐘以上) | AD3: 短暫停線統計 (5分鐘以下) | AF3: 產能/時 | AG3: 達成率 | AH3: 達成率平均
T4: 開始 | U4: 結束 | X4: 開始 | Y4: 結束 | Z4: 次數 | AA4: 時間/分 | AD4: 總次數 | AE4: 設備因素(次數)
A5: 自動一線 (ET-600) | B5: =VLOOKUP(D5,廠價表!$C$1:$E$43,2,0) -> #N/A | F5: =VLOOKUP(D5,廠價表!$C$1:$E$43,3,0) -> #N/A | G5: 2263 | H5: =F5*G5 -> #N/A | J5: =VLOOKUP(D5,產線配置圖!$A$3:$C$40,2,0) -> #N/A | K5: =VLOOKUP(D5,產線配置圖!$A$3:$C$40,3,0) -> #N/A | L5: =K5/J5 -> #N/A | M5: 15 | N5: =G5/W5*60 -> 1444.4681 | O5: =N5/M5 -> 96.297872 | P5: =M5-J5 -> #N/A | Q5: =O5-L5 -> #N/A | R5: =O5/L5 -> #N/A | S5: =R15 -> #N/A | T5: 0.29097222 | U5: 0.35625 | W5: =(U5-T5)*24*60 -> 94 | AF5: =N5-K5 -> #N/A | AG5: =N5/K5 -> #N/A | AH5: =AG15 -> #N/A
B6: =VLOOKUP(D6,廠價表!$C$1:$E$43,2,0) -> #N/A | F6: =VLOOKUP(D6,廠價表!$C$1:$E$43,3,0) -> #N/A | G6: 1180 | H6: =F6*G6 -> #N/A | J6: =VLOOKUP(D6,產線配置圖!$A$3:$C$40,2,0) -> #N/A | K6: =VLOOKUP(D6,產線配置圖!$A$3:$C$40,3,0) -> #N/A | L6: =K6/J6 -> #N/A | M6: 17 | N6: =G6/W6*60 -> 1609.0909 | O6: =N6/M6 -> 94.652406 | P6: =M6-J6 -> #N/A | Q6: =O6-L6 -> #N/A | R6: =O6/L6 -> #N/A | T6: 0.36458333 | U6: 0.39513889 | V6: =(T6-U5)*24*60 -> 12 | W6: =(U6-T6)*24*60 -> 44 | AF6: =N6-K6 -> #N/A | AG6: =N6/K6 -> #N/A
B7: =VLOOKUP(D7,廠價表!$C$1:$E$43,2,0) -> #N/A | F7: =VLOOKUP(D7,廠價表!$C$1:$E$43,3,0) -> #N/A | G7: 3398 | H7: =F7*G7 -> #N/A | J7: =VLOOKUP(D7,產線配置圖!$A$3:$C$40,2,0) -> #N/A | K7: =VLOOKUP(D7,產線配置圖!$A$3:$C$40,3,0) -> #N/A | L7: =K7/J7 -> #N/A | M7: 13 | N7: =G7/W7*60 -> 1960.3846 | O7: =N7/M7 -> 150.79882 | P7: =M7-J7 -> #N/A | Q7: =O7-L7 -> #N/A | R7: =O7/L7 -> #N/A | T7: 0.40138889 | U7: 0.47361111 | V7: =(T7-U6)*24*60 -> 9 | W7: =(U7-T7)*24*60 -> 104 | AF7: =N7-K7 -> #N/A | AG7: =N7/K7 -> #N/A
W8: =(U8-T8)*24*60 -> 0 | X8: 0.48611111 | Y8: 0.52777778 | AF8: =N8-K8 -> 0 | AG8: =N8/K8 -> #DIV/0!
W9: =(U9-T9)*24*60 -> 0 | AF9: =N9-K9 -> 0 | AG9: =N9/K9 -> #DIV/0!
W10: =(U10-T10)*24*60 -> 0 | AF10: =N10-K10 -> 0 | AG10: =N10/K10 -> #DIV/0!
W11: =(U11-T11)*24*60 -> 0 | AF11: =N11-K11 -> 0 | AG11: =N11/K11 -> #DIV/0!
W12: =(U12-T12)*24*60 -> 0
W13: =(U13-T13)*24*60 -> 0
W14: =(U14-T14)*24*60 -> 0
C15: 4度一組 | D15: 平均 | J15: =AVERAGE(J5:J14) -> #N/A | K15: =AVERAGE(K5:K14) -> #N/A | L15: =AVERAGE(L5:L14) -> #N/A | M15: =AVERAGE(M5:M14) -> 15 | N15: =AVERAGE(N5:N14) -> 1671.3145 | O15: =AVERAGE(O5:O14) -> 113.91637 | P15: =M15-J15 -> #N/A | Q15: =O15-L15 -> #N/A | R15: =O15/L15 -> #N/A | Z15: =SUM(Z5:Z14) -> 0 | AA15: =SUM(AA5:AA14) -> 0 | AD15: =SUM(AD5:AD14) -> 0 | AE15: =SUM(AE5:AE14) -> 0 | AF15: =N15-K15 -> #N/A | AG15: =N15/K15 -> #N/A
A16: 自動二線 (ET-600) | B16: =VLOOKUP(D16,廠價表!$C$1:$E$43,2,0) -> #N/A | F16: =VLOOKUP(D16,廠價表!$C$1:$E$43,3,0) -> #N/A | G16: 2263 | H16: =F16*G16 -> #N/A | J16: =VLOOKUP(D16,產線配置圖!$A$3:$C$40,2,0) -> #N/A | K16: =VLOOKUP(D16,產線配置圖!$A$3:$C$40,3,0) -> #N/A | L16: =K16/J16 -> #N/A | M16: 13 | N16: =G16/W16*60 -> 2225.9016 | O16: =N16/M16 -> 171.2232 | P16: =M16-J16 -> #N/A | Q16: =O16-L16 -> #N/A | R16: =O16/L16 -> #N/A | S16: =R26 -> #N/A | T16: 0.29097222 | U16: 0.33333333 | W16: =(U16-T16)*24*60 -> 61 | AF16: =N16-K16 -> #N/A | AG16: =N16/K16 -> #N/A | AH16: =AG26 -> #N/A
B17: =VLOOKUP(D17,廠價表!$C$1:$E$43,2,0) -> #N/A | F17: =VLOOKUP(D17,廠價表!$C$1:$E$43,3,0) -> #N/A | G17: 1180 | H17: =F17*G17 -> #N/A | J17: =VLOOKUP(D17,產線配置圖!$A$3:$C$40,2,0) -> #N/A | K17: =VLOOKUP(D17,產線配置圖!$A$3:$C$40,3,0) -> #N/A | L17: =K17/J17 -> #N/A | M17: 13 | N17: =G17/W17*60 -> 823.25581 | O17: =N17/M17 -> 63.32737 | P17: =M17-J17 -> #N/A | Q17: =O17-L17 -> #N/A | R17: =O17/L17 -> #N/A | T17: 0.34166667 | U17: 0.40138889 | V17: =(T17-U16)*24*60 -> 12 | W17: =(U17-T17)*24*60 -> 86 | AF17: =N17-K17 -> #N/A | AG17: =N17/K17 -> #N/A
B18: =VLOOKUP(D18,廠價表!$C$1:$E$43,2,0) -> #N/A | F18: =VLOOKUP(D18,廠價表!$C$1:$E$43,3,0) -> #N/A | G18: 3398 | H18: =F18*G18 -> #N/A | J18: =VLOOKUP(D18,產線配置圖!$A$3:$C$40,2,0) -> #N/A | K18: =VLOOKUP(D18,產線配置圖!$A$3:$C$40,3,0) -> #N/A | L18: =K18/J18 -> #N/A | M18: 12 | N18: =G18/W18*60 -> 1941.7143 | O18: =N18/M18 -> 161.80952 | P18: =M18-J18 -> #N/A | Q18: =O18-L18 -> #N/A | R18: =O18/L18 -> #N/A | T18: 0.40972222 | U18: 0.48263889 | V18: =(T18-U17)*24*60 -> 12 | W18: =(U18-T18)*24*60 -> 105 | X18: 0.48611111 | Y18: 0.52777778 | AF18: =N18-K18 -> #N/A | AG18: =N18/K18 -> #N/A
V19: =(T19-U18)*24*60 -> -695 | W19: =(U19-T19)*24*60 -> 0 | AF19: =N19-K19 -> 0 | AG19: =N19/K19 -> #DIV/0!
V20: =(T20-U19)*24*60 -> 0 | W20: =(U20-T20)*24*60 -> 0
W21: =(U21-T21)*24*60 -> 0
W22: 0
W23: =(U23-T23)*24*60 -> 0
H24: =F24*G24 -> 0 | W24: =(U24-T24)*24*60 -> 0
H25: =F25*G25 -> 0 | W25: =(U25-T25)*24*60 -> 0
C26: 4度二組A | D26: 平均 | J26: =AVERAGE(J16:J25) -> #N/A | K26: =AVERAGE(K16:K25) -> #N/A | L26: =AVERAGE(L16:L25) -> #N/A | M26: =AVERAGE(M16:M25) -> 12.666667 | N26: =AVERAGE(N16:N25) -> 1663.6239 | O26: =AVERAGE(O16:O25) -> 132.12003 | P26: =M26-J26 -> #N/A | Q26: =O26-L26 -> #N/A | R26: =O26/L26 -> #N/A | Z26: =SUM(Z16:Z25) -> 0 | AA26: =SUM(AA16:AA25) -> 0 | AD26: =SUM(AD16:AD25) -> 0 | AE26: =SUM(AE16:AE25) -> 0 | AF26: =N26-K26 -> #N/A | AG26: =N26/K26 -> #N/A
A27: 手工三線 (ET-55) | B27: =VLOOKUP(D27,廠價表!$C$1:$E$43,2,0) -> #N/A | F27: =VLOOKUP(D27,廠價表!$C$1:$E$43,3,0) -> #N/A | G27: 2263 | H27: =F27*G27 -> #N/A | J27: =VLOOKUP(D27,產線配置圖!$A$3:$C$40,2,0) -> #N/A | K27: =VLOOKUP(D27,產線配置圖!$A$3:$C$40,3,0) -> #N/A | L27: =K27/J27 -> #N/A | M27: 14 | N27: =G27/W27*60 -> 1212.3214 | O27: =N27/M27 -> 86.594388 | P27: =M27-J27 -> #N/A | Q27: =O27-L27 -> #N/A | R27: =O27/L27 -> #N/A | S27: =R37 -> #N/A | T27: 0.29166667 | U27: 0.36944444 | W27: =(U27-T27)*24*60 -> 112 | AF27: =N27-K27 -> #N/A | AG27: =N27/K27 -> #N/A | AH27: =AG37 -> #N/A
B28: =VLOOKUP(D28,廠價表!$C$1:$E$43,2,0) -> #N/A | F28: =VLOOKUP(D28,廠價表!$C$1:$E$43,3,0) -> #N/A | G28: 1180 | H28: =F28*G28 -> #N/A | J28: =VLOOKUP(D28,產線配置圖!$A$3:$C$40,2,0) -> #N/A | K28: =VLOOKUP(D28,產線配置圖!$A$3:$C$40,3,0) -> #N/A | L28: =K28/J28 -> #N/A | M28: 16 | N28: =G28/W28*60 -> 1089.2308 | O28: =N28/M28 -> 68.076923 | P28: =M28-J28 -> #N/A | Q28: =O28-L28 -> #N/A | R28: =O28/L28 -> #N/A | T28: 0.375 | U28: 0.42013889 | V28: =(T28-U27)*24*60 -> 8 | W28: =(U28-T28)*24*60 -> 65 | AF28: =N28-K28 -> #N/A | AG28: =N28/K28 -> #N/A
B29: =VLOOKUP(D29,廠價表!$C$1:$E$43,2,0) -> #N/A | F29: =VLOOKUP(D29,廠價表!$C$1:$E$43,3,0) -> #N/A | G29: 3398 | H29: =F29*G29 -> #N/A | J29: =VLOOKUP(D29,產線配置圖!$A$3:$C$40,2,0) -> #N/A | K29: =VLOOKUP(D29,產線配置圖!$A$3:$C$40,3,0) -> #N/A | L29: =K29/J29 -> #N/A | M29: 14 | N29: =G29/W29*60 -> 3136.6154 | O29: =N29/M29 -> 224.04396 | P29: =M29-J29 -> #N/A | Q29: =O29-L29 -> #N/A | R29: =O29/L29 -> #N/A | T29: 0.43055556 | U29: 0.47569444 | V29: =(T29-U28)*24*60 -> 15 | W29: =(U29-T29)*24*60 -> 65 | AF29: =N29-K29 -> #N/A | AG29: =N29/K29 -> #N/A
T30: 0.53958333 | U30: 0.56944444 | V30: =(T30-U29)*24*60 -> 92 | W30: =(U30-T30)*24*60 -> 43 | X30: 0.49652778 | Y30: 0.53819444 | AF30: =N30-K30 -> 0 | AG30: =N30/K30 -> #DIV/0!
W31: =(U31-T31)*24*60 -> 0 | AF31: =N31-K31 -> 0 | AG31: =N31/K31 -> #DIV/0!
W32: =(U32-T32)*24*60 -> 0
W33: =(U33-T33)*24*60 -> 0
W34: =(U34-T34)*24*60 -> 0
W35: =(U35-T35)*24*60 -> 0
H36: =F36*G36 -> 0 | W36: =(U36-T36)*24*60 -> 0
C37: 4度二組B | D37: 平均 | J37: =AVERAGE(J27:J36) -> #N/A | K37: =AVERAGE(K27:K36) -> #N/A | L37: =AVERAGE(L27:L36) -> #N/A | M37: =AVERAGE(M27:M36) -> 14.666667 | N37: =AVERAGE(N27:N36) -> 1812.7225 | O37: =AVERAGE(O27:O36) -> 126.23842 | P37: =M37-J37 -> #N/A | Q37: =N37-K37 -> #N/A | R37: =O37/L37 -> #N/A | Z37: =SUM(Z27:Z36) -> 0 | AA37: =SUM(AA27:AA36) -> 0 | AD37: =SUM(AD27:AD36) -> 0 | AE37: =SUM(AE27:AE36) -> 0 | AF37: =N37-K37 -> #N/A | AG37: =N37/K37 -> #N/A
A38: 手工四線 (ET-55) | B38: =VLOOKUP(D38,廠價表!$C$1:$E$43,2,0) -> #N/A | F38: =VLOOKUP(D38,廠價表!$C$1:$E$43,3,0) -> #N/A | G38: 2263 | H38: =F38*G38 -> #N/A | J38: =VLOOKUP(D38,產線配置圖!$A$3:$C$40,2,0) -> #N/A | K38: =VLOOKUP(D38,產線配置圖!$A$3:$C$40,3,0) -> #N/A | L38: =K38/J38 -> #N/A | M38: 14 | N38: =G38/W38*60 -> 1967.8261 | O38: =N38/M38 -> 140.55901 | P38: =M38-J38 -> #N/A | Q38: =O38-L38 -> #N/A | R38: =O38/L38 -> #N/A | S38: =R48 -> #N/A | T38: 0.33333333 | U38: 0.38125 | W38: =(U38-T38)*24*60 -> 69 | AF38: =N38-K38 -> #N/A | AG38: =N38/K38 -> #N/A | AH38: =AG48 -> #N/A
B39: =VLOOKUP(D39,廠價表!$C$1:$E$43,2,0) -> #N/A | F39: =VLOOKUP(D39,廠價表!$C$1:$E$43,3,0) -> #N/A | G39: 1180 | H39: =F39*G39 -> #N/A | J39: =VLOOKUP(D39,產線配置圖!$A$3:$C$40,2,0) -> #N/A | K39: =VLOOKUP(D39,產線配置圖!$A$3:$C$40,3,0) -> #N/A | L39: =K39/J39 -> #N/A | M39: 14 | N39: =G39/W39*60 -> 885 | O39: =N39/M39 -> 63.214286 | P39: =M39-J39 -> #N/A | Q39: =O39-L39 -> #N/A | R39: =O39/L39 -> #N/A | T39: 0.38888889 | U39: 0.44444444 | V39: =(T39-U38)*24*60 -> 11 | W39: =(U39-T39)*24*60 -> 80 | AF39: =N39-K39 -> #N/A | AG39: =N39/K39 -> #N/A
B40: =VLOOKUP(D40,廠價表!$C$1:$E$43,2,0) -> #N/A | F40: =VLOOKUP(D40,廠價表!$C$1:$E$43,3,0) -> #N/A | G40: 3398 | H40: =F40*G40 -> #N/A | J40: =VLOOKUP(D40,產線配置圖!$A$3:$C$40,2,0) -> #N/A | K40: =VLOOKUP(D40,產線配置圖!$A$3:$C$40,3,0) -> #N/A | L40: =K40/J40 -> #N/A | M40: 14 | N40: =G40/W40*60 -> 1853.4545 | O40: =N40/M40 -> 132.38961 | P40: =M40-J40 -> #N/A | Q40: =O40-L40 -> #N/A | R40: =O40/L40 -> #N/A | T40: 0.52777778 | U40: 0.60416667 | V40: =(T40-U39)*24*60 -> 120 | W40: =(U40-T40)*24*60 -> 110 | AF40: =N40-K40 -> #N/A | AG40: =N40/K40 -> #N/A
...

Sheet 0601總
B1: 長家廠組合室生產人時性分析
B3: 日期 | D3: 46174 | F3: 訂單量 | G3: ='0601'!E1 -> 64603 | I3: 營業額 | J3: ='0601'!G1 -> 3077066
B4: 項目 | D4: 3 | F4: ➀ | H4: ➁ | J4: ③ | L4: 異常停線 | N4: 短暫停線
B5: 人時性 | D5: 組合室 | F5: 全溫層 | H5: 義大利麵 | J5: 袋裝小吃、義麵 | L5: 合計次數 | M5: 時間 | N5: 合計次數 | O5: 設備次數
D6: 排關平均 | F6: =AVERAGE(D13:I13) -> 123.9344 | H6: =AVERAGE(D13:H13) -> 123.77612 | J6: =AVERAGE(I13) -> 124.72576 | L6: =SUM(D18:J18) -> 1 | M6: =SUM(D19:J19) -> 42 | N6: =SUM(D20:J20) -> 0 | O6: =SUM(D20:J20) -> 0
D7: 實績平均 | F7: =AVERAGE(D14:I14) -> 113.07645 | H7: =AVERAGE(D14:H14) -> 112.20491 | J7: =AVERAGE(I14) -> 117.43416 | L7: =AVERAGE(K14:L14) -> #DIV/0! | M7: =AVERAGE(L14:M14) -> #DIV/0! | N7: =AVERAGE(M14:N14) -> #DIV/0! | O7: =AVERAGE(N14:O14) -> #DIV/0!
D8: 達成率平均 | F8: =F7/F6 -> 0.91238956 | H8: =H7/H6 -> 0.90651495 | J8: =J7/J6 -> 0.94153896 | L8: =AVERAGE(K15:L15) -> #DIV/0! | M8: =AVERAGE(L15:M15) -> #DIV/0! | N8: =AVERAGE(M15:N15) -> #DIV/0! | O8: =AVERAGE(N15:O15) -> #DIV/0!
J9: ※現行日本鮮食廠以達成率80%為基本(即為現行KPI)
B10: 溫層 | D10: 4度C-各編組展開
B11: 編組 | D11: 1 | E11: 2 | F11: 3 | G11: 4 | H11: 5 | I11: 6 | J11: 7
D12: 自動1線 | E12: 自動2線 | F12: 手工3線 | G12: 手工4線 | H12: 手工5線 | I12: 調理包1線 | J12: 調理包2線
B13: 人時性 | C13: 排關 | D13: =VALUE('0601'!L15) -> 150 | E13: =VALUE('0601'!L26) -> 158.32256 | F13: =VALUE('0601'!L37) -> 104.35284 | G13: =VALUE('0601'!L48) -> 105.25098 | H13: =VALUE('0601'!L58) -> 100.95425 | I13: =VALUE('0601'!L69) -> 124.72576 | J13: ='0601'!L79 -> 0
C14: 實績 | D14: =VALUE('0601'!O15) -> 141.12399 | E14: =VALUE('0601'!O26) -> 137.68361 | F14: =VALUE('0601'!O37) -> 94.47741 | G14: =VALUE('0601'!O48) -> 96.809991 | H14: =VALUE('0601'!O58) -> 90.929545 | I14: =VALUE('0601'!O69) -> 117.43416 | J14: ='0601'!O79 -> 0
C15: 達成率 | D15: =D14/D13 -> 0.94082658 | E15: =E14/E13 -> 0.86963986 | F15: =F14/F13 -> 0.90536504 | G15: =G14/G13 -> 0.91980132 | H15: =H14/H13 -> 0.90070053 | I15: =I14/I13 -> 0.94153896 | J15: ='0601'!S70 -> 0
B16: 作業 時間 | C16: 開始 | D16: ='0601'!T5 -> 0.30208333 | E16: ='0601'!T16 -> 0.30138889 | F16: ='0601'!T27 -> 0.29166667 | G16: ='0601'!T38 -> 0.33333333 | H16: ='0601'!T49 -> 0.29166667 | I16: ='0601'!T59 -> 0.30555556 | J16: ='0601'!T70 -> 0
C17: 結束 | D17: 0.65416667 | E17: 0.67222222 | F17: 0.66527778 | G17: 0.65972222 | H17: 0.69097222 | I17: 0.66319444 | J17: 0
B18: 產線異常 (5分鐘以上) | C18: 次數 | D18: ='0601'!Z15 -> 0 | E18: ='0601'!Z26 -> 1 | F18: ='0601'!Z37 -> 0 | G18: ='0601'!Z48 -> 0 | H18: ='0601'!Z58 -> 0 | I18: ='0601'!Z69 -> 0 | J18: ='0601'!AA79 -> 0
C19: 時間/分 | D19: ='0601'!AA15 -> 0 | E19: ='0601'!AA26 -> 42 | F19: ='0601'!AA37 -> 0 | G19: ='0601'!AA48 -> 0 | H19: ='0601'!AA58 -> 0 | I19: ='0601'!AA69 -> 0 | J19: ='0601'!AB79 -> 0
B20: 短暫停線 (5分鐘以下) | C20: 次數 | D20: ='0601'!AD15 -> 0 | E20: ='0601'!AD26 -> 0 | F20: ='0601'!AD37 -> 0 | G20: ='0601'!AD48 -> 0 | H20: ='0601'!AD58 -> 0 | I20: ='0601'!AD69 -> 0 | J20: ='0601'!AD79 -> 0
C21: 設備次數 | D21: ='0601'!AE15 -> 0 | E21: ='0601'!AE26 -> 0 | F21: ='0601'!AE37 -> 0 | G21: ='0601'!AE48 -> 0 | H21: ='0601'!AE58 -> 0 | I21: ='0601'!AE69 -> 0 | J21: ='0601'!AE79 -> 0
B22: 配置人數 | D22: =VALUE('0601'!M15) -> 15 | E22: =VALUE('0601'!M26) -> 14.333333 | F22: =VALUE('0601'!M37) -> 13.6 | G22: =VALUE('0601'!M48) -> 16 | H22: =VALUE('0601'!M58) -> 15.8 | I22: =VALUE('0601'!M69) -> 12.6 | J22: ='0601'!M79 -> 0
B23: 主要應用設備 | D23: ET-600 | E23: ET-600 | F23: ET-55 | G23: ET-55 | H23: ET-55 | I23: 八爪機 | J23: 八爪機
B24: 次要應用設備 | H24: 封口機 | J24: 封口機
B25: 備註

Sheet 0601
A1: 長家廠4度C日報分析 | D1: 總生產量 | E1: =SUM(G5:G79) -> 64603 | F1: 營業額 | G1: =SUM(H5:H79) -> 3077066 | H1: 出勤人數 | I1: =M15+M26+M48+M58+M69+M79+M37 -> 87.333333 | J1: 產線配置圖 | M1: 生產實績 | P1: 人時性差異分析 | T1: 日報登錄 | Z1: 合計 次數 | AA1: 合計 時間/分 | AB1: 分析說明 | AD1: 合計 次數 | AE1: 合計 設備次數 | AF1: 產能差異分析
A2: 06月01日 星期一 | D2: 人時性 | E2: =AVERAGE(O15,O26,O37,O48,O58,O69,O79) -> 113.07645 | F2: 平均廠價 | G2: =G1/E1 -> 47.630388 | H2: 多次生產數 | I2: =COUNT(I5:I79) -> 0 | Z2: =Z15+Z26+Z37+Z48+Z58+Z69+Z79 -> 1 | AA2: =AA15+AA26+AA37+AA48+AA58+AA69+AA79 -> 42 | AD2: =AD15+AD26+AD37+AD48+AD58+AD69+AD79 -> 0 | AE2: =AE15+AE26+AE37+AE48+AE58+AE69+AE79 -> 0
A3: 線別 | B3: 品類 | D3: 品名 | F3: 廠價 | G3: 生產量 | H3: 營收 | I3: 多次 生產 | J3: 人數 | K3: 產能/時 | L3: 人時性 | M3: 人數 | N3: 產能/時 | O3: 人時性 | P3: 人數 | Q3: 人時性 | R3: 達成率 | S3: 達成率平均 | T3: 生產時間 | V3: 前置、換線時間/分 | W3: 稼動時間/分 | X3: 休息時間 | Z3: 產線異常統計 (5分鐘以上) | AD3: 短暫停線統計 (5分鐘以下) | AF3: 產能/時 | AG3: 達成率 | AH3: 達成率平均
T4: 開始 | U4: 結束 | X4: 開始 | Y4: 結束 | Z4: 次數 | AA4: 時間/分 | AD4: 總次數 | AE4: 設備因素(次數)
A5: 自動一線 (ET-600) | B5: 義大利麵 | D5: 白酒清炒鮮蛤義大利麵 | F5: =VLOOKUP(D5,廠價表!$C$1:$E$43,3,0) -> 56.87 | G5: 2238 | H5: =F5*G5 -> 127275.06 | J5: =VLOOKUP(D5,產線配置圖!$A$3:$C$40,2,0) -> 15 | K5: =VLOOKUP(D5,產線配置圖!$A$3:$C$40,3,0) -> 2250 | L5: =K5/J5 -> 150 | M5: 15 | N5: =G5/W5*60 -> 2131.4286 | O5: =N5/M5 -> 142.09524 | P5: =M5-J5 -> 0 | Q5: =O5-L5 -> -7.9047619 | R5: =O5/L5 -> 0.94730159 | S5: =R15 -> 0.94082658 | T5: 0.30208333 | U5: 0.34583333 | W5: =(U5-T5)*24*60 -> 63 | AF5: =N5-K5 -> -118.57143 | AG5: =N5/K5 -> 0.94730159 | AH5: =AG15 -> 0.94082658
B6: 義大利麵 | D6: 香煎魚排佐檸檬奶油義大利麵 | F6: =VLOOKUP(D6,廠價表!$C$1:$E$43,3,0) -> 58.17 | G6: 3648 | H6: =F6*G6 -> 212204.16 | J6: =VLOOKUP(D6,產線配置圖!$A$3:$C$40,2,0) -> 15 | K6: =VLOOKUP(D6,產線配置圖!$A$3:$C$40,3,0) -> 2250 | L6: =K6/J6 -> 150 | M6: 15 | N6: =G6/W6*60 -> 2145.8824 | O6: =N6/M6 -> 143.05882 | P6: =M6-J6 -> 0 | Q6: =O6-L6 -> -6.9411765 | R6: =O6/L6 -> 0.95372549 | T6: 0.35972222 | U6: 0.43055556 | V6: =(T6-U5)*24*60 -> 20 | W6: =(U6-T6)*24*60 -> 102 | AF6: =N6-K6 -> -104.11765 | AG6: =N6/K6 -> 0.95372549
B7: 義大利麵 | D7: 奶油培根義大利麵 | F7: =VLOOKUP(D7,廠價表!$C$1:$E$43,3,0) -> 49.14 | G7: 4231 | H7: =F7*G7 -> 207911.34 | J7: =VLOOKUP(D7,產線配置圖!$A$3:$C$40,2,0) -> 15 | K7: =VLOOKUP(D7,產線配置圖!$A$3:$C$40,3,0) -> 2250 | L7: =K7/J7 -> 150 | M7: 15 | N7: =G7/W7*60 -> 2151.3559 | O7: =N7/M7 -> 143.42373 | P7: =M7-J7 -> 0 | Q7: =O7-L7 -> -6.5762712 | R7: =O7/L7 -> 0.95615819 | T7: 0.43888889 | U7: 0.52083333 | V7: =(T7-U6)*24*60 -> 12 | W7: =(U7-T7)*24*60 -> 118 | AF7: =N7-K7 -> -98.644068 | AG7: =N7/K7 -> 0.95615819
B8: 義大利麵 | D8: 奶油培根義大利麵 | F8: =VLOOKUP(D8,廠價表!$C$1:$E$43,3,0) -> 49.14 | G8: 2000 | H8: =F8*G8 -> 98280 | J8: =VLOOKUP(D8,產線配置圖!$A$3:$C$40,2,0) -> 15 | K8: =VLOOKUP(D8,產線配置圖!$A$3:$C$40,3,0) -> 2250 | L8: =K8/J8 -> 150 | M8: 15 | N8: =G8/W8*60 -> 2068.9655 | O8: =N8/M8 -> 137.93103 | P8: =M8-J8 -> 0 | Q8: =O8-L8 -> -12.068966 | R8: =O8/L8 -> 0.91954023 | T8: 0.57291667 | U8: 0.61319444 | V8: =(T8-U7)*24*60 -> 75 | W8: =(U8-T8)*24*60 -> 58 | X8: 0.52777778 | Y8: 0.56944444 | AF8: =N8-K8 -> -181.03448 | AG8: =N8/K8 -> 0.91954023
B9: 義大利麵 | D9: 白酒清炒鮮蛤義大利麵 | F9: =VLOOKUP(D9,廠價表!$C$1:$E$43,3,0) -> 56.87 | G9: 939 | H9: =F9*G9 -> 53400.93 | J9: =VLOOKUP(D9,產線配置圖!$A$3:$C$40,2,0) -> 15 | K9: =VLOOKUP(D9,產線配置圖!$A$3:$C$40,3,0) -> 2250 | L9: =K9/J9 -> 150 | M9: 15 | N9: =G9/W9*60 -> 2086.6667 | O9: =N9/M9 -> 139.11111 | P9: =M9-J9 -> 0 | Q9: =O9-L9 -> -10.888889 | R9: =O9/L9 -> 0.92740741 | T9: 0.63541667 | U9: 0.65416667 | V9: =(T9-U8)*24*60 -> 32 | W9: =(U9-T9)*24*60 -> 27 | AF9: =N9-K9 -> -163.33333 | AG9: =N9/K9 -> 0.92740741
W10: =(U10-T10)*24*60 -> 0 | AF10: =N10-K10 -> 0 | AG10: =N10/K10 -> #DIV/0!
W11: =(U11-T11)*24*60 -> 0 | AF11: =N11-K11 -> 0 | AG11: =N11/K11 -> #DIV/0!
W12: =(U12-T12)*24*60 -> 0
W13: =(U13-T13)*24*60 -> 0
W14: =(U14-T14)*24*60 -> 0
C15: 4度一組 | D15: 平均 | J15: =AVERAGE(J5:J14) -> 15 | K15: =AVERAGE(K5:K14) -> 2250 | L15: =AVERAGE(L5:L14) -> 150 | M15: =AVERAGE(M5:M14) -> 15 | N15: =AVERAGE(N5:N14) -> 2116.8598 | O15: =AVERAGE(O5:O14) -> 141.12399 | P15: =M15-J15 -> 0 | Q15: =O15-L15 -> -8.8760128 | R15: =O15/L15 -> 0.94082658 | Z15: =SUM(Z5:Z14) -> 0 | AA15: =SUM(AA5:AA14) -> 0 | AD15: =SUM(AD5:AD14) -> 0 | AE15: =SUM(AE5:AE14) -> 0 | AF15: =N15-K15 -> -133.14019 | AG15: =N15/K15 -> 0.94082658
A16: 自動二線 (ET-600) | B16: 義大利麵 | D16: 青醬蛤蜊義大利麵 | F16: =VLOOKUP(D16,廠價表!$C$1:$E$43,3,0) -> 50.67 | G16: 2265 | H16: =F16*G16 -> 114767.55 | J16: =VLOOKUP(D16,產線配置圖!$A$3:$C$40,2,0) -> 14 | K16: =VLOOKUP(D16,產線配置圖!$A$3:$C$40,3,0) -> 2250 | L16: =K16/J16 -> 160.71429 | M16: 14 | N16: =G16/W16*60 -> 1213.3929 | O16: =N16/M16 -> 86.670918 | P16: =M16-J16 -> 0 | Q16: =O16-L16 -> -74.043367 | R16: =O16/L16 -> 0.53928571 | S16: =R26 -> 0.86963986 | T16: 0.30138889 | U16: 0.37916667 | W16: =(U16-T16)*24*60 -> 112 | Z16: 1 | AA16: 42 | AB16: 8:05-8:47封口機異常鳴叫(斷線) | AF16: =N16-K16 -> -1036.6071 | AG16: =N16/K16 -> 0.53928571 | AH16: =AG26 -> 0.86565397
B17: 義大利麵 | D17: 蒜香奶油蝦蝦義大利麵 | F17: =VLOOKUP(D17,廠價表!$C$1:$E$43,3,0) -> 57.21 | G17: 2217 | H17: =F17*G17 -> 126834.57 | J17: =VLOOKUP(D17,產線配置圖!$A$3:$C$40,2,0) -> 17 | K17: =VLOOKUP(D17,產線配置圖!$A$3:$C$40,3,0) -> 2250 | L17: =K17/J17 -> 132.35294 | M17: 17 | N17: =G17/W17*60 -> 1662.75 | O17: =N17/M17 -> 97.808824 | P17: =M17-J17 -> 0 | Q17: =O17-L17 -> -34.544118 | R17: =O17/L17 -> 0.739 | T17: 0.38611111 | U17: 0.44166667 | V17: =(T17-U16)*24*60 -> 10 | W17: =(U17-T17)*24*60 -> 80 | AF17: =N17-K17 -> -587.25 | AG17: =N17/K17 -> 0.739
B18: 義大利麵 | D18: 義式辣味嫩烤雞腿排義大利麵 | F18: =VLOOKUP(D18,廠價表!$C$1:$E$43,3,0) -> 56.61 | G18: 1575 | H18: =F18*G18 -> 89160.75 | J18: =VLOOKUP(D18,產線配置圖!$A$3:$C$40,2,0) -> 15 | K18: =VLOOKUP(D18,產線配置圖!$A$3:$C$40,3,0) -> 2250 | L18: =K18/J18 -> 150 | M18: 15 | N18: =G18/W18*60 -> 1968.75 | O18: =N18/M18 -> 131.25 | P18: =M18-J18 -> 0 | Q18: =O18-L18 -> -18.75 | R18: =O18/L18 -> 0.875 | T18: 0.44930556 | U18: 0.48263889 | V18: =(T18-U17)*24*60 -> 11 | W18: =(U18-T18)*24*60 -> 48 | AF18: =N18-K18 -> -281.25 | AG18: =N18/K18 -> 0.875
B19: 義大利麵 | D19: 義式蕃茄起司義大利麵 | F19: =VLOOKUP(D19,廠價表!$C$1:$E$43,3,0) -> 50.39 | G19: 1653 | H19: =F19*G19 -> 83294.67 | J19: =VLOOKUP(D19,產線配置圖!$A$3:$C$40,2,0) -> 13 | K19: =VLOOKUP(D19,產線配置圖!$A$3:$C$40,3,0) -> 2250 | L19: =K19/J19 -> 173.07692 | M19: 13 | N19: =G19/W19*60 -> 1907.3077 | O19: =N19/M19 -> 146.71598 | P19: =M19-J19 -> 0 | Q19: =O19-L19 -> -26.360947 | R19: =O19/L19 -> 0.84769231 | T19: 0.48680556 | U19: 0.52291667 | V19: =(T19-U18)*24*60 -> 6 | W19: =(U19-T19)*24*60 -> 52 | X19: 0.52638889 | Y19: 0.56805556 | AF19: =N19-K19 -> -342.69231 | AG19: =N19/K19 -> 0.84769231
B20: 義大利麵 | D20: 義式蕃茄起司義大利麵 | F20: =VLOOKUP(D20,廠價表!$C$1:$E$43,3,0) -> 50.39 | G20: 3573 | H20: =F20*G20 -> 180043.47 | J20: =VLOOKUP(D20,產線配置圖!$A$3:$C$40,2,0) -> 13 | K20: =VLOOKUP(D20,產線配置圖!$A$3:$C$40,3,0) -> 2250 | L20: =K20/J20 -> 173.07692 | M20: 13 | N20: =G20/W20*60 -> 2041.7143 | O20: =N20/M20 -> 157.05495 | P20: =M20-J20 -> 0 | Q20: =O20-L20 -> -16.021978 | R20: =O20/L20 -> 0.90742857 | T20: 0.57152778 | U20: 0.64444444 | V20: =(T20-U19)*24*60 -> 70 | W20: =(U20-T20)*24*60 -> 105
B21: 義大利麵 | D21: 青醬蛤蜊義大利麵 | F21: =VLOOKUP(D21,廠價表!$C$1:$E$43,3,0) -> 50.67 | G21: 1398 | H21: =F21*G21 -> 70836.66 | J21: =VLOOKUP(D21,產線配置圖!$A$3:$C$40,2,0) -> 14 | K21: =VLOOKUP(D21,產線配置圖!$A$3:$C$40,3,0) -> 2250 | L21: =K21/J21 -> 160.71429 | M21: 14 | N21: =G21/W21*60 -> 2892.4138 | O21: =N21/M21 -> 206.60099 | P21: =M21-J21 -> 0 | Q21: =O21-L21 -> 45.8867 | R21: =O21/L21 -> 1.2855172 | T21: 0.65208333 | U21: 0.67222222 | V21: =(T21-U20)*24*60 -> 11 | W21: =(U21-T21)*24*60 -> 29 | AB21: 補封膜
W22: 0
W23: =(U23-T23)*24*60 -> 0
H24: =F24*G24 -> 0 | W24: =(U24-T24)*24*60 -> 0
H25: =F25*G25 -> 0 | W25: =(U25-T25)*24*60 -> 0
C26: 4度二組A | D26: 平均 | J26: =AVERAGE(J16:J25) -> 14.333333 | K26: =AVERAGE(K16:K25) -> 2250 | L26: =AVERAGE(L16:L25) -> 158.32256 | M26: =AVERAGE(M16:M25) -> 14.333333 | N26: =AVERAGE(N16:N25) -> 1947.7214 | O26: =AVERAGE(O16:O25) -> 137.68361 | P26: =M26-J26 -> 0 | Q26: =O26-L26 -> -20.638952 | R26: =O26/L26 -> 0.86963986 | Z26: =SUM(Z16:Z25) -> 1 | AA26: =SUM(AA16:AA25) -> 42 | AD26: =SUM(AD16:AD25) -> 0 | AE26: =SUM(AE16:AE25) -> 0 | AF26: =N26-K26 -> -302.27856 | AG26: =N26/K26 -> 0.86565397
A27: 手工三線 (ET-55) | B27: 義大利麵 | D27: 整條德式香腸義大利麵 | F27: =VLOOKUP(D27,廠價表!$C$1:$E$43,3,0) -> 57.21 | G27: 1429 | H27: =F27*G27 -> 81753.09 | J27: =VLOOKUP(D27,產線配置圖!$A$3:$C$40,2,0) -> 18 | K27: =VLOOKUP(D27,產線配置圖!$A$3:$C$40,3,0) -> 1565 | L27: =K27/J27 -> 86.944444 | M27: 14 | N27: =G27/W27*60 -> 1143.2 | O27: =N27/M27 -> 81.657143 | P27: =M27-J27 -> -4 | Q27: =O27-L27 -> -5.2873016 | R27: =O27/L27 -> 0.93918759 | S27: =R37 -> 0.90536504 | T27: 0.29166667 | U27: 0.34375 | W27: =(U27-T27)*24*60 -> 75 | AF27: =N27-K27 -> -421.8 | AG27: =N27/K27 -> 0.73047923 | AH27: =AG37 -> 0.80453468
B28: 義大利麵 | D28: 焗烤起司肉醬筆尖麵 | F28: =VLOOKUP(D28,廠價表!$C$1:$E$43,3,0) -> 50.67 | G28: 1674 | H28: =F28*G28 -> 84821.58 | J28: =VLOOKUP(D28,產線配置圖!$A$3:$C$40,2,0) -> 13 | K28: =VLOOKUP(D28,產線配置圖!$A$3:$C$40,3,0) -> 1440 | L28: =K28/J28 -> 110.76923 | M28: 13 | N28: =G28/W28*60 -> 1287.6923 | O28: =N28/M28 -> 99.053254 | P28: =M28-J28 -> 0 | Q28: =O28-L28 -> -11.715976 | R28: =O28/L28 -> 0.89423077 | T28: 0.35069444 | U28: 0.40486111 | V28: =(T28-U27)*24*60 -> 10 | W28: =(U28-T28)*24*60 -> 78 | AF28: =N28-K28 -> -152.30769 | AG28: =N28/K28 -> 0.89423077
B29: 義大利麵 | D29: 奶油鮮蝦明太子細扁麵 | F29: =VLOOKUP(D29,廠價表!$C$1:$E$43,3,0) -> 57.21 | G29: 1677 | H29: =F29*G29 -> 95941.17 | J29: =VLOOKUP(D29,產線配置圖!$A$3:$C$40,2,0) -> 18 | K29: =VLOOKUP(D29,產線配置圖!$A$3:$C$40,3,0) -> 1636 | L29: =K29/J29 -> 90.888889 | M29: 15 | N29: =G29/W29*60 -> 1359.7297 | O29: =N29/M29 -> 90.648649 | P29: =M29-J29 -> -3 | Q29: =O29-L29 -> -0.24024024 | R29: =O29/L29 -> 0.99735677 | T29: 0.41180556 | U29: 0.46319444 | V29: =(T29-U28)*24*60 -> 10 | W29: =(U29-T29)*24*60 -> 74 | AF29: =N29-K29 -> -276.27027 | AG29: =N29/K29 -> 0.83113064
B30: 義大利麵 | D30: 奶油鮮蝦明太子細扁麵 | F30: =VLOOKUP(D30,廠價表!$C$1:$E$43,3,0) -> 57.21 | G30: 2530 | H30: =F30*G30 -> 144741.3 | J30: =VLOOKUP(D30,產線配置圖!$A$3:$C$40,2,0) -> 18 | K30: =VLOOKUP(D30,產線配置圖!$A$3:$C$40,3,0) -> 1636 | L30: =K30/J30 -> 90.888889 | M30: 16 | N30: =G30/W30*60 -> 1355.3571 | O30: =N30/M30 -> 84.709821 | P30: =M30-J30 -> -2 | Q30: =O30-L30 -> -6.1790675 | R30: =O30/L30 -> 0.93201515 | T30: 0.52638889 | U30: 0.60416667 | V30: =(T30-U29)*24*60 -> 91 | W30: =(U30-T30)*24*60 -> 112 | X30: 0.52083333 | Y30: 0.52083333 | AF30: =N30-K30 -> -280.64286 | AG30: =N30/K30 -> 0.82845791
B31: 小吃、微波 | D31: 韓式炒冬粉 | F31: =VLOOKUP(D31,廠價表!$C$1:$E$43,3,0) -> 28.26 | G31: 853 | H31: =F31*G31 -> 24105.78 | J31: =VLOOKUP(D31,產線配置圖!$A$3:$C$40,2,0) -> 11 | K31: =VLOOKUP(D31,產線配置圖!$A$3:$C$40,3,0) -> 1565 | L31: =K31/J31 -> 142.27273 | M31: 10 | N31: =G31/W31*60 -> 1163.1818 | O31: =N31/M31 -> 116.31818 | P31: =M31-J31 -> -1 | Q31: =O31-L31 -> -25.954545 | R31: =O31/L31 -> 0.81757188 | T31: 0.63472222 | U31: 0.66527778 | V31: =(T31-U30)*24*60 -> 44 | W31: =(U31-T31)*24*60 -> 44 | AB31: 支援製作 | AF31: =N31-K31 -> -401.81818 | AG31: =N31/K31 -> 0.74324717
W32: =(U32-T32)*24*60 -> 0
W33: =(U33-T33)*24*60 -> 0
W34: =(U34-T34)*24*60 -> 0
W35: =(U35-T35)*24*60 -> 0
H36: =F36*G36 -> 0 | W36: =(U36-T36)*24*60 -> 0
C37: 4度二組B | D37: 平均 | J37: =AVERAGE(J27:J36) -> 15.6 | K37: =AVERAGE(K27:K36) -> 1568.4 | L37: =AVERAGE(L27:L36) -> 104.35284 | M37: =AVERAGE(M27:M36) -> 13.6 | N37: =AVERAGE(N27:N36) -> 1261.8322 | O37: =AVERAGE(O27:O36) -> 94.47741 | P37: =M37-J37 -> -2 | Q37: =N37-K37 -> -306.5678 | R37: =O37/L37 -> 0.90536504 | Z37: =SUM(Z27:Z36) -> 0 | AA37: =SUM(AA27:AA36) -> 0 | AD37: =SUM(AD27:AD36) -> 0 | AE37: =SUM(AE27:AE36) -> 0 | AF37: =N37-K37 -> -306.5678 | AG37: =N37/K37 -> 0.80453468
A38: 手工四線 (ET-55) | B38: 熱乾麵 | D38: 青花椒麻雞肉拌麵 | F38: =VLOOKUP(D38,廠價表!$C$1:$E$43,3,0) -> 49.91 | G38: 2751 | H38: =F38*G38 -> 137302.41 | J38: =VLOOKUP(D38,產線配置圖!$A$3:$C$40,2,0) -> 15 | K38: =VLOOKUP(D38,產線配置圖!$A$3:$C$40,3,0) -> 1714 | L38: =K38/J38 -> 114.26667 | M38: 15 | N38: =G38/W38*60 -> 1618.2353 | O38: =N38/M38 -> 107.88235 | P38: =M38-J38 -> 0 | Q38: =O38-L38 -> -6.3843137 | R38: =O38/L38 -> 0.94412794 | S38: =R48 -> 0.91980132 | T38: 0.33333333 | U38: 0.40416667 | W38: =(U38-T38)*24*60 -> 102 | AF38: =N38-K38 -> -95.764706 | AG38: =N38/K38 -> 0.94412794 | AH38: =AG48 -> 0.92168876
B39: 熱乾麵 | D39: 府城鹽水意麵 | F39: =VLOOKUP(D39,廠價表!$C$1:$E$43,3,0) -> 44.3 | G39: 1814 | H39: =F39*G39 -> 80360.2 | J39: =VLOOKUP(D39,產線配置圖!$A$3:$C$40,2,0) -> 17 | K39: =VLOOKUP(D39,產線配置圖!$A$3:$C$40,3,0) -> 1636 | L39: =K39/J39 -> 96.235294 | M39: 17 | N39: =G39/W39*60 -> 1554.8571 | O39: =N39/M39 -> 91.462185 | P39: =M39-J39 -> 0 | Q39: =O39-L39 -> -4.7731092 | R39: =O39/L39 -> 0.95040168 | T39: 0.41319444 | U39: 0.46180556 | V39: =(T39-U38)*24*60 -> 13 | W39: =(U39-T39)*24*60 -> 70 | X39: 0.46875 | Y39: 0.52083333 | AF39: =N39-K39 -> -81.142857 | AG39: =N39/K39 -> 0.95040168
B40: 熱乾麵 | D40: 府城鹽水意麵 | F40: =VLOOKUP(D40,廠價表!$C$1:$E$43,3,0) -> 44.3 | G40: 4218 | H40: =F40*G40 -> 186857.4 | J40: =VLOOKUP(D40,產線配置圖!$A$3:$C$40,2,0) -> 17 | K40: =VLOOKUP(D40,產線配置圖!$A$3:$C$40,3,0) -> 1636 | L40: =K40/J40 -> 96.235294 | M40: 17 | N40: =G40/W40*60 -> 1562.2222 | O40: =N40/M40 -> 91.895425 | P40: =M40-J40 -> 0 | Q40: =O40-L40 -> -4.3398693 | R40: =O40/L40 -> 0.95490356 | T40: 0.52291667 | U40: 0.63541667 | V40: =(T40-U39)*24*60 -> 88 | W40: =(U40-T40)*24*60 -> 162 | AF40: =N40-K40 -> -73.777778 | AG40: =N40/K40 -> 0.95490356
...

Sheet 0602總
B1: 長家廠組合室生產人時性分析
B3: 日期 | D3: 46175 | F3: 訂單量 | G3: ='0602'!E1 -> 62091 | I3: 營業額 | J3: ='0602'!G1 -> 2949744.6
B4: 項目 | D4: 3 | F4: ➀ | H4: ➁ | J4: ③ | L4: 異常停線 | N4: 短暫停線
B5: 人時性 | D5: 組合室 | F5: 全溫層 | H5: 義大利麵 | J5: 袋裝小吃、義麵 | L5: 合計次數 | M5: 時間 | N5: 合計次數 | O5: 設備次數
D6: 排關平均 | F6: =AVERAGE(D13:I13) -> 122.64385 | H6: =AVERAGE(D13:H13) -> 122.22747 | J6: =AVERAGE(I13) -> 124.72576 | L6: =SUM(D18:J18) -> 2 | M6: =SUM(D19:J19) -> 23 | N6: =SUM(D20:J20) -> 0 | O6: =SUM(D20:J20) -> 0
D7: 實績平均 | F7: =AVERAGE(D14:I14) -> 104.08944 | H7: =AVERAGE(D14:H14) -> 102.77121 | J7: =AVERAGE(I14) -> 110.68059 | L7: =AVERAGE(K14:L14) -> #DIV/0! | M7: =AVERAGE(L14:M14) -> #DIV/0! | N7: =AVERAGE(M14:N14) -> #DIV/0! | O7: =AVERAGE(N14:O14) -> #DIV/0!
D8: 達成率平均 | F8: =F7/F6 -> 0.84871304 | H8: =H7/H6 -> 0.84081921 | J8: =J7/J6 -> 0.88739164 | L8: =AVERAGE(K15:L15) -> #DIV/0! | M8: =AVERAGE(L15:M15) -> #DIV/0! | N8: =AVERAGE(M15:N15) -> #DIV/0! | O8: =AVERAGE(N15:O15) -> #DIV/0!
J9: ※現行日本鮮食廠以達成率80%為基本(即為現行KPI)
B10: 溫層 | D10: 4度C-各編組展開
B11: 編組 | D11: 1 | E11: 2 | F11: 3 | G11: 4 | H11: 5 | I11: 6 | J11: 7
D12: 自動1線 | E12: 自動2線 | F12: 手工3線 | G12: 手工4線 | H12: 手工5線 | I12: 調理包1線 | J12: 調理包2線
B13: 人時性 | C13: 排關 | D13: =VALUE('0602'!L15) -> 150 | E13: =VALUE('0602'!L26) -> 158.32256 | F13: =VALUE('0602'!L37) -> 93.287179 | G13: =VALUE('0602'!L48) -> 106.35463 | H13: =VALUE('0602'!L58) -> 103.17298 | I13: =VALUE('0602'!L69) -> 124.72576 | J13: ='0602'!L79 -> 0
C14: 實績 | D14: =VALUE('0602'!O15) -> 122.60897 | E14: =VALUE('0602'!O26) -> 131.88798 | F14: =VALUE('0602'!O37) -> 84.92311 | G14: =VALUE('0602'!O48) -> 86.435846 | H14: =VALUE('0602'!O58) -> 88.000123 | I14: =VALUE('0602'!O69) -> 110.68059 | J14: ='0602'!O79 -> 0
C15: 達成率 | D15: =D14/D13 -> 0.81739313 | E15: =E14/E13 -> 0.83303339 | F15: =F14/F13 -> 0.91034064 | G15: =G14/G13 -> 0.81271352 | H15: =H14/H13 -> 0.85293764 | I15: =I14/I13 -> 0.88739164 | J15: ='0602'!S70 -> 0
B16: 作業 時間 | C16: 開始 | D16: ='0602'!T5 -> 0.29166667 | E16: ='0602'!T16 -> 0.29236111 | F16: ='0602'!T27 -> 0.29166667 | G16: ='0602'!T38 -> 0.33333333 | H16: ='0602'!T49 -> 0.29166667 | I16: ='0602'!T59 -> 0.29166667 | J16: ='0602'!T70 -> 0
C17: 結束 | D17: 0.66666667 | E17: 0.66666667 | F17: 0.63402778 | G17: 0.70486111 | H17: 0.675 | I17: 0.68055556 | J17: 0
B18: 產線異常 (5分鐘以上) | C18: 次數 | D18: ='0602'!Z15 -> 2 | E18: ='0602'!Z26 -> 0 | F18: ='0602'!Z37 -> 0 | G18: ='0602'!Z48 -> 0 | H18: ='0602'!Z58 -> 0 | I18: ='0602'!Z69 -> 0 | J18: ='0602'!AA79 -> 0
C19: 時間/分 | D19: ='0602'!AA15 -> 23 | E19: ='0602'!AA26 -> 0 | F19: ='0602'!AA37 -> 0 | G19: ='0602'!AA48 -> 0 | H19: ='0602'!AA58 -> 0 | I19: ='0602'!AA69 -> 0 | J19: ='0602'!AB79 -> 0
B20: 短暫停線 (5分鐘以下) | C20: 次數 | D20: ='0602'!AD15 -> 0 | E20: ='0602'!AD26 -> 0 | F20: ='0602'!AD37 -> 0 | G20: ='0602'!AD48 -> 0 | H20: ='0602'!AD58 -> 0 | I20: ='0602'!AD69 -> 0 | J20: ='0602'!AD79 -> 0
C21: 設備次數 | D21: ='0602'!AE15 -> 0 | E21: ='0602'!AE26 -> 0 | F21: ='0602'!AE37 -> 0 | G21: ='0602'!AE48 -> 0 | H21: ='0602'!AE58 -> 0 | I21: ='0602'!AE69 -> 0 | J21: ='0602'!AE79 -> 0
B22: 配置人數 | D22: =VALUE('0602'!M15) -> 15 | E22: =VALUE('0602'!M26) -> 14.333333 | F22: =VALUE('0602'!M37) -> 16.2 | G22: =VALUE('0602'!M48) -> 15.4 | H22: =VALUE('0602'!M58) -> 16.333333 | I22: =VALUE('0602'!M69) -> 12.6 | J22: ='0602'!M79 -> 0
B23: 主要應用設備 | D23: ET-600 | E23: ET-600 | F23: ET-55 | G23: ET-55 | H23: ET-55 | I23: 八爪機 | J23: 八爪機
B24: 次要應用設備 | H24: 封口機 | J24: 封口機
B25: 備註

Sheet 0602
A1: 長家廠4度C日報分析 | D1: 總生產量 | E1: =SUM(G5:G79) -> 62091 | F1: 營業額 | G1: =SUM(H5:H79) -> 2949744.6 | H1: 出勤人數 | I1: =M15+M26+M48+M58+M69+M79+M37 -> 89.866667 | J1: 產線配置圖 | M1: 生產實績 | P1: 人時性差異分析 | T1: 日報登錄 | Z1: 合計 次數 | AA1: 合計 時間/分 | AB1: 分析說明 | AD1: 合計 次數 | AE1: 合計 設備次數 | AF1: 產能差異分析
A2: 06月02日 星期二 | D2: 人時性 | E2: =AVERAGE(O15,O26,O37,O48,O58,O69,O79) -> 104.08944 | F2: 平均廠價 | G2: =G1/E1 -> 47.506798 | H2: 多次生產數 | I2: =COUNT(I5:I79) -> 0 | Z2: =Z15+Z26+Z37+Z48+Z58+Z69+Z79 -> 2 | AA2: =AA15+AA26+AA37+AA48+AA58+AA69+AA79 -> 23 | AD2: =AD15+AD26+AD37+AD48+AD58+AD69+AD79 -> 0 | AE2: =AE15+AE26+AE37+AE48+AE58+AE69+AE79 -> 0
A3: 線別 | B3: 品類 | D3: 品名 | F3: 廠價 | G3: 生產量 | H3: 營收 | I3: 多次 生產 | J3: 人數 | K3: 產能/時 | L3: 人時性 | M3: 人數 | N3: 產能/時 | O3: 人時性 | P3: 人數 | Q3: 人時性 | R3: 達成率 | S3: 達成率平均 | T3: 生產時間 | V3: 前置、換線時間/分 | W3: 稼動時間/分 | X3: 休息時間 | Z3: 產線異常統計 (5分鐘以上) | AB3: 今日為學生第一天上線，產速降低 | AD3: 短暫停線統計 (5分鐘以下) | AF3: 產能/時 | AG3: 達成率 | AH3: 達成率平均
T4: 開始 | U4: 結束 | X4: 開始 | Y4: 結束 | Z4: 次數 | AA4: 時間/分 | AD4: 總次數 | AE4: 設備因素(次數)
A5: 自動一線 (ET-600) | B5: 義大利麵 | D5: 白酒清炒鮮蛤義大利麵 | F5: =VLOOKUP(D5,廠價表!$C$1:$E$43,3,0) -> 56.87 | G5: 2287 | H5: =F5*G5 -> 130061.69 | J5: =VLOOKUP(D5,產線配置圖!$A$3:$C$40,2,0) -> 15 | K5: =VLOOKUP(D5,產線配置圖!$A$3:$C$40,3,0) -> 2250 | L5: =K5/J5 -> 150 | M5: 15 | N5: =G5/W5*60 -> 1879.726 | O5: =N5/M5 -> 125.31507 | P5: =M5-J5 -> 0 | Q5: =O5-L5 -> -24.684932 | R5: =O5/L5 -> 0.83543379 | S5: =R15 -> 0.81739313 | T5: 0.29166667 | U5: 0.34236111 | W5: =(U5-T5)*24*60 -> 73 | AF5: =N5-K5 -> -370.27397 | AG5: =N5/K5 -> 0.83543379 | AH5: =AG15 -> 0.81739313
B6: 義大利麵 | D6: 香煎魚排佐檸檬奶油義大利麵 | F6: =VLOOKUP(D6,廠價表!$C$1:$E$43,3,0) -> 58.17 | G6: 3425 | H6: =F6*G6 -> 199232.25 | J6: =VLOOKUP(D6,產線配置圖!$A$3:$C$40,2,0) -> 15 | K6: =VLOOKUP(D6,產線配置圖!$A$3:$C$40,3,0) -> 2250 | L6: =K6/J6 -> 150 | M6: 15 | N6: =G6/W6*60 -> 1726.8908 | O6: =N6/M6 -> 115.12605 | P6: =M6-J6 -> 0 | Q6: =O6-L6 -> -34.87395 | R6: =O6/L6 -> 0.767507 | T6: 0.34930556 | U6: 0.43194444 | V6: =(T6-U5)*24*60 -> 10 | W6: =(U6-T6)*24*60 -> 119 | Z6: 1 | AA6: 17 | AB6: 08:23-08:40封膜異常 | AF6: =N6-K6 -> -523.10924 | AG6: =N6/K6 -> 0.767507
B7: 義大利麵 | D7: 奶油培根義大利麵 | F7: =VLOOKUP(D7,廠價表!$C$1:$E$43,3,0) -> 49.14 | G7: 1992 | H7: =F7*G7 -> 97886.88 | J7: =VLOOKUP(D7,產線配置圖!$A$3:$C$40,2,0) -> 15 | K7: =VLOOKUP(D7,產線配置圖!$A$3:$C$40,3,0) -> 2250 | L7: =K7/J7 -> 150 | M7: 15 | N7: =G7/W7*60 -> 1927.7419 | O7: =N7/M7 -> 128.51613 | P7: =M7-J7 -> 0 | Q7: =O7-L7 -> -21.483871 | R7: =O7/L7 -> 0.85677419 | T7: 0.43958333 | U7: 0.48263889 | V7: =(T7-U6)*24*60 -> 11 | W7: =(U7-T7)*24*60 -> 62 | AF7: =N7-K7 -> -322.25806 | AG7: =N7/K7 -> 0.85677419
B8: 義大利麵 | D8: 奶油培根義大利麵 | F8: =VLOOKUP(D8,廠價表!$C$1:$E$43,3,0) -> 49.14 | G8: 4141 | H8: =F8*G8 -> 203488.74 | J8: =VLOOKUP(D8,產線配置圖!$A$3:$C$40,2,0) -> 15 | K8: =VLOOKUP(D8,產線配置圖!$A$3:$C$40,3,0) -> 2250 | L8: =K8/J8 -> 150 | M8: 15 | N8: =G8/W8*60 -> 1840.4444 | O8: =N8/M8 -> 122.6963 | P8: =M8-J8 -> 0 | Q8: =O8-L8 -> -27.303704 | R8: =O8/L8 -> 0.81797531 | T8: 0.54861111 | U8: 0.64236111 | V8: =(T8-U7)*24*60 -> 95 | W8: =(U8-T8)*24*60 -> 135 | Z8: 1 | AA8: 6 | AB8: 14:12-14:18封膜異常 | AF8: =N8-K8 -> -409.55556 | AG8: =N8/K8 -> 0.81797531
B9: 義大利麵 | D9: 白酒清炒鮮蛤義大利麵 | F9: =VLOOKUP(D9,廠價表!$C$1:$E$43,3,0) -> 56.87 | G9: 698 | H9: =F9*G9 -> 39695.26 | J9: =VLOOKUP(D9,產線配置圖!$A$3:$C$40,2,0) -> 15 | K9: =VLOOKUP(D9,產線配置圖!$A$3:$C$40,3,0) -> 2250 | L9: =K9/J9 -> 150 | M9: 15 | N9: =G9/W9*60 -> 1820.8696 | O9: =N9/M9 -> 121.3913 | P9: =M9-J9 -> 0 | Q9: =O9-L9 -> -28.608696 | R9: =O9/L9 -> 0.80927536 | T9: 0.65069444 | U9: 0.66666667 | V9: =(T9-U8)*24*60 -> 12 | W9: =(U9-T9)*24*60 -> 23 | AB9: 生產數量少 | AF9: =N9-K9 -> -429.13043 | AG9: =N9/K9 -> 0.80927536
W10: =(U10-T10)*24*60 -> 0
W11: =(U11-T11)*24*60 -> 0
W12: =(U12-T12)*24*60 -> 0
W13: =(U13-T13)*24*60 -> 0
W14: =(U14-T14)*24*60 -> 0
C15: 4度一組 | D15: 平均 | J15: =AVERAGE(J5:J14) -> 15 | K15: =AVERAGE(K5:K14) -> 2250 | L15: =AVERAGE(L5:L14) -> 150 | M15: =AVERAGE(M5:M14) -> 15 | N15: =AVERAGE(N5:N14) -> 1839.1345 | O15: =AVERAGE(O5:O14) -> 122.60897 | P15: =M15-J15 -> 0 | Q15: =O15-L15 -> -27.39103 | R15: =O15/L15 -> 0.81739313 | Z15: =SUM(Z5:Z14) -> 2 | AA15: =SUM(AA5:AA14) -> 23 | AD15: =SUM(AD5:AD14) -> 0 | AE15: =SUM(AE5:AE14) -> 0 | AF15: =N15-K15 -> -410.86545 | AG15: =N15/K15 -> 0.81739313
A16: 自動二線 (ET-600) | B16: 義大利麵 | D16: 青醬蛤蜊義大利麵 | F16: =VLOOKUP(D16,廠價表!$C$1:$E$43,3,0) -> 50.67 | G16: 2136 | H16: =F16*G16 -> 108231.12 | J16: =VLOOKUP(D16,產線配置圖!$A$3:$C$40,2,0) -> 14 | K16: =VLOOKUP(D16,產線配置圖!$A$3:$C$40,3,0) -> 2250 | L16: =K16/J16 -> 160.71429 | M16: 14 | N16: =G16/W16*60 -> 2100.9836 | O16: =N16/M16 -> 150.07026 | P16: =M16-J16 -> 0 | Q16: =O16-L16 -> -10.644028 | R16: =O16/L16 -> 0.93377049 | S16: =R26 -> 0.83303339 | T16: 0.29236111 | U16: 0.33472222 | W16: =(U16-T16)*24*60 -> 61 | AF16: =N16-K16 -> -149.01639 | AG16: =N16/K16 -> 0.93377049 | AH16: =AG26 -> 0.83266424
B17: 義大利麵 | D17: 蒜香奶油蝦蝦義大利麵 | F17: =VLOOKUP(D17,廠價表!$C$1:$E$43,3,0) -> 57.21 | G17: 2021 | H17: =F17*G17 -> 115621.41 | J17: =VLOOKUP(D17,產線配置圖!$A$3:$C$40,2,0) -> 17 | K17: =VLOOKUP(D17,產線配置圖!$A$3:$C$40,3,0) -> 2250 | L17: =K17/J17 -> 132.35294 | M17: 17 | N17: =G17/W17*60 -> 1809.8507 | O17: =N17/M17 -> 106.46181 | P17: =M17-J17 -> 0 | Q17: =O17-L17 -> -25.891133 | R17: =O17/L17 -> 0.80437811 | T17: 0.34305556 | U17: 0.38958333 | V17: =(T17-U16)*24*60 -> 12 | W17: =(U17-T17)*24*60 -> 67 | AF17: =N17-K17 -> -440.14925 | AG17: =N17/K17 -> 0.80437811
B18: 義大利麵 | D18: 義式辣味嫩烤雞腿排義大利麵 | F18: =VLOOKUP(D18,廠價表!$C$1:$E$43,3,0) -> 56.61 | G18: 1338 | H18: =F18*G18 -> 75744.18 | J18: =VLOOKUP(D18,產線配置圖!$A$3:$C$40,2,0) -> 15 | K18: =VLOOKUP(D18,產線配置圖!$A$3:$C$40,3,0) -> 2250 | L18: =K18/J18 -> 150 | M18: 15 | N18: =G18/W18*60 -> 1866.9767 | O18: =N18/M18 -> 124.46512 | P18: =M18-J18 -> 0 | Q18: =O18-L18 -> -25.534884 | R18: =O18/L18 -> 0.82976744 | T18: 0.40277778 | U18: 0.43263889 | V18: =(T18-U17)*24*60 -> 19 | W18: =(U18-T18)*24*60 -> 43 | AF18: =N18-K18 -> -383.02326 | AG18: =N18/K18 -> 0.82976744
B19: 義大利麵 | D19: 義式蕃茄起司義大利麵 | F19: =VLOOKUP(D19,廠價表!$C$1:$E$43,3,0) -> 50.39 | G19: 1698 | H19: =F19*G19 -> 85562.22 | J19: =VLOOKUP(D19,產線配置圖!$A$3:$C$40,2,0) -> 13 | K19: =VLOOKUP(D19,產線配置圖!$A$3:$C$40,3,0) -> 2250 | L19: =K19/J19 -> 173.07692 | M19: 13 | N19: =G19/W19*60 -> 1852.3636 | O19: =N19/M19 -> 142.48951 | P19: =M19-J19 -> 0 | Q19: =O19-L19 -> -30.587413 | R19: =O19/L19 -> 0.82327273 | T19: 0.44097222 | U19: 0.47916667 | V19: =(T19-U18)*24*60 -> 12 | W19: =(U19-T19)*24*60 -> 55 | AF19: =N19-K19 -> -397.63636 | AG19: =N19/K19 -> 0.82327273
B20: 義大利麵 | D20: 義式蕃茄起司義大利麵 | F20: =VLOOKUP(D20,廠價表!$C$1:$E$43,3,0) -> 50.39 | G20: 3192 | H20: =F20*G20 -> 160844.88 | J20: =VLOOKUP(D20,產線配置圖!$A$3:$C$40,2,0) -> 13 | K20: =VLOOKUP(D20,產線配置圖!$A$3:$C$40,3,0) -> 2250 | L20: =K20/J20 -> 173.07692 | M20: 13 | N20: =G20/W20*60 -> 1806.7925 | O20: =N20/M20 -> 138.98403 | P20: =M20-J20 -> 0 | Q20: =O20-L20 -> -34.092888 | R20: =O20/L20 -> 0.80301887 | T20: 0.55625 | U20: 0.62986111 | V20: =(T20-U19)*24*60 -> 111 | W20: =(U20-T20)*24*60 -> 106
B21: 義大利麵 | D21: 青醬蛤蜊義大利麵 | F21: =VLOOKUP(D21,廠價表!$C$1:$E$43,3,0) -> 50.67 | G21: 1353 | H21: =F21*G21 -> 68556.51 | J21: =VLOOKUP(D21,產線配置圖!$A$3:$C$40,2,0) -> 14 | K21: =VLOOKUP(D21,產線配置圖!$A$3:$C$40,3,0) -> 2250 | L21: =K21/J21 -> 160.71429 | M21: 14 | N21: =G21/W21*60 -> 1804 | O21: =N21/M21 -> 128.85714 | P21: =M21-J21 -> 0 | Q21: =O21-L21 -> -31.857143 | R21: =O21/L21 -> 0.80177778 | T21: 0.63541667 | U21: 0.66666667 | V21: =(T21-U20)*24*60 -> 8 | W21: =(U21-T21)*24*60 -> 45 | AB21: 生產數量少
W22: 0
W23: =(U23-T23)*24*60 -> 0
H24: =F24*G24 -> 0 | W24: =(U24-T24)*24*60 -> 0
H25: =F25*G25 -> 0 | W25: =(U25-T25)*24*60 -> 0
C26: 4度二組A | D26: 平均 | J26: =AVERAGE(J16:J25) -> 14.333333 | K26: =AVERAGE(K16:K25) -> 2250 | L26: =AVERAGE(L16:L25) -> 158.32256 | M26: =AVERAGE(M16:M25) -> 14.333333 | N26: =AVERAGE(N16:N25) -> 1873.4945 | O26: =AVERAGE(O16:O25) -> 131.88798 | P26: =M26-J26 -> 0 | Q26: =O26-L26 -> -26.434581 | R26: =O26/L26 -> 0.83303339 | Z26: =SUM(Z16:Z25) -> 0 | AA26: =SUM(AA16:AA25) -> 0 | AD26: =SUM(AD16:AD25) -> 0 | AE26: =SUM(AE16:AE25) -> 0 | AF26: =N26-K26 -> -376.50547 | AG26: =N26/K26 -> 0.83266424
A27: 手工三線 (ET-55) | B27: 義大利麵 | D27: 焗烤起司肉醬筆尖麵 | F27: =VLOOKUP(D27,廠價表!$C$1:$E$43,3,0) -> 50.67 | G27: 1169 | H27: =F27*G27 -> 59233.23 | J27: =VLOOKUP(D27,產線配置圖!$A$3:$C$40,2,0) -> 13 | K27: =VLOOKUP(D27,產線配置圖!$A$3:$C$40,3,0) -> 1440 | L27: =K27/J27 -> 110.76923 | M27: 13 | N27: =G27/W27*60 -> 1275.2727 | O27: =N27/M27 -> 98.097902 | P27: =M27-J27 -> 0 | Q27: =O27-L27 -> -12.671329 | R27: =O27/L27 -> 0.88560606 | S27: =R37 -> 0.91034064 | T27: 0.29166667 | U27: 0.32986111 | W27: =(U27-T27)*24*60 -> 55 | AF27: =N27-K27 -> -164.72727 | AG27: =N27/K27 -> 0.88560606 | AH27: =AG37 -> 0.87045049
B28: 義大利麵 | D28: 整條德式香腸義大利麵 | F28: =VLOOKUP(D28,廠價表!$C$1:$E$43,3,0) -> 57.21 | G28: 1123 | H28: =F28*G28 -> 64246.83 | J28: =VLOOKUP(D28,產線配置圖!$A$3:$C$40,2,0) -> 18 | K28: =VLOOKUP(D28,產線配置圖!$A$3:$C$40,3,0) -> 1565 | L28: =K28/J28 -> 86.944444 | M28: 17 | N28: =G28/W28*60 -> 1375.102 | O28: =N28/M28 -> 80.888355 | P28: =M28-J28 -> -1 | Q28: =O28-L28 -> -6.0560891 | R28: =O28/L28 -> 0.9303453 | T28: 0.33541667 | U28: 0.36944444 | V28: =(T28-U27)*24*60 -> 8 | W28: =(U28-T28)*24*60 -> 49 | AF28: =N28-K28 -> -189.89796 | AG28: =N28/K28 -> 0.87865945
B29: 義大利麵 | D29: 奶油鮮蝦明太子細扁麵 | F29: =VLOOKUP(D29,廠價表!$C$1:$E$43,3,0) -> 57.21 | G29: 2745 | H29: =F29*G29 -> 157041.45 | J29: =VLOOKUP(D29,產線配置圖!$A$3:$C$40,2,0) -> 18 | K29: =VLOOKUP(D29,產線配置圖!$A$3:$C$40,3,0) -> 1636 | L29: =K29/J29 -> 90.888889 | M29: 17 | N29: =G29/W29*60 -> 1407.6923 | O29: =N29/M29 -> 82.80543 | P29: =M29-J29 -> -1 | Q29: =O29-L29 -> -8.083459 | R29: =O29/L29 -> 0.91106219 | T29: 0.375 | U29: 0.45625 | V29: =(T29-U28)*24*60 -> 8 | W29: =(U29-T29)*24*60 -> 117 | AF29: =N29-K29 -> -228.30769 | AG29: =N29/K29 -> 0.86044762
B30: 義大利麵 | D30: 奶油鮮蝦明太子細扁麵 | F30: =VLOOKUP(D30,廠價表!$C$1:$E$43,3,0) -> 57.21 | G30: 1210 | H30: =F30*G30 -> 69224.1 | J30: =VLOOKUP(D30,產線配置圖!$A$3:$C$40,2,0) -> 18 | K30: =VLOOKUP(D30,產線配置圖!$A$3:$C$40,3,0) -> 1636 | L30: =K30/J30 -> 90.888889 | M30: 17 | N30: =G30/W30*60 -> 1396.1538 | O30: =N30/M30 -> 82.126697 | P30: =M30-J30 -> -1 | Q30: =O30-L30 -> -8.7621921 | R30: =O30/L30 -> 0.90359446 | T30: 0.51944444 | U30: 0.55555556 | V30: =(T30-U29)*24*60 -> 91 | W30: =(U30-T30)*24*60 -> 52 | AF30: =N30-K30 -> -239.84615 | AG30: =N30/K30 -> 0.85339477
B31: 義大利麵 | D31: 黑松露野菇義大利麵 | F31: =VLOOKUP(D31,廠價表!$C$1:$E$43,3,0) -> 50.289 | G31: 1852 | H31: =F31*G31 -> 93135.228 | J31: =VLOOKUP(D31,產線配置圖!$A$3:$C$40,2,0) -> 18 | K31: =VLOOKUP(D31,產線配置圖!$A$3:$C$40,3,0) -> 1565 | L31: =K31/J31 -> 86.944444 | M31: 17 | N31: =G31/W31*60 -> 1371.8519 | O31: =N31/M31 -> 80.697168 | P31: =M31-J31 -> -1 | Q31: =O31-L31 -> -6.2472767 | R31: =O31/L31 -> 0.92814634 | T31: 0.57777778 | U31: 0.63402778 | V31: =(T31-U30)*24*60 -> 32 | W31: =(U31-T31)*24*60 -> 81 | AB31: 13:28-13:44試產焦糖拿鐵烤雞細扁麵94份 | AF31: =N31-K31 -> -193.14815 | AG31: =N31/K31 -> 0.87658265
W32: =(U32-T32)*24*60 -> 0
W33: =(U33-T33)*24*60 -> 0
W34: =(U34-T34)*24*60 -> 0
W35: =(U35-T35)*24*60 -> 0
H36: =F36*G36 -> 0 | W36: =(U36-T36)*24*60 -> 0
C37: 4度二組B | D37: 平均 | J37: =AVERAGE(J27:J36) -> 17 | K37: =AVERAGE(K27:K36) -> 1568.4 | L37: =AVERAGE(L27:L36) -> 93.287179 | M37: =AVERAGE(M27:M36) -> 16.2 | N37: =AVERAGE(N27:N36) -> 1365.2146 | O37: =AVERAGE(O27:O36) -> 84.92311 | P37: =M37-J37 -> -0.8 | Q37: =N37-K37 -> -203.18545 | R37: =O37/L37 -> 0.91034064 | Z37: =SUM(Z27:Z36) -> 0 | AA37: =SUM(AA27:AA36) -> 0 | AD37: =SUM(AD27:AD36) -> 0 | AE37: =SUM(AE27:AE36) -> 0 | AF37: =N37-K37 -> -203.18545 | AG37: =N37/K37 -> 0.87045049
A38: 手工四線 (ET-55) | B38: 熱乾麵 | D38: 青花椒麻雞肉拌麵 | F38: =VLOOKUP(D38,廠價表!$C$1:$E$43,3,0) -> 49.91 | G38: 947 | H38: =F38*G38 -> 47264.77 | J38: =VLOOKUP(D38,產線配置圖!$A$3:$C$40,2,0) -> 15 | K38: =VLOOKUP(D38,產線配置圖!$A$3:$C$40,3,0) -> 1714 | L38: =K38/J38 -> 114.26667 | M38: 15 | N38: =G38/W38*60 -> 1262.6667 | O38: =N38/M38 -> 84.177778 | P38: =M38-J38 -> 0 | Q38: =O38-L38 -> -30.088889 | R38: =O38/L38 -> 0.73667834 | S38: =R48 -> 0.81271352 | T38: 0.33333333 | U38: 0.36458333 | W38: =(U38-T38)*24*60 -> 45 | AB38: 生產數量少、湯凍異常故延後開線 | AF38: =N38-K38 -> -451.33333 | AG38: =N38/K38 -> 0.73667834 | AH38: =AG48 -> 0.81498158
B39: 義大利麵 | D39: 焗烤起司肉醬筆尖麵 | F39: =VLOOKUP(D39,廠價表!$C$1:$E$43,3,0) -> 50.67 | G39: 395 | H39: =F39*G39 -> 20014.65 | J39: =VLOOKUP(D39,產線配置圖!$A$3:$C$40,2,0) -> 13 | K39: =VLOOKUP(D39,產線配置圖!$A$3:$C$40,3,0) -> 1440 | L39: =K39/J39 -> 110.76923 | M39: 13 | N39: =G39/W39*60 -> 1077.2727 | O39: =N39/M39 -> 82.867133 | P39: =M39-J39 -> 0 | Q39: =O39-L39 -> -27.902098 | R39: =O39/L39 -> 0.74810606 | T39: 0.39236111 | U39: 0.40763889 | V39: =(T39-U38)*24*60 -> 40 | W39: =(U39-T39)*24*60 -> 22 | AB39: 生產數量少 | AF39: =N39-K39 -> -362.72727 | AG39: =N39/K39 -> 0.74810606
B40: 熱乾麵 | D40: 青花椒麻雞肉拌麵 | F40: =VLOOKUP(D40,廠價表!$C$1:$E$43,3,0) -> 49.91 | G40: 1173 | H40: =F40*G40 -> 58544.43 | J40: =VLOOKUP(D40,產線配置圖!$A$3:$C$40,2,0) -> 15 | K40: =VLOOKUP(D40,產線配置圖!$A$3:$C$40,3,0) -> 1714 | L40: =K40/J40 -> 114.26667 | M40: 15 | N40: =G40/W40*60 -> 1599.5455 | O40: =N40/M40 -> 106.63636 | P40: =M40-J40 -> 0 | Q40: =O40-L40 -> -7.630303 | R40: =O40/L40 -> 0.93322372 | T40: 0.41388889 | U40: 0.44444444 | V40: =(T40-U39)*24*60 -> 9 | W40: =(U40-T40)*24*60 -> 44 | AF40: =N40-K40 -> -114.45455 | AG40: =N40/K40 -> 0.93322372
...

Sheet 0603總
B1: 長家廠組合室生產人時性分析
B3: 日期 | D3: 46176 | F3: 訂單量 | G3: ='0603'!E1 -> 55658 | I3: 營業額 | J3: ='0603'!G1 -> 2651893.7
B4: 項目 | D4: 3 | F4: ➀ | H4: ➁ | J4: ③ | L4: 異常停線 | N4: 短暫停線
B5: 人時性 | D5: 組合室 | F5: 全溫層 | H5: 義大利麵 | J5: 袋裝小吃、義麵 | L5: 合計次數 | M5: 時間 | N5: 合計次數 | O5: 設備次數
D6: 排關平均 | F6: =AVERAGE(D13:I13) -> 120.02477 | H6: =AVERAGE(D13:H13) -> 119.08457 | J6: =AVERAGE(I13) -> 124.72576 | L6: =SUM(D18:J18) -> 0 | M6: =SUM(D19:J19) -> 0 | N6: =SUM(D20:J20) -> 0 | O6: =SUM(D20:J20) -> 0
D7: 實績平均 | F7: =AVERAGE(D14:I14) -> 104.55711 | H7: =AVERAGE(D14:H14) -> 105.73305 | J7: =AVERAGE(I14) -> 98.677447 | L7: =AVERAGE(K14:L14) -> #DIV/0! | M7: =AVERAGE(L14:M14) -> #DIV/0! | N7: =AVERAGE(M14:N14) -> #DIV/0! | O7: =AVERAGE(N14:O14) -> #DIV/0!
D8: 達成率平均 | F8: =F7/F6 -> 0.87112947 | H8: =H7/H6 -> 0.887882 | J8: =J7/J6 -> 0.79115532 | L8: =AVERAGE(K15:L15) -> #DIV/0! | M8: =AVERAGE(L15:M15) -> #DIV/0! | N8: =AVERAGE(M15:N15) -> #DIV/0! | O8: =AVERAGE(N15:O15) -> #DIV/0!
J9: ※現行日本鮮食廠以達成率80%為基本(即為現行KPI)
B10: 溫層 | D10: 4度C-各編組展開
B11: 編組 | D11: 1 | E11: 2 | F11: 3 | G11: 4 | H11: 5 | I11: 6 | J11: 7
D12: 自動1線 | E12: 自動2線 | F12: 手工3線 | G12: 手工4線 | H12: 手工5線 | I12: 調理包1線 | J12: 調理包2線
B13: 人時性 | C13: 排關 | D13: =VALUE('0603'!L15) -> 138.17778 | E13: =VALUE('0603'!L26) -> 157.84421 | F13: =VALUE('0603'!L37) -> 96.200855 | G13: =VALUE('0603'!L48) -> 102.24575 | H13: =VALUE('0603'!L58) -> 100.95425 | I13: =VALUE('0603'!L69) -> 124.72576 | J13: ='0603'!L79 -> 0
C14: 實績 | D14: =VALUE('0603'!O15) -> 121.74859 | E14: =VALUE('0603'!O26) -> 136.93895 | F14: =VALUE('0603'!O37) -> 86.978469 | G14: =VALUE('0603'!O48) -> 93.728224 | H14: =VALUE('0603'!O58) -> 89.270995 | I14: =VALUE('0603'!O69) -> 98.677447 | J14: ='0603'!O79 -> 0
C15: 達成率 | D15: =D14/D13 -> 0.8811011 | E15: =E14/E13 -> 0.8675576 | F15: =F14/F13 -> 0.90413406 | G15: =G14/G13 -> 0.91669553 | H15: =H14/H13 -> 0.8842718 | I15: =I14/I13 -> 0.79115532 | J15: ='0603'!S70 -> 0
B16: 作業 時間 | C16: 開始 | D16: ='0603'!T5 -> 0.29166667 | E16: ='0603'!T16 -> 0.29166667 | F16: ='0603'!T27 -> 0.29166667 | G16: ='0603'!T38 -> 0.33333333 | H16: ='0603'!T49 -> 0.29166667 | I16: ='0603'!T59 -> 0.29166667 | J16: ='0603'!T70 -> 0.34722222
C17: 結束 | D17: 0.64236111 | E17: 0.60277778 | F17: 0.46180556 | G17: 0.62847222 | H17: 0.65486111 | I17: 0.64930556 | J17: 0
B18: 產線異常 (5分鐘以上) | C18: 次數 | D18: ='0603'!Z15 -> 0 | E18: ='0603'!Z26 -> 0 | F18: ='0603'!Z37 -> 0 | G18: ='0603'!Z48 -> 0 | H18: ='0603'!Z58 -> 0 | I18: ='0603'!Z69 -> 0 | J18: ='0603'!AA79 -> 0
C19: 時間/分 | D19: ='0603'!AA15 -> 0 | E19: ='0603'!AA26 -> 0 | F19: ='0603'!AA37 -> 0 | G19: ='0603'!AA48 -> 0 | H19: ='0603'!AA58 -> 0 | I19: ='0603'!AA69 -> 0 | J19: ='0603'!AB79 -> 0
B20: 短暫停線 (5分鐘以下) | C20: 次數 | D20: ='0603'!AD15 -> 0 | E20: ='0603'!AD26 -> 0 | F20: ='0603'!AD37 -> 0 | G20: ='0603'!AD48 -> 0 | H20: ='0603'!AD58 -> 0 | I20: ='0603'!AD69 -> 0 | J20: ='0603'!AD79 -> 0
C21: 設備次數 | D21: ='0603'!AE15 -> 0 | E21: ='0603'!AE26 -> 0 | F21: ='0603'!AE37 -> 0 | G21: ='0603'!AE48 -> 0 | H21: ='0603'!AE58 -> 0 | I21: ='0603'!AE69 -> 0 | J21: ='0603'!AE79 -> 0
B22: 配置人數 | D22: =VALUE('0603'!M15) -> 15.4 | E22: =VALUE('0603'!M26) -> 14.4 | F22: =VALUE('0603'!M37) -> 16.333333 | G22: =VALUE('0603'!M48) -> 16 | H22: =VALUE('0603'!M58) -> 16.8 | I22: =VALUE('0603'!M69) -> 14.8 | J22: ='0603'!M79 -> 0
B23: 主要應用設備 | D23: ET-600 | E23: ET-600 | F23: ET-55 | G23: ET-55 | H23: ET-55 | I23: 八爪機 | J23: 八爪機
B24: 次要應用設備 | H24: 封口機 | J24: 封口機
B25: 備註

Sheet 0603
A1: 長家廠4度C日報分析 | D1: 總生產量 | E1: =SUM(G5:G79) -> 55658 | F1: 營業額 | G1: =SUM(H5:H79) -> 2651893.7 | H1: 出勤人數 | I1: =M15+M26+M48+M58+M69+M79+M37 -> 93.733333 | J1: 產線配置圖 | M1: 生產實績 | P1: 人時性差異分析 | T1: 日報登錄 | Z1: 合計 次數 | AA1: 合計 時間/分 | AB1: 分析說明 | AD1: 合計 次數 | AE1: 合計 設備次數 | AF1: 產能差異分析
A2: 06月02日 星期三 | D2: 人時性 | E2: =AVERAGE(O15,O26,O37,O48,O58,O69,O79) -> 104.55711 | F2: 平均廠價 | G2: =G1/E1 -> 47.646227 | H2: 多次生產數 | I2: =COUNT(I5:I79) -> 0 | Z2: =Z15+Z26+Z37+Z48+Z58+Z69+Z79 -> 0 | AA2: =AA15+AA26+AA37+AA48+AA58+AA69+AA79 -> 0 | AD2: =AD15+AD26+AD37+AD48+AD58+AD69+AD79 -> 0 | AE2: =AE15+AE26+AE37+AE48+AE58+AE69+AE79 -> 0
A3: 線別 | B3: 品類 | D3: 品名 | F3: 廠價 | G3: 生產量 | H3: 營收 | I3: 多次 生產 | J3: 人數 | K3: 產能/時 | L3: 人時性 | M3: 人數 | N3: 產能/時 | O3: 人時性 | P3: 人數 | Q3: 人時性 | R3: 達成率 | S3: 達成率平均 | T3: 生產時間 | V3: 前置、換線時間/分 | W3: 稼動時間/分 | X3: 休息時間 | Z3: 產線異常統計 (5分鐘以上) | AD3: 短暫停線統計 (5分鐘以下) | AF3: 產能/時 | AG3: 達成率 | AH3: 達成率平均
T4: 開始 | U4: 結束 | X4: 開始 | Y4: 結束 | Z4: 次數 | AA4: 時間/分 | AD4: 總次數 | AE4: 設備因素(次數)
A5: 自動一線 (ET-600) | B5: 義大利麵 | D5: 白酒清炒鮮蛤義大利麵 | F5: =VLOOKUP(D5,廠價表!$C$1:$E$43,3,0) -> 56.87 | G5: 2718 | H5: =F5*G5 -> 154572.66 | J5: =VLOOKUP(D5,產線配置圖!$A$3:$C$40,2,0) -> 15 | K5: =VLOOKUP(D5,產線配置圖!$A$3:$C$40,3,0) -> 2250 | L5: =K5/J5 -> 150 | M5: 15 | N5: =G5/W5*60 -> 2145.7895 | O5: =N5/M5 -> 143.05263 | P5: =M5-J5 -> 0 | Q5: =O5-L5 -> -6.9473684 | R5: =O5/L5 -> 0.95368421 | S5: =R15 -> 0.8811011 | T5: 0.29166667 | U5: 0.34444444 | W5: =(U5-T5)*24*60 -> 76 | AF5: =N5-K5 -> -104.21053 | AG5: =N5/K5 -> 0.95368421 | AH5: =AG15 -> 0.87015281
B6: 義大利麵 | D6: 香煎魚排佐檸檬奶油義大利麵 | F6: =VLOOKUP(D6,廠價表!$C$1:$E$43,3,0) -> 58.17 | G6: 3088 | H6: =F6*G6 -> 179628.96 | J6: =VLOOKUP(D6,產線配置圖!$A$3:$C$40,2,0) -> 15 | K6: =VLOOKUP(D6,產線配置圖!$A$3:$C$40,3,0) -> 2250 | L6: =K6/J6 -> 150 | M6: 15 | N6: =G6/W6*60 -> 2154.4186 | O6: =N6/M6 -> 143.62791 | P6: =M6-J6 -> 0 | Q6: =O6-L6 -> -6.372093 | R6: =O6/L6 -> 0.95751938 | T6: 0.35208333 | U6: 0.41180556 | V6: =(T6-U5)*24*60 -> 11 | W6: =(U6-T6)*24*60 -> 86 | AF6: =N6-K6 -> -95.581395 | AG6: =N6/K6 -> 0.95751938
B7: 義大利麵 | D7: 奶油培根義大利麵 | F7: =VLOOKUP(D7,廠價表!$C$1:$E$43,3,0) -> 49.14 | G7: 2886 | H7: =F7*G7 -> 141818.04 | J7: =VLOOKUP(D7,產線配置圖!$A$3:$C$40,2,0) -> 15 | K7: =VLOOKUP(D7,產線配置圖!$A$3:$C$40,3,0) -> 2250 | L7: =K7/J7 -> 150 | M7: 15 | N7: =G7/W7*60 -> 2013.4884 | O7: =N7/M7 -> 134.23256 | P7: =M7-J7 -> 0 | Q7: =O7-L7 -> -15.767442 | R7: =O7/L7 -> 0.89488372 | T7: 0.41944444 | U7: 0.47916667 | V7: =(T7-U6)*24*60 -> 11 | W7: =(U7-T7)*24*60 -> 86 | AF7: =N7-K7 -> -236.51163 | AG7: =N7/K7 -> 0.89488372
B8: 義大利麵 | D8: 奶油培根義大利麵 | F8: =VLOOKUP(D8,廠價表!$C$1:$E$43,3,0) -> 49.14 | G8: 2676 | H8: =F8*G8 -> 131498.64 | J8: =VLOOKUP(D8,產線配置圖!$A$3:$C$40,2,0) -> 15 | K8: =VLOOKUP(D8,產線配置圖!$A$3:$C$40,3,0) -> 2250 | L8: =K8/J8 -> 150 | M8: 15 | N8: =G8/W8*60 -> 1888.9412 | O8: =N8/M8 -> 125.92941 | P8: =M8-J8 -> 0 | Q8: =O8-L8 -> -24.070588 | R8: =O8/L8 -> 0.83952941 | T8: 0.54166667 | U8: 0.60069444 | V8: =(T8-U7)*24*60 -> 90 | W8: =(U8-T8)*24*60 -> 85 | AF8: =N8-K8 -> -361.05882 | AG8: =N8/K8 -> 0.83952941
B9: 義大利麵 | D9: 奶油鮮蝦明太子細扁麵 | F9: =VLOOKUP(D9,廠價表!$C$1:$E$43,3,0) -> 57.21 | G9: 684 | H9: =F9*G9 -> 39131.64 | J9: =VLOOKUP(D9,產線配置圖!$A$3:$C$40,2,0) -> 18 | K9: =VLOOKUP(D9,產線配置圖!$A$3:$C$40,3,0) -> 1636 | L9: =K9/J9 -> 90.888889 | M9: 17 | N9: =G9/W9*60 -> 1052.3077 | O9: =N9/M9 -> 61.900452 | P9: =M9-J9 -> -1 | Q9: =O9-L9 -> -28.988436 | R9: =O9/L9 -> 0.68105632 | T9: 0.61527778 | U9: 0.64236111 | V9: =(T9-U8)*24*60 -> 21 | W9: =(U9-T9)*24*60 -> 39 | AB9: 生產數量少、支援製作 | AF9: =N9-K9 -> -583.69231 | AG9: =N9/K9 -> 0.64321986
W10: =(U10-T10)*24*60 -> 0 | AF10: =N10-K10 -> 0 | AG10: =N10/K10 -> #DIV/0!
W11: =(U11-T11)*24*60 -> 0 | AF11: =N11-K11 -> 0 | AG11: =N11/K11 -> #DIV/0!
W12: =(U12-T12)*24*60 -> 0
W13: =(U13-T13)*24*60 -> 0
W14: =(U14-T14)*24*60 -> 0
C15: 4度一組 | D15: 平均 | J15: =AVERAGE(J5:J14) -> 15.6 | K15: =AVERAGE(K5:K14) -> 2127.2 | L15: =AVERAGE(L5:L14) -> 138.17778 | M15: =AVERAGE(M5:M14) -> 15.4 | N15: =AVERAGE(N5:N14) -> 1850.9891 | O15: =AVERAGE(O5:O14) -> 121.74859 | P15: =M15-J15 -> -0.2 | Q15: =O15-L15 -> -16.429186 | R15: =O15/L15 -> 0.8811011 | Z15: =SUM(Z5:Z14) -> 0 | AA15: =SUM(AA5:AA14) -> 0 | AD15: =SUM(AD5:AD14) -> 0 | AE15: =SUM(AE5:AE14) -> 0 | AF15: =N15-K15 -> -276.21094 | AG15: =N15/K15 -> 0.87015281
A16: 自動二線 (ET-600) | B16: 義大利麵 | D16: 青醬蛤蜊義大利麵 | F16: =VLOOKUP(D16,廠價表!$C$1:$E$43,3,0) -> 50.67 | G16: 3184 | H16: =F16*G16 -> 161333.28 | J16: =VLOOKUP(D16,產線配置圖!$A$3:$C$40,2,0) -> 14 | K16: =VLOOKUP(D16,產線配置圖!$A$3:$C$40,3,0) -> 2250 | L16: =K16/J16 -> 160.71429 | M16: 14 | N16: =G16/W16*60 -> 2170.9091 | O16: =N16/M16 -> 155.06494 | P16: =M16-J16 -> 0 | Q16: =O16-L16 -> -5.6493506 | R16: =O16/L16 -> 0.96484848 | S16: =R26 -> 0.8675576 | T16: 0.29166667 | U16: 0.35277778 | W16: =(U16-T16)*24*60 -> 88 | AF16: =N16-K16 -> -79.090909 | AG16: =N16/K16 -> 0.96484848 | AH16: =AG26 -> 0.86632479
B17: 義大利麵 | D17: 蒜香奶油蝦蝦義大利麵 | F17: =VLOOKUP(D17,廠價表!$C$1:$E$43,3,0) -> 57.21 | G17: 1962 | H17: =F17*G17 -> 112246.02 | J17: =VLOOKUP(D17,產線配置圖!$A$3:$C$40,2,0) -> 17 | K17: =VLOOKUP(D17,產線配置圖!$A$3:$C$40,3,0) -> 2250 | L17: =K17/J17 -> 132.35294 | M17: 17 | N17: =G17/W17*60 -> 1839.375 | O17: =N17/M17 -> 108.19853 | P17: =M17-J17 -> 0 | Q17: =O17-L17 -> -24.154412 | R17: =O17/L17 -> 0.8175 | T17: 0.36041667 | U17: 0.40486111 | V17: =(T17-U16)*24*60 -> 11 | W17: =(U17-T17)*24*60 -> 64 | AF17: =N17-K17 -> -410.625 | AG17: =N17/K17 -> 0.8175
B18: 義大利麵 | D18: 義式辣味嫩烤雞腿排義大利麵 | F18: =VLOOKUP(D18,廠價表!$C$1:$E$43,3,0) -> 56.61 | G18: 1222 | H18: =F18*G18 -> 69177.42 | J18: =VLOOKUP(D18,產線配置圖!$A$3:$C$40,2,0) -> 15 | K18: =VLOOKUP(D18,產線配置圖!$A$3:$C$40,3,0) -> 2250 | L18: =K18/J18 -> 150 | M18: 15 | N18: =G18/W18*60 -> 1929.4737 | O18: =N18/M18 -> 128.63158 | P18: =M18-J18 -> 0 | Q18: =O18-L18 -> -21.368421 | R18: =O18/L18 -> 0.85754386 | T18: 0.41111111 | U18: 0.4375 | V18: =(T18-U17)*24*60 -> 9 | W18: =(U18-T18)*24*60 -> 38 | AF18: =N18-K18 -> -320.52632 | AG18: =N18/K18 -> 0.85754386
